{
  "xsize": 16,
  "zsize": 16,
  "refpalette": "lcmt:rails",
  "slices": [
    [
      "      yyIyy     ",
      "      yyIyy     ",
      "      yyIyy     ",
      "      yyIyy     ",
      "      yyIyy     ",
      "      yyIyy     ",
      "      yyIyy     ",
      "      yyIyy     ",
      "      yyIyy     ",
      "      yyIyy     ",
      "      yyIyy     ",
      "      yyIyy     ",
      "      yyIyy     ",
      "      yyIyy     ",
      "      yyIyy     ",
      "      yyIyy     "
    ],
    [
      "      yJkJy     ",
      "      yJkJy     ",
      "      yJkJy     ",
      "      yJkJy     ",
      "      yJkJy     ",
      "      yJkJy     ",
      "      yJkJy     ",
      "      yJkJy     ",
      "      ygmgy     ",
      "      yJkJy     ",
      "      yJkJy     ",
      "      yJkJy     ",
      "      yJkJy     ",
      "      yJkJy     ",
      "      yJkJy     ",
      "      yJkJy     "
    ],
    [
      "      y~~~y     ",
      "      y~~~y     ",
      "      y~~~y     ",
      "      y~~~y     ",
      "      y~~~y     ",
      "      y~~~y     ",
      "      y~~~y     ",
      "      y~~~y     ",
      "      y~~~y     ",
      "      y~~~y     ",
      "      y~~~y     ",
      "      y~~~y     ",
      "      y~~~y     ",
      "      y~~~y     ",
      "      y~~~y     ",
      "      y~~~y     "
    ],
    [
      "      +~~~+     ",
      "      +~~~+     ",
      "      +~~~+     ",
      "      +~~~+     ",
      "      +~~~+     ",
      "      +~~~+     ",
      "      +~~~+     ",
      "      +~~~+     ",
      "      +~~~+     ",
      "      +~~~+     ",
      "      +~~~+     ",
      "      +~~~+     ",
      "      +~~~+     ",
      "      +~~~+     ",
      "      +~~~+     ",
      "      +~~~+     "
    ],
    [
      "      +~~~+     ",
      "      +~~~+     ",
      "      +~~~+     ",
      "      +~~~+     ",
      "      +~~~+     ",
      "      +~~~+     ",
      "      +~~~+     ",
      "      +~~~+     ",
      "      +~~~+     ",
      "      +~~~+     ",
      "      +~~~+     ",
      "      +~~~+     ",
      "      +~~~+     ",
      "      +~~~+     ",
      "      +~~~+     ",
      "      +~~~+     "
    ],
    [
      "      yy+yy     ",
      "      yy+yy     ",
      "      yy+yy     ",
      "      yy+yy     ",
      "      yy+yy     ",
      "      yy+yy     ",
      "      yy+yy     ",
      "      yy+yy     ",
      "      yyOyy     ",
      "      yy+yy     ",
      "      yy+yy     ",
      "      yy+yy     ",
      "      yy+yy     ",
      "      yy+yy     ",
      "      yy+yy     ",
      "      yy+yy     "
    ]
  ]
}