{
  "xsize": 16,
  "zsize": 16,
  "refpalette": "lostcities:rails",
  "slices": [
    [
      "                ",
      "                ",
      "                ",
      "yy              ",
      "yy              ",
      "II              ",
      "yyy             ",
      "II              ",
      "yyy             ",
      "II              ",
      "yy              ",
      "yy              ",
      "                ",
      "                ",
      "                ",
      "                "
    ],
    [
      "                ",
      "                ",
      "                ",
      "yyy             ",
      "JJy             ",
      "fiI             ",
      "JJg             ",
      "fiI             ",
      "JJg             ",
      "fiI             ",
      "JJy             ",
      "yyy             ",
      "                ",
      "                ",
      "                ",
      "                "
    ],
    [
      "                ",
      "                ",
      "                ",
      "yyyy            ",
      "~~Jy            ",
      "~~iI            ",
      "~~Jy            ",
      "~~iI            ",
      "~~Jy            ",
      "~~iI            ",
      "~~Jy            ",
      "yyyy            ",
      "                ",
      "                ",
      "                ",
      "                "
    ],
    [
      "                ",
      "                ",
      "                ",
      "yyyyy           ",
      "~~~Jy           ",
      "~~~jI           ",
      "~~~Jy           ",
      "~~~jI           ",
      "~~~Jy           ",
      "~~~jI           ",
      "~~~Jy           ",
      "yyyyy           ",
      "                ",
      "                ",
      "                ",
      "                "
    ],
    [
      "                ",
      "                ",
      "                ",
      "yyyyyy          ",
      "~~~~Jy          ",
      "~~~~jI          ",
      "~~~~Jy          ",
      "~~~~jI          ",
      "~~~~Jy          ",
      "~~~~jI          ",
      "~~~~Jy          ",
      "yyyyyy          ",
      "                ",
      "                ",
      "                ",
      "                "
    ],
    [
      "                ",
      "                ",
      "                ",
      "yyyyyyy         ",
      "y~~~~Jy         ",
      "y~~~~jI         ",
      "y~~~~Jy         ",
      "y~~~~jI         ",
      "y~~~~Jy         ",
      "y~~~~jI         ",
      "y~~~~Jy         ",
      "yyyyyyy         ",
      "                ",
      "                ",
      "                ",
      "                "
    ],
    [
      "                ",
      "                ",
      "                ",
      " yyyyyyy        ",
      " y~~~~Jy        ",
      " y~~~~jI        ",
      " y~~~~Jy        ",
      " y~~~~jI        ",
      " y~~~~Jy        ",
      " y~~~~jI        ",
      " y~~~~Jy        ",
      " yyyyyyy        ",
      "                ",
      "                ",
      "                ",
      "                "
    ],
    [
      "                ",
      "                ",
      "                ",
      "  yyyyyyy       ",
      "  y~~~~Jy       ",
      "  y~~~~iI       ",
      "  y~~~~Jyy      ",
      "  y~~~~iI       ",
      "  y~~~~Jyy      ",
      "  y~~~~iI       ",
      "  y~~~~Jy       ",
      "  yyyyyyy       ",
      "                ",
      "                ",
      "                ",
      "                "
    ],
    [
      "                ",
      "                ",
      "                ",
      "   yyyyyyy      ",
      "   y~~~~Jy      ",
      "   y~~~~iI      ",
      "   y~~~~Jg      ",
      "   y~~~~iI      ",
      "   y~~~~Jg      ",
      "   y~~~~iI      ",
      "   y~~~~Jy      ",
      "   yyyyyyy      ",
      "                ",
      "                ",
      "                ",
      "                "
    ],
    [
      "                ",
      "                ",
      "                ",
      "    yyyyyyy     ",
      "    y~~~~Jy     ",
      "    y~~~~iI     ",
      "    y~~~~Jy     ",
      "    y~~~~iI     ",
      "    y~~~~Jy     ",
      "    y~~~~iI     ",
      "    y~~~~Jy     ",
      "    yyyyyyy     ",
      "                ",
      "                ",
      "                ",
      "                "
    ],
    [
      "                ",
      "                ",
      "                ",
      "     yyyyyyy    ",
      "     y~~~~Jy    ",
      "     y~~~~jI    ",
      "     y~~~~Jy    ",
      "     y~~~~jI    ",
      "     y~~~~Jy    ",
      "     y~~~~jI    ",
      "     y~~~~Jy    ",
      "     yyyyyyy    ",
      "                ",
      "                ",
      "                ",
      "                "
    ],
    [
      "                ",
      "                ",
      "                ",
      "      yyyyyyy   ",
      "      y~~~~Jy   ",
      "      y~~~~jI   ",
      "      y~~~~Jy y ",
      "      y~~~~jI   ",
      "      y~~~~Jy y ",
      "      y~~~~jI   ",
      "      y~~~~Jy   ",
      "      yyyyyyy   ",
      "                ",
      "                ",
      "                ",
      "                "
    ],
    [
      "                ",
      "                ",
      "                ",
      "       yyyyyyyyy",
      "       y~~~~Jyyy",
      "       y~~~~jIII",
      "       y~~~~Jygy",
      "       y~~~~jIII",
      "       y~~~~Jygy",
      "       y~~~~jIII",
      "       y~~~~Jyyy",
      "       yyyyyyyyy",
      "                ",
      "                ",
      "                ",
      "                "
    ],
    [
      "                ",
      "                ",
      "                ",
      "        yyyyyyyy",
      "        y~~~~JJJ",
      "        y~~~~fff",
      "        y~~~~JJJ",
      "        y~~~~fff",
      "        y~~~~JJJ",
      "        y~~~~fff",
      "        y~~~~JJJ",
      "        yyyyyyyy",
      "                ",
      "                ",
      "                ",
      "                "
    ],
    [
      "                ",
      "                ",
      "                ",
      "         yyyyyyy",
      "         y~~~~~~",
      "         y~~~~~~",
      "         y~~~~~~",
      "         y~~~~~~",
      "         y~~~~~~",
      "         y~~~~~~",
      "         y~~~~~~",
      "         yyyyyyy",
      "                ",
      "                ",
      "                ",
      "                "
    ],
    [
      "                ",
      "                ",
      "                ",
      "          yyyyyy",
      "          y~~~~~",
      "          y~~~~~",
      "          y~~~~~",
      "          y~~~~~",
      "          y~~~~~",
      "          y~~~~~",
      "          y~~~~~",
      "          yyyyyy",
      "                ",
      "                ",
      "                ",
      "                "
    ],
    [
      "                ",
      "                ",
      "                ",
      "           yyyyy",
      "           y~~~~",
      "           y~~~~",
      "           y~~~~",
      "           y~~~~",
      "           y~~~~",
      "           y~~~~",
      "           y~~~~",
      "           yyyyy",
      "                ",
      "                ",
      "                ",
      "                "
    ],
    [
      "                ",
      "                ",
      "                ",
      "            yyyy",
      "            yyyy",
      "            yyyy",
      "            yyyy",
      "            yyyy",
      "            yyyy",
      "            yyyy",
      "            yyyy",
      "            yyyy",
      "                ",
      "                ",
      "                ",
      "                "
    ]
  ]
}