{
  "xsize": 16,
  "zsize": 16,
  "refpalette": "lcmt:rails",
  "slices": [
    [
      "y              y",
      "y              y",
      "y              y",
      "yyyyyyyyyyyyyyyy",
      "yyyyyyyyyyyyyyyy",
      "IIIIIIIIIIIIIIII",
      "yyyyyyyyyyyyyyyy",
      "IIIIIIIIIIIIIIII",
      "yyyyyyyyyyyyyyyy",
      "IIIIIIIIIIIIIIII",
      "yyyyyyyyyyyyyyyy",
      "yyyyyyyyyyyyyyyy",
      "y              y",
      "y              y",
      "y              y",
      "y               "
    ],
    [
      "y              y",
      "y              y",
      "y              y",
      "yyyyyyyyyyyyyyyy",
      "JJJJJJJJJJJJJJJJ",
      "eeeeeeefeeeeeeee",
      "JJJJJJJgJJJJJJJJ",
      "eeeeeeefeeeeeeee",
      "JJJJJJJgJJJJJJJJ",
      "eeeeeeefeeeeeeee",
      "JJJJJJJJJJJJJJJJ",
      "yyyyyyyyyyyyyyyy",
      "y              y",
      "y              y",
      "y              y",
      "y               "
    ],
    [
      "y              y",
      "y              y",
      "y              y",
      "yyyyyyyyyyyyyyyy",
      "~~~~~~~~~~~~~~~~",
      "~~~~~~~~~~~~~~~~",
      "~~~~~~~~~~~~~~~~",
      "~~~~~~~~~~~~~~~~",
      "~~~~~~~~~~~~~~~~",
      "~~~~~~~~~~~~~~~~",
      "~~~~~~~~~~~~~~~~",
      "yyyyyyyyyyyyyyyy",
      "y              y",
      "y              y",
      "y              y",
      "y               "
    ],
    [
      "y              y",
      "y              y",
      "y              y",
      "yyyyyyyyyyyyyyyy",
      "~~~~~~~~~~~~~~~~",
      "~~~~~~~~~~~~~~~~",
      "~~~~~~~~~~~~~~~~",
      "~~~~~~~~~~~~~~~~",
      "~~~~~~~~~~~~~~~~",
      "~~~~~~~~~~~~~~~~",
      "~~~~~~~~~~~~~~~~",
      "yyyyyyyyyyyyyyyy",
      "y              y",
      "y              y",
      "y              y",
      "y               "
    ],
    [
      "y              y",
      "y              y",
      "y              y",
      "yyyyyyyyyyyyyyyy",
      "~~~~~~~~~~~~~~~~",
      "~~~~~~~~~~~~~~~~",
      "~~~~~~~~~~~~~~~~",
      "~~~~~~~~~~~~~~~~",
      "~~~~~~~~~~~~~~~~",
      "~~~~~~~~~~~~~~~~",
      "~~~~~~~~~~~~~~~~",
      "yyyyyyyyyyyyyyyy",
      "y              y",
      "y              y",
      "y              y",
      "y               "
    ],
    [
      "y              y",
      "y              y",
      "y              y",
      "yyyyyyyyyyyyyyyy",
      "yyyyyyyyyyyyyyyy",
      "yyyyyyyyyyyyyyyy",
      "yyyyyyyyyyyyyyyy",
      "yyyyyyyoyyyyyyyy",
      "yyyyyyyyyyyyyyyy",
      "yyyyyyyyyyyyyyyy",
      "yyyyyyyyyyyyyyyy",
      "yyyyyyyyyyyyyyyy",
      "y              y",
      "y              y",
      "y              y",
      "y               "
    ]
  ]
}