{
  "xsize": 16,
  "zsize": 16,
  "refpalette": "lcmt:rails",
  "slices": [
    [
      "      yyIyy     ",
      "      yyIyy     ",
      "      yyIyy     ",
      "      yyIyy     ",
      "      yyIyy     ",
      "      yyIyy     ",
      "      yyIyy     ",
      "      yyIyy     ",
      "      yyIyy     ",
      "      yyIyy     ",
      "      yyIyy     ",
      "      yyIyy     ",
      "      yyIyy     ",
      "      yyIyy     ",
      "      yyIyy     ",
      "      yyIyy     "
    ],
    [
      "      yJkJy     ",
      "      yJkJy     ",
      "      yJkJy     ",
      "      yJkJy     ",
      "      yJkJy     ",
      "      yJkJy     ",
      "      yJkJy     ",
      "      yJkJy     ",
      "      ygmgy     ",
      "      yJkJy     ",
      "      yJkJy     ",
      "      yJkJy     ",
      "      yJkJy     ",
      "      yJkJy     ",
      "      yJkJy     ",
      "      yJkJy     "
    ],
    [
      "      y~~~y     ",
      "      y~~~y     ",
      "      y~~~y     ",
      "      y~~~y     ",
      "      y~~~y     ",
      "      y~~~y     ",
      "      y~~~y     ",
      "      y~~~y     ",
      "      y~~~y     ",
      "      y~~~y     ",
      "      y~~~y     ",
      "      y~~~y     ",
      "      y~~~y     ",
      "      y~~~y     ",
      "      y~~~y     ",
      "      y~~~y     "
    ],
    [
      "      y~~~y     ",
      "      y~~~y     ",
      "      y~~~y     ",
      "      y~~~y     ",
      "      y~~~y     ",
      "      y~~~y     ",
      "      y~~~y     ",
      "      y~~~y     ",
      "      y~~~y     ",
      "      y~~~y     ",
      "      y~~~y     ",
      "      y~~~y     ",
      "      y~~~y     ",
      "      y~~~y     ",
      "      y~~~y     ",
      "      y~~~y     "
    ],
    [
      "      y~~~y     ",
      "      y~~~y     ",
      "      y~~~y     ",
      "      y~~~y     ",
      "      y~~~y     ",
      "      y~~~y     ",
      "      y~~~y     ",
      "      y~~~y     ",
      "      y~~~y     ",
      "      y~~~y     ",
      "      y~~~y     ",
      "      y~~~y     ",
      "      y~~~y     ",
      "      y~~~y     ",
      "      y~~~y     ",
      "      y~~~y     "
    ],
    [
      "      yyyyy     ",
      "      yyyyy     ",
      "      yyyyy     ",
      "      yyyyy     ",
      "      yyyyy     ",
      "      yyyyy     ",
      "      yyyyy     ",
      "      yyyyy     ",
      "      yyoyy     ",
      "      yyyyy     ",
      "      yyyyy     ",
      "      yyyyy     ",
      "      yyyyy     ",
      "      yyyyy     ",
      "      yyyyy     ",
      "      yyyyy     "
    ]
  ]
}