{
  "xsize": 16,
  "zsize": 16,
  "refpalette": "lcmt:rails",
  "slices": [
    [
      "y              y",
      "y              y",
      "y              y",
      "yyyyyyyyyyyyyyyy",
      "yyyyyyyyyyyyyyyy",
      "IIIIIIIIIIIyyyyI",
      "yyyyyyyyyyyyyyyy",
      "IIIIIIIIIIIyyyyI",
      "yyyyyyyyyyyyyyyy",
      "IIIIIIIIIIIyyyyI",
      "yyyyyyyyyyyyyyyy",
      "yyyyyyyyyyyyyyyy",
      "y              y",
      "y              y",
      "y              y",
      "y               "
    ],
    [
      "y              y",
      "y              y",
      "y              y",
      "yyyyyyyyyyyyyyyy",
      "JJJJJJJJJJJJJJJJ",
      "eeeeeeefeeeJyyJe",
      "JJJJJJJgJJJJyyJJ",
      "eeeeeeefeeeJyyJe",
      "JJJJJJJgJJJJyyJJ",
      "eeeeeeefeeeJyyJe",
      "JJJJJJJJJJJJJJJJ",
      "yyyyyyyyyyyyyyyy",
      "y              y",
      "y              y",
      "y              y",
      "y               "
    ],
    [
      "y              y",
      "y              y",
      "y              y",
      "yyyyyyyyyyyyyyyy",
      "~~~~~~~~~~~~~~~y",
      "~~~~~~~~~~~~~~~y",
      "~~~~~~~~~~~~~~~y",
      "~~~~~~~~~~~~~~~y",
      "~~~~~~~~~~~~~~~y",
      "~~~~~~~~~~~~~~~y",
      "~~~~~~~~~~~~~~~y",
      "yyyyyyyyyyyyyyyy",
      "y              y",
      "y              y",
      "y              y",
      "y               "
    ],
    [
      "y              y",
      "y              y",
      "y              y",
      "yyyyyyyyyyyyyyyy",
      "~~~~~~~~~~~~~~~y",
      "~~~~~~~~~~~~~~~y",
      "~~~~~~~~~~~~~~~y",
      "~~~~~~~~~~~~~~~y",
      "~~~~~~~~~~~~~~~y",
      "~~~~~~~~~~~~~~~y",
      "~~~~~~~~~~~~~~~y",
      "yyyyyyyyyyyyyyyy",
      "y              y",
      "y              y",
      "y              y",
      "y               "
    ],
    [
      "y              y",
      "y              y",
      "y              y",
      "yyyyyyyyyyyyyyyy",
      "~~~~~~~~~~~~~~~y",
      "~~~~~~~~~~~~~~~y",
      "~~~~~~~~~~~~~~~y",
      "~~~~~~~~~~~~~~~y",
      "~~~~~~~~~~~~~~~y",
      "~~~~~~~~~~~~~~~y",
      "~~~~~~~~~~~~~~~y",
      "yyyyyyyyyyyyyyyy",
      "y              y",
      "y              y",
      "y              y",
      "y               "
    ],
    [
      "y              y",
      "y              y",
      "y              y",
      "yyyyyyyyyyyyyyyy",
      "yyyyyyyyyyyyyyyy",
      "yyyyyyyyyyyyyyyy",
      "yyyyyyyyyyyyyyyy",
      "yyyyyyyoyyyyyyyy",
      "yyyyyyyyyyyyyyyy",
      "yyyyyyyyyyyyyyyy",
      "yyyyyyyyyyyyyyyy",
      "yyyyyyyyyyyyyyyy",
      "y              y",
      "y              y",
      "y              y",
      "y               "
    ]
  ]
}