{
  "xsize": 16,
  "zsize": 16,
  "refpalette": "lcmt:rails",
  "slices": [
    [
      "      yyIyy     ",
      "      yyIyy     ",
      "      yyIyy     ",
      "yyyyyyyyIyyyyyyy",
      "yyyyyyyyIyyyyyyy",
      "yyyyyyyyIIIIIIII",
      "yyyyyyyyyyyyyyyy",
      "IIIIIIIIIIIIIIII",
      "yyyyyyyyyyyyyyyy",
      "yyyyyyyyIIIIIIII",
      "yyyyyyyyIyyyyyyy",
      "yyyyyyyyIyyyyyyy",
      "      yyIyy     ",
      "      yyIyy     ",
      "      yyIyy     ",
      "      yyIyy     "
    ],
    [
      "      yJkJy     ",
      "      ygmgy     ",
      "      yJkJy     ",
      "yyyyyyyJkJyyyyyy",
      "yyyyyyyJkJJJJJJJ",
      "yyyyyyyJnfeeeeee",
      "JgJJJJJJJgJJJJJJ",
      "efeeeeeeefeeeeee",
      "JgJJJJJJJgJJJJJJ",
      "yyyyyyyJqfeeeeee",
      "yyyyyyyJkJJJJJJJ",
      "yyyyyyyJkJyyyyyy",
      "      yJkJy     ",
      "      yJkJy     ",
      "      ygmgy     ",
      "      yJkJy     "
    ],
    [
      "      y~~~y     ",
      "      y~~~y     ",
      "      y~~~y     ",
      "yyyyyyy~~~yyyyyy",
      "~~~~~~~~~~~~~~~~",
      "~~~~~~~~~~~~~~~~",
      "~~~~~~~~~~~~~~~~",
      "~~~~~~~~~~~~~~~~",
      "~~~~~~~~~~~~~~~~",
      "~~~~~~~~~~~~~~~~",
      "~~~~~~~~~~~~~~~~",
      "yyyyyyy~~~yyyyyy",
      "      y~~~y     ",
      "      y~~~y     ",
      "      y~~~y     ",
      "      y~~~y     "
    ],
    [
      "      y~~~y     ",
      "      y~~~y     ",
      "      y~~~y     ",
      "yyyyyyy~~~yyyyyy",
      "~~~~~~~~~~~~~~~~",
      "~~~~~~~~~~~~~~~~",
      "~~~~~~~~~~~~~~~~",
      "~~~~~~~~~~~~~~~~",
      "~~~~~~~~~~~~~~~~",
      "~~~~~~~~~~~~~~~~",
      "~~~~~~~~~~~~~~~~",
      "yyyyyyy~~~yyyyyy",
      "      y~~~y     ",
      "      y~~~y     ",
      "      y~~~y     ",
      "      y~~~y     "
    ],
    [
      "      y~~~y     ",
      "      y~~~y     ",
      "      y~~~y     ",
      "yyyyyyy~~~yyyyyy",
      "~~~~~~~~~~~~~~~~",
      "~~~~~~~~~~~~~~~~",
      "~~~~~~~~~~~~~~~~",
      "~~~~~~~~~~~~~~~~",
      "~~~~~~~~~~~~~~~~",
      "~~~~~~~~~~~~~~~~",
      "~~~~~~~~~~~~~~~~",
      "yyyyyyy~~~yyyyyy",
      "      y~~~y     ",
      "      y~~~y     ",
      "      y~~~y     ",
      "      y~~~y     "
    ],
    [
      "      yyyyy     ",
      "      yyyyy     ",
      "      yyyyy     ",
      "yyyyyyyyyyyyyyyy",
      "yyyyyyyyyyyyyyyy",
      "yyyyyyyyyyyyyyyy",
      "yyyyyyyyyyyyyyyy",
      "yyyyyyyyoyyyyyyy",
      "yyyyyyyyyyyyyyyy",
      "yyyyyyyyyyyyyyyy",
      "yyyyyyyyyyyyyyyy",
      "yyyyyyyyyyyyyyyy",
      "      yyyyy     ",
      "      yyyyy     ",
      "      yyyyy     ",
      "      yyyyy     "
    ]
  ]
}