{
  "xsize": 16,
  "zsize": 16,
  "refpalette": "lcmt:rails",
  "slices": [
    [
      "                ",
      "                ",
      "                ",
      "y               ",
      "y               ",
      "I               ",
      "y               ",
      "I               ",
      "y               ",
      "I               ",
      "y               ",
      "y               ",
      "                ",
      "                ",
      "                ",
      "                "
    ],
    [
      "                ",
      "                ",
      "                ",
      "yy              ",
      "Jy              ",
      "jI              ",
      "Jy              ",
      "jI              ",
      "Jy              ",
      "jI              ",
      "Jy              ",
      "yy              ",
      "                ",
      "                ",
      "                ",
      "                "
    ],
    [
      "                ",
      "                ",
      "                ",
      "yyy             ",
      "~Jy             ",
      "~jI             ",
      "~Jy             ",
      "~jI             ",
      "~Jy             ",
      "~jI             ",
      "~Jy             ",
      "yyy             ",
      "                ",
      "                ",
      "                ",
      "                "
    ],
    [
      "                ",
      "                ",
      "                ",
      "yyyy            ",
      "~~Jy            ",
      "~~jI            ",
      "~~Jy            ",
      "~~jI            ",
      "~~Jy            ",
      "~~jI            ",
      "~~Jy            ",
      "yyyy            ",
      "                ",
      "                ",
      "                ",
      "                "
    ],
    [
      "                ",
      "                ",
      "                ",
      "yyyyy           ",
      "~~~Jy           ",
      "~~~jI           ",
      "~~~Jy           ",
      "~~~jI           ",
      "~~~Jy           ",
      "~~~jI           ",
      "~~~Jy           ",
      "yyyyy           ",
      "                ",
      "                ",
      "                ",
      "                "
    ],
    [
      "                ",
      "                ",
      "                ",
      "yyyyyy          ",
      "~~~~Jy          ",
      "~~~~jI          ",
      "~~~~Jy y        ",
      "~~~~jI          ",
      "~~~~Jy y        ",
      "~~~~jI          ",
      "~~~~Jy          ",
      "yyyyyy          ",
      "                ",
      "                ",
      "                ",
      "                "
    ],
    [
      "                ",
      "                ",
      "                ",
      "yyyyyyy         ",
      "y~~~~Jyyyyyyyyyy",
      "y~~~~jIIIIIIIIII",
      "y~~~~Jygyyyyyyyy",
      "y~~~~jIIIIIIIIII",
      "y~~~~Jygyyyyyyyy",
      "y~~~~jIIIIIIIIII",
      "y~~~~Jyyyyyyyyyy",
      "yyyyyyy         ",
      "                ",
      "                ",
      "                ",
      "                "
    ],
    [
      "               y",
      "               y",
      "               y",
      " yyyyyy        y",
      " y~~~~JJJJJJJJJJ",
      " y~~~~efeeeeeeee",
      " y~~~~JJJJJJJJJJ",
      " y~~~~efeeeeeeee",
      " y~~~~JJJJJJJJJJ",
      " y~~~~efeeeeeeee",
      " y~~~~JJJJJJJJJJ",
      " yyyyyy        y",
      "               y",
      "               y",
      "               y",
      "               y"
    ],
    [
      "                ",
      "                ",
      "                ",
      " y::::y         ",
      " :~~~~~~~~~~~~~~",
      " :~~~~~~~~~~~~~~",
      " :~~~~~~~~~~~~~~",
      " :~~~~~~~~~~~~~~",
      " :~~~~~~~~~~~~~~",
      " :~~~~~~~~~~~~~~",
      " :~~~~~~~~~~~~~~",
      " y::::y         ",
      "                ",
      "                ",
      "                ",
      "                "
    ],
    [
      "                ",
      "                ",
      "                ",
      " y::::y         ",
      " :~~~~~~~~~~~~~~",
      " :~~~~~~~~~~~~~~",
      " :~~~~~~~~~~~~~~",
      " :~~~~~~~~~~~~~~",
      " :~~~~~~~~~~~~~~",
      " :~~~~~~~~~~~~~~",
      " :~~~~~~~~~~~~~~",
      " y::::y         ",
      "                ",
      "                ",
      "                ",
      "                "
    ],
    [
      "                ",
      "                ",
      "                ",
      " y~~~~y         ",
      " ~~~~~~~~~~~~~~~",
      " ~~~~~~~~~~~~~~~",
      " ~~~~~~~~~~~~~~~",
      " ~~~~~~~~~~~~~~~",
      " ~~~~~~~~~~~~~~~",
      " ~~~~~~~~~~~~~~~",
      " ~~~~~~~~~~~~~~~",
      " y~~~~y         ",
      "                ",
      "                ",
      "                ",
      "                "
    ],
    [
      "                ",
      "                ",
      "                ",
      " ______         ",
      " _~~~~_~~~~~~~~~",
      " _~~~~_~~~~~~~~~",
      " _~~~~_~~~~~~~~~",
      " _~~~~_~~~~~~~~~",
      " _~~~~_~~~~~~~~~",
      " _~~~~_~~~~~~~~~",
      " _~~~~_~~~~~~~~~",
      " ______         ",
      "                ",
      "                ",
      "                ",
      "                "
    ]
  ]
}