{
  "xsize": 16,
  "zsize": 16,
  "refpalette": "lostcities:rails",
  "slices": [
    [
      "                ",
      "                ",
      "                ",
      "yyyyyyyyyyyyyyyy",
      "yyyyyyyyyyyyyyyy",
      "IIIIIIIIIIIIIIII",
      "yyyyyyyyyyyyyyyy",
      "IIIIIIIIIIIIIIII",
      "yyyyyyyyyyyyyyyy",
      "IIIIIIIIIIIIIIII",
      "yyyyyyyyyyyyyyyy",
      "yyyyyyyyyyyyyyyy",
      "                ",
      "                ",
      "                ",
      "                "
    ],
    [
      "                ",
      "                ",
      "                ",
      "yyyyyyyyyyyyyyyy",
      "JJJJJJJJJJJJJJJJ",
      "eeeeeeefeeeeeeee",
      "JJJJJJJgJJJJJJJJ",
      "eeeeeeefeeeeeeee",
      "JJJJJJJgJJJJJJJJ",
      "eeeeeeefeeeeeeee",
      "JJJJJJJJJJJJJJJJ",
      "yyyyyyyyyyyyyyyy",
      "                ",
      "                ",
      "                ",
      "                "
    ],
    [
      "                ",
      "                ",
      "                ",
      "yyyyyyyyyyyyyyyy",
      "~~~~~~~~~~~~~~~~",
      "~~~~~~~~~~~~~~~~",
      "~~~~~~~~~~~~~~~~",
      "~~~~~~~~~~~~~~~~",
      "~~~~~~~~~~~~~~~~",
      "~~~~~~~~~~~~~~~~",
      "~~~~~~~~~~~~~~~~",
      "yyyyyyyyyyyyyyyy",
      "                ",
      "                ",
      "                ",
      "                "
    ],
    [
      "                ",
      "                ",
      "                ",
      "++++++++++++++++",
      "~~~~~~~~~~~~~~~~",
      "~~~~~~~~~~~~~~~~",
      "~~~~~~~~~~~~~~~~",
      "~~~~~~~~~~~~~~~~",
      "~~~~~~~~~~~~~~~~",
      "~~~~~~~~~~~~~~~~",
      "~~~~~~~~~~~~~~~~",
      "++++++++++++++++",
      "                ",
      "                ",
      "                ",
      "                "
    ],
    [
      "                ",
      "                ",
      "                ",
      "++++++++++++++++",
      "~~~~~~~~~~~~~~~~",
      "~~~~~~~~~~~~~~~~",
      "~~~~~~~~~~~~~~~~",
      "~~~~~~~~~~~~~~~~",
      "~~~~~~~~~~~~~~~~",
      "~~~~~~~~~~~~~~~~",
      "~~~~~~~~~~~~~~~~",
      "++++++++++++++++",
      "                ",
      "                ",
      "                ",
      "                "
    ],
    [
      "                ",
      "                ",
      "                ",
      "yyyyyyyyyyyyyyyy",
      "yyyyyyyyyyyyyyyy",
      "++++++++++++++++",
      "++++++++++++++++",
      "+++++++O++++++++",
      "++++++++++++++++",
      "++++++++++++++++",
      "yyyyyyyyyyyyyyyy",
      "yyyyyyyyyyyyyyyy",
      "                ",
      "                ",
      "                ",
      "                "
    ]
  ]
}