{
  "xsize": 16,
  "zsize": 16,
  "refpalette": "lostcities:rails",
  "slices": [
    [
      "                ",
      "                ",
      "                ",
      "                ",
      "                ",
      "                ",
      "                ",
      "                ",
      "                ",
      "                ",
      "yyyyyyyyyyy     ",
      "y~~~~~~~~~y     ",
      "y~~~~~~~~~y     ",
      "y~~=~~~~~~y     ",
      "y~~=~~~~~~y     ",
      "yyyyyyyyyyy     "
    ],
    [
      "                ",
      "                ",
      "                ",
      "                ",
      "                ",
      "                ",
      "                ",
      "                ",
      "                ",
      "                ",
      "yyyyyyyyyyy     ",
      "y~~~~~~~~~y     ",
      "y~~~~~~~~~y     ",
      "y~~~=~~~~~y     ",
      "y~~~=~~~~~y     ",
      "yyyyyyyyyyy     "
    ],
    [
      "                ",
      "                ",
      "                ",
      "                ",
      "                ",
      "                ",
      "                ",
      "                ",
      "                ",
      "                ",
      "yyyyyhyyyyy     ",
      "y~~~~~~~~~y     ",
      "y~~~~~~~~~y     ",
      "y~~~~=~~~~y     ",
      "y~~~~=~~~~y     ",
      "yyyyyyyyyyy     "
    ],
    [
      "                ",
      "                ",
      "                ",
      "                ",
      "                ",
      "                ",
      "                ",
      "                ",
      "                ",
      "                ",
      "yyyyyyyyyyy     ",
      "y~~~~~~~~~y     ",
      "y~~~~~~~~~y     ",
      "y~~~~~=~~~y     ",
      "y~~~~~=~~~y     ",
      "yyyyyyyyyyy     "
    ],
    [
      "                ",
      "                ",
      "                ",
      "                ",
      "                ",
      "                ",
      "                ",
      "                ",
      "                ",
      "                ",
      "yyyyyyyyyyy     ",
      "y~~~~~~~~~y     ",
      "y~~~~~~~~~y     ",
      "y~~~~~~=~~y     ",
      "y~~~~~~=~~y     ",
      "yyyyyyyyyyy     "
    ],
    [
      "                ",
      "                ",
      "                ",
      "                ",
      "                ",
      "                ",
      "                ",
      "                ",
      "                ",
      "                ",
      "yyyyyyyyyyy     ",
      "yQQQQQQQQQy     ",
      "yQQQQQQQQQy     ",
      "yQQQ~~~~=Qy     ",
      "yQQQ~~~~=Qy     ",
      "yyyyyyyyyyy     "
    ]
  ]
}