{
  "refpalette": "lcmt:rails",
  "xsize": 16,
  "zsize": 16,
  "slices": [
    [
      "yyyyyyyyyyyyyyyy",
      "yyyyyyyyyyyyyyyy",
      "yyyyyyyyyyyyyyyy",
      "yyyyyyyyyyyyyyyy",
      "yyyyyyyyyyyyyyyy",
      "IIIIIIIIIIIIIIII",
      "yyyyyyyyyyyyyyyy",
      "IIIIIIIIIIIIIIII",
      "yyyyyyyyyyyyyyyy",
      "IIIIIIIIIIIIIIII",
      "yyyyyyyyyyyyyyyy",
      "yyyyyyyyyyyyyyyy",
      "yyyyyyyyyyyyyyyy",
      "yyyyyyyyyyyyyyyy",
      "yyyyyyyyyyyyyyyy",
      "yyyyyyyyyyyyyyyy"
    ],
    [
      "yyyyyyyyyyyyyyyy",
      "QQQQQQQQQQQQQQQQ",
      "QQQMQQQoQQQMQQQQ",
      "QQQQQQQQQQQQQQQQ",
      "JJJJJJJJJJJJJJJJ",
      "eeeeeeefeeeeeeee",
      "JJJJJJJgJJJJJJJJ",
      "eeeeeeefeeeeeeee",
      "JJJJJJJgJJJJJJJJ",
      "eeeeeeefeeeeeeee",
      "JJJJJJJJJJJJJJJJ",
      "QQQQQQQQQQQQQQQQ",
      "QQQQQQQQQQQQQQQQ",
      "QQQMQQQoQQQMQQQQ",
      "QQQQQQQQQQQQQQQQ",
      "yyyyyyyyyyyyyyyy"
    ],
    [
      "                ",
      "   N       N    ",
      " ((*((   ((*((  ",
      "                ",
      "                ",
      "                ",
      "                ",
      "                ",
      "                ",
      "                ",
      "                ",
      "                ",
      "                ",
      " ))*))   ))*))  ",
      "   N       N    ",
      "                "
    ],
    [
      "                ",
      "   U       U    ",
      "                ",
      "                ",
      "                ",
      "                ",
      "                ",
      "                ",
      "                ",
      "                ",
      "                ",
      "                ",
      "                ",
      "                ",
      "   U       U    ",
      "                "
    ],
    [
      "                ",
      "   U       U    ",
      "                ",
      "                ",
      "                ",
      "                ",
      "                ",
      "                ",
      "                ",
      "                ",
      "                ",
      "                ",
      "                ",
      "                ",
      "   U       U    ",
      "                "
    ],
    [
      "))))))))))))))))",
      "   U       U    ",
      "                ",
      "                ",
      "                ",
      "                ",
      "                ",
      "                ",
      "                ",
      "                ",
      "                ",
      "                ",
      "                ",
      "                ",
      "   U       U    ",
      "(((((((((((((((("
    ],
    [
      "                ",
      "))))))))))))))))",
      "+++Q+++++++Q++++",
      "+++Q+++++++Q++++",
      "+++Q+++++++Q++++",
      "+++Q+++++++Q++++",
      "+++Q+++++++Q++++",
      "+++Q+++++++Q++++",
      "+++Q+++++++Q++++",
      "+++Q+++++++Q++++",
      "+++Q+++++++Q++++",
      "+++Q+++++++Q++++",
      "+++Q+++++++Q++++",
      "+++Q+++++++Q++++",
      "((((((((((((((((",
      "                "
    ]
  ]
}
