{
  "meta": [
    {
      "key": "dontconnect",
      "boolean": true
    }
  ],
  "xsize": 16,
  "zsize": 16,
  "slices": [
    [
      "################",
      "#SSQQSSQQSSQQSSQ",
      "#SSQQSSQQSSQQSSQ",
      "#QQSSQQSSQQSSQQS",
      "#QQSSQQSSQQSSQQS",
      "#SSQQSSQQSSQQSSQ",
      "#SSQQSSQQSSQQSSQ",
      "#QQSSQQSSQQSSQQS",
      "#QQSSQQSSQQSSQQS",
      "#SSQQSSQQSSQQSSQ",
      "#SSQQSSQQSSQQSSQ",
      "#QQSSQQSSQQSSQQS",
      "#QQSSQQSSQQSSQQS",
      "#SSQQSSQQSSQQSSQ",
      "#SSQQSSQQSSQQSSQ",
      "#QQSSQQSSQQSSQQS"
    ],
    [
      "iiiiiii      iii",
      "if ((           ",
      "i               ",
      "i               ",
      "i               ",
      "       #))))#   ",
      "                ",
      "                ",
      "                ",
      "                ",
      "       f    f   ",
      "i               ",
      "i               ",
      "i               ",
      "i               ",
      "i               "
    ],
    [
      "                ",
      " j              ",
      "                ",
      "                ",
      "                ",
      "       `    `   ",
      "       #))))#   ",
      "                ",
      "                ",
      "                ",
      "       j    j   ",
      "                ",
      "                ",
      "                ",
      "                ",
      "                "
    ],
    [
      "                ",
      " j              ",
      "                ",
      "                ",
      "                ",
      "                ",
      "       `    `   ",
      "       #))))#   ",
      "                ",
      "                ",
      "       j    j   ",
      "                ",
      "                ",
      "                ",
      "                ",
      "                "
    ],
    [
      "                ",
      " j              ",
      "                ",
      "                ",
      "                ",
      "                ",
      "                ",
      "       `    `   ",
      "       #))))#   ",
      "       E    E   ",
      "       j    j   ",
      "                ",
      "                ",
      "                ",
      "                ",
      "                "
    ],
    [
      "                ",
      " j              ",
      "                ",
      "                ",
      "                ",
      "                ",
      "                ",
      "                ",
      "       `    `   ",
      "       #))))#   ",
      "       j    j   ",
      "                ",
      "                ",
      "                ",
      "                ",
      "                "
    ]
  ]
}