{
  "xsize": 16,
  "zsize": 16,
  "slices": [
    [
      "QQQQQQQQQQQQQQQQ",
      "QSSQQSSQQSSQQSSQ",
      "QSSQQSSQQSSQQSSQ",
      "SQQSSQQSSQQSSQQQ",
      "SQQSSQQSSQQSSQQQ",
      "QSSQQSSQQSSQQSSQ",
      "QSSQQSSQQSSQQSSQ",
      "SQQSSQQSSQQSSQQQ",
      "SQQSSQQSSQQSSQQQ",
      "QSSQQSSQQSSQQSSQ",
      "QSSQQSSQQSSQQSSQ",
      "SQQSSQQSSQQSSQQQ",
      "SQQSSQQSSQQSSQQQ",
      "QSSQQSSQQSSQQSSQ",
      "QSSQQSSQQSSQQSSQ",
      "SQQSSQQSSQQSSQQQ"
    ],
    [
      "################",
      "`              #",
      "`              #",
      "`              #",
      "`              #",
      "`              #",
      "`              #",
      "`              #",
      "`              #",
      "`              #",
      "`              #",
      "`              #",
      "`              #",
      "`              #",
      "`              #",
      "`              #"
    ],
    [
      "################",
      "               #",
      "               #",
      "               #",
      "               #",
      "               #",
      "               #",
      "               #",
      "               #",
      "               #",
      "               #",
      "               #",
      "               #",
      "               #",
      "               #",
      "               #"
    ],
    [
      "##aa#aa#aa#aa###",
      "               #",
      "               #",
      "               a",
      "               a",
      "               #",
      "               a",
      "               a",
      "               #",
      "               a",
      "               a",
      "               #",
      "               a",
      "               a",
      "               #",
      "               a"
    ],
    [
      "################",
      "       E       #",
      "               #",
      "               #",
      "               #",
      "               #",
      "               #",
      "               #",
      "              E#",
      "               #",
      "               #",
      "               #",
      "               #",
      "               #",
      "               #",
      "               #"
    ],
    [
      "################",
      "################",
      "################",
      "################",
      "################",
      "################",
      "################",
      "################",
      "################",
      "################",
      "################",
      "################",
      "################",
      "################",
      "################",
      "################"
    ]
  ]
}