{
  "meta": [
    {
      "key": "dontconnect",
      "boolean": true
    }
  ],
  "xsize": 16,
  "zsize": 16,
  "slices": [
    [
      " f######))))####",
      " #SQQSSQQSSQQSSQ",
      " #SQQSSQQSSQQSSQ",
      " #QSSQQSSQQSSQQS",
      " #QSSQQSSQQSSQQS",
      " #SQQSSQQSSQQSSQ",
      " #SQQSSQQSSQQSSQ",
      " #QSSQQSSQQSSQQS",
      " #QSSQQSSQQSSQQS",
      " #SQQSSQQSSQQSSQ",
      " #SQQSSQQSSQQSSQ",
      " #QSSQQSSQQSSQQS",
      " #QSSQQSSQQSSQQS",
      " #SQQSSQQSSQQSSQ",
      " f##############",
      "                "
    ],
    [
      " j``````    ````",
      " `              ",
      " `              ",
      " `              ",
      " `              ",
      " `              ",
      " `              ",
      " `              ",
      " `              ",
      " `              ",
      " `              ",
      " `              ",
      " `              ",
      " `              ",
      " j``````````````",
      "                "
    ],
    [
      " j              ",
      "                ",
      "                ",
      "                ",
      "                ",
      "                ",
      "                ",
      "                ",
      "                ",
      "                ",
      "                ",
      "                ",
      "                ",
      "                ",
      " j              ",
      "                "
    ],
    [
      " j              ",
      "                ",
      "                ",
      "                ",
      "                ",
      "                ",
      "                ",
      "                ",
      "                ",
      "                ",
      "                ",
      "                ",
      "                ",
      "                ",
      " j              ",
      "                "
    ],
    [
      " j     E    E   ",
      "                ",
      "                ",
      "                ",
      "                ",
      "                ",
      "                ",
      "                ",
      "                ",
      "                ",
      "                ",
      "                ",
      "                ",
      "                ",
      " j              ",
      "                "
    ],
    [
      "################",
      "################",
      "################",
      "################",
      "################",
      "################",
      "################",
      "################",
      "################",
      "################",
      "################",
      "################",
      "################",
      "################",
      "################",
      "################"
    ]
  ]
}