{
  "xsize": 16,
  "zsize": 16,
  "slices": [
    [
      "#QQSSQQSSQQSSQQ#",
      "#SSQQSSQQSSQQSS#",
      "#SSQQSSQQSSQQSS#",
      "#QQSSQQSSQQSSQQ#",
      "#QQSSQQSSQQSSQQ#",
      "#SSQQSSQQSSQQSS#",
      "#SSQQSSQQSSQQSS#",
      "#QQSSQQSSQQSSQQ#",
      "#QQSSQQSSQQSSQQ#",
      "#SSQQSSQQSSQQSS#",
      "#SSQQSSQQSSQQSS#",
      "#QQSSQQSSQQSSQQ#",
      "#QQSSQQSSQQSSQQ#",
      "#SSQQSSQQSSQQSS#",
      "#SSQQSSQQSSQQSS#",
      "################"
    ],
    [
      "a              #",
      "a              #",
      "a             ##",
      "a             # ",
      "a             # ",
      "a             # ",
      "a             ##",
      "a              #",
      "a              #",
      "a             ##",
      "a             # ",
      "a             # ",
      "a             # ",
      "a             ##",
      "a #####  #######",
      "###   ####   ###"
    ],
    [
      "a              a",
      "a              a",
      "a             ##",
      "a             a ",
      "a             a ",
      "a             a ",
      "a             ##",
      "a              a",
      "a              a",
      "a             ##",
      "a             a ",
      "a             a ",
      "a             a ",
      "a             ##",
      "a #aaa#  #aaa###",
      "###   #aa#   ###"
    ],
    [
      "a              a",
      "a              a",
      "a             ##",
      "a             a ",
      "a             a ",
      "a             a ",
      "a            :##",
      "a              a",
      "a              a",
      "a            :##",
      "a             a ",
      "a             a ",
      "a             a ",
      "a     :  :    ##",
      "a #aaa#  #aaa###",
      "###   #aa#   ###"
    ],
    [
      "a              a",
      "a              a",
      "a             ##",
      "a             a ",
      "a             a ",
      "a             a ",
      "a            e##",
      "a              a",
      "a              a",
      "a            e##",
      "a             a ",
      "a             a ",
      "a             a ",
      "a     e  e    ##",
      "a #aaa#  #aaa###",
      "###   #aa#   ###"
    ],
    [
      "a              a",
      "a              a",
      "a             ##",
      "a             a ",
      "a             a ",
      "a             a ",
      "a             ##",
      "a              a",
      "a              a",
      "a             ##",
      "a             a ",
      "a             a ",
      "a             a ",
      "a             ##",
      "a #aaa#  #aaa###",
      "###   #aa#   ###"
    ]
  ]
}