{
  "meta": [
    {
      "key": "dontconnect",
      "boolean": true
    }
  ],
  "xsize": 16,
  "zsize": 16,
  "slices": [
    [
      "a   ####))))####",
      "a   #SSQQSSQQSSQ",
      "a   #SSQQSSQQSSQ",
      "a   #QQSSQQSSQQS",
      "a   #QQSSQQSSQQS",
      "a   #SSQQSSQQSSQ",
      "a   #SSQQSSQQSSQ",
      "a   #QQSSQQSSQQS",
      "a   #QQSSQQSSQQS",
      "a   #SSQQSSQQSSQ",
      "a   #SSQQSSQQSSQ",
      "a   ############",
      "a               ",
      "a               ",
      "a               ",
      "aaaaaaaaaaaaaaaa"
    ],
    [
      "a   ````    ````",
      "a   `           ",
      "a   `           ",
      "a   `           ",
      "a   `           ",
      "a   `           ",
      "a   `           ",
      "a   `           ",
      "a   `           ",
      "a   `           ",
      "a   `           ",
      "a   ````````````",
      "a               ",
      "a               ",
      "a               ",
      "aaaaaaaaaaaaaaaa"
    ],
    [
      "a               ",
      "a               ",
      "a               ",
      "a               ",
      "a               ",
      "a               ",
      "a               ",
      "a               ",
      "a               ",
      "a               ",
      "a               ",
      "a               ",
      "a               ",
      "a               ",
      "a               ",
      "aaaaaaaaaaaaaaaa"
    ],
    [
      "a               ",
      "a               ",
      "a               ",
      "a               ",
      "a               ",
      "a               ",
      "a               ",
      "a               ",
      "a               ",
      "a               ",
      "a               ",
      "a               ",
      "a               ",
      "a               ",
      "a               ",
      "aaaaaaaaaaaaaaaa"
    ],
    [
      "a      E    E   ",
      "a               ",
      "a               ",
      "a               ",
      "a               ",
      "a               ",
      "a               ",
      "a               ",
      "a               ",
      "a               ",
      "a               ",
      "a               ",
      "a               ",
      "a               ",
      "a               ",
      "aaaaaaaaaaaaaaaa"
    ],
    [
      "################",
      "################",
      "################",
      "################",
      "################",
      "################",
      "################",
      "################",
      "################",
      "################",
      "################",
      "################",
      "################",
      "################",
      "################",
      "################"
    ]
  ]
}