{
  "xsize": 16,
  "zsize": 16,
  "slices": [
    [
      "################",
      "QSSQQSSQQSSQQSS#",
      "QSSQQSSQQSSQQSS#",
      "SQQSSQQSSQQSSQQ#",
      "SQQSSQQSSQQSSQQ#",
      "QSSQQSSQQSSQQSS#",
      "QSSQQSSQQSSQQSS#",
      "SQQSSQQSSQQSSQQ#",
      "SQQSSQQSSQQSSQQ#",
      "QSSQQSSQQSSQQSS#",
      "QSSQQSSQQSSQQSS#",
      "SQQSSQQSSQQSSQQ#",
      "SQQSSQQSSQQSSQQ#",
      "QSSQQSSQQSSQQSS#",
      "QSSQQSSQQSSQQSS#",
      "SQQSSQQSSQQSSQQ#"
    ],
    [
      "###   ####   ###",
      "# #####  #######",
      "              ##",
      "              # ",
      "              # ",
      "              # ",
      "              ##",
      "               #",
      "               #",
      "              ##",
      "              # ",
      "              # ",
      "              # ",
      "              ##",
      "               #",
      "               #"
    ],
    [
      "###   #aa#   ###",
      "# #aaa#  #aaa###",
      "              ##",
      "              a ",
      "              a ",
      "              a ",
      "              ##",
      "               a",
      "               a",
      "              ##",
      "              a ",
      "              a ",
      "              a ",
      "              ##",
      "               a",
      "               a"
    ],
    [
      "###   #aa#   ###",
      "# #aaa#  #aaa###",
      "      :  :    ##",
      "              a ",
      "              a ",
      "              a ",
      "             :##",
      "               a",
      "               a",
      "             :##",
      "              a ",
      "              a ",
      "              a ",
      "              ##",
      "               a",
      "               a"
    ],
    [
      "###   #aa#   ###",
      "# #aaa#  #aaa###",
      "      e  e    ##",
      "              a ",
      "              a ",
      "              a ",
      "             e##",
      "               a",
      "               a",
      "             e##",
      "              a ",
      "              a ",
      "              a ",
      "              ##",
      "               a",
      "               a"
    ],
    [
      "###   #aa#   ###",
      "# #aaa#  #aaa###",
      "              ##",
      "              a ",
      "              a ",
      "              a ",
      "              ##",
      "               a",
      "               a",
      "              ##",
      "              a ",
      "              a ",
      "              a ",
      "              ##",
      "               a",
      "               a"
    ]
  ]
}