{
  "xsize": 16,
  "zsize": 16,
  "slices": [
    [
      "QQQQQQQQQQQQQQQQ",
      "QSSQQSSQQSSQQSSQ",
      "QSSQQSSQQSSQQSSQ",
      "QQQSSQQSSQQSSQQQ",
      "QQQSSQQSSQQSSQQQ",
      "QSSQQSSQQSSQQSSQ",
      "QSSQQSSQQSSQQSSQ",
      "QQQSSQQSSQQSSQQQ",
      "QQQSSQQSSQQSSQQQ",
      "QSSQQSSQQSSQQSSQ",
      "QSSQQSSQQSSQQSSQ",
      "QQQSSQQSSQQSSQQQ",
      "QQQSSQQSSQQSSQQQ",
      "QSSQQSSQQSSQQSSQ",
      "QSSQQSSQQSSQQSSQ",
      "QQQSSQQSSQQSSQQQ"
    ],
    [
      "################",
      "#              #",
      "a              #",
      "a              #",
      "a              #",
      "a              #",
      "a              #",
      "a              #",
      "a              #",
      "a              #",
      "a              #",
      "a              #",
      "a              #",
      "a              #",
      "a              #",
      "a              #"
    ],
    [
      "################",
      "#              #",
      "a              #",
      "a              #",
      "a              #",
      "a              #",
      "a              #",
      "a              #",
      "a              #",
      "a              #",
      "a              #",
      "a              #",
      "a              #",
      "a              #",
      "a              #",
      "a              #"
    ],
    [
      "##aa#aa#aa#aa###",
      "#              #",
      "a              #",
      "a              a",
      "a              a",
      "a              #",
      "a              a",
      "a              a",
      "a              #",
      "a              a",
      "a              a",
      "a              #",
      "a              a",
      "a              a",
      "a              #",
      "a              a"
    ],
    [
      "################",
      "#      E       #",
      "a              #",
      "a              #",
      "a              #",
      "a              #",
      "a              #",
      "a             E#",
      "a              #",
      "a              #",
      "a              #",
      "a              #",
      "a              #",
      "a              #",
      "a              #",
      "a              #"
    ],
    [
      "################",
      "################",
      "################",
      "################",
      "################",
      "################",
      "################",
      "################",
      "################",
      "################",
      "################",
      "################",
      "################",
      "################",
      "################",
      "################"
    ]
  ]
}