{
  "xsize": 16,
  "zsize": 16,
  "slices": [
    [
      "#QQSSQQSSQQSSQQS",
      "#SSQQSSQQSSQQSSQ",
      "#SSQQSSQQSSQQSSQ",
      "#QQSSQQSSQQSSQQS",
      "#QQSSQQSSQQSSQQS",
      "#SSQQSSQQSSQQSSQ",
      "#SSQQSSQQSSQQSSQ",
      "#QQSSQQSSQQSSQQS",
      "#QQSSQQSSQQSSQQS",
      "#SSQQSSQQSSQQSSQ",
      "#SSQQSSQQSSQQSSQ",
      "#QQSSQQSSQQSSQQS",
      "#QQSSQQSSQQSSQQS",
      "#SSQQSSQQSSQQSSQ",
      "#SSQQSSQQSSQQSSQ",
      "################"
    ],
    [
      "#               ",
      "#               ",
      "#               ",
      "#               ",
      "#               ",
      "#               ",
      "#               ",
      "#               ",
      "#               ",
      "#               ",
      "#               ",
      "#               ",
      "#               ",
      "#               ",
      "#               ",
      "################"
    ],
    [
      "#               ",
      "#               ",
      "#               ",
      "#               ",
      "#               ",
      "#               ",
      "#               ",
      "#               ",
      "#               ",
      "#               ",
      "#               ",
      "#               ",
      "#               ",
      "#               ",
      "#               ",
      "################"
    ],
    [
      "a               ",
      "#               ",
      "a               ",
      "a               ",
      "#               ",
      "a               ",
      "a               ",
      "#               ",
      "a               ",
      "a               ",
      "#               ",
      "a               ",
      "a               ",
      "#               ",
      "#               ",
      "###aa#aa#aa#aa#a"
    ],
    [
      "#               ",
      "#               ",
      "#               ",
      "#               ",
      "#               ",
      "#               ",
      "#               ",
      "#E              ",
      "#               ",
      "#               ",
      "#               ",
      "#               ",
      "#               ",
      "#               ",
      "#       E       ",
      "################"
    ],
    [
      "################",
      "################",
      "################",
      "################",
      "################",
      "################",
      "################",
      "################",
      "################",
      "################",
      "################",
      "################",
      "################",
      "################",
      "################",
      "################"
    ]
  ]
}