{
  "xsize": 16,
  "zsize": 16,
  "slices": [
    [
      "################",
      "QSSQQSSQQSSQQSS#",
      "QSSQQSSQQSSQQSS#",
      "SQQSSQQSSQQSSQQ#",
      "SQQSSQQSSQQSSQQ#",
      "QSSQQSSQQSSQQSS#",
      "QSSQQSSQQSSQQSS#",
      "SQQSSQQSSQQSSQQ#",
      "SQQSSQQSSQQSSQQ#",
      "QSSQQSSQQSSQQSS#",
      "QSSQQSSQQSSQQSS#",
      "SQQSSQQSSQQSSQQ#",
      "SQQSSQQSSQQSSQQ#",
      "QSSQQSSQQSSQQSS#",
      "QSSQQSSQQSSQQSS#",
      "SQQSSQQSSQQSSQQ#"
    ],
    [
      "################",
      "               #",
      "               #",
      "               #",
      "               #",
      "               #",
      "               #",
      "               #",
      "               #",
      "               #",
      "               #",
      "               #",
      "               #",
      "               #",
      "               #",
      "               #"
    ],
    [
      "################",
      "               #",
      "               #",
      "               #",
      "               #",
      "               #",
      "               #",
      "               #",
      "               #",
      "               #",
      "               #",
      "               #",
      "               #",
      "               #",
      "               #",
      "               #"
    ],
    [
      "a#aa#aa#aa#aa###",
      "               #",
      "               #",
      "               a",
      "               a",
      "               #",
      "               a",
      "               a",
      "               #",
      "               a",
      "               a",
      "               #",
      "               a",
      "               a",
      "               #",
      "               a"
    ],
    [
      "################",
      "       E       #",
      "               #",
      "               #",
      "               #",
      "               #",
      "               #",
      "               #",
      "              E#",
      "               #",
      "               #",
      "               #",
      "               #",
      "               #",
      "               #",
      "               #"
    ],
    [
      "################",
      "################",
      "################",
      "################",
      "################",
      "################",
      "################",
      "################",
      "################",
      "################",
      "################",
      "################",
      "################",
      "################",
      "################",
      "################"
    ]
  ]
}