{
  "xsize": 16,
  "zsize": 16,
  "slices": [
    [
      "SQQSSQQSSQQSSQQQ",
      "QSSQQSSQQSSQQSSQ",
      "QSSQQSSQQSSQQSSQ",
      "SQQSSQQSSQQSSQQQ",
      "SQQSSQQSSQQSSQQQ",
      "QSSQQSSQQSSQQSSQ",
      "QSSQQSSQQSSQQSSQ",
      "SQQSSQQSSQQSSQQQ",
      "SQQSSQQSSQQSSQQQ",
      "QSSQQSSQQSSQQSSQ",
      "QSSQQSSQQSSQQSSQ",
      "SQQSSQQSSQQSSQQQ",
      "SQQSSQQSSQQSSQQQ",
      "QSSQQSSQQSSQQSSQ",
      "QSSQQSSQQSSQQSSQ",
      "QQQQQQQQQQQQQQQQ"
    ],
    [
      "#              #",
      "               #",
      "               #",
      "               #",
      "               #",
      "               #",
      "       f  f    #",
      "       `))`    #",
      "       `  `    #",
      "       `  `    #",
      "       `  `    #",
      "#      `  `    #",
      "#      f  f    #",
      "#              #",
      "#              #",
      "################"
    ],
    [
      "#              #",
      "               #",
      "               #",
      "               #",
      "               #",
      "               #",
      "       j  j    #",
      "       `  `    #",
      "       `))`    #",
      "       `  `    #",
      "       `  `    #",
      "#      `  `    #",
      "#      j  j    #",
      "#              #",
      "#              #",
      "################"
    ],
    [
      "#              a",
      "               #",
      "               a",
      "               a",
      "               #",
      "               a",
      "       j  j    a",
      "       `  `    #",
      "       `  `    a",
      "       `))`    a",
      "       `  `    #",
      "#      `  `    a",
      "#      j  j    a",
      "#              #",
      "#              #",
      "##aa#aa#aa#aa###"
    ],
    [
      "#              #",
      "               #",
      "               #",
      "               #",
      "               #",
      "               #",
      "       j  j    #",
      "       `  `   E#",
      "       `  `    #",
      "       `  `    #",
      "       `))`    #",
      "#      `  `    #",
      "#      j  j    #",
      "#              #",
      "#              #",
      "################"
    ],
    [
      "################",
      "################",
      "################",
      "################",
      "################",
      "################",
      "################",
      "########  ######",
      "########  ######",
      "########  ######",
      "########  ######",
      "########))######",
      "################",
      "################",
      "################",
      "################"
    ]
  ]
}