{
  "xsize": 16,
  "zsize": 16,
  "refpalette": "pomkotsmechs:scattered",
  "slices": [
    [
      "*vvvvvvvv       ",
      "**vvvvvvv       ",
      "***vvvvvvv      ",
      "***vv&&&&&&&    ",
      "****v&vvvv&&    ",
      "****v&vvvv&&    ",
      "****v&vvvv&&    ",
      "****v&vvvv&&    ",
      "****v&vvvv&&    ",
      "****v&vvvv&&    ",
      "***vv&vvvv&&    ",
      "***vv&vvv &&    ",
      "**vvv&vvv &&    ",
      "*vvvv&vv  &&    ",
      "vvvvv&&&&&&&    ",
      "vvvvvvv         "
    ],
    [
      "&&&&&&          ",
      "&&&&&&#         ",
      "&&&&&&          ",
      "&&&&&&&&&&&&    ",
      "&&&&&&     &    ",
      "&&&&&&     &    ",
      "&&&&&&     &    ",
      "&&&&&&     &    ",
      "&&&&&&     &    ",
      "&&&&&&     &    ",
      "&&&&&&     &    ",
      "&&&&&&     &    ",
      "&&&&&&     &    ",
      "&&&&&&     &    ",
      "&&&&&&&&&&&&    ",
      "&&&&&&          "
    ],
    [
      "     &          ",
      " #'##&#         ",
      "#####&          ",
      "####&&&&&&&     ",
      " #' &&    &     ",
      "    &&    &     ",
      "    &&    &     ",
      "    &&    &     ",
      "  ' &&    &     ",
      "    &&    &     ",
      "    &&    &     ",
      "  ' &&    &     ",
      "    &&    &     ",
      "    &&    &     ",
      "    &&&&&&&     ",
      "  '  &          "
    ],
    [
      "(((  &          ",
      "((( #&#         ",
      " ####&          ",
      " ##&&&&&&&&     ",
      "(((& &    &     ",
      "(((& &    &     ",
      "(((& &    &     ",
      "(((& &    &     ",
      "(((& &    &     ",
      "   & &    &     ",
      "   & &    &     ",
      "(((& &    &     ",
      "(((& &    &     ",
      "(((& &    &     ",
      "(((&&&&&&&&     ",
      "(((  &          "
    ],
    [
      "))& #&          ",
      "&&(##&#         ",
      " ####&          ",
      " ##&&&&&&&      ",
      "&&(& &   &      ",
      "  && &   &      ",
      "  && &   &      ",
      "))&& &   &      ",
      "&&(& &   &      ",
      "   & &   &      ",
      "   & &   &      ",
      "&&(& &   &      ",
      "  && &   &      ",
      "  && &   &      ",
      "))&&&&&&&&      ",
      "&&(  &          "
    ],
    [
      "  & #&          ",
      "&&(##&#         ",
      " ####&          ",
      " #&&&&&&&&      ",
      "&&(  &   &      ",
      "  &  &   &      ",
      "  &  &   &      ",
      "  &  &   &      ",
      "&&(  &   &      ",
      "  &  &   &      ",
      "  &  &   &      ",
      "&&(  &   &      ",
      "  &  &   &      ",
      "  &  &   &      ",
      "  &&&&&&&&      ",
      "&&(  &          "
    ],
    [
      "((&# &          ",
      "&&(##&#         ",
      "  ####          ",
      " #&&#& &&&      ",
      "&&(# &   &      ",
      "((&  &   &      ",
      "((&  &   &      ",
      "((&  &  #&#     ",
      "&&(  &  #&      ",
      "  &  &   &      ",
      "  &  &   &      ",
      "&&(  &   &      ",
      "((&  &   &      ",
      "((&  &   &      ",
      "((&&&&&&&&      ",
      "&&(  &          "
    ],
    [
      "(((# &          ",
      "(((###          ",
      "  ###           ",
      "  &&#   &       ",
      "(((#    &       ",
      "(((  &  &       ",
      "(((  &  &#      ",
      "(((  & #&##     ",
      "(((  & #&#      ",
      "  &  &  &       ",
      "  &  &  &       ",
      "(((  &  &       ",
      "(((  &  &       ",
      "(((  &  &       ",
      "(((&&&&&&       ",
      "(((  &          "
    ],
    [
      "   ##&          ",
      "  '###          ",
      "  ###           ",
      " &&&            ",
      " &'             ",
      " &      &       ",
      " &   &  &       ",
      " &   &  &#      ",
      " &'  & #&#      ",
      " &   & #&#      ",
      " &   &  &       ",
      " &'  &  &       ",
      " &   &  &       ",
      " &   &  &       ",
      " &&&&&&&&       ",
      "  '  &          "
    ],
    [
      "((( #&          ",
      "(((###          ",
      "  ####          ",
      " &&##           ",
      "(((             ",
      "(((             ",
      "(((  & &        ",
      "(((  & &        ",
      "(((  & &#       ",
      " &   &#&##      ",
      " &   & &#       ",
      "(((  & &        ",
      "(((  & &        ",
      "(((  & &        ",
      "(((&&&&&        ",
      "(((  &          "
    ],
    [
      "))& #&          ",
      "&&(###          ",
      "   ###          ",
      "&&& #           ",
      "&&(             ",
      "& &             ",
      "& &             ",
      "))&  & &        ",
      "&&(  & &        ",
      "&    &#&#       ",
      "&    &#&#       ",
      "&&(  &#&#       ",
      "& &  &#&        ",
      "& &  & &        ",
      "))&&&&&&        ",
      "&&(  &          "
    ],
    [
      "  & #&          ",
      "&&(####         ",
      "   ###          ",
      "&&&&#           ",
      "&&(             ",
      "& &  &          ",
      "& &  &          ",
      "& &  &&         ",
      "&&(  &&         ",
      "&    &&#        ",
      "&    &&#        ",
      "&&(  &&##       ",
      "& &  &&#        ",
      "& &  &&         ",
      "&&&&&&&         ",
      "&&(  &          "
    ],
    [
      "((&  &          ",
      "&&( #&#         ",
      "   ####         ",
      "&&&&&&          ",
      "&&(  &          ",
      "((&  &&         ",
      "((&  &&         ",
      "((&  &&         ",
      "&&(  &&         ",
      "     &&         ",
      "     &&         ",
      "&&(  &&#        ",
      "((&  &&#        ",
      "((&  &&         ",
      "((&&&&&         ",
      "&&(  &          "
    ],
    [
      "(((  &          ",
      "(((  &          ",
      "    #&#         ",
      "&&&&&&&         ",
      "(((  &&         ",
      "(((  &&         ",
      "(((  &&         ",
      "(((  &&         ",
      "(((  &&         ",
      "     &&         ",
      "     &&         ",
      "(((  &&         ",
      "(((  &&#        ",
      "(((  &&#        ",
      "(((&&&&         ",
      "(((  &          "
    ],
    [
      "     &          ",
      "     &          ",
      "    #&#         ",
      "&&&&&&          ",
      "     &          ",
      "     &          ",
      "     &          ",
      "     &          ",
      "     &          ",
      "     &          ",
      "     &          ",
      "     &          ",
      "     &#         ",
      "    #&##        ",
      "&&&&&&#         ",
      "   ##&          "
    ],
    [
      "&&&&&&          ",
      "&&&&&&          ",
      "&&&&&&#         ",
      "&&&&&&          ",
      "&&&&&&          ",
      "&&&&&&          ",
      "&&&&&&          ",
      "&&&&&&          ",
      "&&&&&&          ",
      "&&&&&&          ",
      "&&&&&&          ",
      "&&&&&&          ",
      "&&&&&&          ",
      "&&&&&&#         ",
      "&&&&&&#         ",
      "   &&&#         "
    ],
    [
      "                ",
      "#               ",
      "##  ##          ",
      "&&&&&#          ",
      "#   &           ",
      "   #&#          ",
      "    &           ",
      "    &           ",
      "    &           ",
      "    &           ",
      "    &           ",
      "    &           ",
      "    &           ",
      "    &#          ",
      "  &&&#          ",
      "    ##          "
    ],
    [
      "                ",
      "                ",
      "##  ##          ",
      "&&&&&##         ",
      "&# #&#          ",
      "&  #&#          ",
      "&   &           ",
      "&   &           ",
      "&   &           ",
      "&   &           ",
      "&   &           ",
      "&   &           ",
      "&   &           ",
      "&   &           ",
      "&&&&&           ",
      "                "
    ],
    [
      "                ",
      "                ",
      " #####          ",
      "#&&&&##         ",
      " &&#&#          ",
      " && &           ",
      " && &           ",
      " && &           ",
      " && &           ",
      " && &           ",
      " && &           ",
      " && &           ",
      " && &           ",
      " && &           ",
      " &&&&           ",
      "                "
    ],
    [
      "                ",
      "                ",
      "  ##            ",
      " ##&##          ",
      "  #&#           ",
      "   &            ",
      "   &            ",
      "   &            ",
      "   &            ",
      "   &            ",
      "   &            ",
      "   &            ",
      "   &            ",
      "   &            ",
      "   &            ",
      "                "
    ],
    [
      "                ",
      "                ",
      "                ",
      "  ##            ",
      "                ",
      "                ",
      "                ",
      "                ",
      "                ",
      "                ",
      "                ",
      "                ",
      "                ",
      "                ",
      "                ",
      "                "
    ],
    [
      "                ",
      "                ",
      "                ",
      "                ",
      "                ",
      "                ",
      "                ",
      "                ",
      "                ",
      "                ",
      "                ",
      "                ",
      "                ",
      "                ",
      "                ",
      "                "
    ],
    [
      "                ",
      "                ",
      "                ",
      "                ",
      "                ",
      "                ",
      "                ",
      "                ",
      "                ",
      "                ",
      "                ",
      "                ",
      "                ",
      "                ",
      "                ",
      "                "
    ],
    [
      "                ",
      "                ",
      "                ",
      "                ",
      "                ",
      "                ",
      "                ",
      "                ",
      "                ",
      "                ",
      "                ",
      "                ",
      "                ",
      "                ",
      "                ",
      "                "
    ]
  ]
}