{
  "xsize": 16,
  "zsize": 16,
  "refpalette": "pomkotsmechs:scattered",
  "slices": [
    [
      "  &&&&&&&&&&&&&&",
      "&&&&&&&&&&&&&&&&",
      "&&&&&&&&&&&&&&&&",
      "&&&&&&&&&&&&&&&&",
      "&&&&&&&&&&&&&&&&",
      "&&&&&&&&&&&&&&&&",
      "&&&&&&&&&&&&&&&&",
      "&&&&&&&&&&&&&&&&",
      "&&&&&&&&&&&&&&&&",
      "&&&&&&&&&&&&&&&&",
      "&&&&&&&&&&&&&&&&",
      "&&&&&&&&&&&&&&&&",
      "&&&&&&&&&&&&&&&&",
      "&&&&&&&&&&&&&&&&",
      "&&&&&&&&&&&&&&&&",
      "&&&&&&&&&&&&&&&&"
    ],
    [
      "      $$$$$$$$$$",
      "  &&&&&&&&&&&&&&",
      "     m          ",
      "                ",
      "                ",
      " j              ",
      "&&&&&&&&&&&&&&&&",
      "$$$$$$$$$$$$$$$$",
      "$$$$$$$$$$$$$$$$",
      "$$$$$ccccc$$$$$$",
      "$$$cc$$$$$cc$$$$",
      "$$c$$$$$$$$$c$$$",
      "$c$$$$$$$$$$$c$$",
      "$c$$$$$$$$$$$c$$",
      "c$$$$$$$$$$$$$c$",
      "c$$$$$$$$$$$$$c$"
    ],
    [
      "                ",
      "   eeeeeeeeeeeee",
      "     n          ",
      "                ",
      "                ",
      "                ",
      "eeeeeeeeeeeeeeee",
      "j               ",
      "         $  $  $",
      "     j          ",
      "                ",
      "         $  $  $",
      "                ",
      "      j         ",
      "         $  $  $",
      "                "
    ],
    [
      "                ",
      "          j     ",
      "                ",
      "                ",
      "                ",
      "                ",
      "                ",
      "                ",
      "         $  $  $",
      "                ",
      "                ",
      "         $  $  $",
      "                ",
      "                ",
      "         $  $  $",
      "                "
    ],
    [
      "                ",
      "                ",
      "                ",
      "                ",
      "                ",
      "                ",
      "                ",
      "                ",
      "         $  $  $",
      "                ",
      "                ",
      "         $  $  $",
      "                ",
      "                ",
      "         $  $  $",
      "                "
    ],
    [
      "                ",
      "                ",
      "                ",
      "                ",
      "                ",
      "                ",
      "                ",
      "                ",
      "         )))))))",
      "         )$$$$$)",
      "         )$$$$$)",
      "         )$$$$$)",
      "         )$$$$$)",
      "         )$$$$$)",
      "          $$$$$ ",
      "         )$$$$$)"
    ],
    [
      "                ",
      "                ",
      "                ",
      "                ",
      "                ",
      "                ",
      "                ",
      "                ",
      "         )))))))",
      "         )$$$$$)",
      "          $   $)",
      "              $)",
      "              $)",
      "              $)",
      "          $  g$ ",
      "         )$   $)"
    ],
    [
      "                ",
      "                ",
      "                ",
      "                ",
      "                ",
      "                ",
      "                ",
      "                ",
      "         )))))))",
      "          $$$$$)",
      "              $)",
      "              $)",
      "              $)",
      "              $)",
      "              $ ",
      "              $)"
    ],
    [
      "                ",
      "                ",
      "                ",
      "                ",
      "                ",
      "                ",
      "                ",
      "                ",
      "         )))))))",
      "           $$$$)",
      "              $)",
      "              $)",
      "              $)",
      "              $)",
      "              $ ",
      "              $)"
    ],
    [
      "                ",
      "                ",
      "                ",
      "                ",
      "                ",
      "                ",
      "                ",
      "                ",
      "         )))))))",
      "           $$$$)",
      "            $$$)",
      "            $$$)",
      "            $$$)",
      "            $$$)",
      "            $$$ ",
      "           $$$$)"
    ],
    [
      "                ",
      "                ",
      "                ",
      "                ",
      "                ",
      "                ",
      "                ",
      "                ",
      "         )))))))",
      "           )))))",
      "            ))))",
      "            ))))",
      "            ))))",
      "            ))))",
      "               a",
      "           )))))"
    ],
    [
      "                ",
      "                ",
      "                ",
      "                ",
      "                ",
      "                ",
      "                ",
      "                ",
      "                ",
      "                ",
      "                ",
      "                ",
      "                ",
      "                ",
      "                ",
      "               a"
    ],
    [
      "                ",
      "                ",
      "                ",
      "                ",
      "                ",
      "                ",
      "                ",
      "                ",
      "                ",
      "                ",
      "                ",
      "                ",
      "                ",
      "                ",
      "                ",
      "                "
    ],
    [
      "                ",
      "                ",
      "                ",
      "                ",
      "                ",
      "                ",
      "                ",
      "                ",
      "                ",
      "                ",
      "                ",
      "                ",
      "                ",
      "                ",
      "                ",
      "                "
    ],
    [
      "                ",
      "                ",
      "                ",
      "                ",
      "                ",
      "                ",
      "                ",
      "                ",
      "                ",
      "                ",
      "                ",
      "                ",
      "                ",
      "                ",
      "                ",
      "                "
    ],
    [
      "&&&&&&&&&&&&&&&&",
      "&&&&&&&&&&&&&&&&",
      "kkkkkkkkkkkkkkkk",
      "                ",
      "                ",
      "hhhhhhhhhhhhhhhh",
      "&&&&&&&&&&&&&&&&",
      "&&&&&&&&&&&&&&&&",
      "                ",
      "                ",
      "                ",
      "                ",
      "                ",
      "                ",
      "                ",
      "                "
    ],
    [
      "                ",
      "                ",
      "eeeeeeeeeeeeeeee",
      "                ",
      "                ",
      "eeeeeeeeeeeeeeee",
      "                ",
      "                ",
      "                ",
      "                ",
      "                ",
      "                ",
      "                ",
      "                ",
      "                ",
      "                "
    ],
    [
      "                ",
      "                ",
      "                ",
      "                ",
      "                ",
      "                ",
      "                ",
      "                ",
      "                ",
      "                ",
      "                ",
      "                ",
      "                ",
      "                ",
      "                ",
      "                "
    ],
    [
      "                ",
      "                ",
      "                ",
      "                ",
      "                ",
      "                ",
      "                ",
      "                ",
      "                ",
      "                ",
      "                ",
      "                ",
      "                ",
      "                ",
      "                ",
      "                "
    ],
    [
      "                ",
      "                ",
      "                ",
      "                ",
      "                ",
      "                ",
      "                ",
      "                ",
      "                ",
      "                ",
      "                ",
      "                ",
      "                ",
      "                ",
      "                ",
      "                "
    ],
    [
      "                ",
      "                ",
      "                ",
      "                ",
      "                ",
      "                ",
      "                ",
      "                ",
      "                ",
      "                ",
      "                ",
      "                ",
      "                ",
      "                ",
      "                ",
      "                "
    ],
    [
      "                ",
      "                ",
      "                ",
      "                ",
      "                ",
      "                ",
      "                ",
      "                ",
      "                ",
      "                ",
      "                ",
      "                ",
      "                ",
      "                ",
      "                ",
      "                "
    ],
    [
      "                ",
      "                ",
      "                ",
      "                ",
      "                ",
      "                ",
      "                ",
      "                ",
      "                ",
      "                ",
      "                ",
      "                ",
      "                ",
      "                ",
      "                ",
      "                "
    ],
    [
      "                ",
      "                ",
      "                ",
      "                ",
      "                ",
      "                ",
      "                ",
      "                ",
      "                ",
      "                ",
      "                ",
      "                ",
      "                ",
      "                ",
      "                ",
      "                "
    ],
    [
      "                ",
      "                ",
      "                ",
      "                ",
      "                ",
      "                ",
      "                ",
      "                ",
      "                ",
      "                ",
      "                ",
      "                ",
      "                ",
      "                ",
      "                ",
      "                "
    ],
    [
      "                ",
      "                ",
      "                ",
      "                ",
      "                ",
      "                ",
      "                ",
      "                ",
      "                ",
      "                ",
      "                ",
      "                ",
      "                ",
      "                ",
      "                ",
      "                "
    ],
    [
      "                ",
      "                ",
      "                ",
      "                ",
      "                ",
      "                ",
      "                ",
      "                ",
      "                ",
      "                ",
      "                ",
      "                ",
      "                ",
      "                ",
      "                ",
      "                "
    ],
    [
      "                ",
      "                ",
      "                ",
      "                ",
      "                ",
      "                ",
      "                ",
      "                ",
      "                ",
      "                ",
      "                ",
      "                ",
      "                ",
      "                ",
      "                ",
      "                "
    ],
    [
      "                ",
      "                ",
      "                ",
      "                ",
      "                ",
      "                ",
      "                ",
      "                ",
      "                ",
      "                ",
      "                ",
      "                ",
      "                ",
      "                ",
      "                ",
      "                "
    ],
    [
      "                ",
      "                ",
      "                ",
      "                ",
      "                ",
      "                ",
      "                ",
      "                ",
      "                ",
      "                ",
      "                ",
      "                ",
      "                ",
      "                ",
      "                ",
      "                "
    ],
    [
      "&&&&&&&         ",
      "&&&&&&&&        ",
      "                ",
      "                ",
      "                ",
      "                ",
      "&&&&&&&&&&&&&&&&",
      "&&&&&&&&&&&&&&&&",
      "                ",
      "                ",
      "                ",
      "                ",
      "                ",
      "                ",
      "                ",
      "                "
    ],
    [
      "$$$$$$$$$       ",
      "$$$$$$$$$$$     ",
      "$$$$$$$$$$$$$$$$",
      "$$$$$$$$$$$$$$$$",
      "$$$$$$$$$$$$$$$$",
      "$$$$$$$$$$$$$$$$",
      "$$$$$$$$$$$$$$$$",
      "$$$$$$$$$$$$$$$$",
      "$$$$$$$$$$$$$$$$",
      "                ",
      "                ",
      "                ",
      "                ",
      "                ",
      "                ",
      "                "
    ],
    [
      "llllllllllll    ",
      "llllllllllllllll",
      "llllllllllllllll",
      "llllllllllllllll",
      "llllllllllllllll",
      "llllllllllllllll",
      "llllllllllllllll",
      "llllllllllllllll",
      "llllllllllllllll",
      "llllllllllllllll",
      "llllllllllllllll",
      "llllllllllllllll",
      "llllllllllllllll",
      "llllllllllllllll",
      "llllllllllllllll",
      "llllllllllllllll"
    ],
    [
      "                ",
      "    j           ",
      "                ",
      "                ",
      "                ",
      " m              ",
      "                ",
      "j               ",
      "      j         ",
      "          m     ",
      "    j  j        ",
      "                ",
      "          j     ",
      "      j         ",
      "                ",
      "        j       "
    ],
    [
      "                ",
      "                ",
      "                ",
      "                ",
      "                ",
      " n              ",
      "                ",
      "                ",
      "                ",
      "          n     ",
      "                ",
      "                ",
      "                ",
      "                ",
      "                ",
      "                "
    ],
    [
      "                ",
      "                ",
      "                ",
      "                ",
      "                ",
      "                ",
      "                ",
      "                ",
      "                ",
      "                ",
      "                ",
      "                ",
      "                ",
      "                ",
      "                ",
      "                "
    ]
  ]
}