{
  "xsize": 16,
  "zsize": 16,
  "refpalette": "pomkotsmechs:scattered",
  "slices": [
    [
      "                ",
      "                ",
      "                ",
      "                ",
      "                ",
      "                ",
      "                ",
      "            $ $ ",
      "             $  ",
      "            $ $ ",
      "                ",
      "                ",
      "                ",
      "                ",
      "                ",
      "                "
    ],
    [
      "00022200&&&&0022",
      "0022220&&vv&&022",
      "vvvv 20&vvv&0000",
      "vvvvv20&v &0220&",
      "vvvvv20&&&02220&",
      "vvvvv20&&02330&v",
      "vvvvv20&&02320&v",
      "22222220002320&v",
      "3222232200222&&v",
      "220223322222v&&&",
      "00&0022222220&&&",
      "&&&&&00023220&&&",
      " &&&&&&02222&&vv",
      "000000002220&&vv",
      "222222002220&&&v",
      "22222222220000&&"
    ],
    [
      "                ",
      "                ",
      "                ",
      "#               ",
      ".               ",
      ".               ",
      "                ",
      "                ",
      "           !!   ",
      "           !!   ",
      "                ",
      "                ",
      "                ",
      "                ",
      "                ",
      "                "
    ],
    [
      "                ",
      "                ",
      "                ",
      "#               ",
      "A               ",
      "A               ",
      "                ",
      "                ",
      "           !!   ",
      "           !!   ",
      "                ",
      "                ",
      "                ",
      "                ",
      "                ",
      "                "
    ],
    [
      "                ",
      "                ",
      "                ",
      "                ",
      "X               ",
      "X               ",
      "                ",
      "                ",
      "           !!   ",
      "           !!   ",
      "                ",
      "                ",
      "                ",
      "                ",
      "                ",
      "                "
    ],
    [
      "                ",
      "                ",
      "                ",
      "#               ",
      ".               ",
      ".               ",
      "                ",
      "                ",
      "           !!   ",
      "           !!   ",
      "                ",
      "                ",
      "                ",
      "                ",
      "                ",
      "                "
    ],
    [
      "                ",
      "                ",
      "                ",
      "                ",
      "                ",
      "                ",
      "                ",
      "                ",
      "           !!   ",
      "           !!   ",
      "                ",
      "                ",
      "                ",
      "                ",
      "                ",
      "                "
    ],
    [
      "                ",
      "                ",
      "                ",
      "                ",
      "                ",
      "                ",
      "                ",
      "                ",
      "           !!   ",
      "           !!   ",
      "                ",
      "                ",
      "                ",
      "                ",
      "                ",
      "                "
    ],
    [
      "                ",
      "                ",
      "                ",
      "                ",
      "                ",
      "                ",
      "                ",
      "                ",
      "           !!   ",
      "           !    ",
      "                ",
      "                ",
      "                ",
      "                ",
      "                ",
      "                "
    ],
    [
      "^^^^^^^^^^^^^^^ ",
      "^^^^^^^^^    ^^ ",
      "^^^^^^^^^    ^^ ",
      "^^^^^^^^^^  ^^^ ",
      "^^^^^^^^^^^^^^^ ",
      "^^^^^^^^^^^^^^^ ",
      "^^^^^^^^^^^^^^^ ",
      "^^^^^^^^^^^^^ ^ ",
      "^^^^^^^^^^^^    ",
      "^^^^^^^^^^^^    ",
      "^^^^^^^^^^^^^   ",
      "^^^^^^^^^^^^^^^ ",
      "                ",
      "                ",
      "                ",
      "                "
    ],
    [
      "!!!!!!!  #   !  ",
      "!!!!!!!         ",
      "!!!!!!!         ",
      "!!!!!!!!        ",
      "!!!!!!!!!!   !  ",
      "!!!!!!!!!!!!!!  ",
      "!!!!!!!!!!!!!!  ",
      "!!!!!!!!!!!!    ",
      "!!!!!!!!!!      ",
      "!!!!!!!!!!      ",
      "!!!!!!!!!!!!    ",
      "                ",
      "                ",
      "                ",
      "                ",
      "                "
    ],
    [
      "                ",
      "                ",
      "                ",
      "                ",
      "                ",
      "                ",
      "                ",
      "                ",
      "                ",
      "                ",
      "                ",
      "                ",
      "                ",
      "                ",
      "                ",
      "                "
    ],
    [
      "                ",
      "                ",
      "                ",
      "                ",
      "                ",
      "                ",
      "                ",
      "                ",
      "                ",
      "                ",
      "                ",
      "                ",
      "                ",
      "                ",
      "                ",
      "                "
    ],
    [
      "                ",
      "                ",
      "                ",
      "                ",
      "                ",
      "                ",
      "                ",
      "                ",
      "                ",
      "                ",
      "                ",
      "                ",
      "                ",
      "                ",
      "                ",
      "                "
    ],
    [
      "                ",
      "                ",
      "                ",
      "                ",
      "                ",
      "                ",
      "                ",
      "                ",
      "                ",
      "                ",
      "                ",
      "                ",
      "                ",
      "                ",
      "                ",
      "                "
    ],
    [
      "                ",
      "                ",
      "                ",
      "                ",
      "                ",
      "                ",
      "                ",
      "                ",
      "                ",
      "                ",
      "                ",
      "                ",
      "                ",
      "                ",
      "                ",
      "                "
    ],
    [
      "                ",
      "                ",
      "                ",
      "                ",
      "                ",
      "                ",
      "                ",
      "                ",
      "                ",
      "                ",
      "                ",
      "                ",
      "                ",
      "                ",
      "                ",
      "                "
    ],
    [
      "                ",
      "                ",
      "                ",
      "                ",
      "                ",
      "                ",
      "                ",
      "                ",
      "                ",
      "                ",
      "                ",
      "                ",
      "                ",
      "                ",
      "                ",
      "                "
    ]
  ]
}