{
  "xsize": 16,
  "zsize": 16,
  "refpalette": "pomkotsmechs:scattered",
  "slices": [
    [
      "***********vvv**",
      "************vv**",
      "*************v**",
      "*************v**",
      "****************",
      "****************",
      "****************",
      "****************",
      "****************",
      "****************",
      "*************v**",
      "*************v**",
      "************vv**",
      "***********vvv**",
      "**********vvvv**",
      "vv******vvvvvvvv"
    ],
    [
      "&&&&&&&&&&&&&&&&",
      "&&&&&&&&&&&&&&&&",
      "&&&&&&&&&&&&&&&&",
      "&&&&&&&&&&&&&&&&",
      "&&&&&&&&&&&&&&&&",
      "&&&&&&&&&&&&&&&&",
      "&&&&&&&&&&&&&&&&",
      "&&&&&&&&&&&&&&&&",
      "&&&&&&&&&&&&&&&&",
      "&&&&&&&&&&&&&&&&",
      "&&&&&&&&&&&&&&&&",
      "&&&&&&&&&&&&&&&&",
      "&&&&&&&&&&&&&&&&",
      "&&&&&&&&&&&&&&&&",
      "&&&&&&&&&&&&&&&&",
      "&&&&&&&&&&&&&&&&"
    ],
    [
      "                ",
      " '            ' ",
      "                ",
      "                ",
      " '            ' ",
      "                ",
      "                ",
      "                ",
      " '            ' ",
      "                ",
      "                ",
      " '            ' ",
      "                ",
      "                ",
      "                ",
      " '            ' "
    ],
    [
      "((            ((",
      "((            ((",
      "                ",
      "                ",
      "((            ((",
      "((            ((",
      "((            ((",
      "((            ((",
      "((            ((",
      "                ",
      "                ",
      "((            ((",
      "((            ((",
      "((            ((",
      "((            ((",
      "((            (("
    ],
    [
      " &            & ",
      "&(            (&",
      "                ",
      "                ",
      "&(            (&",
      " &            & ",
      " &            & ",
      " &            & ",
      "&(            (&",
      "                ",
      "                ",
      "&(            (&",
      " &            & ",
      " &            & ",
      " &            & ",
      "&(            (&"
    ],
    [
      " &            & ",
      "&(            (&",
      "                ",
      "                ",
      "&(            (&",
      " &            & ",
      " &            & ",
      " &            & ",
      "&(            (&",
      "                ",
      "                ",
      "&(            (&",
      " &            & ",
      " &            & ",
      " &            & ",
      "&(            (&"
    ],
    [
      "(&            &(",
      "&(            (&",
      "                ",
      "                ",
      "&(            (&",
      "(&            &(",
      "(&            &(",
      "(&            &(",
      "&(            (&",
      "                ",
      "                ",
      "&(            (&",
      "(&            &(",
      "(&            &(",
      "(&            &(",
      "&(            (&"
    ],
    [
      "((            ((",
      "((            ((",
      "                ",
      "                ",
      "((            ((",
      "((            ((",
      "((            ((",
      "((            ((",
      "((            ((",
      "                ",
      "                ",
      "((            ((",
      "((            ((",
      "((            ((",
      "((            ((",
      "((            (("
    ],
    [
      "                ",
      " '            ' ",
      "                ",
      "                ",
      " '            ' ",
      "                ",
      "                ",
      "                ",
      " '            ' ",
      "                ",
      "                ",
      " '            ' ",
      "                ",
      "                ",
      "                ",
      " '            ' "
    ],
    [
      "((            ((",
      "((            ((",
      "                ",
      "                ",
      "((            ((",
      "((            ((",
      "((            ((",
      "((            ((",
      "((            ((",
      "                ",
      "                ",
      "((            ((",
      "((            ((",
      "((            ((",
      "((            ((",
      "((            (("
    ],
    [
      " &            & ",
      "&(            (&",
      "                ",
      "                ",
      "&(            (&",
      " &            & ",
      " &            & ",
      " &            & ",
      "&(            (&",
      "                ",
      "                ",
      "&(            (&",
      " &            & ",
      " &            & ",
      " &            & ",
      "&(            (&"
    ],
    [
      " &            & ",
      "&(            (&",
      "                ",
      "                ",
      "&(            (&",
      " &            & ",
      " &            & ",
      " &            & ",
      "&(            (&",
      "                ",
      "                ",
      "&(            (&",
      " &            & ",
      " &            & ",
      " &            & ",
      "&(            (&"
    ],
    [
      "(&            &(",
      "&(            (&",
      "                ",
      "&              &",
      "&(            (&",
      "(&            &(",
      "(&            &(",
      "(&            &(",
      "&(            (&",
      "&              &",
      "&              &",
      "&(            (&",
      "(&            &(",
      "(&            &(",
      "(&            &(",
      "&(            (&"
    ],
    [
      " (           #((",
      " (            ((",
      "                ",
      "&              &",
      "((            ((",
      "((            ((",
      "((            ((",
      "((            ((",
      "((            ((",
      "&              &",
      "&              &",
      "((            ((",
      "((            ((",
      "((            ((",
      "((            ((",
      "((            (("
    ],
    [
      "           ###  ",
      "          ##### ",
      "          #   ##",
      "&              &",
      "&              &",
      "&              &",
      "&              &",
      "&              &",
      "&              &",
      "&              &",
      "&              &",
      "&              &",
      "&              &",
      "&              &",
      "&              &",
      "                "
    ],
    [
      " &&&&&&&&&&&&&&&",
      " &&&&&&&&&&&&&&&",
      "&&&&&&&&&&&&&&&&",
      "&&&&&&&&&&&&&&&&",
      "&&&&&&&&&&&&&&&&",
      "&&&&&&&&&&&&&&&&",
      "&&&&&&&&&&&&&&&&",
      "&&&&&&&&&&&&&&&&",
      "&&&&&&&&&&&&&&&&",
      "&&&&&&&&&&&&&&&&",
      "&&&&&&&&&&&&&&&&",
      "&&&&&&&&&&&&&&&&",
      "&&&&&&&&&&&&&&&&",
      "&&&&&&&&&&&&&&&&",
      "&&&&&&&&&&&&&&&&",
      "&&&&&&&&&&&&&&& "
    ],
    [
      "           ###  ",
      "          ######",
      "          #   ##",
      "&&            &&",
      " &            & ",
      " &            & ",
      " &            & ",
      " &            & ",
      " &            & ",
      " &            & ",
      "#&#           & ",
      " &            & ",
      " &            & ",
      " &            & ",
      "&&            &&",
      "                "
    ],
    [
      "            #   ",
      "                ",
      "               #",
      "&              &",
      "&              &",
      "&              &",
      "&              &",
      "&              &",
      "&              &",
      "&#             &",
      "&##            &",
      "&#             &",
      "&              &",
      "&              &",
      "&              &",
      "                "
    ],
    [
      "                ",
      "                ",
      "                ",
      "                ",
      "                ",
      "                ",
      "                ",
      "                ",
      "                ",
      "                ",
      "##              ",
      "                ",
      "                ",
      "                ",
      "                ",
      "                "
    ],
    [
      "                ",
      "                ",
      "                ",
      "                ",
      "                ",
      "                ",
      "                ",
      "                ",
      "                ",
      "                ",
      "                ",
      "                ",
      "                ",
      "                ",
      "                ",
      "                "
    ],
    [
      "                ",
      "                ",
      "                ",
      "                ",
      "                ",
      "                ",
      "                ",
      "                ",
      "                ",
      "                ",
      "                ",
      "                ",
      "                ",
      "                ",
      "                ",
      "                "
    ],
    [
      "                ",
      "                ",
      "                ",
      "                ",
      "                ",
      "                ",
      "                ",
      "                ",
      "                ",
      "                ",
      "                ",
      "                ",
      "                ",
      "                ",
      "                ",
      "                "
    ],
    [
      "                ",
      "                ",
      "                ",
      "                ",
      "                ",
      "                ",
      "                ",
      "                ",
      "                ",
      "                ",
      "                ",
      "                ",
      "                ",
      "                ",
      "                ",
      "                "
    ],
    [
      "                ",
      "                ",
      "                ",
      "                ",
      "                ",
      "                ",
      "                ",
      "                ",
      "                ",
      "                ",
      "                ",
      "                ",
      "                ",
      "                ",
      "                ",
      "                "
    ]
  ]
}