{
  "xsize": 16,
  "zsize": 16,
  "refpalette": "lostcities:scattered",
  "slices": [
    [
      "   &&&&&&&&&&&&&",
      " &&&&&&&&&&&&&&&",
      "&&&&&&&&&&&&&&&&",
      "&&&&&&&&&&&&&&&&",
      "&&&&&&&&&&&&&&&&",
      "&&&&&&&&&&&&&&&&",
      "&&&&&&&&&&&&&&&&",
      "&&&&&&&&&&&&&&&&",
      "&&&&&&&&&&&&&&&&",
      "&&&&&&&&&&&&&&&&",
      "&&&&&&&&&&&&&&&&",
      "&&&&&&&&&&&&&&&&",
      "&&&&&&&&&&&&&&&&",
      "&&&&&&&&&&&&&&&&",
      "&&&&&&&&&&&&&&&&",
      "&&&&&&&&&&&&&&&&"
    ],
    [
      "      $$$$$$$$c$",
      "   $$$$$$$$$$$c$",
      " $$$$$$$$$$$$$c$",
      " $$$$$$$$$$$$$c$",
      " $$$$$$$$$$$$$c$",
      " c$$$$$$$$$$$c$$",
      " c$$$$$$$$$$$c$$",
      "$$c$$$$$$$$$c$$$",
      "$$$cc$$$$$cc$$$$",
      "$$$$$ccccc$$$$$$",
      "$$$$$$$$$$$$$$$$",
      "$$$$$$$$$$$$$$$$",
      " &&&&&&&&&&&&&&&",
      " &$$$$$$$$$$$$$$",
      " $$$$$$$$$$$$$$$",
      "  $$            "
    ],
    [
      "            aaa ",
      "              aa",
      "   j j          ",
      "       $$$$$$$$$",
      "     j          ",
      " j        j     ",
      "    aaaa        ",
      "      a$$$$$$$$$",
      "   j  aaaa      ",
      "       aa       ",
      "       a        ",
      "       $$$$$$$$$",
      " ͷeeeeeeeeeeeeee",
      "  $$$           ",
      "  $$++++++++++++",
      "  $$            "
    ],
    [
      "       (&&&&&&&&",
      "       (&&&&&&&&",
      "       (&&&&&&&&",
      "       (&&&&&&&&",
      "       (&&&&&&&&",
      "       (&&&&&&&&",
      "    j  (&&&&&&&&",
      "       (&&&&&&&&",
      "      a(&&&&&&&&",
      "      a(&&&&&&&&",
      "      a(&&&&&&&&",
      "      a(((((((((",
      "       a   j    ",
      "  $$$           ",
      " $$$++++++++++++",
      "  $$            "
    ],
    [
      "       &aaa aaaa",
      "       (      aa",
      "       &       a",
      "       &        ",
      "       &        ",
      "       &  j     ",
      "       &        ",
      "       &        ",
      "      j&        ",
      "       & m      ",
      "       &     ͸  ",
      "      a(&&&&&&&&",
      "       a        ",
      "  $$$           ",
      "$$$$++++++++++++",
      "  $$            "
    ],
    [
      "       &a       ",
      "       (       a",
      "       &       a",
      "       &        ",
      "       &        ",
      "       &        ",
      "       &        ",
      "       &        ",
      "       &        ",
      "       & n      ",
      "       &        ",
      "      a(&&&&&&&&",
      "       a        ",
      "  $$$           ",
      "$$$$++++++++++++",
      "  $$            "
    ],
    [
      "                ",
      "                ",
      "               a",
      "                ",
      "       &        ",
      "       &        ",
      "       &        ",
      "       &        ",
      "       &        ",
      "       &        ",
      "      a&a       ",
      "      a(&&&&&&&&",
      "       a        ",
      "  $$$           ",
      "$$$$++++++++++++",
      "  $$            "
    ],
    [
      "                ",
      "               a",
      "               a",
      "                ",
      "                ",
      "                ",
      "                ",
      "       &        ",
      "       &        ",
      "       &        ",
      "      a&a       ",
      "       (&&&&&&&&",
      "                ",
      "  $$$           ",
      "$$$$++++++++++++",
      "  $$            "
    ],
    [
      "                ",
      "               a",
      "                ",
      "                ",
      "                ",
      "                ",
      "                ",
      "                ",
      "       &        ",
      "       &        ",
      "      a&a       ",
      "       (&&&&&&&&",
      "                ",
      "  $$$           ",
      "$$$$++++++++++++",
      "  $$            "
    ],
    [
      "               a",
      "             aaa",
      "              aa",
      "                ",
      "                ",
      "                ",
      "                ",
      "                ",
      "                ",
      "       &aaaaaaaa",
      "      a&a       ",
      "       (&&&&&&&&",
      "                ",
      "  $$$           ",
      "$$$$++++++++++++",
      "  $$            "
    ],
    [
      "             &&&",
      "            a(((",
      "            &&&&",
      "            &&&&",
      "            &&&&",
      "            &&&&",
      "           &&&&&",
      "          &&&&&&",
      "       aa&&&&&&&",
      "      a(&&&&&&&&",
      "      a(&&&&&&&&",
      "       (((((((((",
      "                ",
      "  $$$           ",
      "$$$$++++++++++++",
      "  $$            "
    ],
    [
      "                ",
      "             aaa",
      "              aa",
      "                ",
      "                ",
      "              j ",
      "                ",
      "                ",
      "                ",
      "       aaaaaaaaa",
      "       a        ",
      "                ",
      "                ",
      "   $$           ",
      "   $++++++++++++",
      "   $            "
    ],
    [
      "                ",
      "                ",
      "                ",
      "                ",
      "                ",
      "                ",
      "                ",
      "                ",
      "                ",
      "                ",
      "                ",
      "                ",
      "                ",
      "   $$           ",
      "   $++++++++++++",
      "                "
    ],
    [
      "                ",
      "                ",
      "                ",
      "                ",
      "                ",
      "                ",
      "                ",
      "                ",
      "                ",
      "                ",
      "                ",
      "                ",
      "                ",
      "    $           ",
      "    ++++++++++++",
      "                "
    ],
    [
      "                ",
      "                ",
      "                ",
      "                ",
      "                ",
      "                ",
      "                ",
      "                ",
      "                ",
      "                ",
      "                ",
      "                ",
      "                ",
      "    $           ",
      "    ++++++++++++",
      "                "
    ],
    [
      "                ",
      "                ",
      "                ",
      "                ",
      "                ",
      "                ",
      "                ",
      "                ",
      "                ",
      "                ",
      "                ",
      "&&&&&&&&&&&&&&&&",
      "  &&&&&&&&&&&&&&",
      "   k$kkkkkkkkkkk",
      "    ++++++++++++",
      "                "
    ],
    [
      "                ",
      "                ",
      "                ",
      "                ",
      "                ",
      "                ",
      "                ",
      "                ",
      "                ",
      "                ",
      "                ",
      "                ",
      "                ",
      "   e$eeeeeeeeeee",
      "    ++++++++++++",
      "                "
    ],
    [
      "                ",
      "                ",
      "                ",
      "                ",
      "                ",
      "                ",
      "                ",
      "                ",
      "                ",
      "                ",
      "                ",
      "                ",
      "                ",
      "   $$           ",
      "    ++++++++++++",
      "                "
    ],
    [
      "                ",
      "                ",
      "                ",
      "                ",
      "                ",
      "                ",
      "                ",
      "                ",
      "                ",
      "                ",
      "                ",
      "                ",
      "                ",
      "   $$           ",
      "   $++++++++++++",
      "   $            "
    ],
    [
      "                ",
      "                ",
      "                ",
      "                ",
      "                ",
      "                ",
      "                ",
      "                ",
      "                ",
      "                ",
      "                ",
      "                ",
      "                ",
      "   $$           ",
      "   $++++++++++++",
      "   $            "
    ],
    [
      "                ",
      "                ",
      "                ",
      "                ",
      "                ",
      "                ",
      "                ",
      "                ",
      "                ",
      "                ",
      "                ",
      "                ",
      "                ",
      "  $$$           ",
      "  $$++++++++++++",
      "  $$            "
    ],
    [
      "                ",
      "                ",
      "                ",
      "                ",
      "                ",
      "                ",
      "                ",
      "                ",
      "                ",
      "                ",
      "                ",
      "                ",
      "                ",
      "  $$$           ",
      "$$$$++++++++++++",
      "  $$            "
    ],
    [
      "                ",
      "                ",
      "                ",
      "                ",
      "                ",
      "                ",
      "                ",
      "                ",
      "                ",
      "                ",
      "                ",
      "                ",
      "                ",
      "  $$$           ",
      "$$$$++++++++++++",
      "  $$            "
    ],
    [
      "                ",
      "                ",
      "                ",
      "                ",
      "                ",
      "                ",
      "                ",
      "                ",
      "                ",
      "                ",
      "                ",
      "                ",
      "                ",
      "  $$$           ",
      "$$$$++++++++++++",
      "  $$            "
    ],
    [
      "                ",
      "                ",
      "                ",
      "                ",
      "                ",
      "                ",
      "                ",
      "                ",
      "                ",
      "                ",
      "                ",
      "                ",
      "                ",
      "  $$$           ",
      "$$$$++++++++++++",
      "  $$            "
    ],
    [
      "                ",
      "                ",
      "                ",
      "                ",
      "                ",
      "                ",
      "                ",
      "                ",
      "                ",
      "                ",
      "                ",
      "                ",
      "                ",
      "  $$$           ",
      "$$$$++++++++++++",
      "  $$            "
    ],
    [
      "                ",
      "                ",
      "                ",
      "                ",
      "                ",
      "                ",
      "                ",
      "                ",
      "                ",
      "                ",
      "                ",
      "                ",
      "                ",
      "$$$$$$$$$$$$$$$$",
      "$$$$$$$$$$$$$$$$",
      "  $$$$$$$$$$$$$$"
    ],
    [
      "                ",
      "                ",
      "                ",
      "                ",
      "                ",
      "                ",
      "                ",
      "                ",
      "                ",
      "                ",
      "                ",
      "                ",
      "                ",
      "$$$$$$$$$$$$$$  ",
      "$$$$$$$$$$$$$$$ ",
      "  $$$$$$$$$$$$$ "
    ],
    [
      "                ",
      "                ",
      "                ",
      "                ",
      "                ",
      "                ",
      "                ",
      "                ",
      "                ",
      "                ",
      "                ",
      "                ",
      "                ",
      "  $$$$          ",
      "  $$$           ",
      "  $$$           "
    ],
    [
      "                ",
      "                ",
      "                ",
      "                ",
      "                ",
      "                ",
      "                ",
      "                ",
      "                ",
      "                ",
      "                ",
      "                ",
      "                ",
      "  $$$$          ",
      "  $$$           ",
      "  $$$           "
    ],
    [
      "                ",
      "                ",
      "                ",
      "                ",
      "                ",
      "                ",
      "                ",
      "                ",
      "                ",
      "                ",
      "                ",
      "&&&&&&          ",
      "&&&&&&          ",
      "&&$$&$&         ",
      "  $$$           ",
      "  $$$           "
    ],
    [
      "                ",
      "                ",
      "                ",
      "                ",
      "                ",
      "                ",
      "                ",
      "                ",
      "                ",
      "                ",
      "$$$$$$          ",
      "$$$$$$          ",
      "$$$$$$          ",
      "$$$$$$$         ",
      "$$$$$$$$        ",
      "$$$$$$$$$       "
    ],
    [
      "llllllllllllllll",
      "llllllllllllllll",
      "llllllllllllllll",
      "llllllllllllllll",
      "lllllllllllllll ",
      "llllllllllll    ",
      "lllllllll       ",
      "llllllll        ",
      "lllllll         ",
      "llllll          ",
      "                ",
      "  m             ",
      "                ",
      "   m            ",
      "                ",
      "                "
    ],
    [
      "                ",
      "     m          ",
      "  j             ",
      "                ",
      "     j          ",
      "j         j     ",
      "   j            ",
      "                ",
      "   j  j         ",
      "                ",
      "                ",
      "  n             ",
      "                ",
      "   n            ",
      "                ",
      "                "
    ],
    [
      "                ",
      "     n          ",
      "                ",
      "                ",
      "                ",
      "                ",
      "                ",
      "                ",
      "                ",
      "                ",
      "                ",
      "                ",
      "                ",
      "                ",
      "                ",
      "                "
    ],
    [
      "                ",
      "                ",
      "                ",
      "                ",
      "                ",
      "                ",
      "                ",
      "                ",
      "                ",
      "                ",
      "                ",
      "                ",
      "                ",
      "                ",
      "                ",
      "                "
    ]
  ]
}