{
  "xsize": 16,
  "zsize": 16,
  "refpalette": "lostcities:scattered",
  "slices": [
    [
      "&&&&&&&&&&&&&&&&",
      "&&&&&&&&&&&&&&&&",
      "&&&&&&&&&&&&&&&&",
      "&&&&&&&&&&&&&&&&",
      "&&&&&&&&&&&&&&&&",
      "&&&&&&&&&&&&&&&&",
      "&&&&&&&&&&&&&&&&",
      "&&&&&&&&&&&&&&&&",
      "&&&&&&&&aa &&&&&",
      "&&&&&&&aaaa&&&&&",
      "&&&&& aaaaa&&&&&",
      "&&&      aa&&&&&",
      "          &&&&&&",
      "   m     &&&&&&&",
      "        &&&&&&&&",
      "      &&&&&&&&&&"
    ],
    [
      "$$$$$ccccc$$$$$$",
      "$$$$$$$$$$$$$$$$",
      "$$$$$$$$$$$$$$$$",
      "&&&&&&&&&&&&&&&&",
      "                ",
      "                ",
      "  j      j      ",
      "       $a  j    ",
      "&&&&&&aaaa  &&&&",
      "$$$$$ aaaa   $$$",
      "$$$ j   aa   $$$",
      "       $    $$$$",
      "            $$$$",
      "   n       $c$$$",
      "          $$$c$$",
      "       $$$$$$c$$"
    ],
    [
      "                ",
      "a               ",
      "aa              ",
      "eeeeeeeeeeeeeeee",
      "                ",
      "                ",
      "       a        ",
      "      a$$$$$$$$$",
      "eeeeeeaaa    eee",
      "      jaaaaa    ",
      "           aaaa ",
      "       $$$$$$$$$",
      "                ",
      "                ",
      "       a        ",
      "       $$$$$$$$$"
    ],
    [
      "                ",
      "                ",
      "a               ",
      "                ",
      "                ",
      "                ",
      "       a        ",
      "      a(((((((((",
      "      a(&&&&&&&&",
      "       (&&&&&&&&",
      "       (&&&&&&&&",
      "       (&&&&&&&&",
      "       (&&&&&&&&",
      "       (&&&&&&&&",
      "      a(&&&&&&&&",
      "       (&&&&&&&&"
    ],
    [
      "                ",
      "                ",
      "a               ",
      "                ",
      "                ",
      "                ",
      "       j        ",
      "       a   &&&&&",
      "       aamaa    ",
      "        aaaaa   ",
      "       &  aaaaa ",
      "       &   aa aa",
      "       &        ",
      "       &       j",
      "      a&aaa     ",
      "      a&aaaaa   "
    ],
    [
      "                ",
      "                ",
      "                ",
      "                ",
      "                ",
      "                ",
      "                ",
      "            &&&&",
      "         n      ",
      "          aa    ",
      "           aa   ",
      "       &       a",
      "       &        ",
      "       &        ",
      "       &a       ",
      "      a&aaa     "
    ],
    [
      "                ",
      "                ",
      "                ",
      "                ",
      "                ",
      "                ",
      "                ",
      "             &&&",
      "                ",
      "                ",
      "                ",
      "       &       a",
      "       &        ",
      "       &        ",
      "       &j       ",
      "       aa       "
    ],
    [
      "                ",
      "                ",
      "                ",
      "                ",
      "                ",
      "                ",
      "                ",
      "             &&&",
      "                ",
      "                ",
      "               a",
      "               a",
      "                ",
      "                ",
      "                ",
      "                "
    ],
    [
      "                ",
      "                ",
      "                ",
      "                ",
      "                ",
      "                ",
      "                ",
      "             &&&",
      "                ",
      "              aa",
      "               a",
      "                ",
      "                ",
      "                ",
      "                ",
      "                "
    ],
    [
      "                ",
      "                ",
      "                ",
      "                ",
      "                ",
      "                ",
      "                ",
      "             &&&",
      "              aa",
      "             aaa",
      "              aa",
      "               a",
      "                ",
      "                ",
      "                ",
      "                "
    ],
    [
      "                ",
      "                ",
      "                ",
      "                ",
      "                ",
      "                ",
      "                ",
      "             (((",
      "             &&&",
      "            a&&&",
      "             a&&",
      "              &&",
      "              &&",
      "              &&",
      "              &&",
      "             &&&"
    ],
    [
      "                ",
      "                ",
      "                ",
      "                ",
      "                ",
      "                ",
      "                ",
      "                ",
      "                ",
      "             aaa",
      "                ",
      "                ",
      "                ",
      "                ",
      "                ",
      "             j  "
    ],
    [
      "                ",
      "                ",
      "                ",
      "                ",
      "                ",
      "                ",
      "                ",
      "                ",
      "                ",
      "                ",
      "                ",
      "                ",
      "                ",
      "                ",
      "                ",
      "                "
    ],
    [
      "                ",
      "                ",
      "                ",
      "                ",
      "                ",
      "                ",
      "                ",
      "                ",
      "                ",
      "                ",
      "                ",
      "                ",
      "                ",
      "                ",
      "                ",
      "                "
    ],
    [
      "                ",
      "                ",
      "                ",
      "                ",
      "                ",
      "                ",
      "                ",
      "                ",
      "                ",
      "                ",
      "                ",
      "                ",
      "                ",
      "                ",
      "                ",
      "                "
    ],
    [
      "                ",
      "                ",
      "&&&&&&&&&&&&&&&&",
      "&&&&&&&&&&&&&&&&",
      "kkkkkkkkkkkkkkkk",
      "                ",
      "                ",
      "hhhhhhhhhhhhhhhh",
      "&&&&&&&&&&&&&&&&",
      "&&&&&&&&&&&&&&&&",
      "                ",
      "                ",
      "                ",
      "                ",
      "                ",
      "                "
    ],
    [
      "                ",
      "                ",
      "                ",
      "                ",
      "eeeeeeeeeeeeeeee",
      "                ",
      "                ",
      "eeeeeeeeeeeeeeee",
      "                ",
      "                ",
      "                ",
      "                ",
      "                ",
      "                ",
      "                ",
      "                "
    ],
    [
      "                ",
      "                ",
      "                ",
      "                ",
      "                ",
      "                ",
      "                ",
      "                ",
      "                ",
      "                ",
      "                ",
      "                ",
      "                ",
      "                ",
      "                ",
      "                "
    ],
    [
      "                ",
      "                ",
      "                ",
      "                ",
      "                ",
      "                ",
      "                ",
      "                ",
      "                ",
      "                ",
      "                ",
      "                ",
      "                ",
      "                ",
      "                ",
      "                "
    ],
    [
      "                ",
      "                ",
      "                ",
      "                ",
      "                ",
      "                ",
      "                ",
      "                ",
      "                ",
      "                ",
      "                ",
      "                ",
      "                ",
      "                ",
      "                ",
      "                "
    ],
    [
      "                ",
      "                ",
      "                ",
      "                ",
      "                ",
      "                ",
      "                ",
      "                ",
      "                ",
      "                ",
      "                ",
      "                ",
      "                ",
      "                ",
      "                ",
      "                "
    ],
    [
      "                ",
      "                ",
      "                ",
      "                ",
      "                ",
      "                ",
      "                ",
      "                ",
      "                ",
      "                ",
      "                ",
      "                ",
      "                ",
      "                ",
      "                ",
      "                "
    ],
    [
      "                ",
      "                ",
      "                ",
      "                ",
      "                ",
      "                ",
      "                ",
      "                ",
      "                ",
      "                ",
      "                ",
      "                ",
      "                ",
      "                ",
      "                ",
      "                "
    ],
    [
      "                ",
      "                ",
      "                ",
      "                ",
      "                ",
      "                ",
      "                ",
      "                ",
      "                ",
      "                ",
      "                ",
      "                ",
      "                ",
      "                ",
      "                ",
      "                "
    ],
    [
      "                ",
      "                ",
      "                ",
      "                ",
      "                ",
      "                ",
      "                ",
      "                ",
      "                ",
      "                ",
      "                ",
      "                ",
      "                ",
      "                ",
      "                ",
      "                "
    ],
    [
      "                ",
      "                ",
      "                ",
      "                ",
      "                ",
      "                ",
      "                ",
      "                ",
      "                ",
      "                ",
      "                ",
      "                ",
      "                ",
      "                ",
      "                ",
      "                "
    ],
    [
      "                ",
      "                ",
      "                ",
      "                ",
      "                ",
      "                ",
      "                ",
      "                ",
      "                ",
      "                ",
      "                ",
      "                ",
      "                ",
      "                ",
      "                ",
      "                "
    ],
    [
      "                ",
      "                ",
      "                ",
      "                ",
      "                ",
      "                ",
      "                ",
      "                ",
      "                ",
      "                ",
      "                ",
      "                ",
      "                ",
      "                ",
      "                ",
      "                "
    ],
    [
      "                ",
      "                ",
      "                ",
      "                ",
      "                ",
      "                ",
      "                ",
      "                ",
      "                ",
      "                ",
      "                ",
      "                ",
      "                ",
      "                ",
      "                ",
      "                "
    ],
    [
      "                ",
      "                ",
      "                ",
      "                ",
      "                ",
      "                ",
      "                ",
      "                ",
      "                ",
      "                ",
      "                ",
      "                ",
      "                ",
      "                ",
      "                ",
      "                "
    ],
    [
      "                ",
      "                ",
      "&&&&&&&&&&&&&&&&",
      "&&&&&&&&&&&&&&&&",
      "                ",
      "                ",
      "                ",
      "                ",
      "&&&&&&&&&&&&&&&&",
      "&&&&&&&&&&&&&&&&",
      "                ",
      "                ",
      "                ",
      "                ",
      "                ",
      "                "
    ],
    [
      "                ",
      "$$$$$$$$$$$$$$$$",
      "$$$$$$$$$$$$$$$$",
      "$$$$$$$$$$$$$$$$",
      "$$$$$$$$$$$$$$$$",
      "$$$$$$$$$$$$$$$$",
      "$$$$$$$$$$$$$$$$",
      "$$$$$$$$$$$$$$$$",
      "$$$$$$$$$$$$$$$$",
      "$$$$$$$$$$$$$$$$",
      "$$$$$$$$$$$$$$$$",
      "                ",
      "                ",
      "                ",
      "                ",
      "                "
    ],
    [
      "llllllllllllllll",
      "llllllllllllllll",
      "llllllllllllllll",
      "llllllllllllllll",
      "llllllllllllllll",
      "llllllllllllllll",
      "llllllllllllllll",
      "llllllllllllllll",
      "llllllllllllllll",
      "llllllllllllllll",
      "llllllllllllllll",
      "llllllllllllllll",
      "llllllllllllllll",
      "llllllllllllllll",
      "llllllllllllllll",
      "llllllllllllllll"
    ],
    [
      "                ",
      "                ",
      "                ",
      "                ",
      "                ",
      "                ",
      "                ",
      "                ",
      "                ",
      "                ",
      "                ",
      "              j ",
      "                ",
      "               j",
      "   j    j       ",
      "             j  "
    ],
    [
      "                ",
      "                ",
      "                ",
      "                ",
      "                ",
      "                ",
      "                ",
      "                ",
      "                ",
      "                ",
      "                ",
      "                ",
      "                ",
      "                ",
      "                ",
      "                "
    ],
    [
      "                ",
      "                ",
      "                ",
      "                ",
      "                ",
      "                ",
      "                ",
      "                ",
      "                ",
      "                ",
      "                ",
      "                ",
      "                ",
      "                ",
      "                ",
      "                "
    ]
  ]
}