{
  "xsize": 16,
  "zsize": 16,
  "refpalette": "pomkotsmechs:scattered",
  "slices": [
    [
      "                ",
      "                ",
      "                ",
      "                ",
      "                ",
      "                ",
      "                ",
      "       $ $      ",
      "        $       ",
      "       $ $      ",
      "                ",
      "                ",
      "                ",
      "                ",
      "                ",
      "                "
    ],
    [
      "0vvvvv&023333vv0",
      "0v&vvv&03333vvvv",
      "0vvvvv&02332vvvv",
      "0v&vvv&02220vvv ",
      "2v&vvv&&000&vvvv",
      "3v0&vv&&00&&vvvv",
      "vvv&&& 0000&v&&v",
      "vvvv0022220&&&02",
      "vvvv22333320&022",
      "vvv002333320&&02",
      "vvvv&023332&&&&0",
      "vvvvv&03330&vv&&",
      "vvvvvv&2220&v&&&",
      "vvvvvv&0220&&002",
      "vvvvvvvv20000233",
      "vvvvvvvv22222333"
    ],
    [
      "                ",
      "                ",
      "                ",
      "                ",
      "  ..           .",
      "# ..           .",
      "###             ",
      " #              ",
      "#!!           !!",
      "#!!           !!",
      "                ",
      "                ",
      "                ",
      "                ",
      "                ",
      "                "
    ],
    [
      "                ",
      "                ",
      "                ",
      "               #",
      "  .A           .",
      " #.A           .",
      "                ",
      " #              ",
      "#!!           !!",
      " !!           !!",
      "                ",
      "                ",
      "                ",
      "                ",
      "                ",
      "                "
    ],
    [
      "                ",
      "                ",
      "                ",
      "               #",
      "  .X           .",
      " #.X           .",
      "                ",
      " #              ",
      "#!!           !!",
      " !!           !!",
      "                ",
      "                ",
      "                ",
      "                ",
      "                ",
      "                "
    ],
    [
      "                ",
      "                ",
      "                ",
      "                ",
      "  ..           .",
      "  ..           .",
      "#               ",
      "#               ",
      "#!!           !!",
      " !!           !!",
      "                ",
      "                ",
      "                ",
      "                ",
      "                ",
      "                "
    ],
    [
      "                ",
      "                ",
      "                ",
      "                ",
      "  '            '",
      "                ",
      "                ",
      "                ",
      "#!!           !!",
      " !!           !!",
      "                ",
      "                ",
      "                ",
      "                ",
      "                ",
      "                "
    ],
    [
      "                ",
      "                ",
      "                ",
      "                ",
      "  '            '",
      "                ",
      "                ",
      "                ",
      "#!!           !!",
      " !!           !!",
      "                ",
      "                ",
      "                ",
      "                ",
      "                ",
      "                "
    ],
    [
      "                ",
      "                ",
      "                ",
      "        #       ",
      "  '     #      '",
      "                ",
      "                ",
      "                ",
      "#!!           !!",
      "  !           !!",
      "                ",
      "                ",
      "                ",
      "                ",
      "                ",
      "                "
    ],
    [
      "^^^^^^^^^^^^^^^^",
      "^^^^^^^^^^^^^^^^",
      "^^^^^^^ #^^^^^^^",
      "^^^^^^^##^^^^^^^",
      "^^^^^^^^^^^^^^^^",
      "^^^^^^^^^^^^^^^^",
      "^^^^^^^^^^^^^^^^",
      "^^^^^^^^^^^^^^^^",
      "#^^^^^^^^^^^^^^^",
      " ^^^^^^^^^^^^^^^",
      " ^^^^^^^^^^^^^^^",
      " ^^^^^^^^^^^^^^^",
      "                ",
      "                ",
      "                ",
      "                "
    ],
    [
      "!!!!!!!  !!!!!!!",
      "!!!!!!    !!!!!!",
      "!!!!!      !!!!!",
      "!!!!!   #  !!!!!",
      "!!!!!####  !!!!!",
      "!!!!!!!    !!!!!",
      "!!!!!!!!  !!!!!!",
      "###!!!!!!!!!!!!!",
      "###!!!!!!!!!!!!!",
      "   !!!!!!!!!!!!!",
      "  !!!!!!!!!!!!!!",
      "                ",
      "                ",
      "                ",
      "                ",
      "                "
    ],
    [
      "                ",
      "                ",
      "                ",
      "                ",
      "   ##           ",
      "  ##            ",
      "###             ",
      "                ",
      "                ",
      "                ",
      "                ",
      "                ",
      "                ",
      "                ",
      "                ",
      "                "
    ],
    [
      "                ",
      "                ",
      "                ",
      "                ",
      "                ",
      "                ",
      "                ",
      "                ",
      "                ",
      "                ",
      "                ",
      "                ",
      "                ",
      "                ",
      "                ",
      "                "
    ],
    [
      "                ",
      "                ",
      "                ",
      "                ",
      "                ",
      "                ",
      "                ",
      "                ",
      "                ",
      "                ",
      "                ",
      "                ",
      "                ",
      "                ",
      "                ",
      "                "
    ],
    [
      "                ",
      "                ",
      "                ",
      "                ",
      "                ",
      "                ",
      "                ",
      "                ",
      "                ",
      "                ",
      "                ",
      "                ",
      "                ",
      "                ",
      "                ",
      "                "
    ],
    [
      "                ",
      "                ",
      "                ",
      "                ",
      "                ",
      "                ",
      "                ",
      "                ",
      "                ",
      "                ",
      "                ",
      "                ",
      "                ",
      "                ",
      "                ",
      "                "
    ],
    [
      "                ",
      "                ",
      "                ",
      "                ",
      "                ",
      "                ",
      "                ",
      "                ",
      "                ",
      "                ",
      "                ",
      "                ",
      "                ",
      "                ",
      "                ",
      "                "
    ],
    [
      "                ",
      "                ",
      "                ",
      "                ",
      "                ",
      "                ",
      "                ",
      "                ",
      "                ",
      "                ",
      "                ",
      "                ",
      "                ",
      "                ",
      "                ",
      "                "
    ]
  ]
}