{
  "xsize": 16,
  "zsize": 16,
  "refpalette": "pomkotsmechs:scattered",
  "slices": [
    [
      "                ",
      "                ",
      "      $         ",
      "      $&000&vvv&",
      "      $vvvvvvvvv",
      "       &vvvvvvvv",
      "       0vvvvvvvv",
      "       2vvvvvvvv",
      "       3vvvvvvvv",
      "       3vvvvvvvv",
      "       3vvvvvvvv",
      "       3vvvvvvvv",
      "       2vvvvvvvv",
      "       0vvvvvvvv",
      "       &vvvvvvvv",
      "       &vvvvvvvv"
    ],
    [
      "                ",
      "                ",
      "      $         ",
      "      $555555555",
      "      $566666666",
      "       566666666",
      "       566666666",
      "       566666666",
      "       566666677",
      "       566666677",
      "       566666676",
      "       566666677",
      "       566666677",
      "       566666677",
      "       566666677",
      "       566666676"
    ],
    [
      "                ",
      "                ",
      "      $         ",
      "      $555555555",
      "      $5        ",
      "       5        ",
      "       5        ",
      "       5        ",
      "       5       8",
      "       5      98",
      "       5        ",
      "       5       8",
      "       5      98",
      "       5       8",
      "       5        ",
      "       5        "
    ],
    [
      "                ",
      "                ",
      "      $         ",
      "      $555555555",
      "      $5        ",
      "       5        ",
      "       5        ",
      "       5        ",
      "       5        ",
      "       5        ",
      "       5        ",
      "       5        ",
      "       5        ",
      "       5        ",
      "       5        ",
      "       5        "
    ],
    [
      "                ",
      "                ",
      "      $         ",
      "      $555555555",
      "      $5        ",
      "       5        ",
      "       5        ",
      "       5        ",
      "       5        ",
      "       5        ",
      "       5        ",
      "       5        ",
      "       5        ",
      "       5        ",
      "       5        ",
      "       5        "
    ],
    [
      "                ",
      "                ",
      "       $        ",
      "       $55555555",
      "       $        ",
      "       5        ",
      "       5        ",
      "       5        ",
      "       5        ",
      "       5        ",
      "       5        ",
      "       5        ",
      "       5        ",
      "       5        ",
      "       5        ",
      "       5        "
    ],
    [
      "                ",
      "                ",
      "       $        ",
      "       $55555555",
      "       $5       ",
      "        5       ",
      "        5       ",
      "        5       ",
      "        5       ",
      "        5       ",
      "        5       ",
      "        5       ",
      "        5       ",
      "        5       ",
      "        5       ",
      "        5       "
    ],
    [
      "                ",
      "                ",
      "       $$       ",
      "       $$5555555",
      "       $$       ",
      "        5       ",
      "        5       ",
      "        5       ",
      "        5       ",
      "        5       ",
      "        5       ",
      "        5       ",
      "        5       ",
      "        5       ",
      "        5       ",
      "        5       "
    ],
    [
      "                ",
      "                ",
      "        $       ",
      "        $5555555",
      "        $5      ",
      "         5      ",
      "         5      ",
      "         5      ",
      "         5      ",
      "         5      ",
      "         5      ",
      "         5      ",
      "         5      ",
      "         5      ",
      "         5      ",
      "         5      "
    ],
    [
      "                ",
      "                ",
      "        $$     #",
      "        $$555555",
      "        $$     #",
      "         5      ",
      "         5      ",
      "         5      ",
      "         5      ",
      "         5      ",
      "         5      ",
      "         5      ",
      "         5      ",
      "         5      ",
      "         5      ",
      "         5##    "
    ],
    [
      "                ",
      "                ",
      "         $     #",
      "         $555555",
      "         $5    #",
      "          5     ",
      "          5     ",
      "          5     ",
      "          5     ",
      "          5     ",
      "          5     ",
      "          5     ",
      "          5     ",
      "          5     ",
      "          5##   ",
      "         #5##   "
    ],
    [
      "                ",
      "                ",
      "          $   ##",
      "          $55555",
      "          $5  ##",
      "           5    ",
      "           5    ",
      "           5    ",
      "           5    ",
      "           5    ",
      "           5    ",
      "           5    ",
      "           5    ",
      "           5##  ",
      "          #5##  ",
      "          #5#   "
    ],
    [
      "                ",
      "                ",
      "           $  # ",
      "           $5555",
      "           $5 # ",
      "            5   ",
      "            5   ",
      "            5   ",
      "            5   ",
      "            5   ",
      "            5   ",
      "            5   ",
      "            5## ",
      "           #5## ",
      "           #5#  ",
      "           #5   "
    ],
    [
      "                ",
      "                ",
      "            $   ",
      "            $555",
      "            $55 ",
      "             55 ",
      "             55 ",
      "             55 ",
      "             55 ",
      "             55 ",
      "             55 ",
      "             55 ",
      "             55#",
      "            #55#",
      "            #55 ",
      "             55 "
    ],
    [
      "                ",
      "                ",
      "             $$ ",
      "             $$5",
      "             $$5",
      "               5",
      "               5",
      "               5",
      "               5",
      "               5",
      "               5",
      "              #5",
      "             ##5",
      "             ##5",
      "               5",
      "               5"
    ],
    [
      "                ",
      "                ",
      "              $ ",
      "              $ ",
      "              $ ",
      "                ",
      "                ",
      "                ",
      "                ",
      "                ",
      "                ",
      "               #",
      "              ##",
      "                ",
      "                ",
      "                "
    ],
    [
      "                ",
      "                ",
      "                ",
      "                ",
      "                ",
      "                ",
      "                ",
      "                ",
      "                ",
      "                ",
      "                ",
      "                ",
      "                ",
      "                ",
      "                ",
      "                "
    ],
    [
      "                ",
      "                ",
      "                ",
      "                ",
      "                ",
      "                ",
      "                ",
      "                ",
      "                ",
      "                ",
      "                ",
      "                ",
      "                ",
      "                ",
      "                ",
      "                "
    ]
  ]
}