{
  "xsize": 16,
  "zsize": 16,
  "refpalette": "lostcities:scattered",
  "slices": [
    [
      "    &&&&&&&&&&&w",
      "    &&&&&&&&&&&w",
      "    &&&&&&&&&&& ",
      "    &&&&&&&&&&& ",
      "    &&&&&&&&&&& ",
      "    &&&&&&&&&&& ",
      "    &&&&&&&&&&& ",
      "    &&&&&&&&&&&&",
      "    &&&&&&&&&&&&",
      "    &&&&&&&&&&&&",
      "    &&&&&&&&&&&&",
      "    &&&&&&&&&&&&",
      "    &&&&&&&&&&&&",
      "    &&&&&&&&&&&&",
      "    &&&&&&&&&&&&",
      "    &&&&&&&&&&&&"
    ],
    [
      "     $$$$c$$$$ w",
      "     $$$$c$$$$  ",
      "     $$$$c$$$$  ",
      "     $$$$$c$$$  ",
      "     $$$$$c$$$  ",
      "     $$$$$$c$$  ",
      "     $$$$$$$cc  ",
      "     $$$$$$$$$  ",
      "     $$$$$$$$$  ",
      "     $$$$$$$$$$ ",
      "    $$$&&&&&&&&&",
      "    $$$       j ",
      "     $   j      ",
      "     $ m        ",
      "    $$$         ",
      "    $$$&&&&&&&&&"
    ],
    [
      "     f         w",
      "     f          ",
      "     f          ",
      "     f          ",
      "     f          ",
      "     f      j   ",
      "     f    j     ",
      "     f          ",
      "     f          ",
      "     f$         ",
      "    $$$eeeeeee  ",
      "    $$$         ",
      "     $          ",
      "     $ n        ",
      "    $$$         ",
      "    $$$eeeeeeeee"
    ],
    [
      "     f         w",
      "     f          ",
      "     f          ",
      "     f          ",
      "     f          ",
      "     f          ",
      "     f          ",
      "     f          ",
      "     f          ",
      "     f$         ",
      "    $$$         ",
      "    $$$         ",
      "     $          ",
      "     $          ",
      "    $$$         ",
      "    $$$j        "
    ],
    [
      "     f         w",
      "     f          ",
      "     f          ",
      "     f          ",
      "     f          ",
      "     f          ",
      "     f          ",
      "     f          ",
      "     f          ",
      "     f$         ",
      "    $$$         ",
      "    $$$         ",
      "     $          ",
      "     $          ",
      "    $$$         ",
      "    $$$         "
    ],
    [
      "     f        uw",
      "     f          ",
      "     f          ",
      "     f          ",
      "     f          ",
      "     f          ",
      "     f          ",
      "     f          ",
      "     f          ",
      "     f$         ",
      "    $$$         ",
      "    $$$         ",
      "     $          ",
      "     $          ",
      "    $$$         ",
      "    $$$         "
    ],
    [
      "     f       uuw",
      "     f       put",
      "     f       ptt",
      "     f         p",
      "     f          ",
      "     f          ",
      "     f          ",
      "     f          ",
      "     f          ",
      "     f$         ",
      "    $$$         ",
      "    $$$         ",
      "     $          ",
      "     $          ",
      "    $$$         ",
      "    $$$         "
    ],
    [
      "     f     qrpw ",
      "     f      qrpp",
      "     f      rpuw",
      "     f          ",
      "     f          ",
      "     f          ",
      "     f          ",
      "     f          ",
      "     f          ",
      "     f$         ",
      "    $$$         ",
      "    $$$         ",
      "     $          ",
      "     $          ",
      "    $$$         ",
      "    $$$         "
    ],
    [
      "     f     sqrpp",
      "     f     xsqrr",
      "     f      qrpp",
      "     f       qrq",
      "     f          ",
      "     f          ",
      "     f          ",
      "     f          ",
      "     f          ",
      "     f$         ",
      "    $$$         ",
      "    $$$         ",
      "     $          ",
      "     $          ",
      "    $$$         ",
      "    $$$         "
    ],
    [
      "     f     xsqrr",
      "     f     yxsqq",
      "     f      sqrr",
      "     f      ss q",
      "     f          ",
      "     f          ",
      "     f          ",
      "     f          ",
      "     f          ",
      "     f$         ",
      "    $$$         ",
      "    $$$         ",
      "     $          ",
      "     $          ",
      "    $$$         ",
      "    $$$         "
    ],
    [
      "     f     yxsq ",
      "     f      yxss",
      "     f       sqq",
      "     f       xss",
      "     f        x ",
      "     f          ",
      "     f          ",
      "     f          ",
      "     f          ",
      "     f$         ",
      "    $$$         ",
      "    $$$         ",
      "     $          ",
      "     $          ",
      "    $$$         ",
      "    $$$         "
    ],
    [
      "     f     #xxss",
      "     f     ##yxx",
      "     f       xss",
      "     f        xx",
      "     f         y",
      "     f          ",
      "                ",
      "                ",
      "                ",
      "                ",
      "    $           ",
      "    $           ",
      "     $          ",
      "     $          ",
      "    $$$         ",
      "    $$$         "
    ],
    [
      "     f      #yxx",
      "     f       yyy",
      "     f       yxx",
      "     f        yy",
      "     f          ",
      "                ",
      "                ",
      "                ",
      "                ",
      "                ",
      "                ",
      "                ",
      "                ",
      "     $          ",
      "    $$$         ",
      "    $$$         "
    ],
    [
      "     f       #yy",
      "     f        ##",
      "     f        yy",
      "     f         #",
      "     f          ",
      "                ",
      "                ",
      "                ",
      "                ",
      "                ",
      "                ",
      "                ",
      "                ",
      "                ",
      "    $$          ",
      "    $$$         "
    ],
    [
      "     f        ##",
      "     f        ##",
      "     f         #",
      "     f          ",
      "     f          ",
      "                ",
      "                ",
      "                ",
      "                ",
      "                ",
      "                ",
      "                ",
      "                ",
      "                ",
      "    $           ",
      "    $$          "
    ],
    [
      "     f         #",
      "     f         #",
      "     f         #",
      "     f          ",
      "     f          ",
      "                ",
      "                ",
      "                ",
      "                ",
      "                ",
      "                ",
      "                ",
      "                ",
      "                ",
      "    $           ",
      "    $$          "
    ],
    [
      "     f          ",
      "     f         #",
      "     f          ",
      "     f          ",
      "     f          ",
      "                ",
      "                ",
      "                ",
      "                ",
      "                ",
      "                ",
      "                ",
      "                ",
      "                ",
      "    $           ",
      "    $$          "
    ],
    [
      "     f          ",
      "     f          ",
      "     f          ",
      "     f          ",
      "     f          ",
      "                ",
      "                ",
      "                ",
      "                ",
      "                ",
      "                ",
      "                ",
      "                ",
      "                ",
      "    $           ",
      "    $$          "
    ],
    [
      "     f          ",
      "     f          ",
      "     f          ",
      "     f          ",
      "     f          ",
      "     f          ",
      "                ",
      "                ",
      "                ",
      "                ",
      "                ",
      "                ",
      "                ",
      "                ",
      "    $           ",
      "    $$$         "
    ],
    [
      "     f          ",
      "     f          ",
      "     f          ",
      "     f          ",
      "     f          ",
      "     f          ",
      "     f          ",
      "     f          ",
      "     f          ",
      "                ",
      "    $           ",
      "    $           ",
      "                ",
      "     $          ",
      "    $$          ",
      "    $$$         "
    ],
    [
      "     f          ",
      "     f          ",
      "     f          ",
      "     f          ",
      "     f          ",
      "     f          ",
      "     f          ",
      "     f          ",
      "     f          ",
      "     f$         ",
      "    $$$         ",
      "    $$$         ",
      "     $          ",
      "     $          ",
      "    $$$         ",
      "    $$$         "
    ],
    [
      "     f          ",
      "     f          ",
      "     f          ",
      "     f          ",
      "     f          ",
      "     f          ",
      "     f          ",
      "     f          ",
      "     f          ",
      "     f$         ",
      "    $$$         ",
      "    $$$         ",
      "     $          ",
      "     $          ",
      "    $$$         ",
      "    $$$         "
    ],
    [
      "     f          ",
      "     f          ",
      "     f          ",
      "     f          ",
      "     f          ",
      "     f          ",
      "     f          ",
      "     f          ",
      "     f          ",
      "     f$         ",
      "    $$$         ",
      "    $$$         ",
      "     $          ",
      "     $          ",
      "    $$$         ",
      "    $$$         "
    ],
    [
      "     f          ",
      "     f          ",
      "     f          ",
      "     f          ",
      "     f          ",
      "     f          ",
      "     f          ",
      "     f          ",
      "     f          ",
      "     f$         ",
      "    $$$         ",
      "    $$$         ",
      "     $          ",
      "     $          ",
      "    $$$         ",
      "    $$$         "
    ],
    [
      "     f          ",
      "     f          ",
      "     f          ",
      "     f          ",
      "     f          ",
      "     f          ",
      "     f          ",
      "     f          ",
      "     f          ",
      "     f$         ",
      "    $$$         ",
      "    $$$         ",
      "     $          ",
      "     $          ",
      "    $$$         ",
      "    $$$         "
    ],
    [
      "     f          ",
      "     f          ",
      "     f          ",
      "     f          ",
      "     f          ",
      "     f          ",
      "     f          ",
      "     f          ",
      "     f          ",
      "     f$         ",
      "    $$$         ",
      "    $$$         ",
      "     $          ",
      "     $          ",
      "    $$$         ",
      "    $$$         "
    ],
    [
      "    $$$         ",
      "    $$$         ",
      "    $$$         ",
      "    $$$         ",
      "    $$$         ",
      "    $$$         ",
      "    $$$         ",
      "    $$$         ",
      "    $$$         ",
      "    $$$         ",
      "    $$$         ",
      "    $$$         ",
      "     $$         ",
      "     $$         ",
      "    $$$         ",
      "    $$$         "
    ],
    [
      "    $$$         ",
      "    $$$         ",
      "    $$$         ",
      "    $$$         ",
      "    $$$         ",
      "    $$$         ",
      "    $$$         ",
      "    $$$         ",
      "    $$$         ",
      "    $$$         ",
      "    $$$         ",
      "    $$$         ",
      "     $$         ",
      "     $$         ",
      "    $$$         ",
      "    $$$         "
    ],
    [
      "                ",
      "                ",
      "                ",
      "                ",
      "      $         ",
      "                ",
      "                ",
      "                ",
      "      $         ",
      "    $$$         ",
      "    $$$         ",
      "    $$$         ",
      "                ",
      "                ",
      "    $$$         ",
      "    $$$         "
    ],
    [
      "                ",
      "                ",
      "                ",
      "                ",
      "                ",
      "                ",
      "                ",
      "                ",
      "      $         ",
      "    $$$         ",
      "    $$$         ",
      "    $$$         ",
      "                ",
      "                ",
      "    $$$         ",
      "    $$$         "
    ],
    [
      "                ",
      "                ",
      "                ",
      "                ",
      "                ",
      "                ",
      "                ",
      "                ",
      "                ",
      "    $$        &&",
      "    $$        &&",
      "    $$          ",
      "                ",
      "      &         ",
      "    $$$         ",
      "    $$$&   &&&&&"
    ],
    [
      "                ",
      "                ",
      "                ",
      "                ",
      "                ",
      "                ",
      "                ",
      "                ",
      "               $",
      "    $          $",
      "    $          $",
      "    $$         $",
      "    $$         $",
      "    $$        $$",
      "    $$        $$",
      "    $$$      $$$"
    ],
    [
      "                ",
      "                ",
      "                ",
      "                ",
      "                ",
      "                ",
      "                ",
      "                ",
      "                ",
      "               l",
      "    l          l",
      "    l          l",
      "    l          l",
      "    ll         l",
      "    ll        ll",
      "    lll      lll"
    ],
    [
      "                ",
      "                ",
      "                ",
      "                ",
      "                ",
      "                ",
      "                ",
      "                ",
      "                ",
      "                ",
      "                ",
      "                ",
      "                ",
      "                ",
      "                ",
      "                "
    ],
    [
      "                ",
      "                ",
      "                ",
      "                ",
      "                ",
      "                ",
      "                ",
      "                ",
      "                ",
      "                ",
      "                ",
      "                ",
      "                ",
      "                ",
      "                ",
      "                "
    ],
    [
      "                ",
      "                ",
      "                ",
      "                ",
      "                ",
      "                ",
      "                ",
      "                ",
      "                ",
      "                ",
      "                ",
      "                ",
      "                ",
      "                ",
      "                ",
      "                "
    ]
  ]
}