{
  "xsize": 16,
  "zsize": 16,
  "refpalette": "lostcities:scattered",
  "slices": [
    [
      "                ",
      "             %% ",
      "             %% ",
      "                ",
      "      ##        ",
      "       ## #     ",
      "        # #     ",
      "                ",
      "         $$     ",
      "        $$$$    ",
      "        $$$$    ",
      "         $$     ",
      "                ",
      " %%             ",
      " %%             ",
      "                "
    ],
    [
      "vv223320&00220  ",
      "vv022220&&022%% ",
      "vvv0220&&&022%% ",
      "&vv0000&&&&02   ",
      "&&vv00vvvv&0    ",
      "&&vvv0&vv&vv    ",
      "002vvvvvvvv#    ",
      "022vvvvvvv#     ",
      "222vvvvvv$$     ",
      "222vvvvv$$$$    ",
      "320vvvv $$$$    ",
      "322vvv   $$     ",
      "32vv            ",
      "3%%             ",
      " %%             ",
      "                "
    ],
    [
      "$$$$$$$      $  ",
      "$$$$$$$      %% ",
      "$$$$$$$     $%% ",
      "$$$$$$$#    $   ",
      "$$$$$$$#   $    ",
      "$$$$$$$## #$    ",
      "$$$$$$$ ##$#    ",
      "         $#     ",
      "        $$$     ",
      "       $$$$$    ",
      "      $ $$$$    ",
      "    $$   $$     ",
      "  $$            ",
      "$%%             ",
      " %%             ",
      "                "
    ],
    [
      "#####$       $  ",
      "#####$#      %% ",
      " ####$##    $%% ",
      "     $##    $   ",
      "     $#    $    ",
      "$$$$$$    #$    ",
      "         #$#    ",
      "         $#     ",
      "        $$$     ",
      "       $$$$$    ",
      "      $ $$$$    ",
      "    $$   $$     ",
      "  $$            ",
      "$%%             ",
      " %%             ",
      "                "
    ],
    [
      " ###$##      $  ",
      " ###$##      %% ",
      "   #$##     $%% ",
      "    $##     $   ",
      "$$$$$      $    ",
      "          #$    ",
      "         #$#    ",
      "         $#     ",
      "        $$$     ",
      "       $$$$$    ",
      "     #$ $$$$    ",
      "    $$#  $$     ",
      "  $$ #          ",
      "$%%             ",
      " %%             ",
      "                "
    ],
    [
      "  #####      $  ",
      "  #$###      %% ",
      "  #$##      $%% ",
      "$$$$        $   ",
      "           $    ",
      "          #$    ",
      "         #$#    ",
      "         $#     ",
      "        $$$     ",
      "      #$$$$$    ",
      "     #$#$$$$    ",
      "    $$## $$     ",
      "  $$ ##         ",
      "$%%             ",
      " %%             ",
      "                "
    ],
    [
      "     #       $  ",
      "   ###       %% ",
      "  #$#       $%% ",
      "$$$$        $   ",
      "           $    ",
      "          #$    ",
      "         #$#    ",
      "         $##    ",
      "        $$$#    ",
      "      #$$$$$    ",
      "     #$#$$$$    ",
      "    $$#  $$     ",
      "  $$            ",
      "$%%             ",
      " %%             ",
      "                "
    ],
    [
      "             $  ",
      "  $          %% ",
      "$$$#        $%% ",
      "            $   ",
      "           $    ",
      "          #$    ",
      "         #$#    ",
      "         $##    ",
      "        $$$#    ",
      "      #$$$$$    ",
      "     #$#$$$$    ",
      "    $$#  $$     ",
      "  $$            ",
      "$%%             ",
      " %%             ",
      "                "
    ],
    [
      " $           $  ",
      "$$           %% ",
      "            $%% ",
      "            $   ",
      "           $    ",
      "           $    ",
      "          #     ",
      "         ##     ",
      "       #$$$#    ",
      "      #$$$$$    ",
      "     #$#$$$$    ",
      "    $$## $$     ",
      "  $$            ",
      "  %             ",
      " %%             ",
      "                "
    ],
    [
      "$            $  ",
      "             %% ",
      "            $%% ",
      "            $   ",
      "           $    ",
      "                ",
      "                ",
      "         #      ",
      "       ##$#     ",
      "      #$$$$$    ",
      "      $#$$$$    ",
      "    $$   $$     ",
      "   $            ",
      "                ",
      "  %             ",
      "                "
    ],
    [
      "$            $  ",
      "             %% ",
      "            $%% ",
      "            $   ",
      "                ",
      "                ",
      "                ",
      "                ",
      "       # #      ",
      "      #$$$$$    ",
      "      $#$$$$    ",
      "    $$   $$     ",
      "   $            ",
      "                ",
      "  %             ",
      "                "
    ],
    [
      "             $  ",
      "             %% ",
      "            $%% ",
      "            $   ",
      "                ",
      "                ",
      "                ",
      "                ",
      "       ###      ",
      "      #$$$$     ",
      "      $#$$$$    ",
      "    $$  #$$     ",
      "   $            ",
      "                ",
      "  %             ",
      "                "
    ],
    [
      "                ",
      "             %% ",
      "             %% ",
      "                ",
      "                ",
      "                ",
      "                ",
      "                ",
      "         #      ",
      "       #$$$     ",
      "       #$$$$    ",
      "        #$$     ",
      "                ",
      "  %             ",
      "  %             ",
      "                "
    ],
    [
      "                ",
      "             %% ",
      "             %% ",
      "                ",
      "                ",
      "                ",
      "                ",
      "                ",
      "         #      ",
      "        $$#     ",
      "       #$$$$    ",
      "        #$$     ",
      "                ",
      " %%             ",
      " %%             ",
      "                "
    ],
    [
      "                ",
      "                ",
      "                ",
      "                ",
      "                ",
      "                ",
      "                ",
      "         #      ",
      "        ###     ",
      "        $$#     ",
      "       #$$$     ",
      "        #$$     ",
      "                ",
      "                ",
      "                ",
      "                "
    ],
    [
      "                ",
      "                ",
      "                ",
      "                ",
      "                ",
      "                ",
      "                ",
      "         #      ",
      "        #$#     ",
      "        $$      ",
      "        $$$     ",
      "         $$     ",
      "                ",
      "                ",
      "                ",
      "                "
    ],
    [
      "                ",
      "                ",
      "                ",
      "                ",
      "                ",
      "                ",
      "                ",
      "                ",
      "         $      ",
      "        $$$     ",
      "        $$$     ",
      "         $$     ",
      "                ",
      "                ",
      "                ",
      "                "
    ],
    [
      "                ",
      "                ",
      "                ",
      "                ",
      "                ",
      "                ",
      "                ",
      "                ",
      "         $$     ",
      "        $$$$    ",
      "        $$$$    ",
      "         $$     ",
      "                ",
      "                ",
      "                ",
      "                "
    ],
    [
      "                ",
      "                ",
      "                ",
      "                ",
      "                ",
      "                ",
      "                ",
      "         $$     ",
      "        $$$$    ",
      "       $$$$$$   ",
      "       $$$$$$   ",
      "        $$$$    ",
      "         $$     ",
      "                ",
      "                ",
      "                "
    ],
    [
      "                ",
      "                ",
      "                ",
      "                ",
      "                ",
      "                ",
      "                ",
      "                ",
      "        $$$$    ",
      "        $$$$    ",
      "        $$$$    ",
      "        $$$$    ",
      "                ",
      "                ",
      "                ",
      "                "
    ],
    [
      "                ",
      "                ",
      "                ",
      "                ",
      "                ",
      "                ",
      "                ",
      "                ",
      "        $  $    ",
      "                ",
      "                ",
      "        $  $    ",
      "                ",
      "                ",
      "                ",
      "                "
    ],
    [
      "                ",
      "                ",
      "                ",
      "                ",
      "                ",
      "                ",
      "                ",
      "                ",
      "        $  $    ",
      "                ",
      "                ",
      "        $  $    ",
      "                ",
      "                ",
      "                ",
      "                "
    ],
    [
      "                ",
      "                ",
      "                ",
      "                ",
      "                ",
      "                ",
      "                ",
      "                ",
      "        $  $    ",
      "                ",
      "                ",
      "        $  $    ",
      "                ",
      "                ",
      "                ",
      "                "
    ],
    [
      "                ",
      "                ",
      "                ",
      "                ",
      "                ",
      "                ",
      "                ",
      "         $$     ",
      "        $$$$    ",
      "       $$  $$   ",
      "       $$  $$   ",
      "        $$$$    ",
      "         $$     ",
      "                ",
      "                ",
      "                "
    ]
  ]
}