{
  "xsize": 16,
  "zsize": 16,
  "refpalette": "pomkotsmechs:scattered",
  "slices": [
    [
      "vvv33320&&&&    ",
      "vvvv3320&&&&    ",
      "vvvv3320&&&0    ",
      "vvvvvv320002    ",
      "vvvvvv332222    ",
      "vvvvvv333220    ",
      "vvvvvv332200    ",
      "vvvvvv222200    ",
      "vvvvvv002220    ",
      "vvvvvv&02222    ",
      "0vvvvv&&2332    ",
      "&&vvv&&02333    ",
      "&v&&&002$       ",
      "vv&02222$       ",
      "        $       ",
      "                "
    ],
    [
      "<7676%%%%%%     ",
      "77676665  %     ",
      "76776665  %     ",
      "77676665  %     ",
      "77676665  %     ",
      "66666665  %     ",
      "66666665  %     ",
      "66666665  %     ",
      "66666665  %     ",
      "66666665  %     ",
      "6666666%%%%     ",
      "66666665        ",
      "66666665$       ",
      "55555555$       ",
      "        $       ",
      "                "
    ],
    [
      "    %%%%$$%     ",
      "    %  5  $     ",
      "    %  5  $     ",
      "    %  5  $     ",
      "    %  5  $     ",
      "    %  5  $     ",
      "    %  5  $     ",
      "    %  5  $     ",
      "    %  5  $     ",
      "    %  5  $     ",
      "    %%%%%%%     ",
      "       5        ",
      "       5$       ",
      "55555555$       ",
      "        $       ",
      "                "
    ],
    [
      "    %%%%$$%     ",
      "    $  5  $     ",
      "    $  5  $     ",
      "    $  5  $     ",
      "    $  5  $     ",
      "    $  5  $     ",
      "    $  5  $     ",
      "    $  5  $     ",
      "    $  5  $     ",
      "    $  5  $     ",
      "    %%%%%%%     ",
      "       5        ",
      "       5$       ",
      "55555555$       ",
      "        $       ",
      "                "
    ],
    [
      "    %%%%$$%     ",
      "    $  5  $     ",
      "    $  5        ",
      "    $  5        ",
      "    $  5        ",
      "    $  5        ",
      "    $  5$       ",
      "    $  5$       ",
      "    $  5$       ",
      "    $  5$ $     ",
      "    %%%%%%%     ",
      "       5        ",
      "       5$       ",
      "55555555$       ",
      "        $       ",
      "                "
    ],
    [
      "    %%%%$$%     ",
      "    $  5  $     ",
      "    $  5  $     ",
      "    $  5  $     ",
      "    $  5$ $     ",
      "    $  5$ $     ",
      "    $  5$ $     ",
      "    $  5$ $     ",
      "    $  5$ $     ",
      "    $   $ $     ",
      "    %%%%%%%     ",
      "       5        ",
      "       $        ",
      "5555555$        ",
      "       $        ",
      "                "
    ],
    [
      "    %%%%%%%     ",
      "    %$$$$$%     ",
      "    %$$$$$%     ",
      "    %$$$$$%     ",
      "    %$$$$$%     ",
      "    %$$$$$%     ",
      "    %$$$$$%     ",
      "    %$$$$$%     ",
      "    %$$$ $%     ",
      "    %$$$$$%     ",
      "    %%%%%%%     ",
      "      5         ",
      "      5$        ",
      " 555555$        ",
      "       $        ",
      "                "
    ],
    [
      "      5         ",
      "      5         ",
      "      5         ",
      "      5         ",
      "      5         ",
      "      5 $       ",
      "      5         ",
      "      5 $       ",
      "      5$ $      ",
      "      5 $       ",
      "      5         ",
      "      5         ",
      "      $$        ",
      "55555 $$        ",
      "      $$        ",
      "                "
    ],
    [
      "     5          ",
      "     5          ",
      "     5          ",
      "     5          ",
      "     5          ",
      "     5  $       ",
      "     5          ",
      "     5  $       ",
      "     5 $ $      ",
      "     5  $       ",
      "     5          ",
      "     5          ",
      "     5$         ",
      "555   $         ",
      "                ",
      "                "
    ],
    [
      "     5          ",
      "     5          ",
      "     5          ",
      "     5          ",
      "     5          ",
      "     5  $       ",
      "     5          ",
      "     5  $       ",
      "     5 $ $      ",
      "     5  $       ",
      "     5          ",
      "     5          ",
      "                ",
      "5               ",
      "                ",
      "                "
    ],
    [
      "    5           ",
      "    5           ",
      "    5           ",
      "    5           ",
      "    5           ",
      "    5   $       ",
      "    5   $       ",
      "    5   $       ",
      "    5  $ $      ",
      "    5   $       ",
      "    5           ",
      "    5           ",
      "                ",
      "5               ",
      "                ",
      "                "
    ],
    [
      "   5            ",
      "   5            ",
      "   5            ",
      "   5            ",
      "   5            ",
      "   5    $       ",
      "   5            ",
      "   5    $       ",
      "   5   $ $      ",
      "   5    $       ",
      "   5            ",
      "   5            ",
      "                ",
      "5               ",
      "                ",
      "                "
    ],
    [
      "  5             ",
      "  5             ",
      "  5             ",
      "  5             ",
      "  5             ",
      "  5     $       ",
      "  5             ",
      "  5     $       ",
      "  5    $ $      ",
      "  5     $       ",
      "  5             ",
      "  5             ",
      "                ",
      "5               ",
      "                ",
      "                "
    ],
    [
      "55              ",
      "55              ",
      "55              ",
      "55              ",
      "55              ",
      "55      $       ",
      "55              ",
      "55      $       ",
      "55     $ $      ",
      "55      $       ",
      "55              ",
      "55              ",
      "55$             ",
      "55              ",
      "                ",
      "                "
    ],
    [
      "                ",
      "                ",
      "                ",
      "                ",
      "                ",
      "                ",
      "                ",
      "        $       ",
      "       $ $      ",
      "        $       ",
      "                ",
      "                ",
      "$$              ",
      "$$              ",
      "$$              ",
      "                "
    ],
    [
      "                ",
      "                ",
      "                ",
      "                ",
      "                ",
      "                ",
      "                ",
      "        $       ",
      "       $ $      ",
      "        $       ",
      "                ",
      "                ",
      "$               ",
      "$               ",
      "$               ",
      "                "
    ],
    [
      "                ",
      "                ",
      "                ",
      "                ",
      "                ",
      "                ",
      "                ",
      "                ",
      "                ",
      "                ",
      "                ",
      "                ",
      "                ",
      "                ",
      "                ",
      "                "
    ],
    [
      "                ",
      "                ",
      "                ",
      "                ",
      "                ",
      "                ",
      "                ",
      "                ",
      "                ",
      "                ",
      "                ",
      "                ",
      "                ",
      "                ",
      "                ",
      "                "
    ]
  ]
}