{
  "xsize": 16,
  "zsize": 16,
  "refpalette": "pomkotsmechs:scattered",
  "slices": [
    [
      "                ",
      "                ",
      "                ",
      "                ",
      "                ",
      "                ",
      "                ",
      "                ",
      "                ",
      "                ",
      "                ",
      "                ",
      "                ",
      "                ",
      "                ",
      "                "
    ],
    [
      "                ",
      "                ",
      "                ",
      "                ",
      "                ",
      "                ",
      "                ",
      "                ",
      "                ",
      "                ",
      "                ",
      "                ",
      "                ",
      "                ",
      "                ",
      "                "
    ],
    [
      "                ",
      "                ",
      "                ",
      "                ",
      "                ",
      "                ",
      "                ",
      "                ",
      "                ",
      "                ",
      "                ",
      "                ",
      "                ",
      "                ",
      "                ",
      "                "
    ],
    [
      "                ",
      "                ",
      "                ",
      "                ",
      "                ",
      "                ",
      "                ",
      "                ",
      "                ",
      "                ",
      "                ",
      "                ",
      "                ",
      "                ",
      "                ",
      "                "
    ],
    [
      "                ",
      "                ",
      "                ",
      "                ",
      "                ",
      "                ",
      "                ",
      "                ",
      "                ",
      "                ",
      "                ",
      "                ",
      "                ",
      "                ",
      "                ",
      "                "
    ],
    [
      "                ",
      "                ",
      "                ",
      "                ",
      "                ",
      "                ",
      "                ",
      "                ",
      "                ",
      "                ",
      "                ",
      "                ",
      "                ",
      "                ",
      "                ",
      "                "
    ],
    [
      "                ",
      "                ",
      "                ",
      "                ",
      "                ",
      "                ",
      "                ",
      "                ",
      "                ",
      "                ",
      "                ",
      "                ",
      "                ",
      "                ",
      "                ",
      "                "
    ],
    [
      "                ",
      "                ",
      "                ",
      "                ",
      "                ",
      "                ",
      "                ",
      "                ",
      "                ",
      "                ",
      "                ",
      "                ",
      "                ",
      "                ",
      "                ",
      "                "
    ],
    [
      "                ",
      "                ",
      "                ",
      "                ",
      "                ",
      "                ",
      "                ",
      "                ",
      "                ",
      "                ",
      "                ",
      "                ",
      "                ",
      "                ",
      "                ",
      "                "
    ],
    [
      "................",
      "................",
      "................",
      "................",
      "................",
      "................",
      "................",
      "................",
      "................",
      "................",
      "................",
      "................",
      "................",
      "................",
      "................",
      "........  ......"
    ],
    [
      "................",
      "................",
      "................",
      "................",
      "................",
      "................",
      "................",
      "................",
      "................",
      "................",
      "................",
      "................",
      ".........  .....",
      ".....        .  ",
      "....            ",
      "....            "
    ],
    [
      "                ",
      "                ",
      "                ",
      "                ",
      "                ",
      "                ",
      "                ",
      "                ",
      "                ",
      "                ",
      "                ",
      "                ",
      "                ",
      "                ",
      "                ",
      "                "
    ],
    [
      "                ",
      "                ",
      "                ",
      "                ",
      "                ",
      "                ",
      "                ",
      "                ",
      "                ",
      "                ",
      "                ",
      "                ",
      "                ",
      "                ",
      "                ",
      "                "
    ],
    [
      "                ",
      "                ",
      "                ",
      "                ",
      "                ",
      "                ",
      "                ",
      "                ",
      "                ",
      "                ",
      "                ",
      "                ",
      "                ",
      "                ",
      "                ",
      "                "
    ],
    [
      "                ",
      "                ",
      "                ",
      "                ",
      "                ",
      "                ",
      "                ",
      "                ",
      "                ",
      "                ",
      "                ",
      "                ",
      "                ",
      "                ",
      "                ",
      "                "
    ],
    [
      "................",
      "................",
      "................",
      "................",
      "................",
      "................",
      "................",
      "................",
      "................",
      "................",
      "................",
      "................",
      "................",
      "......    ......",
      "......      ....",
      ".....        ..."
    ],
    [
      "                ",
      "                ",
      "                ",
      "                ",
      "                ",
      "                ",
      "                ",
      "                ",
      "                ",
      "    VL          ",
      ") )) R          ",
      ") ))            ",
      "                ",
      "                ",
      "                ",
      "    V           "
    ],
    [
      "                ",
      "                ",
      "                ",
      "                ",
      "                ",
      "                ",
      "                ",
      "                ",
      "                ",
      "     Q          ",
      ") ))            ",
      ") ))            ",
      "                ",
      "                ",
      "                ",
      "                "
    ],
    [
      "                ",
      "                ",
      "                ",
      "                ",
      "                ",
      "                ",
      "                ",
      "                ",
      "                ",
      "     Q          ",
      "                ",
      "                ",
      "                ",
      "                ",
      "                ",
      "     Q          "
    ],
    [
      "                ",
      "                ",
      "                ",
      "                ",
      "                ",
      "                ",
      "                ",
      "                ",
      "                ",
      "     Q          ",
      "                ",
      "                ",
      "                ",
      "                ",
      "                ",
      "     Q          "
    ],
    [
      "                ",
      "                ",
      "                ",
      "                ",
      "                ",
      "                ",
      "                ",
      "                ",
      "                ",
      "     Q          ",
      "                ",
      "      #         ",
      "                ",
      "                ",
      "                ",
      "     Q          "
    ],
    [
      "                ",
      "                ",
      "                ",
      "                ",
      "               #",
      "               #",
      "                ",
      "                ",
      "                ",
      "AAAAAAW         ",
      "     AX         ",
      "     AW#        ",
      "     AX         ",
      "     AX         ",
      "     AW         ",
      "AAAAAAW         "
    ],
    [
      "                ",
      "                ",
      "                ",
      "                ",
      "                ",
      "                ",
      "                ",
      "                ",
      "                ",
      "AAAAAX          ",
      "AAAAAX#         ",
      "AAAAAX##        ",
      "AAAAAX##        ",
      "AAAAAX#         ",
      "AAAAAX          ",
      "AAAAAX          "
    ],
    [
      "                ",
      "                ",
      "                ",
      "                ",
      "                ",
      "                ",
      "                ",
      "                ",
      "                ",
      "                ",
      "                ",
      "      #         ",
      "     ###        ",
      "     ###        ",
      "      #         ",
      "                "
    ],
    [
      "                ",
      "                ",
      "                ",
      "                ",
      "                ",
      "                ",
      "                ",
      "                ",
      "                ",
      "                ",
      "                ",
      "     ##         ",
      "    ####        ",
      "    ####        ",
      "     ##         ",
      "                "
    ],
    [
      "                ",
      "                ",
      "                ",
      "                ",
      "                ",
      "                ",
      "                ",
      "                ",
      "                ",
      "                ",
      "                ",
      "     #          ",
      "    ###         ",
      "    ###         ",
      "    ###         ",
      "     #          "
    ],
    [
      "                ",
      "                ",
      "                ",
      "                ",
      "                ",
      "                ",
      "                ",
      "                ",
      "                ",
      "                ",
      "    #           ",
      "    #           ",
      "     #          ",
      "    ###         ",
      "    ###         ",
      "    ###         "
    ],
    [
      "................",
      "................",
      "                ",
      "                ",
      "                ",
      "................",
      "................",
      "                ",
      "                ",
      "    #           ",
      "................",
      "................",
      "    ##          ",
      "    ###         ",
      "     ##         ",
      "................"
    ],
    [
      "                ",
      "                ",
      "                ",
      "                ",
      "                ",
      "          .     ",
      "          .     ",
      "                ",
      "                ",
      "    #           ",
      "   ###          ",
      "   ###          ",
      "   ###          ",
      "   ####         ",
      "    ###         ",
      "     ##   .     "
    ],
    [
      "                ",
      "                ",
      "                ",
      "                ",
      "                ",
      "          .     ",
      "          .     ",
      "                ",
      "                ",
      "                ",
      "    #           ",
      "   ###          ",
      "   ###          ",
      "  ####          ",
      "   ####         ",
      "    ##    .     "
    ],
    [
      "                ",
      "                ",
      "                ",
      "                ",
      "                ",
      ".         .     ",
      ".         .     ",
      "                ",
      "                ",
      "                ",
      "    #           ",
      "   ###          ",
      "   ###          ",
      "  ###           ",
      "  ####          ",
      ".  ##     .     "
    ],
    [
      "                ",
      "                ",
      "                ",
      "                ",
      "                ",
      "...       .     ",
      "...       .     ",
      "                ",
      "                ",
      "                ",
      "                ",
      "    #           ",
      "   ###          ",
      "   ##           ",
      "  ####          ",
      "...###    .     "
    ],
    [
      "                ",
      "                ",
      "                ",
      "                ",
      "                ",
      "  ....    .    .",
      "  ....    .    .",
      "                ",
      "                ",
      "                ",
      "                ",
      "    #           ",
      "   ###          ",
      "   ###          ",
      "   ##           ",
      "  ....    .    ."
    ],
    [
      "                ",
      "                ",
      "                ",
      "                ",
      "                ",
      "  .  ...  .  ...",
      "  .  ...  .  ...",
      "                ",
      "                ",
      "                ",
      "                ",
      "                ",
      "   ##           ",
      "  ####          ",
      "  ###           ",
      "  .##...  .  ..."
    ],
    [
      "                ",
      "                ",
      "                ",
      "                ",
      "                ",
      " ..    .......  ",
      " ..    .......  ",
      "                ",
      "                ",
      "                ",
      "                ",
      "                ",
      "                ",
      "   ##           ",
      "  ###           ",
      " ..#   .......  "
    ],
    [
      "                ",
      "                ",
      "                ",
      "                ",
      "                ",
      "#.     .  .  .  ",
      " .     .  .  .  ",
      "                ",
      "                ",
      "                ",
      "                ",
      "                ",
      "                ",
      "   #            ",
      "  ###           ",
      " .###  .  .  .  "
    ],
    [
      ".               ",
      ".               ",
      "J               ",
      "J               ",
      "J               ",
      "..    ..  .  .. ",
      "..    ..  .  .. ",
      "J               ",
      "J               ",
      "J               ",
      ".               ",
      ".               ",
      "J               ",
      "J               ",
      "J  #            ",
      "..### ..  .  .. "
    ],
    [
      " .              ",
      " .              ",
      " J #            ",
      " J##            ",
      "#J#             ",
      "#.#   .   .   . ",
      "#.##  .   .   . ",
      " J #            ",
      " J              ",
      " J #            ",
      " . #            ",
      " . #            ",
      " J #            ",
      " J #            ",
      " J #            ",
      " .### .   .   . "
    ],
    [
      " ... #          ",
      " ...##         #",
      " .JJ#          #",
      " .JJ#          #",
      " .JJ            ",
      "#...  .   .   . ",
      "#...# .   .   . ",
      " .JJ#           ",
      " .JJ            ",
      " .JJ#           ",
      " ...#           ",
      " ...#           ",
      " .JJ#           ",
      " .JJ#           ",
      " .JJ#           ",
      " ...# .   .   . "
    ],
    [
      "    ...       ..",
      "   #...       ..",
      "  ##JJ        #J",
      "  ##JJ         J",
      "  # JJ         J",
      " #  ...   .   ..",
      " ###...   .   ..",
      "  ##JJ         J",
      "  ##JJ         J",
      "  ##JJ         J",
      "   #...       ..",
      "   #...       ..",
      "   #JJ         J",
      "   #JJ         J",
      "   #JJ         J",
      "   #...   .   .."
    ],
    [
      "    ##......... ",
      "    ##.........#",
      "   ## .JJJJJJJ.#",
      "      .JJJJJJJ. ",
      "      .JJJJJJJ. ",
      "      ......... ",
      "      ......... ",
      "   ## .JJJJJJJ. ",
      "   #  .JJJJJJJ. ",
      "   #  .JJJJJJJ. ",
      "      ......... ",
      "      ......... ",
      "      .JJJJJJJ. ",
      "      .JJJJJJJ. ",
      "      .JJJJJJJ. ",
      "      ......... "
    ],
    [
      "     ##         ",
      "                ",
      "                ",
      "                ",
      "                ",
      "                ",
      "                ",
      "                ",
      "                ",
      "                ",
      "                ",
      "                ",
      "                ",
      "                ",
      "                ",
      "                "
    ],
    [
      "                ",
      "                ",
      "                ",
      "                ",
      "                ",
      "                ",
      "                ",
      "                ",
      "                ",
      "                ",
      "                ",
      "                ",
      "                ",
      "                ",
      "                ",
      "                "
    ],
    [
      "                ",
      "                ",
      "                ",
      "                ",
      "                ",
      "                ",
      "                ",
      "                ",
      "                ",
      "                ",
      "                ",
      "                ",
      "                ",
      "                ",
      "                ",
      "                "
    ],
    [
      "                ",
      "                ",
      "                ",
      "                ",
      "                ",
      "                ",
      "                ",
      "                ",
      "                ",
      "                ",
      "                ",
      "                ",
      "                ",
      "                ",
      "                ",
      "                "
    ],
    [
      "                ",
      "                ",
      "                ",
      "                ",
      "                ",
      "                ",
      "                ",
      "                ",
      "                ",
      "                ",
      "                ",
      "                ",
      "                ",
      "                ",
      "                ",
      "                "
    ],
    [
      "                ",
      "                ",
      "                ",
      "                ",
      "                ",
      "                ",
      "                ",
      "                ",
      "                ",
      "                ",
      "                ",
      "                ",
      "                ",
      "                ",
      "                ",
      "                "
    ],
    [
      "                ",
      "                ",
      "                ",
      "                ",
      "                ",
      "                ",
      "                ",
      "                ",
      "                ",
      "                ",
      "                ",
      "                ",
      "                ",
      "                ",
      "                ",
      "                "
    ]
  ]
}