{
  "xsize": 16,
  "zsize": 16,
  "refpalette": "pomkotsmechs:scattered",
  "slices": [
    [
      "    &&&&&&&&&&&&",
      "    &&&&&&&&&&&&",
      "    &&&&&&&&&&&&",
      "    &&&&&&&&&&&&",
      "    &&&&&&&&&&&&",
      "    &&&&&&&&&&&&",
      "    &&&&&&&&&&&&",
      "    &&&&&&&&&&&&",
      "    &&&&&&&&&&&&",
      "    &&&&&&&&&&&&",
      "    &&&&&&&&&&&&",
      "    &&&&&&&&&&&&",
      "    &&&&&&&&&&&&",
      "    &&&&&&&&&&&&",
      "    &&&&&&&&&&&&",
      "    &&&&&&&&&&&&"
    ],
    [
      "     $$$$$$$$$cc",
      "     $$$$$$$cc$$",
      "     $$$$$$c$$$$",
      "     $$$$$c$$$$$",
      "     $$$$$c$$$$$",
      "     $$$$c$$$$$$",
      "     $$$$c$$$$$$",
      "     $$$$c$$$$$$",
      "     $$$$c$$$$$$",
      "     $$$$c$$$$$$",
      "     $$$$$c$$$$$",
      "     $$$$$c$$$$$",
      "     $$$$$$c$$$$",
      "     $$$$$$$cc$$",
      "     $$$$$$$$$cc",
      "     $$$$$$$$$$$"
    ],
    [
      "     f  bbbbb m ",
      "     f  bbbb    ",
      "     f $ b$  $ j",
      "     f j j      ",
      "     f          ",
      "     f $  $  $  ",
      "     f          ",
      "     f         j",
      "     f $  $  $  ",
      "     f          ",
      "     f     j    ",
      "     f $  $  $j ",
      "     f          ",
      "     f          ",
      "     f $  $  $  ",
      "     f          "
    ],
    [
      "     f   bbb  n ",
      "     f          ",
      "     f $  $  $  ",
      "     f          ",
      "     f          ",
      "     f $  $  $  ",
      "     f          ",
      "     f          ",
      "     f $  $  $  ",
      "     f          ",
      "     f          ",
      "     f $  $  $  ",
      "     f          ",
      "     f          ",
      "     f $  $  $  ",
      "     f          "
    ],
    [
      "     f    j     ",
      "     f          ",
      "     f $  $  $  ",
      "     f          ",
      "     f          ",
      "     f $  $  $  ",
      "     f          ",
      "     f          ",
      "     f $  $  $  ",
      "     f          ",
      "     f          ",
      "     f $  $  $  ",
      "     f          ",
      "     f          ",
      "     f $  $  $  ",
      "     f          "
    ],
    [
      "     f          ",
      "     f          ",
      "     f )))))))  ",
      "     f )$$$$$)  ",
      "     f )$$$$$)  ",
      "     f )$$$$$)  ",
      "     f )   $$)  ",
      "     f     $$)  ",
      "     f     $$j  ",
      "     f )$$$$$)  ",
      "     f )$$$$$)  ",
      "     f )$$$$$)  ",
      "     f )$$$$$)  ",
      "     f )))))))  ",
      "     f )))))))  ",
      "     f          "
    ],
    [
      "     f          ",
      "     f          ",
      "     f )))))))  ",
      "     f )$$$$$)  ",
      "     f )$ o $)  ",
      "     f     j$)  ",
      "     f      $)  ",
      "     f      $)  ",
      "     f          ",
      "     f          ",
      "     f )$  m    ",
      "     f )$   $)  ",
      "     f )$$$$$)  ",
      "     f )     )  ",
      "     f )))))))  ",
      "     f          "
    ],
    [
      "     f          ",
      "     f          ",
      "     f )))))))  ",
      "     f )$$$$$)  ",
      "     f )$   $)  ",
      "     f      $)  ",
      "     f      $)  ",
      "                ",
      "     f          ",
      "     f          ",
      "     f )$  n    ",
      "     f )$       ",
      "     f )$$$$$   ",
      "     f )     )  ",
      "     f )))))))  ",
      "     f          "
    ],
    [
      "     f          ",
      "     f          ",
      "     f )))))))  ",
      "     f )$$$$$)  ",
      "     f )$   $)  ",
      "     f      $)  ",
      "     f          ",
      "                ",
      "     f          ",
      "     f          ",
      "     f )$       ",
      "     f )$       ",
      "     f )$$$$    ",
      "     f )     )  ",
      "     f )))))))  ",
      "     f          "
    ],
    [
      "     f          ",
      "     f          ",
      "     f )))))))  ",
      "     f )$$$$$)  ",
      "     f )$$$$$)  ",
      "     f )  $$$)  ",
      "     f          ",
      "     f          ",
      "     f          ",
      "     f          ",
      "     f )$$      ",
      "     f )$$$     ",
      "     f )$$$$    ",
      "     f )     )  ",
      "     f )))))))  ",
      "     f          "
    ],
    [
      "     f          ",
      "     f          ",
      "     f )))))))  ",
      "     f )))))))  ",
      "     f )))))))  ",
      "     f )))))))  ",
      "     f ))))     ",
      "     f          ",
      "     f          ",
      "     f )))      ",
      "     f )))      ",
      "     f ))))     ",
      "     f )))))    ",
      "     f )))))))  ",
      "     f )))))))  ",
      "     f          "
    ],
    [
      "     f          ",
      "     f          ",
      "     f          ",
      "     f          ",
      "     f          ",
      "     f       j  ",
      "     f          ",
      "     f          ",
      "     f          ",
      "     f          ",
      "     f          ",
      "     f          ",
      "     f          ",
      "     f       j  ",
      "     f          ",
      "     f          "
    ],
    [
      "     f          ",
      "     f          ",
      "     f          ",
      "     f          ",
      "     f          ",
      "     f          ",
      "     f          ",
      "     f          ",
      "     f          ",
      "     f          ",
      "     f          ",
      "     f          ",
      "     f          ",
      "     f          ",
      "     f          ",
      "     f          "
    ],
    [
      "     f          ",
      "     f          ",
      "     f          ",
      "     f          ",
      "     f          ",
      "     f          ",
      "     f          ",
      "     f          ",
      "     f          ",
      "     f          ",
      "     f          ",
      "     f          ",
      "     f          ",
      "     f          ",
      "     f          ",
      "     f          "
    ],
    [
      "     f          ",
      "     f          ",
      "     f          ",
      "     f          ",
      "     f          ",
      "     f          ",
      "     f          ",
      "     f          ",
      "     f          ",
      "     f          ",
      "     f          ",
      "     f          ",
      "     f          ",
      "     f          ",
      "     f          ",
      "                "
    ],
    [
      "     f          ",
      "     f          ",
      "     f          ",
      "     f          ",
      "     f          ",
      "     f          ",
      "     f          ",
      "     f          ",
      "     f          ",
      "     f          ",
      "     f          ",
      "     f          ",
      "     f          ",
      "                ",
      "                ",
      "                "
    ],
    [
      "     f          ",
      "     f          ",
      "     f          ",
      "     f          ",
      "     f          ",
      "     f          ",
      "     f          ",
      "     f          ",
      "     f          ",
      "     f          ",
      "     f          ",
      "     f          ",
      "                ",
      "                ",
      "                ",
      "                "
    ],
    [
      "     f          ",
      "     f          ",
      "     f          ",
      "     f          ",
      "     f          ",
      "     f          ",
      "     f          ",
      "     f          ",
      "     f          ",
      "     f          ",
      "     f          ",
      "                ",
      "                ",
      "                ",
      "                ",
      "                "
    ],
    [
      "     f          ",
      "     f          ",
      "     f          ",
      "     f          ",
      "     f          ",
      "     f          ",
      "     f          ",
      "     f          ",
      "     f          ",
      "     f          ",
      "                ",
      "                ",
      "                ",
      "                ",
      "                ",
      "                "
    ],
    [
      "     f          ",
      "     f          ",
      "     f          ",
      "     f          ",
      "     f          ",
      "     f          ",
      "     f          ",
      "     f          ",
      "                ",
      "                ",
      "                ",
      "                ",
      "                ",
      "                ",
      "                ",
      "                "
    ],
    [
      "     f          ",
      "     f          ",
      "     f          ",
      "     f          ",
      "     f          ",
      "     f          ",
      "     f          ",
      "                ",
      "                ",
      "                ",
      "                ",
      "                ",
      "                ",
      "                ",
      "                ",
      "                "
    ],
    [
      "     f          ",
      "     f          ",
      "     f          ",
      "     f          ",
      "     f          ",
      "                ",
      "                ",
      "                ",
      "                ",
      "                ",
      "                ",
      "                ",
      "                ",
      "                ",
      "                ",
      "                "
    ],
    [
      "                ",
      "                ",
      "                ",
      "                ",
      "                ",
      "                ",
      "                ",
      "                ",
      "                ",
      "                ",
      "                ",
      "                ",
      "                ",
      "                ",
      "                ",
      "                "
    ],
    [
      "                ",
      "                ",
      "                ",
      "                ",
      "                ",
      "                ",
      "                ",
      "                ",
      "                ",
      "                ",
      "                ",
      "                ",
      "                ",
      "                ",
      "                ",
      "                "
    ],
    [
      "                ",
      "                ",
      "                ",
      "                ",
      "                ",
      "                ",
      "                ",
      "                ",
      "                ",
      "                ",
      "                ",
      "                ",
      "                ",
      "                ",
      "                ",
      "                "
    ],
    [
      "                ",
      "                ",
      "                ",
      "                ",
      "                ",
      "                ",
      "                ",
      "                ",
      "                ",
      "                ",
      "                ",
      "                ",
      "                ",
      "                ",
      "                ",
      "                "
    ],
    [
      "                ",
      "                ",
      "                ",
      "                ",
      "                ",
      "                ",
      "                ",
      "                ",
      "                ",
      "                ",
      "                ",
      "                ",
      "                ",
      "                ",
      "    $$$         ",
      "    $$$         "
    ],
    [
      "                ",
      "                ",
      "                ",
      "                ",
      "                ",
      "                ",
      "                ",
      "                ",
      "                ",
      "                ",
      "                ",
      "                ",
      "    $$$         ",
      "    $$$         ",
      "    $$$         ",
      "    $$$         "
    ],
    [
      "                ",
      "                ",
      "                ",
      "                ",
      "                ",
      "                ",
      "                ",
      "                ",
      "                ",
      "                ",
      "                ",
      "      $         ",
      "                ",
      "                ",
      "                ",
      "      $         "
    ],
    [
      "                ",
      "                ",
      "                ",
      "                ",
      "                ",
      "                ",
      "                ",
      "                ",
      "                ",
      "                ",
      "                ",
      "                ",
      "                ",
      "                ",
      "                ",
      "      $         "
    ],
    [
      "                ",
      "                ",
      "                ",
      "                ",
      "                ",
      "                ",
      "                ",
      "      $         ",
      "      &         ",
      "                ",
      "                ",
      "                ",
      "                ",
      "                ",
      "                ",
      "                "
    ],
    [
      "    $           ",
      "                ",
      "                ",
      "                ",
      "       $        ",
      "      $$        ",
      "    $$$$        ",
      "    $$$$        ",
      "    $$          ",
      "    $           ",
      "                ",
      "                ",
      "                ",
      "                ",
      "                ",
      "                "
    ],
    [
      "    llllllllllll",
      "    llllllllllll",
      "    llllllllllll",
      "    llllllllllll",
      "    llllllllllll",
      "    llllllllllll",
      "    llllllllllll",
      "    lllllll     ",
      "    l           ",
      "                ",
      "                ",
      "                ",
      "                ",
      "                ",
      "                ",
      "                "
    ],
    [
      "          j   m ",
      "                ",
      "               j",
      "       j j      ",
      "                ",
      "           j j  ",
      "                ",
      "                ",
      "                ",
      "                ",
      "                ",
      "                ",
      "                ",
      "                ",
      "                ",
      "                "
    ],
    [
      "              n ",
      "                ",
      "                ",
      "                ",
      "                ",
      "                ",
      "                ",
      "                ",
      "                ",
      "                ",
      "                ",
      "                ",
      "                ",
      "                ",
      "                ",
      "                "
    ],
    [
      "                ",
      "                ",
      "                ",
      "                ",
      "                ",
      "                ",
      "                ",
      "                ",
      "                ",
      "                ",
      "                ",
      "                ",
      "                ",
      "                ",
      "                ",
      "                "
    ]
  ]
}