{
  "xsize": 16,
  "zsize": 16,
  "refpalette": "pomkotsmechs:scattered",
  "slices": [
    [
      "      !!        ",
      "   !!!!!!!!     ",
      "  !!!!!!!!!!    ",
      " !!!!vvvv!!!!   ",
      " !!!vvvvvv!!!   ",
      " !!vvvvvvvv!!   ",
      "!!!vvvvvvvv!!!  ",
      "!!!vvvvvvvv!!!  ",
      " !!vv  vvvv!!   ",
      " !!!vvvvvv!!!   ",
      " !!!!vvvv!!!!   ",
      "  !!!!!!!!!!    ",
      "   !!!!!!!!     ",
      "      !!        ",
      "                ",
      "                "
    ],
    [
      "vvvvvv!!vvvvvvvv",
      "vvv!!!!!!!!vvvvv",
      "vv!!!!!!!!!!vvvv",
      "v!!!!!!!!!!!!vvv",
      "v!!!!!!!!!!!!vvv",
      "v!!!!!!!!!!!!vvv",
      "!!!!!!!!!!!!!!vv",
      "!!!!!!!!!!!!!!vv",
      "v!!!!!!!!!!!!vvv",
      "v!!!!!!!!!!!!vvv",
      "v!!!!!!!!!!!!vvv",
      "vv!!!!!!!!!!vvvv",
      "vvv!!!!!!!!vvvvv",
      "vvvvvv!!vvvvvvvv",
      "vvvvvvvvvvvvvvvv",
      "vvvvvvvvvvvvvvvv"
    ],
    [
      "                ",
      "                ",
      "                ",
      "                ",
      "                ",
      "                ",
      "                ",
      "                ",
      "                ",
      "                ",
      "                ",
      "                ",
      "  $             ",
      "                ",
      "                ",
      "          #     "
    ],
    [
      "                ",
      "                ",
      "                ",
      "                ",
      "                ",
      "                ",
      "                ",
      "                ",
      "                ",
      "                ",
      "                ",
      "                ",
      "  $             ",
      "                ",
      "                ",
      "          ##    "
    ],
    [
      "                ",
      "                ",
      "                ",
      "                ",
      "                ",
      "                ",
      "                ",
      "                ",
      "                ",
      "                ",
      "                ",
      "                ",
      "  $             ",
      "                ",
      "                ",
      "          ##    "
    ],
    [
      "                ",
      "                ",
      "                ",
      "                ",
      "                ",
      "                ",
      "                ",
      "                ",
      "                ",
      "                ",
      "                ",
      "                ",
      "  $             ",
      "                ",
      "                ",
      "           #    "
    ],
    [
      "                ",
      "                ",
      "                ",
      "                ",
      "                ",
      "                ",
      "                ",
      "                ",
      "                ",
      "                ",
      "                ",
      "                ",
      "  $             ",
      "                ",
      "                ",
      "           ##   "
    ],
    [
      "                ",
      "                ",
      "                ",
      "                ",
      "                ",
      "                ",
      "                ",
      "                ",
      "                ",
      "                ",
      "                ",
      "                ",
      "v $             ",
      "v               ",
      "           #    ",
      "          ###   "
    ],
    [
      "                ",
      "                ",
      "                ",
      "                ",
      "                ",
      "                ",
      "                ",
      "                ",
      "                ",
      "                ",
      "                ",
      " vv             ",
      "Εvv             ",
      "Εvv             ",
      "           #    ",
      "          ###   "
    ],
    [
      "                ",
      "                ",
      "                ",
      "                ",
      "                ",
      "                ",
      "                ",
      "                ",
      "                ",
      "                ",
      " vv             ",
      " ΖΖ             ",
      "                ",
      "                ",
      "           ##   ",
      "          ####  "
    ],
    [
      "                ",
      "                ",
      "                ",
      "                ",
      "                ",
      "                ",
      "                ",
      "                ",
      "                ",
      " vv             ",
      " ΖΖ             ",
      "                ",
      "                ",
      "                ",
      "            #   ",
      "           ###  "
    ],
    [
      "                ",
      "                ",
      "                ",
      "                ",
      "                ",
      "                ",
      "                ",
      "                ",
      " vv             ",
      " ΖΖ             ",
      "                ",
      "                ",
      "                ",
      "            #   ",
      "#           #   ",
      "##         ###  "
    ],
    [
      "!!!!!!!!!!!!!!!!",
      "!!!!!!!!!!!!!!!!",
      "!!!!!!!!!!!!!!!!",
      "!!!!!!!!!!!!!!!!",
      "!!!!!!!!!!!!!!!!",
      "!!!!!!!!!!!!!!!!",
      "!!!!!!!!!!!!!!!!",
      "!vv!!!!!!!!!!!!!",
      "!ΖΖ!!!!!!!!!!!!!",
      "!  !!!!!!!!!!!!!",
      "!  !!!!!!!!!!!!!",
      "!  !!!!!!!!!!!!!",
      "!  !!!!!!!!!!!!!",
      "!!!!!!!!!!!!!!!!",
      "!!!!!!!!!!!!!!!!",
      "!!!!!!!!!!!!!!!!"
    ],
    [
      "               #",
      "                ",
      "                ",
      "                ",
      "   $$$$$$$$     ",
      "   $$$$$$$$     ",
      "   $$$$$$$$     ",
      "   $$$$$$$$     ",
      "   $$$$$$$$     ",
      "   $$$$$$$$     ",
      "   $$$$$$$$     ",
      "                ",
      "            #   ",
      "#          ###  ",
      "##          #   ",
      "##          #   "
    ],
    [
      "                ",
      "                ",
      "                ",
      "                ",
      "   $$$$$$$$     ",
      "   $$$$$$$$     ",
      "   $$$$$$$$     ",
      "   $$$$$$$$     ",
      "   $$$$$$$$     ",
      "   $$$$$$$$     ",
      "   $$$$$$$$     ",
      "                ",
      "            ##  ",
      "#          #### ",
      "##          ##  ",
      "#               "
    ],
    [
      "                ",
      "                ",
      "                ",
      "                ",
      "                ",
      "    $    $      ",
      "    $    $      ",
      "    $ $$ $      ",
      "    $    $      ",
      "    $    $      ",
      "                ",
      "                ",
      "             #  ",
      "#           ### ",
      "##           #  ",
      "##              "
    ],
    [
      "                ",
      "                ",
      "                ",
      "                ",
      "                ",
      "    $ $$ $      ",
      "    $$$$$$      ",
      "    $$  $$      ",
      "    $    $      ",
      "    $    $      ",
      "                ",
      "                ",
      "             #  ",
      "            ### ",
      "#            #  ",
      "##              "
    ],
    [
      "                ",
      "                ",
      "                ",
      "      $$        ",
      "     $$$$       ",
      "    $$  $$      ",
      "    $$  $$      ",
      "    $$  $$      ",
      "    $$  $$      ",
      "    $    $      ",
      "                ",
      "                ",
      "             #  ",
      "            ### ",
      "#            #  ",
      "##              "
    ],
    [
      "                ",
      "      $$        ",
      "      $$        ",
      "     $  $       ",
      "     $  $       ",
      "     $  $       ",
      "     $  $       ",
      "     $$$$       ",
      "      $$        ",
      "                ",
      "                ",
      "                ",
      "             ## ",
      "            ####",
      "#            ## ",
      "##              "
    ],
    [
      "      $$        ",
      "     $$$$       ",
      "     $  $       ",
      "     $  $       ",
      "     $  $       ",
      "     $$$$       ",
      "      $$        ",
      "                ",
      "                ",
      "                ",
      "                ",
      "                ",
      "              # ",
      "             ###",
      "#             # ",
      "##              "
    ],
    [
      "     $  $       ",
      "     $  $       ",
      "     $  $       ",
      "     $  $       ",
      "      $$        ",
      "      $$        ",
      "                ",
      "                ",
      "                ",
      "                ",
      "                ",
      "                ",
      "              # ",
      "             ###",
      "#             # ",
      "##              "
    ],
    [
      "     $  $       ",
      "     $  $       ",
      "     $$$$       ",
      "      $$        ",
      "                ",
      "                ",
      "                ",
      "                ",
      "                ",
      "                ",
      "                ",
      "                ",
      "              # ",
      "             ###",
      "              # ",
      "#               "
    ],
    [
      "     $$$$      #",
      "      $$        ",
      "                ",
      "                ",
      "                ",
      "                ",
      "                ",
      "                ",
      "                ",
      "                ",
      "                ",
      "                ",
      "              ##",
      "             ###",
      "              ##",
      "#               "
    ],
    [
      "             ###",
      "                ",
      "                ",
      "                ",
      "                ",
      "                ",
      "                ",
      "                ",
      "                ",
      "                ",
      "                ",
      "               #",
      "               #",
      "              ##",
      "#              #",
      "##              "
    ],
    [
      "           ###!!",
      "             # !",
      "                ",
      "                ",
      "                ",
      "                ",
      "                ",
      "                ",
      "                ",
      "                ",
      "               #",
      "              ##",
      "              #!",
      "              !!",
      "!              #",
      "!!              "
    ],
    [
      "!!        ##!!# ",
      "!          ##!! ",
      "#             !!",
      "#              !",
      "               !",
      "               !",
      "               !",
      "               !",
      "               !",
      "#              !",
      "               !",
      "              !!",
      "!            !!#",
      "!!          !! #",
      " !!        !!   ",
      "# !!!!!!!!!!    "
    ],
    [
      "  !!!    !!!##  ",
      " !!       #!!   ",
      "!!         #!!  ",
      "!#           !! ",
      "!            !! ",
      "!            !! ",
      "              ! ",
      "              ! ",
      "!            !! ",
      "!            !! ",
      "!            !! ",
      "!!          !! #",
      " !!        !!   ",
      "  !!!!  !!!!    ",
      "   !!!!!!!!     ",
      "                "
    ],
    [
      "           #    ",
      "   !!    !!#    ",
      "##!!!    !!!    ",
      "#!!!!    !!!!   ",
      "#!!!      !!!   ",
      " !!        !!   ",
      "!!!        !!!  ",
      "!!!        !!!  ",
      " !!        !!   ",
      " !!!      !!!   ",
      " !!!!    !!!!   ",
      "  !!!!!!!!!!    ",
      "   !!!!!!!!     ",
      "      !!        ",
      "                ",
      "                "
    ],
    [
      "                ",
      "                ",
      "                ",
      "##              ",
      "    !    !      ",
      "   !!    !!     ",
      "   !!    !!     ",
      "   !!    !!     ",
      "   !!    !!     ",
      "    !    !      ",
      "     !!!!       ",
      "                ",
      "                ",
      "                ",
      "                ",
      "                "
    ],
    [
      "                ",
      "                ",
      "                ",
      "                ",
      "                ",
      "                ",
      "                ",
      "                ",
      "                ",
      "                ",
      "                ",
      "                ",
      "                ",
      "                ",
      "                ",
      "                "
    ]
  ]
}