{
  "xsize": 16,
  "zsize": 16,
  "refpalette": "pomkotsmechs:scattered",
  "slices": [
    [
      "                ",
      "                ",
      "                ",
      "                ",
      "                ",
      "                ",
      "                ",
      "                ",
      "                ",
      "                ",
      "                ",
      "                ",
      "                ",
      "                ",
      "                ",
      "                "
    ],
    [
      "vvvvvvvvvvvvvvvv",
      "vvvvvvvvvvvvvvvv",
      "vvvvvvvvvvvvvvvv",
      "vvvvvvvvvvvvvvvv",
      "vvvvvvvvvvvvvvvv",
      "vvvvvvvvvvvvvvvv",
      "vvvvvvvvvvvvvvvv",
      "vvvvvvvvvvvvvvvv",
      "vvvvvvvvvvvvvvvv",
      "vvvvvvvvvvvvvvvv",
      "vvvvvvvvvvvvvvvv",
      "vvvvvvvvvvvvvvvv",
      "vvvvvvvvvvvvvvvv",
      "vvvvvvvvvvvvvvvv",
      "vvvvvvvvvvvvvvvv",
      "vvvvvvvvvvvvvvvv"
    ],
    [
      "$$$$$$$$$$$$$$$$",
      "$$$$$$$$$$$$$$$$",
      "$$$$$$$$$$$$$$$$",
      "$$$$$$$$$$$$$$$$",
      "$$$$$$$$$$$$$$$$",
      "$$$$$$$$$$$$$$$$",
      "$$$$$$$$$$$$$$$$",
      "$$$$$$$$$$$$$$$$",
      "$$$$$$$$$$$$$$$$",
      "$$$$$$$$$$$$$$$$",
      "$$$$$$$$$$$$$$$$",
      "$$$$$$$$$$$$$$$$",
      "$$$$$$$$$$$$$$$$",
      "$$$$$$$$$$$$$$$$",
      "$$$$$$$$$$$$$$$$",
      "$$$$$$$$$$$$$$$$"
    ],
    [
      "                ",
      "                ",
      "                ",
      "                ",
      "              # ",
      "             ###",
      "              # ",
      "                ",
      "                ",
      "                ",
      "                ",
      "                ",
      "                ",
      "                ",
      "                ",
      "                "
    ],
    [
      "                ",
      "                ",
      "                ",
      "                ",
      "              # ",
      "             ###",
      "              # ",
      "                ",
      "                ",
      "                ",
      "                ",
      "                ",
      "                ",
      "                ",
      "                ",
      "                "
    ],
    [
      "                ",
      "                ",
      "                ",
      "                ",
      "              # ",
      "             ###",
      "              # ",
      "                ",
      "                ",
      "                ",
      "                ",
      "                ",
      "                ",
      "                ",
      "                ",
      "                "
    ],
    [
      "                ",
      "                ",
      "                ",
      "                ",
      "             ## ",
      "            ####",
      "             ## ",
      "                ",
      "                ",
      "                ",
      "                ",
      "                ",
      "                ",
      "                ",
      "                ",
      "                "
    ],
    [
      "                ",
      "                ",
      "                ",
      "                ",
      "             #  ",
      "            ### ",
      "             #  ",
      "                ",
      "                ",
      "                ",
      "                ",
      "                ",
      "                ",
      "                ",
      "                ",
      "                "
    ],
    [
      "   #     ##     ",
      "                ",
      "                ",
      "                ",
      "             #  ",
      "            ### ",
      "#            #  ",
      "                ",
      "                ",
      "                ",
      "                ",
      "                ",
      "                ",
      "                ",
      "                ",
      "                "
    ],
    [
      "   # #  ##      ",
      "                ",
      "                ",
      "                ",
      "             #  ",
      "#           ### ",
      "#            #  ",
      "                ",
      "#               ",
      "#               ",
      "                ",
      "                ",
      "                ",
      "                ",
      "                ",
      "#               "
    ],
    [
      "   ########     ",
      "     #  ##      ",
      "                ",
      "                ",
      "#            #  ",
      "##          ### ",
      "#            #  ",
      "                ",
      "                ",
      "                ",
      "                ",
      "#               ",
      "#               ",
      "#               ",
      "#               ",
      "#               "
    ],
    [
      "$$$$$$$$$$$$$$$$",
      "$    #####     $",
      "$       #      $",
      "$               ",
      "$#           #  ",
      "$##         ### ",
      "$#           #  ",
      "$               ",
      "$               ",
      "$               ",
      "$#              ",
      "$#             $",
      "$#             $",
      "$#             $",
      "$              $",
      "$$$$$$$$$$$$$$$$"
    ],
    [
      "     ## #       ",
      " $$$$$$$$$$$$$$ ",
      " $      #     $ ",
      " $              ",
      " $#          #  ",
      "#$#         ### ",
      " $           #  ",
      " $            $ ",
      " $            $ ",
      " $            $ ",
      "#$#           $ ",
      "#$#           $ ",
      "#$            $ ",
      "#$            $ ",
      " $$$$$$$$$$$$$$ ",
      "                "
    ],
    [
      "        #       ",
      " $$$$$$$$$$$$$$ ",
      " $     ###      ",
      " $#     #       ",
      "#$##        ##  ",
      "#$#        #### ",
      " $#         ##  ",
      " $#           $ ",
      "#$#           $ ",
      "#$#           $ ",
      "#$#           $ ",
      "#$            $ ",
      " $            $ ",
      " $            $ ",
      " $$$$$$$$$$$$$$ ",
      "                "
    ],
    [
      "                ",
      "        #       ",
      "  $$$$$$$$$$    ",
      "  $#    #       ",
      " #$##       #   ",
      " #$#       ###  ",
      " #$#        #   ",
      " #$#         $  ",
      "##$#         $  ",
      " #$          $  ",
      " #$          $  ",
      "  $          $  ",
      "  $          $  ",
      "  $$$$$$$$$$$$  ",
      "                ",
      "                "
    ],
    [
      "                ",
      "                ",
      "        #       ",
      "   $$$$$$$$$    ",
      "  #$#       #   ",
      "  #$       ###  ",
      "  #$       #$#  ",
      "  #$        $   ",
      " ##$        $   ",
      "   $        $   ",
      "   $        $   ",
      "   $        $   ",
      "   $$$$$$$$$$   ",
      "                ",
      "                ",
      "                "
    ],
    [
      "                ",
      "                ",
      "                ",
      "                ",
      "   #$$$$$$$$#   ",
      "    $     #$##  ",
      "    $      $##  ",
      "    $      $#   ",
      "    $      $    ",
      "    $      $    ",
      "    $      $    ",
      "    $$$$$$$$    ",
      "                ",
      "                ",
      "                ",
      "                "
    ],
    [
      "                ",
      "                ",
      "                ",
      "    ##          ",
      "   #$$$$$$$$#   ",
      "    $######$##  ",
      "    $     #$##  ",
      "    $      $#   ",
      "    $      $    ",
      "    $      $    ",
      "    $      $    ",
      "    $$$$$$$$    ",
      "                ",
      "                ",
      "                ",
      "                "
    ],
    [
      "                ",
      "                ",
      "                ",
      "     ##         ",
      "    #######     ",
      "     $$$$$$##   ",
      "     $####$##   ",
      "     $    $#    ",
      "     $    $     ",
      "     $    $     ",
      "     $$$$$$     ",
      "                ",
      "                ",
      "                ",
      "                ",
      "                "
    ],
    [
      "                ",
      "                ",
      "                ",
      "                ",
      "     ##  #      ",
      "      #####     ",
      "      $$$$##    ",
      "      $  $      ",
      "      $  $      ",
      "      $$$$      ",
      "                ",
      "                ",
      "                ",
      "                ",
      "                ",
      "                "
    ],
    [
      "                ",
      "                ",
      "                ",
      "                ",
      "                ",
      "         #      ",
      "         #      ",
      "       $$       ",
      "       $$       ",
      "                ",
      "                ",
      "                ",
      "                ",
      "                ",
      "                ",
      "                "
    ],
    [
      "                ",
      "                ",
      "                ",
      "                ",
      "                ",
      "                ",
      "                ",
      "       $$       ",
      "       $$       ",
      "                ",
      "                ",
      "                ",
      "                ",
      "                ",
      "                ",
      "                "
    ],
    [
      "                ",
      "                ",
      "                ",
      "                ",
      "                ",
      "                ",
      "                ",
      "                ",
      "                ",
      "                ",
      "                ",
      "                ",
      "                ",
      "                ",
      "                ",
      "                "
    ],
    [
      "                ",
      "                ",
      "                ",
      "                ",
      "                ",
      "                ",
      "                ",
      "                ",
      "                ",
      "                ",
      "                ",
      "                ",
      "                ",
      "                ",
      "                ",
      "                "
    ]
  ]
}