{
  "xsize": 16,
  "zsize": 16,
  "refpalette": "pomkotsmechs:scattered",
  "slices": [
    [
      "5vvvvvvvvvvvvvvv",
      "5vvvvvvvvvvvvvvv",
      "5vvvvvvvvvvvvvvv",
      "5vvvvvvvvvvvvvvv",
      "5vvvvvvvvvvvvvvv",
      "5vvvvvvvvvvvvvvv",
      "5vvvvvvvvvvvvvvv",
      "5vvvvvvvvvvvvvvv",
      "5vvvvvvvvvvvvvvv",
      "5vvvv20&v&02vvvv",
      "5vvv3320&&023332",
      "5vv3333000023220",
      "5vv333320002220&",
      "v&v23322200000&v",
      "                ",
      "                "
    ],
    [
      "6676677777777777",
      "6<77777766<76676",
      "6766776776777767",
      "6767676776777776",
      "7777767677667766",
      "7677666777776676",
      "6666666666666666",
      "6666666666666666",
      "6666666666666666",
      "6666666666666666",
      "6666666666666666",
      "6666666666666666",
      "666666   6666666",
      "55555%   %555555",
      "                ",
      "                "
    ],
    [
      "                ",
      "                ",
      "                ",
      "                ",
      "                ",
      "                ",
      "                ",
      "                ",
      "                ",
      "                ",
      "                ",
      "                ",
      "            #   ",
      "55555%   %555555",
      "            #   ",
      "                "
    ],
    [
      "                ",
      "                ",
      "                ",
      "                ",
      "                ",
      "                ",
      "                ",
      "                ",
      "                ",
      "                ",
      "                ",
      "                ",
      "#           #   ",
      "55555%   %555555",
      "#           #   ",
      "                "
    ],
    [
      "                ",
      "                ",
      "                ",
      "                ",
      "                ",
      "                ",
      "                ",
      "                ",
      "                ",
      "                ",
      "                ",
      "                ",
      "#           #   ",
      "55555%   %555555",
      "#           #   ",
      "                "
    ],
    [
      "                ",
      "                ",
      "                ",
      "                ",
      "                ",
      "                ",
      "                ",
      "                ",
      "                ",
      "                ",
      "                ",
      "                ",
      "#           #   ",
      "55555%   %555555",
      "#           #   ",
      "                "
    ],
    [
      "                ",
      "                ",
      "                ",
      "                ",
      "                ",
      "                ",
      "                ",
      "                ",
      "                ",
      "                ",
      "                ",
      "                ",
      "##          #   ",
      "55555%% %%555555",
      "##          #   ",
      "                "
    ],
    [
      "                ",
      "                ",
      "                ",
      "                ",
      "                ",
      "                ",
      "                ",
      "                ",
      "                ",
      "                ",
      "                ",
      "                ",
      " ##         #   ",
      "555555%%%5555555",
      " ##         #   ",
      "                "
    ],
    [
      "                ",
      "                ",
      "                ",
      "                ",
      "                ",
      "                ",
      "                ",
      "                ",
      "                ",
      "                ",
      "                ",
      "                ",
      "  #         #   ",
      "5555555555555555",
      "  #         #   ",
      "                "
    ],
    [
      "                ",
      "                ",
      "                ",
      "                ",
      "                ",
      "                ",
      "                ",
      "                ",
      "                ",
      "                ",
      "                ",
      "                ",
      "  #         #   ",
      "5555555555555555",
      "  #         #   ",
      "                "
    ],
    [
      "                ",
      "                ",
      "                ",
      "                ",
      "                ",
      "                ",
      "                ",
      "                ",
      "                ",
      "                ",
      "                ",
      "                ",
      "  ##        #   ",
      "5555555555555555",
      "  ##        #   ",
      "                "
    ],
    [
      "                ",
      "                ",
      "                ",
      "                ",
      "                ",
      "                ",
      "                ",
      "                ",
      "                ",
      "                ",
      "                ",
      "                ",
      "   #        #   ",
      "5555555555555555",
      "   #        #   ",
      "                "
    ],
    [
      "                ",
      "                ",
      "                ",
      "                ",
      "                ",
      "                ",
      "                ",
      "                ",
      "                ",
      "                ",
      "                ",
      "                ",
      "   ##       #   ",
      "5555555555555555",
      "   ##       #   ",
      "                "
    ],
    [
      "                ",
      "                ",
      "                ",
      "                ",
      "                ",
      "                ",
      "                ",
      "                ",
      "                ",
      "                ",
      "                ",
      "                ",
      "    #       #   ",
      "5555555555555555",
      "    #       #   ",
      "                "
    ],
    [
      "5             55",
      "5             55",
      "              55",
      "              55",
      "              55",
      "              55",
      "              55",
      "              55",
      "              55",
      "              55",
      "              55",
      "              55",
      "    #       # 55",
      "5  5555555555555",
      "    #       #   ",
      "                "
    ],
    [
      " 55         55  ",
      " 55##       55  ",
      " 55 ##      55  ",
      "     ##     55  ",
      "      ##    55  ",
      "       #    55  ",
      "       ###  55  ",
      "         #  55  ",
      "        ### 55  ",
      "       ## # 55  ",
      "      ##  # 55  ",
      "      #   # 55  ",
      "    ##     #55$$",
      "$5555555555555$$",
      "$   ##     ## $$",
      "                "
    ],
    [
      "   555555555    ",
      "  #555555555    ",
      "   555555555    ",
      "   555555555    ",
      "    55555555    ",
      "    55555555    ",
      "     5555555    ",
      "     5555555    ",
      "     5555555    ",
      "     5555555    ",
      "    55555555    ",
      "    55555555    ",
      "   555555555$$$ ",
      "  $555555555$$$ ",
      "$$$  #     #$$$ ",
      "                "
    ],
    [
      "  $         $   ",
      "  $##       $   ",
      "  $ ##      $   ",
      "  $  ##     $   ",
      "      ##    $   ",
      "       #    $   ",
      "       ###  $   ",
      "         #  $   ",
      "        ### $   ",
      "       #### $   ",
      "      ##  # $   ",
      "     ### ###$   ",
      "  @$$$$$$$$$@   ",
      "   $$$$$$$$$#   ",
      "   $$$$$$$$$#   ",
      "     #     #    "
    ]
  ]
}