{
  "xsize": 16,
  "zsize": 16,
  "refpalette": "pomkotsmechs:scattered",
  "slices": [
    [
      "$$$$$$$$$$$$    ",
      "$$$$$$$$$$      ",
      "$$$$$$$$$ j   j ",
      "$$$$$$$$$       ",
      "$$$$$$$$$   j   ",
      "$$$$$$$$$       ",
      "$$$$$$$$$$ j  &&",
      "$$$$$$$$$$$&&&&&",
      "$$$$$$$$$$$&&&&&",
      "$$$$$$$$$$$&&&&&",
      "$$$$$$$$$$$&&&&&",
      "$$$$$$$$$$$&&&&&",
      "$$$$$$$$$$$&&&&&",
      "$$$$$$$$$$$&&&&&",
      "$$$$$$$$$$$&&&&&",
      "$$$$$$$$$$$&&&&&"
    ],
    [
      " j j            ",
      "                ",
      "                ",
      "    m           ",
      "  j    m        ",
      "                ",
      "                ",
      "              &$",
      "           j&&&&",
      "     j      &&&&",
      "                ",
      "                ",
      "       j    &&&&",
      "            &&&&",
      "     j  j   &&&$",
      "           j&&$$"
    ],
    [
      "                ",
      "                ",
      "                ",
      "    n           ",
      "       n        ",
      "                ",
      "                ",
      "                ",
      "             &&e",
      "                ",
      "                ",
      "                ",
      "                ",
      "             &&e",
      "             && ",
      "                "
    ],
    [
      "                ",
      "                ",
      "                ",
      "                ",
      "                ",
      "                ",
      "                ",
      "                ",
      "              } ",
      "                ",
      "                ",
      "                ",
      "                ",
      "             z{ ",
      "             |} ",
      "                "
    ],
    [
      "                ",
      "                ",
      "                ",
      "                ",
      "                ",
      "                ",
      "                ",
      "                ",
      "              } ",
      "                ",
      "                ",
      "                ",
      "                ",
      "             z{ ",
      "             |} ",
      "                "
    ],
    [
      "                ",
      "                ",
      "                ",
      "                ",
      "                ",
      "                ",
      "                ",
      "                ",
      "              } ",
      "                ",
      "                ",
      "                ",
      "                ",
      "             z{ ",
      "             |} ",
      "                "
    ],
    [
      "                ",
      "                ",
      "                ",
      "                ",
      "                ",
      "                ",
      "                ",
      "                ",
      "              } ",
      "                ",
      "                ",
      "                ",
      "                ",
      "             z{ ",
      "             |} ",
      "                "
    ],
    [
      "                ",
      "                ",
      "                ",
      "                ",
      "                ",
      "                ",
      "                ",
      "              { ",
      "             |} ",
      "                ",
      "                ",
      "                ",
      "                ",
      "             z{ ",
      "             |} ",
      "                "
    ],
    [
      "                ",
      "                ",
      "                ",
      "                ",
      "                ",
      "                ",
      "                ",
      "             z{ ",
      "             |} ",
      "                ",
      "                ",
      "                ",
      "                ",
      "             z{ ",
      "             |} ",
      "                "
    ],
    [
      "                ",
      "                ",
      "                ",
      "                ",
      "                ",
      "                ",
      "                ",
      "             z{ ",
      "             |} ",
      "                ",
      "                ",
      "                ",
      "                ",
      "             z{ ",
      "             |} ",
      "                "
    ],
    [
      "                ",
      "                ",
      "                ",
      "                ",
      "                ",
      "                ",
      "                ",
      "             z{ ",
      "             |} ",
      "                ",
      "                ",
      "                ",
      "                ",
      "             z{ ",
      "             |} ",
      "                "
    ],
    [
      "                ",
      "                ",
      "                ",
      "                ",
      "                ",
      "                ",
      "                ",
      "             z{ ",
      "             |} ",
      "                ",
      "                ",
      "                ",
      "                ",
      "             z{ ",
      "             |} ",
      "                "
    ],
    [
      "                ",
      "                ",
      "                ",
      "                ",
      "                ",
      "                ",
      "                ",
      "             z{ ",
      "             |} ",
      "                ",
      "                ",
      "                ",
      "                ",
      "             z{ ",
      "             |} ",
      "                "
    ],
    [
      "                ",
      "                ",
      "                ",
      "                ",
      "                ",
      "                ",
      "                ",
      "             z{ ",
      "             |} ",
      "                ",
      "                ",
      "                ",
      "                ",
      "             z{ ",
      "             |} ",
      "                "
    ],
    [
      "                ",
      "                ",
      "                ",
      "                ",
      "                ",
      "                ",
      "                ",
      "             && ",
      "             && ",
      "                ",
      "                ",
      "                ",
      "                ",
      "             && ",
      "             && ",
      "                "
    ],
    [
      "kk&&&&kkkkkkͱ&&$",
      "  &&&&      Ͳ&&$",
      "  &&&&      Ͳ&&$",
      "  &&&&      Ͳ&&$",
      "   &&&      Ͳ&&$",
      "     &      Ͳ&&$",
      "     &      Ͳ&&$",
      "     &      Ͳ&&&",
      "     &      Ͳ&&&",
      "    &&      |kkk",
      "    &&          ",
      "  &&&&          ",
      "  &&&&      zhhh",
      "  &&&&      Ͳ&&&",
      "  &&&&      Ͳ&&&",
      "  &&&&      Ͳ&& "
    ],
    [
      "ee{  zeeeeee{   ",
      "  ͳ  ͳ      ͳ   ",
      "  ͳ  ͳ      ͳ   ",
      "  ͳ  ͳ      ͳ   ",
      "  ͳ  ͳ      ͳ   ",
      "     ͳ      ͳ   ",
      "     ͳ      ͳ   ",
      "     ͳ      Ͳh{ ",
      "     ͳ      Ͳͱͱ ",
      "     ͳ      |kke",
      "  ͳ  ͳ          ",
      "  ͳ  ͳ          ",
      "  ͳ  ͳ      zhhe",
      "  ͳ  ͳ      ͲͱͰ ",
      "  ͳ  ͳ      Ͳk} ",
      "  ͳ  ͳ      ͳ   "
    ],
    [
      "                ",
      "                ",
      "                ",
      "                ",
      "                ",
      "                ",
      "                ",
      "             z{ ",
      "             |} ",
      "                ",
      "                ",
      "                ",
      "                ",
      "             z{ ",
      "             |} ",
      "                "
    ],
    [
      "                ",
      "                ",
      "                ",
      "                ",
      "                ",
      "                ",
      "                ",
      "             z{ ",
      "             |} ",
      "                ",
      "                ",
      "                ",
      "                ",
      "             z{ ",
      "             |} ",
      "                "
    ],
    [
      "                ",
      "                ",
      "                ",
      "                ",
      "                ",
      "                ",
      "                ",
      "             z{ ",
      "             |} ",
      "                ",
      "                ",
      "                ",
      "                ",
      "             z{ ",
      "             |} ",
      "                "
    ],
    [
      "                ",
      "                ",
      "                ",
      "                ",
      "                ",
      "                ",
      "                ",
      "             z{ ",
      "             |} ",
      "                ",
      "                ",
      "                ",
      "                ",
      "             z{ ",
      "             |} ",
      "                "
    ],
    [
      "                ",
      "                ",
      "                ",
      "                ",
      "                ",
      "                ",
      "                ",
      "             z{ ",
      "             |} ",
      "                ",
      "                ",
      "                ",
      "                ",
      "             z{ ",
      "             |} ",
      "                "
    ],
    [
      "                ",
      "                ",
      "                ",
      "                ",
      "                ",
      "                ",
      "                ",
      "             z{ ",
      "             |} ",
      "                ",
      "                ",
      "                ",
      "                ",
      "             z{ ",
      "             |} ",
      "                "
    ],
    [
      "                ",
      "                ",
      "                ",
      "                ",
      "                ",
      "                ",
      "                ",
      "             z{ ",
      "             |} ",
      "                ",
      "                ",
      "                ",
      "                ",
      "             z{ ",
      "             |} ",
      "                "
    ],
    [
      "                ",
      "                ",
      "                ",
      "                ",
      "                ",
      "                ",
      "                ",
      "             z{ ",
      "             |} ",
      "                ",
      "                ",
      "                ",
      "                ",
      "             z{ ",
      "             |} ",
      "                "
    ],
    [
      "                ",
      "                ",
      "                ",
      "                ",
      "                ",
      "                ",
      "                ",
      "             z{ ",
      "             |} ",
      "                ",
      "                ",
      "                ",
      "                ",
      "             z{ ",
      "             |} ",
      "                "
    ],
    [
      "                ",
      "                ",
      "                ",
      "                ",
      "                ",
      "                ",
      "                ",
      "             z{ ",
      "             |} ",
      "                ",
      "                ",
      "                ",
      "                ",
      "             z{ ",
      "             |} ",
      "                "
    ],
    [
      "                ",
      "                ",
      "                ",
      "                ",
      "                ",
      "                ",
      "                ",
      "             z{ ",
      "             |} ",
      "                ",
      "                ",
      "                ",
      "                ",
      "             z{ ",
      "             |} ",
      "                "
    ],
    [
      "                ",
      "                ",
      "                ",
      "                ",
      "                ",
      "                ",
      "                ",
      "             z{ ",
      "             |} ",
      "                ",
      "                ",
      "                ",
      "                ",
      "             z{ ",
      "             |} ",
      "                "
    ],
    [
      "                ",
      "                ",
      "                ",
      "                ",
      "                ",
      "                ",
      "                ",
      "             && ",
      "             && ",
      "                ",
      "                ",
      "                ",
      "                ",
      "             && ",
      "             && ",
      "                "
    ],
    [
      "             && ",
      "             && ",
      "             && ",
      "             && ",
      "             && ",
      "             && ",
      "            &&&&",
      "            &ͱͱ&",
      "            &ͱͱ&",
      "            &&&&",
      "                ",
      "                ",
      "            &&&&",
      "            &ͱͱ&",
      "            &ͱͱ&",
      "            &&&&"
    ],
    [
      "            $$$$",
      "            $$$$",
      "            $$$$",
      "            $$$$",
      "            $$$$",
      "            $$$$",
      "$$$$$$$$$$$$$$$$",
      "$$$$$$$$$$$$$$$$",
      "$$$$$$$$$$$$$$$$",
      "$$$$$$$$$$$$$$$$",
      "$$$$$$$$$$$$$$$$",
      "$$$$$$$$$$$$$$$$",
      "$$$$$$$$$$$$$$$$",
      "$$$$$$$$$$$$$$$$",
      "$$$$$$$$$$$$$$$$",
      "$$$$$$$$$$$$$$$$"
    ],
    [
      "llllllllllllllll",
      "llllllllllllllll",
      "llllllllllllllll",
      "llllllllllllllll",
      "llllllllllllllll",
      "llllllllllllllll",
      "llllllllllllllll",
      "llllllllllllllll",
      "llllllllllllllll",
      "llllllllllllllll",
      "llllllllllllllll",
      "llllllllllllllll",
      "llllllllllllllll",
      "llllllllllllllll",
      "llllllllllllllll",
      "llllllllllllllll"
    ],
    [
      "                ",
      "          m     ",
      "              m ",
      "  m j           ",
      "       j    j   ",
      "                ",
      "           j    ",
      "                ",
      "                ",
      "     j          ",
      "                ",
      "                ",
      "    m  m        ",
      "  j             ",
      "     j  m       ",
      "                "
    ],
    [
      "                ",
      "          n     ",
      "              n ",
      "  n             ",
      "                ",
      "                ",
      "                ",
      "                ",
      "                ",
      "                ",
      "                ",
      "                ",
      "    n  n        ",
      "                ",
      "        n       ",
      "                "
    ],
    [
      "                ",
      "                ",
      "                ",
      "                ",
      "                ",
      "                ",
      "                ",
      "                ",
      "                ",
      "                ",
      "                ",
      "                ",
      "                ",
      "                ",
      "                ",
      "                "
    ]
  ]
}