{
  "xsize": 16,
  "zsize": 16,
  "refpalette": "pomkotsmechs:scattered",
  "slices": [
    [
      "    &&&&&&&&&&&&",
      "    &&&&&&&&&&&&",
      "    &&&&&&&&&&&&",
      "    &&&&&&&&&&&&",
      "    &&&&&&&&&&&&",
      "    &&&&&&&&&&&&",
      "    &&&&&&&&&&&&",
      "    &&&&&&&&&&&&",
      "    &&&&&&&&&&&&",
      "    &&&&&&&&&&&&",
      "    &&&&&&&&&&&&",
      "    &&&&&&&&&&&&",
      "    &&&&&&&&&&&&",
      "    &&&&&&&&&&&&",
      "    &&&&&&&&&&&&",
      "    &&&&&&&&&&&&"
    ],
    [
      "     $$$$c$$$$$$",
      "     $$$$$c$$$$$",
      "     $$$$$c$$$$$",
      "     $$$$$$c$$$$",
      "     $$$$$$$cc$$",
      "     $$$$$$$$$cc",
      "     $$$$$$$$$$$",
      "     $$$$$$$$$$$",
      "    $$$&&&&&&&&&",
      "    $$$bbbbbbb  ",
      "     $ bbbbbb  j",
      "     $bbbbbbb   ",
      "    $$$bbbbbb   ",
      "    $$$&&&&&&&&&",
      "     $$$$$$$$$$$",
      "     $$$$$$$$$$$"
    ],
    [
      "     f  bbbbbbbb",
      "     f  bbbbbbbb",
      "     f  bbbbbbbb",
      "     f  bbbbbbbb",
      "     f  bbbbbbbb",
      "     f  bbbbbbbb",
      "     f  bbbbbbbb",
      "     f$ bbbbbbbb",
      "    $$$eeeeeeeee",
      "    $$$bbbbbbb  ",
      "     $ bbbbbb   ",
      "     $ bbbbbba  ",
      "    $$$bbbbbba  ",
      "    $$$eeeeeeeee",
      "     f$bbbbbb   ",
      "     f bbbbbb   "
    ],
    [
      "     f  bbbbbbbb",
      "     f  bbbbbbbb",
      "     f  bbbbbbbb",
      "     f  bbbbbbbb",
      "     f   bbbbbbb",
      "     f   bbbbbbb",
      "     f   bbbbbbb",
      "     f$ bbbbbbbb",
      "    $$$ bbbbbbb ",
      "    $$$ bbbbbb  ",
      "     $ abbbb    ",
      "     $aabbbba   ",
      "    $$$abbbba   ",
      "    $$$abbbb    ",
      "     f$ bbbbj   ",
      "     f  bbbb    "
    ],
    [
      "     f   bbbbbbb",
      "     f   bbbbbbb",
      "     f   bbbbbbb",
      "     f   bbbbbbb",
      "     f    bbbbbb",
      "     f    bbbbbb",
      "     f   bbbbbbb",
      "     f$  bbbbbb ",
      "    $$$  bbbbbb ",
      "    $$$   bbb   ",
      "     $          ",
      "     $aaaaaa    ",
      "    $$$a   j    ",
      "    $$$         ",
      "     f$  j      ",
      "     f          "
    ],
    [
      "     f   bbbbbbb",
      "     f    bbbbbb",
      "     f    bbbbbb",
      "     f    bbbbbb",
      "     f    bbbbbb",
      "     f    bbbbbb",
      "     f    bbbbbb",
      "     f$   bbbbbb",
      "    $$$    bbbb ",
      "    $$$   j     ",
      "     $          ",
      "     $a         ",
      "    $$$a        ",
      "    $$$         ",
      "     f$         ",
      "     f          "
    ],
    [
      "     f    bbbbbb",
      "     f     bbbbb",
      "     f     bbbbb",
      "     f     bbbbb",
      "     f     bbbbb",
      "     f     bbbbb",
      "     f     bbbbb",
      "     f$    bbbbb",
      "    $$$     bbb ",
      "    $$$         ",
      "     $a         ",
      "    a$aa        ",
      "    $$$a        ",
      "    $$$         ",
      "     f$         ",
      "     f          "
    ],
    [
      "     f     bbbbb",
      "     f     bbbbb",
      "     f     bbbbb",
      "     f     bbbbb",
      "     f     bbbbb",
      "     f     bbbbb",
      "     f     bbbbb",
      "     f$     bbbb",
      "    $$$      b  ",
      "    $$$         ",
      "     $          ",
      "    a$a         ",
      "    $$$         ",
      "    $$$         ",
      "     f$         ",
      "     f          "
    ],
    [
      "     f      bbbb",
      "     f      bbbb",
      "     f     bbbbb",
      "     f     bbbbb",
      "     f     bbbbb",
      "     f      bbbb",
      "     f      bbbb",
      "     f$      bb ",
      "    $$$         ",
      "    $$$         ",
      "     $          ",
      "    a$a         ",
      "    $$$         ",
      "    $$$         ",
      "     f$         ",
      "     f          "
    ],
    [
      "     f       bbb",
      "     f      bbbb",
      "     f      bbbb",
      "     f     bbbbb",
      "     f      bbbb",
      "     f      bbbb",
      "     f        bb",
      "     f$         ",
      "    $$$         ",
      "    $$$         ",
      "     $          ",
      "    a$a         ",
      "    $$$         ",
      "    $$$         ",
      "     f$         ",
      "     f          "
    ],
    [
      "     f        bb",
      "     f      bbbb",
      "     f      bbbb",
      "     f     bbbbb",
      "     f      bbbb",
      "     f      bbbb",
      "     f        bb",
      "     f$         ",
      "    $$$         ",
      "    $$$         ",
      "     $          ",
      "    a$a         ",
      "    $$$         ",
      "    $$$         ",
      "     f$         ",
      "     f          "
    ],
    [
      "     f        b ",
      "     f      bbbb",
      "     f      bbbb",
      "     f     bbbbb",
      "     f      bbbb",
      "     f      bbbb",
      "     f        bb",
      "     f$         ",
      "    $$$         ",
      "    $$$         ",
      "    a$a         ",
      "    a$a         ",
      "    $$$         ",
      "    $$$         ",
      "     f$         ",
      "     f          "
    ],
    [
      "     f        bb",
      "     f      bbbb",
      "     f      bbbb",
      "     f     bbbbb",
      "     f      bbbb",
      "     f      bbbb",
      "     f        bb",
      "     f$         ",
      "    $$$         ",
      "    $$$         ",
      "    a$a         ",
      "     $          ",
      "    $$$         ",
      "    $$$         ",
      "     f$         ",
      "     f          "
    ],
    [
      "     f       bbb",
      "     f      bbbb",
      "     f      bbbb",
      "     f      bbbb",
      "     f      bbbb",
      "     f      bbbb",
      "     f        bb",
      "     f$         ",
      "    $$$         ",
      "    $$$         ",
      "     $          ",
      "     $          ",
      "    $$$         ",
      "    $$$         ",
      "     f$         ",
      "     f          "
    ],
    [
      "     f      bbbb",
      "     f     bbbbb",
      "     f      bbbb",
      "     f      bbbb",
      "     f      bbbb",
      "     f      bbbb",
      "     f        bb",
      "     f$         ",
      "    $$$         ",
      "    $$$         ",
      "     $          ",
      "     $          ",
      "    $$$         ",
      "    $$$         ",
      "     f$         ",
      "     f          "
    ],
    [
      "     f$$$$$$$$$$",
      "     f$$$$$$$$$$",
      "     f$$$  bbbbb",
      "     f$$    bbbb",
      "     f$     bbbb",
      "     f$      bbb",
      "     f$       bb",
      "     f$&        ",
      "    $$$&&       ",
      "    $$$kkk      ",
      "     $          ",
      "     $          ",
      "    $$$hhhhhhhhh",
      "    $$$&&&&&&&&&",
      "     f$&&&&&&&&&",
      "     f          "
    ],
    [
      "           bbbbb",
      "     f    bbbbbb",
      "     f    bbbbbb",
      "     f     bbbbb",
      "     f      bbbb",
      "     f       bbb",
      "     f        bb",
      "     f$         ",
      "    $$$         ",
      "    $$$eeee     ",
      "     $          ",
      "     $          ",
      "    $$$eeeeeeee ",
      "    $$$         ",
      "     f$         ",
      "     f          "
    ],
    [
      "           bbbbb",
      "     f    bbbbbb",
      "     f     bbbbb",
      "     f     bbbbb",
      "     f      bbbb",
      "     f       bbb",
      "     f        bb",
      "     f$         ",
      "    $$$         ",
      "    $$$         ",
      "     $          ",
      "     $          ",
      "    $$$         ",
      "    $$$         ",
      "     f$         ",
      "     f          "
    ],
    [
      "           bbbbb",
      "     f     bbbbb",
      "     f     bbbbb",
      "     f     bbbbb",
      "     f      bbbb",
      "     f       bbb",
      "     f        bb",
      "     f$         ",
      "    $$$         ",
      "    $$$         ",
      "     $          ",
      "     $          ",
      "    $$$         ",
      "    $$$         ",
      "     f$         ",
      "     f          "
    ],
    [
      "            bbbb",
      "     f     bbbbb",
      "     f     bbbbb",
      "     f      bbbb",
      "     f      bbbb",
      "     f       bbb",
      "     f        bb",
      "     f$         ",
      "    $$$         ",
      "    $$$         ",
      "     $          ",
      "     $          ",
      "    $$$         ",
      "    $$$         ",
      "     f$         ",
      "     f          "
    ],
    [
      "            bbbb",
      "     f      bbbb",
      "     f      bbbb",
      "     f       bbb",
      "     f       bbb",
      "     f       bbb",
      "     f        bb",
      "     f$         ",
      "    $$$         ",
      "    $$$         ",
      "     $          ",
      "     $          ",
      "    $$$         ",
      "    $$$         ",
      "     f$         ",
      "     f          "
    ],
    [
      "               b",
      "     f       bbb",
      "     f       bbb",
      "     f       bbb",
      "     f       bbb",
      "     f       bbb",
      "     f         b",
      "     f$         ",
      "    $$$         ",
      "    $$$         ",
      "     $          ",
      "     $          ",
      "    $$$         ",
      "    $$$         ",
      "     f$         ",
      "     f          "
    ],
    [
      "                ",
      "     f        bb",
      "     f       bbb",
      "     f       bbb",
      "     f       bbb",
      "     f        bb",
      "     f         b",
      "     f$         ",
      "    $$$         ",
      "    $$$         ",
      "     $          ",
      "     $          ",
      "    $$$         ",
      "    $$$         ",
      "     f          ",
      "     f          "
    ],
    [
      "     f          ",
      "     f        bb",
      "     f        bb",
      "     f       bbb",
      "     f        bb",
      "     f        bb",
      "     f          ",
      "     f$         ",
      "    $$$         ",
      "    $$$         ",
      "     $          ",
      "     $          ",
      "    $$$         ",
      "    $$          ",
      "                ",
      "                "
    ],
    [
      "     f        a ",
      "     f       abb",
      "     f        bb",
      "     f        bb",
      "     f        bb",
      "     f        bb",
      "     f         a",
      "     f$         ",
      "    $$$         ",
      "    $$$         ",
      "     $          ",
      "     $          ",
      "    $$$         ",
      "    $$          ",
      "                ",
      "                "
    ],
    [
      "     f        a ",
      "     f       abb",
      "     f        bb",
      "     f        bb",
      "     f        bb",
      "     f        ab",
      "     f         a",
      "     f$         ",
      "    $$$         ",
      "    $$$         ",
      "     $          ",
      "     $          ",
      "    $$$         ",
      "    $           ",
      "                ",
      "                "
    ],
    [
      "    $$$       aa",
      "    $$$      abb",
      "    $$$       bb",
      "    $$$       bb",
      "    $$$      abb",
      "    $$$       ab",
      "    $$$        a",
      "    $$$         ",
      "    $$$         ",
      "    $$$         ",
      "     $$         ",
      "     $$         ",
      "    $$$         ",
      "    $           ",
      "                ",
      "                "
    ],
    [
      "    $$$       aa",
      "    $$$      abb",
      "    $$$      abb",
      "    $$$      abb",
      "    $$$      abb",
      "    $$$       bb",
      "    $$$        a",
      "    $$$         ",
      "    $$$         ",
      "    $$$         ",
      "     $$         ",
      "     $$         ",
      "    $$$         ",
      "    $           ",
      "                ",
      "                "
    ],
    [
      "              aa",
      "             aab",
      "      $     aabb",
      "            aabb",
      "            aabb",
      "             abb",
      "      $        a",
      "    $$$         ",
      "    $$$         ",
      "    $$$         ",
      "                ",
      "                ",
      "    $$$         ",
      "    $$          ",
      "                ",
      "                "
    ],
    [
      "               a",
      "            aaab",
      "      $    aaabb",
      "           aaabb",
      "            aabb",
      "             aab",
      "      $        a",
      "    $$$         ",
      "    $$$         ",
      "    $$$         ",
      "                ",
      "                ",
      "    $$$         ",
      "    $$$         ",
      "    $           ",
      "                "
    ],
    [
      "             aaa",
      "            aaab",
      "           aaabb",
      "      &    aaabb",
      "      &    aaabb",
      "      &    aaaab",
      "      $     aa b",
      "    $$&&&&&&&&&&",
      "    $$$&&&&&&&&&",
      "    $$$         ",
      "      &        a",
      "      &        a",
      "    $$$        a",
      "    $$$&&&&&&&&&",
      "    $$& &&&&&&&&",
      "                "
    ],
    [
      "            aaaa",
      "    $      aaaab",
      "    $$     aaaab",
      "    $$$    aaabb",
      "    $$$$   aaabb",
      "    $$$$  aaaaab",
      "    $$$$$$$$$$$$",
      "    $$$$$$$$$$$$",
      "    $$$$$$$$$$$$",
      "    $$$$$$$$$$$$",
      "    $$$$$$$$$$$$",
      "    $$$$$$$$$$$$",
      "    $$$$$$$$$$$$",
      "    $$$$$$$$$$$$",
      "    $$$$$$$$$$$$",
      "    $$$$$$$$$$$$"
    ],
    [
      "            aaaa",
      "    l       aaaa",
      "    ll      aaab",
      "    lll    aaaab",
      "    llll   aaaab",
      "    lllllaaaaaal",
      "    llllllllllll",
      "    llllllllllll",
      "    llllllllllll",
      "    llllllllllll",
      "    llllllllllll",
      "    llllllllllll",
      "    llllllllllll",
      "    llllllllllll",
      "    llllllllllll",
      "    llllllllllll"
    ],
    [
      "            aaaa",
      "            aaaa",
      "            aaab",
      "           aaaab",
      "          aaaaab",
      "      a  aaaaaab",
      "      a aaaaaaaa",
      "      aaaaaaaaaa",
      "      aaaaaaaaaa",
      "       aaaaaaaaa",
      "         aaaaaaa",
      "         aaaaaaa",
      "       j  aaaaaa",
      "           a aaa",
      "         j  j  a",
      "     j          "
    ],
    [
      "           aaaaa",
      "           aaaaa",
      "            aaaa",
      "            aaaa",
      "           aaaaa",
      "           aaaaa",
      "         a aaaaa",
      "         aaaaaaa",
      "            aaaa",
      "               a",
      "          aa    ",
      "           a    ",
      "           a    ",
      "                ",
      "                ",
      "                "
    ],
    [
      "            aaaa",
      "            aaaa",
      "            aaaa",
      "            aaaa",
      "            aaaa",
      "             aaa",
      "              aa",
      "              aa",
      "               a",
      "                ",
      "                ",
      "                ",
      "           j    ",
      "                ",
      "                ",
      "                "
    ]
  ]
}