{
  "xsize": 16,
  "zsize": 16,
  "refpalette": "pomkotsmechs:scattered",
  "slices": [
    [
      "$$$$$$$$$$ j    ",
      "$$$$$$$$$$      ",
      "$$$$$$$$$$      ",
      "$$$$$$$$$$      ",
      "$$$$$$$$$$      ",
      "$$$$$$$$$$      ",
      "$$$$$$$$$$      ",
      "$$$$$$$$$$      ",
      "$$$$$$$$$$$ j  &",
      "$$$$$$$$$$$    &",
      "$$$$$$$$$$$&&&&&",
      "$$$$$$$$$$$&&&&&",
      "$$$$$$$$$$$&&&&&",
      "$$$$$$$$$$$&&&&&",
      "$$$$$$$$$$$&&&&&",
      "$$$$$$$$$$$&&&&&"
    ],
    [
      "                ",
      "  j             ",
      "                ",
      "j    m          ",
      "         j      ",
      "        j       ",
      "    m           ",
      "                ",
      "j    j          ",
      "   j            ",
      "               $",
      "   m        &&&$",
      "            &&& ",
      "$$$$$$$$$$$$$$$ ",
      "$$$$$$$$$$$$$$$ ",
      "              $ "
    ],
    [
      "                ",
      "                ",
      "                ",
      "     n          ",
      "                ",
      "                ",
      "    n           ",
      "                ",
      "                ",
      "                ",
      "                ",
      "   n         && ",
      "             && ",
      "a            $$ ",
      "+++ ++++++++++$ ",
      "              $ "
    ],
    [
      "                ",
      "                ",
      "                ",
      "                ",
      "                ",
      "                ",
      "                ",
      "                ",
      "                ",
      "                ",
      "                ",
      "             z{ ",
      "             |} ",
      "a            $$ ",
      "+++ ++++++++++$ ",
      "              $ "
    ],
    [
      "                ",
      "                ",
      "                ",
      "                ",
      "                ",
      "                ",
      "                ",
      "                ",
      "                ",
      "                ",
      "                ",
      "             z{ ",
      "             |} ",
      "a            $$$",
      "++++++++++++++$ ",
      "              $$"
    ],
    [
      "                ",
      "                ",
      "                ",
      "                ",
      "                ",
      "                ",
      "                ",
      "                ",
      "                ",
      "                ",
      "                ",
      "             z{ ",
      "             |} ",
      "a            $$$",
      "++++++++++++++$$",
      "a             $$"
    ],
    [
      "                ",
      "                ",
      "                ",
      "                ",
      "                ",
      "                ",
      "                ",
      "                ",
      "                ",
      "                ",
      "                ",
      "             z{ ",
      "             |} ",
      "a            $$$",
      "++++++++++++++$$",
      "a             $$"
    ],
    [
      "                ",
      "                ",
      "                ",
      "                ",
      "                ",
      "                ",
      "                ",
      "                ",
      "                ",
      "                ",
      "                ",
      "             z{ ",
      "             |} ",
      "a            $$$",
      "++++++++++++++$$",
      "a             $$"
    ],
    [
      "                ",
      "                ",
      "                ",
      "                ",
      "                ",
      "                ",
      "                ",
      "                ",
      "                ",
      "                ",
      "                ",
      "             z{ ",
      "             |} ",
      "a            $$$",
      "++++++++++++++$$",
      "a             $$"
    ],
    [
      "                ",
      "                ",
      "                ",
      "                ",
      "                ",
      "                ",
      "                ",
      "                ",
      "                ",
      "                ",
      "                ",
      "             z{ ",
      "             |} ",
      "aa           $$$",
      "++++++++++++++$$",
      "aa            $$"
    ],
    [
      "                ",
      "                ",
      "                ",
      "                ",
      "                ",
      "                ",
      "                ",
      "                ",
      "                ",
      "                ",
      "                ",
      "             z{ ",
      "             |} ",
      "aa           $$$",
      "++++++++++++++$$",
      "aa            $$"
    ],
    [
      "                ",
      "                ",
      "                ",
      "                ",
      "                ",
      "                ",
      "                ",
      "                ",
      "                ",
      "                ",
      "                ",
      "             z{ ",
      "             |} ",
      "aa           $$ ",
      "++++++++++++++  ",
      "aa              "
    ],
    [
      "                ",
      "                ",
      "                ",
      "                ",
      "                ",
      "                ",
      "                ",
      "                ",
      "                ",
      "                ",
      "                ",
      "             z{ ",
      "             |} ",
      " a           $  ",
      "+++++++++++++   ",
      " a              "
    ],
    [
      "                ",
      "                ",
      "                ",
      "                ",
      "                ",
      "                ",
      "                ",
      "                ",
      "                ",
      "                ",
      "                ",
      "             z{ ",
      "             |} ",
      " a              ",
      "++++++++++++    ",
      " a              "
    ],
    [
      "                ",
      "                ",
      "                ",
      "                ",
      "                ",
      "                ",
      "                ",
      "                ",
      "                ",
      "                ",
      "                ",
      "             && ",
      "             && ",
      "   aa           ",
      "+++++++++++     ",
      "                "
    ],
    [
      "  &&&&      Ͳ&& ",
      "  &&&&      Ͳ&& ",
      "  &&&&      Ͳ&& ",
      "  &&&&      Ͳ&& ",
      "  &&&&      Ͳ&& ",
      "  &&&&      Ͳ&& ",
      "  &&&&      Ͳ&& ",
      "  &&&&      Ͳ&& ",
      "  &&&&      Ͳ&& ",
      "  &&&&      Ͳ&& ",
      "  &&&&      Ͳ&& ",
      "  &&&&      Ͳ&&&",
      "  &&&&      Ͳ&  ",
      "aa&&&&          ",
      "++&&&&++++      ",
      "a  a            "
    ],
    [
      "  ͳ  ͳ      ͳ   ",
      "  ͳ  ͳ      ͳ   ",
      "  ͳ  ͳ      ͳ   ",
      "  ͳ  ͳ      ͳ   ",
      "  ͵  ͵      ͳ   ",
      "            ͳ   ",
      "            ͳ   ",
      "            ͳ   ",
      "            ͳ   ",
      "            ͳ   ",
      "            ͳ   ",
      "            Ͳh{ ",
      "                ",
      "aaaaa           ",
      "++++++++++      ",
      "aaaa            "
    ],
    [
      "                ",
      "                ",
      "                ",
      "                ",
      "                ",
      "                ",
      "                ",
      "                ",
      "                ",
      "                ",
      "                ",
      "             z{ ",
      "                ",
      "aa              ",
      "+++++++++       ",
      "                "
    ],
    [
      "                ",
      "                ",
      "                ",
      "                ",
      "                ",
      "                ",
      "                ",
      "                ",
      "                ",
      "                ",
      "                ",
      "              { ",
      "                ",
      "                ",
      "++++++++        ",
      "                "
    ],
    [
      "                ",
      "                ",
      "                ",
      "                ",
      "                ",
      "                ",
      "                ",
      "                ",
      "                ",
      "                ",
      "                ",
      "              { ",
      "                ",
      "                ",
      "++++++          ",
      "                "
    ],
    [
      "                ",
      "                ",
      "                ",
      "                ",
      "                ",
      "                ",
      "                ",
      "                ",
      "                ",
      "                ",
      "                ",
      "              { ",
      "                ",
      "                ",
      "+++++           ",
      "                "
    ],
    [
      "                ",
      "                ",
      "                ",
      "                ",
      "                ",
      "                ",
      "                ",
      "                ",
      "                ",
      "                ",
      "                ",
      "             z{ ",
      "                ",
      "                ",
      "++++            ",
      "                "
    ],
    [
      "                ",
      "                ",
      "                ",
      "                ",
      "                ",
      "                ",
      "                ",
      "                ",
      "                ",
      "                ",
      "                ",
      "             z{ ",
      "              } ",
      "               $",
      "++             $",
      "               $"
    ],
    [
      "                ",
      "                ",
      "                ",
      "                ",
      "                ",
      "                ",
      "                ",
      "                ",
      "                ",
      "                ",
      "                ",
      "             z{ ",
      "             |} ",
      "               $",
      "+              $",
      "               $"
    ],
    [
      "                ",
      "                ",
      "                ",
      "                ",
      "                ",
      "                ",
      "                ",
      "                ",
      "                ",
      "                ",
      "                ",
      "             z{ ",
      "             |} ",
      "              $$",
      "              $$",
      "              $$"
    ],
    [
      "                ",
      "                ",
      "                ",
      "                ",
      "                ",
      "                ",
      "                ",
      "                ",
      "                ",
      "                ",
      "                ",
      "             z{ ",
      "             |} ",
      "             $$$",
      "             +$$",
      "              $$"
    ],
    [
      "                ",
      "                ",
      "                ",
      "                ",
      "                ",
      "                ",
      "                ",
      "                ",
      "                ",
      "                ",
      "                ",
      "             z{ ",
      "             |} ",
      "            $$$$",
      "            $$$$",
      "            $$$$"
    ],
    [
      "                ",
      "                ",
      "                ",
      "                ",
      "                ",
      "                ",
      "                ",
      "                ",
      "                ",
      "                ",
      "                ",
      "             z{ ",
      "             |} ",
      "          $$$$$$",
      "          $$$$$$",
      "          $$$$$$"
    ],
    [
      "                ",
      "                ",
      "                ",
      "                ",
      "                ",
      "                ",
      "                ",
      "                ",
      "                ",
      "                ",
      "                ",
      "             z{ ",
      "             |} ",
      "        $   $$$$",
      "             $$$",
      "             $$$"
    ],
    [
      "                ",
      "                ",
      "                ",
      "                ",
      "                ",
      "                ",
      "                ",
      "                ",
      "                ",
      "                ",
      "                ",
      "             && ",
      "             && ",
      "        $   $$$$",
      "             $$$",
      "             $$$"
    ],
    [
      "             && ",
      "             && ",
      "             && ",
      "             && ",
      "             && ",
      "             && ",
      "             && ",
      "             && ",
      "             && ",
      "             && ",
      "            &&&&",
      "            &ͱͱ&",
      "            &ͱͱ&",
      "     &&&$&&&$&$$",
      "             $$$",
      "             $$$"
    ],
    [
      "            $$$$",
      "            $$$$",
      "            $$$$",
      "            $$$$",
      "            $$$$",
      "            $$$$",
      "            $$$$",
      "            $$$$",
      "            $$$$",
      "            $$$$",
      "$$$$$$$$$$$$$$$$",
      "$$$$$$$$$$$$$$$$",
      "  $$$$$$$$$$$$$$",
      "   $$$$$$$$$$$$$",
      "     $$$$$$$$$$$",
      "     $$$$$$$$$$$"
    ],
    [
      "llllllllllllllll",
      "llllllllllllllll",
      "llllllllllllllll",
      "llllllllllllllll",
      "llllllllllllllll",
      "llllllllllllllll",
      "llllllllllllllll",
      "llllllllllllllll",
      "llllllllllllllll",
      "llllllllllllllll",
      "            j   ",
      "   j  j         ",
      "            m  j",
      "                ",
      "      j      m  ",
      "         j      "
    ],
    [
      "           j    ",
      "                ",
      "             m  ",
      "                ",
      "j         j     ",
      "        j       ",
      "    j           ",
      "                ",
      "j  m j      j   ",
      "        j j     ",
      "                ",
      "                ",
      "            n   ",
      "                ",
      "             n  ",
      "                "
    ],
    [
      "                ",
      "                ",
      "             n  ",
      "                ",
      "                ",
      "                ",
      "                ",
      "                ",
      "   n            ",
      "                ",
      "                ",
      "                ",
      "                ",
      "                ",
      "                ",
      "                "
    ],
    [
      "                ",
      "                ",
      "                ",
      "                ",
      "                ",
      "                ",
      "                ",
      "                ",
      "                ",
      "                ",
      "                ",
      "                ",
      "                ",
      "                ",
      "                ",
      "                "
    ]
  ]
}