{
  "xsize": 16,
  "zsize": 16,
  "refpalette": "pomkotsmechs:scattered",
  "slices": [
    [
      "                ",
      "     &&&&&&&    ",
      "     &    &&    ",
      "     &    &&    ",
      "     &    &&    ",
      "     &    &&    ",
      "     &    &&    ",
      "     &    &&    ",
      "vv   &    &&    ",
      "vvvv &    &&    ",
      "vvvvv&    &&    ",
      "vvvvv&    &&    ",
      "vvvvv&&&&&&&    ",
      "vvvvvvv         ",
      "vvvvvvvv        ",
      "vvvvvvvv        "
    ],
    [
      "                ",
      "    &&&&&&&&    ",
      "&&&&&&     &    ",
      "&&&&&&     &    ",
      "&&&&&&     &    ",
      "&&&&&&     &    ",
      "&&&&&&#    &    ",
      "&&&&&&     &    ",
      "&&&&&&     &    ",
      "&&&&&&     &    ",
      "&&&&&&     &    ",
      "&&&&&&     &    ",
      "&&&&&&&&&&&&    ",
      "&&&&&&          ",
      "&&&&&&          ",
      "&&&&&&          "
    ],
    [
      "                ",
      "    &&&&&&&     ",
      "&&&&&&    &     ",
      "    &&    &     ",
      "    &&    &     ",
      "    &&#   &     ",
      "  ' &&#   &     ",
      "    &&    &     ",
      "    &&    &     ",
      "    &&    &     ",
      "  ' &&    &     ",
      "    &&    &     ",
      "    &&&&&&&     ",
      "  '  &          ",
      "     &          ",
      "     &          "
    ],
    [
      "                ",
      "   &&&&&&&&     ",
      "&&&&&&    &     ",
      "   & &    &     ",
      "   & &#   &     ",
      "   &#&##  &     ",
      "(((&#&#   &     ",
      "(((& &    &     ",
      "(((& &    &     ",
      "(((& &    &     ",
      "(((& &    &     ",
      "   & &    &     ",
      "   &&&&&&&&     ",
      "(((  &          ",
      "(((  &          ",
      "(((  &          "
    ],
    [
      "                ",
      "   &&&&&&&      ",
      "&&&&&&   &      ",
      "   & &   &      ",
      "   & &#  &      ",
      "   & &## &      ",
      "&&(&#&#  &      ",
      "  &&#&   &      ",
      "  &&#&   &      ",
      "))&& &   &      ",
      "&&(& &   &      ",
      "   & &   &      ",
      "   &&&&&&&      ",
      "&&(  &          ",
      "  &  &          ",
      "  &  &          "
    ],
    [
      "                ",
      "  &&&&&&&&      ",
      "&&&&&&   &      ",
      "  &  &   &      ",
      "  &  &#  &      ",
      "  &  &## &      ",
      "&&(##&#  &      ",
      "  &##&   &      ",
      " #&##&   &      ",
      "  &# &   &      ",
      "&&(  &   &      ",
      "  &  &   &      ",
      "  &&&&&&&&      ",
      "&&(  &          ",
      "  &  &          ",
      "  &  &          "
    ],
    [
      "                ",
      "  &&&&&&&&      ",
      "&&&&&&   &      ",
      "  &  &   &      ",
      "  &  &## &      ",
      "  &  &## &      ",
      "&&( #&#  &      ",
      "((&##&   &      ",
      "((&##&   &      ",
      "((&  &   &      ",
      "&&(  &   &      ",
      "  &  &   &      ",
      "  &&&&&&&&      ",
      "&&(  &          ",
      "((&  &          ",
      "((&  &          "
    ],
    [
      "                ",
      "  &&&&&&&       ",
      "&&&&&&  &       ",
      "  &  &##&       ",
      "  &  &##&       ",
      "  & #&##&       ",
      "(((##&# &       ",
      "(((##&  &       ",
      "(((##&  &       ",
      "(((  &  &       ",
      "(((  &  &       ",
      "  &  &  &       ",
      "  &&&&&&&       ",
      "(((  &          ",
      "(((  &          ",
      "(((  &          "
    ],
    [
      "                ",
      " &&&&&&&&       ",
      "&&&&&&  &       ",
      " &   & #&#      ",
      " &   &##&       ",
      " &  #&##&       ",
      " &' #&# &       ",
      " &# #&  &       ",
      " &## &  &       ",
      " &#  &  &       ",
      " &'  &  &       ",
      " &   &  &       ",
      " &&&&&&&&       ",
      "  '  &          ",
      "     &          ",
      "     &          "
    ],
    [
      "                ",
      " &&&&&&&        ",
      "&&&&&& &#       ",
      " &   &#&##      ",
      " &    #&#       ",
      " &   # #        ",
      "(((  # &        ",
      "(((  & &        ",
      "(((# & &        ",
      "(((  & &        ",
      "(((  & &        ",
      " &   & &        ",
      " &&&&&&&        ",
      "(((  &          ",
      "(((  &          ",
      "(((  &          "
    ],
    [
      "                ",
      "&&&&&&&&        ",
      "&&&&&& &        ",
      "&    &#&#       ",
      "&      #        ",
      "&               ",
      "&&(             ",
      "& &  & &        ",
      "&#&# & &        ",
      "))&  & &        ",
      "&&(  & &        ",
      "&    & &        ",
      "&&&&&&&&        ",
      "&&(  &          ",
      "  &  &          ",
      "  &  &          "
    ],
    [
      "                ",
      "&&&&&&&         ",
      "&&&&&&&         ",
      "&    & #        ",
      "&               ",
      "&               ",
      "&&(             ",
      "& &  &          ",
      "&#&# &&         ",
      "& &  &&         ",
      "&&(  &&         ",
      "&    &&         ",
      "&&&&&&&         ",
      "&&(  &          ",
      "  &  &          ",
      "  &  &          "
    ],
    [
      "                ",
      "&&&&&&&         ",
      "&&&&&&&         ",
      "     &&         ",
      "     &          ",
      "                ",
      "&&(             ",
      "((&#            ",
      "((&# &&         ",
      "((&  &&         ",
      "&&(  &&         ",
      "     &&         ",
      "&&&&&&&         ",
      "&&(  &          ",
      "((&  &          ",
      "((&  &          "
    ],
    [
      "                ",
      "&&&&&&&         ",
      "&&&&&&&         ",
      "     &&         ",
      "                ",
      "                ",
      "(((             ",
      "(((#            ",
      "(((#            ",
      "(((   &         ",
      "(((  &&         ",
      "     &&         ",
      "&&&&&&&         ",
      "(((  &          ",
      "(((  &          ",
      "(((  &          "
    ],
    [
      "                ",
      "&&&&&&          ",
      "&&&&&&          ",
      "     &          ",
      "                ",
      "                ",
      "                ",
      " ##             ",
      "###             ",
      " #              ",
      "     &          ",
      "     &          ",
      "&&&&&&          ",
      "     &          ",
      "     &          ",
      "     &          "
    ],
    [
      "                ",
      "&&&&&&          ",
      "&&&&&&          ",
      "&&&&&&          ",
      "&&&&&           ",
      "&&&             ",
      "&&              ",
      "&&              ",
      "&&#             ",
      "&&              ",
      "                ",
      "   &&&          ",
      "  &&&&          ",
      "  &&&&          ",
      " &&&&&          ",
      "&&&&&&          "
    ],
    [
      "                ",
      "&&&&&           ",
      "    &           ",
      "    &           ",
      "    &           ",
      "                ",
      " #              ",
      "###             ",
      "###             ",
      " #              ",
      "                ",
      "                ",
      "    &           ",
      "                ",
      "                ",
      "                "
    ],
    [
      "                ",
      "&&&&&           ",
      "&   &           ",
      "&   &           ",
      "&   &           ",
      "&               ",
      "&#              ",
      "&##             ",
      "&#              ",
      "&               ",
      "                ",
      "                ",
      "                ",
      "                ",
      "                ",
      "                "
    ],
    [
      "                ",
      " &&&&           ",
      " && &           ",
      " && &           ",
      " && &           ",
      " &&             ",
      " &              ",
      "#&#             ",
      "##              ",
      "                ",
      "                ",
      "                ",
      "                ",
      "                ",
      "                ",
      "                "
    ],
    [
      "                ",
      "   &            ",
      "   &            ",
      "   &            ",
      "   &            ",
      "                ",
      "                ",
      " #              ",
      "                ",
      "                ",
      "                ",
      "                ",
      "                ",
      "                ",
      "                ",
      "                "
    ],
    [
      "                ",
      "                ",
      "                ",
      "                ",
      "                ",
      "                ",
      "                ",
      "                ",
      "                ",
      "                ",
      "                ",
      "                ",
      "                ",
      "                ",
      "                ",
      "                "
    ],
    [
      "                ",
      "                ",
      "                ",
      "                ",
      "                ",
      "                ",
      "                ",
      "                ",
      "                ",
      "                ",
      "                ",
      "                ",
      "                ",
      "                ",
      "                ",
      "                "
    ],
    [
      "                ",
      "                ",
      "                ",
      "                ",
      "                ",
      "                ",
      "                ",
      "                ",
      "                ",
      "                ",
      "                ",
      "                ",
      "                ",
      "                ",
      "                ",
      "                "
    ],
    [
      "                ",
      "                ",
      "                ",
      "                ",
      "                ",
      "                ",
      "                ",
      "                ",
      "                ",
      "                ",
      "                ",
      "                ",
      "                ",
      "                ",
      "                ",
      "                "
    ]
  ]
}