{
  "xsize": 16,
  "zsize": 16,
  "refpalette": "pomkotsmechs:scattered",
  "slices": [
    [
      "                ",
      "                ",
      "                ",
      "                ",
      "                ",
      "                ",
      "                ",
      "                ",
      "                ",
      "                ",
      "                ",
      "                ",
      "                ",
      "                ",
      "                ",
      "                "
    ],
    [
      "                ",
      "                ",
      "                ",
      "                ",
      "                ",
      "                ",
      "                ",
      "                ",
      "                ",
      "                ",
      "                ",
      "                ",
      "                ",
      "                ",
      "                ",
      "                "
    ],
    [
      "                ",
      "                ",
      "                ",
      "                ",
      "                ",
      "                ",
      "                ",
      "                ",
      "                ",
      "                ",
      "                ",
      "                ",
      "                ",
      "                ",
      "                ",
      "                "
    ],
    [
      "                ",
      "                ",
      "                ",
      "                ",
      "                ",
      "                ",
      "                ",
      "                ",
      "                ",
      "                ",
      "                ",
      "                ",
      "                ",
      "                ",
      "                ",
      "                "
    ],
    [
      "                ",
      "                ",
      "                ",
      "                ",
      "                ",
      "                ",
      "                ",
      "                ",
      "                ",
      "                ",
      "                ",
      "                ",
      "                ",
      "                ",
      "                ",
      "                "
    ],
    [
      "                ",
      "                ",
      "                ",
      "                ",
      "                ",
      "                ",
      "                ",
      "                ",
      "                ",
      "                ",
      "                ",
      "                ",
      "                ",
      "                ",
      "                ",
      "                "
    ],
    [
      "                ",
      "                ",
      "                ",
      "                ",
      "                ",
      "                ",
      "                ",
      "                ",
      "                ",
      "                ",
      "                ",
      "                ",
      "                ",
      "                ",
      "                ",
      "                "
    ],
    [
      "                ",
      "                ",
      "                ",
      "                ",
      "                ",
      "                ",
      "                ",
      "                ",
      "                ",
      "                ",
      "                ",
      "                ",
      "                ",
      "                ",
      "                ",
      "                "
    ],
    [
      "                ",
      "                ",
      "                ",
      "                ",
      "                ",
      "                ",
      "                ",
      "                ",
      "                ",
      "                ",
      "                ",
      "                ",
      "                ",
      "                ",
      "                ",
      "                "
    ],
    [
      "................",
      "................",
      "................",
      "................",
      "................",
      "................",
      "................",
      "................",
      "................",
      "................",
      "................",
      "................",
      "................",
      "................",
      "................",
      "................"
    ],
    [
      "................",
      "................",
      "................",
      "................",
      "................",
      "................",
      "................",
      "................",
      "................",
      "................",
      "................",
      "................",
      "................",
      "................",
      "................",
      "................"
    ],
    [
      "                ",
      "                ",
      "                ",
      "                ",
      "                ",
      "                ",
      "                ",
      "                ",
      "                ",
      "                ",
      "                ",
      "                ",
      "                ",
      "                ",
      "                ",
      "                "
    ],
    [
      "                ",
      "                ",
      "                ",
      "                ",
      "                ",
      "                ",
      "                ",
      "                ",
      "                ",
      "                ",
      "                ",
      "                ",
      "                ",
      "                ",
      "                ",
      "                "
    ],
    [
      "                ",
      "                ",
      "                ",
      "                ",
      "                ",
      "                ",
      "                ",
      "                ",
      "                ",
      "                ",
      "                ",
      "                ",
      "                ",
      "                ",
      "                ",
      "                "
    ],
    [
      "                ",
      "                ",
      "                ",
      "                ",
      "                ",
      "                ",
      "            ##  ",
      "             #  ",
      "                ",
      "                ",
      "                ",
      "                ",
      "    ##          ",
      "     ##         ",
      "                ",
      "                "
    ],
    [
      "................",
      "................",
      "................",
      "................",
      "................",
      "................",
      "................",
      "................",
      "................",
      "................",
      "................",
      "................",
      "................",
      "................",
      "................",
      "................"
    ],
    [
      "                ",
      "                ",
      "                ",
      "               .",
      "              ST",
      "              ST",
      "            ##ST",
      "            ##ST",
      "             #ST",
      "              ST",
      "               .",
      "    #          U",
      "   ###          ",
      "    ###         ",
      "                ",
      "                "
    ],
    [
      "                ",
      "                ",
      "                ",
      "               .",
      "                ",
      "                ",
      "                ",
      "             ###",
      "              ##",
      "               #",
      "               .",
      "    #          U",
      "   ###          ",
      "    #           ",
      "                ",
      "                "
    ],
    [
      "                ",
      "                ",
      "                ",
      "               .",
      "                ",
      "                ",
      "                ",
      "               #",
      "              ##",
      "               #",
      "               .",
      "    #          U",
      "   ###          ",
      "    #           ",
      "                ",
      "                "
    ],
    [
      "                ",
      "                ",
      "                ",
      "               .",
      "                ",
      "                ",
      "                ",
      "               #",
      "              ##",
      "               #",
      "               .",
      "    #          U",
      "   ###          ",
      "    #           ",
      "                ",
      "                "
    ],
    [
      "                ",
      "                ",
      "                ",
      "               A",
      "                ",
      "                ",
      "                ",
      "               #",
      "              ##",
      "              ##",
      "               A",
      "    #          U",
      "   ###          ",
      "    #           ",
      "                ",
      "                "
    ],
    [
      "                ",
      "                ",
      "                ",
      "               A",
      "                ",
      "                ",
      "                ",
      "                ",
      "               #",
      "              ##",
      "               .",
      "    ##         U",
      "   ####         ",
      "    ##          ",
      "                ",
      "                "
    ],
    [
      "                ",
      "                ",
      "                ",
      "               .",
      "                ",
      "                ",
      "                ",
      "                ",
      "               #",
      "              ##",
      "               .",
      "     #         U",
      "    ###         ",
      "     #          ",
      "                ",
      "                "
    ],
    [
      "                ",
      "                ",
      "                ",
      "               .",
      "                ",
      "                ",
      "                ",
      "                ",
      "               #",
      "              ##",
      "               .",
      "     #         U",
      "    ###         ",
      "     #          ",
      "                ",
      "                "
    ],
    [
      "                ",
      "                ",
      "                ",
      "               A",
      "               .",
      "               .",
      "               .",
      "               .",
      "               .",
      "              #.",
      "               A",
      "     #         .",
      "    ###        .",
      "     #          ",
      "                ",
      "                "
    ],
    [
      "                ",
      "                ",
      "                ",
      "               .",
      "                ",
      "                ",
      "                ",
      "                ",
      "               #",
      "              ##",
      "              #.",
      "     #         #",
      "    ###         ",
      "     #          ",
      "                ",
      "                "
    ],
    [
      "                ",
      "                ",
      "                ",
      "               .",
      "                ",
      "                ",
      "                ",
      "                ",
      "                ",
      "               #",
      "              #.",
      "     #         #",
      "    ###         ",
      "     #          ",
      "                ",
      "                "
    ],
    [
      "               .",
      "................",
      "................",
      "               .",
      "               .",
      "               .",
      "................",
      "................",
      "               .",
      "               .",
      "              #.",
      "................",
      "................",
      "     #          ",
      "                ",
      "                "
    ],
    [
      "                ",
      "          .     ",
      "          .     ",
      "                ",
      "                ",
      "                ",
      "                ",
      "                ",
      "                ",
      "                ",
      "               #",
      "     #    .    #",
      "    ###   .    #",
      "     #          ",
      "                ",
      "                "
    ],
    [
      "                ",
      "          .     ",
      "          .     ",
      "                ",
      "                ",
      "                ",
      "                ",
      "                ",
      "                ",
      "                ",
      "                ",
      "     #    .     ",
      "    ###   .    #",
      "     #          ",
      "                ",
      "                "
    ],
    [
      "                ",
      ".         .     ",
      ".         .     ",
      "                ",
      "                ",
      "                ",
      "                ",
      "                ",
      "                ",
      "                ",
      "                ",
      ".    #    .    #",
      ".   ###   .    #",
      "     #          ",
      "                ",
      "                "
    ],
    [
      "                ",
      "...       .     ",
      "...       .     ",
      "                ",
      "                ",
      "                ",
      "                ",
      "                ",
      "                ",
      "                ",
      "               #",
      "...  #    .   ##",
      "... ###   .    #",
      "     #          ",
      "                ",
      "                "
    ],
    [
      "                ",
      "  ....    .    .",
      "  ....    .    .",
      "                ",
      "                ",
      "                ",
      "                ",
      "                ",
      "                ",
      "                ",
      "               #",
      "  ....    .   #.",
      "  ....#   .   #.",
      "     #         #",
      "                ",
      "                "
    ],
    [
      "                ",
      "  .  ...  .  ...",
      "     ...  .  ...",
      "                ",
      "                ",
      "                ",
      "                ",
      "                ",
      "                ",
      "                ",
      "              # ",
      "  .  ...  .  ...",
      "  . #...  .  ...",
      "     #        ##",
      "                ",
      "                "
    ],
    [
      "                ",
      "       .......  ",
      "       .......  ",
      "                ",
      "                ",
      "                ",
      "                ",
      "                ",
      "                ",
      "                ",
      "             ## ",
      " ..    .......##",
      " ..  # .......##",
      "                ",
      "                ",
      "                "
    ],
    [
      "                ",
      "       .  .  .  ",
      "       .  .  .  ",
      "                ",
      "                ",
      "                ",
      "                ",
      "                ",
      "                ",
      "                ",
      "             ## ",
      " .     .  . #.##",
      " .     .  .  .##",
      "              # ",
      "                ",
      "                "
    ],
    [
      "                ",
      "      ..  .  .. ",
      "      ..  .  .. ",
      "                ",
      "                ",
      "                ",
      "                ",
      "                ",
      "J               ",
      "J               ",
      "J               ",
      "..    ..  .  .. ",
      "..    ..  .  ..#",
      "J             # ",
      "J               ",
      "J               "
    ],
    [
      "                ",
      "      .   .   . ",
      "      .   .   . ",
      "                ",
      "                ",
      "                ",
      " .              ",
      " .              ",
      " J              ",
      " J              ",
      " J              ",
      " .    .   .   . ",
      " .    .   .  #.#",
      " J            # ",
      " J              ",
      " J              "
    ],
    [
      "  JJ          ##",
      "  ..  .   .   . ",
      "  ..  .   .   . ",
      "  JJ            ",
      "  JJ            ",
      " .JJ            ",
      " ...            ",
      " ...            ",
      " .JJ            ",
      " .JJ            ",
      " .JJ            ",
      " ...  .   .   .#",
      " ...  .   .  #.#",
      " .JJ          ##",
      " .JJ            ",
      " .JJ            "
    ],
    [
      "    JJ       ##J",
      "    ...   .  #..",
      "    ...   .###..",
      "    JJ    ##   J",
      "    JJ         J",
      "    JJ    #    J",
      "    ...   #   ..",
      "    ...   #   ..",
      "    JJ    #    J",
      "    JJ    #    J",
      "    JJ    ##   J",
      "    ...   .#  ..",
      "    ... ##.# #..",
      "    JJ ##  #  #J",
      "    JJ##       J",
      "    JJ#        J"
    ],
    [
      "      .JJJJJJJ.#",
      "      .........#",
      "      ......... ",
      "      .JJJJJJJ. ",
      "      .JJJJJJJ. ",
      "      .JJJJJJJ. ",
      "      ......... ",
      "      ......... ",
      "      .JJJJJJJ. ",
      "      .JJJJJJJ. ",
      "      .JJJJJJJ. ",
      "      .........#",
      "      .........#",
      "      .JJJJJJJ.#",
      "     #.JJJJJJJ. ",
      "     #.JJJJJJJ. "
    ],
    [
      "             ## ",
      "             ## ",
      "           ###  ",
      "          ##    ",
      "                ",
      "          #     ",
      "          #     ",
      "          #     ",
      "          #     ",
      "          #     ",
      "         ###    ",
      "         ###    ",
      "        #### ###",
      "       #####    ",
      "      ##        ",
      "      #         "
    ],
    [
      "                ",
      "                ",
      "                ",
      "                ",
      "                ",
      "                ",
      "                ",
      "                ",
      "                ",
      "                ",
      "          #     ",
      "          #     ",
      "         ##     ",
      "                ",
      "                ",
      "                "
    ],
    [
      "                ",
      "                ",
      "                ",
      "                ",
      "                ",
      "                ",
      "                ",
      "                ",
      "                ",
      "                ",
      "                ",
      "                ",
      "                ",
      "                ",
      "                ",
      "                "
    ],
    [
      "                ",
      "                ",
      "                ",
      "                ",
      "                ",
      "                ",
      "                ",
      "                ",
      "                ",
      "                ",
      "                ",
      "                ",
      "                ",
      "                ",
      "                ",
      "                "
    ],
    [
      "                ",
      "                ",
      "                ",
      "                ",
      "                ",
      "                ",
      "                ",
      "                ",
      "                ",
      "                ",
      "                ",
      "                ",
      "                ",
      "                ",
      "                ",
      "                "
    ],
    [
      "                ",
      "                ",
      "                ",
      "                ",
      "                ",
      "                ",
      "                ",
      "                ",
      "                ",
      "                ",
      "                ",
      "                ",
      "                ",
      "                ",
      "                ",
      "                "
    ],
    [
      "                ",
      "                ",
      "                ",
      "                ",
      "                ",
      "                ",
      "                ",
      "                ",
      "                ",
      "                ",
      "                ",
      "                ",
      "                ",
      "                ",
      "                ",
      "                "
    ]
  ]
}