{
  "xsize": 16,
  "zsize": 16,
  "refpalette": "lostcities:scattered",
  "slices": [
    [
      "&&&&&&&&&&&&&&&&",
      "&&&&&&&&&&&&&&&&",
      "&&&&&&&&&&&&&&&&",
      "&&&&&&&&&&&&&&&&",
      "&&&&&&&&&&&&&&&&",
      "&&&&&&&&&&&&&&&&",
      "&&&&&&&&&&&&&&&&",
      "&&&&&&&&&&&&&&&&",
      "&&&&&&&&&&&&&&&&",
      "&&&&&&&&&&&&&&&&",
      "&&&&&&&&&&&&&&&&",
      "&&&&&&&&&&&&&&&&",
      "&&&&&&&&&&&&&&&&",
      "&&&&&&&&&&&&&&&&",
      "&&&&&&&&&&&&&&&&",
      "&&&&&&&&&&&&&&&&"
    ],
    [
      "  $$   aa     aa",
      "$$$$$$$$$$$$$$$$",
      "  $$$$$$$$$$$$$$",
      "     aaa  aaaaa ",
      "&&&&&&&&&&&&&&&&",
      "$$$$$$$$$$$$$$$$",
      "$$$$$$$$$$$$$$$$",
      "$$$$$ccccc$$$$$$",
      "$$$cc$$$$$cc$$$$",
      "$$c$$$$$$$$$c$$$",
      "$c$$$$$$$$$$$c$$",
      "$c$$$$$$$$$$$c$$",
      "c$$$$$$$$$$$$$c$",
      "c$$$$$$$$$$$$$c$",
      "c$$$$$$$$$$$$$c$",
      " $$$$$$$$$$$$$c$"
    ],
    [
      "a $$   aa     a ",
      "$$$$dddddddddddd",
      "a $$$ aaaa aaaa ",
      "     aaaa aaa   ",
      "eeeeeeeeeeeeeeee",
      "   aaaa   aa j  ",
      "   aaa   aam    ",
      "  aaa           ",
      "  a%a           ",
      "   %    j       ",
      "        aaaaaa  ",
      "        aaaaaaaa",
      "     j     aaa a",
      "        j j  aa ",
      "j          aaaaa",
      "        j aaaaaa"
    ],
    [
      "aa$$  aa    aaa ",
      "$$$$dddddddddddd",
      "aa$$$aaaa   aaa ",
      "    aaaa   a    ",
      "    aaa   aa    ",
      "    aaa         ",
      "    aa     n    ",
      "   a            ",
      "   Ͷ            ",
      "                ",
      "                ",
      "           aaa  ",
      "                ",
      "                ",
      "             aa ",
      "           aaaaa"
    ],
    [
      " a$$ aaa    a   ",
      "$$$$dddddddddddd",
      "aa$$$aaa    a   ",
      " aa  aa         ",
      "     a          ",
      "     a          ",
      "                ",
      "                ",
      "                ",
      "                ",
      "                ",
      "                ",
      "                ",
      "                ",
      "                ",
      "                "
    ],
    [
      "  $$ a a   aa   ",
      "$$$$dddddddddddd",
      " a$$$a a   aa   ",
      " aaa            ",
      "  a             ",
      "                ",
      "                ",
      "                ",
      "                ",
      "                ",
      "                ",
      "                ",
      "                ",
      "                ",
      "                ",
      "                "
    ],
    [
      "  $$  aa  aa    ",
      "$$$$dddddddddddd",
      " a$$$ aa  aa    ",
      " aaaa           ",
      "  aa            ",
      "                ",
      "                ",
      "                ",
      "                ",
      "                ",
      "                ",
      "                ",
      "                ",
      "                ",
      "                ",
      "                "
    ],
    [
      "  $$ aaa        ",
      "$$$$dddddddddddd",
      " a$$$aaa        ",
      "  aaa           ",
      "   a            ",
      "                ",
      "                ",
      "                ",
      "                ",
      "                ",
      "                ",
      "                ",
      "                ",
      "                ",
      "                ",
      "                "
    ],
    [
      "  $$ a a        ",
      "$$$$dddddddddddd",
      "  $$$a a        ",
      "  aaa           ",
      "   a            ",
      "                ",
      "                ",
      "                ",
      "                ",
      "                ",
      "                ",
      "                ",
      "                ",
      "                ",
      "                ",
      "                "
    ],
    [
      "  $$ aaa        ",
      "$$$$dddddddddddd",
      "  $$$aaa        ",
      "   a            ",
      "                ",
      "                ",
      "                ",
      "                ",
      "                ",
      "                ",
      "                ",
      "                ",
      "                ",
      "                ",
      "                ",
      "                "
    ],
    [
      "  $$  a         ",
      "$$$$dddddddddd  ",
      "  $$$aa         ",
      "   aa           ",
      "                ",
      "                ",
      "                ",
      "                ",
      "                ",
      "                ",
      "                ",
      "                ",
      "                ",
      "                ",
      "                ",
      "                "
    ],
    [
      "  $$            ",
      "$$$$dddddddddd  ",
      "  $$$a          ",
      "    a           ",
      "                ",
      "                ",
      "                ",
      "                ",
      "                ",
      "                ",
      "                ",
      "                ",
      "                ",
      "                ",
      "                ",
      "                "
    ],
    [
      "  $$            ",
      "$$$$ddddddddd   ",
      "  $$$a          ",
      "    a           ",
      "                ",
      "                ",
      "                ",
      "                ",
      "                ",
      "                ",
      "                ",
      "                ",
      "                ",
      "                ",
      "                ",
      "                "
    ],
    [
      "  $$            ",
      "$$$$ddddddddd   ",
      "  $$$a          ",
      "    a           ",
      "                ",
      "                ",
      "                ",
      "                ",
      "                ",
      "                ",
      "                ",
      "                ",
      "                ",
      "                ",
      "                ",
      "                "
    ],
    [
      "  $$            ",
      "$$$$ddddddddd   ",
      "  $$$a a        ",
      "    a     a     ",
      "          a     ",
      "          a     ",
      "          aa    ",
      "           aa   ",
      "            aaa ",
      "              aa",
      "               a",
      "               a",
      "                ",
      "                ",
      "                ",
      "                "
    ],
    [
      "  $$   a        ",
      "$$$$ddddddddd   ",
      "  $$$ aaa a     ",
      "hhhhhhhhhhhhh   ",
      "&&&&&&&&&&&&&&  ",
      "&&&&&&&&&&&&&&&&",
      "$$$$$$$$$$$$$$$$",
      "$$$$$$$$$$$$$$$$",
      "$$$$$$$$$$$$$$$$",
      "$$$$$$$$$$$$$$$$",
      "$$$$$$$$$$$$$$$$",
      "$$$$$$$$$$$$$$$$",
      "$$$$$$$$$$$$$$$$",
      "$$$$$$$$$$$$$$$$",
      "$$$$$$$$     $$$",
      "$$$$$$$        $"
    ],
    [
      "  $$ aaa        ",
      "$$$$ddddddddd   ",
      "  $$$aaaaaa     ",
      "eeeeeeeeeeeeee  ",
      "       aaaa     ",
      "          a     ",
      "          aa    ",
      "           aa   ",
      "            aaa ",
      "              aa",
      "                ",
      "                ",
      "                ",
      "                ",
      "     g          ",
      "                "
    ],
    [
      "  $$aa a        ",
      "$$$$ddddddddd   ",
      "  $$$aaaaa      ",
      "    a  aaaa     ",
      "                ",
      "                ",
      "                ",
      "                ",
      "                ",
      "                ",
      "                ",
      "                ",
      "                ",
      "                ",
      "                ",
      "                "
    ],
    [
      "  $$            ",
      "$$$$dddddddddd  ",
      "  $$$a aa       ",
      "   aa           ",
      "                ",
      "                ",
      "                ",
      "                ",
      "                ",
      "                ",
      "                ",
      "                ",
      "                ",
      "                ",
      "                ",
      "                "
    ],
    [
      "  $$            ",
      "$$$$dddddddddd  ",
      " a$$$           ",
      "   a            ",
      "                ",
      "                ",
      "                ",
      "                ",
      "                ",
      "                ",
      "                ",
      "                ",
      "                ",
      "                ",
      "                ",
      "                "
    ],
    [
      "aa$$            ",
      "$$$$dddddddddd  ",
      "aa$$$           ",
      " aaa            ",
      "                ",
      "                ",
      "                ",
      "                ",
      "                ",
      "                ",
      "                ",
      "                ",
      "                ",
      "                ",
      "                ",
      "                "
    ],
    [
      "  $$            ",
      "$$$$dddddddddd  ",
      " a$$$           ",
      "  a             ",
      "                ",
      "                ",
      "                ",
      "                ",
      "                ",
      "                ",
      "                ",
      "                ",
      "                ",
      "                ",
      "                ",
      "                "
    ],
    [
      "  $$            ",
      "$$$$dddddddddd  ",
      "  $$$           ",
      "                ",
      "                ",
      "                ",
      "                ",
      "                ",
      "                ",
      "                ",
      "                ",
      "                ",
      "                ",
      "                ",
      "                ",
      "                "
    ],
    [
      "  $$            ",
      "$$$$dddddddddd  ",
      "  $$$           ",
      "                ",
      "                ",
      "                ",
      "                ",
      "                ",
      "                ",
      "                ",
      "                ",
      "                ",
      "                ",
      "                ",
      "                ",
      "                "
    ],
    [
      "  $$            ",
      "$$$$         d  ",
      "  $$$           ",
      "                ",
      "                ",
      "                ",
      "                ",
      "                ",
      "                ",
      "                ",
      "                ",
      "                ",
      "                ",
      "                ",
      "                ",
      "                "
    ],
    [
      "                ",
      "$$$             ",
      "  $             ",
      "                ",
      "                ",
      "                ",
      "                ",
      "                ",
      "                ",
      "                ",
      "                ",
      "                ",
      "                ",
      "                ",
      "                ",
      "                "
    ],
    [
      "                ",
      "$$              ",
      "$$$             ",
      "                ",
      "                ",
      "                ",
      "                ",
      "                ",
      "                ",
      "                ",
      "                ",
      "                ",
      "                ",
      "                ",
      "                ",
      "                "
    ],
    [
      "                ",
      "$               ",
      "$$              ",
      "                ",
      "                ",
      "                ",
      "                ",
      "                ",
      "                ",
      "                ",
      "                ",
      "                ",
      "                ",
      "                ",
      "                ",
      "                "
    ],
    [
      "                ",
      "                ",
      "                ",
      "                ",
      "                ",
      "                ",
      "                ",
      "                ",
      "                ",
      "                ",
      "                ",
      "                ",
      "                ",
      "                ",
      "                ",
      "                "
    ],
    [
      "                ",
      "                ",
      "                ",
      "                ",
      "                ",
      "                ",
      "                ",
      "                ",
      "                ",
      "                ",
      "                ",
      "                ",
      "                ",
      "                ",
      "                ",
      "                "
    ],
    [
      "                ",
      "                ",
      "&&$             ",
      "                ",
      "&&&&&           ",
      "&&&&&           ",
      "                ",
      "                ",
      "                ",
      "                ",
      "                ",
      "                ",
      "                ",
      "                ",
      "                ",
      "                "
    ],
    [
      "$$$             ",
      "$$$             ",
      "$$$$            ",
      "$$$$$           ",
      "$$$$$           ",
      "$$$$$$          ",
      "$$$$$$$         ",
      "                ",
      "                ",
      "                ",
      "                ",
      "                ",
      "                ",
      "                ",
      "                ",
      "                "
    ],
    [
      "lllll           ",
      "llll            ",
      "llll            ",
      "llll            ",
      "lllll           ",
      "llllll          ",
      "llllllll        ",
      "llllllllllll    ",
      "llllllllllllllll",
      "llllllllllllllll",
      "llllllllllllllll",
      "llllllllllllllll",
      "llllllllllllllll",
      "llllllllllllllll",
      "llllllllllllllll",
      "llllllllllllllll"
    ],
    [
      "                ",
      "                ",
      "                ",
      "                ",
      "                ",
      "                ",
      "                ",
      "                ",
      "                ",
      "                ",
      "                ",
      "                ",
      "     j          ",
      "                ",
      "j               ",
      "        j       "
    ],
    [
      "                ",
      "                ",
      "                ",
      "                ",
      "                ",
      "                ",
      "                ",
      "                ",
      "                ",
      "                ",
      "                ",
      "                ",
      "                ",
      "                ",
      "                ",
      "                "
    ],
    [
      "                ",
      "                ",
      "                ",
      "                ",
      "                ",
      "                ",
      "                ",
      "                ",
      "                ",
      "                ",
      "                ",
      "                ",
      "                ",
      "                ",
      "                ",
      "                "
    ]
  ]
}