{
  "xsize": 16,
  "zsize": 16,
  "refpalette": "pomkotsmechs:scattered",
  "slices": [
    [
      "                ",
      "             %% ",
      "             %% ",
      "                ",
      "     $$         ",
      "    $$$$        ",
      "    $$$$        ",
      "     $$         ",
      "           #    ",
      "           #    ",
      "                ",
      "                ",
      "                ",
      " %%             ",
      " %%             ",
      "                "
    ],
    [
      "                ",
      "             %% ",
      "             %%2",
      "            &002",
      "     $$   &&&002",
      "    $$$$ &&&&000",
      "    $$$$vvv&&&00",
      "     $$vvvvv&&00",
      "      vvvvvv&&00",
      "     0&vvvvv&&00",
      "    320&vvvv&000",
      "    3320&vvv&022",
      "   33330&vv&&02v",
      " %%33330&vv&022v",
      " %%33320&vv&02vv",
      "  22220&&&&&00vv"
    ],
    [
      "                ",
      "             %% ",
      "             %%$",
      "            $$  ",
      "     $$   $$    ",
      "    $$$$ $      ",
      "    $$$$$       ",
      "     $$$        ",
      "     #$#   ##   ",
      "     $#  $$$$$$$",
      "    $    $$$$$$$",
      "    $    $$$$$$$",
      "   $     $$$$$$$",
      " %%$     $$$$$$$",
      " %%      $$$$$$$",
      " #$#     $$$$$$$"
    ],
    [
      "                ",
      "             %% ",
      "            #%%$",
      "           #$$  ",
      "     $$   $$#   ",
      "    $$$$ $      ",
      "    $$$$$       ",
      "     $$$        ",
      "     #$#        ",
      "     $#    ###  ",
      "    $     $$$$$$",
      "    $     $ ####",
      "   $      $  ###",
      " %%$      $   ##",
      " %%       $    #",
      " #$#      $     "
    ],
    [
      "                ",
      "             %% ",
      "           ##%%$",
      "          ##$$  ",
      "     $$   $$#   ",
      "    $$$$ $ #    ",
      "    $$$$$       ",
      "     $$$        ",
      "    ##$#        ",
      "    #$#         ",
      "    $#      ### ",
      "    $      $$$$#",
      "   $       $ ###",
      " %%$       $   #",
      " %%        $   #",
      " #$#       $    "
    ],
    [
      "                ",
      "             %% ",
      "             %%$",
      "           #$$  ",
      "    #$$   $$#   ",
      "   #$$$$ $ #    ",
      "    $$$$$       ",
      "     $$$        ",
      "     #$         ",
      "    #$#         ",
      "    $#          ",
      "    $        ## ",
      "   $        $$  ",
      " %%$        $  #",
      " %%         $   ",
      " #$#        $   "
    ],
    [
      "                ",
      "             %% ",
      "             %%$",
      "           #$$  ",
      "    #$$   $$#   ",
      "   #$$$$ $ #    ",
      "    $$$$$       ",
      "     $$$        ",
      "    ##$         ",
      "   ##$#         ",
      "   #$#          ",
      "    $           ",
      "   $        $$  ",
      " %%$        $  #",
      " %%         $   ",
      " #$#        $   "
    ],
    [
      "                ",
      "             %% ",
      "             %%$",
      "           #$$  ",
      "    #$$   $$#   ",
      "   #$$$$ $ #    ",
      "    $$$$$       ",
      "     $$$        ",
      "      $         ",
      "    #$          ",
      "   #$#          ",
      "   #$#          ",
      "   $#           ",
      " %%$         $$#",
      " %%          $  ",
      " #$#         $  "
    ],
    [
      "                ",
      "             %% ",
      "             %%$",
      "     #     #$$  ",
      "    #$$   $$#   ",
      "   #$$$$ $ #    ",
      "    $$$$$       ",
      "     $$$        ",
      "      $         ",
      "     $          ",
      "   #$           ",
      "  ##$#          ",
      "  #$#           ",
      " %%$            ",
      " %%           $$",
      " #$#          $ "
    ],
    [
      "                ",
      "             %  ",
      "             %  ",
      "     #    ##$   ",
      "    #$$  #$$#   ",
      "    $$$$ $##    ",
      "    $$$$$       ",
      "     $$$        ",
      "      $         ",
      "     $          ",
      "    $           ",
      "  ##$           ",
      " ##$#           ",
      " %%$            ",
      " %%             ",
      " #$#           $"
    ],
    [
      "                ",
      "                ",
      "                ",
      "     #    #     ",
      "    #$$  #$$    ",
      "    $$$$ $#     ",
      "    $$$$$       ",
      "     $$$        ",
      "      $         ",
      "     $          ",
      "    $           ",
      "  # $           ",
      " ##$            ",
      "#%%$            ",
      " %%             ",
      " #$#           $"
    ],
    [
      "                ",
      "                ",
      "                ",
      "     #    #     ",
      "    #$$  #$$    ",
      "    $$$$ $#     ",
      "    $$$$$       ",
      "     $$$        ",
      "      $         ",
      "     $          ",
      "    $           ",
      "    $           ",
      " ##$            ",
      "##%$            ",
      " #%#            ",
      " #$##           "
    ],
    [
      "                ",
      "                ",
      "                ",
      "     #          ",
      "    #$$   #     ",
      "    $$$$        ",
      "    $$$$        ",
      "     $$         ",
      "                ",
      "                ",
      "                ",
      "                ",
      "                ",
      " #%             ",
      "  %#            ",
      " ####           "
    ],
    [
      "                ",
      "                ",
      "                ",
      "     #          ",
      "    #$$         ",
      "    $$$$        ",
      "    $$$$        ",
      "     $$         ",
      "                ",
      "                ",
      "                ",
      "                ",
      "                ",
      " %%             ",
      " %%             ",
      "  ##            "
    ],
    [
      "                ",
      "                ",
      "                ",
      "     #          ",
      "    #$$         ",
      "    $$$$        ",
      "    $$$$        ",
      "     $$         ",
      "                ",
      "                ",
      "                ",
      "                ",
      "                ",
      "                ",
      "                ",
      "                "
    ],
    [
      "                ",
      "                ",
      "                ",
      "     #          ",
      "    #$$         ",
      "    $$$$        ",
      "    $$$$        ",
      "     $$         ",
      "                ",
      "                ",
      "                ",
      "                ",
      "                ",
      "                ",
      "                ",
      "                "
    ],
    [
      "                ",
      "                ",
      "                ",
      "     ##         ",
      "    #$$#        ",
      "    $$$$        ",
      "    $$$$        ",
      "     $$         ",
      "                ",
      "                ",
      "                ",
      "                ",
      "                ",
      "                ",
      "                ",
      "                "
    ],
    [
      "                ",
      "                ",
      "                ",
      "      #         ",
      "     $$#        ",
      "    $$$$        ",
      "    $$$$        ",
      "     $$         ",
      "                ",
      "                ",
      "                ",
      "                ",
      "                ",
      "                ",
      "                ",
      "                "
    ],
    [
      "                ",
      "                ",
      "      #         ",
      "     $$#        ",
      "    $$$$        ",
      "   $$$$$$       ",
      "   $$$$$$       ",
      "    $$$$        ",
      "     $$         ",
      "                ",
      "                ",
      "                ",
      "                ",
      "                ",
      "                ",
      "                "
    ],
    [
      "                ",
      "                ",
      "                ",
      "      #         ",
      "    $$$$        ",
      "    $$$$        ",
      "    $$$$        ",
      "    $$$$        ",
      "                ",
      "                ",
      "                ",
      "                ",
      "                ",
      "                ",
      "                ",
      "                "
    ],
    [
      "                ",
      "                ",
      "                ",
      "                ",
      "    $  $        ",
      "                ",
      "                ",
      "    $  $        ",
      "                ",
      "                ",
      "                ",
      "                ",
      "                ",
      "                ",
      "                ",
      "                "
    ],
    [
      "                ",
      "                ",
      "                ",
      "                ",
      "    $  $        ",
      "                ",
      "                ",
      "    $  $        ",
      "                ",
      "                ",
      "                ",
      "                ",
      "                ",
      "                ",
      "                ",
      "                "
    ],
    [
      "                ",
      "                ",
      "                ",
      "                ",
      "    $  $        ",
      "                ",
      "                ",
      "    $  $        ",
      "                ",
      "                ",
      "                ",
      "                ",
      "                ",
      "                ",
      "                ",
      "                "
    ],
    [
      "                ",
      "                ",
      "                ",
      "     $$         ",
      "    $$$$        ",
      "   $$  $$       ",
      "   $$  $$       ",
      "    $$$$        ",
      "     $$         ",
      "                ",
      "                ",
      "                ",
      "                ",
      "                ",
      "                ",
      "                "
    ]
  ]
}