{
  "xsize": 16,
  "zsize": 16,
  "refpalette": "lostcities:scattered",
  "slices": [
    [
      "$$$$$$$$$$$&&&&&",
      "$$$$$$$$$$$&&&&&",
      "$$$$$$$$$$$&&&&&",
      "$$$$$$$$$$$&&&&&",
      "$$$$$$$$$$$&&&&&",
      "$$$$$$$$$$$&&&&&",
      "$$$$$$$$$$$&&&&&",
      "$$$$$$$$$$$&&&&&",
      "$$$$$$$$$$$&&&&&",
      "$$$$$$$$$$$&&&&&",
      "$$$$$$$$$$$&&&&&",
      "$$$$$$$$$$$&&&&&",
      "$$$$$$$$$$$$$$&&",
      "$$$$$$$$$$$$$$&&",
      "$$$$$$$$$$$$$$&&",
      "$$$$$$$$$$$$$$&&"
    ],
    [
      "       a      $$",
      "$$$$$$$$$$$$$$$$",
      "$$$$$$$$$$$$$$$$",
      "      aaa   &&&&",
      "       a    &&&&",
      "   j        &&&$",
      " m       j  &&$$",
      "             &$$",
      "             &$$",
      "   j       j &$$",
      "             &$$",
      "             &$$",
      "             S$$",
      "    j        S$$",
      "          j  S$$",
      "      m  j  j   "
    ],
    [
      "       a      $$",
      "dddddddddddddd$$",
      "       a     $$$",
      "       a       a",
      "             &&e",
      "             && ",
      " n           j  ",
      "                ",
      "                ",
      "                ",
      "                ",
      "                ",
      "                ",
      "                ",
      "                ",
      "      n         "
    ],
    [
      "       a      $$",
      "dddddddddddddd$$",
      "       a     $$$",
      "                ",
      "             z{ ",
      "             |} ",
      "                ",
      "                ",
      "                ",
      "                ",
      "                ",
      "                ",
      "                ",
      "                ",
      "                ",
      "                "
    ],
    [
      "       a      $$",
      "dddddddddddddd$$",
      "       a     $$$",
      "                ",
      "             z{ ",
      "             |} ",
      "                ",
      "                ",
      "                ",
      "                ",
      "                ",
      "                ",
      "                ",
      "                ",
      "                ",
      "                "
    ],
    [
      "       a      $$",
      "dddddddddddddd$$",
      "       a     $$$",
      "                ",
      "             z{ ",
      "             |} ",
      "                ",
      "                ",
      "                ",
      "                ",
      "                ",
      "                ",
      "                ",
      "                ",
      "                ",
      "                "
    ],
    [
      "       a      $$",
      "dddddddddddddd$$",
      "       a     $$$",
      "                ",
      "             z{ ",
      "             |} ",
      "                ",
      "                ",
      "                ",
      "                ",
      "                ",
      "                ",
      "                ",
      "                ",
      "                ",
      "                "
    ],
    [
      "       a      $$",
      "dddddddddddddd$$",
      "       a     $$$",
      "                ",
      "             z{ ",
      "             |} ",
      "                ",
      "                ",
      "                ",
      "                ",
      "                ",
      "                ",
      "                ",
      "                ",
      "                ",
      "                "
    ],
    [
      "       a      $$",
      "dddddddddddddd$$",
      "       a     $$$",
      "                ",
      "             z{ ",
      "             |} ",
      "                ",
      "                ",
      "                ",
      "                ",
      "                ",
      "                ",
      "                ",
      "                ",
      "                ",
      "                "
    ],
    [
      "       aa     $$",
      "dddddddddddddd$$",
      "       aa    $$$",
      "                ",
      "             z{ ",
      "             |} ",
      "                ",
      "                ",
      "                ",
      "                ",
      "                ",
      "                ",
      "                ",
      "                ",
      "                ",
      "                "
    ],
    [
      "        a     $$",
      "dddddddddddddd$$",
      "        a    $$$",
      "                ",
      "             z{ ",
      "             |} ",
      "                ",
      "                ",
      "                ",
      "                ",
      "                ",
      "                ",
      "                ",
      "                ",
      "                ",
      "                "
    ],
    [
      "        a     $$",
      "dddddddddddddd$$",
      "        a    $$$",
      "                ",
      "             z{ ",
      "             |} ",
      "                ",
      "                ",
      "                ",
      "                ",
      "                ",
      "                ",
      "                ",
      "                ",
      "                ",
      "                "
    ],
    [
      "        a     $$",
      "dddddddddddddd$$",
      "        a    $$$",
      "                ",
      "             z{ ",
      "             |} ",
      "                ",
      "                ",
      "                ",
      "                ",
      "                ",
      "                ",
      "                ",
      "                ",
      "                ",
      "                "
    ],
    [
      "        a     $$",
      "dddddddddddddd$$",
      "       aa    $$$",
      "                ",
      "             z{ ",
      "             |} ",
      "                ",
      "                ",
      "                ",
      "                ",
      "                ",
      "                ",
      "                ",
      "                ",
      "                ",
      "                "
    ],
    [
      "       aa     $$",
      "dddddddddddddd$$",
      "      aaaa   $$$",
      "       aa       ",
      "             && ",
      "             && ",
      "                ",
      "                ",
      "                ",
      "                ",
      "                ",
      "                ",
      "                ",
      "                ",
      "                ",
      "                "
    ],
    [
      "  &&&& aa     $$",
      "dd&&&&dddddddd$$",
      "  &&&& aaa   $$$",
      "  &&&&  a   zhhh",
      "  &&&&      Ͳ&&&",
      "  &&&&      Ͳ&&&",
      "  &&&&      Ͳ&&$",
      "  &&&&      Ͳ&&$",
      "  &&&&      Ͳ&&$",
      "  &&&&      Ͳ&&$",
      "  &&&&      Ͳ&&$",
      "  &&&&      Ͳ&&$",
      "hh&&&&hhhhhhͱ&&$",
      "&&&&&&&&&&&&&&&$",
      "&&&&&&&&&&&&&&&$",
      "&&&&&&&&&&&&&&&$"
    ],
    [
      "      aa      $$",
      "dddddddddddddd$$",
      "  ʹ  ʹaaa    $$$",
      "  ͳ  ͳ      zhhe",
      "  ͳ  ͳ      ͲͱͰ ",
      "  ͳ  ͳ      Ͳk} ",
      "  ͳ  ͳ      ͳ   ",
      "  ͳ  ͳ      ͳ   ",
      "  ͳ  ͳ      ͳ   ",
      "  ͳ  ͳ      ͳ   ",
      "  ͳ  ͳ      ͳ   ",
      "  ͳ  ͳ      ͳ   ",
      "ee}  |eeeeee}   ",
      "                ",
      "                ",
      "                "
    ],
    [
      "     aa       $$",
      "dddddddddddddd$$",
      "     aa      $$$",
      "                ",
      "             z{ ",
      "             |} ",
      "                ",
      "                ",
      "                ",
      "                ",
      "                ",
      "                ",
      "                ",
      "                ",
      "                ",
      "                "
    ],
    [
      "     a        $$",
      "dddddddddddddd$$",
      "     a       $$$",
      "                ",
      "             z{ ",
      "             |} ",
      "                ",
      "                ",
      "                ",
      "                ",
      "                ",
      "                ",
      "                ",
      "                ",
      "                ",
      "                "
    ],
    [
      "    aa        $$",
      "dddddddddddddd$$",
      "    aa       $$$",
      "                ",
      "             z{ ",
      "             |} ",
      "                ",
      "                ",
      "                ",
      "                ",
      "                ",
      "                ",
      "                ",
      "                ",
      "                ",
      "                "
    ],
    [
      "    aa        $$",
      "dddddddddddddd$$",
      "    aa       $$$",
      "                ",
      "             z{ ",
      "             |} ",
      "                ",
      "                ",
      "                ",
      "                ",
      "                ",
      "                ",
      "                ",
      "                ",
      "                ",
      "                "
    ],
    [
      "     aaa      $$",
      "dddddddddddddd$$",
      "     aaa     $$$",
      "                ",
      "             z{ ",
      "             |} ",
      "                ",
      "                ",
      "                ",
      "                ",
      "                ",
      "                ",
      "                ",
      "                ",
      "                ",
      "                "
    ],
    [
      "       aa     $$",
      "dddddddddddddd$$",
      "       aa    $$$",
      "                ",
      "             z{ ",
      "             |} ",
      "                ",
      "                ",
      "                ",
      "                ",
      "                ",
      "                ",
      "                ",
      "                ",
      "                ",
      "                "
    ],
    [
      "        aa    $$",
      "dddddddddddddd$$",
      "        aa   $$$",
      "                ",
      "             z{ ",
      "             |} ",
      "                ",
      "                ",
      "                ",
      "                ",
      "                ",
      "                ",
      "                ",
      "                ",
      "                ",
      "                "
    ],
    [
      "         aaa  $$",
      "dddddddddddddd$$",
      "         aaa $$$",
      "                ",
      "             z{ ",
      "             |} ",
      "                ",
      "                ",
      "                ",
      "                ",
      "                ",
      "                ",
      "                ",
      "                ",
      "                ",
      "                "
    ],
    [
      "           aa $$",
      "dddddddddddddd$$",
      "           aa$$$",
      "                ",
      "             z{ ",
      "             |} ",
      "                ",
      "                ",
      "                ",
      "                ",
      "                ",
      "                ",
      "                ",
      "                ",
      "                ",
      "                "
    ],
    [
      "$$$$$$$$$$$$$$$$",
      "$$$$$$$$$$$$$$$$",
      "$$$$$$$$$$$$$$$$",
      "                ",
      "             z{ ",
      "             |} ",
      "                ",
      "                ",
      "                ",
      "                ",
      "                ",
      "                ",
      "                ",
      "                ",
      "                ",
      "                "
    ],
    [
      "$$$$$$$$$$$$$$$$",
      "$$$$$$$$$$$$$$$$",
      "$$$$$$$$$$$$$$$$",
      "                ",
      "             z{ ",
      "             |} ",
      "                ",
      "                ",
      "                ",
      "                ",
      "                ",
      "                ",
      "                ",
      "                ",
      "                ",
      "                "
    ],
    [
      "             $$$",
      "             $$$",
      "$   $   $   $$$$",
      "                ",
      "             z{ ",
      "             |} ",
      "                ",
      "                ",
      "                ",
      "                ",
      "                ",
      "                ",
      "                ",
      "                ",
      "                ",
      "                "
    ],
    [
      "             $$$",
      "             $$$",
      "$   $   $   $$$$",
      "                ",
      "             && ",
      "             && ",
      "                ",
      "                ",
      "                ",
      "                ",
      "                ",
      "                ",
      "                ",
      "                ",
      "                ",
      "                "
    ],
    [
      "             $$$",
      "             $$$",
      "$&&&$&&&$&&&$&$$",
      "            &&&&",
      "            &ͱͱ&",
      "            &ͱͱ&",
      "            &&&&",
      "             && ",
      "             && ",
      "             && ",
      "             && ",
      "             && ",
      "             && ",
      "             && ",
      "             && ",
      "             && "
    ],
    [
      "$$$$$$$$$$$$$$$$",
      "$$$$$$$$$$$$$$$$",
      "$$$$$$$$$$$$$$$$",
      "$$$$$$$$$$$$$$$$",
      "$$$$$$$$$$$$$$$$",
      "$$$$$$$$$$$$$$$$",
      "$$$$$$$$$$$$$$$$",
      "            $$$$",
      "            $$$$",
      "            $$$$",
      "            $$$$",
      "            $$$$",
      "            $$$$",
      "            $$$$",
      "            $$$$",
      "            $$$$"
    ],
    [
      "llllllllllllllll",
      "llllllllllllllll",
      "llllllllllllllll",
      "llllllllllllllll",
      "llllllllllllllll",
      "llllllllllllllll",
      "llllllllllllllll",
      "llllllllllllllll",
      "llllllllllllllll",
      "llllllllllllllll",
      "llllllllllllllll",
      "llllllllllllllll",
      "llllllllllllllll",
      "llllllllllllllll",
      "llllllllllllllll",
      "llllllllllllllll"
    ],
    [
      "                ",
      "   j            ",
      "                ",
      "   j     j      ",
      "                ",
      "   j            ",
      " j       j   j  ",
      "                ",
      "        j       ",
      "   j       j    ",
      "                ",
      "                ",
      "                ",
      "    j  j        ",
      "          j     ",
      "      j     j   "
    ],
    [
      "                ",
      "                ",
      "                ",
      "                ",
      "                ",
      "                ",
      "                ",
      "                ",
      "                ",
      "                ",
      "                ",
      "                ",
      "                ",
      "                ",
      "                ",
      "                "
    ],
    [
      "                ",
      "                ",
      "                ",
      "                ",
      "                ",
      "                ",
      "                ",
      "                ",
      "                ",
      "                ",
      "                ",
      "                ",
      "                ",
      "                ",
      "                ",
      "                "
    ]
  ]
}