{
  "xsize": 16,
  "zsize": 16,
  "refpalette": "lostcities:scattered",
  "slices": [
    [
      "&&&&j         $$",
      "&&&&       $$$$$",
      "&&&&      $$$$$$",
      "&&&&&   &&$$$$$$",
      "&&&&&&&&&&$$$$$$",
      "&&&&&&&&&&&&&$$$",
      "&&&&&&&&&&&&&$$$",
      "&&&&&&&&&&&&&$$$",
      "&&&&&&&&&&&&&$$$",
      "&&&&&&&&&&&&&$$$",
      "&&&&&&&&&&&&&$$$",
      "&&&&&&&&&&&&&$$$",
      "&&&&&&&&&&&&&$$$",
      "&&&&&&&&&&&&&$$$",
      "&&&&&&&&&&&&&$$$",
      "&&&&&&&&&&&&&$$$"
    ],
    [
      "$$$             ",
      "$$$             ",
      "$$$             ",
      "$$$       Z     ",
      "$$$$  j  $Z   j ",
      "$$$$$$c$$$&j    ",
      "$$$$$$c$$$&   j ",
      "$$$$$c$$$$&     ",
      "$$$cc$$$$$& j   ",
      "ccc$$$$$$$&    a",
      "$$$$$$$$$$&& j a",
      "$$$$$$$$$&&&   a",
      "&&&&&&&&&&&&   a",
      "$$$$$$$&&$$$$$$$",
      "$$$$$$$$$$$$$$$$",
      "     $$  $$     "
    ],
    [
      "ww              ",
      "www             ",
      " w              ",
      "                ",
      " m              ",
      "   j            ",
      "         m      ",
      "                ",
      "    j   j m     ",
      "                ",
      "  j      m      ",
      "         &&     ",
      "eeeeeeeee&&     ",
      "    $$    $$  aa",
      "+++++$     +++++",
      "     $         a"
    ],
    [
      "                ",
      "ww              ",
      "                ",
      "                ",
      " n              ",
      "                ",
      "         n      ",
      "                ",
      "          n     ",
      "                ",
      "         n      ",
      "         z{     ",
      "         |}     ",
      "    $$     $  aa",
      "+++++       ++++",
      "               a"
    ],
    [
      "                ",
      "mw              ",
      "                ",
      "                ",
      "                ",
      "                ",
      "                ",
      "                ",
      "                ",
      "                ",
      "                ",
      "         z{     ",
      "          }     ",
      "    $         aa",
      "+++++       ++++",
      "               a"
    ],
    [
      "ww              ",
      "nw              ",
      " p              ",
      "                ",
      "                ",
      "                ",
      "                ",
      "                ",
      "                ",
      "                ",
      "                ",
      "         z{     ",
      "                ",
      "    $         aa",
      "+++++        +++",
      "               a"
    ],
    [
      "pwp             ",
      "wwp             ",
      "ppr             ",
      "                ",
      "                ",
      "                ",
      "                ",
      "                ",
      "                ",
      "                ",
      "                ",
      "         z{     ",
      "                ",
      "    $         aa",
      "+++++        +++",
      "              aa"
    ],
    [
      "wtp             ",
      "wpwp            ",
      "tppr            ",
      "prrq            ",
      " q              ",
      "                ",
      "                ",
      "                ",
      "                ",
      "                ",
      "                ",
      "          {     ",
      "                ",
      "    $         a ",
      "+++++        +++",
      "              a "
    ],
    [
      "wprq            ",
      "pppr            ",
      "wprqs           ",
      "prqs            ",
      "rqs             ",
      "                ",
      "                ",
      "                ",
      "                ",
      "                ",
      "                ",
      "          {     ",
      "                ",
      "    $         a ",
      "+++++        +++",
      "              a "
    ],
    [
      "wprq            ",
      "tupr            ",
      "pprq            ",
      "rrqs            ",
      "qq              ",
      "                ",
      "                ",
      "p               ",
      "                ",
      "                ",
      "                ",
      "          {     ",
      "                ",
      "    $         a ",
      "+++++        +++",
      "              a "
    ],
    [
      "ppr             ",
      "pwpr            ",
      "rprq            ",
      "qrq             ",
      "                ",
      "r               ",
      "rq              ",
      "r               ",
      "q               ",
      "                ",
      "                ",
      "         z{     ",
      "                ",
      "    $         aa",
      "+++++        +++",
      "              aa"
    ],
    [
      "rpr             ",
      " wpr            ",
      "rpr             ",
      "qr              ",
      "r               ",
      "q               ",
      "qs              ",
      "qs              ",
      "s               ",
      "                ",
      "                ",
      "         z{     ",
      "                ",
      "    $          a",
      "+++++        +++",
      "               a"
    ],
    [
      "qrq             ",
      "rpr             ",
      "qrq             ",
      "                ",
      "q               ",
      "s               ",
      "s               ",
      "sx              ",
      "x               ",
      "y               ",
      "                ",
      "         z{     ",
      "                ",
      "    $          a",
      "++++         +++",
      "               a"
    ],
    [
      "sq              ",
      "qrq             ",
      "                ",
      "                ",
      "s               ",
      "x               ",
      "x               ",
      "x               ",
      "y               ",
      "                ",
      "                ",
      "         z{     ",
      "          }     ",
      "               a",
      "+++          +++",
      "               a"
    ],
    [
      "xs              ",
      "s               ",
      "                ",
      "                ",
      "                ",
      "                ",
      "y               ",
      "y               ",
      "                ",
      "                ",
      "                ",
      "         &&     ",
      "          &     ",
      "               a",
      "+           ++++",
      "               a"
    ],
    [
      "         &&Ͱ    ",
      "         &&Ͱ    ",
      "         &&Ͱ    ",
      "         &&Ͱ    ",
      "         &&Ͱ    ",
      "         &&Ͱ    ",
      "         &&Ͱ    ",
      "         &&Ͱ    ",
      "         &&Ͱ    ",
      "         &&Ͱ    ",
      "         &&Ͱ    ",
      "&&&&&&&&&&&Ͱ    ",
      "&&&&      &Ͱ    ",
      "k          $  aa",
      "            ++++",
      "               a"
    ],
    [
      "           ͳ    ",
      "           ͳ    ",
      "           ͳ    ",
      "           ͳ    ",
      "           ͳ    ",
      "           ͳ    ",
      "           ͳ    ",
      "           ͳ    ",
      "           ͳ    ",
      "           ͳ    ",
      "           ͳ    ",
      "         zhͰ    ",
      "          ͱͰ    ",
      "           $  aa",
      "            ++++",
      "                "
    ],
    [
      "                ",
      "                ",
      "                ",
      "                ",
      "                ",
      "                ",
      "                ",
      "                ",
      "                ",
      "                ",
      "                ",
      "         z{     ",
      "          }     ",
      "           $   a",
      "           +++++",
      "                "
    ],
    [
      "                ",
      "                ",
      "                ",
      "                ",
      "                ",
      "                ",
      "                ",
      "                ",
      "                ",
      "                ",
      "                ",
      "         z{     ",
      "          }     ",
      "           $    ",
      "           +++++",
      "                "
    ],
    [
      "                ",
      "                ",
      "                ",
      "                ",
      "                ",
      "                ",
      "                ",
      "                ",
      "                ",
      "                ",
      "                ",
      "         z{     ",
      "          }     ",
      "           $    ",
      "           +++++",
      "                "
    ],
    [
      "                ",
      "                ",
      "                ",
      "                ",
      "                ",
      "                ",
      "                ",
      "                ",
      "                ",
      "                ",
      "                ",
      "         z{     ",
      "          }     ",
      "           $    ",
      "           +++++",
      "                "
    ],
    [
      "                ",
      "                ",
      "                ",
      "                ",
      "                ",
      "                ",
      "                ",
      "                ",
      "                ",
      "                ",
      "                ",
      "         z{     ",
      "          }     ",
      "           $    ",
      "           +++++",
      "                "
    ],
    [
      "                ",
      "                ",
      "                ",
      "                ",
      "                ",
      "                ",
      "                ",
      "                ",
      "                ",
      "                ",
      "                ",
      "         z{     ",
      "          }     ",
      "           $    ",
      "           +++++",
      "                "
    ],
    [
      "                ",
      "                ",
      "                ",
      "                ",
      "                ",
      "                ",
      "                ",
      "                ",
      "                ",
      "                ",
      "                ",
      "         z{     ",
      "          }     ",
      "           $    ",
      "           +++++",
      "                "
    ],
    [
      "                ",
      "                ",
      "                ",
      "                ",
      "                ",
      "                ",
      "                ",
      "                ",
      "                ",
      "                ",
      "                ",
      "         z{     ",
      "          }     ",
      "           $    ",
      "           ++++ ",
      "                "
    ],
    [
      "                ",
      "                ",
      "                ",
      "                ",
      "                ",
      "                ",
      "                ",
      "                ",
      "                ",
      "                ",
      "                ",
      "         z{     ",
      "         |}     ",
      "          $$    ",
      "           +++  ",
      "                "
    ],
    [
      "                ",
      "                ",
      "                ",
      "                ",
      "                ",
      "                ",
      "                ",
      "                ",
      "                ",
      "                ",
      "                ",
      "         z{     ",
      "         |}     ",
      "          $$$   ",
      "          $$$   ",
      "           $$$  "
    ],
    [
      "                ",
      "                ",
      "                ",
      "                ",
      "                ",
      "                ",
      "                ",
      "                ",
      "                ",
      "                ",
      "                ",
      "         z{     ",
      "         |}     ",
      "         $$$$   ",
      "          $$$   ",
      "          $$$   "
    ],
    [
      "                ",
      "                ",
      "                ",
      "                ",
      "                ",
      "                ",
      "                ",
      "                ",
      "                ",
      "                ",
      "                ",
      "         z{     ",
      "         |}     ",
      "         $$$$   ",
      "         $$$    ",
      "          $$    "
    ],
    [
      "                ",
      "                ",
      "                ",
      "                ",
      "                ",
      "                ",
      "                ",
      "                ",
      "                ",
      "                ",
      "                ",
      "         &&     ",
      "         &&     ",
      "         $$$$   ",
      "         $$$    ",
      "         $$$    "
    ],
    [
      "         &&     ",
      "         &&     ",
      "         &&     ",
      "         &&     ",
      "         &&     ",
      "         &&     ",
      "         &&     ",
      "          &     ",
      "         &&     ",
      "         &&     ",
      "         &&&    ",
      "        &ͱͱ&    ",
      "        &ͱͱ&    ",
      "        &$$&$   ",
      "         $$$    ",
      "         $$$    "
    ],
    [
      "        $$$$    ",
      "        $$$$    ",
      "        $$$$    ",
      "        $$$$    ",
      "         $$$    ",
      "          $$    ",
      "         m$$    ",
      "          $$    ",
      "          $$    ",
      "         $$$    ",
      "         $$$$$$$",
      "        $$$$$$$$",
      "       $$$$$$$$ ",
      "       $$$$$$$  ",
      "       $$$$$$$  ",
      "       $$$$$$$$ "
    ],
    [
      "llllllllllllllll",
      "llllllllllllllll",
      "llllllllllllllll",
      "l       llllllll",
      "         lllllll",
      "          llllll",
      "         nllllll",
      "          llllll",
      "          llllll",
      "         lllllll",
      "             j  ",
      "        j       ",
      "              j ",
      "                ",
      "                ",
      "                "
    ],
    [
      "    j           ",
      "                ",
      "                ",
      "                ",
      "          j   m ",
      "                ",
      "              j ",
      "                ",
      "          j j   ",
      "                ",
      "                ",
      "                ",
      "                ",
      "                ",
      "                ",
      "                "
    ],
    [
      "                ",
      "                ",
      "                ",
      "                ",
      "              n ",
      "                ",
      "                ",
      "                ",
      "                ",
      "                ",
      "                ",
      "                ",
      "                ",
      "                ",
      "                ",
      "                "
    ],
    [
      "                ",
      "                ",
      "                ",
      "                ",
      "                ",
      "                ",
      "                ",
      "                ",
      "                ",
      "                ",
      "                ",
      "                ",
      "                ",
      "                ",
      "                ",
      "                "
    ]
  ]
}