{
  "xsize": 16,
  "zsize": 16,
  "refpalette": "pomkotsmechs:scattered",
  "slices": [
    [
      "                ",
      "                ",
      "                ",
      "                ",
      "                ",
      "                ",
      "                ",
      "                ",
      "                ",
      "                ",
      "                ",
      "                ",
      " $ $            ",
      "  $             ",
      " $ $            ",
      "                "
    ],
    [
      "02200&0vvvvvvvvv",
      "02220&&vvvvvvvvv",
      "02320&&vvvvvvvvv",
      "02220&&vvvvvvvvv",
      "0220&vvvvvvvvvvv",
      "000&&vvvvvvvvvvv",
      "&00&vvvvvvvvvvvv",
      "0000&vv&vvvvvvvv",
      "02200&&&0223vvvv",
      "222200&&023333vv",
      "2222200&&023332&",
      "223220&&&&02320&",
      "2233220&vv&020&&",
      "2233320&&v&&&&&&",
      "v23333220&&&&&&&",
      "vvv223322000&&&0"
    ],
    [
      "     (((((((((((",
      "    (!!!!!!!!!!!",
      "    (!!!!!!!!!!!",
      "    (!!!!!!!!!!!",
      "    (!!!!!!!!!!!",
      "    (!!!!!!!!!!!",
      "    (!!!!!!!!!!!",
      "    (!!!!!!!!!!!",
      "    (!!!!!!!!!!!",
      "    (!!!!!!!!!!!",
      "    (!!!!!!!!!!!",
      "    (!!!!!!!!!!!",
      "     (((((((((((",
      "                ",
      "                ",
      "                "
    ],
    [
      "            ##  ",
      "     &JJJJJJJ&J ",
      "     !##        ",
      "     !          ",
      "     !          ",
      "     !##        ",
      "     !          ",
      "     !          ",
      "     !          ",
      "     !          ",
      "     !        ##",
      "     &JJJJJJJJ&J",
      "                ",
      "                ",
      "                ",
      "                "
    ],
    [
      "            #   ",
      "     &JJJJJJJ&J ",
      "     ! #        ",
      "     J          ",
      "     J          ",
      "     J#         ",
      "     !          ",
      "     J          ",
      "     J          ",
      "     J          ",
      "     !          ",
      "     &JJJJJJJJ&J",
      "                ",
      "                ",
      "                ",
      "                "
    ],
    [
      "            #   ",
      "     &JJJJJJJ&J ",
      "     ! #        ",
      "     J          ",
      "     J          ",
      "     J          ",
      "     !#         ",
      "     J          ",
      "     J          ",
      "     J          ",
      "     !          ",
      "     &JJJJJJJJ&J",
      "                ",
      "                ",
      "                ",
      "                "
    ],
    [
      "            #   ",
      "     &JJJJJJJ&&&",
      "     ! ##       ",
      "     J          ",
      "     J          ",
      "     J          ",
      "     !##        ",
      "     J          ",
      "     J          ",
      "     J          ",
      "     !          ",
      "     &JJJJJJJJ&&",
      "                ",
      "                ",
      "                ",
      "                "
    ],
    [
      "           ##   ",
      "     &JJJJJJJ&JJ",
      "     !  #       ",
      "     !          ",
      "     !          ",
      "     !          ",
      "     !#         ",
      "     !          ",
      "     !          ",
      "     !          ",
      "     !          ",
      "     &JJJJJJJJ&J",
      "                ",
      "                ",
      "                ",
      "                "
    ],
    [
      "           #    ",
      "     &%%%%%%%&%%",
      "        #       ",
      "                ",
      "     %          ",
      "     %          ",
      "     %          ",
      "     %#         ",
      "     %          ",
      "     %          ",
      "     %          ",
      "     &%%%%%%%%&%",
      "                ",
      "                ",
      "                ",
      "                "
    ],
    [
      "                ",
      "             &  ",
      "        !!!!!!!!",
      "        !!!!!!!!",
      "      !!!!!!!!!!",
      "      !!!!!!!!!!",
      "      !!!!!!!!!!",
      "      !!!!!!!!!!",
      "      !!!!!!!!!!",
      "      !!!!!!!!!!",
      "      !!!!!!!!!!",
      "     &        & ",
      "                ",
      "                ",
      "                ",
      "                "
    ],
    [
      "           #    ",
      "        ^^^^^^^^",
      "         ^^^^^^^",
      "         ^^^^^^^",
      "     ^    ^^^^^^",
      "     ^^   ^^^^^^",
      "     ^^^^^^^^^^^",
      "     ^^^^^^^^^^^",
      "     ^^^^^^^^^^^",
      "     ^^^^^^^^^^^",
      "     ^^^^^^^^^^^",
      "     ^^^^^^^^^^^",
      "                ",
      "                ",
      "                ",
      "                "
    ],
    [
      "                ",
      "           #    ",
      "            ##  ",
      "              # ",
      "               #",
      "               #",
      "                ",
      "                ",
      "                ",
      "                ",
      "                ",
      "                ",
      "                ",
      "                ",
      "                ",
      "                "
    ],
    [
      "                ",
      "           #    ",
      "                ",
      "                ",
      "                ",
      "                ",
      "                ",
      "                ",
      "                ",
      "                ",
      "                ",
      "                ",
      "                ",
      "                ",
      "                ",
      "                "
    ],
    [
      "                ",
      "                ",
      "                ",
      "                ",
      "                ",
      "                ",
      "                ",
      "                ",
      "                ",
      "                ",
      "                ",
      "                ",
      "                ",
      "                ",
      "                ",
      "                "
    ],
    [
      "                ",
      "                ",
      "                ",
      "                ",
      "                ",
      "                ",
      "                ",
      "                ",
      "                ",
      "                ",
      "                ",
      "                ",
      "                ",
      "                ",
      "                ",
      "                "
    ],
    [
      "                ",
      "                ",
      "                ",
      "                ",
      "                ",
      "                ",
      "                ",
      "                ",
      "                ",
      "                ",
      "                ",
      "                ",
      "                ",
      "                ",
      "                ",
      "                "
    ],
    [
      "                ",
      "                ",
      "                ",
      "                ",
      "                ",
      "                ",
      "                ",
      "                ",
      "                ",
      "                ",
      "                ",
      "                ",
      "                ",
      "                ",
      "                ",
      "                "
    ],
    [
      "                ",
      "                ",
      "                ",
      "                ",
      "                ",
      "                ",
      "                ",
      "                ",
      "                ",
      "                ",
      "                ",
      "                ",
      "                ",
      "                ",
      "                ",
      "                "
    ]
  ]
}