{
  "xsize": 16,
  "zsize": 16,
  "refpalette": "lostcities:scattered",
  "slices": [
    [
      "           &&&&&",
      "$          &&&&&",
      "$       n   &&&&",
      "$$        j&&&&&",
      "$$$j       &&&&&",
      "$$$$$ j    &&&&&",
      "$$$$$$$   $&&&&&",
      "$$$$$$$$$$$&&&&&",
      "j  $$$$$$$$&&&&&",
      "    $$$$$$$&&&&&",
      "    $$$$$$$&&&&&",
      "    $$$$$$$&&&&&",
      "   $$$$$$$$&&&  ",
      "   $$$$$$$$&    ",
      "  $$$$$$$$$     ",
      "$$$$$$$$$$      "
    ],
    [
      "           j &$$",
      "            &&$$",
      "            &&&$",
      "            &&&&",
      "            &&&&",
      "                ",
      "j               ",
      "            &&&&",
      "            &&&&",
      "            &&&$",
      "      j     &&$$",
      "             &$ ",
      "                ",
      "     j j        ",
      "                ",
      "  j             "
    ],
    [
      "                ",
      "             a a",
      "            a&&a",
      "             &&e",
      "                ",
      "                ",
      "                ",
      "                ",
      "             &&e",
      "             && ",
      "                ",
      "                ",
      "                ",
      "                ",
      "                ",
      "                "
    ],
    [
      "                ",
      "             a a",
      "            az{a",
      "             |}a",
      "                ",
      "                ",
      "                ",
      "                ",
      "             z{ ",
      "             |} ",
      "                ",
      "                ",
      "                ",
      "                ",
      "                ",
      "                "
    ],
    [
      "                ",
      "             aaa",
      "            az{a",
      "             |}a",
      "                ",
      "                ",
      "                ",
      "                ",
      "             z{ ",
      "             |} ",
      "                ",
      "                ",
      "                ",
      "                ",
      "                ",
      "                "
    ],
    [
      "                ",
      "             aa ",
      "            az{a",
      "             |} ",
      "                ",
      "                ",
      "                ",
      "                ",
      "             z{ ",
      "             |} ",
      "                ",
      "                ",
      "                ",
      "                ",
      "                ",
      "                "
    ],
    [
      "                ",
      "             aa ",
      "            az{a",
      "             |} ",
      "                ",
      "q               ",
      "                ",
      "                ",
      "             z{ ",
      "             |} ",
      "                ",
      "                ",
      "                ",
      "                ",
      "                ",
      "                "
    ],
    [
      "                ",
      "             a  ",
      "            az{ ",
      "             |} ",
      "s               ",
      "q               ",
      "r               ",
      "                ",
      "             z{ ",
      "             |} ",
      "                ",
      "                ",
      "                ",
      "                ",
      "                ",
      "                "
    ],
    [
      "                ",
      "             a  ",
      "            az{ ",
      "             |} ",
      "                ",
      "q               ",
      "q               ",
      "s               ",
      "             z{ ",
      "             |} ",
      "                ",
      "                ",
      "                ",
      "                ",
      "                ",
      "                "
    ],
    [
      "                ",
      "             a  ",
      "            az{ ",
      "             |} ",
      "                ",
      "                ",
      "                ",
      "                ",
      "             z{ ",
      "             |} ",
      "                ",
      "                ",
      "                ",
      "                ",
      "                ",
      "                "
    ],
    [
      "                ",
      "             a  ",
      "            az{ ",
      "             |} ",
      "                ",
      "                ",
      "                ",
      "                ",
      "             z{ ",
      "             |} ",
      "                ",
      "                ",
      "                ",
      "                ",
      "                ",
      "                "
    ],
    [
      "                ",
      "             a  ",
      "            az{ ",
      "             |} ",
      "                ",
      "                ",
      "                ",
      "                ",
      "             z{ ",
      "             |} ",
      "                ",
      "                ",
      "                ",
      "                ",
      "                ",
      "                "
    ],
    [
      "                ",
      "             a  ",
      "            az{ ",
      "             |} ",
      "                ",
      "                ",
      "                ",
      "                ",
      "             z{ ",
      "             |} ",
      "                ",
      "                ",
      "                ",
      "                ",
      "                ",
      "                "
    ],
    [
      "                ",
      "             a  ",
      "            az{ ",
      "             |} ",
      "                ",
      "                ",
      "                ",
      "                ",
      "             z{ ",
      "             |} ",
      "                ",
      "                ",
      "                ",
      "                ",
      "                ",
      "                "
    ],
    [
      "                ",
      "             a  ",
      "            a&& ",
      "             && ",
      "                ",
      "                ",
      "                ",
      "                ",
      "             && ",
      "             && ",
      "                ",
      "                ",
      "                ",
      "                ",
      "                ",
      "                "
    ],
    [
      "  &&&&      Ͳ&& ",
      "  &&&&      Ͳ&& ",
      "  &&&&     aͲ&&&",
      "  &&&&      Ͳ&&&",
      "  &&&&      |kkk",
      "  &&&&          ",
      "  &&&&          ",
      "  &&&&      zhhh",
      "  &&&&      Ͳ&&&",
      "  &&&&      Ͳ&&&",
      "  &&&&      Ͳ&& ",
      "  &&&&      Ͳ&& ",
      "  &&&&      Ͳ&& ",
      "  &&&&      Ͳ&& ",
      "  &&&&      Ͳ&& ",
      "  &&&&      Ͳ&& "
    ],
    [
      "  ͳ  ͳ      ͳ   ",
      "  ͳ  ͳ      ͳ   ",
      "  ͳ  ͳ     aͲh{ ",
      "  ͳ  ͳ     aͲͱͱ ",
      "  ͳ  ͳ      |kke",
      "  ͳ  ͳ          ",
      "  ͳ  ͳ          ",
      "  ͳ  ͳ      zhhe",
      "  ͳ  ͳ      Ͳhh ",
      "  ͳ  ͳ      Ͳk} ",
      "  ͳ  ͳ      ͳ   ",
      "  ͳ  ͳ      ͳ   ",
      "  ͳ  ͳ      ͳ   ",
      "  ͳ  ͳ      ͳ   ",
      "  ͳ  ͳ      ͳ   ",
      "  ͳ  ͳ      ͳ   "
    ],
    [
      "                ",
      "                ",
      "            az{ ",
      "            a|} ",
      "             a  ",
      "                ",
      "                ",
      "                ",
      "             z{ ",
      "             |} ",
      "                ",
      "                ",
      "                ",
      "                ",
      "                ",
      "                "
    ],
    [
      "                ",
      "                ",
      "             z{ ",
      "            a|} ",
      "             a  ",
      "                ",
      "                ",
      "                ",
      "             z{ ",
      "             |} ",
      "                ",
      "                ",
      "                ",
      "                ",
      "                ",
      "                "
    ],
    [
      "                ",
      "             aa ",
      "            az{a",
      "            a|} ",
      "             a  ",
      "                ",
      "                ",
      "                ",
      "             z{ ",
      "             |} ",
      "                ",
      "                ",
      "                ",
      "                ",
      "                ",
      "                "
    ],
    [
      "                ",
      "              a ",
      "             z{a",
      "             |} ",
      "                ",
      "                ",
      "                ",
      "                ",
      "             z{ ",
      "             |} ",
      "                ",
      "                ",
      "                ",
      "                ",
      "                ",
      "                "
    ],
    [
      "                ",
      "              a ",
      "             z{a",
      "             |} ",
      "                ",
      "                ",
      "                ",
      "                ",
      "             z{ ",
      "             |} ",
      "                ",
      "                ",
      "                ",
      "                ",
      "                ",
      "                "
    ],
    [
      "                ",
      "              a ",
      "             z{a",
      "             |} ",
      "                ",
      "                ",
      "                ",
      "                ",
      "             z{ ",
      "             |} ",
      "                ",
      "                ",
      "                ",
      "                ",
      "                ",
      "                "
    ],
    [
      "                ",
      "              a ",
      "             z{a",
      "             |} ",
      "                ",
      "                ",
      "                ",
      "                ",
      "             z{ ",
      "             |} ",
      "                ",
      "                ",
      "                ",
      "                ",
      "                ",
      "                "
    ],
    [
      "                ",
      "              a ",
      "             z{a",
      "             |} ",
      "                ",
      "                ",
      "                ",
      "                ",
      "             z{ ",
      "             |} ",
      "                ",
      "                ",
      "                ",
      "                ",
      "                ",
      "                "
    ],
    [
      "                ",
      "              a ",
      "             z{a",
      "             |} ",
      "                ",
      "                ",
      "                ",
      "                ",
      "             z{ ",
      "             |} ",
      "                ",
      "                ",
      "                ",
      "                ",
      "                ",
      "                "
    ],
    [
      "                ",
      "              a ",
      "             z{a",
      "             |} ",
      "                ",
      "                ",
      "                ",
      "                ",
      "             z{ ",
      "             |} ",
      "                ",
      "                ",
      "                ",
      "                ",
      "                ",
      "                "
    ],
    [
      "                ",
      "             aa ",
      "            az{a",
      "             |} ",
      "                ",
      "                ",
      "                ",
      "                ",
      "             z{ ",
      "             |} ",
      "                ",
      "                ",
      "                ",
      "                ",
      "                ",
      "                "
    ],
    [
      "                ",
      "             a  ",
      "            az{ ",
      "            a|} ",
      "             a  ",
      "            aa  ",
      "            a   ",
      "                ",
      "             z{ ",
      "             |} ",
      "                ",
      "                ",
      "                ",
      "                ",
      "                ",
      "                "
    ],
    [
      "                ",
      "             a  ",
      "            a&& ",
      "            a&& ",
      "            aaa ",
      "           aaaa ",
      "           aaa  ",
      "            a   ",
      "             && ",
      "             && ",
      "                ",
      "                ",
      "                ",
      "                ",
      "                ",
      "                "
    ],
    [
      "             && ",
      "            &&&&",
      "            &ͱͱ&",
      "            &ͱͱ&",
      "            &&&&",
      "           aaa  ",
      "           aaa  ",
      "           a&&&&",
      "            &ͱͱ&",
      "            &ͱͱ&",
      "            &&&&",
      "             && ",
      "             && ",
      "             && ",
      "             && ",
      "             && "
    ],
    [
      "            $$$$",
      "$$$$$$$$$$$$$$$$",
      "$$$$$$$$$$$$$$$$",
      "$$$$$$$$$$$$$$$$",
      "$$$$$$$$$$$$$$$$",
      "$$$$$$$$$$$$$$$$",
      "$$$$$$$$$$$$$$$$",
      "$$$$$$$$$$$$$$$$",
      "$$$$$$$$$$$$$$$$",
      "$$$$$$$$$$$$$$$$",
      "$$$$$$$$$$$$$$$$",
      "            $$$$",
      "            $$$$",
      "            $$$$",
      "            $$$$",
      "            $$$$"
    ],
    [
      "llllllllllllllll",
      "llllllllllllllll",
      "llllllllllllllll",
      "llllllllllllllll",
      "llllllllllllllll",
      "llllllllllllllll",
      "llllllllllllllll",
      "llllllllllllllll",
      "llllllllllllllll",
      "llllllllllllllll",
      "llllllllllllllll",
      "llllllllllllllll",
      "llllllllllllllll",
      "llllllllllllllll",
      "llllllllllllllll",
      "llllllllllllllll"
    ],
    [
      "                ",
      "                ",
      "                ",
      "                ",
      "                ",
      "                ",
      "                ",
      "                ",
      "                ",
      "                ",
      "                ",
      "                ",
      "                ",
      "                ",
      "                ",
      "                "
    ],
    [
      "                ",
      "                ",
      "                ",
      "                ",
      "                ",
      "                ",
      "                ",
      "                ",
      "                ",
      "                ",
      "                ",
      "                ",
      "                ",
      "                ",
      "                ",
      "                "
    ],
    [
      "                ",
      "                ",
      "                ",
      "                ",
      "                ",
      "                ",
      "                ",
      "                ",
      "                ",
      "                ",
      "                ",
      "                ",
      "                ",
      "                ",
      "                ",
      "                "
    ]
  ]
}