{
  "xsize": 16,
  "zsize": 16,
  "refpalette": "pomkotsmechs:scattered",
  "slices": [
    [
      "5vvvvvvvvvvvvvvv",
      "5vvvvvvvvvvvvvvv",
      "5vvvvvvvvvvvvvvv",
      "5vvvvvvvvvvvvvvv",
      "5vvvvvvvvvvvvvvv",
      "5vvvvvvvvvvvvvvv",
      "5vvvvvvvvvvvvvvv",
      "5vvvvvvvvvvvvvvv",
      "5vvvvvvvvvvvvvvv",
      "5vvvvvvvvvvvvvvv",
      "5vvvvvvvvvvvvvvv",
      "5vvvvvvvvvvvvvvv",
      "5vvvvvvvvvvvvvvv",
      "5vvvvvvvvvvvvvvv",
      "5vvvvvvvvvvvvvvv",
      "5vvvvvvvvvvvvvvv"
    ],
    [
      "7777667666666777",
      "6666666666666777",
      "6666666666666777",
      "6777766666666776",
      "7776776666666667",
      "6677777666666676",
      "7777777666666667",
      "67<7667666666676",
      "7777677666666666",
      "6767667666666666",
      "7677767666666666",
      "7777767666666667",
      "6666666666666667",
      "7777666666666667",
      "6767776666666667",
      "7777766666666667"
    ],
    [
      "             8  ",
      "             88 ",
      "             888",
      "              8 ",
      "               9",
      "                ",
      "                ",
      "                ",
      "                ",
      "                ",
      "                ",
      "                ",
      "                ",
      "                ",
      "                ",
      "                "
    ],
    [
      "                ",
      "                ",
      "                ",
      "                ",
      "                ",
      "                ",
      "                ",
      "                ",
      "                ",
      "                ",
      "                ",
      "                ",
      "                ",
      "                ",
      "                ",
      "                "
    ],
    [
      "                ",
      "                ",
      "                ",
      "                ",
      "                ",
      "                ",
      "                ",
      "                ",
      "                ",
      "                ",
      "                ",
      "                ",
      "                ",
      "                ",
      "                ",
      "                "
    ],
    [
      "                ",
      "                ",
      "                ",
      "                ",
      "                ",
      "                ",
      "                ",
      "                ",
      "                ",
      "                ",
      "                ",
      "                ",
      "                ",
      "                ",
      "                ",
      "                "
    ],
    [
      "                ",
      "                ",
      "                ",
      "                ",
      "                ",
      "                ",
      "                ",
      "                ",
      "                ",
      "                ",
      "                ",
      "                ",
      "                ",
      "                ",
      "                ",
      "                "
    ],
    [
      "                ",
      "                ",
      "                ",
      "                ",
      "                ",
      "                ",
      "                ",
      "                ",
      "                ",
      "                ",
      "                ",
      "                ",
      "                ",
      "                ",
      "                ",
      "                "
    ],
    [
      "                ",
      "                ",
      "                ",
      "                ",
      "                ",
      "                ",
      "                ",
      "                ",
      "                ",
      "                ",
      "                ",
      "                ",
      "                ",
      "                ",
      "                ",
      "                "
    ],
    [
      "                ",
      "                ",
      "                ",
      "                ",
      "                ",
      "                ",
      "                ",
      "                ",
      "                ",
      "                ",
      "                ",
      "                ",
      "                ",
      "                ",
      "                ",
      "                "
    ],
    [
      "                ",
      "                ",
      "                ",
      "                ",
      "                ",
      "                ",
      "                ",
      "                ",
      "                ",
      "                ",
      "                ",
      "                ",
      "                ",
      "                ",
      "                ",
      "                "
    ],
    [
      "                ",
      "                ",
      "                ",
      "                ",
      "                ",
      "                ",
      "                ",
      "                ",
      "                ",
      "                ",
      "                ",
      "                ",
      "                ",
      "                ",
      "                ",
      "                "
    ],
    [
      "                ",
      "                ",
      "                ",
      "                ",
      "                ",
      "                ",
      "               #",
      "                ",
      "                ",
      "                ",
      "                ",
      "                ",
      "                ",
      "                ",
      "                ",
      "                "
    ],
    [
      "    #           ",
      "                ",
      "                ",
      "                ",
      "                ",
      "               #",
      "             ###",
      "               #",
      "                ",
      "                ",
      "                ",
      "                ",
      "                ",
      "                ",
      "                ",
      "                "
    ],
    [
      "    #         55",
      "              55",
      "              55",
      "              55",
      "              55",
      "5            #55",
      "5           ##55",
      "5            #55",
      "5             55",
      "5             55",
      "5             55",
      "5             55",
      "5             55",
      "5             55",
      "5             55",
      "5             55"
    ],
    [
      "    #       55  ",
      "            55  ",
      "            55  ",
      "  5         55  ",
      " 55         55  ",
      " 55         55  ",
      " 55         55##",
      " 55         55# ",
      " 55         55  ",
      " 55         55  ",
      " 55         55  ",
      " 55         55  ",
      " 55         55  ",
      " 55         55  ",
      " 55         55  ",
      "$55         55$$"
    ],
    [
      "    55555555    ",
      "   555555555    ",
      "   555555555    ",
      "   555555555    ",
      "   555555555    ",
      "   555555555    ",
      "   555555555 #  ",
      "   555555555 #  ",
      "   555555555    ",
      "   555555555    ",
      "   555555555    ",
      "   555555555    ",
      "   555555555    ",
      "   555555555    ",
      "   555555555    ",
      "$$$555555555$$$ "
    ],
    [
      "       #    $   ",
      "  $         $   ",
      "  $         $   ",
      "  $         $   ",
      "  $         $   ",
      "  $         $   ",
      "  $         $   ",
      "  $         $   ",
      "  $         $   ",
      "  $         $   ",
      "  $         $   ",
      "  $         $   ",
      "  $         $   ",
      "  $         $   ",
      "  $         $   ",
      "  $$$$$$$$$$$$$ "
    ]
  ]
}