{
  "xsize": 16,
  "zsize": 16,
  "refpalette": "pomkotsmechs:scattered",
  "slices": [
    [
      "                ",
      "                ",
      "                ",
      "                ",
      "                ",
      "                ",
      "                ",
      "      ..        ",
      "      ..        ",
      "                ",
      "                ",
      "                ",
      "                ",
      "                ",
      "                ",
      "                "
    ],
    [
      "                ",
      "                ",
      "                ",
      "                ",
      "                ",
      "                ",
      "                ",
      "      ..        ",
      "      ..        ",
      "                ",
      "                ",
      "                ",
      "                ",
      "                ",
      "                ",
      "                "
    ],
    [
      "                ",
      "                ",
      "                ",
      "                ",
      "                ",
      "                ",
      "                ",
      "      ..        ",
      "      ..        ",
      "                ",
      "                ",
      "                ",
      "                ",
      "                ",
      "                ",
      "                "
    ],
    [
      "                ",
      "                ",
      "                ",
      "                ",
      "                ",
      "                ",
      "                ",
      "      ..        ",
      "      ..        ",
      "                ",
      "                ",
      "                ",
      "                ",
      "                ",
      "                ",
      "                "
    ],
    [
      "                ",
      "                ",
      "                ",
      "                ",
      "                ",
      "                ",
      "                ",
      "      ..        ",
      "      ..        ",
      "                ",
      "                ",
      "                ",
      "                ",
      "                ",
      "                ",
      "                "
    ],
    [
      "                ",
      "                ",
      "                ",
      "                ",
      "                ",
      "                ",
      "                ",
      "      ..        ",
      "      ..        ",
      "                ",
      "                ",
      "                ",
      "                ",
      "                ",
      "                ",
      "                "
    ],
    [
      "                ",
      "                ",
      "                ",
      "                ",
      "                ",
      "                ",
      "                ",
      "      ..        ",
      "      ..        ",
      "                ",
      "                ",
      "                ",
      "                ",
      "                ",
      "                ",
      "                "
    ],
    [
      "                ",
      "                ",
      "                ",
      "                ",
      "                ",
      "                ",
      "                ",
      "      ..        ",
      "      ..        ",
      "                ",
      "                ",
      "                ",
      "                ",
      "                ",
      "                ",
      "                "
    ],
    [
      "                ",
      "                ",
      "                ",
      "                ",
      "                ",
      "                ",
      "                ",
      "      ..        ",
      "      ..        ",
      "                ",
      "                ",
      "                ",
      "                ",
      "                ",
      "                ",
      "                "
    ],
    [
      "                ",
      "                ",
      "                ",
      "                ",
      "                ",
      "                ",
      "                ",
      "      ..        ",
      "      ..        ",
      "                ",
      "                ",
      "                ",
      "                ",
      "                ",
      "                ",
      "                "
    ],
    [
      "                ",
      "                ",
      "                ",
      "                ",
      "                ",
      "                ",
      "                ",
      "      ..        ",
      "      ..        ",
      "                ",
      "                ",
      "                ",
      "                ",
      "                ",
      "                ",
      "                "
    ],
    [
      "......          ",
      "......          ",
      "......          ",
      "......          ",
      "......          ",
      "......          ",
      "......          ",
      "........        ",
      "      ..        ",
      "                ",
      "                ",
      "                ",
      "                ",
      "                ",
      "                ",
      "                "
    ],
    [
      "     .          ",
      "     .          ",
      "     .          ",
      "     .          ",
      "     .          ",
      "     .          ",
      "     .          ",
      "........        ",
      "      ..        ",
      "                ",
      "                ",
      "                ",
      "                ",
      "                ",
      "                ",
      "                "
    ],
    [
      "     .          ",
      "     .          ",
      "     .          ",
      "     .          ",
      "     .          ",
      "     .          ",
      "     .          ",
      "........        ",
      "      ..        ",
      "                ",
      "                ",
      "                ",
      "                ",
      "                ",
      "                ",
      "                "
    ],
    [
      "................",
      "................",
      "..............  ",
      ".............   ",
      "............    ",
      "............    ",
      "............   .",
      "............   .",
      "............  ..",
      "...........   ..",
      "..........     .",
      "..........     .",
      "..........     .",
      "..........    ..",
      "................",
      "................"
    ],
    [
      ".............   ",
      "............    ",
      "............    ",
      "...........     ",
      "...........     ",
      "...........     ",
      "...........     ",
      "..........      ",
      "..........      ",
      ".........       ",
      ".........       ",
      ".........      .",
      ".........      .",
      "..........    ..",
      "................",
      "................"
    ],
    [
      "     .          ",
      "                ",
      "                ",
      "     .          ",
      "     .          ",
      "     .          ",
      "     .          ",
      "........        ",
      "      ..        ",
      "                ",
      "                ",
      "                ",
      "        %      %",
      "                ",
      "          %%    ",
      "                "
    ],
    [
      "     .          ",
      "                ",
      "                ",
      "     .          ",
      "                ",
      "                ",
      "     .          ",
      ".   ....        ",
      "      ..        ",
      "                ",
      "                ",
      "        I       ",
      "        I      I",
      "         I      ",
      "          II    ",
      "                "
    ],
    [
      "     .          ",
      "                ",
      "                ",
      "     .          ",
      "                ",
      "                ",
      "     .          ",
      ".   ....        ",
      "      ..        ",
      "                ",
      "                ",
      "        I      I",
      "        I      I",
      "         I      ",
      "          II    ",
      "                "
    ],
    [
      "     .          ",
      "     .          ",
      "     .          ",
      "     .          ",
      "     .          ",
      "     .          ",
      "     .          ",
      "........        ",
      "      ..        ",
      "                ",
      "          I     ",
      "        II     I",
      "        II  II I",
      "         II I   ",
      "          II    ",
      "                "
    ],
    [
      "     .          ",
      "     .          ",
      "     .          ",
      "     .          ",
      "     .          ",
      "     .          ",
      "     .          ",
      "........        ",
      "      ..        ",
      "                ",
      "          I     ",
      "        II  I  I",
      "        II  II I",
      "         IIII   ",
      "          II    ",
      "                "
    ],
    [
      "......          ",
      "......          ",
      "......          ",
      "......          ",
      "......          ",
      "......          ",
      "......          ",
      "........        ",
      "      ..        ",
      "                ",
      "                ",
      "         IIII   ",
      "         IIII   ",
      "          II    ",
      "                ",
      "                "
    ],
    [
      "      .         ",
      "      .         ",
      "      .         ",
      "      .         ",
      "      .         ",
      "      .         ",
      "      .         ",
      "      ..        ",
      "........        ",
      "                ",
      "                ",
      "                ",
      "                ",
      "                ",
      "                ",
      "                "
    ],
    [
      "                ",
      "                ",
      "                ",
      "                ",
      "                ",
      "                ",
      "                ",
      "      ..        ",
      "      ..        ",
      "                ",
      "                ",
      "                ",
      "                ",
      "                ",
      "                ",
      "                "
    ],
    [
      "                ",
      "                ",
      "                ",
      "                ",
      "                ",
      "                ",
      "                ",
      "      ..        ",
      "      ..        ",
      "                ",
      "                ",
      "                ",
      "#               ",
      "                ",
      "                ",
      "                "
    ],
    [
      "                ",
      "                ",
      "                ",
      "                ",
      "                ",
      "#      #        ",
      "##    ##        ",
      " #   #..        ",
      "      ..        ",
      "                ",
      "                ",
      "                ",
      "#               ",
      "                ",
      "                ",
      "                "
    ],
    [
      "................",
      "................",
      "................",
      "................",
      "................",
      "................",
      "................",
      "................",
      "................",
      "................",
      "................",
      " ...............",
      "................",
      "................",
      "................",
      "................"
    ],
    [
      "                ",
      "                ",
      "                ",
      "#    $ ###  $   ",
      "##    ####      ",
      "##    ###       ",
      "##    ##        ",
      " #   ##         ",
      "                ",
      "                ",
      "                ",
      "               #",
      "#    $      $  #",
      "                ",
      "                ",
      "                "
    ],
    [
      "DEEEEEDDEEEEEDDE",
      "DEEEEEDDEEEEEDDE",
      "DEEEEEDDEEEEEDDE",
      "HEEEEEDHEEEEEDHE",
      "DGGGGGGDGGGGGGDG",
      "#      ##       ",
      "                ",
      "                ",
      "                ",
      "                ",
      "               #",
      " GGGGGGDGGGGGGDG",
      "#EEEEEDHEEEEEDHE",
      "DEEEEEDDEEEEEDDE",
      "DEEEEEDDEEEEEDDE",
      "DEEEEEDDEEEEEDDE"
    ],
    [
      "  EEEE  EEEEE  E",
      "  EEEE   EEEE  E",
      "  EEE   EEEEE  E",
      "H       #EEEE HE",
      "#       ##      ",
      "                ",
      "                ",
      "                ",
      "                ",
      "                ",
      "                ",
      "               #",
      "#EEEEE HEEEEE HE",
      " EEEEE  EEEEE  E",
      " EEEEE  EEEEE  E",
      " EEEEE  EEEEE  E"
    ],
    [
      "  EEEE   EEEE  E",
      "  EEE    EEEE  E",
      "  EEE   #EEEE  E",
      "        ### E HE",
      "         #      ",
      "                ",
      "                ",
      "                ",
      "                ",
      "                ",
      "                ",
      "               #",
      "#EEEEE HEEEEE HE",
      " EEEEE  EEEEE  E",
      " EEEEE  EEEEE  E",
      " EEEEE  EEEEE  E"
    ],
    [
      "  EEE    EEEE #E",
      "         EEEE #E",
      "         #EEE# E",
      "         #### HE",
      "                ",
      "                ",
      "                ",
      "                ",
      "                ",
      "                ",
      "                ",
      "               #",
      "HEEEEE HEEEEE HE",
      "#EEEEE #EEEEE##E",
      " EEEEE #EEEEE  E",
      " EEEEE  EEEEE  E"
    ],
    [
      "             #DE",
      "            ##DE",
      "          ####DE",
      "            ##HE",
      "                ",
      "                ",
      "                ",
      "                ",
      "                ",
      "                ",
      "               #",
      "#             ##",
      "HEEEEE HEEEEE#HE",
      "DEEEEE#DEEEEE#DE",
      "DEEEEE#DEEEEE#DE",
      "DEEEEE#DEEEEE DE"
    ],
    [
      "             G# ",
      "            #G##",
      "            #G# ",
      "             G  ",
      "            DGDD",
      "                ",
      "                ",
      "                ",
      "                ",
      "                ",
      "               #",
      "DDDDDGDDDDDDGDDD",
      "####  G    ##G##",
      "##### G######G##",
      "#### #G##  ##G# ",
      "#    #G#     G  "
    ],
    [
      "                ",
      "             ## ",
      "             #  ",
      "                ",
      "                ",
      "                ",
      "                ",
      "                ",
      "                ",
      "                ",
      "                ",
      "               #",
      "              ##",
      "####       ###  ",
      "#     ##     #  ",
      "                "
    ],
    [
      "                ",
      "                ",
      "                ",
      "                ",
      "                ",
      "                ",
      "                ",
      "                ",
      "                ",
      "                ",
      "                ",
      "                ",
      "                ",
      "                ",
      "                ",
      "                "
    ],
    [
      "                ",
      "                ",
      "                ",
      "                ",
      "                ",
      "                ",
      "                ",
      "                ",
      "                ",
      "                ",
      "                ",
      "                ",
      "                ",
      "                ",
      "                ",
      "                "
    ],
    [
      "                ",
      "                ",
      "                ",
      "                ",
      "                ",
      "                ",
      "                ",
      "                ",
      "                ",
      "                ",
      "                ",
      "                ",
      "                ",
      "                ",
      "                ",
      "                "
    ],
    [
      "                ",
      "                ",
      "                ",
      "                ",
      "                ",
      "                ",
      "                ",
      "                ",
      "                ",
      "                ",
      "                ",
      "                ",
      "                ",
      "                ",
      "                ",
      "                "
    ],
    [
      "                ",
      "                ",
      "                ",
      "                ",
      "                ",
      "                ",
      "                ",
      "                ",
      "                ",
      "                ",
      "                ",
      "                ",
      "                ",
      "                ",
      "                ",
      "                "
    ],
    [
      "                ",
      "                ",
      "                ",
      "                ",
      "                ",
      "                ",
      "                ",
      "                ",
      "                ",
      "                ",
      "                ",
      "                ",
      "                ",
      "                ",
      "                ",
      "                "
    ],
    [
      "                ",
      "                ",
      "                ",
      "                ",
      "                ",
      "                ",
      "                ",
      "                ",
      "                ",
      "                ",
      "                ",
      "                ",
      "                ",
      "                ",
      "                ",
      "                "
    ],
    [
      "                ",
      "                ",
      "                ",
      "                ",
      "                ",
      "                ",
      "                ",
      "                ",
      "                ",
      "                ",
      "                ",
      "                ",
      "                ",
      "                ",
      "                ",
      "                "
    ],
    [
      "                ",
      "                ",
      "                ",
      "                ",
      "                ",
      "                ",
      "                ",
      "                ",
      "                ",
      "                ",
      "                ",
      "                ",
      "                ",
      "                ",
      "                ",
      "                "
    ],
    [
      "                ",
      "                ",
      "                ",
      "                ",
      "                ",
      "                ",
      "                ",
      "                ",
      "                ",
      "                ",
      "                ",
      "                ",
      "                ",
      "                ",
      "                ",
      "                "
    ],
    [
      "                ",
      "                ",
      "                ",
      "                ",
      "                ",
      "                ",
      "                ",
      "                ",
      "                ",
      "                ",
      "                ",
      "                ",
      "                ",
      "                ",
      "                ",
      "                "
    ],
    [
      "                ",
      "                ",
      "                ",
      "                ",
      "                ",
      "                ",
      "                ",
      "                ",
      "                ",
      "                ",
      "                ",
      "                ",
      "                ",
      "                ",
      "                ",
      "                "
    ],
    [
      "                ",
      "                ",
      "                ",
      "                ",
      "                ",
      "                ",
      "                ",
      "                ",
      "                ",
      "                ",
      "                ",
      "                ",
      "                ",
      "                ",
      "                ",
      "                "
    ]
  ]
}