{
  "xsize": 16,
  "zsize": 16,
  "refpalette": "pomkotsmechs:scattered",
  "slices": [
    [
      "    &&&&&&&&&&&&",
      "    &&&&&&&&&&&&",
      "    &&&&&&&&&&&&",
      "    &&&&&&&&&&&&",
      "    &&&&&&&&&&&&",
      "    &&&&&&&     ",
      "    &&&&&&      ",
      "    &&&&&  j  ww",
      "    &&&&&     ww",
      "    &&&&&       ",
      "    &&&&&&&     ",
      "    &&&&&&&&&&&&",
      "    &&&&&&&&&&&&",
      "    &&&&&&&&&&&&",
      "    &&&&&&&&&&&&",
      "    &&&&&&&&&&&&"
    ],
    [
      "     $$$$$$$$$$$",
      "     $$$$$$$$$$$",
      "     $$$$$$$$$cc",
      "     $$$$$$$cc$$",
      "     $$$$$$     ",
      "     $$$$$      ",
      "     $$$$       ",
      "     $$$      ww",
      "     $$$      wj",
      "     $$$        ",
      "     $$$$       ",
      "     $$$$c      ",
      "     $$$$$c$$$$$",
      "     $$$$$c$$$$$",
      "     $$$$$$c$$$$",
      "     $$   $$cc$$"
    ],
    [
      "     f$     j   ",
      "     f          ",
      "     f    j j   ",
      "     f          ",
      "     f    j     ",
      "     fm         ",
      "     f          ",
      "     f        ww",
      "     f        w ",
      "     f          ",
      "     f          ",
      "     f   w      ",
      "     f  ww      ",
      "     f  www     ",
      "     f   w      ",
      "     f          "
    ],
    [
      "     f$         ",
      "     f          ",
      "     f          ",
      "     f          ",
      "     f          ",
      "     fn         ",
      "     f         w",
      "     f       pww",
      "     f       rp ",
      "     f       rr ",
      "     f          ",
      "     f          ",
      "     f   w      ",
      "     f   w      ",
      "     f          ",
      "  p             "
    ],
    [
      "     f$         ",
      "     f          ",
      "     f          ",
      "     f          ",
      "     f          ",
      "     f          ",
      "     f        pw",
      "     f       pww",
      "     f       rpw",
      "     f       rp ",
      "     f          ",
      "     f          ",
      "     f          ",
      "     f   w      ",
      "  r  f          ",
      "pwpp            "
    ],
    [
      "     f$         ",
      "     f          ",
      "     f          ",
      "     f          ",
      "     f        q ",
      "     f        rp",
      "     f      rppt",
      "     f     rpuww",
      "     f      rpww",
      "     f      rpwp",
      "     f       rpr",
      "     f          ",
      "     f pw       ",
      "     f  wwp     ",
      " prprf          ",
      "ptptpf          "
    ],
    [
      "     f$         ",
      "     f          ",
      "     f          ",
      "     f          ",
      "     f       q  ",
      "     f      qrrp",
      "     f      rppw",
      "     f     rpwpw",
      "     f     rrppp",
      "     f     sqrpr",
      "     f  p     rq",
      "     f ppp      ",
      "     frppwp     ",
      "     f wwwp     ",
      "rpr  f pppr     ",
      "pwpprf          "
    ],
    [
      "     f$         ",
      "     f          ",
      "     f          ",
      "     f          ",
      "     f         q",
      "     f       qrr",
      "     f      qrpp",
      "     f     qrpuw",
      "     f     qrptp",
      "     f     sqrpr",
      "     frppr  sqrq",
      "     fpupp    q ",
      "     frpwwup    ",
      "  q  fpuupprq   ",
      " rrqsf ppwpr    ",
      "rpprqf   prq    "
    ],
    [
      "     f$         ",
      "     f          ",
      "     f          ",
      "     f          ",
      "     f          ",
      "     f        qq",
      "     f     xsqrr",
      "     f     sqrpp",
      "     f     qrpwp",
      "     f      qrpr",
      "     f rprr sqrq",
      "     f pw pr    ",
      "     frpwpwpr   ",
      "     fpwppprq   ",
      "  q  frprprqs   ",
      "qrrqsf rqrqs    "
    ],
    [
      "     f$         ",
      "     f          ",
      "     f          ",
      "     f          ",
      "     f          ",
      "     f       s q",
      "     f      sqrq",
      "     f     sqrpr",
      "     f      rpwp",
      "     f s q  qrpr",
      "     fsqrr   qrq",
      "     fqrpprqs   ",
      "     frpwuprq   ",
      "     frpptprq   ",
      "  s  f rrprq    ",
      " rqs f  qrqs    "
    ],
    [
      "     f$         ",
      "     f          ",
      "     f          ",
      "     f          ",
      "     f          ",
      "     f          ",
      "     f       sqs",
      "     f      sqrq",
      "     f      qrpr",
      "     f  s    qr ",
      "     f sqq    q ",
      "     f qrrqs    ",
      "     fqrpprq    ",
      "     f rpwpr    ",
      "     f qrprq    ",
      "  s  f   rq     "
    ],
    [
      "     f$         ",
      "     f          ",
      "     f          ",
      "     f          ",
      "     f          ",
      "     f          ",
      "     f          ",
      "     f       sqs",
      "     f       qrq",
      "     f          ",
      "     f  ss      ",
      "     f sqqq     ",
      "     fsqr rq    ",
      "     f rpwpr    ",
      "     f  rpr     ",
      "  x  f   r      "
    ],
    [
      "     f$         ",
      "     f          ",
      "     f          ",
      "     f          ",
      "     f          ",
      "     f          ",
      "     f          ",
      "     f          ",
      "     f          ",
      "     f          ",
      "     f  x       ",
      "     f  s       ",
      "     f sqrq     ",
      "     f  rpr     ",
      "     f  qrq     ",
      "     f          "
    ],
    [
      "     f$         ",
      "     f          ",
      "     f          ",
      "     f          ",
      "     f          ",
      "     f          ",
      "     f          ",
      "     f          ",
      "     f          ",
      "     f          ",
      "     f          ",
      "     f  xs      ",
      "     f xsq      ",
      "     f  qr      ",
      "     f   q      ",
      "     f          "
    ],
    [
      "     f$         ",
      "     f          ",
      "     f          ",
      "     f          ",
      "     f          ",
      "     f          ",
      "     f          ",
      "     f          ",
      "     f          ",
      "     f          ",
      "     f          ",
      "     f  y       ",
      "     f  xs      ",
      "     f  s       ",
      "     f          ",
      "     f          "
    ],
    [
      "     f$&        ",
      "     f          ",
      "     f          ",
      "     f          ",
      "     f          ",
      "     f          ",
      "     f          ",
      "     f          ",
      "     f          ",
      "     f          ",
      "     f          ",
      "     f          ",
      "     f          ",
      "     f          ",
      "     f          ",
      "     f          "
    ],
    [
      "     f$         ",
      "     f          ",
      "     f          ",
      "     f          ",
      "     f          ",
      "     f          ",
      "     f          ",
      "     f          ",
      "     f          ",
      "     f          ",
      "     f          ",
      "     f          ",
      "     f          ",
      "     f          ",
      "     f          ",
      "     f          "
    ],
    [
      "     f$         ",
      "     f          ",
      "     f          ",
      "     f          ",
      "     f          ",
      "     f          ",
      "     f          ",
      "     f          ",
      "     f          ",
      "     f          ",
      "     f          ",
      "     f          ",
      "     f          ",
      "     f          ",
      "     f          ",
      "     f          "
    ],
    [
      "     f$         ",
      "     f          ",
      "     f          ",
      "     f          ",
      "     f          ",
      "     f          ",
      "     f          ",
      "     f          ",
      "     f          ",
      "     f          ",
      "     f          ",
      "     f          ",
      "     f          ",
      "     f          ",
      "     f          ",
      "     f          "
    ],
    [
      "     f$         ",
      "     f          ",
      "     f          ",
      "     f          ",
      "     f          ",
      "     f          ",
      "     f          ",
      "     f          ",
      "     f          ",
      "     f          ",
      "     f          ",
      "     f          ",
      "     f          ",
      "     f          ",
      "     f          ",
      "     f          "
    ],
    [
      "     f$         ",
      "     f          ",
      "     f          ",
      "     f          ",
      "     f          ",
      "     f          ",
      "     f          ",
      "     f          ",
      "     f          ",
      "     f          ",
      "     f          ",
      "     f          ",
      "     f          ",
      "     f          ",
      "     f          ",
      "     f          "
    ],
    [
      "     f$         ",
      "     f          ",
      "     f          ",
      "     f          ",
      "     f          ",
      "     f          ",
      "     f          ",
      "     f          ",
      "     f          ",
      "     f          ",
      "     f          ",
      "     f          ",
      "     f          ",
      "     f          ",
      "     f          ",
      "     f          "
    ],
    [
      "     f$         ",
      "     f          ",
      "     f          ",
      "     f          ",
      "     f          ",
      "     f          ",
      "     f          ",
      "     f          ",
      "     f          ",
      "     f          ",
      "     f          ",
      "     f          ",
      "     f          ",
      "     f          ",
      "     f          ",
      "     f          "
    ],
    [
      "     f$         ",
      "     f          ",
      "     f          ",
      "     f          ",
      "     f          ",
      "     f          ",
      "     f          ",
      "     f          ",
      "     f          ",
      "     f          ",
      "     f          ",
      "     f          ",
      "     f          ",
      "     f          ",
      "     f          ",
      "     f          "
    ],
    [
      "     f$         ",
      "     f          ",
      "     f          ",
      "     f          ",
      "     f          ",
      "     f          ",
      "     f          ",
      "     f          ",
      "     f          ",
      "     f          ",
      "     f          ",
      "     f          ",
      "     f          ",
      "     f          ",
      "     f          ",
      "                "
    ],
    [
      "     f$         ",
      "     f          ",
      "     f          ",
      "     f          ",
      "     f          ",
      "     f          ",
      "     f          ",
      "     f          ",
      "     f          ",
      "     f          ",
      "     f          ",
      "     f          ",
      "     f          ",
      "     f          ",
      "                ",
      "                "
    ],
    [
      "    $$$         ",
      "    $$$         ",
      "    $$$         ",
      "    $$$         ",
      "    $$$         ",
      "    $$$         ",
      "    $$$         ",
      "    $$$         ",
      "    $$$         ",
      "    $$$         ",
      "    $$$         ",
      "    $$$         ",
      "    $$          ",
      "    $           ",
      "                ",
      "                "
    ],
    [
      "    $$$         ",
      "    $$$         ",
      "    $$$         ",
      "    $$$         ",
      "    $$$         ",
      "    $$$         ",
      "    $$$         ",
      "    $$$         ",
      "    $$$         ",
      "    $$$         ",
      "    $$$         ",
      "    $$$         ",
      "    $$          ",
      "    $           ",
      "                ",
      "                "
    ],
    [
      "    $$$         ",
      "      $         ",
      "                ",
      "                ",
      "                ",
      "      $         ",
      "                ",
      "                ",
      "                ",
      "      $         ",
      "                ",
      "                ",
      "                ",
      "                ",
      "                ",
      "                "
    ],
    [
      "    $$$         ",
      "      $         ",
      "                ",
      "                ",
      "                ",
      "      $         ",
      "                ",
      "                ",
      "                ",
      "      $         ",
      "                ",
      "                ",
      "                ",
      "                ",
      "                ",
      "                "
    ],
    [
      "    $$&&&&&&&&&&",
      "      $         ",
      "      &         ",
      "      &         ",
      "      &         ",
      "      $         ",
      "      &         ",
      "      &         ",
      "      &         ",
      "      $         ",
      "      &         ",
      "      &         ",
      "      &         ",
      "                ",
      "                ",
      "                "
    ],
    [
      "    $$$$$$$$$$$$",
      "    $$$$$$$$$$$$",
      "    $$$$        ",
      "    $$$$        ",
      "    $$$$        ",
      "    $$$$        ",
      "    $$$$        ",
      "    $$$$        ",
      "    $$$$        ",
      "    $$$$        ",
      "    $$$$        ",
      "    $$$$        ",
      "    $$$$        ",
      "    $$$$        ",
      "                ",
      "                "
    ],
    [
      "    llll   lllll",
      "    llllllllllll",
      "    llllllllllll",
      "    llllllllllll",
      "    llllllllllll",
      "    llllllllllll",
      "    llllllllllll",
      "    llllllllllll",
      "    llllllllllll",
      "    llllllllllll",
      "    llllllllllll",
      "    llllllllllll",
      "    llllllllllll",
      "    llllllllllll",
      "    llllllllllll",
      "        llllllll"
    ],
    [
      "            j   ",
      "                ",
      "         j  j   ",
      "                ",
      "          j     ",
      "      j         ",
      "                ",
      "      j    j    ",
      "               j",
      "                ",
      "       j  j     ",
      "                ",
      "                ",
      "                ",
      "       j        ",
      "           j   j"
    ],
    [
      "                ",
      "                ",
      "                ",
      "                ",
      "                ",
      "                ",
      "                ",
      "                ",
      "                ",
      "                ",
      "                ",
      "                ",
      "                ",
      "                ",
      "                ",
      "                "
    ],
    [
      "                ",
      "                ",
      "                ",
      "                ",
      "                ",
      "                ",
      "                ",
      "                ",
      "                ",
      "                ",
      "                ",
      "                ",
      "                ",
      "                ",
      "                ",
      "                "
    ]
  ]
}