{
  "xsize": 16,
  "zsize": 16,
  "refpalette": "lostcities:scattered",
  "slices": [
    [
      "         vvvvvvv",
      "          vvvvvv",
      "           vvvvv",
      "    &&&&&&& vvvv",
      "    &&    &   vv",
      "    &&    &     ",
      "    &&    &     ",
      "    &&    &     ",
      "    &&    &     ",
      "    &&    &     ",
      "    &&    &     ",
      "    &&    &     ",
      "    &&    &     ",
      "    &&    &     ",
      "    &&&&&&&     ",
      "                "
    ],
    [
      "          &&&&&&",
      "          &&&&&&",
      "          &&&&&&",
      "    &&&&&&&&&&&&",
      "    &     &&&&&&",
      "    &     &&&&&&",
      "    &     &&&&&&",
      "    &     &&&&&&",
      "    &     &&&&&&",
      "    &     &&&&&&",
      "    &     &&&&&&",
      "    &     &&&&&&",
      "    &     &&&&&&",
      "    &     &&&&&&",
      "    &&&&&&&&    ",
      "                "
    ],
    [
      "          &     ",
      "          &     ",
      "          &  '  ",
      "     &&&&&&&    ",
      "     &    &&    ",
      "     &    &&    ",
      "     &    && '  ",
      "     &    &&    ",
      "     &    &&    ",
      "     &    &&    ",
      "     &    &&    ",
      "     &    &&    ",
      "     &    &&    ",
      "     &    &&&&&&",
      "     &&&&&&&    ",
      "                "
    ],
    [
      "          &     ",
      "          &     ",
      "          &  (((",
      "     &&&&&&&&(((",
      "     &    & &(((",
      "     &    & &(((",
      "     &    & &(((",
      "     &    & &   ",
      "     &    & &   ",
      "     &    & &   ",
      "     &    & &   ",
      "    #&#   & &   ",
      "     &    & &   ",
      "     &    &&&&&&",
      "     &&&&&&&&   ",
      "                "
    ],
    [
      "          &     ",
      "          &     ",
      "          &  (&&",
      "      &&&&&&&&  ",
      "      &   & &&  ",
      "      &   & &&))",
      "      &   & &(&&",
      "      &   & &   ",
      "      &   & &   ",
      "      &   & &   ",
      "     #&   & &   ",
      "    ##&#  & &   ",
      "     #&   & &   ",
      "      &   &&&&&&",
      "      &&&&&&&   ",
      "                "
    ],
    [
      "          &     ",
      "          &     ",
      "          &  (&&",
      "      &&&&&&&&  ",
      "      &   &  &  ",
      "      &   &  &  ",
      "      &   &  (&&",
      "      &   &  &  ",
      "      &   &  &  ",
      "      &   &  &  ",
      "     #&#  &  &  ",
      "     #&#  &  &  ",
      "      &   &  &  ",
      "      &   &&&&&&",
      "      &&&&&&&&  ",
      "                "
    ],
    [
      "          &     ",
      "          &     ",
      "          &  (&&",
      "      &&&&&&&&((",
      "      &   &  &((",
      "      &   &  &((",
      "      &   &  (&&",
      "      &   &  & #",
      "      &#  &  &  ",
      "     #&#  &  &  ",
      "     #&#  &  &  ",
      "      &   &  &  ",
      "      &   &  &  ",
      "      &   &&&&&&",
      "      &&&&&&&&  ",
      "                "
    ],
    [
      "          &     ",
      "          &     ",
      "          &  (((",
      "       &&&&&&(((",
      "       &  &  (((",
      "       &  &  (((",
      "       &  &  (((",
      "       &  &  &##",
      "      #&# &  & #",
      "     ##&# &  &  ",
      "      #&  &  &  ",
      "       &  &  &  ",
      "       &  &  &  ",
      "       &  &&&&&&",
      "       &&&&&&&  ",
      "                "
    ],
    [
      "          &     ",
      "          &     ",
      "          &  '  ",
      "       &&&&&&&& ",
      "       &  &   & ",
      "       &  &   & ",
      "       &  &  '&#",
      "       &# &   &#",
      "      #&# &   &#",
      "      #&  &   & ",
      "       &  &   & ",
      "       &  &   & ",
      "       &  &   & ",
      "       &  &&&&&&",
      "       &&&&&&&& ",
      "                "
    ],
    [
      "          &     ",
      "          &     ",
      "          &  (((",
      "        &&&&&(((",
      "        & &  (((",
      "        & &  (((",
      "        & &  (((",
      "       #&#&   &#",
      "      ##&#&   &#",
      "       #& &   & ",
      "        & &   & ",
      "        & &   & ",
      "        & &   & ",
      "        & &&&&&&",
      "        &&&&&&& ",
      "                "
    ],
    [
      "          &     ",
      "          &     ",
      "          &  (&&",
      "        &&&&&&&&",
      "        & &  & &",
      "        & &  &))",
      "        &#&  (&&",
      "       #&#&    &",
      "       #& &    &",
      "        & &    &",
      "        & &    &",
      "        & &    &",
      "        & &    &",
      "        & &&&&&&",
      "        &&&&&&&&",
      "                "
    ],
    [
      "          &     ",
      "          &     ",
      "          &  (&&",
      "         &&&&&&&",
      "         &&  & &",
      "         &&  & &",
      "        #&&  (&&",
      "       ##&&    &",
      "        #&&    &",
      "         &&    &",
      "         &&    &",
      "         &&    &",
      "         &&    &",
      "         &&&&&&&",
      "         &&&&&&&",
      "                "
    ],
    [
      "          &     ",
      "          &     ",
      "          &  (&&",
      "         &&&&&((",
      "         &&  &((",
      "        #&&  &((",
      "       ##&&  (&&",
      "        #&&     ",
      "         &&     ",
      "         &&    #",
      "         &&     ",
      "         &&     ",
      "         &&     ",
      "         &&&&&&&",
      "         &&&&&&&",
      "                "
    ],
    [
      "          &     ",
      "          &     ",
      "          &  (((",
      "         &&&&(((",
      "         &&  (((",
      "        #&&  (((",
      "       ##&&  (((",
      "        #&&     ",
      "         &&     ",
      "         &&    #",
      "         &&    #",
      "         &&     ",
      "         &&     ",
      "         &&&&&&&",
      "         &&&&&&&",
      "                "
    ],
    [
      "          &  ## ",
      "          &  #  ",
      "          &     ",
      "         #&&&&&&",
      "        ##&     ",
      "       ###&#    ",
      "       ###&#    ",
      "        ###     ",
      "                ",
      "                ",
      "          &     ",
      "          &     ",
      "          &     ",
      "          &&&&&&",
      "          &&&&&&",
      "               #"
    ],
    [
      "          &&&&&&",
      "          &&&&&&",
      "          &&&&&&",
      "          &&&&&&",
      "         #&&&&&&",
      "        ##&&&&&&",
      "        ##&&&&&&",
      "          # &&&&",
      "                ",
      "                ",
      "          &&&&& ",
      "          &&&&&&",
      "          &&&&&&",
      "          &&&&&&",
      "          &&&&&&",
      "               #"
    ],
    [
      "             ## ",
      "            ### ",
      "            ### ",
      "           &&&&&",
      "           &    ",
      "          #&#   ",
      "          #&    ",
      "                ",
      "                ",
      "                ",
      "                ",
      "           &    ",
      "           &   #",
      "           &   #",
      "           &&&&&",
      "               #"
    ],
    [
      "                ",
      "            ##  ",
      "           #### ",
      "           &&&&&",
      "           &#  &",
      "          #&#  &",
      "           &   &",
      "               &",
      "                ",
      "                ",
      "                ",
      "           &   &",
      "           &   &",
      "           &   &",
      "           &&&&&",
      "               #"
    ],
    [
      "                ",
      "            #   ",
      "           ###  ",
      "           &&&& ",
      "          #&#&& ",
      "          #&#&& ",
      "           & && ",
      "              & ",
      "                ",
      "                ",
      "                ",
      "           & && ",
      "           & && ",
      "           & &&#",
      "           &&&&#",
      "              ##"
    ],
    [
      "                ",
      "                ",
      "            #   ",
      "           #&#  ",
      "           #&#  ",
      "           #&   ",
      "            &   ",
      "                ",
      "                ",
      "                ",
      "                ",
      "            &   ",
      "            &   ",
      "            &   ",
      "            & ##",
      "                "
    ],
    [
      "                ",
      "                ",
      "                ",
      "            #   ",
      "            #   ",
      "                ",
      "                ",
      "                ",
      "                ",
      "                ",
      "                ",
      "                ",
      "                ",
      "                ",
      "                ",
      "                "
    ],
    [
      "                ",
      "                ",
      "                ",
      "                ",
      "                ",
      "                ",
      "                ",
      "                ",
      "                ",
      "                ",
      "                ",
      "                ",
      "                ",
      "                ",
      "                ",
      "                "
    ],
    [
      "                ",
      "                ",
      "                ",
      "                ",
      "                ",
      "                ",
      "                ",
      "                ",
      "                ",
      "                ",
      "                ",
      "                ",
      "                ",
      "                ",
      "                ",
      "                "
    ],
    [
      "                ",
      "                ",
      "                ",
      "                ",
      "                ",
      "                ",
      "                ",
      "                ",
      "                ",
      "                ",
      "                ",
      "                ",
      "                ",
      "                ",
      "                ",
      "                "
    ]
  ]
}