{
  "xsize": 16,
  "zsize": 16,
  "refpalette": "pomkotsmechs:scattered",
  "slices": [
    [
      "&&&&&&&&&&&&&&&&",
      "&&&&&&&&&&&&&&&&",
      "&&&&&&&&&&&&&&&&",
      "    &&&&&&&&&&&&",
      "    &&&&&&&&&&&&",
      "    &&&&&&&&&&&&",
      "    &&&&&&&&&&&&",
      "    &&&&&&&&&&&&",
      "    &&&&&&&&&&&&",
      "    &&&&&&&&&&&&",
      "    &&&&&&&&&&&&",
      "    &&&&&&&&&&&&",
      "    &&&&&&&&&&&&",
      "    &&&&&&&&&&&&",
      "    &&&&&&&&&&&&",
      "    &&&&&&&&&&&&"
    ],
    [
      "$$     a        ",
      "$$$$$$$$$$$$$$$$",
      "$$$$$$$$$$$$$$$$",
      "    $$$aaaa     ",
      "    $$$&&&&&&&&&",
      "     $$$$$$$$$$$",
      "     $$$$$$$$$$$",
      "    b$$$$$$$$$cc",
      "    b$$$$$$$cc$$",
      "    b$$$$$$c$$$$",
      "    b$$$$$c$$$$$",
      "    b$$$$$c$$$$$",
      "     $$$$c$$$$$$",
      "     $$$$c$$$$$$",
      "     $$$$c$$$$$$",
      "     $$$$c$$$$$$"
    ],
    [
      "$$     a        ",
      "$$dddddddddddddd",
      "$$$    aaa      ",
      "    $$$ aaaa    ",
      "    $$$eeeeeeeee",
      "     f$  aaaabbb",
      "     fb    abbbb",
      "    bfbb   bbbbb",
      "    bfbb  bbbbbb",
      "    bfbbbbbbbbbb",
      "    bfbbbbbbbbbb",
      "    bfbbbbbbbbb ",
      "     fbbbbbbbbb ",
      "     fbbbbbbbb  ",
      "     fbbbbbbbbb ",
      "     f bbbbbbbbb"
    ],
    [
      "$$     aa       ",
      "$$dddddddddddddd",
      "$$$    aa       ",
      "    $$$  a      ",
      "    $$$  aaa    ",
      "     f$    aaa b",
      "     f     aaabb",
      "    bfb     abbb",
      "    bfbb   bbbbb",
      "    bfbb  bbbbbb",
      "    bfbb  bbbbb ",
      "     fbbbbbbbb  ",
      "     fbbbbbbbb  ",
      "     fbbbbbbbb  ",
      "     fbbbbbbbb  ",
      "     f bbbbbbbbb"
    ],
    [
      "$$     aa       ",
      "$$dddddddddddddd",
      "$$$    aa       ",
      "    $$$         ",
      "    $$$         ",
      "     f$         ",
      "     f      aa  ",
      "     f       aa ",
      "     f        aa",
      "     f          ",
      "     f          ",
      "     f bb  bb   ",
      "     f bbbbbb   ",
      "     f bbbbbb   ",
      "     f bbbbbbb  ",
      "     f  bbbbbbbb"
    ],
    [
      "$$      aa      ",
      "$$dddddddddddddd",
      "$$$     aa      ",
      "    $$$         ",
      "    $$$         ",
      "     f$         ",
      "     f          ",
      "     f          ",
      "     f          ",
      "     f          ",
      "     f          ",
      "     f          ",
      "     f          ",
      "     f          ",
      "     f   bbbbb  ",
      "     f   bbbbbbb"
    ],
    [
      "$$      aa      ",
      "$$dddddddddddddd",
      "$$$     aa      ",
      "    $$$         ",
      "    $$$         ",
      "     f$         ",
      "     f          ",
      "     f          ",
      "     f          ",
      "     f          ",
      "     f          ",
      "     f          ",
      "     f          ",
      "     f          ",
      "     f    gbbbb ",
      "     f    bbbbbb"
    ],
    [
      "$$       aa     ",
      "$$dddddddddddddd",
      "$$$      aa     ",
      "    $$$         ",
      "    $$$         ",
      "     f$         ",
      "     f          ",
      "     f          ",
      "     f          ",
      "     f          ",
      "     f          ",
      "     f          ",
      "     f          ",
      "     f          ",
      "     f       bb ",
      "     f     bbbbb"
    ],
    [
      "$$       aa     ",
      "$$dddddddddddddd",
      "$$$      aa     ",
      "    $$$         ",
      "    $$$         ",
      "     f$         ",
      "     f          ",
      "     f          ",
      "     f          ",
      "     f          ",
      "     f          ",
      "     f          ",
      "     f          ",
      "     f          ",
      "     f          ",
      "     f      bbbb"
    ],
    [
      "$$        aa    ",
      "$$dddddddddddddd",
      "$$$       aa    ",
      "    $$$         ",
      "    $$$         ",
      "     f$         ",
      "     f          ",
      "     f          ",
      "     f          ",
      "     f          ",
      "     f          ",
      "     f          ",
      "     f          ",
      "     f          ",
      "     f          ",
      "     f        bb"
    ],
    [
      "$$        aa    ",
      "$$dddddddddddddd",
      "$$$       aa    ",
      "    $$$         ",
      "    $$$         ",
      "     f$         ",
      "     f          ",
      "     f          ",
      "     f          ",
      "     f          ",
      "     f          ",
      "     f          ",
      "     f          ",
      "     f          ",
      "     f          ",
      "     f          "
    ],
    [
      "$$         a    ",
      "$$dddddddddddddd",
      "$$$        a    ",
      "    $$$         ",
      "    $$$         ",
      "     f$         ",
      "     f          ",
      "     f          ",
      "     f          ",
      "     f          ",
      "     f          ",
      "     f          ",
      "     f          ",
      "     f          ",
      "     f          ",
      "     f          "
    ],
    [
      "$$        aa    ",
      "$$dddddddddddddd",
      "$$$       aa    ",
      "    $$$         ",
      "    $$$         ",
      "     f$         ",
      "     f          ",
      "     f          ",
      "     f          ",
      "     f          ",
      "     f          ",
      "     f          ",
      "     f          ",
      "     f          ",
      "     f          ",
      "     f          "
    ],
    [
      "$$         aa   ",
      "$$dddddddddddddd",
      "$$$        aa   ",
      "    $$$         ",
      "    $$$         ",
      "     f$         ",
      "     f          ",
      "     f          ",
      "     f          ",
      "     f          ",
      "     f          ",
      "     f          ",
      "     f          ",
      "     f          ",
      "     f          ",
      "     f          "
    ],
    [
      "$$              ",
      "$$dddddddddddddd",
      "$$$             ",
      "    $$$         ",
      "    $$$         ",
      "     f$         ",
      "     f          ",
      "     f          ",
      "     f          ",
      "                ",
      "                ",
      "                ",
      "                ",
      "                ",
      "                ",
      "     f          "
    ],
    [
      "$$              ",
      "$$dddddddddddddd",
      "$$$          aa ",
      "    $$$hhhhhhhhh",
      "    $$$&&&&&&&&&",
      "     f$&&&&&&&&&",
      "     f$$$$$$$$$$",
      "       $$$$$$$$$",
      "        $$$$$$$$",
      "        $$$$$$$$",
      "         $$$$$$$",
      "         $$$$$$$",
      "         $$$$$$$",
      "         $$$$$$$",
      "        $$$$$$$$",
      "        $$$$$$$$"
    ],
    [
      "$$           a  ",
      "$$dddddddddddddd",
      "$$$         aaaa",
      "    $$$eeeeeeeee",
      "    $$$       a ",
      "     f$i        ",
      "                ",
      "                ",
      "                ",
      "                ",
      "                ",
      "                ",
      "                ",
      "                ",
      "                ",
      "           bbb  "
    ],
    [
      "$$          aa  ",
      "$$dddddddddddddd",
      "$$$         aaa ",
      "    $$$       a ",
      "     $$         ",
      "      $         ",
      "                ",
      "                ",
      "                ",
      "                ",
      "                ",
      "                ",
      "                ",
      "                ",
      "                ",
      "           bbbb "
    ],
    [
      "$$           a  ",
      "$$     ddddddddd",
      "$            a  ",
      "                ",
      "                ",
      "                ",
      "                ",
      "                ",
      "                ",
      "                ",
      "                ",
      "                ",
      "                ",
      "                ",
      "                ",
      "            bbb "
    ],
    [
      "             aa ",
      "         ddddddd",
      "             aa ",
      "                ",
      "                ",
      "                ",
      "                ",
      "                ",
      "                ",
      "                ",
      "                ",
      "                ",
      "                ",
      "                ",
      "                ",
      "             b  "
    ],
    [
      "              aa",
      "         ddddddd",
      "              aa",
      "                ",
      "                ",
      "                ",
      "                ",
      "                ",
      "                ",
      "                ",
      "                ",
      "                ",
      "                ",
      "                ",
      "                ",
      "                "
    ],
    [
      "               a",
      "          dddddd",
      "               a",
      "                ",
      "                ",
      "                ",
      "                ",
      "                ",
      "                ",
      "                ",
      "                ",
      "                ",
      "                ",
      "                ",
      "                ",
      "                "
    ],
    [
      "               a",
      "          dddddd",
      "               a",
      "                ",
      "                ",
      "                ",
      "                ",
      "                ",
      "                ",
      "                ",
      "                ",
      "                ",
      "                ",
      "                ",
      "                ",
      "                "
    ],
    [
      "               a",
      "          dddddd",
      "               a",
      "                ",
      "                ",
      "                ",
      "                ",
      "                ",
      "                ",
      "                ",
      "                ",
      "                ",
      "                ",
      "                ",
      "                ",
      "                "
    ],
    [
      "               a",
      "         ddddddd",
      "               a",
      "                ",
      "                ",
      "                ",
      "                ",
      "                ",
      "                ",
      "                ",
      "                ",
      "                ",
      "                ",
      "                ",
      "                ",
      "     f          "
    ],
    [
      "                ",
      "        dddddddd",
      "                ",
      "                ",
      "                ",
      "                ",
      "                ",
      "                ",
      "                ",
      "                ",
      "                ",
      "                ",
      "                ",
      "                ",
      "                ",
      "     f          "
    ],
    [
      "         $$$$$$$",
      "         $$$$$$$",
      "        $$$$$$$$",
      "                ",
      "                ",
      "                ",
      "                ",
      "                ",
      "                ",
      "                ",
      "                ",
      "                ",
      "                ",
      "                ",
      "    $$$         ",
      "    $$$         "
    ],
    [
      "          $$$$$$",
      "          $$$$$$",
      "          $$$$$$",
      "                ",
      "                ",
      "                ",
      "                ",
      "                ",
      "                ",
      "                ",
      "                ",
      "                ",
      "                ",
      "                ",
      "    $$$         ",
      "    $$$        a"
    ],
    [
      "                ",
      "                ",
      "           $   $",
      "                ",
      "                ",
      "                ",
      "                ",
      "                ",
      "                ",
      "                ",
      "                ",
      "                ",
      "                ",
      "                ",
      "      $         ",
      "               a"
    ],
    [
      "                ",
      "                ",
      "                ",
      "                ",
      "                ",
      "                ",
      "                ",
      "                ",
      "                ",
      "                ",
      "                ",
      "                ",
      "                ",
      "                ",
      "               a",
      "                "
    ],
    [
      "                ",
      "                ",
      "                ",
      "                ",
      "                ",
      "                ",
      "                ",
      "                ",
      "                ",
      "                ",
      "                ",
      "                ",
      "                ",
      "               a",
      "              aa",
      "               a"
    ],
    [
      "                ",
      "                ",
      "                ",
      "                ",
      "                ",
      "                ",
      "                ",
      "                ",
      "                ",
      "                ",
      "                ",
      "                ",
      "                ",
      "               a",
      "              aa",
      "              aa"
    ],
    [
      "                ",
      "                ",
      "                ",
      "                ",
      "                ",
      "                ",
      "                ",
      "                ",
      "                ",
      "                ",
      "                ",
      "                ",
      "                ",
      "                ",
      "               a",
      "             aaa"
    ],
    [
      "                ",
      "                ",
      "                ",
      "                ",
      "                ",
      "                ",
      "                ",
      "                ",
      "                ",
      "                ",
      "                ",
      "                ",
      "                ",
      "             aaa",
      "             aaa",
      "            aaaa"
    ],
    [
      "                ",
      "                ",
      "                ",
      "                ",
      "                ",
      "                ",
      "                ",
      "                ",
      "                ",
      "                ",
      "                ",
      "                ",
      "             aaa",
      "            aaaa",
      "            aaaa",
      "           aaaaa"
    ],
    [
      "                ",
      "                ",
      "                ",
      "                ",
      "                ",
      "                ",
      "                ",
      "                ",
      "                ",
      "                ",
      "                ",
      "                ",
      "                ",
      "             aaa",
      "            aaaa",
      "           aaaaa"
    ]
  ]
}