{
  "xsize": 16,
  "zsize": 16,
  "refpalette": "pomkotsmechs:scattered",
  "slices": [
    [
      "&&&&&&&&&&&&&$$$",
      " &&&&&&&&&&&&$$$",
      "    &&&&&&&&&$$$",
      "      &&&&&&&$$$",
      "       &&&&&&$$$",
      "       &&&&&&$$$",
      "        &&&&&$$$",
      "  w     &&&&&$$$",
      "       &&&&&&$$ ",
      "&&&  &&&&&&&&   ",
      "&&&&&&&&&&&     ",
      "&&&&&&&&&       ",
      "&&&&&&&         ",
      "&&&&&           ",
      "&&&&            ",
      "&&&&            "
    ],
    [
      "ccc$$$$$$$&j    ",
      "   $$$$$$$&& m  ",
      "     $$$$&&&    ",
      "       &&&&&    ",
      "        &&&& w  ",
      "        j j www ",
      "            ww  ",
      "  w       && wj ",
      "          &&    ",
      "       w &&&    ",
      "$$$   ww$$      ",
      "ccc$$$$ww       ",
      "$$$cc  w        ",
      "$$$$            ",
      "$$$j            ",
      "$$$             "
    ],
    [
      "    ww          ",
      "    ww   j   n  ",
      "         &&     ",
      "        e&&     ",
      "                ",
      "             w  ",
      "             w  ",
      "  w             ",
      "                ",
      "                ",
      "       w        ",
      "       w        ",
      "                ",
      "                ",
      "                ",
      "j               "
    ],
    [
      "     w          ",
      "    ww          ",
      "         z{     ",
      "         |}     ",
      "                ",
      "             w  ",
      "                ",
      "  wp            ",
      "  p             ",
      "                ",
      "       w        ",
      "                ",
      "                ",
      "                ",
      "                ",
      "                "
    ],
    [
      "     w          ",
      "    ww          ",
      "         z{     ",
      "         |}     ",
      "                ",
      "            wwp ",
      "  t        pw   ",
      "  w             ",
      "                ",
      "                ",
      "      pww       ",
      "        wp      ",
      "                ",
      "                ",
      "                ",
      "                "
    ],
    [
      "     pr         ",
      "   pwwp         ",
      "    w    z      ",
      "         |}     ",
      "           pppr ",
      "ppt        wwwp ",
      "utt       rppwp ",
      "uuwu       ppp  ",
      " pptu       p   ",
      "  rp  rppp      ",
      "      pwww      ",
      "      pwppr     ",
      "       ppp      ",
      "        p       ",
      "                ",
      "p               "
    ],
    [
      "   uwpr   r     ",
      "  rpwwp         ",
      "    wp          ",
      "  qs     |j  prq",
      "rqrqr      ppwpr",
      "prprp     puuppr",
      "tpwptp    rpwwup",
      "wp wu     pupp  ",
      "prpw qrp  rppr  ",
      "rq t rpwpp      ",
      "   pqrppuup     ",
      "     puwwpr     ",
      "       ppup     ",
      "       rppr     ",
      "r               ",
      "pwp             "
    ],
    [
      "  puwwpr rrp    ",
      "  rpwwupr       ",
      "  rptppr      s ",
      " xsppr     rqrqs",
      "qsq  q    rprprq",
      "rqrr q    pwpppr",
      "prpppr    rpwpwp",
      "prpwprs    pw pr",
      "qqrppsqrqr rprr ",
      "qrpwsqrprpr     ",
      " qqpqrpppwp     ",
      "    rpwpwpr     ",
      "     rp wp      ",
      "      rrpr      ",
      "rp              ",
      "ptp             "
    ],
    [
      "  pwppprrrrpr   ",
      "  rpwpwpr   r   ",
      "  rpwppr        ",
      " yxxprrq    qrqs",
      "sxss  q    rrprq",
      "qsqqqs    rpptpr",
      "rqrrrqs  qrpwupr",
      "rqrprqs   qrpprq",
      "ssqr sqrq sqrr  ",
      "xqqppqrprr s q  ",
      " sqrqrptppr     ",
      "    qrpuwprq    ",
      "    sqrpprq     ",
      "       rrqs     ",
      "rpr    q s      ",
      "pwpr            "
    ],
    [
      " qrpptprqqrrq   ",
      "  rpwuprqs q    ",
      " sqrpprq        ",
      "  yqrrq      rq ",
      " yxxxy     qrprq",
      "sxsssx     rpwpr",
      "qsqq sx   qrpprq",
      "qs rqs     qrrqs",
      "sxsqqsqr   sqq  ",
      "xsqrrqrprq  s   ",
      " xsqqrpwpr      ",
      "     qrpprq     ",
      "     sqrrq      ",
      "q      qqs      ",
      "rr      s       ",
      "ppr             "
    ],
    [
      "  qrpwprqsqqs   ",
      "  qrpprqsx      ",
      " xsqrrqsx       ",
      " ##sqq       r  ",
      " #xyy       rpr ",
      "xyxx y     rpwpr",
      "sxss x    sqr rq",
      "sxsq x     sqqq ",
      "xyxssx r z{ ss  ",
      "#xsqqsrpr|}     ",
      "  xs rpwpr      ",
      "     qr rqs     ",
      "      qqqs      ",
      "       ss       ",
      "q               ",
      "rrq             "
    ],
    [
      "   rpwpr xs     ",
      "  sqrprqs       ",
      "  xsqrqs        ",
      "    q s         ",
      "  #         qrq ",
      "yyyy        rpr ",
      "xyxx y     sqrq ",
      "xyxsxy      s   ",
      "y#yxx    z{ x   ",
      "#yxs  qrq|}     ",
      "      rpr       ",
      "      qrqs      ",
      "        s       ",
      "        x       ",
      "s               ",
      "qr              "
    ],
    [
      "    rprq        ",
      "   sqrqs        ",
      "   xsqs         ",
      "                ",
      "             q  ",
      "  #         qr  ",
      "y#yy       xsq  ",
      "y#yxy       xs  ",
      "###yy    z{     ",
      "# y    q |}     ",
      "       rq       ",
      "       qsx      ",
      "       sx       ",
      "                ",
      "                ",
      "s               "
    ],
    [
      "    qrq         ",
      "   xsqs         ",
      "                ",
      "                ",
      "                ",
      "            s   ",
      " ###        xs  ",
      "###y#       y   ",
      "####     z{     ",
      "         |}     ",
      "        s       ",
      "       sx       ",
      "        y       ",
      "                ",
      "                ",
      "x               "
    ],
    [
      "                ",
      "                ",
      "                ",
      "                ",
      "                ",
      "                ",
      "                ",
      "####            ",
      "  #      &&     ",
      "         &&     ",
      "                ",
      "                ",
      "                ",
      "                ",
      "                ",
      "                "
    ],
    [
      "                ",
      "                ",
      "                ",
      "                ",
      "                ",
      "                ",
      "                ",
      " #        h{    ",
      "         &&Ͱ    ",
      "         &&Ͱ    ",
      "         &&Ͱ    ",
      "         &&Ͱ    ",
      "         &&Ͱ    ",
      "         &&Ͱ    ",
      "         &&Ͱ    ",
      "         &&Ͱ    "
    ],
    [
      "                ",
      "                ",
      "                ",
      "                ",
      "                ",
      "                ",
      "                ",
      "           {    ",
      "          hͰ    ",
      "          kͰ    ",
      "           ͳ    ",
      "           ͳ    ",
      "           ͳ    ",
      "           ͳ    ",
      "           ͳ    ",
      "           ͳ    "
    ],
    [
      "                ",
      "                ",
      "                ",
      "                ",
      "                ",
      "                ",
      "                ",
      "                ",
      "                ",
      "                ",
      "                ",
      "                ",
      "                ",
      "                ",
      "                ",
      "                "
    ],
    [
      "                ",
      "                ",
      "                ",
      "                ",
      "                ",
      "                ",
      "                ",
      "                ",
      "                ",
      "                ",
      "                ",
      "                ",
      "                ",
      "                ",
      "                ",
      "                "
    ],
    [
      "                ",
      "                ",
      "                ",
      "                ",
      "                ",
      "                ",
      "                ",
      "                ",
      "                ",
      "                ",
      "                ",
      "                ",
      "                ",
      "                ",
      "                ",
      "                "
    ],
    [
      "                ",
      "                ",
      "                ",
      "                ",
      "                ",
      "                ",
      "                ",
      "                ",
      "                ",
      "                ",
      "                ",
      "                ",
      "                ",
      "                ",
      "                ",
      "                "
    ],
    [
      "                ",
      "                ",
      "          {     ",
      "          }     ",
      "                ",
      "                ",
      "                ",
      "                ",
      "                ",
      "                ",
      "                ",
      "                ",
      "                ",
      "                ",
      "                ",
      "                "
    ],
    [
      "                ",
      "                ",
      "         z{     ",
      "         |}     ",
      "                ",
      "                ",
      "                ",
      "                ",
      "          {     ",
      "                ",
      "                ",
      "                ",
      "                ",
      "                ",
      "                ",
      "                "
    ],
    [
      "                ",
      "                ",
      "         z{     ",
      "         |}     ",
      "                ",
      "                ",
      "                ",
      "                ",
      "          {     ",
      "          }     ",
      "                ",
      "                ",
      "                ",
      "                ",
      "                ",
      "                "
    ],
    [
      "                ",
      "                ",
      "         z{     ",
      "         |}     ",
      "                ",
      "                ",
      "                ",
      "                ",
      "         z{     ",
      "         |}     ",
      "                ",
      "                ",
      "                ",
      "                ",
      "                ",
      "                "
    ],
    [
      "                ",
      "                ",
      "         z{     ",
      "         |}     ",
      "                ",
      "                ",
      "                ",
      "                ",
      "         z{     ",
      "         |}     ",
      "                ",
      "                ",
      "                ",
      "                ",
      "                ",
      "                "
    ],
    [
      "                ",
      "                ",
      "         z{     ",
      "         |}     ",
      "                ",
      "                ",
      "                ",
      "                ",
      "         z{     ",
      "         |}     ",
      "                ",
      "                ",
      "                ",
      "                ",
      "                ",
      "                "
    ],
    [
      "                ",
      "                ",
      "         z{     ",
      "         |}     ",
      "                ",
      "                ",
      "                ",
      "                ",
      "         z{     ",
      "         |}     ",
      "                ",
      "                ",
      "                ",
      "                ",
      "                ",
      "                "
    ],
    [
      "                ",
      "                ",
      "         z{     ",
      "         |}     ",
      "                ",
      "                ",
      "                ",
      "                ",
      "         z{     ",
      "         |}     ",
      "                ",
      "                ",
      "                ",
      "                ",
      "                ",
      "                "
    ],
    [
      "                ",
      "                ",
      "         &&     ",
      "         &&     ",
      "                ",
      "                ",
      "                ",
      "                ",
      "         &&     ",
      "         &&     ",
      "                ",
      "                ",
      "                ",
      "                ",
      "                ",
      "                "
    ],
    [
      "         &&     ",
      "        &&&&    ",
      "&&&&&&&&&ͱͱ&    ",
      "&&&&&&&&&ͱͱ&    ",
      "        &&&&    ",
      "                ",
      "                ",
      "        &&&&    ",
      "&&&&&&&&&ͱͱ&    ",
      "&&&&&&&&&ͱͱ&    ",
      "        &&&&    ",
      "         &&     ",
      "         &&     ",
      "         &&     ",
      "         &&     ",
      "         &&     "
    ],
    [
      "        $$$$    ",
      "$$$$$$$$$$$$$$$$",
      "$$$$$$$$$$$$$$$$",
      "$$$$$$$$$$$$$$$$",
      "$$$$$$$$$$$$$$$$",
      "$$$$$$$$$$$$$$$$",
      "$$$$$$$$$$$$$$$$",
      "$$$$$$$$$$$$$$$$",
      "$$$$$$$$$$$$$$$$",
      "$$$$$$$$$$$$$$$$",
      "$$$$$$$$$$$$$$$$",
      "        $$$$    ",
      "        $$$$    ",
      "        $$$$    ",
      "        $$$$    ",
      "        $$$$    "
    ],
    [
      "llllllllllllllll",
      "llllllllllllllll",
      "llllllllllllllll",
      "llllllllllllllll",
      "llllllllllllllll",
      "llllllllllllllll",
      "llllllllllllllll",
      "llllllllllllllll",
      "llllllllllllllll",
      "llllllllllllllll",
      "llllllllllllllll",
      "llllllllllllllll",
      "llllllllllllllll",
      "llllllllllllllll",
      "llllllllllllllll",
      "llllllllllllllll"
    ],
    [
      "    j j    j    ",
      "m        j   j  ",
      "                ",
      "   m j    j     ",
      "                ",
      "        m j  j  ",
      "                ",
      "                ",
      "      j  j    j ",
      "  j j           ",
      "                ",
      "         m  j   ",
      "                ",
      "                ",
      "          m  m  ",
      "j               "
    ],
    [
      "                ",
      "n               ",
      "                ",
      "   n            ",
      "                ",
      "        n       ",
      "                ",
      "                ",
      "                ",
      "                ",
      "                ",
      "         n      ",
      "                ",
      "                ",
      "          n  n  ",
      "                "
    ],
    [
      "                ",
      "                ",
      "                ",
      "                ",
      "                ",
      "                ",
      "                ",
      "                ",
      "                ",
      "                ",
      "                ",
      "                ",
      "                ",
      "                ",
      "                ",
      "                "
    ]
  ]
}