{
  "xsize": 16,
  "zsize": 16,
  "refpalette": "pomkotsmechs:scattered",
  "slices": [
    [
      "                ",
      "                ",
      "                ",
      "                ",
      "                ",
      "                ",
      "                ",
      "                ",
      "                ",
      "                ",
      "                ",
      "                ",
      "            $ $ ",
      "             $  ",
      "            $ $ ",
      "                "
    ],
    [
      "2223v33222000220",
      "223vvvv322222332",
      "2vvvvvv333223333",
      "vvvvvvv333333333",
      "vvvvvvv333322223",
      "vvvvvvv222200022",
      "vvvvvvv2000&&&02",
      "vvvvvvv00&&vv&02",
      "vvvvv2200&vvv&02",
      "vvv&02220&vv&023",
      "&&&&&0220&&&0023",
      "0&&&&22220002233",
      "0&&&023320022333",
      "00&0233332223333",
      "00&023333222333v",
      "2&&&2333322223vv"
    ],
    [
      "          #     ",
      " &        &     ",
      " &A    # A&     ",
      " &        &     ",
      " &        &     ",
      " &        &     ",
      " &        &#    ",
      " &        &     ",
      " &        &     ",
      " &A      A&     ",
      " &        &     ",
      " &&&&&&&&&&     ",
      "                ",
      "                ",
      "                ",
      "                "
    ],
    [
      "          #     ",
      " &        &     ",
      " &A      A&     ",
      " &        &     ",
      " &        &     ",
      " &        &     ",
      " &        &#    ",
      " &        &     ",
      " &        &     ",
      " &A      A&     ",
      " &        &     ",
      " &&&&&&&&&&     ",
      "                ",
      "                ",
      "                ",
      "                "
    ],
    [
      "          #     ",
      " &        &     ",
      " &A      A&     ",
      " &        &     ",
      " &        &     ",
      " &        &#    ",
      " &        &#    ",
      " &        &     ",
      " &        &     ",
      " &A      A&     ",
      " &        &     ",
      " &&&&&&&&&&     ",
      "                ",
      "                ",
      "                ",
      "                "
    ],
    [
      "          #     ",
      " &       #&     ",
      " &A      A&     ",
      " &        &     ",
      " &        &     ",
      " &        &#    ",
      " &        &     ",
      " &        &     ",
      " &        &     ",
      " &A      A&     ",
      " &        &     ",
      " &&&&&&&&&&     ",
      "                ",
      "                ",
      "                ",
      "                "
    ],
    [
      "          #     ",
      " &       #&     ",
      " &A      A&     ",
      " &        &     ",
      " &        &     ",
      " &        &#    ",
      " &        &     ",
      " &        &     ",
      " &        &     ",
      " &A      A&     ",
      " &        &     ",
      " &&&&&&&&&&     ",
      "                ",
      "                ",
      "                ",
      "                "
    ],
    [
      "                ",
      " &       #      ",
      " &A      A      ",
      " &A      A      ",
      " &A      A&     ",
      " &A      A&#    ",
      " &A      A&     ",
      " &A      A&     ",
      " &A      A&     ",
      " &A      A&     ",
      " &        &     ",
      " &&&&&&&&&&     ",
      "                ",
      "                ",
      "                ",
      "                "
    ],
    [
      "                ",
      " &              ",
      " &A      #      ",
      " &       #      ",
      " &        &#    ",
      " &        &#    ",
      " &        &     ",
      " &        &     ",
      " &        &     ",
      " &A      A&     ",
      " &        &     ",
      " &&&&&&&&&&     ",
      "                ",
      "                ",
      "                ",
      "                "
    ],
    [
      "                ",
      " (&&&&&&&       ",
      " (&&&&&&&       ",
      " (&&&&&&&#      ",
      " (&&&&&&&&(#    ",
      " (&&&&&&&&(     ",
      " (&&&&&&&&(     ",
      " (&&&&&&&&(     ",
      " (&&&&&&&&(     ",
      " (&&&&&&&&(     ",
      " (&&&&&&&&(     ",
      " (&&&&&&&&(     ",
      "                ",
      "                ",
      "                ",
      "                "
    ],
    [
      "                ",
      "                ",
      "                ",
      "         #      ",
      "         ##     ",
      "                ",
      "                ",
      "                ",
      "                ",
      "                ",
      "                ",
      "                ",
      "                ",
      "                ",
      "                ",
      "                "
    ],
    [
      "                ",
      "                ",
      "                ",
      "                ",
      "                ",
      "                ",
      "                ",
      "                ",
      "                ",
      "                ",
      "                ",
      "                ",
      "                ",
      "                ",
      "                ",
      "                "
    ],
    [
      "                ",
      "                ",
      "                ",
      "                ",
      "                ",
      "                ",
      "                ",
      "                ",
      "                ",
      "                ",
      "                ",
      "                ",
      "                ",
      "                ",
      "                ",
      "                "
    ],
    [
      "                ",
      "                ",
      "                ",
      "                ",
      "                ",
      "                ",
      "                ",
      "                ",
      "                ",
      "                ",
      "                ",
      "                ",
      "                ",
      "                ",
      "                ",
      "                "
    ],
    [
      "                ",
      "                ",
      "                ",
      "                ",
      "                ",
      "                ",
      "                ",
      "                ",
      "                ",
      "                ",
      "                ",
      "                ",
      "                ",
      "                ",
      "                ",
      "                "
    ],
    [
      "                ",
      "                ",
      "                ",
      "                ",
      "                ",
      "                ",
      "                ",
      "                ",
      "                ",
      "                ",
      "                ",
      "                ",
      "                ",
      "                ",
      "                ",
      "                "
    ],
    [
      "                ",
      "                ",
      "                ",
      "                ",
      "                ",
      "                ",
      "                ",
      "                ",
      "                ",
      "                ",
      "                ",
      "                ",
      "                ",
      "                ",
      "                ",
      "                "
    ],
    [
      "                ",
      "                ",
      "                ",
      "                ",
      "                ",
      "                ",
      "                ",
      "                ",
      "                ",
      "                ",
      "                ",
      "                ",
      "                ",
      "                ",
      "                ",
      "                "
    ]
  ]
}