{
  "xsize": 16,
  "zsize": 16,
  "refpalette": "pomkotsmechs:scattered",
  "slices": [
    [
      "5vvvvvvvvvvvvvvv",
      "5vvvvvvvvvvvvvvv",
      "5vvvvvvvvvvvvvvv",
      "5vvvvvvvvvvvvvvv",
      "5vvvvvvvvvvvvvvv",
      "5vvvvvvvvvvvvvvv",
      "5vvvvvvvvvvvvvvv",
      "5vvvvvvvvvvvvvvv",
      "5vvvvvvvvvvvvvvv",
      "5vvvvvvvvvvvvvvv",
      "5vvvvvvvvvvvvvvv",
      "5vvvvvvvvvvvvvvv",
      "5vvvvvvvvvvvvvvv",
      "5vvvvvvvvvvvvvvv",
      "5vvvvvvvvvvvvvvv",
      "5vvvvvvvvvvvvvvv"
    ],
    [
      "6767776666666667",
      "7<77766666666666",
      "7677776666666666",
      "6777666666666667",
      "7777676666666666",
      "7767676666666666",
      "6666666666666666",
      "6666666666666666",
      "6666666666666666",
      "6666666666666666",
      "6666666666666666",
      "6666666666666666",
      "6666666666666776",
      "7677667666667767",
      "7667766777767776",
      "7676777777776667"
    ],
    [
      "                ",
      "                ",
      "                ",
      "                ",
      "                ",
      "                ",
      "    #           ",
      "    #           ",
      "   ###          ",
      "    #           ",
      "                ",
      "                ",
      "                ",
      "                ",
      "                ",
      "                "
    ],
    [
      "                ",
      "                ",
      "                ",
      "                ",
      "                ",
      "                ",
      "                ",
      "    #           ",
      "   ###          ",
      "    #           ",
      "                ",
      "                ",
      "                ",
      "                ",
      "                ",
      "                "
    ],
    [
      "                ",
      "                ",
      "                ",
      "                ",
      "                ",
      "                ",
      "                ",
      "    #           ",
      "   ###          ",
      "    #           ",
      "                ",
      "                ",
      "                ",
      "                ",
      "                ",
      "                "
    ],
    [
      "                ",
      "                ",
      "                ",
      "                ",
      "                ",
      "                ",
      "                ",
      "    #           ",
      "   ###          ",
      "    #           ",
      "                ",
      "                ",
      "                ",
      "                ",
      "                ",
      "                "
    ],
    [
      "                ",
      "                ",
      "                ",
      "                ",
      "                ",
      "                ",
      "                ",
      "    #           ",
      "   ###          ",
      "    #           ",
      "                ",
      "                ",
      "                ",
      "                ",
      "                ",
      "                "
    ],
    [
      "                ",
      "                ",
      "                ",
      "                ",
      "                ",
      "                ",
      "                ",
      "    #           ",
      "   ###          ",
      "    #           ",
      "                ",
      "                ",
      "                ",
      "                ",
      "                ",
      "                "
    ],
    [
      "                ",
      "                ",
      "                ",
      "                ",
      "                ",
      "                ",
      "                ",
      "    #           ",
      "   ###          ",
      "    #           ",
      "                ",
      "                ",
      "                ",
      "                ",
      "                ",
      "                "
    ],
    [
      "                ",
      "                ",
      "                ",
      "                ",
      "                ",
      "                ",
      "                ",
      "    #           ",
      "   ###          ",
      "   ###          ",
      "    #           ",
      "                ",
      "                ",
      "                ",
      "                ",
      "                "
    ],
    [
      "                ",
      "                ",
      "                ",
      "                ",
      "                ",
      "                ",
      "                ",
      "                ",
      "    #           ",
      "   ###          ",
      "    #           ",
      "                ",
      "                ",
      "                ",
      "                ",
      "                "
    ],
    [
      "                ",
      "                ",
      "                ",
      "                ",
      "                ",
      "                ",
      "                ",
      "                ",
      "    #           ",
      "   ###          ",
      "    #           ",
      "                ",
      "                ",
      "                ",
      "                ",
      "                "
    ],
    [
      "                ",
      "                ",
      "                ",
      "                ",
      "                ",
      "                ",
      "                ",
      "                ",
      "    #           ",
      "   ###          ",
      "    #           ",
      "                ",
      "                ",
      "                ",
      "                ",
      "                "
    ],
    [
      "                ",
      "                ",
      "                ",
      "                ",
      "                ",
      "                ",
      "                ",
      "                ",
      "    #           ",
      "   ###          ",
      "    #           ",
      "                ",
      "##              ",
      "                ",
      "                ",
      "                "
    ],
    [
      "5             55",
      "              55",
      "              55",
      "              55",
      "              55",
      "              55",
      "5             55",
      "5             55",
      "5   #         55",
      "5  ###        55",
      "5   #         55",
      "5#            55",
      "5##           55",
      "5#            55",
      "5             55",
      "5             55"
    ],
    [
      "$55         55$$",
      "  5         55$$",
      "            55  ",
      "            55  ",
      "            55  ",
      "            55  ",
      "            55  ",
      "            55  ",
      "    #       55  ",
      " 55###      55  ",
      " 55##       55  ",
      " 55 #       55  ",
      "#55         55  ",
      " 55         55  ",
      " 55         55  ",
      " 55         55  "
    ],
    [
      "$$$555555555$$$ ",
      " $$555555555$$$ ",
      "   555555555    ",
      "   555555555    ",
      "    55555555    ",
      "    55555555    ",
      "     5555555    ",
      "     5555555    ",
      "   ##5555555    ",
      "  #555555555    ",
      "  #555555555    ",
      "   555555555    ",
      " # 555555555    ",
      "   555555555    ",
      "   555555555    ",
      "   555555555    "
    ],
    [
      "  $$$$$$$$$$$$$ ",
      "  $$$$$$$$$$$$$ ",
      "  $         $   ",
      "  $         $   ",
      "            $   ",
      "            $   ",
      "            $   ",
      "            $   ",
      "   #        $   ",
      "  $##       $   ",
      "  $##       $   ",
      "  $##       $   ",
      "  $         $   ",
      "  $         $   ",
      "  $         $   ",
      "  $         $   "
    ]
  ]
}