{
  "xsize": 16,
  "zsize": 16,
  "refpalette": "lostcities:scattered",
  "slices": [
    [
      " ww &&&& &&&&&&&",
      "wwww&&          ",
      " w  &&          ",
      "    &&     ww   ",
      "    &&      w   ",
      "    &&&         ",
      "    &&&&        ",
      "    &&&&&&&&&   ",
      "    &&&&&&&&&&& ",
      "    &&&&&&&&&&&&",
      "    &&&&&&&&&&&&",
      "    &&&&&&&&&&&&",
      "    &&&&&&&&&&&&",
      "    &&&&&&&&&&&&",
      "    &&&&&&&&&&&&",
      "    &&&&&&&&&&&&"
    ],
    [
      "                ",
      " ww             ",
      "                ",
      "    $      ww   ",
      "    $       w   ",
      "                ",
      "     $          ",
      "    $$$         ",
      "    $$$&&&&&&&  ",
      "     $$$$$$$$$$$",
      "     $$$$$$$$$$$",
      "     $$$$$$$$$cc",
      "   w $$$$$$$cc$$",
      "  www$$$$$$c$$$$",
      "   ww$$$$$c$$$$$",
      "     $$$$$c$$$$$"
    ],
    [
      "                ",
      " w              ",
      "           w    ",
      "          pwwp  ",
      "      w     pr  ",
      "     www    rr  ",
      "     ww         ",
      "    $$w         ",
      "    $$$eeeeee   ",
      "     f$         ",
      "     f    ww   j",
      "     f    wwm   ",
      "     f          ",
      "   wwf          ",
      "     f       j  ",
      "     f   j      "
    ],
    [
      " ww             ",
      " w              ",
      " p         wp   ",
      "         rpwwp  ",
      "          uwpr  ",
      "      w   p pr  ",
      "      w         ",
      "                ",
      "    $$          ",
      "     f$         ",
      "     f     w    ",
      "     f    wwn   ",
      "     f          ",
      "   w f          ",
      "     f          ",
      "     f          "
    ],
    [
      "pwppp       q   ",
      "pwwp      ppr   ",
      "rpp      rptppr ",
      "         rpwwupr",
      "         puwwpr ",
      "      w    pwpr ",
      "           rpr  ",
      "                ",
      "                ",
      "     f          ",
      "     f     w    ",
      "     f    ww    ",
      "   p f          ",
      "   w f          ",
      "   wwf          ",
      "    pf          "
    ],
    [
      "ptwpp        q  ",
      "wpwpr     rprrq ",
      "ppt      rpwppr ",
      "rrp      rpwpwpr",
      " q       pwppprr",
      "     wwprrprprqs",
      "    pw    rqr   ",
      "               p",
      "               r",
      "           p    ",
      "     f     ww   ",
      "     f   rpw    ",
      "  rppf   rrp    ",
      "  pwwf          ",
      "  pwpfp         ",
      "  pwpf          "
    ],
    [
      "rpwwp      q    ",
      "ppp r    sqrrq  ",
      "rpwpr   sqrpprq ",
      "qrpr     rpwuprq",
      "sqr ppprqrpptprq",
      "    wwwp qrrprqs",
      "   rppwp  qqrqs ",
      "    ppp     q   ",
      "     p     r   r",
      "         ptp    ",
      "   q      www   ",
      " qrrp    ppwp   ",
      " rppt    rrp    ",
      " pwpwpr         ",
      "  ptwpp         ",
      "  ptptp        p"
    ],
    [
      "rpwprf          ",
      "putprq    sqq   ",
      "rppr    xsqrrqsx",
      "qrrq  prqqrpprqs",
      " qqsppwprqrpwprq",
      "   puupprsqrprqq",
      "   rpwwup  qrqsr",
      "   pupp        q",
      "   rppr   prr  q",
      "          tpppxs",
      "  sqr   rpwwup  ",
      " sqrpr  pwwwprq ",
      "sqrpwpr rpptp   ",
      " rppp r  rrpr   ",
      " qrpwwp    r  rp",
      " rpwppr       pt"
    ],
    [
      "rpprqf    s     ",
      "pwprqf     q s  ",
      "rprq   s xsqrqs ",
      "qrqsrqrqssqrprqs",
      "   rprprqsrpwprs",
      "   pwppprq rprqs",
      "   rpwpwpr qrq  ",
      "    pw prr     q",
      "    rprr rprr  s",
      "        rpwppr x",
      "   qqs  qrpwwp  ",
      " sqrrq  rppppr  ",
      " qrppr   rpwprq ",
      " rputprq qrprq  ",
      " qrpwpr  srr    ",
      "  rpprqs      rp"
    ],
    [
      "rprqsf          ",
      "pw qsf          ",
      "rprq f$   xsqs  ",
      " rq  qrqs sqrqs ",
      "    rrprq  rprq ",
      "   rpptprq  rq x",
      "  qrpwuprq  q xs",
      "   qrpprqsq s  s",
      "   sqrr  qrrqs s",
      "    s q qrpprq x",
      "        qrpwprq ",
      "  qrqs qrputpr  ",
      " qrprq  qrpprq  ",
      " rpwprq sqrrq   ",
      "  rpprqs sqq  sq",
      "  qrrqs      sqr"
    ],
    [
      "qrqsxf          ",
      "rpr  f          ",
      "qrq  f$         ",
      "    $$$q  xsqs  ",
      "    $rprq  qrq  ",
      "    rpwpr       ",
      "   qrpprq      x",
      "    qrrqs   x yx",
      "    sqq  sqqs   ",
      "     s   qrrqs  ",
      "        qrpprq  ",
      "   rq   rpwprq  ",
      "  rprq  qrprq   ",
      " rpw qs sqrqs   ",
      "  rprqs   qsx   ",
      "   rqs        sq"
    ],
    [
      " qsx f          ",
      "qrqs f          ",
      "     f$         ",
      "    $$$         ",
      "    $$$r        ",
      "    rpwpr       ",
      "   sqr rq      y",
      "    sqqq       y",
      "     ss    sx   ",
      "          rqs   ",
      "        qrprqq  ",
      "        rpwpr   ",
      "  qrq   qrprqs  ",
      "  rpr    qrqs   ",
      "  qrqsx    s    ",
      "    s          s"
    ],
    [
      " sxy f          ",
      "  s  f          ",
      "     f$         ",
      "    $$$         ",
      "    $$$q        ",
      "     $pr        ",
      "    s$rq        ",
      "     s         #",
      "     x          ",
      "           sx   ",
      "          rqs   ",
      "        qrprq   ",
      "         qrqs   ",
      "  qrqs    qs    ",
      "   qsx          ",
      "    x           "
    ],
    [
      "     f          ",
      "     f          ",
      "     f$         ",
      "    $$$         ",
      "    $$$         ",
      "     $r         ",
      "    x$q         ",
      "    $$$         ",
      "    $           ",
      "           x    ",
      "          qs    ",
      "          rq    ",
      "          qs    ",
      "    s           ",
      "   sxy          ",
      "                "
    ],
    [
      "     f          ",
      "     f          ",
      "     f$         ",
      "    $$$         ",
      "    $$$         ",
      "     $          ",
      "     $s         ",
      "    $$$         ",
      "    $$$         ",
      "     f$         ",
      "     f          ",
      "     f          ",
      "                ",
      "                ",
      "                ",
      "     f          "
    ],
    [
      "     f          ",
      "     f          ",
      "     f$&&&&     ",
      "    $$$&&&&     ",
      "    $$$kkkkk    ",
      "     $          ",
      "     $          ",
      "    $$$hhhhh    ",
      "    $$$&&&&&    ",
      "     f$&&&&&    ",
      "     f          ",
      "     f          ",
      "     f          ",
      "     f          ",
      "     f          ",
      "     f          "
    ],
    [
      "     f          ",
      "     f          ",
      "     f$         ",
      "    $$$         ",
      "    $$$eeee     ",
      "     $          ",
      "     $          ",
      "    $$$eeee     ",
      "    $$$         ",
      "     f$         ",
      "     f          ",
      "     f          ",
      "     f          ",
      "     f          ",
      "     f          ",
      "     f          "
    ],
    [
      "     f          ",
      "     f          ",
      "     f$         ",
      "    $$$         ",
      "    $$$         ",
      "     $          ",
      "     $          ",
      "    $$$         ",
      "    $$$         ",
      "     f$         ",
      "     f          ",
      "     f          ",
      "     f          ",
      "     f          ",
      "     f          ",
      "     f          "
    ],
    [
      "     f          ",
      "     f          ",
      "     f$         ",
      "    $$$         ",
      "    $$$         ",
      "     $          ",
      "     $          ",
      "    $$$         ",
      "    $$$         ",
      "     f$         ",
      "     f          ",
      "     f          ",
      "     f          ",
      "     f          ",
      "     f          ",
      "     f          "
    ],
    [
      "     f          ",
      "     f          ",
      "     f$         ",
      "    $$$         ",
      "    $$$         ",
      "     $          ",
      "     $          ",
      "    $$$         ",
      "    $$$         ",
      "     f$         ",
      "     f          ",
      "     f          ",
      "     f          ",
      "     f          ",
      "     f          ",
      "     f          "
    ],
    [
      "     f          ",
      "     f          ",
      "     f$         ",
      "    $$$         ",
      "    $$$         ",
      "     $          ",
      "     $          ",
      "    $$$         ",
      "    $$$         ",
      "     f$         ",
      "     f          ",
      "     f          ",
      "     f          ",
      "     f          ",
      "     f          ",
      "     f          "
    ],
    [
      "     f          ",
      "     f          ",
      "     f$         ",
      "    $$$         ",
      "    $$$         ",
      "                ",
      "     $          ",
      "    $$$         ",
      "    $$$         ",
      "     f$         ",
      "     f          ",
      "     f          ",
      "     f          ",
      "     f          ",
      "     f          ",
      "     f          "
    ],
    [
      "     f          ",
      "     f          ",
      "     f          ",
      "                ",
      "                ",
      "                ",
      "                ",
      "                ",
      "    $$$         ",
      "     f$         ",
      "     f          ",
      "     f          ",
      "     f          ",
      "     f          ",
      "     f          ",
      "     f          "
    ],
    [
      "     f          ",
      "                ",
      "                ",
      "                ",
      "                ",
      "                ",
      "                ",
      "                ",
      "      $         ",
      "     f$         ",
      "     f          ",
      "     f          ",
      "     f          ",
      "     f          ",
      "     f          ",
      "     f          "
    ],
    [
      "                ",
      "                ",
      "                ",
      "                ",
      "                ",
      "                ",
      "                ",
      "                ",
      "                ",
      "     f$         ",
      "     f          ",
      "     f          ",
      "     f          ",
      "     f          ",
      "     f          ",
      "     f          "
    ],
    [
      "                ",
      "                ",
      "                ",
      "                ",
      "                ",
      "                ",
      "                ",
      "                ",
      "                ",
      "     f$         ",
      "     f          ",
      "     f          ",
      "     f          ",
      "     f          ",
      "     f          ",
      "     f          "
    ],
    [
      "                ",
      "                ",
      "                ",
      "                ",
      "                ",
      "                ",
      "                ",
      "                ",
      "                ",
      "    $$$         ",
      "    $$$         ",
      "    $$$         ",
      "    $$$         ",
      "    $$$         ",
      "    $$$         ",
      "    $$$         "
    ],
    [
      "                ",
      "                ",
      "                ",
      "                ",
      "                ",
      "                ",
      "                ",
      "                ",
      "      $         ",
      "    $$$         ",
      "    $$$         ",
      "    $$$         ",
      "    $$$         ",
      "    $$$         ",
      "    $$$         ",
      "    $$$         "
    ],
    [
      "                ",
      "                ",
      "                ",
      "                ",
      "                ",
      "                ",
      "                ",
      "                ",
      "     $$         ",
      "    $$$         ",
      "      $         ",
      "                ",
      "                ",
      "                ",
      "      $         ",
      "                "
    ],
    [
      "                ",
      "                ",
      "                ",
      "                ",
      "                ",
      "                ",
      "                ",
      "                ",
      "    $$$         ",
      "    $$$         ",
      "      $         ",
      "                ",
      "                ",
      "                ",
      "      $         ",
      "                "
    ],
    [
      "                ",
      "                ",
      "            &&&&",
      "           &&&&&",
      "                ",
      "                ",
      "                ",
      "      $         ",
      "    $$$&&&&&&&&&",
      "    $$&&&&&&&&&&",
      "      $         ",
      "      &         ",
      "      &         ",
      "      &         ",
      "      $         ",
      "      &         "
    ],
    [
      "                ",
      "           $$$$$",
      "          $$$$$$",
      "         $$$$$$$",
      "        $$$$$$$$",
      "       $$$$$$$$$",
      "      $$$$$$$$$$",
      "     $$$$$$$$$$$",
      "    $$$$$$$$$$$$",
      "    $$$$$$$$$$$$",
      "    $$$$$$$$$$$$",
      "    $$$$        ",
      "    $$$$        ",
      "    $$$$        ",
      "    $$$$        ",
      "    $$$$        "
    ],
    [
      "        llllllll",
      "        llllllll",
      "       lllllllll",
      "       lllllllll",
      "      llllllllll",
      "      llllllllll",
      "    llllllllllll",
      "    llllllllllll",
      "    llllllllllll",
      "    llllllllllll",
      "    llllllllllll",
      "    llllllllllll",
      "    llllllllllll",
      "    llllllllllll",
      "    llllllllllll",
      "    llllllllllll"
    ],
    [
      "                ",
      "                ",
      "        j j     ",
      "              j ",
      "                ",
      "       j        ",
      "                ",
      "            j   ",
      "                ",
      "     j j     j  ",
      "               j",
      "            j   ",
      "                ",
      "                ",
      "             j  ",
      "       j j      "
    ],
    [
      "                ",
      "                ",
      "                ",
      "                ",
      "                ",
      "                ",
      "                ",
      "                ",
      "                ",
      "                ",
      "                ",
      "                ",
      "                ",
      "                ",
      "                ",
      "                "
    ],
    [
      "                ",
      "                ",
      "                ",
      "                ",
      "                ",
      "                ",
      "                ",
      "                ",
      "                ",
      "                ",
      "                ",
      "                ",
      "                ",
      "                ",
      "                ",
      "                "
    ]
  ]
}