{
  "xsize": 16,
  "zsize": 16,
  "refpalette": "pomkotsmechs:scattered",
  "slices": [
    [
      "                ",
      "                ",
      "                ",
      "023220&v&00200&&",
      "vvvvvv&&&vvvvvvv",
      "vvvvvvvvvvvvvvvv",
      "vvvvvvvvvvvvvvvv",
      "vvvvvvvvvvvvvvvv",
      "vvvvvvvvvvvvvvvv",
      "5555555555555555",
      "5vvvvvvvvvvvvvvv",
      "5vvvvvvvvvvvvvvv",
      "5vvvvvvvvvvvvvvv",
      "5vvvvvvvvvvvvvvv",
      "5vvvvvvvvvvvvvvv",
      "5vvvvvvvvvvvvvvv"
    ],
    [
      "                ",
      "                ",
      " ##             ",
      "55555%   %555555",
      "666666   6666666",
      "6666666666666666",
      "6666666666666666",
      "6666666666666666",
      "7777676666666666",
      "7677767666666777",
      "7767677666666676",
      "67767776;6666776",
      "77<766766666;677",
      "7777676666666777",
      "7767676666666767",
      "7777766666666677"
    ],
    [
      "                ",
      "                ",
      " #              ",
      "55555%   %555555",
      " #              ",
      "                ",
      "                ",
      "                ",
      "8=8=            ",
      "  88            ",
      "88 8 8          ",
      "  8  #8 8    >8 ",
      " 8 =###     > 88",
      "88 8 #        8 ",
      " 8 8         ?  ",
      "  8             "
    ],
    [
      "                ",
      "                ",
      "##              ",
      "55555%   %555555",
      "##              ",
      "                ",
      "                ",
      "                ",
      "                ",
      "                ",
      "                ",
      "     #          ",
      "    ###         ",
      "     #          ",
      "                ",
      "                "
    ],
    [
      "                ",
      "                ",
      "#              #",
      "55555%   %555555",
      "#              #",
      "                ",
      "                ",
      "                ",
      "                ",
      "                ",
      "                ",
      "     #          ",
      "    ###         ",
      "    ###         ",
      "     #          ",
      "                "
    ],
    [
      "                ",
      "                ",
      "#             ##",
      "55555%   %555555",
      "#             ##",
      "                ",
      "                ",
      "                ",
      "                ",
      "                ",
      "                ",
      "                ",
      "     #          ",
      "    ###         ",
      "     #          ",
      "                "
    ],
    [
      "                ",
      "                ",
      "#             # ",
      "55555%% %%555555",
      "#             # ",
      "                ",
      "                ",
      "                ",
      "                ",
      "                ",
      "                ",
      "                ",
      "     #          ",
      "    ###         ",
      "     #          ",
      "                "
    ],
    [
      "                ",
      "                ",
      "##           ## ",
      "555555%%%5555555",
      "##           ## ",
      "                ",
      "                ",
      "                ",
      "                ",
      "                ",
      "                ",
      "                ",
      "     #          ",
      "    ###         ",
      "     #          ",
      "                "
    ],
    [
      "                ",
      "                ",
      "###          #  ",
      "5555555555555555",
      "###          #  ",
      "                ",
      "                ",
      "                ",
      "                ",
      "                ",
      "                ",
      "                ",
      "     #          ",
      "    ###         ",
      "    ###         ",
      "     #          "
    ],
    [
      "                ",
      "                ",
      "# ##         #  ",
      "5555555555555555",
      "# ##         #  ",
      "                ",
      "                ",
      "                ",
      "                ",
      "                ",
      "                ",
      "                ",
      "                ",
      "    ##          ",
      "   ####         ",
      "    ##          "
    ],
    [
      "                ",
      "                ",
      "   ##       ##  ",
      "5555555555555555",
      "   ##       ##  ",
      "                ",
      "                ",
      "                ",
      "                ",
      "                ",
      "                ",
      "                ",
      "                ",
      "    #           ",
      "   ###          ",
      "    #           "
    ],
    [
      "                ",
      "                ",
      "    #      ##   ",
      "5555555555555555",
      "    #      ##   ",
      "                ",
      "                ",
      "                ",
      "                ",
      "                ",
      "                ",
      "                ",
      "                ",
      "    #           ",
      "   ###          ",
      "    #           "
    ],
    [
      "                ",
      "                ",
      "    ##    ##    ",
      "5555555555555555",
      "    ##    ##    ",
      "                ",
      "                ",
      "                ",
      "                ",
      "                ",
      "                ",
      "                ",
      "                ",
      "    #           ",
      "   ###          ",
      "    #           "
    ],
    [
      "                ",
      "                ",
      "     ## ###     ",
      "5555555555555555",
      "     ##   #     ",
      "                ",
      "                ",
      "                ",
      "                ",
      "                ",
      "                ",
      "#               ",
      "#               ",
      "    #           ",
      "   ###          ",
      "   ###          "
    ],
    [
      "                ",
      "        ##      ",
      "      #####     ",
      "5555555555555555",
      "5     ####    55",
      "5             55",
      "5             55",
      "5             55",
      "5             55",
      "5             55",
      "5             55",
      "5#            55",
      "5#            55",
      "5             55",
      "5   #         55",
      "   ###        55"
    ],
    [
      "                ",
      "        #       ",
      "       ###    $$",
      " 5555555555555$$",
      "  5    ###  55$$",
      "         #  55  ",
      " 55      #  55  ",
      " 55     ##  55  ",
      " 55     #   55  ",
      " 55     #   55  ",
      "#55    ##   55  ",
      "#55    #    55  ",
      "##     #    55  ",
      "       #    55  ",
      "    #  #    55  ",
      "   ######   55  "
    ],
    [
      "                ",
      "                ",
      "        ##  $$$ ",
      "   555555555$$$ ",
      "   555555555$$$ ",
      "   555555555    ",
      "   555555555    ",
      "   555555555    ",
      "   555555555    ",
      "   555555555    ",
      "   555555555    ",
      "## 555555555    ",
      "    55555555    ",
      "    55555555    ",
      "    55555555    ",
      "   #55555555    "
    ],
    [
      "                ",
      "        ##      ",
      "   $$$$$$$$$    ",
      "   $$$$$$$$$    ",
      "   $$$$$$$$$@   ",
      "        ### $   ",
      "  $      #  $   ",
      "  $     ##  $   ",
      "  $     #   $   ",
      "  $     #   $   ",
      "  $    ##   $   ",
      "  $    #    $   ",
      "       #    $   ",
      "       #    $   ",
      "      ###   $   ",
      "    #####   $   "
    ]
  ]
}