{
  "xsize": 16,
  "zsize": 16,
  "refpalette": "pomkotsmechs:scattered",
  "slices": [
    [
      "       vvvvvvvv*",
      "       vvvvvvv**",
      "      vvvvvvv***",
      "    &&&&&&&vv***",
      "    &&vvvv&v****",
      "    &&vvvv&v****",
      "    &&vvvv&v****",
      "    &&vvvv&v****",
      "    &&vvvv&v****",
      "    &&vvvv&v****",
      "    &&vvvv&vv***",
      "    && vvv&vv***",
      "    && vvv&vvv**",
      "    &&  vv&vvvv*",
      "    &&&&&&&vvvvv",
      "         vvvvvvv"
    ],
    [
      "          &&&&&&",
      "          &&&&&&",
      "          &&&&&&",
      "    &&&&&&&&&&&&",
      "    &     &&&&&&",
      "    &     &&&&&&",
      "    &     &&&&&&",
      "    &     &&&&&&",
      "    &     &&&&&&",
      "    &     &&&&&&",
      "    &     &&&&&&",
      "    &     &&&&&&",
      "    &     &&&&&&",
      "    &     &&&&&&",
      "    &&&&&&&&&&&&",
      "          &&&&&&"
    ],
    [
      "          &     ",
      "          &  '  ",
      "          &     ",
      "     &&&&&&&    ",
      "     &    && '  ",
      "     &    &&    ",
      "     &    &&    ",
      "     &    &&    ",
      "     &    && '  ",
      "     &    &&    ",
      "     &    &&    ",
      "     &    && '  ",
      "     &    &&    ",
      "     &    &&    ",
      "     &&&&&&&    ",
      "          &  '  "
    ],
    [
      "          &  (((",
      "          &  (((",
      "          &     ",
      "     &&&&&&&&   ",
      "     &    & &(((",
      "     &    & &(((",
      "     &    & &(((",
      "     &    & &(((",
      "     &    & &(((",
      "     &    & &   ",
      "     &    & &   ",
      "     &    & &(((",
      "     &    & &(((",
      "     &    & &(((",
      "     &&&&&&&&(((",
      "          &  ((("
    ],
    [
      "          &  &))",
      "          &  (&&",
      "          &     ",
      "      &&&&&&&   ",
      "      &   & &(&&",
      "      &   & &&  ",
      "      &   & &&  ",
      "      &   & &&))",
      "      &   & &(&&",
      "      &   & &   ",
      "      &   & &   ",
      "      &   & &(&&",
      "      &   & &&  ",
      "      &   & &&  ",
      "      &&&&&&&&))",
      "          &  (&&"
    ],
    [
      "          &  &  ",
      "          &  (&&",
      "          &     ",
      "      &&&&&&&&  ",
      "      &   &  (&&",
      "      &   &  &  ",
      "      &   &  &  ",
      "      &   &  &  ",
      "      &   &  (&&",
      "      &   &  &  ",
      "      &   &  &  ",
      "      &   &  (&&",
      "      &   &  &  ",
      "      &   &  &  ",
      "      &&&&&&&&  ",
      "          &  (&&"
    ],
    [
      "          &  &((",
      "          &  (&&",
      "      #   &     ",
      "     #&&&&&&&&  ",
      "      &   &  (&&",
      "      &   &  &((",
      "      &   &  &((",
      "      &   &  &((",
      "      &   &  (&&",
      "      &   &  &  ",
      "      &   &  &  ",
      "      &   &  (&&",
      "      &   &  &((",
      "      &   &  &((",
      "      &&&&&&&&((",
      "          &  (&&"
    ],
    [
      "          &  (((",
      "          &  (((",
      "      ##  &     ",
      "     ##&&&&&&&  ",
      "      #&  &  (((",
      "       &  &  (((",
      "       &  &  (((",
      "       &  &  (((",
      "       &  &  (((",
      "       &  &  &  ",
      "       &  &  &  ",
      "       &  &  (((",
      "       &  &  (((",
      "       &  &  (((",
      "       &&&&&&(((",
      "          &  ((("
    ],
    [
      "          &     ",
      "          &  '  ",
      "       #  &     ",
      "      #&&&&&&&& ",
      "      #&# &  '& ",
      "      #&# &   & ",
      "       &  &   & ",
      "       &  &   & ",
      "       &  &  '& ",
      "       &  &   & ",
      "       &  &   & ",
      "       &  &  '& ",
      "       &  &   & ",
      "       &  &   & ",
      "       &&&&&&&& ",
      "          &  '  "
    ],
    [
      "          &  (((",
      "          &  (((",
      "          &     ",
      "       #&&&&&&& ",
      "       #& &  (((",
      "      ##&#&  (((",
      "       #& &  (((",
      "        & &  (((",
      "        & &  (((",
      "        & &   & ",
      "        & &   & ",
      "        & &  (((",
      "        & &  (((",
      "        & &  (((",
      "        &&&&&(((",
      "          &  ((("
    ],
    [
      "          &  &))",
      "          &  (&&",
      "          &     ",
      "        &&&&&&&&",
      "        & &  (&&",
      "       #&#&  & &",
      "       #&#&  & &",
      "       #&#&  &))",
      "        & &  (&&",
      "        & &    &",
      "        & &    &",
      "        & &  (&&",
      "        & &  & &",
      "        & &  & &",
      "        &&&&&&))",
      "          &  (&&"
    ],
    [
      "          &  &  ",
      "          &  (&&",
      "          &     ",
      "         &&&&&&&",
      "         &&  (&&",
      "        #&&  & &",
      "        #&&  & &",
      "       ##&&  & &",
      "        #&&  (&&",
      "         &&    &",
      "         &&    &",
      "         &&  (&&",
      "         &&  & &",
      "         &&  & &",
      "         &&&&&&&",
      "          &  (&&"
    ],
    [
      "          &  &((",
      "          &  (&&",
      "          &     ",
      "         &&&&&&&",
      "         &&  (&&",
      "         &&  &((",
      "         &&  &((",
      "        #&&  &((",
      "         &&  (&&",
      "         &&     ",
      "         &&     ",
      "         &&  (&&",
      "         &&  &((",
      "         &&  &((",
      "         &&&&&((",
      "          &  (&&"
    ],
    [
      "          &  (  ",
      "          &     ",
      "          &     ",
      "         &&   &&",
      "             (((",
      "             (((",
      "         &&  (((",
      "        #&&  (((",
      "        #&&  (((",
      "         &&     ",
      "         &&     ",
      "         &&  (((",
      "         &&  (((",
      "         &&  (((",
      "         &&&&(((",
      "          &  ((("
    ],
    [
      "          &     ",
      "          &     ",
      "                ",
      "              &&",
      "                ",
      "                ",
      "          &     ",
      "         #&     ",
      "        ##&#    ",
      "         #&#    ",
      "          &     ",
      "          &     ",
      "          &     ",
      "          &     ",
      "          &&&&&&",
      "          &   ##"
    ],
    [
      "          &&&&  ",
      "          &&    ",
      "                ",
      "             &&&",
      "            &&&&",
      "           &&&&&",
      "          &&&&&&",
      "          &&&&&&",
      "         #&&&&&&",
      "         #&&&&&&",
      "          &&&&&&",
      "          &&&&&&",
      "          &&&&&&",
      "          &&&&&&",
      "          &&&&&&",
      "          &&&&&&"
    ],
    [
      "                ",
      "                ",
      "                ",
      "             &&&",
      "                ",
      "           &    ",
      "           &    ",
      "           &    ",
      "          #&    ",
      "         ##&#   ",
      "         ##&#  #",
      "          #&    ",
      "           &    ",
      "           &   #",
      "           &&&&&",
      "              ##"
    ],
    [
      "                ",
      "                ",
      "                ",
      "           &&&&&",
      "           &   &",
      "           &   &",
      "           &   &",
      "           &   &",
      "           &   &",
      "          #&   &",
      "          #&###&",
      "           &  #&",
      "           &   &",
      "           &   &",
      "           &&&&&",
      "               #"
    ],
    [
      "                ",
      "                ",
      "                ",
      "           &&&& ",
      "           & && ",
      "           & && ",
      "           & && ",
      "           & && ",
      "           & && ",
      "           &#&&#",
      "          #&#&&#",
      "           &#&&#",
      "           & && ",
      "           & && ",
      "           &&&&#",
      "                "
    ],
    [
      "                ",
      "                ",
      "                ",
      "            &   ",
      "            &   ",
      "            &   ",
      "            &   ",
      "            &   ",
      "            &   ",
      "            &#  ",
      "           #&###",
      "           #&## ",
      "            &   ",
      "            &   ",
      "            &   ",
      "                "
    ],
    [
      "                ",
      "                ",
      "                ",
      "                ",
      "                ",
      "                ",
      "                ",
      "                ",
      "                ",
      "                ",
      "            ##  ",
      "            #   ",
      "                ",
      "                ",
      "                ",
      "                "
    ],
    [
      "                ",
      "                ",
      "                ",
      "                ",
      "                ",
      "                ",
      "                ",
      "                ",
      "                ",
      "                ",
      "                ",
      "                ",
      "                ",
      "                ",
      "                ",
      "                "
    ],
    [
      "                ",
      "                ",
      "                ",
      "                ",
      "                ",
      "                ",
      "                ",
      "                ",
      "                ",
      "                ",
      "                ",
      "                ",
      "                ",
      "                ",
      "                ",
      "                "
    ],
    [
      "                ",
      "                ",
      "                ",
      "                ",
      "                ",
      "                ",
      "                ",
      "                ",
      "                ",
      "                ",
      "                ",
      "                ",
      "                ",
      "                ",
      "                ",
      "                "
    ]
  ]
}