{
  "xsize": 16,
  "zsize": 16,
  "refpalette": "lostcities:quarry",
  "slices": [
    [
      "~~~~~~~~~~!~~~~~",
      "~~~~~~~~~$!$$~~~",
      "~~~~~~~~$!''''''",
      "~~~~~~~~~$''''''",
      "~~~~~~~~~~''''''",
      "~~~~~~~~~~''''''",
      "~~~~~~~~~~''''''",
      "~~~~~~~~~~''''''",
      "~~~~~~~~~~!~~~~~",
      "~~~~~~~~~~!~~~~~",
      "~~~~~~~~~~!~~~~~",
      "~~~~~~~~~~!~~~~~",
      "~~~~~~~~~~!~~~~~",
      "~~~~~~~~~~!~~~~~",
      "~~~~~~~~~~!~~~~~",
      "~~~~~~~~~~!~~~~~"
    ],
    [
      "~~~~~~~~~~~~~~~~",
      "~~~~~~~~~~$$$~~~",
      "~~~~~~~~~$!$$$~~",
      "~~~~~~~~~~~00000",
      "~~~~~~~~~~~0~~~~",
      "~~~~~~~~~~~0~~~~",
      "~~~~~~~~~~~00~~0",
      "~~~~~~~~~~!~~~~~",
      "~~~~~~~~~~~~~~~~",
      "~~~~~~~~~~~~~~~~",
      "~~~~~~~~~~~~~~~~",
      "~~~~~~~~~~~~~~~~",
      "~~~~~~~~~~~~~~~~",
      "~~~~~~~~~~~~~~~~",
      "~~~~~~~~~~~~~~~~",
      "~~~~~~~~~~~~~~~~"
    ],
    [
      "~~~~~~~~~~~~~~~~",
      "~~~~~~~~~~~$~~~~",
      "~~~~~~~~~~$$$~~~",
      "~~~~~~~~~~~00~~0",
      "~~~~~~~~~~~0~~~~",
      "~~~~~~~~~~~0~~~~",
      "~~~~~~~~~~~00~~0",
      "~~~~~~~~~~~~~~~~",
      "~~~~~~~~~~~~~~~~",
      "~~~~~~~~~~~~~~~~",
      "~~~~~~~~~~~~~~~~",
      "~~~~~~~~~~~~~~~~",
      "~~~~~~~~~~~~~~~~",
      "~~~~~~~~~~~~~~~~",
      "~~~~~~~~~~~~~~~~",
      "~~~~~~~~~~~~~~~~"
    ],
    [
      "~~~~~~~~~~~~~~~~",
      "~~~~~~~~~~$$~~~~",
      "~~~~~~~~~$$$$~~~",
      "~~~~~~~~~~$00~~0",
      "~~~~~~~~~~~0~~~~",
      "~~~~~~~~~~~0~~~~",
      "~~~~~~~~~~~00~~0",
      "~~~~~~~~~~~~~~~~",
      "~~~~~~~~~~~~~~~~",
      "~~~~~~~~~~~~~~~~",
      "~~~~~~~~~~~~~~~~",
      "~~~~~~~~~~~~~~~~",
      "~~~~~~~~~~~~~~~~",
      "~~~~~~~~~~~~~~~~",
      "~~~~~~~~~~~~~~~~",
      "~~~~~~~~~~~~~~~~"
    ],
    [
      "~~~~~~~~~~~~~~~~",
      "~~~~~~~~~~$$~~~~",
      "~~~~~~~~~$''''''",
      "~~~~~~~~~~''''''",
      "~~~~~~~~~~''''''",
      "~~~~~~~~~~''''''",
      "~~~~~~~~~~''''''",
      "~~~~~~~~~~''''''",
      "~~~~~~~~~~~~~~~~",
      "~~~~~~~~~~~~~~~~",
      "~~~~~~~~~~~~~~~~",
      "~~~~~~~~~~~~~~~~",
      "~~~~~~~~~~~~~~~~",
      "~~~~~~~~~~~~~~~~",
      "~~~~~~~~~~~~~~~~",
      "~~~~~~~~~~~~~~~~"
    ],
    [
      "~~~~~~~~~~~~~~~~",
      "~~~~~~~~~~~~~~~~",
      "~~~~~~~~~~$$~~~~",
      "~~~~~~~~~~~$~~~~",
      "~~~~~~~~~~~~~~~~",
      "~~~~~~~~~~~~~~~~",
      "~~~~~~~~~~~~~~~~",
      "~~~~~~~~~~~~~~~~",
      "~~~~~~~~~~~~~~~~",
      "~~~~~~~~~~~~~~~~",
      "~~~~~~~~~~~~~~~~",
      "~~~~~~~~~~~~~~~~",
      "~~~~~~~~~~~~~~~~",
      "~~~~~~~~~~~~~~~~",
      "~~~~~~~~~~~~~~~~",
      "~~~~~~~~~~~~~~~~"
    ]
  ]
}