{
  "xsize": 16,
  "zsize": 16,
  "refpalette": "lostcities:quarry",
  "slices": [
    [
      "~~!~~~~~~!!!!!~~",
      "~~!~~~~~~!!!!!~~",
      "~~!~~~~~~!!!!!~~",
      "~~!~~~~~~!!!!!~~",
      "~~!~~~~~~!!!!!~~",
      "~~!~~~~~~!!!!!~~",
      "~~!~~~~~~!!!!!~~",
      "~~!~~~~~~!!!!!~~",
      "~~!~~~~~~!!!!!~~",
      "!!!~~~~~~!!!!!~~",
      "~~~~~~~~~~~~~~~~",
      "~~~~~~~~~~~~~~~~",
      "~~~~~~~~~~~~~~~~",
      "~~~~~~~~~~~~~~~~",
      "~~~~~~~~~~~~~~~~",
      "~~~~~~~~~~~~~~~~"
    ],
    [
      "!!!~~~~~~~~~~~~~",
      "!!!~~~~~~~~~~~~~",
      "!!!~~~~~~~~~~~~~",
      "!!!~~~~~~~~~~~~~",
      "!!!~~~~~~~~~~~~~",
      "!!!~~~~~~~$~~~~~",
      "!!!~~~~~~$$$~~~~",
      "!!!~~~~~~$$$~~~~",
      "!!!~~~~~~~$$~~~~",
      "~!!~~~~~~~~~~~~~",
      "~~~~~~~~~~~~~~~~",
      "~~~~~~~~~~~~~~~~",
      "~~~~~~~~~~~~~~~~",
      "~~~~~~~~~~~~~~~~",
      "~~~~~~~~~~~~~~~~",
      "~~~~~~~~~~~~~~~~"
    ],
    [
      "!!!!!!!!!!!!!!~~",
      "!!!!!!!!!!!!!!~~",
      "!!!!!!!!!!!!!~~~",
      "!!!!!!!!!!!!!~~~",
      "!!!!!!!!!!!!~~~~",
      "!!!!!!!!!!!!~~~~",
      "!!!!!!!!!!!$~~~~",
      "!!!!!!!!!!$~~~~~",
      "!!!!!!!!!~~~~~~~",
      "~~!!!!!!~~~~~~~~",
      "!!!!!!~~~~~~~~~~",
      "!!!!~~~~~~~~~~~~",
      "!!!~~~~~~~~~~~~~",
      "~~~~~~~~~~~~~~~~",
      "~~~~~~~~~~~~~~~~",
      "~~~~~~~~~~~~~~~~"
    ],
    [
      "~~~~~~~~~~~~0~~~",
      "~~~~~~~~~~~00~~~",
      "~~~~~~~~~~~0~~~~",
      "~~~~~~~~~~~0~~~~",
      "~~~~~~~~~~0~~~~~",
      "~~~~~~~~~00~~~~~",
      "~~~~~~~~00$$~~~~",
      "~~~~~~~00~$~~~~~",
      "!~~~~~00~~~~~~~~",
      "~~~000~~~~~~~~~~",
      "0000~~~~~~~~~~~~",
      "~~~~~~~~~~~~~~~~",
      "~~~~~~~~~~~~~~~~",
      "~~~~~~~~~~~~~~~~",
      "~~~~~~~~~~~~~~~~",
      "~~~~~~~~~~~~~~~~"
    ],
    [
      "~~~~~~~~~~~~0~~~",
      "~~~~~~~~~~~00~~~",
      "~~~~~~~~~~~~~~~~",
      "~~~~~~~~~~~0~~~~",
      "~~~~~~~~~~0~~~~~",
      "~~~~~~~~~00~~~~~",
      "~~~~~~~~00$$~~~~",
      "~~~~~~~00~$~~~~~",
      "~~~~~~00~~~~~~~~",
      "~~~0~0~~~~~~~~~~",
      "~~00~~~~~~~~~~~~",
      "~~~~~~~~~~~~~~~~",
      "~~~~~~~~~~~~~~~~",
      "~~~~~~~~~~~~~~~~",
      "~~~~~~~~~~~~~~~~",
      "~~~~~~~~~~~~~~~~"
    ],
    [
      "~~~~~~~~~~~~0~~~",
      "~~~~~~~~~~~00~~~",
      "~~~~~~~~~~~0~~~~",
      "~~~~~~~~~~~0~~~~",
      "~~~~~~~~$$0~~~~~",
      "~~~~~~~~~00~~~~~",
      "~~~~~~~~00$$~~~~",
      "~~~~~~~00~$~~~~~",
      "~~~~~~00~~~~~~~~",
      "~~~000~~~~~~~~~~",
      "0000~~~~~~~~~~~~",
      "~~~~~~~~~~~~~~~~",
      "~~~~~~~~~~~~~~~~",
      "~~~~~~~~~~~~~~~~",
      "~~~~~~~~~~~~~~~~",
      "~~~~~~~~~~~~~~~~"
    ]
  ]
}