{
  "xsize": 16,
  "zsize": 16,
  "refpalette": "lostcities:quarry",
  "slices": [
    [
      "~~~~~~~~~~~~$$$~",
      "~~~~~~~~~~~~~$!~",
      "~~~~~~~~~~~~~!!!",
      "~~!!!!!~~~~~~!~~",
      "~~!!!!!~~~~~~!~~",
      "~~!!!!!~~~~~~!~~",
      "~~!!!!!~~~~~~!~~",
      "~~!!!!!~~~~~~!~~",
      "~~!!!!!~~~~~~!~~",
      "~~!!!!!~~~~~~!~~",
      "~~!!!!!~~~~~~!~~",
      "~~!!!!!~~~~~~!~~",
      "~~!!!!!~~~~~~!~~",
      "~~!!!!!~~~~~~!~~",
      "~~!!!!!~~~~~~!~~",
      "~~!!!!!~~~~~~!~~"
    ],
    [
      "~~~~~~~~~~~$$$!!",
      "~~~~~~~~~~~~$$!!",
      "~~~~~~~~~~~~~!!!",
      "~~~~~~~~~~~~~!!!",
      "~~~~~~~~~~~~~!!!",
      "~~~~~~~~~~~~~!!!",
      "~~~~~~~~~~~~~!!!",
      "~~~~~~~~~~~~~!!!",
      "~~~~~~~~~~~~~!!!",
      "~~~~~~~~~~~~~!!!",
      "~~~~~~~~~~~~~!!!",
      "~~~~~~~~~~~~~!!!",
      "~~~~~~~~~~~~~!!!",
      "~~~~~~~~~~~~~!!!",
      "~~~~~~~~~~~~~!!!",
      "~~~~~~~~~~~~~!!!"
    ],
    [
      "~~~~~~~~~~~$!!!!",
      "~~~~~~~~~~!!!!!!",
      "~~~~~~~~!!!!!!!!",
      "~~~~~~~!!!!!!!!!",
      "~~~~~~!!!!!!!!!!",
      "~~~~~!!!!!!!!!!!",
      "~~~~!!!!!!!!!!!!",
      "~~~~!!!!!!!!!!!!",
      "~~~!!!!!!!!!!!!!",
      "~~~!!!!!!!!!!!!!",
      "~~!!!!!!!!!!!!!!",
      "~~!!!!!!!!!!!!!!",
      "~~!!!!!!!!!!!!!!",
      "~~!!!!!!!!!!!!!!",
      "~~!!!!!!!!!!!!!!",
      "~~!!!!!!!!!!!!!!"
    ],
    [
      "~~~~~~~~~~~$$$~~",
      "~~~~~~~~~~~~0000",
      "~~~~~~~~~~000~~~",
      "~~~~~~~~00~~~~~~",
      "~~~~~~~00~~~~~~~",
      "~~~~~~00~~~~~~~~",
      "~~~~~00~~~~~~~~~",
      "~~~~~0~~~~~~~~~~",
      "~~~~0~~~~~~~~~~~",
      "~~~~0~~~~~~~~~~~",
      "~~~00~~~~~~~~~~~",
      "~~~0~~~~~~~~~~~~",
      "~~~0~~~~~~~~~~~~",
      "~~~0~~~~~~~~~~~~",
      "~~~0~~~~~~~~~~~~",
      "~~~0~~~~~~~~~~~~"
    ],
    [
      "~~~~~~~~~~~$$$~~",
      "~~~~~~~~~~~~00~~",
      "~~~~~~~~~~0~0~~~",
      "~~~~~~~~00~~~~~~",
      "~~~~~~~00~~~~~~~",
      "~~~~~~00~~~~~~~~",
      "~~~~~00~~~~~~~~~",
      "~~~~~0~~~~~~~~~~",
      "~~~~0~~~~~~~~~~~",
      "~~~~~~~~~~~~~~~~",
      "~~~00~~~~~~~~~~~",
      "~~~0~~~~~~~~~~~~",
      "~~~~~~~~~~~~~~~~",
      "~~~~~~~~~~~~~~~~",
      "~~~~~~~~~~~~~~~~",
      "~~~~~~~~~~~~~~~~"
    ],
    [
      "~~~~~~~~~~~$$$~~",
      "~~~~~~~~~~~~0000",
      "~~~~~~~~~~000~~$",
      "~~~~~~~~00~~~~~~",
      "~~~~~~~00~~~~~~~",
      "~~~~~~00~~~~~~~~",
      "~~~~~00~~~~~~~~~",
      "~~~~~0~~~~~~~~~~",
      "~~~~0~~~~~~~~~~~",
      "~~~~0~~~~~~~~~~~",
      "~~~00~~~~~~~~~~~",
      "~~~0~~~~~~~~~~~~",
      "~~~0~~~~~~~~~~~~",
      "~~~0~~~~~~~~~~~~",
      "~~~0~~~~~~~~~~~~",
      "~~~0~~~~~~~~~~~~"
    ]
  ]
}