{
  "xsize": 16,
  "zsize": 16,
  "refpalette": "lostcities:quarry",
  "slices": [
    [
      "~~~~~~~~~~~~~~~~",
      "~~~~~~~~~~~~~~~~",
      "~~~~~~~~~~~~~~~~",
      "~~~~~~~~~~~~~~~~",
      "~~~~~~~~~<<~~~~~",
      "000000000<<~~~~~",
      "000000000&~~~~~~",
      "000000000&~~~~~~",
      "000000000&$~~~~~",
      "000000000&$$$~~~",
      "000000000&$$$~~~",
      "000000000&$~~~~~",
      "000000000&~~~~~~",
      "000000000&~~~~~~",
      "000000000&~~~~~~",
      "000000000&~~~~~~"
    ],
    [
      "~~~~~~~~~~~~~~~~",
      "~~~~~~~~~~~~~~~~",
      "~~~~~~~~~~~~~~~~",
      "~~~~~~~~~~~~~~~~",
      "~~~~~~~~~<<~~~~~",
      "000000000<<~~~~~",
      "~~~~~~~~~&~~~~~~",
      "~~~~~~~~~&~~~~~~",
      "~~~~~~~~~&$~~~~~",
      "~~~~~~~~~&$$~~~~",
      "~~~~~~~~~&$~~~~~",
      "~~~~~~~~~&~~~~~~",
      "~~~~~~~~~&~~~~~~",
      "~~~~~~~~~&~~~~~~",
      "~~~~~~~~~&~~~~~~",
      "~~~~~~~~~&~~~~~~"
    ],
    [
      "~~~~~~~~~~~~~~~~",
      "~~~~~~~~~~~~~~~~",
      "~~~~~~~~~~~~~~~~",
      "~~~~~~~~~~~~~~~~",
      "~~~~~~~~~<<~~~~~",
      "~~~00~~~0<<~~~~~",
      "~~~~~~~~~&~~~~~~",
      "~~~~~~~~~&$~~~~~",
      "~~~~~~~~~&$$~~~~",
      "~~~~~~~~~$$$~~~~",
      "~~~~~~~~~~$~~~~~",
      "~~~~~~~~~~~~~~~~",
      "~~~~~~~~~~~~~~~~",
      "~~~~~~~~~&~~~~~~",
      "~~~~~~~~~&~~~~~~",
      "~~~~~~~~~~~~~~~~"
    ],
    [
      "~~~~~~~~~~~~~~~~",
      "~~~~~~~~~~~~~~~~",
      "~~~~~~~~~~~~~~~~",
      "~~~~~~~~~~~~~~~~",
      "~~~~~~~~~<<~~~~~",
      "~~~00~~~0<<~~~~~",
      "~~~~~~~~~&~~~~~~",
      "~~~~~~~~~&$$~~~~",
      "~~~~~~~~~&$$~~~~",
      "~~~~~~~~~~$~~~~~",
      "~~~~~~~~~~~~~~~~",
      "~~~~~~~~~~~~~~~~",
      "~~~~~~~~~~~~~~~~",
      "~~~~~~~~~&~~~~~~",
      "~~~~~~~~~&~~~~~~",
      "~~~~~~~~~~~~~~~~"
    ],
    [
      "~~~~~~~~~~~~~~~~",
      "~~~~~~~~~~~~~~~~",
      "~~~~~~~~~~~~~~~~",
      "~~~~~~~~~~~~~~~~",
      "~~~~~~~~~<<~~~~~",
      "~~~00~~~0<<~~~~~",
      "~~~~~~~~~&$$~~~~",
      "~~~~~~~~~&$$$~~~",
      "~~~~~~~~~&$$~~~~",
      "~~~~~~~~~~$~~~~~",
      "~~~~~~~~~~~~~~~~",
      "~~~~~~~~~~~~~~~~",
      "~~~~~~~~~~~~~~~~",
      "~~~~~~~~~&~~~~~~",
      "~~~~~~~~~&~~~~~~",
      "~~~~~~~~~~~~~~~~"
    ],
    [
      "~~~~~~~~~~~~~~~~",
      "~~~~~~~~~~~~~~~~",
      "~~~~~~~~~~~~~~~~",
      "~~~~~~~~~~~~~~~~",
      "~~~~~~~~~<<~~~~~",
      "~~~00~~~0<<~~~~~",
      "~~~~~~~~~&~$~~~~",
      "~~~~~~~~~&$$$~~~",
      "~~~~~~~~~&$$~~~~",
      "~~~~~~~~~~~~~~~~",
      "~~~~~~~~~~~~~~~~",
      "~~~~~~~~~~~~~~~~",
      "~~~~~~~~~~~~~~~~",
      "~~~~~~~~~&~~~~~~",
      "~~~~~~~~~&~~~~~~",
      "~~~~~~~~~~~~~~~~"
    ]
  ]
}