{
  "xsize": 16,
  "zsize": 16,
  "refpalette": "lostcities:quarry",
  "slices": [
    [
      "''~~~~~~~~~~~~~~",
      "~~~~~~~~~~~~~~~~",
      "~~~~~~~~~~~~~~~~",
      "7~~~~~~~~~~~~~~~",
      "66~~~~~~~~~~~~~~",
      "!~~~~~~~~~~~~~~~",
      "!~~~~~~~~~~~~~~~",
      "~~~~~~~~~~~~~~~~",
      "!~~~~~~~~~~~~~~~",
      "!~~~~~~~~~~~~~~~",
      "$~~~~~~~~~~~~~~~",
      "!~~~~~~~~~~~~~~~",
      "!~~!~~~~~~~~~~~~",
      "!~~!~~~~~~~~~~~~",
      "!~~!~~~~~~~~~~~~",
      "~~~!~!~~~~~~~~~~"
    ],
    [
      "~~~~~~~~~~~~~~~~",
      "~~~~~~~~~~~~~~~~",
      "~~~~~~~~~~~~~~~~",
      "7~~~~~~~~~~~~~~~",
      "!!~~~~~~~~~~~~~~",
      "66~~~~~~~~~~~~~~",
      "!~~~~~~~~~~~~~~~",
      "!~~~~~~~~~~~~~~~",
      "!~~~~~~~~~~~~~~~",
      "~~~~~~~~~~~~~~~~",
      "$~~~~~~~~~~~~~~~",
      "!~~~~~~~~~~~~~~~",
      "!~~~~~~~~~~~~~~~",
      "~~~~~~~~~~~~~~~~",
      "!~~~~~~~~~~~~~~~",
      "!~~~~~~~~~~~~~~~"
    ],
    [
      "~~~~~~~~~~~~~~~~",
      "~~~~~~~~~~~~~~~~",
      "~~~~~~~~~~~~~~~~",
      "7~~~~~~~~~~~~~~~",
      "'~~~~~~~~~~~~~~~",
      "66~~~~~~~~~~~~~~",
      "66~~~~~~~~~~~~~~",
      "!~~~~~~~~~~~~~~~",
      "~~~~~~~~~~~~~~~~",
      "~~~~~~~~~~~~~~~~",
      "$~~~~~~~~~~~~~~~",
      "!~~~~~~~~~~~~~~~",
      "!~~~~~~~~~~~~~~~",
      "~~~~~~~~~~~~~~~~",
      "~~~~~~~~~~~~~~~~",
      "!~~~~~~~~~~~~~~~"
    ],
    [
      "~~~~~~~~~~~~~~~~",
      "~~~~~~~~~~~~~~~~",
      "~~~~~~~~~~~~~~~~",
      "'~~~~~~~~~~~~~~~",
      "'!~~~~~~~~~~~~~~",
      "'!~~~~~~~~~~~~~~",
      "66~~~~~~~~~~~~~~",
      "66~~~~~~~~~~~~~~",
      "!~~~~~~~~~~~~~~~",
      "!~~~~~~~~~~~~~~~",
      "~~~~~~~~~~~~~~~~",
      "!~~~~~~~~~~~~~~~",
      "!~~~~~~~~~~~~~~~",
      "~~~~~~~~~~~~~~~~",
      "!~~~~~~~~~~~~~~~",
      "!~~~~~~~~~~~~~~~"
    ],
    [
      "~~~~~~~~~~~~~~~~",
      "~~~~~~~~~~~~~~~~",
      "~~~~~~~~~~~~~~~~",
      "'~~~~~~~~~~~~~~~",
      "'~~~~~~~~~~~~~~~",
      "!!~~~~~~~~~~~~~~",
      "!!~~~~~~~~~~~~~~",
      "66~~~~~~~~~~~~~~",
      "66~~~~~~~~~~~~~~",
      "!~~~~~~~~~~~~~~~",
      "!~~~~~~~~~~~~~~~",
      "!~~~~~~~~~~~~~~~",
      "!~~~~~~~~~~~~~~~",
      "!~~~~~~~~~~~~~~~",
      "!~~~~~~~~~~~~~~~",
      "66~~~~~~~~~~~~~~"
    ],
    [
      "~~~~~~~~~~~~~~~~",
      "~~~~~~~~~~~~~~~~",
      "~~~~~~~~~~~~~~~~",
      "'~~~~~~~~~~~~~~~",
      "'!~~~~~~~~~~~~~~",
      "!!~~~~~~~~~~~~~~",
      "~~~~~~~~~~~~~~~~",
      "!~~~~~~~~~~~~~~~",
      "!~~~~~~~~~~~~~~~",
      "66~~~~~~~~~~~~~~",
      "66~~~~~~~~~~~~~~",
      "66~~~~~~~~~~~~~~",
      "66~~~~~~~~~~~~~~",
      "66~~~~~~~~~~~~~~",
      "66~~~~~~~~~~~~~~",
      "!!~~~~~~~~~~~~~~"
    ]
  ]
}