{
  "xsize": 16,
  "zsize": 16,
  "refpalette": "lostcities:factory",
  "slices": [
    [
      "   &&& Q        ",
      "   && QQ        ",
      "   &  QQ        ",
      "   &  QQ        ",
      "     QQ     &   ",
      "    QQ     !!&  ",
      " QQQQ      !!   ",
      "QQQQ            ",
      "                ",
      "                ",
      "                ",
      "     !!         ",
      "     !!         ",
      "                ",
      "                ",
      "                "
    ],
    [
      "   &&&  QQ      ",
      "    &   QQ      ",
      "        Q       ",
      "        Q       ",
      "       QQ  &&   ",
      "      QQ   !!&  ",
      "     QQ    !!   ",
      "    QQ          ",
      "QQQQQ           ",
      "QQ              ",
      "                ",
      "     !!         ",
      "     !!         ",
      "                ",
      "                ",
      "                "
    ],
    [
      "   &&&    Q !   ",
      "    &&    Q !   ",
      "         Q  !   ",
      "         Q !!   ",
      "         Q&!&   ",
      "        Q &!!&  ",
      "       QQ !!!   ",
      "      QQ !!     ",
      "     QQ !!      ",
      "  QQQ  !!       ",
      "QQ    !!        ",
      "   !!!!         ",
      "!!!! !!         ",
      "                ",
      "                ",
      "                "
    ],
    [
      "   &&&     Q!   ",
      "   &&&&    Q!   ",
      "    &&    Q !   ",
      "          Q!!   ",
      "          Q!&   ",
      "         Q !!   ",
      "         Q!!!   ",
      "        Q!!     ",
      "       Q!!      ",
      "     QQ!!       ",
      "  QQQ !!        ",
      "QQ !!!!         ",
      "!!!! !!         ",
      "                ",
      "                ",
      "                "
    ],
    [
      "    &&     Q    ",
      "    &&&    Q    ",
      "     &     Q&   ",
      "           Q&&  ",
      "          &Q&&  ",
      "          Q!!   ",
      "          Q!!   ",
      "         Q      ",
      "        Q       ",
      "       Q        ",
      "     QQ         ",
      "QQQQQ!!         ",
      "     !!         ",
      "                ",
      "                ",
      "                "
    ],
    [
      "     &      Q   ",
      "    &&&     Q   ",
      "     &      Q&  ",
      "           &Q&  ",
      "           Q&   ",
      "           Q!   ",
      "          Q!!   ",
      "          Q     ",
      "         Q      ",
      "        Q       ",
      "      QQ        ",
      "    QQ!         ",
      "QQQQ !!         ",
      "                ",
      "                ",
      "                "
    ]
  ]
}