{
  "xsize": 16,
  "zsize": 16,
  "refpalette": "lostcities:factory",
  "slices": [
    [
      "VVVVVVVVVVVVVVVV",
      "VVVVVVVVVVVVVVVV",
      "VVVVVVVVVVVVVVVV",
      "VVVVVVVVVVVVVVVV",
      "VVVVVVVVVVVVVVVV",
      "VVVVVVVVVVVVVVVV",
      "VVVVVVVVVVVVVVVV",
      "VVVVVVVVVVVVVVVV",
      "VVVVVVVVVVVVVVVV",
      "VVVVVVVVVVVVVVVV",
      "VVVVVVVVVVVVVVVV",
      "VVVVVVVVVVVVVVVV",
      "VVVVVVVVVVVVVVVV",
      "VVVVVVVVVVVVVVVV",
      "VVVVVVVVVVVVVVVV",
      "VVVVVVVVVVVVVVVV"
    ],
    [
      " V J   J V J  ! ",
      " V J   J V J !!!",
      " V       V   !!!",
      " V       V   !! ",
      " V       V    ! ",
      " V       V    ! ",
      " V J   J V J  ! ",
      " V J   J V J  ! ",
      " V J   J V J  ! ",
      " V J   J V J  ! ",
      " V J   J V J  ! ",
      " V       V    ! ",
      " V       V    ! ",
      "VV       V    ! ",
      "         V    ! ",
      "         V    ! "
    ],
    [
      "   X   X   X  ! ",
      "   J   J   J !!!",
      "             !!!",
      "             !i ",
      "              i ",
      "              i ",
      "   J   J   J  i ",
      "&  X   X   X  i ",
      "   X   X   X  i ",
      "   X   X   X  i ",
      "   J   J   J  i ",
      "              i ",
      "              i ",
      "              i ",
      "              i ",
      "              i "
    ],
    [
      "              ! ",
      "   J   J   J !!!",
      "             !!!",
      "             !i ",
      "              i ",
      "              i ",
      "   J   J   J  i ",
      "&             i ",
      "              i ",
      "              i ",
      "   J   J   J  i ",
      "              i ",
      "              i ",
      "              i ",
      "              i ",
      "              i "
    ],
    [
      "   J   J   J  ! ",
      "   J   J   J !!!",
      "             !!!",
      "             !i ",
      "              i ",
      "              i ",
      "   J   J   J  i ",
      "&  J   J   J  i ",
      "   J   J   J  i ",
      "   J   J   J  i ",
      "   J   J   J  i ",
      "              i ",
      "              i ",
      "              i ",
      "              i ",
      "              i "
    ],
    [
      " X X   X X X  ! ",
      "JJJJ   JJJJJ !!!",
      "             !!!",
      "             !i ",
      "              i ",
      "              i ",
      "JJJJ   JJJJJ  i ",
      "&X X   X X X  i ",
      " X X   X X X  i ",
      " X X   X X X  i ",
      "JJJJ   JJJJJ  i ",
      "              i ",
      "              i ",
      "              i ",
      "              i ",
      "              i "
    ]
  ]
}