{
  "xsize": 16,
  "zsize": 16,
  "refpalette": "lostcities:factory",
  "slices": [
    [
      "                ",
      "               r",
      "r            rr ",
      " rr  &     rr   ",
      "   rrrrrrrr&&   ",
      "    &&&    &    ",
      "     &          ",
      "                ",
      "                ",
      "                ",
      "                ",
      "                ",
      "                ",
      "                ",
      "                ",
      "                "
    ],
    [
      "                ",
      "               J",
      "J            JJJ",
      "JJJ  &     JJJJ ",
      " JJJrJJJJrJJJ   ",
      "   J&JJJJ J&    ",
      "     &          ",
      "                ",
      "                ",
      "                ",
      "                ",
      "                ",
      "                ",
      "                ",
      "                ",
      "                "
    ],
    [
      "                ",
      "               J",
      "             JJJ",
      "           JJJJ ",
      " JJJrJJJJrJJJ   ",
      "   J&JJJJ J&    ",
      "     &          ",
      "                ",
      "                ",
      "                ",
      "                ",
      "                ",
      "                ",
      "                ",
      "                ",
      "                "
    ],
    [
      "        &       ",
      "        &      J",
      "       &&    JJJ",
      "       &   JJJJ ",
      "  J  JJJJrJJJ   ",
      "   J&JJJJ J&    ",
      "     &          ",
      "                ",
      "                ",
      "                ",
      "                ",
      "                ",
      "                ",
      "                ",
      "                ",
      "                "
    ],
    [
      "   !!!!!!!!!!!!!",
      "    !!!!!!!!!!!!",
      "     !!!!!!!!!!!",
      "     !!!!!!!!!! ",
      "    !!!!!!!!!   ",
      "   !!!!!!!!&    ",
      "    &&&         ",
      "     &          ",
      "                ",
      "                ",
      "                ",
      "                ",
      "                ",
      "                ",
      "                ",
      "                "
    ],
    [
      "        &       ",
      "        &      J",
      "       &&    JJ ",
      "      &&&&&JJ   ",
      "     JJJJJJ&&   ",
      "    &&&& &&&    ",
      "     &&         ",
      "                ",
      "                ",
      "                ",
      "                ",
      "                ",
      "                ",
      "                ",
      "                ",
      "                "
    ]
  ]
}