{
  "xsize": 16,
  "zsize": 16,
  "refpalette": "lostcities:factory",
  "slices": [
    [
      "t              t",
      "    &!!!!!!     ",
      "   &!!VVVV      ",
      "   !VV          ",
      "  !V      &  !  ",
      " !!V     &&&V!! ",
      " !V      &&& V! ",
      " !V      &&  V! ",
      "&!V          V!&",
      "&&&          V! ",
      " &          V!! ",
      "            V!  ",
      "    VV    VV!   ",
      "    !!VVVV!!    ",
      "     !!!!!!     ",
      "t              t"
    ],
    [
      "t              t",
      "     & P5P      ",
      "    &&VVVV      ",
      "    VV&   &&    ",
      "   V &   &&&    ",
      "   V     &&&V   ",
      " PV       &  V  ",
      " 5V          VP ",
      "&PV         &V5&",
      " &          &VP ",
      "            V&  ",
      "            V   ",
      "    VV    VV    ",
      "      VVVV      ",
      "      P5P       ",
      "t              t"
    ],
    [
      "t              t",
      "       P5P      ",
      "     &VVVV &    ",
      "    VV&   &&&   ",
      "   V &   &&&V   ",
      "   V      &&V   ",
      " PV          V  ",
      "&5V          VP ",
      "&PV          V5 ",
      " &V         &VP ",
      "   V&       V&  ",
      "   V        V   ",
      "    VV    VV    ",
      "      VVVV      ",
      "      P5P       ",
      "t              t"
    ],
    [
      "t              t",
      "       P5P &    ",
      "      VVVV&&&   ",
      "    VV    V&&   ",
      "   V      &&V   ",
      "   V        V   ",
      " PV          V  ",
      "&5V          VP ",
      " PV         &V  ",
      "  V&&&     &&V& ",
      "  &V&&     &V&  ",
      "   V&       V   ",
      "    VV    VV    ",
      "      VVVV      ",
      "      P5P       ",
      "t              t"
    ],
    [
      "t              t",
      "       P5P &    ",
      "      VVVV&&&   ",
      "    VV    VV    ",
      "   V        V   ",
      "   V        V   ",
      " PV          V  ",
      "&5V          V  ",
      "&PV &&&&     V  ",
      "  V&&&&     &&  ",
      "   V&&     &V&  ",
      "   V&      &V&  ",
      "    VV    VV&   ",
      "      VVVV      ",
      "      P5P       ",
      "t              t"
    ],
    [
      "t              t",
      "       P5P &    ",
      "      VVVV&&&   ",
      "    VV    VV&   ",
      "   V       &V   ",
      "   V        V   ",
      " PV             ",
      " 5V   &&&    V  ",
      "&PV  &&&&    V  ",
      "  V &&&&    &   ",
      "   V&&&    &V&  ",
      "   V       &V&  ",
      "    VV    VV&   ",
      "      VVVV      ",
      "      P5P       ",
      "t              t"
    ]
  ]
}