{
  "xsize": 16,
  "zsize": 16,
  "refpalette": "lostcities:factory",
  "slices": [
    [
      "             !!!",
      "             !!!",
      "             !!!",
      "/            !!!",
      "3            !!!",
      "             !!!",
      "             !! ",
      "             !! ",
      "             !!!",
      "/            !!!",
      "3            !!!",
      "             !!!",
      " OVVVO OVVVO !!!",
      " VOOOV VOOOV !!!",
      " VOOOV VOOOV  ! ",
      " VOOOV VOOOV    "
    ],
    [
      "             !!!",
      "             !!!",
      "             !!!",
      "/            !!!",
      "3            !!!",
      "             !!!",
      "             !! ",
      "             !! ",
      "             !!!",
      "/            !!!",
      "3            !!!",
      "             !!!",
      " OOOOO OOOOO !!!",
      " OOOOO OOOOO !!!",
      " OOOOO OOOOO !! ",
      " OOOOO OOOOO !! "
    ],
    [
      "              i ",
      "              i ",
      "             !i ",
      "/            !!!",
      "3            !!!",
      "             !!!",
      "              ! ",
      "              ! ",
      "             !!!",
      "/            !!!",
      "3            !!!",
      "             !i ",
      "              i ",
      "              i ",
      "             !i ",
      "                "
    ],
    [
      "                ",
      "                ",
      "             !  ",
      "V            !!!",
      "V            !!!",
      "             !!!",
      "                ",
      "                ",
      "             !!!",
      "V            !!!",
      "V            !!!",
      "             !  ",
      "                ",
      "                ",
      "             !  ",
      "                "
    ],
    [
      "V            V  ",
      "V            V  ",
      "VV           !  ",
      "nVVVVVVVVV  VV!!",
      "nVVVVVVVVVVVV!!!",
      "VV           !!!",
      "             V  ",
      "             V  ",
      "VV           !!!",
      "nVVVVVVVVVVVV!!!",
      "nVVVVVVVVVVVVV!!",
      "VV           !  ",
      "V            V  ",
      "V               ",
      "V               ",
      "V               "
    ],
    [
      "!!rrrrrrrrrr!!!!",
      "!!rrrrrrrrrr!!!!",
      "!!!!!!!!!   !!!!",
      "!!!!!!!!!    !!!",
      "!!!!!!!!!!   !!!",
      "!!!!!!!!!!   !!!",
      "rrrrrrrrrrrr!!!!",
      "rrrrrrrrrrrr!!!!",
      "!!!!!!!!!!   !!!",
      "!!!!!!!!!!   !!!",
      "!!!!!!!!!!   !!!",
      "!!!!!!!!!!   !!!",
      "!!!!!!!!!!   !!!",
      "!!!!!!!!!!!     ",
      "!!!!!!!!!!!     ",
      "!!!!!!!!!!      "
    ]
  ]
}