{
  "xsize": 16,
  "zsize": 16,
  "refpalette": "lostcities:factory",
  "slices": [
    [
      " 0   &5555      ",
      " 0P5&&&&    5   ",
      " 05 5&&    5 5  ",
      " 0 5&&  P   5   ",
      " 0 &&&          ",
      " 0 &&&          ",
      " 0  &           ",
      " 0  !!      !!  ",
      " 0              ",
      " 0!    !  !    !",
      " 0!   &!& !    !",
      " !     &        ",
      "    !!      !!  ",
      "                ",
      " !,,,,,     ,,!,",
      "                "
    ],
    [
      " 0   &&&        ",
      " 0P5 &&&&   5   ",
      " 05 5&&&   5 5  ",
      " 0 5 && P   5   ",
      " 0  &&          ",
      " 0 &&&&         ",
      " 0  &&          ",
      " 0  55      55  ",
      " 0 5555    5555 ",
      " 0555555  555555",
      " 0555555& 555555",
      " ! 5555&   5555 ",
      "    55      55  ",
      "                ",
      " !,,,,     ,,,!,",
      "                "
    ],
    [
      "      &&        ",
      "  P5  &&&   5   ",
      "  5 5&&&&  5 5  ",
      "   5 &&&P   5   ",
      "     &&         ",
      "    &&&         ",
      "    &&&         ",
      "    55      55  ",
      "   5555    5555&",
      "  55  55  55  55",
      "  55  55& 55  55",
      " $ 5555&   5555&",
      "    55      55  ",
      "                ",
      " $            $ ",
      "                "
    ],
    [
      "                ",
      "  P5  &&    5   ",
      "  5 55555555 5  ",
      "   5UUUU5UUU5   ",
      "      &         ",
      "     &          ",
      "    &&&         ",
      "    55&     55  ",
      "   5555    5555 ",
      "  55  55  55  55",
      "  55  55& 55  55",
      " ! 5555&   5555&",
      "    55      55  ",
      "                ",
      " !            ! ",
      "                "
    ],
    [
      "                ",
      "  P5        5   ",
      "  5 5 &&   5 5  ",
      "   5  &     5   ",
      "                ",
      "     &          ",
      "    &&&         ",
      "    55&&    55& ",
      "   5555    5555&",
      "  555555  555555",
      "  555555& 555555",
      "   5555&   5555&",
      "    55      55  ",
      "                ",
      "                ",
      "                "
    ],
    [
      "                ",
      "  P5        5   ",
      "  5 5      5 5  ",
      "   5        5   ",
      "                ",
      "                ",
      "     &&         ",
      "  tttttt  tttttt",
      "  tttttt  ttt&tt",
      "  tttttt  tt &&t",
      "  tttttt& tt  &t",
      "  tttttt  tt   &",
      "  tttttt  tttt t",
      "                ",
      "                ",
      "                "
    ]
  ]
}