{
  "xsize": 16,
  "zsize": 16,
  "refpalette": "lostcities:factory",
  "slices": [
    [
      "    &&&     Jr  ",
      "    &&       JJ ",
      "   &&&       &JJ",
      "    && !!!!   &J",
      "        rr   &  ",
      "        rr  &&& ",
      "       !  ! &&& ",
      "             &  ",
      "             &  ",
      "            &&& ",
      "             &  ",
      "                ",
      "                ",
      "                ",
      "                ",
      "                "
    ],
    [
      "   &&&&     Jr  ",
      "   &&&       JJ ",
      "   &&&       &JJ",
      "    &  !!!!   &J",
      "        rr      ",
      "        rr   &  ",
      "       !  ! &&& ",
      "            &&& ",
      "             &  ",
      "            &&& ",
      "            &&& ",
      "             &  ",
      "                ",
      "                ",
      "                ",
      "                "
    ],
    [
      "   JJ&      JrJJ",
      "   &JJ       JJJ",
      "   &JJJ      &JJ",
      "    &JJ!JJ!   &J",
      "      JJrJJ    &",
      "      JJJrJ     ",
      "       JJJ!  &  ",
      "        JJJJ&&& ",
      "          JJJ&& ",
      "           JJJJ ",
      "            &JJJ",
      "             & J",
      "                ",
      "                ",
      "                ",
      "                "
    ],
    [
      "   JJ       Jr  ",
      "   &JJ       JJ ",
      "   &JJJ       JJ",
      "    &JJ!  !   &J",
      "      JJrJ     &",
      "      JJJr      ",
      "       JJJ!     ",
      "        JJJJ &  ",
      "          JJJ&& ",
      "           JJJJ ",
      "            &JJJ",
      "             & J",
      "                ",
      "                ",
      "                ",
      "                "
    ],
    [
      "            Jr  ",
      "    &        Jr ",
      "    &         Jr",
      "       !  !   &J",
      "        rr     &",
      "        rr      ",
      "       !  !     ",
      "                ",
      "             &  ",
      "             &  ",
      "             &  ",
      "                ",
      "                ",
      "                ",
      "                ",
      "                "
    ],
    [
      "            Jr  ",
      "             JJ ",
      "              JJ",
      "       !  !    J",
      "        rr      ",
      "        rr      ",
      "       !  !     ",
      "                ",
      "                ",
      "                ",
      "                ",
      "                ",
      "                ",
      "                ",
      "                ",
      "                "
    ]
  ]
}