{
  "xsize": 16,
  "zsize": 16,
  "refpalette": "lostcities:factory",
  "slices": [
    [
      " J          J i ",
      " J          J i ",
      " J          J i ",
      " J          J i ",
      " JJJJJJJJJJJJ i ",
      "/            !i ",
      "3    &&      !!!",
      "    &&&&     !!!",
      "    &&&       ! ",
      "     &&&      ! ",
      "      &      !!!",
      "/            !!!",
      "3            !i ",
      "              i ",
      "              i ",
      "              i "
    ],
    [
      " J          J i ",
      " J          J i ",
      " J          J i ",
      " J          J i ",
      " JJJJJJJJJJJJ i ",
      "/            !i ",
      "3     &      !!!",
      "     &&&     !!!",
      "     &&&      ! ",
      "     &&&      ! ",
      "      &      !!!",
      "/            !!!",
      "3            !i ",
      "              i ",
      "              i ",
      "              i "
    ],
    [
      " J          J i ",
      " J          J i ",
      " J          J i ",
      " J          J i ",
      " JJJJJJJJJJJJ i ",
      "/            !i ",
      "3     &      !!!",
      "     &&&     !!!",
      "     &&&      ! ",
      "      &       ! ",
      "             !!!",
      "/            !!!",
      "3            !i ",
      "              i ",
      "              i ",
      "              i "
    ],
    [
      " J          J i ",
      " J          J i ",
      " J          J i ",
      " J          J i ",
      " JJJJJJJJJJJJ i ",
      "/     &      !i ",
      "3    &&&     !!!",
      "     &&&     !!!",
      "     &&&      ! ",
      "      &       ! ",
      "             !!!",
      "/            !!!",
      "3            !i ",
      "              i ",
      "              i ",
      "              i "
    ],
    [
      " J          J i ",
      " J          J i ",
      " J          J i ",
      " J          J i ",
      " JJJJJJJJJJJJ i ",
      "/     &      !i ",
      "3    &&&     !!!",
      "     &&&     !!!",
      "     &&&      ! ",
      "      &       ! ",
      "             !!!",
      "/            !!!",
      "3            !i ",
      "              i ",
      "              i ",
      "              i "
    ],
    [
      " J          J i ",
      " J          J i ",
      " J          J i ",
      " J          J i ",
      " JJJJJJJJJJJJ i ",
      "V     &      !i ",
      "V    &&&     !!!",
      "     &&&     !!!",
      "     &&&      ! ",
      "      &       ! ",
      "             !!!",
      "V            !!!",
      "V            !i ",
      "              i ",
      "              i ",
      "              i "
    ]
  ]
}