{
  "xsize": 16,
  "zsize": 16,
  "refpalette": "lostcities:factory",
  "slices": [
    [
      "vvvvvvvvvvvvvvvv",
      "vvvvvvvvvvvvvvvv",
      "vvvvvvvvvvvvvvvv",
      "vvvvvvvvvvvvvvvv",
      "vvvvvvvvvvvvvvvv",
      "vvv!!vvvvvvvvvvv",
      "vvv!!vvvvvvvvvvv",
      "vvvvvvvvvvvvvvvv",
      "vvvvvvvvvvvvvvvv",
      "vvvvvvvvvvvvvvvv",
      "vvvvvvvvvvvvvvvv",
      "vvvvvvvvv!!vvvvv",
      "vvvvvvvvv!!vvvvv",
      "vvvvvvvvvvvvvvvv",
      "vvvvvvvvvvvvvvvv",
      "vvvvvvvvvvvvvvvv"
    ],
    [
      "                ",
      "                ",
      "                ",
      "                ",
      "                ",
      "   !!           ",
      "  &!!           ",
      "   &            ",
      "                ",
      "                ",
      "                ",
      "         !!     ",
      "         !!     ",
      "                ",
      "                ",
      "                "
    ],
    [
      "                ",
      "                ",
      "                ",
      "                ",
      "   &            ",
      "  &!!           ",
      "  &!!           ",
      "   &            ",
      "                ",
      "                ",
      "                ",
      "         !!     ",
      "        &!!     ",
      "         &      ",
      "                ",
      "                "
    ],
    [
      "                ",
      "                ",
      "                ",
      "                ",
      "   &            ",
      "  &!!           ",
      "   !!           ",
      "                ",
      "                ",
      "                ",
      "                ",
      "         !!     ",
      "        &!!     ",
      "         &      ",
      "                ",
      "                "
    ],
    [
      "   !        QQQQ",
      "   !        QQQQ",
      "   !         QQQ",
      "   !!         QQ",
      "   &!           ",
      "  &!!           ",
      "   !!!          ",
      "     !!         ",
      "      !!        ",
      "       !!       ",
      "        !!      ",
      "         !!!!   ",
      "        &!! !!!!",
      "         &      ",
      "                ",
      "                "
    ],
    [
      "   !     QQQ    ",
      "   !      QQ    ",
      "   !    &&QQQ   ",
      "   !!   & QQQQ  ",
      "   &!      QQQQQ",
      "  &!!       QQQQ",
      "   !!!         Q",
      "     !!         ",
      "      !!        ",
      "       !!       ",
      "        !!      ",
      "         !!!!   ",
      "        &!! !!!!",
      "         &      ",
      "                ",
      "                "
    ]
  ]
}