{
  "xsize": 16,
  "zsize": 16,
  "refpalette": "lostcities:factory",
  "slices": [
    [
      "          &     ",
      "  ͳ,,,,,,,,,,q  ",
      "  !      &&& !  ",
      "         &!!    ",
      "       && &     ",
      "     &&&!&   !  ",
      " &&&&&&&!       ",
      "&&&&&           ",
      " &&&      !!    ",
      "                ",
      "                ",
      "                ",
      "                ",
      "             !  ",
      "    ,,q  ͳ,,,q  ",
      "                "
    ],
    [
      "                ",
      "          &     ",
      "  !       &  !  ",
      "         &55    ",
      "      && 5555   ",
      "     &&&555555  ",
      "     &&&555555  ",
      " &&&  &  5555   ",
      "          55    ",
      "                ",
      "                ",
      "                ",
      "                ",
      "             !  ",
      "                ",
      "                "
    ],
    [
      "                ",
      "                ",
      "  !       && !  ",
      "         &55    ",
      "         5555   ",
      "     &&&55  55  ",
      "   &&&&&55  55  ",
      "     &&  5555   ",
      "          55    ",
      "                ",
      "                ",
      "                ",
      "                ",
      "  !          !  ",
      "                ",
      "                "
    ],
    [
      "                ",
      "           &    ",
      "  !       &&&!  ",
      "         &55&   ",
      "         5555   ",
      "   &&&  55  55  ",
      "  &&&&& 55  55  ",
      "  &&&&   5555   ",
      "          55    ",
      "                ",
      "                ",
      "                ",
      "                ",
      "  !          !  ",
      "                ",
      "                "
    ],
    [
      "           &    ",
      "          &&&   ",
      "  !       &&&!  ",
      "          55&   ",
      "         5555   ",
      "   &    555555  ",
      "  &&&&  555555  ",
      " &&&&    5555   ",
      "  &&      55    ",
      "                ",
      "                ",
      "                ",
      "                ",
      "  !          !  ",
      "                ",
      "                "
    ],
    [
      "!!     !!  &  !!",
      "!tttttttttttttt!",
      "  !tttttttttt!t ",
      "    ttttttttttt ",
      "   tttttttttttt ",
      "   tttttttttttt ",
      " tttttttttttttt ",
      "&tttttttttttttt!",
      " tttttttttttttt!",
      " tttttttttttttt ",
      " tttttttttttttt ",
      " tttttttttttttt ",
      " tttttttttttttt ",
      " t!tttttttttt!t ",
      "!tttttttttttttt!",
      "!!     !!     !!"
    ]
  ]
}