{
  "xsize": 16,
  "zsize": 16,
  "refpalette": "lostcities:factory",
  "slices": [
    [
      " !              ",
      "                ",
      "       OOOO     ",
      "     OO    OO   ",
      "    O        O  ",
      "    O        O  ",
      "   O          O ",
      "   O          O ",
      "   O          O ",
      "   O          O ",
      "    O        O  ",
      "    O       &O  ",
      "     OO&   OO&  ",
      "      &OOOO &   ",
      "       &        ",
      " !              "
    ],
    [
      " !              ",
      "                ",
      "       OOOO     ",
      "     OO    OO   ",
      "    O        O  ",
      "    O        O  ",
      "   O          O ",
      "   O          O ",
      "   O          O ",
      "   O          O ",
      "    O        O  ",
      "    O       &O  ",
      "     OO&   OO&  ",
      "      &OOOO &   ",
      "       &        ",
      " !              "
    ],
    [
      " !              ",
      "                ",
      "       OOOO     ",
      "     OO    OO   ",
      "    O        O  ",
      "    O        O  ",
      "   O          O ",
      "   O          O ",
      "   O          O ",
      "   O          O ",
      "    O        O  ",
      "    O       &O  ",
      "     OO&&  OO&  ",
      "      &OOOO &   ",
      "       &&       ",
      " !              "
    ],
    [
      " !!!          !!",
      " !!            !",
      " !        O     ",
      "!    OO    OO   ",
      "!   O        O  ",
      "    O        O  ",
      "   O          O ",
      "   O          O ",
      "   O          O ",
      "   O          O ",
      "    O        O  ",
      "!   O        O  ",
      "!    OO && OO   ",
      " !     OOOO&    ",
      " !!     &&     !",
      " !!!          !!"
    ],
    [
      " !              ",
      "                ",
      "                ",
      "     O     OO   ",
      "    O        O  ",
      "    O        O  ",
      "   O          O ",
      "   O          O ",
      "   O          O ",
      "   O          O ",
      "    O        O  ",
      "    O      &&O  ",
      "     OO  &&OO&  ",
      "       OOOO&&   ",
      "         &&&    ",
      " !              "
    ],
    [
      " !              ",
      "                ",
      "                ",
      "     O      O   ",
      "    O        O  ",
      "55  O        O  ",
      "   O          O ",
      "55 O          O ",
      "   O          O ",
      "   O          O ",
      "    O        O  ",
      "    O        O  ",
      "     OO  &&OO   ",
      "       OOOO&&   ",
      "         &&&    ",
      " !              "
    ]
  ]
}