{
  "xsize": 16,
  "zsize": 16,
  "refpalette": "lostcities:factory",
  "slices": [
    [
      "!!  !!!!!!!!!!!$",
      "!!!!!!!!!!!!!!!!",
      "     !!!!!!!!!!!",
      "             !!!",
      "             !!!",
      "             !!!",
      "             !!!",
      "             !!!",
      "    55555    !!!",
      "   5     5   !!!",
      "  5       5  !!!",
      " 5         5 !!!",
      " 5         5 !!!",
      " 5         5 !!!",
      " 5         5 !!!",
      " 5         5 !!!"
    ],
    [
      "!   !!!!!!!!!!!!",
      "!! !!!!!!!!!!!!!",
      "     !!!!!!!!!!!",
      "             !!!",
      "             !!!",
      "             !!!",
      "             !!!",
      "             !!!",
      "    55555    !!!",
      "   5     5   !!!",
      "  5       5  !!!",
      " 5         5 !!!",
      "s5         5 !!!",
      "55         5 !!!",
      " 5         5 !!!",
      " 5         5 !!!"
    ],
    [
      "    !!!       !!",
      "!   !!![[[[[[[! ",
      "     !!!   !!!! ",
      "             !!!",
      "             !!!",
      "3            !!!",
      "             !i ",
      "              i ",
      "    55555     i ",
      "   5     5   !i ",
      "  5       5   i ",
      " 5         5  i ",
      " 5         5  i ",
      " 5         5 !i ",
      " 5         5  i ",
      " 5         5  i "
    ],
    [
      "     !!       ! ",
      "!    !!       ! ",
      "!    !!!   !!!! ",
      "             !!!",
      "V            !!!",
      "V            !!!",
      "             !  ",
      "                ",
      "    55555       ",
      "   5     5   !  ",
      "  5       5     ",
      " 5         5    ",
      " 5         5    ",
      " 5         5 !  ",
      " 5         5    ",
      " 5         5    "
    ],
    [
      "              ! ",
      "!    !!       ! ",
      "!    !V!VVVVV!! ",
      "V            !!!",
      "nV   VVVVVVVV!!!",
      "nVVVVVVVVVVVVV!!",
      "V            !  ",
      "V            V  ",
      "V   55555    V  ",
      "V  5     5   !  ",
      "V 5       5  V  ",
      "V5         5 V  ",
      "V5         5 V  ",
      "V5         5 !  ",
      "V5         5 V  ",
      "V5         5 V  "
    ],
    [
      "!      !!!!!!!!!",
      "!!   !!!!!!!!!!!",
      "!!!  !!!!!!!!!!!",
      "!!! !!!!!!!!!!!!",
      "!!!!!!!!!!!!!!!!",
      "!!!!!!!!!!!!!!!!",
      "!rrrrrrrrrrrr!!!",
      "!rrrrrrrrrrrr!!!",
      "!rrr55555rrrr!!!",
      "!rr5     5rrr!!!",
      "!r5       5rr!!!",
      "!5         5r!!!",
      "!5         5r!!!",
      "!5         5r!!!",
      "!5         5r!!!",
      "!5         5r !!"
    ]
  ]
}