{
  "xsize": 16,
  "zsize": 16,
  "refpalette": "lostcities:factory",
  "slices": [
    [
      "vvvvvvvvvvv     ",
      "vvvvvvvvvvv    v",
      "vvvvvvvvvvv  vvv",
      "vvvttttvvttttvvv",
      "vvvttttvvttttvvv",
      "vvvttttvvttttvvv",
      "vvvttttvvttttvvv",
      "vvvttttvvttttvvv",
      "vvvvvvvvvvvvvvvv",
      "vvvvvvvvvvvvvvvv",
      "vvvvvvvvvvvvvvvv",
      "vvvvvvvvvvvvvvvv",
      "vvvvvvvvvvvvvvvv",
      "vvvvvvvvvvvvvvvv",
      "vvvvvvvvvvvvvvvv",
      "vvvvvvvvvvvvvvvv"
    ],
    [
      "                ",
      "                ",
      "  !          !  ",
      "   OOOO  O      ",
      "   O <O  O <O   ",
      "  &O <O& O <O   ",
      " &&O&&O&&O  O   ",
      "  &OOOO&&OOOO   ",
      "       &        ",
      "       &&       ",
      "      &&<< <<   ",
      "       &<< <<   ",
      "                ",
      "  !          !  ",
      "                ",
      "                "
    ],
    [
      "                ",
      "                ",
      "  ! &        !  ",
      "   OVVO         ",
      "   V&<V  V <V   ",
      "   V&<V& V <V   ",
      "  &V&&V& V  V   ",
      "   OVVO& OVVO   ",
      "                ",
      "        &&      ",
      "       &<<&<<   ",
      "        << <<   ",
      "                ",
      "  !          !  ",
      "                ",
      "                "
    ],
    [
      "                ",
      "                ",
      "  ! &&       !  ",
      "   OVVO         ",
      "   V&&V&    V   ",
      "   V&&V& V  V   ",
      "  &V&&V  V  V   ",
      "   OVVO  OVVO   ",
      "                ",
      "                ",
      "        &&      ",
      "                ",
      "                ",
      "  !          !  ",
      "                ",
      "                "
    ],
    [
      "                ",
      "                ",
      "  ! &        !  ",
      "   OO&          ",
      "   OO&&    OO   ",
      "  &OOO&& OOOO   ",
      "  &OOOO  OOOO   ",
      "   OOOO  OOOO   ",
      "                ",
      "                ",
      "                ",
      "                ",
      "                ",
      "  !          !  ",
      "                ",
      "                "
    ],
    [
      "                ",
      "                ",
      "  !          !  ",
      "    &           ",
      "     &&         ",
      "   &&&&&        ",
      "   & &&         ",
      "                ",
      "                ",
      "                ",
      "                ",
      "                ",
      "                ",
      "  !          !  ",
      "                ",
      "                "
    ]
  ]
}