{
  "xsize": 16,
  "zsize": 16,
  "refpalette": "lostcities:factory",
  "slices": [
    [
      "QQQQQQQQ     &  ",
      "QQQQQQQQ        ",
      "QQQQQQQQ        ",
      "QQQQQQQQ        ",
      "QQQQQQQ         ",
      "QQQQQQ     !!   ",
      "QQQQQ      !!   ",
      "QQQQ            ",
      "                ",
      "                ",
      "                ",
      "     !!&        ",
      "     !!&        ",
      "                ",
      "                ",
      "                "
    ],
    [
      "QQQQQQQQQQ      ",
      "QQQQQQQQQQ      ",
      "QQQQQQQQQ       ",
      "QQQQQQQQQ       ",
      "QQQQQQQQQ       ",
      "QQQQQQQQ   !!   ",
      "QQQQQQQ    !!   ",
      "QQQQQQ          ",
      "QQQQQ           ",
      "QQ              ",
      "                ",
      "     !!         ",
      "     !!&        ",
      "                ",
      "                ",
      "                "
    ],
    [
      "QQQQQQQQQQQ !   ",
      "QQQQQQQQQQQ !   ",
      "QQQQQQQQQQ  !   ",
      "QQQQQQQQQQ !!   ",
      "QQQQQQQQQQ !    ",
      "QQQQQQQQQ  !!   ",
      "QQQQQQQQQ !!!   ",
      "QQQQQQQQ !!     ",
      "QQQQQQQ !!      ",
      "QQQQQ  !!       ",
      "QQ    !!        ",
      "   !!!!         ",
      "!!!! !!&        ",
      "                ",
      "                ",
      "                "
    ],
    [
      "QQQQQQQQQQQQ!   ",
      "QQQQQQQQQQQQ!   ",
      "QQQQQQQQQQQ !   ",
      "QQQQQQQQQQQ!!   ",
      "QQQQQQQQQQQ!    ",
      "QQQQQQQQQQ !!   ",
      "QQQQQQQQQQ!!!   ",
      "QQQQQQQQQ!!     ",
      "QQQQQQQQ!!      ",
      "QQQQQQQ!!       ",
      "QQQQQ !!        ",
      "QQ !!!!         ",
      "!!!! !!&        ",
      "                ",
      "                ",
      "                "
    ],
    [
      "QQQQQQQQQQQQV   ",
      "QQQQQQQQQQQQV   ",
      "QQQQQQQQQQQQV   ",
      "QQQQQQQQQQQVV   ",
      "QQQQQQQQQQQV    ",
      "QQQQQQQQQQQV!   ",
      "QQQQQQQQQQV!!   ",
      "QQQQQQQQQVV     ",
      "QQQQQQQQVV      ",
      "QQQQQQQVV       ",
      "QQQQQQVV        ",
      "QQQVVV!         ",
      "VVVV&!!         ",
      "     &&         ",
      "                ",
      "                "
    ],
    [
      "QQQQQQQQQQQQV   ",
      "QQQQQQQQQQQQV   ",
      "QQQQQQQQQQQQV   ",
      "QQQQQQQQQQQVV   ",
      "QQQQQQQQQQQV    ",
      "QQQQQQQQQQQV!   ",
      "QQQQQQQQQQV!!   ",
      "QQQQQQQQQVV     ",
      "QQQQQQQQVV      ",
      "QQQQQQQVV       ",
      "QQQQQQVV        ",
      "QQQVVV!         ",
      "VVVV&!!         ",
      "     &          ",
      "                ",
      "                "
    ]
  ]
}