{
  "xsize": 16,
  "zsize": 16,
  "refpalette": "lostcities:factory",
  "slices": [
    [
      "Vo    VVVV    kV",
      "Vo    VVVV    kV",
      "Vo    VVVV    kV",
      "Vo    VVVV    kV",
      "Vo    VVVV   &kV",
      "m3    VVVV   &2m",
      "      VVVV    &&",
      "      VVVV      ",
      "j/    VVVV    +j",
      "Vo    VVVV    kV",
      "Vo    VVVV    kV",
      "Vo    VVVV    kV",
      "Vo    VVVV    kV",
      "Vo    VVVV    kV",
      "Vo    VVVV    kV",
      "Vo    VVVV    kV"
    ],
    [
      " 0    0  0    0 ",
      " 0    0  0    0 ",
      " 0    0  0    0 ",
      "jo    0  0    kj",
      "no    0  0    kn",
      "m3    0  0   &2m",
      "      0  0    & ",
      "      0  0      ",
      "j/    0  0    +j",
      "no    0  0    kn",
      "mo    0  0    km",
      " 0    0  0    0 ",
      " 0    0  0    0 ",
      " 0    0  0    0 ",
      " 0    0  0    0 ",
      " 0    0  0    0 "
    ],
    [
      "                ",
      "                ",
      "                ",
      "/              +",
      "3             &2",
      "              &&",
      "                ",
      "                ",
      "                ",
      "/              +",
      "3              2",
      "                ",
      "                ",
      "                ",
      "                ",
      "                "
    ],
    [
      "                ",
      "                ",
      "                ",
      "/              +",
      "3             &2",
      "               &",
      "                ",
      "                ",
      "                ",
      "/              +",
      "3              2",
      "                ",
      "                ",
      "                ",
      "                ",
      "                "
    ],
    [
      "                ",
      "                ",
      "                ",
      "/              +",
      "3              2",
      "                ",
      "                ",
      "                ",
      "                ",
      "/              +",
      "3              2",
      "                ",
      "                ",
      "                ",
      "                ",
      "                "
    ],
    [
      "                ",
      "                ",
      "                ",
      "/              +",
      "3              2",
      "                ",
      "                ",
      "                ",
      "                ",
      "/              +",
      "3              2",
      "                ",
      "                ",
      "                ",
      "                ",
      "                "
    ]
  ]
}