{
  "xsize": 16,
  "zsize": 16,
  "refpalette": "lostcities:factory",
  "slices": [
    [
      "J              J",
      "J              J",
      "J              J",
      "VJ            JV",
      " J            J ",
      "  J          J  ",
      "    J      JJ   ",
      "     JJJJJJV    ",
      "     VV    V    ",
      "     VV    V    ",
      "    V      V    ",
      "    V      V    ",
      "    V      V    ",
      "           V    ",
      "           V    ",
      "    V      V    "
    ],
    [
      "J              J",
      "J              J",
      "J              J",
      "!J            JV",
      "!             J!",
      "             J  ",
      "           JJ   ",
      "     JJJJJJ!!   ",
      "     VVVVVVV!   ",
      "      VVVVVV!   ",
      "       VVVVV!   ",
      "       VVVVV!   ",
      "       VVVVV!   ",
      "       VVVVV!   ",
      "   !   VVVVV!   ",
      "   !V VVVVVV!   "
    ],
    [
      "J              J",
      "J              J",
      "               J",
      "              J!",
      "              J&",
      "             J  ",
      "           JJ   ",
      "     JJJJJJ!    ",
      "           !    ",
      "           !    ",
      "           !    ",
      "           !    ",
      "           !    ",
      "           !    ",
      "           !    ",
      "           !    "
    ],
    [
      "J              J",
      "               J",
      "              &J",
      "              J&",
      "              J&",
      "             J  ",
      "    J      JJ   ",
      "     JJJJJJ     ",
      "                ",
      "                ",
      "                ",
      "                ",
      "                ",
      "                ",
      "                ",
      "                "
    ],
    [
      "J              J",
      "               J",
      "              &J",
      "              J&",
      "              J ",
      "             J  ",
      "   JJ      JJ   ",
      "     JJJJJJ     ",
      "                ",
      "                ",
      "                ",
      "                ",
      "                ",
      "                ",
      "                ",
      "                "
    ],
    [
      "J              J",
      "J              J",
      "              &J",
      "              J&",
      "              J ",
      "  J          J  ",
      "   JJ      JJ   ",
      "     JJJJJJ     ",
      "                ",
      "                ",
      "                ",
      "                ",
      "                ",
      "                ",
      "                ",
      "                "
    ]
  ]
}