{
  "xsize": 16,
  "zsize": 16,
  "refpalette": "lostcities:factory",
  "slices": [
    [
      "             55&",
      "5           55  ",
      " 55       55    ",
      "   5555555      ",
      "                ",
      "                ",
      "                ",
      "                ",
      "                ",
      "                ",
      "                ",
      "                ",
      "    55555555    ",
      "  555      555  ",
      "55            55",
      "5              5"
    ],
    [
      "             55&",
      "5           55  ",
      " 55       55    ",
      "   5555555      ",
      "                ",
      "                ",
      "                ",
      "                ",
      "                ",
      "                ",
      "                ",
      "                ",
      "    55555555    ",
      "  555    5 555  ",
      "55            55",
      "5              5"
    ],
    [
      "             55&",
      "5           55  ",
      " 55       55    ",
      "   5555555      ",
      "                ",
      "                ",
      "                ",
      "                ",
      "                ",
      "                ",
      "                ",
      "                ",
      "    55555555    ",
      "  555      555  ",
      "55            55",
      "5              5"
    ],
    [
      "             55!",
      "5           55!!",
      "!55       55!!!!",
      "!!!5555555!!!!  ",
      "!!!!!!!!!!!!!   ",
      "   !!!!!!!      ",
      "                ",
      "                ",
      "                ",
      "                ",
      "                ",
      "                ",
      "    55555555    ",
      "  555      555  ",
      "55            55",
      "5              5"
    ],
    [
      "             55&",
      "5           55 &",
      " 55       55    ",
      "   5555555      ",
      "                ",
      "                ",
      "                ",
      "                ",
      "                ",
      "                ",
      "                ",
      "                ",
      "    55555555    ",
      "  555      555  ",
      "55            55",
      "5              5"
    ],
    [
      "             55&",
      "5           55  ",
      " 55       55    ",
      "   5555555      ",
      "                ",
      "                ",
      "                ",
      "                ",
      "                ",
      "                ",
      "                ",
      "                ",
      "    55555555    ",
      "  555      555  ",
      "55           555",
      "5              5"
    ]
  ]
}