{
  "xsize": 16,
  "zsize": 16,
  "refpalette": "lostcities:factory",
  "slices": [
    [
      "                ",
      "              !!",
      "              !!",
      "5&&             ",
      "5&&             ",
      " 5              ",
      " 5              ",
      " 5              ",
      " 5              ",
      " 5              ",
      " 5              ",
      " 5              ",
      "5               ",
      "5               ",
      "                ",
      "                "
    ],
    [
      "    555555555555",
      "    5555555555!!",
      " && 5555555555!!",
      "5&&&555555555555",
      "5&& 555555555555",
      " 5  555555555555",
      " 5  55555555    ",
      " 5  55555555    ",
      " 5  5555555     ",
      " 5  5555555     ",
      " 5  5555555     ",
      " 5  5555555     ",
      "5   5555555     ",
      "5   55555555    ",
      "    55555555    ",
      "    55555555    "
    ],
    [
      "                ",
      "              !!",
      "  & 5 5 5 5 5 !!",
      "5&&&            ",
      "5&&             ",
      " 5              ",
      " 5              ",
      " 5              ",
      " 5              ",
      " 5              ",
      " 5              ",
      " 5              ",
      "5               ",
      "5               ",
      "                ",
      "                "
    ],
    [
      "                ",
      "  &           !!",
      " &&&5U5U5U5U5U!!",
      "5&&&           Ͳ",
      "5 &            Ͳ",
      " 5             5",
      " 5              ",
      " 5              ",
      " 5              ",
      " 5              ",
      " 5              ",
      " 5              ",
      "5               ",
      "5               ",
      "                ",
      "&               "
    ],
    [
      "!               ",
      "!!&           !!",
      "!!!&          !!",
      "5!!&            ",
      "5!!&            ",
      " 5!!            ",
      " 5!!            ",
      " 5!!            ",
      " 5!!            ",
      " 5!!            ",
      " 5!!            ",
      " 5!!            ",
      "5!!             ",
      "5!!             ",
      "!!!             ",
      "!!              "
    ],
    [
      "                ",
      "                ",
      "  &             ",
      "5&&             ",
      "5&&&            ",
      "&5&             ",
      " 5              ",
      " 5              ",
      " 5              ",
      " 5              ",
      " 5              ",
      " 5              ",
      "5               ",
      "5               ",
      "&               ",
      "&&              "
    ]
  ]
}