{
  "xsize": 16,
  "zsize": 16,
  "refpalette": "lostcities:factory",
  "slices": [
    [
      "                ",
      "                ",
      "                ",
      "                ",
      "                ",
      "                ",
      "&               ",
      "&               ",
      "&               ",
      "                ",
      "  &J JJJJ J     ",
      " JJJrJJJJrJJJ   ",
      "JJJ        JJJJ ",
      "J            JJJ",
      "               J",
      "                "
    ],
    [
      "                ",
      "                ",
      "                ",
      "                ",
      "                ",
      "                ",
      "                ",
      "                ",
      "                ",
      "                ",
      "  &J JJJJ J     ",
      " JJJrJJJJrJJJ   ",
      "JJJ        JJJJ&",
      "J            JJJ",
      "              &J",
      "               &"
    ],
    [
      "                ",
      "  JJJJJJJJJJ    ",
      "JJJJJJJJJJJJJJJ ",
      "JJJ        JJJJJ",
      "               J",
      "                ",
      "                ",
      "                ",
      "                ",
      "                ",
      "  &  JJJ  J     ",
      " JJJ JJJJrJJJ   ",
      "JJJJJJJJJJJJJJJ&",
      "JJJJJJJJJJJJJJJJ",
      "JJJJJJJJJJJJJJJJ",
      "JJJJJJJJJJJJJJJJ"
    ],
    [
      "                ",
      "  JJJJJJJJJJ    ",
      "JJJJJJJJJJJJJJJ ",
      "JJJ        JJJJJ",
      "               J",
      "                ",
      "                ",
      "                ",
      "                ",
      "                ",
      "          J     ",
      " J&   JJ  JJJ   ",
      "JJJ        JJJJ&",
      "J            JJJ",
      "               J",
      "                "
    ],
    [
      "                ",
      "                ",
      "                ",
      "                ",
      "                ",
      "                ",
      "                ",
      "                ",
      "                ",
      "                ",
      "                ",
      " J     r  r   & ",
      "Jrr        rr&&&",
      "r            rr&",
      "              &r",
      "                "
    ],
    [
      "                ",
      "                ",
      "                ",
      "                ",
      "                ",
      "                ",
      "                ",
      "                ",
      "                ",
      "                ",
      "          J     ",
      " JJJ JJJ  JJJ & ",
      "JJJ        JJJJ&",
      "J            JJJ",
      "               J",
      "                "
    ]
  ]
}