{
  "xsize": 16,
  "zsize": 16,
  "refpalette": "lostcities:factory",
  "slices": [
    [
      "VJ          J!i ",
      "VJ          J!i ",
      "VJ          J!i ",
      "VJ          J!i ",
      "VJJJJJJJJJJJJ!i ",
      "VVVVVVVVVVVVV!i ",
      "VVVVVVVVVVVVV!!!",
      "mmmmmmmmmmmmm!!!",
      "      &       ! ",
      "              ! ",
      "jjjjjjjjjjjjj!!!",
      "VVVVVVVVVVVVV!!!",
      "VVVVVVVVVVVVV!i ",
      "V             i ",
      "V             i ",
      "V             i "
    ],
    [
      " J          J i ",
      " J          J i ",
      " J          J i ",
      " J    &     J i ",
      " JJJJJJJJJJJJ i ",
      "/    &&&     !i ",
      "n     &      !!!",
      "m,,,,,,,,,,,,!!!",
      "      &       ! ",
      "              ! ",
      "j,,,,,,,,,,,,!!!",
      "o            !!!",
      "3            !i ",
      "              i ",
      "              i ",
      "              i "
    ],
    [
      " J          J i ",
      " J          J i ",
      " J          J i ",
      " J    &     J i ",
      " JJJJJJJJJJJJ i ",
      "/     &      !i ",
      "3            !!!",
      "      &      !!!",
      "              ! ",
      "              ! ",
      "             !!!",
      "/            !!!",
      "3            !i ",
      "              i ",
      "              i ",
      "              i "
    ],
    [
      " J          J i ",
      " J          J i ",
      " J          J i ",
      " J    &     J i ",
      " JJJJJJJJJJJJ i ",
      "/     &      !i ",
      "3            !!!",
      "             !!!",
      "              ! ",
      "              ! ",
      "             !!!",
      "/            !!!",
      "3            !i ",
      "              i ",
      "              i ",
      "              i "
    ],
    [
      " JJJJJJJJJJJJ i ",
      " JJJJJJJJJJJJ i ",
      " JJJJJJJJJJJJ i ",
      " JJJJJJJJJJJJ i ",
      " JJJJJJJJJJJJ i ",
      "/     &      !i ",
      "3            !!!",
      "             !!!",
      "              ! ",
      "              ! ",
      "             !!!",
      "/            !!!",
      "3            !i ",
      "              i ",
      "              i ",
      "              i "
    ],
    [
      "  5       5   i ",
      "   5     5    i ",
      "    55555     i ",
      "      &       i ",
      "      &       i ",
      "/            !i ",
      "3            !!!",
      "             !!!",
      "              ! ",
      "              ! ",
      "             !!!",
      "/            !!!",
      "3            !i ",
      "              i ",
      "              i ",
      "              i "
    ]
  ]
}