{
  "xsize": 16,
  "zsize": 16,
  "refpalette": "lostcities:factory",
  "slices": [
    [
      " !           !  ",
      "!!!  & !  & !!! ",
      "!!!!JJJJJJJ!!!!!",
      "!!!  &    & !!! ",
      " !           !  ",
      "             J  ",
      "             J  ",
      "   !  !      J  ",
      "    rr       J! ",
      "    rr       J  ",
      "   !  !      J  ",
      "             J  ",
      "             !  ",
      "            !!! ",
      "           !!!!!",
      "!           !!! "
    ],
    [
      " !           !  ",
      "!!!  & !  & !!! ",
      "!!!!!!!!!!!!!!!!",
      "!!!  &    & !!! ",
      " !           !  ",
      "             !  ",
      "             !  ",
      "   !  !      !  ",
      "    rr       !! ",
      "    rr       !  ",
      "   !  !      !  ",
      "             !  ",
      "             !  ",
      "            !!! ",
      "           !!!!!",
      "!           !!! "
    ],
    [
      " !           !  ",
      "!!!  & ! && !!! ",
      "!!!!JJJJJJJ!!!!!",
      "!!!  &   && !!! ",
      " !           !  ",
      "             J  ",
      "             J  ",
      "   !  !      J  ",
      "    rr       J! ",
      "    rr       J  ",
      "   !  !      J  ",
      "             J  ",
      "             !  ",
      "            !!! ",
      "           !!!!!",
      "!           !!! "
    ],
    [
      " !           !  ",
      "!!!  & ! &  !!! ",
      "!!!!JJJJJJJ!!!!!",
      "!!!  &   &  !!! ",
      " !           !  ",
      "             J  ",
      "             J  ",
      "   !  !      J  ",
      "    rr       J! ",
      "    rr       J  ",
      "   !  !      J  ",
      "             J  ",
      "             !  ",
      "            !!! ",
      "           !!!!!",
      "!           !!! "
    ],
    [
      "!!!         !!! ",
      "!!!! & ! & !!!!!",
      "!!!!!!!!!!!!!!!!",
      "!!!! &   & !!!!!",
      "!!!         !!! ",
      "             !  ",
      "             !  ",
      "   !  !      !  ",
      "    rr       !! ",
      "    rr       !  ",
      "   !  !      !  ",
      "             !  ",
      "            !!! ",
      "           !!!!!",
      "           !!!!!",
      "!          !!!!!"
    ],
    [
      " !           !  ",
      "!!! && ! &  !!! ",
      "!!!!JJJJJJJ!!!!!",
      "!!! &&   &  !!! ",
      " !           !  ",
      "             J  ",
      "             J  ",
      "   !JJ!      J  ",
      "   JrrJ      J! ",
      "   JrrJ      J  ",
      "   !JJ!      J  ",
      "             J  ",
      "             !  ",
      "            !!! ",
      "           !!!!!",
      "!           !!! "
    ]
  ]
}