{
  "xsize": 16,
  "zsize": 16,
  "refpalette": "lostcities:factory",
  "slices": [
    [
      "!!!             ",
      "!!!             ",
      "!!!             ",
      "!!!            +",
      "!!!            2",
      "!!!             ",
      " !!             ",
      " !!             ",
      "!!!             ",
      "!!!            +",
      "!!!            2",
      "!!!             ",
      " !!             ",
      "                ",
      "                ",
      "                "
    ],
    [
      "!!!             ",
      "!!!             ",
      "!!!             ",
      "!!!            +",
      "!!!            2",
      "!!!             ",
      " !!             ",
      " !!             ",
      "!!!             ",
      "!!!            +",
      "!!!            2",
      "!!!             ",
      " !!             ",
      " !!             ",
      "                ",
      "                "
    ],
    [
      " ]              ",
      " ]              ",
      " ]!             ",
      "!!!            +",
      "!!!            2",
      "!!!             ",
      " !              ",
      " !              ",
      "!!!             ",
      "!!!            +",
      "!!!            2",
      " ]!             ",
      " ]              ",
      " ]              ",
      " ]              ",
      "                "
    ],
    [
      "                ",
      "                ",
      "  !             ",
      "!!!            V",
      "!!!            V",
      "!!!             ",
      "                ",
      "                ",
      "!!!             ",
      "!!!            V",
      "!!!            V",
      "  !             ",
      "                ",
      "                ",
      "  !             ",
      "                "
    ],
    [
      "  V            V",
      "  V            V",
      "  !           VV",
      "!!VVVVVVVVVVVVVn",
      "!!!VVVVVVVVVVVVn",
      "!!!           VV",
      "  V             ",
      "  V             ",
      "!!!           VV",
      "!!!VVVVVVVVVVVVn",
      "!!VVVVVVVVVVVVVn",
      "  !           VV",
      "  V            V",
      "  V            V",
      "  !            V",
      "  V            V"
    ],
    [
      "   !rrrrrrrrrr!!",
      "    rrrrrrrrrr!!",
      "    !!!!!!!!!!!!",
      "    !!!!!!!!!!!!",
      "    !!!!!!!!!!!!",
      "!    !!!!!!!!!!!",
      "!   rrrrrrrrrrrr",
      "!!rrrrrrrrrrrrrr",
      "!!!!!!!!!!!!!!!!",
      "!!!!!!!!!!!!!!!!",
      "!!!!!!!!!!!!!!!!",
      "!!!!!!!!!!!!!!!!",
      "!!!!!!!!!!!!!!!!",
      "!!!!!!!!!!!!!!!!",
      "!!!!!!!!!!!!!!!!",
      "!!!!!!!!!!!!!!!!"
    ]
  ]
}