{
  "xsize": 16,
  "zsize": 16,
  "refpalette": "lostcities:factory",
  "slices": [
    [
      "&V&      &V&    ",
      " V        V     ",
      " V        V     ",
      " V        V     ",
      " O       &O&    ",
      " V       &V&    ",
      "          V     ",
      "          V     ",
      "          V     ",
      " && &&&   V     ",
      "    &&&&  V     ",
      "     &&   V     ",
      "          V     ",
      "          V     ",
      "   VVVVVVVO     ",
      "                "
    ],
    [
      "&V&   &&&&V&    ",
      " V    &&  V     ",
      " V     &  V     ",
      " V    &&&&V     ",
      " O    &  &O&    ",
      "      &   V     ",
      "     &&   V     ",
      "    &&    V     ",
      "    &&    V     ",
      "   &&&&   V     ",
      "    &&&   V     ",
      "     &    V     ",
      "          V     ",
      "          V     ",
      "    VVVVVVO     ",
      "                "
    ],
    [
      " OVVVVVVVVO&    ",
      " OVVVVVVVVO     ",
      " OVVVVVVVVO     ",
      " OVVVVVVVVO&    ",
      " OOOOOOOOOO&    ",
      "   VVVVVVVO     ",
      "    VVVVVVO     ",
      "   &VVVVVVO     ",
      "   &VVVVVVO     ",
      "   &VVVVVVO     ",
      "    VVVVVVO     ",
      "    VVVVVVO     ",
      "    VVVVVVO     ",
      "    VVVVVVO     ",
      "    OOOOOOO     ",
      "                "
    ],
    [
      "     &&&&&&     ",
      "      &&        ",
      "       &        ",
      "      &&&&&     ",
      "      &   &     ",
      "      &         ",
      "     &&         ",
      "    &&          ",
      "    &           ",
      "    &           ",
      "                ",
      "                ",
      "                ",
      "                ",
      "                ",
      "                "
    ],
    [
      "      &         ",
      "                ",
      "                ",
      "                ",
      "                ",
      "                ",
      "                ",
      "                ",
      "                ",
      "                ",
      "                ",
      "                ",
      "                ",
      "                ",
      "                ",
      "                "
    ],
    [
      "                ",
      "                ",
      "                ",
      "                ",
      "                ",
      "                ",
      "                ",
      "                ",
      "                ",
      "                ",
      "                ",
      "                ",
      "                ",
      "                ",
      "                ",
      "                "
    ]
  ]
}