{
  "xsize": 16,
  "zsize": 16,
  "refpalette": "lostcities:factory",
  "slices": [
    [
      "                ",
      "                ",
      "                ",
      "   OOOOO  OOOOO ",
      "  &OOOOO  OOOOO ",
      "   OOOOO  OOOOO ",
      "   OOOOO  OOOOO&",
      "   OOOOO &OOOOO ",
      "        &&&     ",
      "        &&      ",
      "   OOOOO  OOOOO ",
      "   OOOOO  OOOOO&",
      "   OOOOO  OOOOO ",
      "   OOOOO  OOOOO ",
      "  &OOOOO  OOOOO ",
      "   &            "
    ],
    [
      "                ",
      "                ",
      "                ",
      "   $   $  $   $ ",
      "  &&&           ",
      "  &&&         & ",
      "   &&&    &  &&&",
      "   $   $ &$&  $ ",
      "        &&&     ",
      "       &&&&     ",
      "   $   $&&$   $ ",
      "             &&&",
      "             &&&",
      "   &          & ",
      "  &$&  $  $   $ ",
      "   &            "
    ],
    [
      "                ",
      "                ",
      "                ",
      "   OOOOO  OOOOO ",
      "   OOOOO  OOOOO ",
      "  &OOOOO  OOOOO ",
      "   OOOOO  OOOOO&",
      "   OOOOO &OOOOO&",
      "        &&&   & ",
      "       &&&      ",
      "   OOOOO& OOOOO ",
      "   OOOOO  OOOOO ",
      "   OOOOO  OOOOO&",
      "   OOOOO  OOOOO ",
      "  &OOOOO  OOOOO ",
      "   &            "
    ],
    [
      "                ",
      "                ",
      "                ",
      "    VVVO  OVVVO ",
      "       V  V   V ",
      "   &&&&V  V   V ",
      "    &&<V  V <<V ",
      "     &&O &OVVVO&",
      "        & &   & ",
      "       &&&      ",
      "   OVVVO& OVVVO ",
      "   V   V  V   V ",
      "   V <<V  V <<V&",
      "   VV<<V  VV<<V ",
      "  &OVVVO  OVVVO ",
      "   &            "
    ],
    [
      "                ",
      "                ",
      "                ",
      "    VVVO  OVVVO ",
      "       V  V   V ",
      "      &V  V   V ",
      "     &&V  V   V ",
      "      &O &OVVVO&",
      "        & &   & ",
      "       &&&      ",
      "      VO&&OVVVO ",
      "   V   V& V   V ",
      "   V   V  V  &V&",
      "  &VVVVV  VVVVV ",
      "  &OVVVO  OVVVO ",
      "   &            "
    ],
    [
      "                ",
      "                ",
      "                ",
      "    VVVO  OVV O ",
      "      OV  VOOOV ",
      "      OV  VOOOV ",
      "     &OV  VOOOV ",
      "      &O &OVVVO&",
      "          &   & ",
      "       &&       ",
      "      VO& OVVVO ",
      "    OOOV  VOOOV ",
      "   &OOOV  VOOOV&",
      "  &&OOOV  VOOOV ",
      "   &&VVO  OVVVO ",
      "                "
    ]
  ]
}