{
  "xsize": 16,
  "zsize": 16,
  "refpalette": "lostcities:factory",
  "slices": [
    [
      "              ! ",
      "   +jjjjjjjjj!!!",
      "   kVVVVVVVVV!!!",
      "   kVVVVVVVVV!i ",
      "   kVV        i ",
      "&  kVV        i ",
      "&& kVV        i ",
      "&  kVV        i ",
      "   kVV        i ",
      "mmmnVV        i ",
      "VVVVVV        i ",
      "VVVVVV        i ",
      "VVVVVV        i ",
      "V             i ",
      "V             i ",
      "V             i "
    ],
    [
      "              ! ",
      "   +jj,,,,,,,!!!",
      "   kno       !!!",
      "!  km3       !i ",
      "!  0          i ",
      "!& 0          i ",
      "!& 0          i ",
      "&  0          i ",
      "   0          i ",
      ",,,3          i ",
      "              i ",
      "              i ",
      "              i ",
      "              i ",
      "              i ",
      "              i "
    ],
    [
      "              ! ",
      "             !!!",
      "    +/       !!!",
      "    23       !i ",
      "&             i ",
      "&             i ",
      "&             i ",
      "              i ",
      "              i ",
      "              i ",
      "              i ",
      "              i ",
      "              i ",
      "              i ",
      "              i ",
      "              i "
    ],
    [
      "              ! ",
      "             !!!",
      "    +/       !!!",
      "    23       !i ",
      "&             i ",
      "              i ",
      "              i ",
      "              i ",
      "              i ",
      "              i ",
      "              i ",
      "              i ",
      "              i ",
      "              i ",
      "              i ",
      "              i "
    ],
    [
      "              ! ",
      "             !!!",
      "    +/       !!!",
      "&   23       !i ",
      "&&            i ",
      "&             i ",
      "              i ",
      "              i ",
      "              i ",
      "              i ",
      "              i ",
      "              i ",
      "              i ",
      "              i ",
      "              i ",
      "              i "
    ],
    [
      "              ! ",
      "             !!!",
      "    +/       !!!",
      "&   23       !i ",
      "&&            i ",
      "&             i ",
      "              i ",
      "              i ",
      "              i ",
      "              i ",
      "              i ",
      "              i ",
      "              i ",
      "              i ",
      "              i ",
      "              i "
    ]
  ]
}