{
  "xsize": 16,
  "zsize": 16,
  "refpalette": "lostcities:factory",
  "slices": [
    [
      "vvvvvvvvvvvvvvvv",
      "vvvvvvvvvvvvvvvv",
      "vvvvvvvvvvvvvvvv",
      "vvvvvvvvvvvvvvvv",
      "vvvvvvvvvvvvvvvv",
      "vvvvvvvvvvvvvvvv",
      "vvvvvvvvvvvvvvvv",
      "vvvvvvvvvvvvvvvv",
      "vvvvvvvvvvvvvvvv",
      "vvvvvvvvvvvvvvvv",
      "vvvvvvvvvvvvvvvv",
      "vvvvvvvvvvvvvvvv",
      "vvvvvvvvvvvvvvvv",
      "vvvvvvvvvvvvvvvv",
      "vvvvvvvvvvvvvvvv",
      "vvvvvvvvvvvvvvvv"
    ],
    [
      "        5       ",
      "       5        ",
      "       5        ",
      "       5        ",
      "      5         ",
      "      5         ",
      "      5         ",
      "                ",
      "                ",
      "      5         ",
      "      5         ",
      "      5         ",
      "       5      & ",
      "       5     &&&",
      "       5     &&&",
      "        5    &&&"
    ],
    [
      "        5       ",
      "       5        ",
      "       5        ",
      "       5        ",
      "      5         ",
      "      5         ",
      "      5         ",
      "                ",
      "                ",
      "      5         ",
      "      5         ",
      "      5         ",
      "       5      & ",
      "       5     &&&",
      "       5    &&&&",
      "        5   &&&&"
    ],
    [
      "        5       ",
      "       5        ",
      "       5        ",
      "       5        ",
      "      5         ",
      "     &5&        ",
      "      5         ",
      "                ",
      "                ",
      "      5         ",
      "      5         ",
      "      5         ",
      "       5        ",
      "       5      & ",
      "       5     &&&",
      "        5   &&& "
    ],
    [
      "        5      &",
      "       5        ",
      "       5        ",
      "       5        ",
      "      5         ",
      "     &5&        ",
      "      5         ",
      "      5         ",
      "      5         ",
      "      5         ",
      "      5         ",
      "      5         ",
      "       5        ",
      "       5     && ",
      "       5    &&&&",
      "        5   &&& "
    ],
    [
      "        5      &",
      "       5        ",
      "       5        ",
      "       5        ",
      "      5         ",
      "     &5&        ",
      "      5         ",
      "      5         ",
      "      5         ",
      "      5         ",
      "      5         ",
      "      5         ",
      "       5        ",
      "       5     &  ",
      "       5    &&& ",
      "        5   &&& "
    ]
  ]
}