{
  "xsize": 16,
  "zsize": 16,
  "refpalette": "lostcities:factory",
  "slices": [
    [
      " V        V     ",
      " V        V     ",
      " V        V     ",
      " V        V     ",
      " V &      V     ",
      " OVVVVVVVVO     ",
      "   &            ",
      "                ",
      "                ",
      "       &        ",
      " OVVVVVVVVO     ",
      " V     &  V     ",
      " V        V     ",
      " V        V     ",
      " V        V     ",
      " V       &V&    "
    ],
    [
      " V        V     ",
      " V        V     ",
      " V        V     ",
      " V        V     ",
      " V &&     V     ",
      " OVVVVVVVVO     ",
      "   &&           ",
      "                ",
      "                ",
      "       &        ",
      " OVVVVVVVVO     ",
      " V     &  V     ",
      " V        V     ",
      " V        V     ",
      " V        V     ",
      " V       &V&    "
    ],
    [
      " V        V     ",
      " V        V     ",
      " V        V     ",
      " V        V     ",
      " V  &     V     ",
      " OVVVVVVVVO     ",
      "    &           ",
      "                ",
      "                ",
      "       &&       ",
      " OVVVVVVVVO     ",
      " V     && V     ",
      " V        V     ",
      " V        V     ",
      " V        V     ",
      " V       &V&    "
    ],
    [
      " V        V     ",
      " V        V     ",
      " V        V     ",
      " V        V     ",
      " V  &     V     ",
      " OVVVVVVVVO     ",
      "    &           ",
      "                ",
      "                ",
      "        &       ",
      " OVVVVVVVVO     ",
      " V      & V     ",
      " V        V     ",
      " V        V     ",
      " V        V     ",
      " V       &V&    "
    ],
    [
      " OVVVVVVVVO     ",
      " OVVVVVVVVO     ",
      " OVVVVVVVVO     ",
      " OVVVVVVVVO     ",
      " OVVVVVVVVO     ",
      " OOOOOOOOOO     ",
      "    &           ",
      "                ",
      "                ",
      "        &       ",
      " OOOOOOOOOO     ",
      " OVVVVVVVVO     ",
      " OVVVVVVVVO     ",
      " OVVVVVVVVO     ",
      " OVVVVVVVVO     ",
      " OVVVVVVVVO&    "
    ],
    [
      "                ",
      " !        !     ",
      "                ",
      "                ",
      "    &&          ",
      " ! &&&&   !     ",
      "    &&          ",
      "                ",
      "                ",
      "        &&      ",
      " !     &&&!     ",
      "        &&      ",
      "                ",
      "                ",
      " !        !     ",
      "          &     "
    ]
  ]
}