{
  "xsize": 16,
  "zsize": 16,
  "refpalette": "lostcities:factory",
  "slices": [
    [
      "VVVVVVVVVVVVVVVV",
      "VVVVVVVVVVVVVVVV",
      "VVVVVVVVVVVVVVVV",
      "VVVVVVVVVVVVVVVV",
      "VVVVVVVVVVVVVVVV",
      "VVVVVVVVVVVVVVVV",
      "VVVVVVVVVVVVVVVV",
      "VVVVVVVVVVVVVVVV",
      "VVVVVVVVVVVVVVVV",
      "VVVVVVVVVVVVVVVV",
      "VVVVVVVVVVVVVVVV",
      "VVVVVVVVVVVVVVVV",
      "VVVVVVVVVVVVVVVV",
      "VVVVVVVVVVVVVVVV",
      "VVVVVVVVVVVVVVVV",
      "VVVVVVVVVVVVVVVV"
    ],
    [
      " !  55V5555555  ",
      "!!! 55V5555555  ",
      "!!! 55V5555555  ",
      " !! 55V5555555  ",
      " !  55V5555555  ",
      " !  55V5555555  ",
      " !  55V5555555  ",
      " !  55V5555555  ",
      " !  55V5555555  ",
      " !  55V5555555  ",
      " !  55V5555555  ",
      " !  55V5555555  ",
      " !  55V5555555 J",
      " !  55V5555555V ",
      " !  55V5555555 J",
      " !  5555555555  "
    ],
    [
      " !  55  555555  ",
      "!!! 55       5  ",
      "!!! 55       5  ",
      " ]! 55 VVVVVV5  ",
      " ]  55      V5  ",
      "&]& 55      V5  ",
      " ]  55      V5  ",
      " ]  55 VVVVVV5  ",
      " ]  55      V5  ",
      " ]  55      V5  ",
      " ]  55      V5  ",
      " ]  55 VVVVVV5  ",
      " ]  55      V5 J",
      " ]  55      VVVV",
      " ]  55       5 J",
      " ]  5555555555  "
    ],
    [
      " !  55  555555  ",
      "!!! 55       5  ",
      "!!! 55       5  ",
      " ]! 55       5  ",
      " ]  55       5  ",
      "&]& 55       5  ",
      " ]  55       5  ",
      " ]  55       5  ",
      " ]  55       5  ",
      " ]  55       5  ",
      " ]  55       5  ",
      " ]  55       5  ",
      " ]  55       5 J",
      " ]  55          ",
      " ]  55       5 J",
      " ]  5555555555  "
    ],
    [
      " !  5555555555  ",
      "!!! 55       5  ",
      "!!! 55       5  ",
      " ]! 55       5  ",
      " ]  55       5  ",
      "&]& 55       5  ",
      " ]  55       5  ",
      " ]  55       5  ",
      " ]  55       5  ",
      " ]  55       5  ",
      " ]  55       5  ",
      " ]  55       5  ",
      " ]  55       5 J",
      " ]  55       5  ",
      " ]  55       5 J",
      " ]  5555555555  "
    ],
    [
      " !  55  55  55  ",
      "!!! 55       5  ",
      "!!! 55          ",
      " ]! 55          ",
      " ]  55       5  ",
      "&]& 55       5  ",
      " ]  55          ",
      " ]  55          ",
      " ]  55          ",
      " ]  55          ",
      " ]  55       5  ",
      " ]  55       5  ",
      " ]  55         J",
      " ]  55         J",
      " ]  55       5 J",
      " ]  5555   555  "
    ]
  ]
}