{
  "xsize": 16,
  "zsize": 16,
  "refpalette": "lostcities:factory",
  "slices": [
    [
      "             5  ",
      "      5   & 5   ",
      "       55555    ",
      " 0        &     ",
      " 0            & ",
      " 0           &&&",
      " 0           &&&",
      " 0            & ",
      " 0              ",
      " 0              ",
      " 0              ",
      " 0              ",
      " 0& &           ",
      "&0&&&&          ",
      "&0&&OOOOO       ",
      " 0& OOOOO       "
    ],
    [
      "     5       5  ",
      "      5   &&5   ",
      "       55555&   ",
      "          &&    ",
      " 0           && ",
      " 0          &&&&",
      " 0           && ",
      " 0              ",
      " 0              ",
      " 0              ",
      " 0              ",
      " 0              ",
      " 0              ",
      " 0& &           ",
      "&0&&$&  $       ",
      " 0  &           "
    ],
    [
      "     5       5  ",
      "      5    &5   ",
      "       55555&   ",
      "           & &  ",
      "            &&& ",
      "            &&& ",
      "             &  ",
      "                ",
      "                ",
      "                ",
      "                ",
      "                ",
      "                ",
      "    &           ",
      " & &OOOOO       ",
      "    OOOOO       "
    ],
    [
      "     5       5  ",
      "      5    &5   ",
      "       55555&&  ",
      "           &&&& ",
      "            &&& ",
      "             &  ",
      "                ",
      "                ",
      "                ",
      "                ",
      "                ",
      "                ",
      "                ",
      "    &           ",
      "   &OVVVO       ",
      "    V   V       "
    ],
    [
      "     5     &&5  ",
      "      5   &&5&  ",
      "       55555&&  ",
      "           &&&& ",
      "             &  ",
      "                ",
      "                ",
      "                ",
      "                ",
      "                ",
      "                ",
      "                ",
      "                ",
      "    &           ",
      "   &OVVVO       ",
      "   &V&  V       "
    ],
    [
      "     5      &5  ",
      "      5    &5&  ",
      "       55555&&& ",
      "            &&& ",
      "             &  ",
      "                ",
      "                ",
      "                ",
      "                ",
      "                ",
      "                ",
      "                ",
      "                ",
      "                ",
      "    OVVVO       ",
      "   &VOOOV       "
    ]
  ]
}