{
  "xsize": 16,
  "zsize": 16,
  "refpalette": "lostcities:factory",
  "slices": [
    [
      "t              t",
      "     && 5       ",
      "    &&VVVV      ",
      "    VV&   V     ",
      "   V        &   ",
      "   V       &V&  ",
      "  V        &&V& ",
      " 5V         &V  ",
      "  V          V5 ",
      "  V          V  ",
      "   V        V   ",
      "   V        V   ",
      "   &VV    VV    ",
      "     &VVVV      ",
      "       5        ",
      "t              t"
    ],
    [
      "t              t",
      "      & 5       ",
      "     &VVVV      ",
      "    VV&   VV    ",
      "   V        V   ",
      "   V        V&  ",
      "  V         &V& ",
      " 5V          V  ",
      "  V          V5 ",
      "  V&         V  ",
      "  &V&       V   ",
      "  &V&&     &V&  ",
      "  &&VV&   VV&   ",
      "   &&&VVVV      ",
      "     &&5        ",
      "t              t"
    ],
    [
      "t              t",
      "      &&5       ",
      "     &VVVV      ",
      "    VV&&  VV    ",
      "   V        V   ",
      "   V        V&  ",
      "  V         &V& ",
      " 5V          V  ",
      "             V5 ",
      "             V  ",
      "   &        V   ",
      "   &&&     &V&  ",
      "   &VV&   VV&   ",
      "    &&VVVV      ",
      "      &5        ",
      "t              t"
    ],
    [
      "t              t",
      "       &5       ",
      "      VVVV      ",
      "    VV &  VV    ",
      "   V        V   ",
      "   V        V&  ",
      "  V         &V& ",
      " 5V          V  ",
      "             V5 ",
      "             V  ",
      "            V   ",
      "           &V&  ",
      "    VV    VV&   ",
      "      VVVV      ",
      "       5        ",
      "t              t"
    ],
    [
      "t              t",
      "        5       ",
      "      VVVV      ",
      "    VV    VV    ",
      "   V        V   ",
      "   V        V   ",
      "  V          V  ",
      " 5V          V  ",
      "             V5 ",
      "             V  ",
      "            V   ",
      "           &V&  ",
      "    VV    VV&   ",
      "      VVVV      ",
      "       5        ",
      "t              t"
    ],
    [
      "t              t",
      "        5       ",
      "      VVVV      ",
      "    VV    VV    ",
      "   V        V   ",
      "   V        V   ",
      "  V          V  ",
      " 5V          V  ",
      "  V          V5 ",
      "  V          V  ",
      "   V        V   ",
      "   V       &V&  ",
      "    VV    VV&   ",
      "      VVVV      ",
      "       5        ",
      "t              t"
    ]
  ]
}