{
  "xsize": 16,
  "zsize": 16,
  "refpalette": "lostcities:factory",
  "slices": [
    [
      "                ",
      "                ",
      "                ",
      "                ",
      "                ",
      "                ",
      "     &&         ",
      "  &! &!&        ",
      " &&&rr&         ",
      " &&&rr          ",
      "  &!  !         ",
      "  &&     &      ",
      " &&&&   &&&     ",
      "&&&&   &&&&     ",
      "J&&   &&&&      ",
      "rJ&&  &&&       "
    ],
    [
      "                ",
      "                ",
      "                ",
      "                ",
      "                ",
      "     &          ",
      "  & &&&         ",
      " &&!&&!&        ",
      " &&&rr&         ",
      "  &&rr          ",
      "   !  !         ",
      "  &&&    &      ",
      "  &&&   &&&     ",
      "& &&   &&&      ",
      "J&     &&&      ",
      "rJ&    &&       "
    ],
    [
      "                ",
      "                ",
      "                ",
      "J               ",
      "JJJ             ",
      " JJJ &          ",
      " &JJJJ&         ",
      " &&JJJJ         ",
      "  &JJJJJ        ",
      "  &JJJJJ        ",
      "  &!JJJJJ       ",
      "  &&&  JJJ      ",
      "   &    JJ&     ",
      "&      &&JJ     ",
      "J       &JJ     ",
      "rJ        JJ    "
    ],
    [
      "                ",
      "                ",
      "                ",
      "J               ",
      "JJJ             ",
      " JJJ&&          ",
      " &JJJJ&         ",
      "  &!JJJ         ",
      "  &&rJJJ        ",
      "  &&rrJJ        ",
      "   !  !JJ       ",
      "   &   JJJ      ",
      "        JJ&     ",
      "&       &JJ     ",
      "J        JJ     ",
      "rJ        JJ    "
    ],
    [
      "                ",
      "                ",
      "                ",
      "                ",
      "                ",
      "                ",
      "  &&&&          ",
      "  &!&&!         ",
      "  &&rr          ",
      "   &rr          ",
      "   !  !         ",
      "                ",
      "         &      ",
      "&               ",
      "                ",
      "r               "
    ],
    [
      "                ",
      "                ",
      "                ",
      "                ",
      "                ",
      "                ",
      "   &            ",
      "  &!& !         ",
      "   &rr          ",
      "    rr          ",
      "   !  !         ",
      "                ",
      "                ",
      "                ",
      "J               ",
      "rJ              "
    ]
  ]
}