{
  "xsize": 16,
  "zsize": 16,
  "refpalette": "lostcities:factory",
  "slices": [
    [
      "  Q      &      ",
      "   Q    &&&     ",
      "  &Q    &&&     ",
      " &&Q&    &      ",
      "  &Q&           ",
      "   &Q           ",
      "    Q           ",
      "     Q          ",
      "     Q          ",
      "      Q         ",
      "       QQ       ",
      "         QQ&    ",
      "          &QQQQ ",
      "          &&&& Q",
      "           &&   ",
      "                "
    ],
    [
      "  Q      &      ",
      "  Q     &&&     ",
      "  Q      &      ",
      " &Q&            ",
      "  &Q            ",
      "   Q            ",
      "    Q           ",
      "    Q           ",
      "     Q          ",
      "      Q         ",
      "       Q        ",
      "        QQ      ",
      "          QQ&   ",
      "           &QQQQ",
      "            &   ",
      "                "
    ],
    [
      "  Q      &      ",
      "  Q     &&&     ",
      " &Q&     &      ",
      " &Q&            ",
      "  Q             ",
      "   Q            ",
      "   Q            ",
      "    Q           ",
      "    Q           ",
      "     Q          ",
      "      Q         ",
      "       QQ       ",
      "         QQ &   ",
      "           QQQQQ",
      "            &&  ",
      "                "
    ],
    [
      " Q       &      ",
      " Q&     &&&     ",
      "&&Q&     &      ",
      " &Q             ",
      "  Q             ",
      "  Q             ",
      "   Q            ",
      "   Q            ",
      "    Q           ",
      "     Q          ",
      "      Q         ",
      "       Q        ",
      "        QQ  &&  ",
      "          QQQQ& ",
      "            &&QQ",
      "             &  "
    ],
    [
      " Q       &      ",
      "&Q&     &&&     ",
      "&Q&      &      ",
      " &Q             ",
      "  Q             ",
      "  Q             ",
      "   Q            ",
      "   Q            ",
      "    Q           ",
      "     Q          ",
      "      Q         ",
      "       Q        ",
      "        QQ      ",
      "          QQQ&  ",
      "            &QQQ",
      "             &  "
    ],
    [
      " Q       &      ",
      "&Q&     &&&     ",
      " Q       &      ",
      " Q              ",
      "  Q             ",
      "  Q             ",
      "   Q            ",
      "   Q            ",
      "    Q           ",
      "    Q           ",
      "     Q          ",
      "      QQ        ",
      "        QQ      ",
      "          QQ &  ",
      "            QQQQ",
      "             &  "
    ]
  ]
}