{
  "xsize": 16,
  "zsize": 16,
  "refpalette": "lostcities:factory",
  "slices": [
    [
      "!               ",
      "!               ",
      "!!             !",
      "j/            +j",
      "Vo            kV",
      "Vo            kV",
      "Vo            kV",
      "Vo            kV",
      "Vn5           kV",
      "Vo            kV",
      "Vo            kV",
      "Vnjjjj    jjjjnV",
      "VVVVVVVVVVVVVVVV",
      "VVVVVVVVVVVVVVVV",
      "VVVVVVVVVVVVVVVV",
      "VnmmmmVVVVmmmmnV"
    ],
    [
      "!               ",
      "!               ",
      "!!             !",
      "j/            +j",
      "no            kn",
      "mo            km",
      " 0            0 ",
      " 0            0 ",
      " k5           0 ",
      " 0            0 ",
      "&0            0 ",
      "&2,,,q    ,,,,3 ",
      "&&              ",
      "&             &&",
      "             && ",
      " +,,,,/  +,,,,/ "
    ],
    [
      "!               ",
      "!               ",
      "!!             !",
      "                ",
      "/              +",
      "3              2",
      "                ",
      "                ",
      "  5             ",
      "                ",
      "&&              ",
      "&&&             ",
      "&&              ",
      "                ",
      "                ",
      "             &  "
    ],
    [
      "!               ",
      "!               ",
      "!!             !",
      "                ",
      "/              +",
      "3              2",
      "                ",
      "                ",
      "  5             ",
      "                ",
      "                ",
      "&&              ",
      "                ",
      "                ",
      "                ",
      "                "
    ],
    [
      "!               ",
      "!               ",
      "!!             !",
      "                ",
      "/              +",
      "3              2",
      "                ",
      "                ",
      "  5             ",
      "                ",
      "                ",
      "                ",
      "                ",
      "                ",
      "                ",
      "                "
    ],
    [
      "!               ",
      "!               ",
      "!!             !",
      "                ",
      "/              +",
      "3              2",
      "                ",
      "                ",
      "  5             ",
      "                ",
      "                ",
      "                ",
      "                ",
      "                ",
      "                ",
      "                "
    ]
  ]
}