{
  "xsize": 16,
  "zsize": 16,
  "refpalette": "lostcities:factory",
  "slices": [
    [
      " !              ",
      "!!!jjjjjjjjjj/  ",
      "!!!VVVVVVVVVVo  ",
      " ]!VVVVVVVVVVo  ",
      "&]&        VVo  ",
      " ]         VVo  ",
      " ]         VVo  ",
      " ]    VVV  VVo  ",
      " ]   V   V VVo  ",
      " ]  V     VVVnmm",
      " ]        VVVVVV",
      " ]        VVVVVV",
      " ]       V VVVVV",
      " ]      V      V",
      " ]             V",
      " ]             V"
    ],
    [
      " !              ",
      "!!!,,,,,,,,jj/  ",
      "!!!        kno !",
      " ]!        2mo !",
      "&]&          0 !",
      " ]           0 !",
      " ]           0 !",
      " ]    VVV    0  ",
      " ]   V   V   0  ",
      " ]  V     V  2,,",
      " ]        V     ",
      " ]        V     ",
      " ]       V      ",
      " ]      V       ",
      " ]              ",
      " ]              "
    ],
    [
      " !              ",
      "!!!             ",
      "!!!        +/   ",
      " ]!        23   ",
      "&]&             ",
      " ]              ",
      " ]              ",
      " ]    VVV       ",
      " ]   V   V      ",
      " ]  V     V     ",
      " ]  V     V     ",
      " ]        V     ",
      " ]       V      ",
      " ]     VV       ",
      " ]              ",
      " ]              "
    ],
    [
      " !              ",
      "!!!             ",
      "!!!        +/   ",
      " ]!        23   ",
      "&]&             ",
      " ]              ",
      " ]              ",
      " ]    VVV       ",
      " ]   V   V      ",
      " ]  V     V     ",
      " ]  V     V     ",
      " ]  V     V     ",
      " ]       V      ",
      " ]     VV       ",
      " ]              ",
      " ]              "
    ],
    [
      " !              ",
      "!!!             ",
      "!!!        +/   ",
      "&]!        23   ",
      "&]&             ",
      "&]              ",
      " ]              ",
      "      VVV       ",
      "     V   V      ",
      "    V     V     ",
      "    V     V     ",
      " ]  V     V     ",
      " ]   V   V      ",
      " ]    VVV       ",
      " ]              ",
      " ]              "
    ],
    [
      " !              ",
      "!!!             ",
      "!!!        +/   ",
      "&]!        23   ",
      "&]              ",
      "&]              ",
      "                ",
      "      VVV       ",
      "     V   V      ",
      "    V     V     ",
      "    V     V     ",
      "    V     V     ",
      " ]   V   V      ",
      " ]    VVV       ",
      " ]              ",
      " ]              "
    ]
  ]
}