{
  "xsize": 16,
  "zsize": 16,
  "refpalette": "lostcities:factory",
  "slices": [
    [
      "V             i ",
      "V             i ",
      "V             i ",
      "VVVVVVVVVVVVV!i ",
      "VVVVVVVVVVVVV!!!",
      "mmmmmmmmmmmmm!!!",
      "              ! ",
      "              ! ",
      "jjjjjjjjjjjjj!!!",
      "VVVVVVVVVVVVV!!!",
      "VVVVVVVVVVVVV!i ",
      "V             i ",
      "VOVVVO OVVVO  i ",
      "VVOOOV VOOOV  i ",
      "VVOOOV VOOOV  i ",
      "VVOOOV VOOOV  i "
    ],
    [
      "              i ",
      "              i ",
      "              i ",
      "/            !i ",
      "n            !!!",
      "m,,,,,,,,,,,,!!!",
      "              ! ",
      "              ! ",
      "j,,,,,,,,,,,,!!!",
      "o            !!!",
      "3            !i ",
      "              i ",
      " OOOOO OOOOO  i ",
      " OOOOO OOOOO  i ",
      " OOOOO OOOOO  i ",
      " OOOOO OOOOO  i "
    ],
    [
      "              i ",
      "              i ",
      "              i ",
      "/            !i ",
      "3            !!!",
      "             !!!",
      "              ! ",
      "              ! ",
      "             !!!",
      "/            !!!",
      "3            !i ",
      "              i ",
      " $   $ $   $  i ",
      "              i ",
      "              i ",
      " &           &i "
    ],
    [
      "              i ",
      "              i ",
      "              i ",
      "/            !i ",
      "3            !!!",
      "             !!!",
      "              ! ",
      "              ! ",
      "             !!!",
      "/            !!!",
      "3            !i ",
      "              i ",
      " OOOOO OOOOO  i ",
      " OOOOO OOOOO  i ",
      " OOOOO OOOOO  i ",
      "&OOOOO OOOOO &i "
    ],
    [
      "              i ",
      "              i ",
      "              i ",
      "/            !i ",
      "3            !!!",
      "             !!!",
      "              ! ",
      "              ! ",
      "             !!!",
      "/            !!!",
      "3            !i ",
      "              i ",
      " OVVVO OVVVO  i ",
      " V   V V   V  i ",
      "&V&<<V V <<V  i ",
      "&VV<<V VV<<V    "
    ],
    [
      "              i ",
      "              i ",
      "              i ",
      "/            !i ",
      "3            !!!",
      "             !!!",
      "              ! ",
      "              ! ",
      "             !!!",
      "/            !!!",
      "3            !i ",
      "              i ",
      " OVVVO OVVVO  i ",
      " V   V V   V  i ",
      "&V&  V V   V    ",
      " VVVVV VVVVV    "
    ]
  ]
}