{
  "xsize": 16,
  "zsize": 16,
  "refpalette": "lostcities:factory",
  "slices": [
    [
      "vvvJJJJJJJJJJJJJ",
      "vvvJJJJJJJJJJJJJ",
      "vvvJJJJJJJJJJJJJ",
      "vvvJJJJJJJJJJJJJ",
      "vvvJJJJJJJJJJJJJ",
      "vvvJJJJJJJJJJJJJ",
      "vvvJJJJJJJJJJJJJ",
      "vvvJJJJJJJJJJJJJ",
      "vvvJJJJJJJJJJJJJ",
      "vvvJJJJJJJJJJJJJ",
      "vvvJJJJJJJJJJJJJ",
      "vvvJJJJJJJJJJJJJ",
      "vvvvvvvvvvvvvvvv",
      "vvvvvvvvvvvvvvvv",
      "vvvvvvvvvvvvvvvv",
      "vvvvvvvvvvvvvvvv"
    ],
    [
      "!!!!!        !!!",
      "!!!!!           ",
      "!!!!! JJJJJJ    ",
      "!!!!! J!JJ!J    ",
      "  !   JJrrJJ    ",
      "  !   JJrrJJ    ",
      "  !   J!JJ!J    ",
      " !!   JJJJJJ    ",
      "  !             ",
      "  !             ",
      "  !             ",
      "!!!!!       !!!!",
      "!!!!!       !!!!",
      "!!!!!!!!!!!!!!!!",
      "!!!!!   !   !!!!",
      "!!!!!       !!!!"
    ],
    [
      " !!!         !!!",
      "!!!!!           ",
      " !!!            ",
      "  !    !JJ!     ",
      "  J    JrrJ     ",
      "  J    JrrJ     ",
      "  J    !JJ!     ",
      " !J             ",
      "  J             ",
      "  J             ",
      "  J             ",
      "  !           ! ",
      " !!!         !!!",
      "!!!!!JJJJJJJ!!!!",
      " !!!    !    !!!",
      "  !           ! "
    ],
    [
      " !!!         !!!",
      "!!!!!           ",
      " !!!            ",
      "  !    !  !     ",
      "  J     rr      ",
      "  J     rr      ",
      "  J    !  !     ",
      " !J             ",
      "  J             ",
      "  J             ",
      "  J             ",
      "  !           ! ",
      " !!!     &   !!!",
      "!!!!!JJJJJJJ!!!!",
      " !!!    !&   !!!",
      "  !           ! "
    ],
    [
      " !!!         !!!",
      "!!!!!           ",
      " !!!            ",
      "  !    !  !     ",
      "  !     rr      ",
      "  !     rr      ",
      "  !    !  !     ",
      " !!             ",
      "  !             ",
      "  !             ",
      "  !             ",
      "  !           ! ",
      " !!!     &   !!!",
      "!!!!!!!!!!!!!!!!",
      " !!!    !&   !!!",
      "  !           ! "
    ],
    [
      " !!!         !!!",
      "!!!!!           ",
      " !!!            ",
      "  !    !  !     ",
      "  J     rr      ",
      "  J     rr      ",
      " &J    !  !     ",
      "&!J&            ",
      " &J             ",
      "  J             ",
      "  J             ",
      "  !           ! ",
      " !!!     &   !!!",
      "!!!!!JJJJJJJ!!!!",
      " !!!    !&   !!!",
      "  !           ! "
    ]
  ]
}