{
  "xsize": 16,
  "zsize": 16,
  "refpalette": "lostcities:factory",
  "slices": [
    [
      " !         !!  !",
      " ![[[[[[[[[!!!!!",
      " !        !!!  !",
      "!!!jjjjjjjjjjjjj",
      "!!!VVVVVVVVVVVVV",
      " ]!VVVVVVVVVVVVV",
      " ]!JJJJJJJJJJJJV",
      " ]!J!!!!!!!!!!JV",
      " ]!J!!!!!!!!!!JV",
      "&]!J!!!!!!!!!!JV",
      " ]!J!!!!!!!!!!JV",
      " ]!J!!!!!!!!!!JV",
      " ]!J!!!!!!!!!!JV",
      " ]!J!!!!!!!!!!JV",
      " ]!J!!!!!!!!!!JV",
      " ]!J!!!!!!!!!!JV"
    ],
    [
      " !         !!  !",
      " ![[[[[[[[[!!!!!",
      " !        !!!  !",
      "!!!,,,,,,,,,,,,j",
      "!!!            k",
      " ]!            2",
      " ] JJJJJJJJJJJJ ",
      " ] J          J ",
      " ] J   55555  J ",
      "&]&J  5     5 J ",
      " ] J 5       5J ",
      " ] J5         J&",
      " ] J5         J&",
      " ] J5        &J&",
      " ] J5         J&",
      " ] J5         J "
    ],
    [
      " !         !!  !",
      " ![[[[[[[[[!!!!!",
      " !        !!!  !",
      "!!!             ",
      "!!!            +",
      " ]!            2",
      " ] JJJJJJJJJJJJ ",
      " ] J          J ",
      " ] J   55555  J ",
      "&]&J  5  &&&5 J ",
      " ] J 5       5J ",
      " ] J5         J&",
      " ] J5        &J&",
      " ] J5         J&",
      "   J5         J ",
      "    5    &    J "
    ],
    [
      " !         !!  !",
      " ![[[[[[[[[!!!!!",
      " !        !!!  !",
      "!!!             ",
      "!!!            +",
      " ]!            2",
      " ] JJJJJJJJJJJJ ",
      " ] JJJJJJJJJJJJ ",
      "&] JJJJJJJJJJJJ ",
      "&]&JJJJJJJJJJJJ ",
      "&] JJJJJJJJJJJJ ",
      " ] JJJJJJJJJJJJ&",
      " ] JJJJJJJJJJJJ&",
      " ] JJJJJJJJJJJJ ",
      "    JJJJJJJJJJJ ",
      "    JJJJJJJJJJJ "
    ],
    [
      "!!         !!  !",
      " ![[[[[[[[[!!!!!",
      " !        !!!  !",
      "!!!             ",
      "!!!            +",
      " ]!            2",
      " ]              ",
      " ]              ",
      "&]     55555&   ",
      "&]    5 &&&&5&  ",
      "&]   5   & &&5& ",
      " ]  5        &5&",
      " ]  5         5 ",
      " ]  5         5 ",
      "    5         5 ",
      "    5    &    5 "
    ],
    [
      "$!         !!  !",
      " ![[[[[[[[[!!!!!",
      " !        !!!  !",
      "!!!             ",
      "!!!            +",
      " ]!            2",
      " ]              ",
      " ]              ",
      "&]     55555&   ",
      "&]    5 &&&&5&  ",
      "&]   5   &  &5  ",
      " ]  5         5 ",
      " ]  5         5 ",
      " ]  5         5 ",
      "    5         5 ",
      "    5         5 "
    ]
  ]
}