{
  "xsize": 16,
  "zsize": 16,
  "refpalette": "lostcities:factory",
  "slices": [
    [
      "vvvvvvvvvvvvvvvv",
      "vvvvvvvvvvvvvvvv",
      "vvvvvvvvvvvvvvvv",
      "vvvvvvvvvvvvvvvv",
      "vvvvvvvvvvvvvvvv",
      "vvvvvvvvvvvvvvvv",
      "vvvvvvvvvvvvvvvv",
      "vvvvvvvvvvvvvvvv",
      "vvvvvvvvvvvvvvvv",
      "vvvvvvvvvvvvvvvv",
      "vvvvvvvvvvvvvvvv",
      "vvvvvvvvvvvvvvvv",
      "vvvvvvvvvvvvvvvv",
      "vvvvvvvvvvvvvvvv",
      "vvvvvvvvvvvvvvvv",
      "vvvvvvvvvvvvvvvv"
    ],
    [
      "t              t",
      "       P5P      ",
      "  &&  VVVV      ",
      " &&&VVVVVVVV    ",
      "  &VVVVVVVVVV   ",
      "   VVVVVVVVVV   ",
      " PVVVVVVVVVVVV  ",
      " 5VVVVVVVVVVVVP ",
      " PVVVVVVVVVVVV5 ",
      "  VVVVVVVVVVVVP ",
      "   VVVVVVVVVV   ",
      "   VVVVVVVVVV   ",
      "  &&VVVVVVVV    ",
      "   &  VVVV      ",
      "      P5P       ",
      "t              t"
    ],
    [
      "t              t",
      "       P5P      ",
      "   && VVVV      ",
      "  &&VV    VV    ",
      "  &V&       V   ",
      "   V        V   ",
      " PV   &      V  ",
      " 5V  &&&     VP ",
      " PV  &&&     V5 ",
      "  V &&&&     VP ",
      "   V &&     V   ",
      "  &V        V   ",
      "  &&VV    VV    ",
      "   &  VVVV      ",
      "      P5P       ",
      "t              t"
    ],
    [
      "t              t",
      "    && P5P      ",
      "   &&&VVVV &    ",
      "   &VV    VV&   ",
      "   V&      &V   ",
      "   V        V   ",
      " PV  &&      V  ",
      " 5V &&&&     VP ",
      " PV &&&      V5 ",
      "  V &&&      VP ",
      "  &V &      V   ",
      " &&V        V   ",
      " &&&VV    VV    ",
      "  &&  VVVV      ",
      "      P5P       ",
      "t              t"
    ],
    [
      "t    &         t",
      "    &&&P5P &    ",
      "   &&&VVVV&&&   ",
      "    VV    VV&   ",
      "   V       &V   ",
      "   V        V   ",
      " PV   &&     V  ",
      " 5V  &&&&    VP ",
      "  V &&&&     V5 ",
      "    &&&      VP ",
      "  &V&&      V   ",
      " &&V        V   ",
      "  &&VV    VV    ",
      "      VVVV      ",
      "      P5P       ",
      "t              t"
    ],
    [
      "t    &         t",
      "    &!!!!!!&    ",
      "    !!VVVV!!&   ",
      "   !VV    VV!   ",
      "  !V        V!  ",
      " !!V        V!! ",
      " !V   &&&    V! ",
      " !V  &&&&&   V! ",
      "  V &&&&&    V! ",
      "  V &&&      V! ",
      " &!V&&&     V!! ",
      " &!V&&      V!  ",
      "  &!VV    VV!   ",
      "    !!VVVV!!    ",
      "     !!!!!!     ",
      "t              t"
    ]
  ]
}