{
  "xsize": 16,
  "zsize": 16,
  "refpalette": "lostcities:factory",
  "slices": [
    [
      "             &  ",
      "             &  ",
      "                ",
      "                ",
      "                ",
      "                ",
      "      !  !      ",
      "       !!       ",
      "       !!       ",
      "      !  !      ",
      "                ",
      "                ",
      "                ",
      "                ",
      "                ",
      "                "
    ],
    [
      "VVVVVVVVVvvvVvz|",
      "vvvVVVVVVVvVzv||",
      "vvvvVVVVVVVVz|||",
      "vvvvVVVVVvvVz|||",
      "vVVVzzvVvvvvVzz|",
      "Vzz||zvvvvvvvVVz",
      "z|}}||vvvvvvvvVV",
      "||}}|vvvvvvvVVVz",
      "z|||vvvvvvvzzz||",
      "zzvvvvvvvvvvvv}}",
      "                ",
      "                ",
      "                ",
      "                ",
      "                ",
      "                "
    ],
    [
      "            &55 ",
      "             &55",
      "               5",
      "                ",
      "                ",
      "                ",
      "      !!        ",
      "      !!!!      ",
      "       !!!      ",
      "       !!!      ",
      "                ",
      "                ",
      "                ",
      "                ",
      "                ",
      "                "
    ],
    [
      "            &55 ",
      "             &55",
      "               5",
      "                ",
      "                ",
      "                ",
      "                ",
      "                ",
      "        !       ",
      "                ",
      "                ",
      "                ",
      "                ",
      "                ",
      "                ",
      "                "
    ],
    [
      " 55555      &55 ",
      " 55555       &55",
      " 55555         5",
      " 55555          ",
      " 55555          ",
      " 55555          ",
      " 55555          ",
      " 55555          ",
      " 55555  !       ",
      " !!!!!          ",
      " 55555          ",
      " 55555          ",
      "                ",
      "                ",
      "                ",
      "                "
    ],
    [
      "5     55    &55 ",
      "5     55     &55",
      "5     55       5",
      "5     55        ",
      "5     55        ",
      "5     55        ",
      "5     55        ",
      "5     5!        ",
      "5     55!       ",
      "!!!!!!!5        ",
      "5 ͰͰͰ 55        ",
      "5     55        ",
      "                ",
      "                ",
      "                ",
      "                "
    ]
  ]
}