{
  "xsize": 16,
  "zsize": 16,
  "refpalette": "lostcities:factory",
  "slices": [
    [
      "                ",
      "                ",
      "                ",
      "                ",
      "                ",
      "                ",
      "                ",
      "                ",
      "     JJJJ       ",
      "   JJ           ",
      "  J        & J  ",
      " J        &&& J ",
      " J         & &J&",
      "J             &J",
      "J              J",
      "J              J"
    ],
    [
      "                ",
      "                ",
      "                ",
      "                ",
      "                ",
      "                ",
      "                ",
      "                ",
      "     JJJ        ",
      "   JJ      &    ",
      "  J       &&&J  ",
      " J        &&& J ",
      " J         & &J&",
      "J             &J",
      "J              J",
      "J              J"
    ],
    [
      "                ",
      "                ",
      "                ",
      "                ",
      "                ",
      "                ",
      "                ",
      "                ",
      "     JJJ        ",
      "   JJ      &    ",
      "  J       &&&J  ",
      " J         &  J ",
      " J           &J&",
      "J             &J",
      "J              J",
      "J              J"
    ],
    [
      "                ",
      "                ",
      "                ",
      "                ",
      "                ",
      "                ",
      "                ",
      "                ",
      "     JJJJ       ",
      "   JJ     &JJ   ",
      "  J      &&&&J  ",
      " J        &&  J ",
      " J           &J&",
      "J             &J",
      "J              J",
      "J              J"
    ],
    [
      "V              V",
      "V              V",
      "V              V",
      "V              V",
      "V          &&  V",
      "V              V",
      "                ",
      "                ",
      "     JJJJJJ     ",
      "   JJ     &JJ   ",
      "  J      &&& J  ",
      " J        &   J ",
      " J           &J&",
      "J             &J",
      "J              J",
      "J              J"
    ],
    [
      "rrrrrrrrrrrrrrrr",
      "rrrrrrrrrrrrrrrr",
      "rrrrrrrrrrrrrrrr",
      "rrrrrrrrrrrrrrrr",
      "rrrrrrrrrrrrrrrr",
      "rrrrrrrrrrrrrrrr",
      "rrrrrrrrrrrrrrrr",
      "rrrrrrrrrrrrrrrr",
      "rrrrrJJJJJJrrrrr",
      "rrrJJ     &JJrrr",
      "rrJ      &&& Jrr",
      "rJ        &   Jr",
      "rJ           &Jr",
      "J!            !J",
      "J!            !J",
      "Jr            rJ"
    ]
  ]
}