{
  "xsize": 16,
  "zsize": 16,
  "refpalette": "lostcities:factory",
  "slices": [
    [
      " !!             ",
      "!!!             ",
      "!!!        +/   ",
      "!!!        23   ",
      "!!!             ",
      "!!!             ",
      " !!             ",
      "      VVV       ",
      "     V   V      ",
      "    V     V     ",
      " !  V     V     ",
      " !  V     V     ",
      " !   V   V      ",
      "!!!   VVV       ",
      "!!!             ",
      "!!!             "
    ],
    [
      " !!             ",
      "!!!             ",
      "!!!        +/   ",
      "&!!        23   ",
      "&!!             ",
      "&&              ",
      "                ",
      "  !   VVV       ",
      " !!  V   V      ",
      " !! V     V     ",
      "!!! V     V     ",
      "!!! V     V     ",
      "!!!  V   V      ",
      "!!!   VVV       ",
      "!!!             ",
      "!!!             "
    ],
    [
      " !              ",
      "!!!             ",
      " !!        +/   ",
      " &!        23   ",
      "&&&             ",
      " &              ",
      "                ",
      "  !   VVV       ",
      "     V   V      ",
      " ]  V     V     ",
      " ]  V     V     ",
      " ]! V     V     ",
      " ]   V   V      ",
      " ]    VVV       ",
      " ]              ",
      " ]!             "
    ],
    [
      "                ",
      " !!             ",
      " !!        VV   ",
      "&&!        VV   ",
      "&&&             ",
      "&&              ",
      "                ",
      "  !   VVV       ",
      "     V   V      ",
      "    V     V     ",
      "    V     V     ",
      "  ! V     V     ",
      "     V   V      ",
      "      VVV       ",
      "                ",
      "  !             "
    ],
    [
      "  V             ",
      " !!       VVVV  ",
      " !!VVVVVVVVnnV  ",
      "& VVVVVVVVVnnV  ",
      "&&!       VVVV  ",
      "& V        VV   ",
      "  V        VV   ",
      "  !   VVV  VV   ",
      "  V  V   V VV   ",
      "  V V     VVV   ",
      "  V V     V    V",
      "  ! V     V    V",
      "  V  V   V     V",
      "  V   VVV      V",
      "  V            V",
      "  !            V"
    ],
    [
      "!!!rrrrrrrrrrrrr",
      " !!!!!!!!!!!!!!!",
      " !!!!!!!!!!!!!!!",
      "&!!!!!!!!!!!!!!!",
      "!!!!!!!!!!!!!!!!",
      "!!!!rrrrrrrrrr!!",
      "!!!!rrrrrrrrrr!!",
      "!!!!rrVVVrrrrr!!",
      "!!!!rV   Vrrrr!!",
      "!!!!V     Vrrr!!",
      "!!!!V     Vrrr!!",
      "!!!!V     Vrrr!!",
      "!!!!rV   Vrrrr!!",
      "!!!!rrVVVrrrrr!!",
      "!!!!rrrrrrrrrr!!",
      "!!!!rrrrrrrrrr!!"
    ]
  ]
}