{
  "meta": [
    {
      "key": "dontconnect",
      "boolean": true
    }
  ],
  "xsize": 16,
  "zsize": 16,
  "refpalette": "lostcities:factory_common",
  "slices": [
    [
      "             ff#",
      "             ff#",
      "             ff#",
      "             ff#",
      "             ff#",
      "             ff#",
      "             ff#",
      "             ff#",
      "             ff#",
      "             ff#",
      "             ff#",
      "             ff#",
      "             ff#",
      "             ff#",
      "####a#    #a#fl#",
      " $ $ $aaaa$ $##$"
    ],
    [
      "             : #",
      "             : #",
      "             : #",
      "             : #",
      "             : #",
      "             : #",
      "             : #",
      "             : #",
      "             : #",
      "             : #",
      "             : #",
      "             : #",
      "             : #",
      "             : #",
      "####a#    #a#:l#",
      " $ $ $aaaa$ $##$"
    ],
    [
      "               #",
      "               #",
      "               #",
      "               #",
      "               #",
      "               #",
      "               #",
      "               #",
      "               #",
      "               #",
      "               #",
      "               #",
      "               #",
      "               #",
      "####a#    #a# l#",
      " $ $ $aaaa$ $##$"
    ],
    [
      "               #",
      "               a",
      "               a",
      "               #",
      "               #",
      "               a",
      "               a",
      "               #",
      "               #",
      "               a",
      "               a",
      "               #",
      "               #",
      "               #",
      "####a#    #a# l#",
      " $ $ $aaaa$ $##$"
    ],
    [
      "               #",
      "               #",
      "               #",
      "               #",
      "               #",
      "               #",
      "               #",
      "               #",
      "               #",
      "               #",
      "               #",
      "               #",
      "               #",
      "               #",
      "####a#    #a# l#",
      " $ $ $aaaa$ $##$"
    ],
    [
      "               #",
      "               #",
      "               #",
      "               #",
      "               #",
      "               #",
      "               #",
      "               #",
      "               #",
      "               #",
      "               #",
      "               #",
      "               #",
      "               #",
      "####a#    #a# l#",
      " $ $ $aaaa$ $##$"
    ]
  ]
}
