{
  "xsize": 16,
  "zsize": 16,
  "refpalette": "lostcities:factory",
  "slices": [
    [
      "             55 ",
      "              55",
      "               5",
      "                ",
      "                ",
      "                ",
      "                ",
      "                ",
      "                ",
      "                ",
      "                ",
      "                ",
      "                ",
      "               &",
      "              &5",
      "              55"
    ],
    [
      "             55 ",
      "              55",
      "               5",
      "                ",
      "                ",
      "                ",
      "                ",
      "                ",
      "                ",
      "                ",
      "                ",
      "                ",
      "                ",
      "               &",
      "              &5",
      "              55"
    ],
    [
      "             55!",
      "              55",
      "               5",
      "                ",
      "                ",
      "                ",
      "                ",
      "                ",
      "                ",
      "                ",
      "                ",
      "                ",
      "                ",
      "                ",
      "               5",
      "              55"
    ],
    [
      "             55 ",
      "              55",
      "               5",
      "                ",
      "                ",
      "                ",
      "                ",
      "                ",
      "                ",
      "                ",
      "                ",
      "                ",
      "                ",
      "               &",
      "              &5",
      "              55"
    ],
    [
      "             55 ",
      "              55",
      "               5",
      "                ",
      "                ",
      "                ",
      "                ",
      "                ",
      "                ",
      "                ",
      "                ",
      "                ",
      "                ",
      "              &&",
      "             &&5",
      "              55"
    ],
    [
      "  ͰͰͰͰͰͰͰͰͰͰͰ   ",
      "  ͰͰͰͰͰͰͰͰͰͰͰͰ  ",
      "  ͰͰͰͰͰͰͰͰͰͰͰͰͰ ",
      " ͰͰͰͰͰͰͰͰͰͰͰͰͰͰͰ",
      "ͰͰͰͰͰͰͰͰͰͰͰͰͰͰͰͰ",
      "ͰͰͰͰͰͰͰͰͰͰͰͰͰͰͰͰ",
      "ͰͰͰͰͰͰͰͰͰͰͰͰͰͰͰͰ",
      "ͰͰͰͰͰͰͰͰͰͰͰͰͰͰͰͰ",
      "ͰͰͰͰͰͰͰͰͰͰͰͰͰͰͰͰ",
      "ͰͰͰͰͰͰͰͰͰͰͰͰͰͰͰͰ",
      "ͰͰͰͰͰͰͰͰͰͰͰͰͰͰͰͰ",
      "ͰͰͰͰͰͰͰͰͰͰͰͰͰͰͰͰ",
      "ͰͰͰͰͰͰͰͰͰͰͰͰͰͰͰͰ",
      "ͰͰͰͰͰͰͰͰͰͰͰͰͰͰͰͰ",
      "ͰͰͰͰͰͰͰͰͰͰͰͰͰͰͰ&",
      "ͰͰͰͰͰͰͰͰͰͰͰͰͰͰ&&"
    ]
  ]
}