{
  "xsize": 16,
  "zsize": 16,
  "refpalette": "lostcities:factory",
  "slices": [
    [
      "!!!!!!!!!!!!!!!!",
      "!!!!!!!!!!!!!!!!",
      "!!!!!!!!!!!!!!!!",
      "!!!!!!!!!!!!!!!!",
      "!!!!!!!!!!!!!!!!",
      "!!!!!!!!!!!!!!!!",
      "!!!!!!!!!! !!!!!",
      "!!!!!!!!!!&!!!!!",
      "!!!!!!!!!!&!!!!!",
      "!!!!!!!!!!8!!!!!",
      "!!!!!!!!!!!!!!!!",
      "!!!!!!!!!!!!!!!!",
      "!!!!!!!!!!!!!!!!",
      "!!!!!!!!!!!!!!!!",
      "!!!!!!!!!!!!!!!!",
      "!!!!!!!!!!!!!!!!"
    ],
    [
      "!,,,,!&&  !,,,,!",
      "0      &       0",
      "0 !! !!&!! !!  0",
      "0 !! !! !! !!  0",
      "0              !",
      "! !! !! !! !!   ",
      "  !!&!!&!!&!!   ",
      "  &&&   &&&     ",
      "   &    &&&&    ",
      "       &&&&     ",
      "!      &&      !",
      "0   &&&&       0",
      "0              0",
      "0              0",
      "0              0",
      "!,,,,!    !,,,,!"
    ],
    [
      "$              $",
      "                ",
      "  << << << <<   ",
      "  << << << <<   ",
      "                ",
      "  << <<&<< <<   ",
      " &<<&<<&<< <<   ",
      "  &&   &&&      ",
      "                ",
      "        &       ",
      "                ",
      "                ",
      "                ",
      "                ",
      "                ",
      "$              $"
    ],
    [
      "                ",
      "                ",
      "  << << << <<   ",
      "  << << << <<   ",
      "                ",
      "  << <<&<< <<   ",
      " &<< <<&<< <<   ",
      "  &   &&        ",
      "                ",
      "                ",
      "                ",
      "                ",
      "                ",
      "                ",
      "                ",
      "                "
    ],
    [
      "                ",
      "                ",
      "  <<     < <<   ",
      "  << << << <<   ",
      "                ",
      "  << << << <<   ",
      " &<< <<&<< <<   ",
      "  &             ",
      "                ",
      "                ",
      "                ",
      "                ",
      "                ",
      "                ",
      "                ",
      "                "
    ],
    [
      "                ",
      "                ",
      "  <<     < <<   ",
      "  << <  << <<   ",
      "          &     ",
      "  << << <<&<<   ",
      "  << <<&<<&<<   ",
      "       &&&      ",
      "       &&       ",
      "       &        ",
      "       &        ",
      "       &        ",
      "                ",
      "                ",
      "                ",
      "                "
    ]
  ]
}