{
  "xsize": 16,
  "zsize": 16,
  "refpalette": "lostcities:factory",
  "slices": [
    [
      "                ",
      "                ",
      "!               ",
      "!!              ",
      "!!!             ",
      "!!!             ",
      "!!!             ",
      "!!!             ",
      "!!!   &         ",
      "!!!  &&&        ",
      "!!!   &&       +",
      "!!!            2",
      "!!!             ",
      " !!             ",
      "!!!!!!!!!  !!!!!",
      "$!!!!!!!!!!!!  !"
    ],
    [
      "                ",
      "!               ",
      "!!              ",
      "!!!             ",
      "!!!             ",
      "!!!             ",
      "!!!             ",
      "!!!             ",
      "!!!   &&        ",
      "!!!  &&&&       ",
      "!!!   &&&      +",
      "!!!    &       2",
      "!!!             ",
      " !!             ",
      "!!!!!!!!    !!!!",
      "!!!!!!!!!   !  !"
    ],
    [
      "                ",
      " ]              ",
      " ]!             ",
      " ]              ",
      " ]              ",
      " ]              ",
      " ]!             ",
      " ]              ",
      " ]              ",
      " ]!   &&        ",
      "!!!   &&&      +",
      "!!!    &       2",
      "!!!             ",
      " !              ",
      " !dddddd    !!!!",
      "!!             !"
    ],
    [
      "                ",
      "                ",
      "  !             ",
      "                ",
      "                ",
      "                ",
      "  !             ",
      "                ",
      "                ",
      "  !    &        ",
      "!!!   &&&      V",
      "!!!    &       V",
      "!!!             ",
      "                ",
      " !          !  !",
      " !             !"
    ],
    [
      "  V            V",
      "  V  &         V",
      "  !  &         V",
      "  V &&         V",
      "  V &          V",
      "  V            V",
      "  !            V",
      "  V            V",
      "  V            V",
      "  !    &      VV",
      "!!VVVVV&&  VVVVn",
      "!!!VVVV&   VVVVn",
      "!!!           VV",
      "  V             ",
      " !          !  !",
      " !             !"
    ],
    [
      "!!!!!!!!!!!!!!!!",
      "!!!!!!!!!!!!!!!!",
      "!!!!!!!!!!!!!!!!",
      "!!!!!!!!!!!!!!!!",
      "!!!!!!!!!!!!!!!!",
      "!!!!!!!!!!!!!!!!",
      "!!!!!!!   !!!!!!",
      "!!!!!!!   !!!!!!",
      "!!!!!!!   !!!!!!",
      "!!!!!!!&  !!!!!!",
      "!!!!!!!!& !!!!!!",
      "!!!!!!!!  !!!!!!",
      "!!!!!!!     !!!!",
      "!!!rrrr     rrrr",
      "!!!!!!!     !!!!",
      "!!!!!!       !!!"
    ]
  ]
}