{
  "xsize": 16,
  "zsize": 16,
  "refpalette": "lostcities:factory",
  "slices": [
    [
      " JJ             ",
      " JJ&            ",
      "  JJ&           ",
      "  JJ            ",
      "   JJ           ",
      "&& r            ",
      "&  JJ           ",
      "   JJ           ",
      "   JJ           ",
      "   JJ           ",
      "   r            ",
      "   JJ           ",
      "  JJ            ",
      "  JJ            ",
      " JJ&            ",
      " JJ             "
    ],
    [
      " JJ             ",
      " JJ&            ",
      "  JJ&           ",
      "  JJ            ",
      "   JJ           ",
      "   r            ",
      "&  JJ           ",
      "   JJ           ",
      "   JJ           ",
      "   JJ           ",
      "   r            ",
      "   JJ           ",
      "  JJ            ",
      "  JJ            ",
      " JJ&            ",
      " JJ             "
    ],
    [
      " JJ             ",
      " JJ&            ",
      " &JJ&           ",
      "  JJ            ",
      "   JJ           ",
      "   r            ",
      "&  JJ           ",
      "   JJ           ",
      "   JJ           ",
      "   JJ           ",
      "   r            ",
      "   JJ           ",
      "  JJ            ",
      "  JJ            ",
      " JJ&            ",
      " JJ             "
    ],
    [
      " JJ             ",
      " JJ&            ",
      "  JJ            ",
      "  JJ            ",
      "   JJ           ",
      "   r            ",
      "&  JJ           ",
      "   JJ           ",
      "   JJ           ",
      "   JJ           ",
      "   r            ",
      "   JJ           ",
      "  JJ            ",
      "  JJ            ",
      " JJ&            ",
      " JJ&            "
    ],
    [
      " r&             ",
      " r&&            ",
      " &r&            ",
      "  r             ",
      "   r            ",
      "   r            ",
      "&  r            ",
      "   r            ",
      "   r            ",
      "   r            ",
      "   r            ",
      "   r            ",
      "  r             ",
      "  r             ",
      " r&             ",
      " r&&            "
    ],
    [
      " JJ&            ",
      " JJ&            ",
      " &JJ            ",
      "  JJ            ",
      "   JJ           ",
      "   r            ",
      "&  JJ           ",
      "   JJ           ",
      "   JJ           ",
      "   JJ           ",
      "   r            ",
      "   JJ           ",
      "  JJ            ",
      "  JJ            ",
      " JJ             ",
      " JJ&            "
    ]
  ]
}