{
  "xsize": 16,
  "zsize": 16,
  "refpalette": "lostcities:factory",
  "slices": [
    [
      " ]              ",
      " ]              ",
      " ]              ",
      " ]              ",
      " ]              ",
      " ]              ",
      " ]              ",
      " ]  &&          ",
      " ]  &&&         ",
      " ]  &&&         ",
      " ]!  &         +",
      "!!!             ",
      "!!!             ",
      " !              ",
      " !dddddddd      ",
      " !         !   !"
    ],
    [
      " ]              ",
      " ]              ",
      " ]              ",
      " ]              ",
      " ]              ",
      " ]              ",
      " ]              ",
      " ]   &          ",
      " ]  &&&         ",
      " ]  &&&         ",
      " ]!  &         +",
      "!!!             ",
      "!!!             ",
      " !              ",
      " !dddddddd      ",
      "!!         !   !"
    ],
    [
      " ]              ",
      " ]              ",
      " ]              ",
      " ]              ",
      " ]              ",
      " ]              ",
      " ]              ",
      " ]   &          ",
      " ]  &&&         ",
      " ]  &&&         ",
      " ]!  &&        +",
      "!!!            2",
      "!!!             ",
      " !              ",
      " !dddddddd      ",
      " !         !!  !"
    ],
    [
      " ]              ",
      " ]              ",
      " ]              ",
      " ]              ",
      " ]              ",
      " ]              ",
      " ]              ",
      " ]   &          ",
      " ]  &&&         ",
      " ]  &&&         ",
      " ]! &&&&       +",
      "!!!  &&        2",
      "!!!             ",
      " !              ",
      " !ddddddddd    !",
      " !         !!  !"
    ],
    [
      " ]              ",
      " ]              ",
      " ]              ",
      " ]              ",
      " ]              ",
      " ]              ",
      " ]              ",
      " ]   &          ",
      " ]  &&&         ",
      " ]   &&         ",
      " ]!  &&&       +",
      "!!!   &        2",
      "!!!             ",
      " !              ",
      " !ddddddddd!!!!!",
      "!!         !!  !"
    ],
    [
      " ]              ",
      " ]              ",
      " ]              ",
      " ]              ",
      " ]              ",
      " ]              ",
      " ]              ",
      " ]   &          ",
      " ]  &&&         ",
      " ]   &&         ",
      " ]!  &&&       V",
      "!!!   &&       V",
      "!!!             ",
      " !              ",
      " !ddddddddd!!!!!",
      "E!         !!  !"
    ]
  ]
}