{
  "xsize": 16,
  "zsize": 16,
  "refpalette": "lostcities:factory",
  "slices": [
    [
      " ]!J!!!!!!!!!!JV",
      " ]!J!!!!!!!!!!JV",
      " ]!J!!!!!!!!!!JV",
      " ]!J!!!!!!!!!!JV",
      " ]!JJJJJJJ   JJV",
      " ]!VVVVVVVV    V",
      "!!!VVVVVVVVV  VV",
      "!!!mmmmmmnmmmmmm",
      "&!       5      ",
      "&!              ",
      "!!!jjjjjjjjjjjjj",
      "!!!VVVVVVVVVVVVV",
      " ]!VVVVVVVVVVVVV",
      " ]VVVVVVVVVVVVVV",
      " ]VVVVVVVVVVVVVV",
      " ]VVVVVVVVVVVVVV"
    ],
    [
      " ] J 5       5J ",
      " ] J  5     5 J ",
      " ] J   555    J ",
      " ] J          J ",
      " ] JJJJJJ       ",
      " ]!             ",
      "!!!            n",
      "!!!,,,,,,j,,,  m",
      "&!       5      ",
      "&!              ",
      "!!!,,,,,,,,,,,,j",
      "!!!            k",
      " ]!            2",
      " ]        JJJJJJ",
      " ]  $   $ JJJJJJ",
      " ]        JJJJJJ"
    ],
    [
      "   J 5   &   5J ",
      " ] J  5  && 5 J ",
      " ] J   555&   J ",
      " ] J          J ",
      " ] JJJJJJ     J ",
      " ]!            +",
      "!!!            2",
      "!!!             ",
      " !       5      ",
      "&!              ",
      "!!!             ",
      "!!!            +",
      " ]!            2",
      " ]        JJJJJJ",
      " ]  OOOOO J    J",
      " ]  OOOOO J    J"
    ],
    [
      "    JJJJJJJJJJJ ",
      " ] JJJJJJJJJJJJ ",
      " ] JJJJJJJJJJJJ ",
      " ] JJJJJJJJJJJJ ",
      " ] JJJJJJJ  JJJ ",
      " ]!            +",
      "!!!            2",
      "!!!             ",
      " !       5      ",
      "&!              ",
      "!!!             ",
      "!!!            +",
      "&]!            2",
      " ]        JJJJJJ",
      " ]  OVVVO J    J",
      " ]  V   V J    J"
    ],
    [
      "     5   &   5  ",
      " ]    5  && 5   ",
      " ]     55555    ",
      " ]        &     ",
      " ]              ",
      " ]!            +",
      "!!!            2",
      "!!!             ",
      " !       5      ",
      " !              ",
      "!!!             ",
      "!!!            +",
      "&]!            2",
      " ]        JJJJJJ",
      " ]  OVVVO J     ",
      " ]  V   V J     "
    ],
    [
      "     5       5  ",
      " ]    5   & 5   ",
      " ]     55555    ",
      " ]        &     ",
      " ]              ",
      " ]!            +",
      "!!!            2",
      "!!!             ",
      " !       5      ",
      " !              ",
      "!!!             ",
      "!!!            +",
      "&]!            2",
      "&]        JJJJJJ",
      " ]  OVVVO J     ",
      " ]  VOOOV J     "
    ]
  ]
}