{
  "xsize": 16,
  "zsize": 16,
  "refpalette": "lostcities:factory",
  "slices": [
    [
      "             !! ",
      "             !!!",
      "    +/       !!!",
      "&   23       !!!",
      "&&           !!!",
      "&&           !!!",
      "&            !!!",
      "             !!!",
      "             !!!",
      "             !!!",
      "             !!!",
      "             !!!",
      "             !!!",
      "             !!!",
      "             !!!",
      "             !!!"
    ],
    [
      "             !! ",
      "             !!!",
      "    +/       !!!",
      "    23       !!!",
      "&            !!!",
      "&&           !!!",
      "&            !!!",
      "             !!!",
      "             !!!",
      "             !!!",
      "             !!!",
      "             !!!",
      "             !!!",
      "             !!!",
      "             !!!",
      "             !!!"
    ],
    [
      "              ! ",
      "             !!!",
      "    +/       !!!",
      "    23       !!!",
      "&            !i ",
      "&&            i ",
      "&             i ",
      "             !i ",
      "              i ",
      "              i ",
      "              i ",
      "             !i ",
      "              i ",
      "              i ",
      "              i ",
      "             !i "
    ],
    [
      "                ",
      "             !!!",
      "    VV       !!!",
      "    VV       !!!",
      "&&           !  ",
      "&&&             ",
      "&&              ",
      "             !  ",
      "                ",
      "                ",
      "                ",
      "             !  ",
      "                ",
      "                ",
      "                ",
      "             !  "
    ],
    [
      "             V  ",
      "   VVVV      !!!",
      "   VnnVVVVVVV!!!",
      "    nnVVVVVVVV!!",
      "&&           !  ",
      "&&&          V  ",
      " &           V  ",
      "             !  ",
      "             V  ",
      "             V  ",
      "V               ",
      "V               ",
      "V               ",
      "V            V  ",
      "V            V  ",
      "V            !  "
    ],
    [
      "rrrrrrrrrrrrr!!!",
      "!!!!!!!!!!!!!!!!",
      "!!!!!!!!!!!!!!!!",
      "!!    !!!!!!!!!!",
      "!!      !!!!!!!!",
      "!!&       rr!!!!",
      "!&          !!!!",
      "             !!!",
      "              !!",
      " !r             ",
      "!!rrrr          ",
      "!!rrrrrrrrrr    ",
      "!!rrrrrrrrrr    ",
      "!!rrrrrrrrrr!!! ",
      "!!rrrrrrrrrr!!!!",
      "!!rrrrrrrrrr!!!!"
    ]
  ]
}