{
  "xsize": 16,
  "zsize": 16,
  "refpalette": "lostcities:factory",
  "slices": [
    [
      "vvvvvvvvvvvvvvvv",
      "vvvvvvvvvvvvvvvv",
      "vvvvvvvvvvvvvvvv",
      "vvvvvvvvvvvvvvvv",
      "vvvvvvvvvvvvvvvv",
      "vvvvvvvvvvv!!vvv",
      "vvvvvvvvvvv!!vvv",
      "vvvvvvvvvvvvvvvv",
      "vvvvvvvvvvvvvvvv",
      "vvvvvvvvvvvvvvvv",
      "vvvvvvvvvvvvvvvv",
      "vvvvv!!vvvvvvvvv",
      "vvvvv!!vvvvvvvvv",
      "vvvvvvvvvvvvvvvv",
      "vvvvvvvvvvvvvvvv",
      "vvvvvvvvvvvvvvvv"
    ],
    [
      "             &  ",
      "                ",
      "                ",
      "                ",
      "                ",
      "           !!   ",
      "           !!   ",
      "                ",
      "                ",
      "                ",
      "      &         ",
      "     !!         ",
      "     !!         ",
      "                ",
      "                ",
      "                "
    ],
    [
      "             &  ",
      "                ",
      "                ",
      "                ",
      "                ",
      "           !!   ",
      "           !!   ",
      "                ",
      "                ",
      "                ",
      "                ",
      "     !!&        ",
      "     !!         ",
      "                ",
      "                ",
      "                "
    ],
    [
      "             &  ",
      "                ",
      "                ",
      "                ",
      "                ",
      "           !!   ",
      "           !!   ",
      "                ",
      "                ",
      "                ",
      "                ",
      "     !!&        ",
      "     !!         ",
      "                ",
      "                ",
      "                "
    ],
    [
      "QQQQ        !&  ",
      "QQQQ        !   ",
      "QQQ         !   ",
      "QQ         !!   ",
      "           !    ",
      "           !!   ",
      "          !!!   ",
      "         !!     ",
      "        !!      ",
      "       !!       ",
      "      !!        ",
      "   !!!!&        ",
      "!!!! !!         ",
      "                ",
      "                ",
      "                "
    ],
    [
      "QQQQQQQ     !&  ",
      "QQQQQQ      !   ",
      "QQQQQQ      !   ",
      "QQQQQQ     !!   ",
      "QQQQQ      !    ",
      "QQQQ       !!   ",
      "Q         !!!   ",
      "         !!     ",
      "        !!      ",
      "       !!       ",
      "      !!        ",
      "   !!!!&        ",
      "!!!! !!         ",
      "                ",
      "                ",
      "                "
    ]
  ]
}