{
  "xsize": 16,
  "zsize": 16,
  "refpalette": "lostcities:factory",
  "slices": [
    [
      "        &5&  55 ",
      "        &5&   55",
      "       &&5&    5",
      "        &5      ",
      "         5      ",
      "         5      ",
      "         5      ",
      "         5      ",
      "         5      ",
      "    !!!!!!      ",
      "ͰͰ   ͰͰͰ 5      ",
      "  ͰͰͰ    5      ",
      "                ",
      "                ",
      "                ",
      "                "
    ],
    [
      "        5&   55 ",
      "        5&    55",
      "       &5&     5",
      "       &5&      ",
      "       &5       ",
      "        5       ",
      "        5       ",
      "        5       ",
      "        5       ",
      "      !!!       ",
      "ͰͰͰͰͰͰͰͰ5       ",
      "        5       ",
      "                ",
      "                ",
      "                ",
      "                "
    ],
    [
      "       55    55 ",
      "       55     55",
      "     &&55      5",
      "      &55&      ",
      "      &55&      ",
      "       55&      ",
      "       55       ",
      "       55       ",
      "       55       ",
      "      !!!       ",
      "   ͰͰͰͰ55       ",
      "       55       ",
      "                ",
      "                ",
      "                ",
      "                "
    ],
    [
      "5   & 55     55 ",
      "5   &&55      55",
      "5   &&55       5",
      "5    &55&       ",
      "      55&       ",
      "      55&       ",
      "      55        ",
      "       5        ",
      "       5        ",
      "       !        ",
      "   ͰͰ 55        ",
      "      55        ",
      "                ",
      "                ",
      "                ",
      "                "
    ],
    [
      " 55555       55 ",
      " 55555&       55",
      " 55555&        5",
      " 55555&&        ",
      " 55555 &        ",
      "    55          ",
      "                ",
      "                ",
      "                ",
      "                ",
      "                ",
      "     5          ",
      "                ",
      "                ",
      "                ",
      "                "
    ],
    [
      "    &        55 ",
      "    &&        55",
      "     &         5",
      "                ",
      "                ",
      "                ",
      "                ",
      "                ",
      "                ",
      "                ",
      "                ",
      "                ",
      "                ",
      "                ",
      "                ",
      "                "
    ]
  ]
}