{
  "xsize": 16,
  "zsize": 16,
  "refpalette": "lostcities:factory",
  "slices": [
    [
      "     V     &  V ",
      "     V    &&& V ",
      "     V    &&& V ",
      "     V     &  V ",
      "     O        O ",
      "     V        V ",
      "     V        V ",
      "     V        V ",
      "     V        V ",
      "     V    &   V ",
      "     V   &&&    ",
      "     V   &&&  & ",
      "    &V&   &     ",
      "     V          ",
      "     OVVVVVVVVO ",
      "                "
    ],
    [
      "           &&   ",
      "          &&&&  ",
      "     V     &&   ",
      "            &   ",
      "            &   ",
      "           &&   ",
      "     V     &    ",
      "     V     &    ",
      "     V    &&    ",
      "     V   &&     ",
      "     V&   &&    ",
      "     V& &&&&&   ",
      "    &V&   &&    ",
      "    &V&         ",
      "     OVVVVVVVV  ",
      "                "
    ],
    [
      "        VVVVV   ",
      "        VVVVV&  ",
      "        VVVVV&  ",
      "        VVVVV&  ",
      "        OOOOO&  ",
      "        VVVVV&  ",
      "     O VVVVVV   ",
      "     OVVVVVVV   ",
      "     OVVVVVVV   ",
      "     OVVVVVVV   ",
      "     OVVVVVVV   ",
      "     OVVVVVV&   ",
      "    &OVVVVVV    ",
      "    &OVVVVVV    ",
      "     OOOOOOOOO  ",
      "                "
    ],
    [
      "                ",
      "            &   ",
      "            &   ",
      "            &   ",
      "            &   ",
      "           &&   ",
      "           &    ",
      "           &    ",
      "          &&    ",
      "         &&     ",
      "      &         ",
      "      & &&&&    ",
      "     &&         ",
      "     &          ",
      "                ",
      "                "
    ],
    [
      "                ",
      "                ",
      "                ",
      "                ",
      "                ",
      "                ",
      "                ",
      "                ",
      "                ",
      "                ",
      "                ",
      "                ",
      "                ",
      "                ",
      "                ",
      "                "
    ],
    [
      "                ",
      "                ",
      "                ",
      "                ",
      "                ",
      "                ",
      "                ",
      "                ",
      "                ",
      "                ",
      "                ",
      "                ",
      "                ",
      "                ",
      "                ",
      "                "
    ]
  ]
}