{
  "xsize": 16,
  "zsize": 16,
  "refpalette": "lostcities:factory",
  "slices": [
    [
      "    &&&   &JJ   ",
      "           JJ   ",
      "          JJ    ",
      "          JJ    ",
      "         JJ     ",
      "          r     ",
      "         JJ     ",
      "         JJ     ",
      "         JJ     ",
      "         JJ     ",
      "        &&r     ",
      "        &JJ     ",
      "         &JJ    ",
      "          JJ    ",
      "           JJ   ",
      "     &     JJ   "
    ],
    [
      "  &&&&&   &JJ   ",
      "    &&    &JJ   ",
      "          JJ    ",
      "          JJ    ",
      "         JJ     ",
      "          r     ",
      "         JJ     ",
      "         JJ     ",
      "         JJ     ",
      "        &JJ     ",
      "        &&r     ",
      "        &JJ     ",
      "         &JJ    ",
      "          JJ    ",
      "           JJ   ",
      "    &&     JJ   "
    ],
    [
      "  JJ&&     JJJJJ",
      "  JJ&     &JJJJJ",
      " JJJ      JJJJJJ",
      " JJ       JJJJJJ",
      " JJ      JJJJJJJ",
      " JJ       rJJJJJ",
      " JJ      JJJJJJJ",
      " JJJJJJJJJJJJJJJ",
      " JJJJJJJJJJJJJJJ",
      " JJ     &JJJJJJJ",
      " JJ      &rJJJJJ",
      " JJJ    &JJJJJJJ",
      "  JJ     &JJJJJJ",
      "  JJ      JJJJJJ",
      "  JJ       JJJJJ",
      "   JJ      JJJJJ"
    ],
    [
      "  JJ&      JJ   ",
      "  JJ      &JJ   ",
      " JJJ      JJ    ",
      " JJ       JJ    ",
      " JJ      JJ     ",
      " JJ       r     ",
      " JJ      JJ     ",
      " JJ      JJ     ",
      " JJ      JJ     ",
      " JJ     &JJ     ",
      " JJ      &r     ",
      " JJJ     JJ     ",
      "  JJ      JJ    ",
      "  JJ      JJ    ",
      "  JJ       JJ   ",
      "   JJ      JJ   "
    ],
    [
      "   &       Jr   ",
      "          &Jr   ",
      "          Jr    ",
      "          Jr    ",
      "         Jr     ",
      "          r     ",
      "         Jr     ",
      "         Jr     ",
      "         Jr     ",
      "        &Jr     ",
      "         &r     ",
      "         Jr     ",
      "          Jr    ",
      "          Jr    ",
      "           Jr   ",
      "           Jr   "
    ],
    [
      "          &JJ   ",
      "         &&JJ   ",
      "         &JJ    ",
      "          JJ    ",
      "         JJ     ",
      "          r     ",
      "         JJ     ",
      "         JJ     ",
      "         JJ     ",
      "        &JJ     ",
      "         &r     ",
      "         JJ     ",
      "          JJ    ",
      "          JJ    ",
      "           JJ   ",
      "           JJ   "
    ]
  ]
}