{
  "xsize": 16,
  "zsize": 16,
  "refpalette": "lostcities:factory",
  "slices": [
    [
      "                ",
      "                ",
      "                ",
      "                ",
      "                ",
      "                ",
      "      !  !      ",
      "       !!       ",
      "       !!       ",
      "      !  !      ",
      "                ",
      "                ",
      "                ",
      "                ",
      "                ",
      "                "
    ],
    [
      "zzz|zzVVzz||v   ",
      "zzzzVVvvVVz|v   ",
      "|zzVvvvvvvVzv   ",
      "||zVvvvvvvvVv   ",
      "||zVVvvvvvvVv   ",
      "||zVVvvvvvvVv   ",
      "|zVVVvvvvvVVv   ",
      "zzVVvvvvVVzzz   ",
      "zVVvvvvvVz||z   ",
      "VVVvvvvVz|||z   ",
      "VVvvvvvVz|}|v   ",
      "vVvvvvvV|}}}v   ",
      "vvvvvvvV|}}|v   ",
      "vvvvvvVz|}}|z   ",
      "vVvvvvVz|}||z   ",
      "zVvvvVVz|}||z   "
    ],
    [
      "                ",
      "                ",
      "                ",
      "                ",
      "                ",
      "                ",
      "                ",
      "                ",
      "                ",
      "       !!       ",
      "       !!       ",
      "                ",
      "                ",
      "                ",
      "       !!       ",
      "       !!       "
    ],
    [
      "                ",
      "                ",
      "                ",
      "                ",
      "                ",
      "                ",
      "                ",
      "                ",
      "                ",
      "                ",
      "ͱͱͱͱͱͱͱͱͱͱ      ",
      "ͱͱͱͱͱͱͱͱͱͱ      ",
      "ͱͱͱͱͱͱͱͱͱͱ      ",
      "ͱͱͱͱͱͱͱͱͱͱ      ",
      "ͱͱͱͱͱͱͱͱͱͱ      ",
      "                "
    ],
    [
      "                ",
      "                ",
      "                ",
      "                ",
      "                ",
      "                ",
      "                ",
      "                ",
      "                ",
      "ͱͱͱͱͱͱͱͱͱͱ      ",
      "         ͱ      ",
      "         ͱ      ",
      "         ͱ      ",
      "         ͱ      ",
      "&        ͱ      ",
      "ͱͱͱͱͱͱͱͱͱͱ      "
    ],
    [
      "                ",
      "                ",
      "                ",
      "                ",
      "                ",
      "                ",
      "                ",
      "                ",
      "ͱͱͱͱͱͱͱͱͱͱ      ",
      "         ͱ      ",
      "         ͱ      ",
      "         ͱ      ",
      "         ͱ      ",
      "&        ͱ      ",
      "&&       ͱ      ",
      "&&       ͱ      "
    ]
  ]
}