{
  "xsize": 16,
  "zsize": 16,
  "refpalette": "lostcities:factory",
  "slices": [
    [
      "JJJJJJJJJJJJJJJJ",
      "JJJJJJJJJJJJJJJJ",
      "JJJJJJJJJJJJJJJJ",
      "JJJJJJJJvJJJJJJJ",
      "JJJJJJJJJJJJJJJJ",
      "JJJJJJJJJJJJJJJJ",
      "JJJJJJJJJJJJJJJJ",
      "JJJJJJJJJJJJJJJJ",
      "JJJJJJJJJJJJJJJJ",
      "JJJJ JJJJJJJJJJJ",
      "JJJ   JJJJJJJJJJ",
      "JJ&   JJJJJJJJJJ",
      "JJ    JJJJJJJJJJ",
      "JJ    JJJJJJJJJJ",
      "JJ    JJJJJJJJJJ",
      "JJ   JJJJJJJJJJJ"
    ],
    [
      "!&         &  !&",
      "!          &  !!",
      "           &    ",
      "           &&   ",
      "            &   ",
      "            &   ",
      "            &   ",
      "            &   ",
      "            &   ",
      " &          &&  ",
      " &           &  ",
      "&&           &  ",
      "&            && ",
      "             &&&",
      "&            &!!",
      "              ! "
    ],
    [
      "&&            !&",
      "&             !!",
      "                ",
      "                ",
      "                ",
      "                ",
      "                ",
      "                ",
      "                ",
      "                ",
      "                ",
      "                ",
      "                ",
      "              & ",
      "&            &!!",
      "              ! "
    ],
    [
      "!&            !&",
      "!             !!",
      "                ",
      "                ",
      "                ",
      "                ",
      "                ",
      "                ",
      "                ",
      "                ",
      "                ",
      "                ",
      "                ",
      "              & ",
      "             &!!",
      "              ! "
    ],
    [
      "&             !&",
      "              !!",
      "                ",
      "                ",
      "                ",
      "                ",
      "                ",
      "                ",
      "                ",
      "                ",
      "                ",
      "                ",
      "                ",
      "              & ",
      "             &!!",
      "              ! "
    ],
    [
      "&             !&",
      "              !!",
      "                ",
      "                ",
      "                ",
      "                ",
      "                ",
      "                ",
      "                ",
      "                ",
      "                ",
      "                ",
      "                ",
      "              & ",
      "             &!!",
      "              ! "
    ]
  ]
}