{
  "xsize": 16,
  "zsize": 16,
  "refpalette": "lostcities:factory",
  "slices": [
    [
      "J              J",
      "J              J",
      "J              J",
      "VJ            JV",
      " J            J&",
      "  J            &",
      "   JJ      J    ",
      "    VJJJJJJV    ",
      "    VVVVVVVV    ",
      "    VVVVVVVV    ",
      "    VVVVVVVV    ",
      "    VVVVVVVV    ",
      "    VVVVVVVV    ",
      "    VVVVVVVV    ",
      "    VVVVVVVV    ",
      "    VVVVVVVV    "
    ],
    [
      "J              J",
      "J&             J",
      "J              J",
      "VJ            JV",
      " J            J&",
      "  J          J  ",
      "   JJ      JJ   ",
      "    VJJJJJJV    ",
      "    V      V    ",
      "    V      V    ",
      "    V      V    ",
      "    V      V    ",
      "    V      V    ",
      "    V      V    ",
      "    V      V    ",
      "    V      V    "
    ],
    [
      "J              J",
      "J              J",
      "J              J",
      "VJ            JV",
      " J            J&",
      "  J          J  ",
      "   JJ      JJ   ",
      "    VJJJJJJV    ",
      "    V      V    ",
      "    V      V    ",
      "    V      V    ",
      "    V      V    ",
      "    V      V    ",
      "    V      V    ",
      "    V      V    ",
      "    V      V    "
    ],
    [
      "J              J",
      "J              J",
      "J              J",
      "VJ            JV",
      " J            J&",
      "  J          J  ",
      "   JJ      JJ   ",
      "    VJJJJJJV    ",
      "    V      V    ",
      "    V      V    ",
      "    V      V    ",
      "    V      V    ",
      "    V      V    ",
      "    V      V    ",
      "    V      V    ",
      "    V      V    "
    ],
    [
      "J              J",
      "J              J",
      "J              J",
      "VJ            JV",
      " J            J&",
      "  J          J  ",
      "   JJ      JJ   ",
      "    VJJJJJJV    ",
      "    V      V    ",
      "    V      V    ",
      "    V      V    ",
      "    V      V    ",
      "    V      V    ",
      "    V      V    ",
      "    V      V    ",
      "    V      V    "
    ],
    [
      "J              J",
      "J              J",
      "J              J",
      "VJ            JV",
      " J            J&",
      "  J          J  ",
      "   JJ      JJ   ",
      "    VJJJJJJV    ",
      "           V    ",
      "    V      V    ",
      "    V      V    ",
      "    V      V    ",
      "    V      V    ",
      "    V      V    ",
      "    V      V    ",
      "    V      V    "
    ]
  ]
}