{
  "xsize": 16,
  "zsize": 16,
  "refpalette": "lostcities:factory",
  "slices": [
    [
      "!!!          !!!",
      "!!!          !!!",
      "!!!          !!!",
      "   5        5   ",
      " P5 5   &       ",
      "   5   &&&      ",
      "      5555      ",
      "      5555 &&   ",
      "      5555 &&   ",
      "      5555&&    ",
      "  P5     &&&5   ",
      "  5 5  &  &5 5P ",
      " ! 5    P   5   ",
      "!!!          !! ",
      "!!!          !! ",
      "!!!          !! "
    ],
    [
      "$$$          $$$",
      "$!$          $!$",
      "$$$          $$$",
      "   5        5   ",
      " P5 5   &       ",
      "   5   &&&      ",
      "       &&&      ",
      "        &       ",
      "                ",
      "           &&   ",
      "  P5      &&5&  ",
      "  5 5      5&5P ",
      " ! 5    P   5   ",
      "$$$          $  ",
      "$!$          $! ",
      "$$$          $  "
    ],
    [
      " $            $ ",
      "$!$          $!$",
      " $            $ ",
      "   5        5   ",
      " P5 5  &&  5 5  ",
      "   5   &&&  5   ",
      "        &       ",
      "                ",
      "                ",
      "            &   ",
      "  P5       &5&  ",
      "  5 5      5&5P ",
      "   5    P   5   ",
      " $              ",
      "$!$          $! ",
      " $              "
    ],
    [
      "                ",
      " !            ! ",
      "                ",
      "   5   &    5   ",
      " P5 5 &&&  5 5  ",
      "   5  &&&&  5   ",
      "       &&       ",
      "                ",
      "                ",
      "                ",
      "  P5        5   ",
      "  5 55555555 5P ",
      "   5UUUU5UUU5   ",
      "                ",
      " !            ! ",
      "                "
    ],
    [
      "                ",
      " !            ! ",
      "       &        ",
      "   5  &&&   5   ",
      " P5 5 &&&  5 5  ",
      "   5   &&   5   ",
      "                ",
      "                ",
      "                ",
      "                ",
      "  P5        5   ",
      "  5 5      5 5P ",
      "   5        5   ",
      "                ",
      " !            ! ",
      "                "
    ],
    [
      " $            $ ",
      "$!$          $!$",
      " $     &      $ ",
      "   5UUUUUUUU5   ",
      " P5 5  &   5 5  ",
      "   5        5   ",
      "                ",
      "                ",
      "                ",
      "                ",
      "  P5        5   ",
      "  5 5      5 5P ",
      "   5        5   ",
      " $            $ ",
      "$!$          $!$",
      " $            $ "
    ]
  ]
}