{
  "xsize": 16,
  "zsize": 16,
  "refpalette": "lostcities:factory",
  "slices": [
    [
      "vvvvvvvvvvvvvvvv",
      "vvvvvvvvvvvvvvvv",
      "vvvvvvvvvvvvvvvv",
      "vvvJJJJJJJJJJJJJ",
      "vvvJJJJJJJJJJJJJ",
      "vvvJJJJJJJJJJJJJ",
      "vvvJJJJJJJJJJJJJ",
      "vvvJJJJJJJJJJJJJ",
      "vvvJJJJJJJJJJJJJ",
      "vvvJJJJJJJJJJJJJ",
      "vvvJJJJJJJJJJJJJ",
      "vvvJJJJJJJJJJJJJ",
      "vvvJJJJJJJJJJJJJ",
      "vvvJJJJJJJJJJJJJ",
      "vvvJJJJJJJJJJJJJ",
      "vvvJJJJJJJJJJJJJ"
    ],
    [
      "!!!!!       !!!!",
      "!!!!!   !   !!!!",
      "!!!!!!!!!!!!!!!!",
      "!!!!!       !!!!",
      "!!!!!       !!!!",
      "  !             ",
      " &!  &JJJJJJ    ",
      "&&! &&J!JJ!J    ",
      "&!!  &JJrrJJ    ",
      " &!   JJrrJJ    ",
      "  !   J!JJ!J    ",
      "  !   JJJJJJ    ",
      "!!!!!           ",
      "!!!!!           ",
      "!!!!!        !!!",
      "!!!!!       !!!!"
    ],
    [
      "  !     &     ! ",
      " !!!   &!&   !!!",
      "!!!!!JJJJJJJ!!!!",
      " !!!         !!!",
      "  !           ! ",
      "  J             ",
      " &J &&&         ",
      "&&J&&&&!JJ!     ",
      "&!J&&&&JrrJ     ",
      " &J    JrrJ     ",
      "  J    !JJ!     ",
      "  J             ",
      "  !             ",
      " !!!            ",
      "!!!!!           ",
      " !!!         !!!"
    ],
    [
      "  !     &     ! ",
      " !!!   &!&   !!!",
      "!!!!!JJJJJJJ!!!!",
      " !!!         !!!",
      "  !           ! ",
      "  J             ",
      "  J &&          ",
      " &J&&&&!  !     ",
      "&!J&&&  rr      ",
      " &J&&   rr      ",
      "  J    !  !     ",
      "  J             ",
      "  !             ",
      " !!!            ",
      "!!!!!        !!!",
      " !!!        !!!!"
    ],
    [
      "  !     &     ! ",
      " !!!   &!&   !!!",
      "!!!!!!!!!!!!!!!!",
      " !!!         !!!",
      "  !           ! ",
      "  !             ",
      "  !  &          ",
      " &!&&&&!  !     ",
      "&!!&&&& rr      ",
      " &!& &  rr      ",
      "  !    !  !     ",
      "  !             ",
      "  !             ",
      " !!!            ",
      "!!!!!          &",
      " !!!         !!!"
    ],
    [
      "  !     &     ! ",
      " !!!   &!&   !!!",
      "!!!!!JJJJJJJ!!!!",
      " !!!         !!!",
      "  !           ! ",
      "  J             ",
      "  J             ",
      " &J && !  !     ",
      "&!J&&&& rr      ",
      " &J &&  rr      ",
      "  J    !  !     ",
      "  J             ",
      "  !             ",
      " !!!            ",
      "!!!!!           ",
      " !!!         !!!"
    ]
  ]
}