{
  "xsize": 16,
  "zsize": 16,
  "slices": [
    [
      "               `",
      "               `",
      "  ###          `",
      "  #G#          `",
      "  #G#          `",
      "  #G#          `",
      "  ###  j++j    `",
      "       +  +    `",
      "  ###  +  +    `",
      "  #G#  +  +    `",
      "  #G#  +  +    `",
      "  ###  j  j    `",
      "               `",
      "               `",
      "               `",
      "````````````````"
    ],
    [
      "                ",
      "                ",
      "                ",
      "   K            ",
      "   K            ",
      "   K            ",
      "       j++j     ",
      "       +  +     ",
      "       +  +     ",
      "   K   +  +     ",
      "   K   +  +     ",
      "       j  j     ",
      "                ",
      "                ",
      "                ",
      "                "
    ],
    [
      "                ",
      "                ",
      "                ",
      "                ",
      "                ",
      "                ",
      "       ####     ",
      "       ####     ",
      "       ####     ",
      "       ####     ",
      "       ####     ",
      "       ####     ",
      "                ",
      "                ",
      "                ",
      "                "
    ]
  ]
}
