{
  "xsize": 16,
  "zsize": 16,
  "slices": [
    [
      "################",
      "#SSQQSSQQSSQQSSQ",
      "#SSQQSSQQSSQQSSQ",
      "#QQSSQQSSQQSSQQS",
      "#QQSSQQSSQQSSQQS",
      "#SSQQSSQQSSQQSSQ",
      "#SSQQSSQQSSQQSSQ",
      "#QQSSQQSSQQSSQQS",
      "#QQSSQQSSQQSSQQS",
      "#SSQQSSQQSSQQSSQ",
      "#SSQQSSQQSSQQSSQ",
      "#QQSSQQSSQQSSQQS",
      "#QQSSQQSSQQSSQQS",
      "#SSQQSSQQSSQQSSQ",
      "#SSQQSSQQSSQQSSQ",
      "#QQSSQQSSQQSSQQS"
    ],
    [
      "aaaaaaaaaaaaaaaa",
      "a               ",
      "a               ",
      "a               ",
      "a               ",
      "a      #))))#   ",
      "a               ",
      "a               ",
      "a               ",
      "a               ",
      "a      f    f   ",
      "a               ",
      "a               ",
      "a               ",
      "a               ",
      "a               "
    ],
    [
      "aaaaaaaaaaaaaaaa",
      "a               ",
      "a               ",
      "a               ",
      "a               ",
      "a      `    `   ",
      "a      #))))#   ",
      "a               ",
      "a               ",
      "a               ",
      "a      j    j   ",
      "a               ",
      "a               ",
      "a               ",
      "a               ",
      "a               "
    ],
    [
      "aaaaaaaaaaaaaaaa",
      "a               ",
      "a               ",
      "a               ",
      "a               ",
      "a               ",
      "a      `    `   ",
      "a      #))))#   ",
      "a               ",
      "a               ",
      "a      j    j   ",
      "a               ",
      "a               ",
      "a               ",
      "a               ",
      "a               "
    ],
    [
      "aaaaaaaaaaaaaaaa",
      "a               ",
      "a               ",
      "a               ",
      "a               ",
      "a               ",
      "a               ",
      "a      `    `   ",
      "a      #))))#   ",
      "a      E    E   ",
      "a      j    j   ",
      "a               ",
      "a               ",
      "a               ",
      "a               ",
      "a               "
    ],
    [
      "aaaaaaaaaaaaaaaa",
      "a               ",
      "a               ",
      "a               ",
      "a               ",
      "a               ",
      "a               ",
      "a               ",
      "a      `    `   ",
      "a      #))))#   ",
      "a      j    j   ",
      "a               ",
      "a               ",
      "a               ",
      "a               ",
      "a               "
    ]
  ]
}