{
  "xsize": 16,
  "zsize": 16,
  "slices": [
    [
      "SQQSSQQSSQQSSQQ#",
      "QSSQQSSQQSSQQSS#",
      "QSSQQSSQQSSQQSS#",
      "SQQSSQQSSQQSSQQ#",
      "SQQSSQQSSQQSSQQ#",
      "QSSQQSSQQSSQQSS#",
      "QSSQQSSQQSSQQSS#",
      "SQQSSQQS  QSSQQ#",
      "SQQSSQQS  QSSQQ#",
      "QSSQQSSQ  SQQSS#",
      "QSSQQSSQ  SQQSS#",
      "SQQSSQQS  QSSQQ#",
      "SQQSSQQS))QSSQQ#",
      "QSSQQSSQQSSQQSS#",
      "QSSQQSSQQSSQQSS#",
      "################"
    ],
    [
      "               #",
      "               #",
      "               #",
      "               #",
      "               #",
      "               #",
      "       f  f    #",
      "       `))`    #",
      "       `  `    #",
      "       `  `    #",
      "       `  `    #",
      "       `  `    #",
      "       f  f    #",
      "               #",
      "               #",
      "################"
    ],
    [
      "               #",
      "               #",
      "               #",
      "               #",
      "               #",
      "               #",
      "       j  j    #",
      "       `  `    #",
      "       `))`    #",
      "       `  `    #",
      "       `  `    #",
      "       `  `    #",
      "       j  j    #",
      "               #",
      "               #",
      "################"
    ],
    [
      "               a",
      "               #",
      "               a",
      "               a",
      "               #",
      "               a",
      "       j  j    a",
      "       `  `    #",
      "       `  `    a",
      "       `))`    a",
      "       `  `    #",
      "       `  `    a",
      "       j  j    a",
      "               #",
      "               #",
      "a#aa#aa#aa#aa###"
    ],
    [
      "               #",
      "               #",
      "               #",
      "               #",
      "               #",
      "               #",
      "       j  j    #",
      "       `  `   E#",
      "       `  `    #",
      "       `  `    #",
      "       `))`    #",
      "       `  `    #",
      "       j  j    #",
      "               #",
      "               #",
      "################"
    ],
    [
      "################",
      "################",
      "################",
      "################",
      "################",
      "################",
      "################",
      "########  ######",
      "########  ######",
      "########  ######",
      "########  ######",
      "########))######",
      "################",
      "################",
      "################",
      "################"
    ]
  ]
}