{
  "xsize": 16,
  "zsize": 16,
  "slices": [
    [
      "SQQSSQQSSQQSSQQ#",
      "QSSQQSSQQSSQQSS#",
      "QSSQQSSQQSSQQSS#",
      "SQQSSQQSSQQSSQQ#",
      "SQQSSQQSSQQSSQQ#",
      "QSSQQSSQQSSQQSS#",
      "QSSQQSSQQSSQQSS#",
      "SQQSSQQSSQQSSQQ#",
      "SQQSSQQSSQQSSQQ#",
      "QSSQQSSQQSSQQSS#",
      "QSSQQSSQQSSQQSS#",
      "SQQSSQQSSQQSSQQ#",
      "SQQSSQQSSQQSSQQ#",
      "QSSQQSSQQSSQQSS#",
      "QSSQQSSQQSSQQSS#",
      "################"
    ],
    [
      "               #",
      "               #",
      "              ##",
      "              # ",
      "              # ",
      "              # ",
      "              ##",
      "               #",
      "               #",
      "              ##",
      "              # ",
      "              # ",
      "              # ",
      "              ##",
      "  #####  #######",
      "###   ####   ###"
    ],
    [
      "               a",
      "               a",
      "              ##",
      "              a ",
      "              a ",
      "              a ",
      "              ##",
      "               a",
      "               a",
      "              ##",
      "              a ",
      "              a ",
      "              a ",
      "              ##",
      "  #aaa#  #aaa###",
      "###   #aa#   ###"
    ],
    [
      "               a",
      "               a",
      "              ##",
      "              a ",
      "              a ",
      "              a ",
      "             :##",
      "               a",
      "               a",
      "             :##",
      "              a ",
      "              a ",
      "              a ",
      "      :  :    ##",
      "  #aaa#  #aaa###",
      "###   #aa#   ###"
    ],
    [
      "               a",
      "               a",
      "              ##",
      "              a ",
      "              a ",
      "              a ",
      "             e##",
      "               a",
      "               a",
      "             e##",
      "              a ",
      "              a ",
      "              a ",
      "      e  e    ##",
      "  #aaa#  #aaa###",
      "###   #aa#   ###"
    ],
    [
      "               a",
      "               a",
      "              ##",
      "              a ",
      "              a ",
      "              a ",
      "              ##",
      "               a",
      "               a",
      "              ##",
      "              a ",
      "              a ",
      "              a ",
      "              ##",
      "  #aaa#  #aaa###",
      "###   #aa#   ###"
    ]
  ]
}