{
  "xsize": 16,
  "zsize": 16,
  "refpalette": "lostcities:offshore",
  "slices": [
    [
      "       !!       ",
      " !AA! !!!! !AA! ",
      " B  B  !!  B. B ",
      " B  B      B  B ",
      " !AA!      !AA! ",
      "                ",
      " !            ! ",
      "!!!          !!!",
      "!!!          !!!",
      " !            ! ",
      "                ",
      " !AA!      !AA! ",
      " B  B      B  B ",
      " B  B  !!  B  B ",
      " !AA! !!!! !AA! ",
      "       !!       "
    ],
    [
      "!!!!!!!!!!!!!!!!",
      "!!!!!!!!!!!!!!!!",
      "!!!!!!!!!!!!!!!!",
      "!!!!!!!!!!!!!!!!",
      "!!!!!!!!!!!!!!!!",
      "!!!!!!!!!!!!!!!!",
      "!!!!!!!!!!!!!!!!",
      "!!!!!!!!!!!!!!!!",
      "!!!!!!!!!!!!!!!!",
      "!!!!!!!!!!!!!!!!",
      "!!!!!!!!!!!!!!!!",
      "!!!!!!!!!!!!!!!!",
      "!!!!!!!!!!!!!!!!",
      "!!!!!!!!!!!!!!!!",
      "!!!!!!!!!!!!!!!!",
      "!!!!!!!!!!!!!!!!"
    ],
    [
      "  &  &   & .&   ",
      "          ...   ",
      "           ...  ",
      "            ..  ",
      "  &  &   &  &.. ",
      "            ... ",
      "             .  ",
      "  &  &   &  &   ",
      "                ",
      "                ",
      "                ",
      "  &  &   &  &   ",
      "                ",
      "                ",
      "                ",
      "                "
    ],
    [
      "DDD  DDDDD .DDDD",
      "DDD  DDDDD..DDDD",
      "DDD  DDDDD..DDDD",
      "DDD  DDDDD .DDDD",
      "DDD  DDDDD  DDDD",
      "            ... ",
      "             .  ",
      "DDD  DDDDD  DDDD",
      "DDD  DDDDD  DDDD",
      "DDD  DDDDD  DDDD",
      "DDD  DDDDD  DDDD",
      "DDD  DDDDD  DDDD",
      "                ",
      "                ",
      "                ",
      "                "
    ],
    [
      "$$D  D$$$D  D$$$",
      "  $  $$  $..$   ",
      "  $  $EE $..$E  ",
      "  $  $EE $..$E  ",
      "$$D  D$$$D .D$$$",
      "            ... ",
      "            ..  ",
      "$$D  D$$$D  D$$$",
      "  $  $$  $  $   ",
      "  $  $EE $  $E  ",
      "  $  $EE $  $E  ",
      "$$D  D$$$D  D$$$",
      "                ",
      "                ",
      "                ",
      "                "
    ],
    [
      "$$D  D$$$D  D$$$",
      "  $  $$  $. $   ",
      "  $  $$  $..$   ",
      "  $  $$  $..$.  ",
      "$$D  D$$$D .D$$$",
      "            ... ",
      "           .... ",
      "$$D  D$$$D  D$$$",
      "  $  $$  $  $   ",
      "  $  $$  $  $   ",
      "  $  $$  $  $   ",
      "$$D  D$$$D  D$$$",
      "                ",
      "                ",
      "                ",
      "                "
    ]
  ]
}