{
  "xsize": 16,
  "zsize": 16,
  "refpalette": "lostcities:offshore",
  "slices": [
    [
      "        !!!!!   ",
      "         !!!    ",
      "!  !      !     ",
      " @@       !     ",
      " @@       !     ",
      "!  !      !     ",
      "          !!    ",
      "          !     ",
      "          !     ",
      "         !!!    ",
      "        !!!!!   ",
      "         !!!    ",
      "!!!!!!!!!!!!!   ",
      "    !    !!!   #",
      "          !   #!",
      "             #!#"
    ],
    [
      "        !!!!!   ",
      "         !!!    ",
      "!  !      !     ",
      " @@       #     ",
      " @@       #     ",
      "!  !      #     ",
      "          #!    ",
      "          #     ",
      "          #     ",
      "         !#!    ",
      "        !!!!!   ",
      "         !!!!!!!",
      "!#######!!!!!!!!",
      "    !    !!!!!! ",
      "          !!!! !",
      "           !! ! "
    ],
    [
      "        !!!!!   ",
      "         !!!    ",
      "!  !      !     ",
      " @@       #     ",
      " @@       #     ",
      "!  !      #     ",
      "          #!    ",
      "          #     ",
      "         !#!    ",
      "        !!#!!   ",
      "        !!!!!   ",
      "        !!!!!   ",
      "!#######!!!!!   ",
      "    !    !!!    ",
      "          !  ###",
      "             #!#"
    ],
    [
      "        !!!!!   ",
      "         !!!    ",
      "!  !      !     ",
      " @@       !     ",
      " @@       !     ",
      "!  !      !     ",
      "          !!    ",
      "          !     ",
      "          !     ",
      "         !!!    ",
      "        !!!!!   ",
      "         !!!!   ",
      "!!!!!!!!!!!!!   ",
      "    !    !!!    ",
      "          !    !",
      "              !#"
    ],
    [
      "        !!!!!   ",
      "         !!!    ",
      "!  !      !     ",
      " @@       #     ",
      " @@       #     ",
      "!  !      #     ",
      "          #!    ",
      "          #     ",
      "          #     ",
      "         !#!    ",
      "        !!!!!   ",
      "         !!!!   ",
      "!#######!!!!!   ",
      "    !    !!!    ",
      "          !    !",
      "              ! "
    ],
    [
      "        !!!!!   ",
      "         !!!    ",
      "!  !      !     ",
      " @@       #     ",
      " @@       #     ",
      "!  !      #     ",
      "          #!    ",
      "          #     ",
      "          #     ",
      "         !#!    ",
      "        !!!!!!!!",
      "         !!!    ",
      "!#######!!!!!   ",
      "    !    !!!    ",
      "          !    !",
      "          !   ! "
    ]
  ]
}