{
  "xsize": 16,
  "zsize": 16,
  "refpalette": "lostcities:offshore",
  "slices": [
    [
      " +,           / ",
      "              / ",
      "              / ",
      "              / ",
      "              / ",
      "              / ",
      "              / ",
      "             !!!",
      "              ! ",
      "              !!",
      "              / ",
      "              / ",
      "              / ",
      "              / ",
      "              / ",
      "              / "
    ],
    [
      " +,           / ",
      "              / ",
      "              / ",
      "              / ",
      "              / ",
      "              / ",
      "              / ",
      "             !!!",
      "              ! ",
      "              !!",
      "              / ",
      "              / ",
      "              / ",
      "              / ",
      "              / ",
      "              / "
    ],
    [
      " +,           / ",
      "              / ",
      "              / ",
      "              / ",
      "              / ",
      "              / ",
      "              / ",
      "             !!!",
      "              ! ",
      "              !!",
      "              / ",
      "              / ",
      "              / ",
      "              / ",
      "              / ",
      "              / "
    ],
    [
      " +,           / ",
      "              / ",
      "              / ",
      "              / ",
      "              / ",
      "              / ",
      "              / ",
      "             !!!",
      "              ! ",
      "              !!",
      "              / ",
      "              / ",
      "              / ",
      "              / ",
      "              / ",
      "              / "
    ],
    [
      " $$           / ",
      "              / ",
      "              / ",
      "              / ",
      "              / ",
      "              / ",
      "              / ",
      "             !!!",
      "              ! ",
      "              !!",
      "              / ",
      "              / ",
      "              / ",
      "              / ",
      "              / ",
      "              / "
    ],
    [
      "9$$$$$$$$$$$$$/ ",
      "9$$6666666666,/ ",
      "9$$           / ",
      "9$$           / ",
      "9$$           / ",
      "9$$           / ",
      "9$$           / ",
      "9$$          !!!",
      "9$$           ! ",
      "9$$           !!",
      "9$$           / ",
      "9$$           / ",
      "9$$           / ",
      "9$$           / ",
      "9$$           / ",
      "9$$33333333333/ "
    ]
  ]
}