{
  "xsize": 16,
  "zsize": 16,
  "refpalette": "lostcities:offshore",
  "slices": [
    [
      " !!!!!!!!!!!!!! ",
      " !!!!!!!!!!!!!! ",
      " !!!!!!!!!!!!!! ",
      " !!!!!!!!!!!!!! ",
      "                ",
      "  D$$$D  D$$$D  ",
      "  $$$$$  $$$$$  ",
      "  $   $  $  .$. ",
      "  $   $  $   $  ",
      "  D$$$D  D$$$D  ",
      "                ",
      "                ",
      "  D$$$D  D$$$D  ",
      "  $   $  $   $  ",
      "  $   $  $   $  ",
      "  $   $  $   $  "
    ],
    [
      "                ",
      "  EE EE  EE EE  ",
      "  EE EE  EE EE  ",
      "                ",
      "                ",
      "  D$$$D  D$$$D  ",
      "  $DDD$  $DDD$. ",
      "  $DDD$  $DDD$. ",
      "  $DDD$  $DDD$  ",
      "  D$$$D  D$$$D  ",
      "                ",
      "                ",
      "  D$$$D  D$$$D  ",
      "  $DDD$  $DDD$  ",
      "  $DDD$  $DDD$  ",
      "  $DDD$  $DDD$  "
    ],
    [
      "                ",
      "  EE EE  EE EE  ",
      "  EE EE  EE EE  ",
      "                ",
      "                ",
      "  DDDDD  DDDDD  ",
      "  DDDDD  DDDDD. ",
      "  DDDDD  DDDDD  ",
      "  DDDDD  DDDDD  ",
      "  DDDDD  DDDDD  ",
      "                ",
      "      ..        ",
      "  DDDDD. DDDDD  ",
      "  DDDDD  DDDDD  ",
      "  DDDDD  DDDD   ",
      "  DDDDD  DDDD   "
    ],
    [
      "                ",
      "                ",
      "                ",
      "                ",
      "                ",
      "  &   &  &   &  ",
      "            ... ",
      "             .  ",
      "                ",
      "  &   &  &   &  ",
      "       .        ",
      "      ...       ",
      "  &  .&..&   &  ",
      "      ..        ",
      "                ",
      "         ..     "
    ],
    [
      "                ",
      "                ",
      "                ",
      "                ",
      "                ",
      "  DD  D  DDDDD  ",
      "  DDDDD  DDDDD. ",
      "  DDDDD  DDDDD  ",
      "  DDDDD  DDDDD  ",
      "  DDDDD  DDDDD  ",
      "       ..       ",
      "      ...       ",
      "  DDDDD. DDDDD  ",
      "  DDDDD  DDDD   ",
      "  DDDDD  DDD    ",
      "  DDDDD  DDD    "
    ],
    [
      "                ",
      "                ",
      "                ",
      "                ",
      "                ",
      "  D   D  D$$$D  ",
      "  $EE$$  $EE$$. ",
      "  $EE $  $EE $  ",
      "  $   $  $   $  ",
      "  D$$$D .D$$$D  ",
      "       ...      ",
      "      ....      ",
      "  D$$$D..D$$$D  ",
      "  $EE $  $E     ",
      "  $   $  $      ",
      "  $   $  $..    "
    ]
  ]
}