{
  "xsize": 16,
  "zsize": 16,
  "refpalette": "lostcities:offshore",
  "slices": [
    [
      "                ",
      "                ",
      "     G      ..  ",
      "           .HIH ",
      "           $$$$ ",
      "         $$    $",
      "        $       ",
      "        $       ",
      "      H$        ",
      "I     I$        ",
      "      H$        ",
      "       $        ",
      "        $       ",
      "        $       ",
      "         $$    $",
      "           $$$$ "
    ],
    [
      "                ",
      "                ",
      "     G      .   ",
      "          !!!!!!",
      "         !!$$$$!",
      "        !$$    $",
      "       !$       ",
      "      !!$       ",
      "      !$        ",
      "I     !$        ",
      "      !$        ",
      "      !$        ",
      "      !!$       ",
      "       !$       ",
      "        !$$    $",
      "         !!$$$$!"
    ],
    [
      "                ",
      "                ",
      "     G      .   ",
      "          !!!!!!",
      "         !!$$$$!",
      "          $    $",
      "       !$       ",
      "      !!$       ",
      "      !$        ",
      "I     !$        ",
      "      !$        ",
      "      !$        ",
      "      !!$       ",
      "       !$       ",
      "        !$$    $",
      "         !!$$$$!"
    ],
    [
      "                ",
      "                ",
      "     G      .   ",
      "           ..I  ",
      "           $$$$ ",
      "            .  $",
      "                ",
      "        $       ",
      "       $        ",
      "I     I$        ",
      "       $        ",
      "       $        ",
      "        $       ",
      "        $       ",
      "         $$    $",
      "           $$$$ "
    ],
    [
      "                ",
      "                ",
      "     G          ",
      "            .I  ",
      "           $$$$ ",
      "            .  $",
      "                ",
      "        $       ",
      "       $        ",
      "I     I$        ",
      "       $        ",
      "       $        ",
      "        $       ",
      "        $       ",
      "         $$    $",
      "           $$$$ "
    ],
    [
      "                ",
      "                ",
      "     G          ",
      "            .I  ",
      "           $$$$ ",
      "            .  $",
      "                ",
      "        $       ",
      "       $        ",
      "I     I$        ",
      "       $        ",
      "       $        ",
      "        $       ",
      "        $       ",
      "         $$    $",
      "           $$$$ "
    ]
  ]
}