{
  "xsize": 16,
  "zsize": 16,
  "refpalette": "lostcities:offshore",
  "slices": [
    [
      "$$$D            ",
      "                ",
      "                ",
      "$$$D            ",
      "   $            ",
      "   $            ",
      "   $            ",
      "$$$D            ",
      "          !     ",
      "         !!!    ",
      "$$$D    !!!!!   ",
      "$$$$     !!!    ",
      "   $      !     ",
      "   $           #",
      "$$$D          #!",
      "             #!#"
    ],
    [
      "$$$D            ",
      "                ",
      "                ",
      "$$$D            ",
      "DDD$            ",
      "DDD$            ",
      "DDD$            ",
      "$$$D            ",
      "          !     ",
      "         !!!    ",
      "$$$D    !!!!!   ",
      "DDD$     !!!!!!!",
      "DDD$      !!!!!!",
      "DDD$       !!!! ",
      "$$$D       !!! !",
      "           !! ! "
    ],
    [
      "DDDD            ",
      "                ",
      "                ",
      "DDDD            ",
      "DDDD            ",
      "DDDD            ",
      "DDDD            ",
      "DDDD            ",
      "         !!!    ",
      "        !!!!!   ",
      "DDDD    !!!!!   ",
      "DDDD    !!!!!   ",
      "DDDD     !!!!   ",
      "DDDD            ",
      "DDDD         ###",
      "             #!#"
    ],
    [
      "   &            ",
      "                ",
      "                ",
      "   &            ",
      "                ",
      "                ",
      "                ",
      "   &            ",
      "          !     ",
      "         !!!    ",
      "   &    !!!!!   ",
      "         !!!!   ",
      "          !     ",
      "                ",
      "   &           !",
      "              !#"
    ],
    [
      "DDDD            ",
      "                ",
      "                ",
      "DDDD            ",
      "DDDD            ",
      "DDDD            ",
      "DDDD            ",
      "DDDD            ",
      "          !     ",
      "         !!!    ",
      "DDDD    !!!!!   ",
      "DDDD     !!!!   ",
      "DDDD      !     ",
      "DDDD            ",
      "DDDD           !",
      "              ! "
    ],
    [
      "$$$D            ",
      "                ",
      "                ",
      "$$$D            ",
      "EE $            ",
      "   $            ",
      "   $            ",
      "$$$D            ",
      "          !     ",
      "         !!!    ",
      "$$$D    !!!!!!!!",
      "EE$$     !!!    ",
      "EE $      !     ",
      "   $      !     ",
      "$$$D      !    !",
      "          !   ! "
    ]
  ]
}