{
  "xsize": 16,
  "zsize": 16,
  "refpalette": "lostcities:offshore",
  "slices": [
    [
      "                ",
      "                ",
      "                ",
      "                ",
      "                ",
      "                ",
      "                ",
      "                ",
      "                ",
      "                ",
      "                ",
      "m               ",
      " mm            m",
      "   mm        mm ",
      "     mmmmmmmm   ",
      "   !       ...! "
    ],
    [
      "                ",
      "                ",
      "                ",
      "                ",
      "                ",
      "                ",
      "                ",
      "                ",
      "                ",
      "                ",
      "                ",
      "m               ",
      "!mm            m",
      " !!mm        mm!",
      "   !!mmmmmmmm!! ",
      "   ! !!!!!!!!.! "
    ],
    [
      "                ",
      "                ",
      "                ",
      "                ",
      "                ",
      "                ",
      "                ",
      "                ",
      "                ",
      "                ",
      "                ",
      "m               ",
      "!mm            m",
      " !!mm      ..mm!",
      "   !!mmmmmmmm!! ",
      "   ! !!!!!!!!.! "
    ],
    [
      "mmmmmmmmmmmmmmmm",
      "mmmmmmmmmmmmmmmm",
      "mmmmmmmmmmmmmmmm",
      "mmmmmmmmmmmmmmmm",
      "mmmmmmmmmmmmmmmm",
      "mmmmmmmmmmmmmmmm",
      "mmmmmmmmmmmmmmmm",
      "mmmmmmmmmmmmmmmm",
      "mmmmmmmmmmmmmmmm",
      "mmmmmmmmmmmmmmmm",
      "mmmmmmmmmmmmmmmm",
      "mmmmmmmmmmmmmmmm",
      " mmmmmmmmmmmmmmm",
      "   mmmmmmmmmmmm ",
      "     mmmmmmmm.  ",
      "            .   "
    ],
    [
      "mmmmmmmmmmmmmmmm",
      "mmmmmmmmmmmmmmmm",
      "mmmmmmmmmmmmmmmm",
      "mmmmmmmmmmmmmmmm",
      "mmmmmmmmmmmmmmmm",
      "mmmmmmmmmmmmmmmm",
      "mmmmmmmmmmmmmmmm",
      "mmmmmmmmmmmmmmmm",
      "mmmmmmmmmmmmmmmm",
      "mmmmmmmmmmmmmmmm",
      " mmmmmmmmmmmmmmm",
      "  mmmmmmmmmmmmmm",
      "   mmmmmmmmmmmm ",
      "      mmmmmm.   ",
      "           ..   ",
      "                "
    ],
    [
      "mmmmmmmmmmmmmmmm",
      "mmmmmmmmmmmmmmmm",
      "mmmmmmmmmmmmmmmm",
      "mmmmmmmmmmmmmmmm",
      "mmmmmmmmmmmmmmmm",
      "mmmmmmmmmmmmmmmm",
      "mmmmmmmmmmmmmmmm",
      "mmmmmmmmmmmmmmmm",
      "mmmmmmmmmmmmmmmm",
      " mmmmmmmmmmmmmmm",
      "  mmmmmmmmmmmmmm",
      "   mmmmmmmmmmmm ",
      "      mmmmmm.   ",
      "           .    ",
      "                ",
      "                "
    ]
  ]
}