{
  "xsize": 16,
  "zsize": 16,
  "refpalette": "lostcities:offshore",
  "slices": [
    [
      "                ",
      "                ",
      "        G       ",
      "HIH             ",
      "$$$             ",
      "   $$           ",
      "     $          ",
      "     $          ",
      "     !$         ",
      "    !!$H        ",
      "   !!!$I        ",
      "    !!$H        ",
      "     $          ",
      "#    $          ",
      "!# $$           ",
      "$$$             "
    ],
    [
      "                ",
      "                ",
      "        G       ",
      "HIH             ",
      "$$$             ",
      "   $$           ",
      "     $          ",
      "     $          ",
      "     !$         ",
      "    !!$H        ",
      "   !!!$I        ",
      "!!!!!!$H        ",
      "!!!!!$          ",
      " !!!!$          ",
      "! !$$           ",
      "$$$!!           "
    ],
    [
      "                ",
      "                ",
      "        G       ",
      "!!!!            ",
      "$$$!!           ",
      "   $$!          ",
      "     $!         ",
      "     $!!        ",
      "    !!$!        ",
      "   !!!$!        ",
      "   !!!$!        ",
      "   !!!$!        ",
      "   !!$!!        ",
      "##   $!         ",
      "!# $$!          ",
      "$$$!!           "
    ],
    [
      "                ",
      "                ",
      "        G       ",
      "!!!!            ",
      "$$$!!           ",
      "   $$!          ",
      "     $!         ",
      "     $!!        ",
      "     !$!        ",
      "    !!$!        ",
      "   !!!$!        ",
      "    !!$!        ",
      "     $!!        ",
      "     $!         ",
      "!  $$!          ",
      "$$$!!           "
    ],
    [
      "                ",
      "                ",
      "        G       ",
      "HIH             ",
      "$$$             ",
      "   $$           ",
      "     $          ",
      "     $          ",
      "     !$         ",
      "    !!$H        ",
      "   !!!$I        ",
      "    !!$H        ",
      "     $          ",
      "     $          ",
      "!  $$           ",
      "$$$             "
    ],
    [
      "                ",
      "                ",
      "        G       ",
      "HIH             ",
      "$$$             ",
      "   $$           ",
      "     $          ",
      "     $          ",
      "     !$         ",
      "    !!$H        ",
      "!!!!!!$I        ",
      "    !!$H        ",
      "     $          ",
      "     $          ",
      "!  $$!          ",
      "$$$  !          "
    ]
  ]
}