{
  "xsize": 16,
  "zsize": 16,
  "refpalette": "lostcities:offshore",
  "slices": [
    [
      " D$$$D  D$$$D  D",
      "                ",
      "                ",
      " D$$$D  D$$$D  D",
      " $   $  $   $  $",
      " $   $  $   $  $",
      " $   $  $   $  $",
      " D$$$D  D$$$D  D",
      "                ",
      "                ",
      " D$$$D  D$$$D  D",
      " $$$$$  $$$$$  $",
      " $   $  $   $  $",
      " $   $  $   $  $",
      " D$$$D  D$$$D  D",
      "                "
    ],
    [
      " D$$$D  D$$$D  D",
      "                ",
      "                ",
      " D$$$D  D$$$D  D",
      " $DDD$  $DDD$  $",
      " $DDD$  $DDD$  $",
      " $DDD$  $DDD$  $",
      " D$$$D  D$$$D  D",
      "                ",
      "                ",
      " D$$$D  D$$$D  D",
      " $DDD$  $DDD$  $",
      " $DDD$  $DDD$  $",
      " $DDD$  $DDD$  $",
      " D$$$D  D$$$D  D",
      "                "
    ],
    [
      " DDDDD  DDDDD  D",
      "                ",
      "                ",
      " DDDDD  DDDDD  D",
      " DDDDD  DDDDD  D",
      " DDDDD  DDDDD  D",
      " DDDDD  DDDDD  D",
      " DDDDD  DDDDD  D",
      "                ",
      "                ",
      " DDDDD  DDDDD  D",
      " DDDDD  DDDDD  D",
      " DDDDD  DDDDD  D",
      " DDDDD  DDDDD  D",
      " DDDDD  DDDDD  D",
      "                "
    ],
    [
      "                ",
      "                ",
      "                ",
      "                ",
      "                ",
      "                ",
      "                ",
      "                ",
      "                ",
      "                ",
      "                ",
      "                ",
      "                ",
      "                ",
      "                ",
      "                "
    ],
    [
      "                ",
      "                ",
      "                ",
      "                ",
      "                ",
      "                ",
      "                ",
      "                ",
      "                ",
      "                ",
      "                ",
      "                ",
      "                ",
      "                ",
      "                ",
      "                "
    ],
    [
      "                ",
      "                ",
      "                ",
      "                ",
      "                ",
      "                ",
      "                ",
      "                ",
      "                ",
      "                ",
      "                ",
      "                ",
      "                ",
      "                ",
      "                ",
      "                "
    ]
  ]
}