{
  "xsize": 16,
  "zsize": 16,
  "refpalette": "lostcities:offshore",
  "slices": [
    [
      "                ",
      "                ",
      "     G          ",
      "            .I  ",
      "           .$$$ ",
      "            .  $",
      "                ",
      "        $       ",
      "       $        ",
      "I     I$        ",
      "       $        ",
      "       $        ",
      "        $       ",
      "        $       ",
      "         $$    $",
      "           $$$$ "
    ],
    [
      "                ",
      "                ",
      "           ..   ",
      "           ..I  ",
      "           .$$$ ",
      "            .  $",
      "                ",
      "                ",
      "       $        ",
      "      I$        ",
      "       $        ",
      "       $        ",
      "        $       ",
      "        $       ",
      "         $$    $",
      "           $$$$ "
    ],
    [
      "                ",
      "           .    ",
      "          ...   ",
      "          ...I  ",
      "           .$$$ ",
      "               $",
      "                ",
      "                ",
      "                ",
      "      I$        ",
      "       $        ",
      "       $        ",
      "        $       ",
      "        $       ",
      "         $$    $",
      "           $$$$ "
    ],
    [
      "                ",
      "           .    ",
      "          GGGGGG",
      "          ...I  ",
      "           $$$$ ",
      "            .  $",
      "     G          ",
      "     G          ",
      "     G          ",
      "     GI         ",
      "     G $        ",
      "     G $        ",
      "     G  $       ",
      "     G  $       ",
      "     G   $$    $",
      "     G     $$$$ "
    ],
    [
      "                ",
      "                ",
      "           .    ",
      "           ..I  ",
      "          .$$$$ ",
      "           ..  $",
      "                ",
      "                ",
      "                ",
      "                ",
      "                ",
      "       $        ",
      "        $       ",
      "        $       ",
      "         $$    $",
      "           $$$$ "
    ],
    [
      "                ",
      "                ",
      "                ",
      "           . I  ",
      "          .$$$$ ",
      "          $$$$$$",
      "           $$$$$",
      "           $$$$$",
      "          $$$$$$",
      "          $$$$$$",
      "          $$$$$$",
      "        $$$$$$$$",
      "        $$$$$$$$",
      "        $$$$$$$$",
      "         $$$$$$$",
      "           $$$$ "
    ]
  ]
}