{
  "xsize": 16,
  "zsize": 16,
  "refpalette": "lostcities:offshore",
  "slices": [
    [
      "       !!       ",
      " !AA! !!!! !AA! ",
      " B  B  !!  B  B ",
      " B  B      B  B ",
      " !AA!      !AA! ",
      "                ",
      " !            ! ",
      "!!!          !!!",
      "!!!          !!!",
      " !            ! ",
      "                ",
      " !AA!      !AA! ",
      " B  B      B  B ",
      " B  B  !!  B  B ",
      " !AA! !!!! !AA! ",
      "       !!       "
    ],
    [
      "$$!!!!!!!!!!!!!!",
      "$$!!!!!!!!!!!!!!",
      "$$!!!!!!!!!!!!!!",
      "$$!!!!!!!!!!!!!!",
      "$$!!!!!!!!!!!!!!",
      "$$!!!!!!!!!!!!!!",
      "$$!!!!!!!!!!!!!!",
      "$$!!!!!!!!!!!!!!",
      "$$!!!!!!!!!!!!!!",
      "$$!!!!!!!!!!!!!!",
      "$$!!!!!!!!!!!!!!",
      "$$!!!!!!!!!!!!!!",
      "$$!!!!!!!!!!!!!!",
      "$$!!!!!!!!!!!!!!",
      "$$!!!!!!!!!!!!!!",
      "$$!!!!!!!!!!!!!!"
    ],
    [
      "!!!!!!!!!E!!!!! ",
      "!!!!!!!E!E!!!!! ",
      "!!!!!!!!!i!!!!! ",
      "!!!!!!!jkI!!!!! ",
      "!!!!!!!!!!!!!!! ",
      "!!!!!!!!!!!!!!! ",
      "!!!!!!!!!!!!!!! ",
      "!!!!!!!!!!!!!!! ",
      "!!!!!!!!!!!!!!! ",
      "                ",
      "                ",
      "!!!!!!!!!!!!!!! ",
      "!!!!!!!!!!!!!!! ",
      "!!!!!!!!!!!!!!! ",
      "!!!!!!!!!!!!!!! ",
      "!!!!!!!!!!!!!!! "
    ],
    [
      "  !E!!!!!!E!    ",
      " !!E!!=!!!!!    ",
      " !!E!!!!!!!!    ",
      "  !E!!!!!!E!    ",
      " !!E!!E!!E!!    ",
      "!!!!!!!!!!!!    ",
      "&&          &&& ",
      "!&          &!& ",
      "&&          &&& ",
      "                ",
      "                ",
      "&&          &&& ",
      "!&          &!& ",
      "&!! !! !! !!&&& ",
      " !!!!!!!!!!!    ",
      "  !EEEEEEEE!    "
    ],
    [
      "   E  )(* E     ",
      " EEEEE=EE EE    ",
      " EEEEE+EE EE    ",
      "   E      E     ",
      " EEEEEEEEEEE    ",
      " EE EE EE EE    ",
      "&            &  ",
      "!&          &!& ",
      "&            &  ",
      "                ",
      "                ",
      "&            &  ",
      "!&          &!& ",
      "&EE EE EE EE &  ",
      " EE EE EE EE    ",
      "   EEEEEEEE     "
    ],
    [
      "  !E!!)(*lE!    ",
      " EEEEE=EE!EE    ",
      " EEEEEgEE!EE    ",
      "  !E!!!!!!E!    ",
      " EEEEEEEEEEE    ",
      " EE!EE!EE!EE    ",
      "                ",
      "!            !  ",
      "                ",
      "                ",
      "                ",
      "                ",
      "!            !  ",
      " EE EE EE EE    ",
      " EE!EE!EE!EE    ",
      "  !EEEEEEEE!    "
    ]
  ]
}