{
  "xsize": 16,
  "zsize": 16,
  "refpalette": "lostcities:offshore",
  "slices": [
    [
      "                ",
      "                ",
      "        G       ",
      " I     ...      ",
      "$$$ .. ...      ",
      "   $$....       ",
      "    .$.         ",
      "     $          ",
      "      $         ",
      "      $         ",
      "      $I        ",
      "      $         ",
      "     $          ",
      "     $          ",
      "   $$           ",
      "$$$             "
    ],
    [
      "                ",
      "        .       ",
      "       .G.      ",
      " I   .....      ",
      "$$$ ... .       ",
      "   $$..         ",
      "    .$          ",
      "     $          ",
      "      $         ",
      "      $         ",
      "      $I        ",
      "      $         ",
      "     $          ",
      "     $          ",
      "   $$           ",
      "$$$             "
    ],
    [
      "                ",
      "        .       ",
      "      ..G.      ",
      " I   ....       ",
      "$$$ ....        ",
      "   $$..         ",
      "    .$          ",
      "     $          ",
      "      $         ",
      "      $         ",
      "      $I        ",
      "      $         ",
      "     $          ",
      "     $          ",
      "   $$           ",
      "$$$             "
    ],
    [
      "                ",
      "      ...       ",
      "GGGGGGGGG.      ",
      " I   ...G       ",
      "$$$.... G       ",
      "  .$$.  G       ",
      "   ..$  G       ",
      "     $  G       ",
      "      $ G       ",
      "      $ G       ",
      "      $IG       ",
      "      $ G       ",
      "     $  G       ",
      "     $  G       ",
      "   $$   G       ",
      "$$$     G       "
    ],
    [
      "                ",
      "                ",
      "      ...       ",
      " I    .         ",
      "$$$ .           ",
      "   $$.          ",
      "    .$          ",
      "     $          ",
      "      $         ",
      "      $         ",
      "      $I        ",
      "      $         ",
      "     $          ",
      "     $          ",
      "   $$           ",
      "$$$             "
    ],
    [
      "                ",
      "                ",
      "                ",
      " I              ",
      "$$$ .           ",
      "$$$$$.          ",
      "$$$$$$          ",
      "$$$$$$          ",
      "$$$$$$$         ",
      "$$$$$$$         ",
      "$$$$$$$I        ",
      "$$$$$$$         ",
      "$$$$$$          ",
      "$$$$$$          ",
      "$$$$$           ",
      "$$$             "
    ]
  ]
}