{
  "xsize": 16,
  "zsize": 16,
  "refpalette": "lostcities:offshore",
  "slices": [
    [
      "       !!      H",
      " !AAG !!!G !AA! ",
      " B  B  !!  B  B ",
      " B  B      B  B ",
      " !AA!      !AA! ",
      "                ",
      " !            ! ",
      "!!!          !!!",
      "!!!          !!!",
      " !            ! ",
      "                ",
      " !AA!      !AA! ",
      " B  B      B  B ",
      " B  B  !!  B  B ",
      " !AA! !!!! !AA! ",
      "       !!       "
    ],
    [
      "!!!!!!!!!!!!!!!H",
      "!!!!G!!!!G!!!!!!",
      "!!$$$$$$$$$$$$$$",
      "!!$$$$$$$$$$$$$$",
      "!!$$$$$$$$$$$$$$",
      "!!$$$$$$$$$$$$$$",
      "!!$$$$$$$$$$$$$$",
      "!!$$$$$$$$$$$$$$",
      "!!$$$$$$$$$$$$$$",
      "!!$$$$$$$$$$$$$$",
      "!!$$$$$$$$$$$$$$",
      "!!$$$$$$$$$$$$$$",
      "!!$$$$$$$$$$$$$$",
      "!!$$$$$$$$$$$$$$",
      "!!$$$$$$$$$$$$$$",
      "!!$$$$$$$$$$$$$$"
    ],
    [
      "               H",
      "    G    G      ",
      "                ",
      "                ",
      "                ",
      "                ",
      "                ",
      "                ",
      "                ",
      "                ",
      "                ",
      "                ",
      "                ",
      "                ",
      "   !      !     ",
      "                "
    ],
    [
      "    G    G     H",
      "GGGGG    GGGGGGG",
      "                ",
      "                ",
      "                ",
      "                ",
      "                ",
      "                ",
      "                ",
      "                ",
      "                ",
      "                ",
      "                ",
      "                ",
      "   & !!!! &     ",
      "                "
    ],
    [
      "               H",
      "    G    G      ",
      "                ",
      "                ",
      "                ",
      "                ",
      "                ",
      "                ",
      "                ",
      "                ",
      "                ",
      "                ",
      "                ",
      "      $$        ",
      "   !!$$$$!!     ",
      "     $$$$       "
    ],
    [
      "               H",
      "    G    G      ",
      "                ",
      "                ",
      "                ",
      "                ",
      "                ",
      "                ",
      "                ",
      "                ",
      "                ",
      "                ",
      "     $$$$       ",
      "    $$  $$      ",
      "   !$    $!     ",
      "    $$$$$$      "
    ]
  ]
}