{
  "xsize": 16,
  "zsize": 16,
  "refpalette": "lostcities:offshore",
  "slices": [
    [
      "                ",
      "                ",
      "                ",
      "                ",
      "                ",
      "                ",
      "                ",
      "                ",
      "!!        !!  !!",
      " !''''''''!!!!!!",
      " !        !!  !!",
      "!!!             ",
      "!!!          )* ",
      " %!          +, ",
      " %              ",
      " %              "
    ],
    [
      "                ",
      "                ",
      "                ",
      "                ",
      "                ",
      "                ",
      "                ",
      "                ",
      " !        !!  !!",
      " !''''''''!!!!!!",
      " !        !!  !!",
      "!!!             ",
      "!!!          )* ",
      " %!          +, ",
      " %              ",
      " %              "
    ],
    [
      "                ",
      "                ",
      "                ",
      "                ",
      "                ",
      "                ",
      "                ",
      "                ",
      " !        !!  !!",
      " !''''''''!!!!!!",
      " !        !!  !!",
      "!!!             ",
      "!!!          )* ",
      " %!          +, ",
      " %              ",
      " %              "
    ],
    [
      "                ",
      "                ",
      "                ",
      "                ",
      "                ",
      "                ",
      "                ",
      "                ",
      "!!        !!  !!",
      " !''''''''!!!!!!",
      " !        !!  !!",
      "!!!             ",
      "!!!          )* ",
      " %!          +, ",
      " %              ",
      " %              "
    ],
    [
      "                ",
      "                ",
      "                ",
      "                ",
      "                ",
      "                ",
      "                ",
      "                ",
      "2!        !!  !!",
      " !''''''''!!!!!!",
      " !        !!  !!",
      "!!!             ",
      "!!!          $$ ",
      " %!          $$ ",
      " %              ",
      " %              "
    ],
    [
      "                ",
      "                ",
      "                ",
      "                ",
      "                ",
      "                ",
      "                ",
      "                ",
      " !        !!  !!",
      " !''''''''!!!!!!",
      " !        !!  !!",
      "!!!333333333333*",
      "!!!$$$$$$$$$$$$5",
      " %!$$$$$$$$$$$$5",
      " %           $$5",
      " %           $$5"
    ]
  ]
}