{
  "xsize": 16,
  "zsize": 16,
  "refpalette": "lostcities:offshore",
  "slices": [
    [
      "IH     !!       ",
      " !AA! !!G! !AA! ",
      " B  B  !!  B  B ",
      " B  B      B  B ",
      " !AA!      !AA! ",
      "                ",
      " !            ! ",
      "!!!          !!!",
      "!!!          !!!",
      " !            ! ",
      "                ",
      " !AA!      !AA! ",
      " B  B      B  B ",
      " B  B  !!  B  B ",
      " !AA! !!!! !AA! ",
      "       !!       "
    ],
    [
      "IH!!!!!!!!!!!!!!",
      "!!!!!!!!G!!!!!!!",
      "$$!!!!!!!!!!!!!!",
      "$$!!!!!!!!!!!!!!",
      "$$!!!!!!!!!!!!!!",
      "$$!!!!!!!!!!!!!!",
      "$$!!!!!!!!!!!!!!",
      "$$!!!!!!!!!!!!!!",
      "$$!!!!!!!!!!!!!!",
      "$$!!!!!!!!!!!!!!",
      "$$!!!!!!!!!!!!!!",
      "$$!!!!!!!!!!!!!!",
      "$$!!!!!!!!!!!!!!",
      "$$!!!!!!!!!!!!!!",
      "$$!!!!!!!!!!!!!!",
      "$$!!!!!!!!!!!!!!"
    ],
    [
      "IH              ",
      "        G       ",
      "                ",
      "                ",
      "                ",
      "                ",
      "                ",
      "                ",
      "                ",
      "                ",
      "                ",
      "                ",
      "                ",
      "                ",
      "!      !        ",
      "                "
    ],
    [
      "IH      G       ",
      "GGGGGGGGG       ",
      "                ",
      "                ",
      "                ",
      "                ",
      "                ",
      "                ",
      "                ",
      "                ",
      "                ",
      "                ",
      "                ",
      "                ",
      "& !!!! &        ",
      "                "
    ],
    [
      "IH              ",
      "        G       ",
      "                ",
      "                ",
      "                ",
      "                ",
      "                ",
      "                ",
      "                ",
      "                ",
      "                ",
      "                ",
      "                ",
      "   $$           ",
      "!!$$$$!!        ",
      "  $$$$          "
    ],
    [
      "IH              ",
      "        G       ",
      "                ",
      "                ",
      "                ",
      "                ",
      "                ",
      "                ",
      "                ",
      "                ",
      "                ",
      "                ",
      "  $$$$          ",
      " $$  $$         ",
      "!$    $!        ",
      " $$$$$$         "
    ]
  ]
}