{
  "xsize": 16,
  "zsize": 16,
  "refpalette": "lostcities:offshore",
  "slices": [
    [
      "                ",
      "                ",
      "        G       ",
      "HIH             ",
      "$$$             ",
      "   $$           ",
      "     $          ",
      "     $          ",
      "     !$         ",
      "    !!$H        ",
      "   !!!$I        ",
      "    !!$H        ",
      "     $          ",
      "#    $          ",
      "!# $$           ",
      "$$$             "
    ],
    [
      "                ",
      "                ",
      "        G       ",
      "HIH             ",
      "$$$             ",
      "   $$           ",
      "     $          ",
      "     $          ",
      "     !$         ",
      "    !!$H        ",
      "   !!!$I        ",
      "!!!!!!$H        ",
      "!!!!!$          ",
      " !!!!$          ",
      "! !$$           ",
      "$$$!!           "
    ],
    [
      "!!!!!!!!!!!!!!!!",
      "!!!!!!!!!!!!!!!!",
      "!!!!!!!!G!!!!!!!",
      "!!!!!!!!!!!!!!!!",
      "$$$!!!!!!!!!!!!!",
      "!!!$$!!!!!!!!!!!",
      "!!!!!$!!!!!!!!!!",
      "!!!!!$!!!!!!!!!!",
      "!!!!!!$!!!!!!!!!",
      "!!!!!!$!!!!!!!!!",
      "!!!!!!$!!!!!!!!!",
      "!!!!!!$!!!!!!!!!",
      "!!!!!$!!!!!!!!!!",
      "!!!!!$!!!!!!!!!!",
      "!!!$$!!!!!!!!!!!",
      "$$$!!!!!!!!!!!!!"
    ],
    [
      "       !!       ",
      " !AA! !!!! !AA! ",
      " B  B  !G  B  B ",
      "!!!!B      B  B ",
      "$$$!!      !AA! ",
      "   $$!          ",
      " !   $!       ! ",
      "!!!  $!!     !!!",
      "!!!   $!     !!!",
      " !    $!      ! ",
      "      $!        ",
      " !AA! $!   !AA! ",
      " B  B$!!   B  B ",
      " B  B$!!!  B  B ",
      " !A$$!!!!! !AA! ",
      "$$$!!  !!       "
    ],
    [
      "                ",
      " )((*  !!  )((* ",
      " =  =   G  =  = ",
      "HIH =      =  = ",
      "$$$(,      +((, ",
      "   $$           ",
      "     $          ",
      " !   $        ! ",
      " !    $       ! ",
      "      $H        ",
      "      $I        ",
      " )((* $H   )((* ",
      " =  =$     =  = ",
      " =  =$     =  = ",
      " +($$  !!  +((, ",
      "$$$             "
    ],
    [
      "                ",
      " )((*  !!  )((* ",
      " =  =   G  =  = ",
      "HIH =      =  = ",
      "$$$(,      +((, ",
      "   $$           ",
      "     $          ",
      " !   $        ! ",
      " !    $       ! ",
      "      $H        ",
      "      $I        ",
      " )((* $H   )((* ",
      " =  =$     =  = ",
      " =  =$     =  = ",
      " +($$  !!  +((, ",
      "$$$             "
    ]
  ]
}