{
  "xsize": 16,
  "zsize": 16,
  "refpalette": "lostcities:offshore",
  "slices": [
    [
      "                ",
      "                ",
      "                ",
      "                ",
      "                ",
      "                ",
      "                ",
      "                ",
      " !        !!  !!",
      " !''''''''!!!!!!",
      " !        !!  !!",
      "!!!((((((((((33*",
      "!!!          9<5",
      " %!          +65",
      " %             =",
      " %             ="
    ],
    [
      "                ",
      "                ",
      "                ",
      "                ",
      "                ",
      "                ",
      "                ",
      "                ",
      " !        !!  !!",
      " !''''''''!!!!!!",
      " !        !!  !!",
      "!!!             ",
      "!!!          )* ",
      " %!          +, ",
      " %              ",
      " %              "
    ],
    [
      "                ",
      "                ",
      "                ",
      "                ",
      "                ",
      "                ",
      "                ",
      "                ",
      "!!        !!  !!",
      " !''''''''!!!!!!",
      " !        !!  !!",
      "!!!             ",
      "!!!          )* ",
      " %!          +, ",
      " %              ",
      " %              "
    ],
    [
      "                ",
      "                ",
      "                ",
      "                ",
      "                ",
      "                ",
      "                ",
      "                ",
      "&!        !!  !!",
      " !''''''''!!!!!!",
      " !        !!  !!",
      "!!!             ",
      "!!!          )* ",
      " %!          +, ",
      " %              ",
      " %              "
    ],
    [
      "                ",
      "                ",
      "                ",
      "                ",
      "                ",
      "                ",
      "                ",
      "                ",
      "&!!!!!!!!!!!  !!",
      "!!!!!!!!!!!!!!!!",
      "!!!!!!!!!!!!!!!!",
      "!!!             ",
      "!!!          )* ",
      "!!!          +, ",
      "!!!             ",
      "!!!             "
    ],
    [
      "                ",
      "                ",
      "                ",
      "                ",
      "                ",
      "                ",
      "                ",
      "                ",
      "!!!!!!!!!!!!  !!",
      "!!!!!!!!!!!!!!!!",
      "!!!!!!!!!!!!!!!!",
      "!!!             ",
      "!!!          )* ",
      "!!!          +, ",
      "!!!             ",
      "!!!             "
    ]
  ]
}