{
  "xsize": 16,
  "zsize": 16,
  "refpalette": "lostcities:offshore",
  "slices": [
    [
      "                ",
      "                ",
      "                ",
      "                ",
      "       PPbc     ",
      "                ",
      "                ",
      "                ",
      "                ",
      "                ",
      "       PPbc     ",
      "                ",
      "                ",
      "                ",
      "                ",
      "                "
    ],
    [
      "                ",
      "                ",
      "                ",
      "                ",
      "       MPPP     ",
      "                ",
      "                ",
      "                ",
      "                ",
      "                ",
      "       MPPP     ",
      "                ",
      "                ",
      "                ",
      "                ",
      "                "
    ],
    [
      "!!!!!!!!!!!$$   ",
      "!!!!!!!!!!!$$   ",
      "!!!!!!!!!!!$$   ",
      "!!!!!!!!!!!$$   ",
      "!!!!!!!!!!!$$   ",
      "!!!!!!!!!!!$$   ",
      "!!!!!!!!!!!$$   ",
      "!!!!!!!!!!!$$   ",
      "!!!!!!!!!!!$$   ",
      "!!!!!!!!!!!$$   ",
      "!!!!!!!!!!!$$   ",
      "!!!!!!!!!!!$$   ",
      "!!!!!!!!!!!$$   ",
      "!!!!!!!!!!!$$   ",
      "!!!!!!!!!!!$$   ",
      "!!!!!!!!!!!$$   "
    ],
    [
      "                ",
      "                ",
      "                ",
      "                ",
      "                ",
      " J              ",
      "                ",
      "                ",
      "                ",
      " J              ",
      "                ",
      "                ",
      "                ",
      "                ",
      "                ",
      "                "
    ],
    [
      "                ",
      "                ",
      "                ",
      "                ",
      "                ",
      " K              ",
      "                ",
      "                ",
      "                ",
      " K              ",
      "                ",
      "                ",
      "                ",
      "                ",
      "                ",
      "                "
    ],
    [
      "                ",
      "                ",
      "                ",
      "                ",
      "                ",
      " K              ",
      "                ",
      "                ",
      "                ",
      " K              ",
      "                ",
      "                ",
      "                ",
      "                ",
      "                ",
      "                "
    ]
  ]
}