{
  "xsize": 16,
  "zsize": 16,
  "refpalette": "lostcities:offshore",
  "slices": [
    [
      "                ",
      "                ",
      "                ",
      "                ",
      "                ",
      "                ",
      "                ",
      "                ",
      "                ",
      "                ",
      "                ",
      "                ",
      " D$$$D  D$$$D  D",
      " $$$$$  $$$$$  $",
      " $   $  $   $  $",
      " $   $  $   $  $"
    ],
    [
      "                ",
      "                ",
      "                ",
      "                ",
      "                ",
      "                ",
      "                ",
      "                ",
      "                ",
      "                ",
      "                ",
      "                ",
      " D$$$D  D$$$D  D",
      " $DDD$  $DDD$  $",
      " $DDD$  $DDD$  $",
      " $DDD$  $DDD$  $"
    ],
    [
      "                ",
      "                ",
      "                ",
      "                ",
      "                ",
      "                ",
      "                ",
      "                ",
      "                ",
      "                ",
      "                ",
      "                ",
      " DDDDD  DDDDD  D",
      " DDDDD  DDDDD  D",
      " DDDDD  DDDDD  D",
      " DDDDD  DDDDD  D"
    ],
    [
      "                ",
      "                ",
      "                ",
      "                ",
      "                ",
      "                ",
      "                ",
      "                ",
      "                ",
      "                ",
      "                ",
      "                ",
      " &   &  &   &  &",
      "                ",
      "                ",
      "                "
    ],
    [
      "                ",
      "                ",
      "                ",
      "                ",
      "                ",
      "                ",
      "                ",
      "                ",
      "                ",
      "                ",
      "                ",
      "                ",
      " DDDDD  DDDDD  D",
      " DDDDD  DDDDD  D",
      " DDDDD  DDDDD  D",
      " DDDDD  DDDDD  D"
    ],
    [
      "                ",
      "                ",
      "                ",
      "                ",
      "                ",
      "                ",
      "                ",
      "                ",
      "                ",
      "                ",
      "                ",
      "                ",
      " D$$$D  D$$$D  D",
      " $EE$$  $EE$$  $",
      " $EE $  $EE $  $",
      " $   $  $   $  $"
    ]
  ]
}