{
  "xsize": 16,
  "zsize": 16,
  "refpalette": "lostcities:offshore",
  "slices": [
    [
      "     m          ",
      "     m          ",
      "     m          ",
      "     m          ",
      "     m          ",
      "     m          ",
      "    m           ",
      "    m !         ",
      "   m            ",
      "   m            ",
      "  m             ",
      " m !            ",
      "m               ",
      "                ",
      "                ",
      "                "
    ],
    [
      "     m!         ",
      "     m!         ",
      "     m!         ",
      "     m!         ",
      "     m!         ",
      "     m!         ",
      "    m!          ",
      "    m!!         ",
      "   m!           ",
      "   m!           ",
      "  m!            ",
      " m!!            ",
      "m!!             ",
      "!               ",
      "                ",
      "                "
    ],
    [
      "     m!         ",
      "     m!         ",
      "     m!         ",
      "     m!         ",
      "     m!         ",
      "     m!         ",
      "    m!          ",
      "    m!!         ",
      "   m!           ",
      "   m!           ",
      "  m!            ",
      " m!!            ",
      "m!!             ",
      "!               ",
      "                ",
      "                "
    ],
    [
      "mmmmmm          ",
      "mmmmmm          ",
      "mmmmmm          ",
      "mmmmmm          ",
      "mmmmmm          ",
      "mmmmmm          ",
      "mmmmm           ",
      "mmmmm           ",
      "mmmm            ",
      "mmmm            ",
      "mmm             ",
      "mm              ",
      "m               ",
      "                ",
      "                ",
      "                "
    ],
    [
      "mmmmm           ",
      "mmmmm           ",
      "mmmmm           ",
      "mmmmm           ",
      "mmmmm           ",
      "mmmm            ",
      "mmmm            ",
      "mmmm            ",
      "mmm             ",
      "mm              ",
      "m               ",
      "                ",
      "                ",
      "                ",
      "                ",
      "                "
    ],
    [
      "mmmm            ",
      "mmmm            ",
      "mmmm            ",
      "mmmm            ",
      "mmmm            ",
      "mmm             ",
      "mmm             ",
      "mmm             ",
      "mm              ",
      "m               ",
      "                ",
      "                ",
      "                ",
      "                ",
      "                ",
      "                "
    ]
  ]
}