{
  "xsize": 16,
  "zsize": 16,
  "refpalette": "lostcities:offshore",
  "slices": [
    [
      "                ",
      "  )((*  !!  )((*",
      "  =  =      =  =",
      "  =  =      =  =",
      "  +((,      +((,",
      "                ",
      "                ",
      "  !            !",
      "  !            !",
      "                ",
      "                ",
      "  )((*      )((*",
      "  =  =      =  =",
      "  =  =      =  =",
      "  +((,  !!  +((,",
      "                "
    ],
    [
      "        !!      ",
      "  !AA! !!!! !AA!",
      "  B  B  !!  B  B",
      "  B  B      B  B",
      "  !AA!      !AA!",
      "                ",
      "  !            !",
      "!!!!          !!",
      "!!!!          !!",
      "  !            !",
      "                ",
      "  !AA!      !AA!",
      "  B  B      B  B",
      "  B  B  !!  B  B",
      "  !AA! !!!! !AA!",
      "        !!      "
    ],
    [
      "$$$$$$$$$$$$$$$$",
      "$$$$$$$$$$$$$$$$",
      "$$$$$$$$$$$$$$$$",
      "$$$$$$$$$$$$$$$$",
      "$$$$$$$$$$$$$$$$",
      "$$$$$$$$$$$$$$$$",
      "$$$$$$$$$$$$$$$$",
      "$$$$$$$$$$$$$$$$",
      "$$$$$$$$$$$$$$$$",
      "$$$$$$$$$$$$$$$$",
      "$$$$$$$$$$$$$$$$",
      "$$$$$$$$$$$$$$$$",
      "$$$$$$$$$$$$$$$$",
      "$$$$$$$$$$$$$$$$",
      "$$$$$$$$$$$$$$$$",
      "$$$$$$$$$$$$$$$$"
    ],
    [
      " &   &  &   &  &",
      "                ",
      "                ",
      " &   &  &   &  &",
      "                ",
      "                ",
      "                ",
      " &   &  &   &  &",
      "                ",
      "                ",
      " &   &  &   &  &",
      "                ",
      "                ",
      "                ",
      " &   &  &   &  &",
      "                "
    ],
    [
      " DDDDD  DDDDD  D",
      "                ",
      "                ",
      " DDDDD  DDDDD  D",
      " DDDDD  DDDDD  D",
      " DDDDD  DDDDD  D",
      " DDDDD  DDDDD  D",
      " DDDDD  DDDDD  D",
      "                ",
      "                ",
      " DDDDD  DDDDD  D",
      " DDDDD  DDDDD  D",
      " DDDDD  DDDDD  D",
      " DDDDD  DDDDD  D",
      " DDDDD  DDDDD  D",
      "                "
    ],
    [
      " D$$$D  D$$$D  D",
      "                ",
      "                ",
      " D$$$D  D$$$D  D",
      " $EE $  $EE $  $",
      " $   $  $   $  $",
      " $   $  $   $  $",
      " D$$$D  D$$$D  D",
      "                ",
      "                ",
      " D$$$D  D$$$D  D",
      " $EE$$  $EE$$  $",
      " $EE $  $EE $  $",
      " $   $  $   $  $",
      " D$$$D  D$$$D  D",
      "                "
    ]
  ]
}