{
  "xsize": 16,
  "zsize": 16,
  "refpalette": "lostcities:offshore",
  "slices": [
    [
      "                ",
      "             A! ",
      "              B ",
      "              B ",
      "       PPbc  A! ",
      "                ",
      "              ! ",
      "             !!!",
      "             !!!",
      "              ! ",
      "       PPbc     ",
      "             A! ",
      "              B ",
      "              B ",
      "             A! ",
      "                "
    ],
    [
      "      .      !!!",
      "      .      !!!",
      "      .      !!!",
      "      .      !!!",
      "       MPPP  !!!",
      "             !!!",
      "             !!!",
      "             !!!",
      "             !!!",
      "             !!!",
      "       MPPP  !!!",
      "             !!!",
      "             !!!",
      "             !!!",
      "             !!!",
      "             !!!"
    ],
    [
      "!!!!!!!!!!!$$   ",
      "!!!!!!!!!!!$$   ",
      "!!!!!!!!!!!$$   ",
      "!!!!!!!!!!!$$   ",
      "!!!!!!!!!!!$$   ",
      "!!!!!!!!!!!$$   ",
      "!!!!!!!!!!!$$   ",
      "!!!!!!!!!!!$$   ",
      "!!!!!!!!!!!$$   ",
      "!!!!!!!!!!!$$   ",
      "!!!!!!!!!!!$$   ",
      "!!!!!!!!!!!$$   ",
      "!!!!!!!!!!!$$   ",
      "!!!!!!!!!!!$$   ",
      "!!!!!!!!!!!$$   ",
      "!!!!!!!!!!!$$   "
    ],
    [
      "     ..         ",
      "      .         ",
      "      .         ",
      "     ...        ",
      "      .         ",
      " J              ",
      "                ",
      "                ",
      "                ",
      " J              ",
      "                ",
      "                ",
      "                ",
      "                ",
      "                ",
      "                "
    ],
    [
      "     .          ",
      "                ",
      "      .         ",
      "     ...        ",
      "     ..         ",
      " K              ",
      "                ",
      "                ",
      "                ",
      " K              ",
      "                ",
      "                ",
      "                ",
      "                ",
      "                ",
      "                "
    ],
    [
      "    ..          ",
      "                ",
      "      .         ",
      "     ...        ",
      "    ....        ",
      " K   ..         ",
      "                ",
      "                ",
      "                ",
      " K              ",
      "                ",
      "                ",
      "                ",
      "                ",
      "                ",
      "                "
    ]
  ]
}