{
  "xsize": 16,
  "zsize": 16,
  "refpalette": "lostcities:offshore",
  "slices": [
    [
      "       !!       ",
      " !AA! !!!! !AA! ",
      " B  B  !!  B  B ",
      " B  B      B  B ",
      " !AA!      !AA! ",
      "                ",
      " !            ! ",
      "!!!          !!!",
      "!!!          !!!",
      " !            ! ",
      "                ",
      " !AA!      !AA! ",
      " B  B      B  B ",
      " B  B  !!  B  B ",
      " !AA! !!!! !AA! ",
      "       !!       "
    ],
    [
      "$$!!!!!!!!!!!!!!",
      "$$!!!!!!!!!!!!!!",
      "$$!!!!!!!!!!!!!!",
      "$$!!!!!!!!!!!!!!",
      "$$!!!!!!!!!!!!!!",
      "$$!!!!!!!!!!!!!!",
      "$$!!!!!!!!!!!!!!",
      "$$!!!!!!!!!!!!!!",
      "$$!!!!!!!!!!!!!!",
      "$$!!!!!!!!!!!!!!",
      "$$!!!!!!!!!!!!!!",
      "$$!!!!!!!!!!!!!!",
      "$$!!!!!!!!!!!!!!",
      "$$!!!!!!!!!!!!!!",
      "$$!!!!!!!!!!!!!!",
      "$$!!!!!!!!!!!!!!"
    ],
    [
      "!!!!!!!!!!!!!!! ",
      "!!!!!!!!!E!!!!! ",
      "!!!!!!!!!E!!!!! ",
      "!!!!!!!E!E!!!!! ",
      "!!!!!!!!!i!!!!! ",
      "!!!!!!!jkI!!!!! ",
      "!!!!!!!!!!!!!!! ",
      "!!!!!!!!!!!!!!! ",
      "!!!!!!!!!!!!!!! ",
      "!!!!!!!!!!!!!!! ",
      "!!!!!!!!!!!!!!! ",
      "                ",
      "                ",
      "                ",
      "                ",
      "                "
    ],
    [
      " !!E!!!!!!!!    ",
      " !!E!!h!!!!!    ",
      "  !E!!!!!!E!    ",
      " !!E!!=!!!!!    ",
      ".!!E!!!!!!!!    ",
      "..!E!!!!!!E!    ",
      ".!!E!!E!!E!!    ",
      "!!!!!!!!!!!!    ",
      "&&          &&& ",
      "!&          &!& ",
      "&&          &&& ",
      "                ",
      "                ",
      "                ",
      "                ",
      "                "
    ],
    [
      " EEEEE EE EE    ",
      " EEEEE EE EE    ",
      "   E  )(* E     ",
      " EEEEE=EE EE    ",
      ".EEEEE+EE EE    ",
      ".. E      E     ",
      ".EEEEEEEEEEE    ",
      " EE EE EE EE    ",
      "&            &  ",
      "!&          &!& ",
      "&            &  ",
      "                ",
      "                ",
      "                ",
      "                ",
      "                "
    ],
    [
      " EEEEE!EE!EE    ",
      " EEEEE!EEIEE    ",
      "  !E!!)(*lE!    ",
      " EEEEE=EE!EE    ",
      ".EEEEEgEE!EE    ",
      "..!E!!!!!!E!    ",
      ".EEEEEEEEEEE    ",
      " EE!EE!EE!EE    ",
      "                ",
      "!            !  ",
      "                ",
      "                ",
      "                ",
      "                ",
      "                ",
      "                "
    ]
  ]
}