{
  "xsize": 16,
  "zsize": 16,
  "refpalette": "lostcities:offshore",
  "slices": [
    [
      "                ",
      "                ",
      "                ",
      "                ",
      "                ",
      "                ",
      "                ",
      "                ",
      "                ",
      "                ",
      "                ",
      "      .         ",
      "     ...        ",
      "      .         ",
      "                ",
      "                "
    ],
    [
      "                ",
      "                ",
      "                ",
      "                ",
      "                ",
      "                ",
      "                ",
      "                ",
      "                ",
      "                ",
      "                ",
      "      .         ",
      "     ...        ",
      "      .         ",
      "                ",
      "                "
    ],
    [
      "                ",
      "                ",
      "                ",
      "                ",
      "                ",
      "                ",
      "                ",
      "                ",
      "                ",
      "                ",
      "                ",
      "      .         ",
      "     ...        ",
      "      .         ",
      "                ",
      "                "
    ],
    [
      "!!!!!!!!!!!!!!!!",
      "!!!!!!!!!!!!!!!!",
      "          !!!!!!",
      "          !!!!!!",
      "          !!!!!!",
      "          !!!!!!",
      "          !!!!!!",
      "          #!!!!!",
      "          !##!!!",
      "          !!!#!!",
      "          !!!!#!",
      "      .   !!!!#!",
      "#!!!!!!!!!!!!!!#",
      "#!!!!!!!!!!!!!!#",
      "#!!!!!!!!!!!!!!#",
      "#!!!!!!!!!!!!!!#"
    ],
    [
      "       !!!      ",
      " !AA!!!!!!!!AA!!",
      "           BB BB",
      "           BB BB",
      "           !AA!!",
      "                ",
      "              !!",
      "          ## !!!",
      "           ##!!!",
      "             #!!",
      "              ##",
      "      .    !AA##",
      "#BB BB..   BB B#",
      "#BB BB.!!! BB B#",
      "#!AA!!!!!!!!AA!#",
      "##     !!!     #"
    ],
    [
      "                ",
      " )((** !!! )((**",
      "           == ==",
      "           == ==",
      "           +((,,",
      "                ",
      "                ",
      "          ##  !!",
      "           ###!!",
      "             ## ",
      "              ##",
      "      .    )((##",
      "#== ==..   == =#",
      "#== ==.    == =#",
      "#+((,, !!! +((,#",
      "##             #"
    ]
  ]
}