{
  "xsize": 16,
  "zsize": 16,
  "refpalette": "lostcities:offshore",
  "slices": [
    [
      "EE EE  D$$$D  D$",
      "EE EE  $DDD$  $D",
      "       $DDD$  $D",
      "EE EE  $DDD$  $D",
      "EE EE  D$$$D  D$",
      "                ",
      "                ",
      "EE EE  D$$$D  D$",
      "EE EE  $DDD$  $D",
      "       $DDD$  $D",
      "EE EE  $DDD$  $D",
      "EE EE  D$$$D  D$",
      "                ",
      "                ",
      "                ",
      "                "
    ],
    [
      "EE EE  DDDDD  DD",
      "EE EE  DDDDD  DD",
      "       DDDDD  DD",
      "EE EE  DDDDD  DD",
      "EE EE  DDDDD  DD",
      "                ",
      "                ",
      "EE EE  DDDDD  DD",
      "EE EE  DDDDD  DD",
      "       DDDDD  DD",
      "EE EE  DDDDD  DD",
      "EE EE  DDDDD  DD",
      "                ",
      "                ",
      "                ",
      "                "
    ],
    [
      "       &   &  & ",
      "                ",
      "                ",
      "                ",
      "       &   &  & ",
      "                ",
      "                ",
      "       &   &  & ",
      "                ",
      "                ",
      "                ",
      "       &   &  & ",
      "                ",
      "                ",
      "                ",
      "                "
    ],
    [
      "       DDDDD  DD",
      "       DDDDD  DD",
      "       DDDDD  DD",
      "       DDDDD  DD",
      "       DDDDD  DD",
      "                ",
      "                ",
      "       DDDDD  DD",
      "       DDDDD  DD",
      "       DDDDD  DD",
      "       DDDDD  DD",
      "       DDDDD  DD",
      "                ",
      "                ",
      "                ",
      "                "
    ],
    [
      "       D$$$D  D$",
      "       $$  $  $ ",
      "       $EE $  $E",
      "       $EE $  $E",
      "       D$$$D  D$",
      "                ",
      "                ",
      "       D$$$D  D$",
      "       $$  $  $ ",
      "       $EE $  $E",
      "       $EE $  $E",
      "       D$$$D  D$",
      "                ",
      "                ",
      "                ",
      "                "
    ],
    [
      "       D$$$D  D$",
      "       $$  $  $ ",
      "       $$  $  $ ",
      "       $$  $  $ ",
      "       D$$$D  D$",
      "                ",
      "                ",
      "       D$$$D  D$",
      "       $$  $  $ ",
      "       $$  $  $ ",
      "       $$  $  $ ",
      "       D$$$D  D$",
      "                ",
      "                ",
      "                ",
      "                "
    ]
  ]
}