{
  "xsize": 16,
  "zsize": 16,
  "refpalette": "lostcities:offshore",
  "slices": [
    [
      "!!!!!!!!!!!!!   ",
      "!!!!!!!!!!!!!   ",
      "!!!!!!!!!!!!!   ",
      "!!!!!!!!!!!!!   ",
      "!!!!!!!!!!!!!   ",
      "!!o! ! !!!!!!.  ",
      "!!p!!! !!!!!!   ",
      "!!I!!   !!!!!   ",
      "!!!!!!!!!!!!!   ",
      "!!!!!!!!!!!!!   ",
      "!!!!!!!!!!!!!   ",
      "!!!!!!!!!!!!!   ",
      "!!!!!!!!!!!!!   ",
      "                ",
      "                ",
      "                "
    ],
    [
      "!!!!!!!!!!!#!   ",
      "!!!!!!!!!!!#!   ",
      "!!!!!!!!!!!#!   ",
      "!!!!!!!!!!!#!   ",
      "!!!!!!!!!!!#!.  ",
      "!!!!!!!!!!!#!.  ",
      "!!!!!!!!!!!#!   ",
      "!!!     !!!#!   ",
      "!!!!!!!!!!!#!   ",
      "!!!!!!!!!!!#!   ",
      "!!!!!!!!!!&&&   ",
      "##########&!&   ",
      "!!!!!!!!!!&&&   ",
      "                ",
      "                ",
      "                "
    ],
    [
      "     ...   #    ",
      "      .    #    ",
      "           #    ",
      "           #.   ",
      "          .#..  ",
      "     =     #.   ",
      "     ,     #    ",
      "        !  #    ",
      "           #    ",
      "           #    ",
      "           &    ",
      "##########&!&   ",
      "           &    ",
      "                ",
      "                ",
      "                "
    ],
    [
      "      .    #    ",
      "           #    ",
      "                ",
      "           ..   ",
      "          ...   ",
      "     =     .    ",
      "     ,          ",
      "      !!        ",
      "           #    ",
      "           #    ",
      "                ",
      "# # # # ## !    ",
      "                ",
      "                ",
      "                ",
      "                "
    ],
    [
      "           #    ",
      "           #    ",
      "           #.   ",
      "           #..  ",
      "          .#..  ",
      "     =     #.   ",
      "     5     #    ",
      "     !!    #    ",
      "           #    ",
      "           #    ",
      "                ",
      "# # # # ## !    ",
      "                ",
      "                ",
      "                ",
      "                "
    ],
    [
      "        .. #    ",
      "        .  #    ",
      ".      ..  #.   ",
      "..   ......#..  ",
      "......     #.   ",
      " ..  =     #    ",
      "     5     #    ",
      "  q!!!     #    ",
      "           #    ",
      "           #    ",
      "           &    ",
      "##########&!&   ",
      "           &    ",
      "                ",
      "                ",
      "                "
    ]
  ]
}