{
  "xsize": 16,
  "zsize": 16,
  "refpalette": "lostcities:offshore",
  "slices": [
    [
      "                ",
      "                ",
      "                ",
      "                ",
      "                ",
      "                ",
      "                ",
      "                ",
      "                ",
      "                ",
      "                ",
      "                ",
      "                ",
      "                ",
      "                ",
      "                "
    ],
    [
      "                ",
      "                ",
      "                ",
      "                ",
      "                ",
      "                ",
      "                ",
      "                ",
      "                ",
      "                ",
      "                ",
      "                ",
      "                ",
      "                ",
      "                ",
      "                "
    ],
    [
      "                ",
      "                ",
      "                ",
      "                ",
      "                ",
      "                ",
      "                ",
      "                ",
      "                ",
      "                ",
      "                ",
      "                ",
      "                ",
      "                ",
      "                ",
      "                "
    ],
    [
      "#!!!!!!!!!!!!!!#",
      "#!!!!!!!!!!!!!!#",
      "!#!!!!!!!!!!!!#!",
      "!#!!!!!!!!!!!!#!",
      "!!#!!!!!!!!!!#!!",
      "!!!##!!!!!!##!!!",
      "!!!!!######!!!!!",
      "!!!!!!!!!!!!!!!!",
      "!!!!!!!!!!!!!!!!",
      "!!!!!!!!!!!!!!!!",
      "!!!!!!!!!!!!!!!!",
      "!!!!!!!!!!!!!!!!",
      "!!!!!!!!!!!!!!!!",
      "!!!!!!!!!!!!!!!!",
      "!!!!!!!!!!!!!!!!",
      "!!!!!!!!!!!!!!!!"
    ],
    [
      "##     !!!     #",
      "#!AA!!!!!!!!AA!#",
      " ## BB !!! BB ##",
      " ## BB     BB ##",
      " !#A!!     !A#!!",
      "   ###     ###  ",
      " !!  #######  !!",
      "!!!!         !!!",
      "!!!!         !!!",
      " !!           !!",
      "                ",
      " !AA!!     !AA!!",
      " BB BB     BB BB",
      " BB BB !!! BB BB",
      " !AA!!!!!!!!AA!!",
      "        !!      "
    ],
    [
      "##             #",
      "#)((** !!! )((*#",
      " ## ==     == ##",
      " ## ==     == ##",
      " +#(,,     +(#,,",
      "   ###     ###  ",
      "     #######    ",
      " !!           !!",
      " !!           !!",
      "                ",
      "                ",
      " )((**     )((**",
      " == ==     == ==",
      " == ==     == ==",
      " +((,, !!! +((,,",
      "                "
    ]
  ]
}