{
  "xsize": 16,
  "zsize": 16,
  "refpalette": "lostcities:offshore",
  "slices": [
    [
      " %              ",
      " %              ",
      " %              ",
      " %!          )* ",
      "!!!          +, ",
      "!!!             ",
      " !        !!  !!",
      " !--------!!!!!!",
      "!!        !!  !!",
      "                ",
      "                ",
      "                ",
      "                ",
      "                ",
      "                ",
      "                "
    ],
    [
      " %              ",
      " %              ",
      " %              ",
      " %!          )* ",
      "!!!          +, ",
      "!!!             ",
      " !        !!  !!",
      " !--------!!!!!!",
      " !        !!  !!",
      "                ",
      "                ",
      "                ",
      "                ",
      "                ",
      "                ",
      "                "
    ],
    [
      " %              ",
      " %              ",
      " %              ",
      " %!          )* ",
      "!!!          +, ",
      "!!!             ",
      " !        !!  !!",
      " !--------!!!!!!",
      " !        !!  !!",
      "                ",
      "                ",
      "                ",
      "                ",
      "                ",
      "                ",
      "                "
    ],
    [
      " %              ",
      " %              ",
      " %              ",
      " %!          )* ",
      "!!!          +, ",
      "!!!             ",
      " !        !!  !!",
      " !--------!!!!!!",
      "!!        !!  !!",
      "                ",
      "                ",
      "                ",
      "                ",
      "                ",
      "                ",
      "                "
    ],
    [
      " %              ",
      " %              ",
      " %              ",
      " %!          $$ ",
      "!!!          $$ ",
      "!!!             ",
      " !        !!  !!",
      " !--------!!!!!!",
      "7!        !!  !!",
      "                ",
      "                ",
      "                ",
      "                ",
      "                ",
      "                ",
      "                "
    ],
    [
      " %           $$5",
      " %           $$5",
      " %           $$5",
      " %!$$$$$$$$$$$$5",
      "!!!$$$$$$$$$$$$5",
      "!!!666666666666,",
      " !        !!  !!",
      " !--------!!!!!!",
      " !        !!  !!",
      "                ",
      "                ",
      "                ",
      "                ",
      "                ",
      "                ",
      "                "
    ]
  ]
}