{
  "xsize": 16,
  "zsize": 16,
  "refpalette": "lostcities:offshore",
  "slices": [
    [
      "                ",
      "                ",
      "                ",
      "                ",
      "                ",
      "                ",
      "                ",
      "                ",
      "!!  !!        !!",
      "!!!!!!''''''''! ",
      "!!  !!        ! ",
      "             !!!",
      " )*          !!!",
      " +,          !/ ",
      "              / ",
      "              / "
    ],
    [
      "                ",
      "                ",
      "                ",
      "                ",
      "                ",
      "                ",
      "                ",
      "                ",
      "!!  !!        ! ",
      "!!!!!!''''''''! ",
      "!!  !!        ! ",
      "             !!!",
      " )*          !!!",
      " +,          !/ ",
      "              / ",
      "              / "
    ],
    [
      "                ",
      "                ",
      "                ",
      "                ",
      "                ",
      "                ",
      "                ",
      "                ",
      "!!  !!        ! ",
      "!!!!!!''''''''! ",
      "!!  !!        ! ",
      "             !!!",
      " )*          !!!",
      " +,          !/ ",
      "              / ",
      "              / "
    ],
    [
      "                ",
      "                ",
      "                ",
      "                ",
      "                ",
      "                ",
      "                ",
      "                ",
      "!!  !!        !!",
      "!!!!!!''''''''! ",
      "!!  !!        ! ",
      "             !!!",
      " )*          !!!",
      " +,          !/ ",
      "              / ",
      "              / "
    ],
    [
      "                ",
      "                ",
      "                ",
      "                ",
      "                ",
      "                ",
      "                ",
      "                ",
      "!!  !!        !8",
      "!!!!!!''''''''! ",
      "!!  !!        ! ",
      "             !!!",
      " $$          !!!",
      " $$          !/ ",
      "              / ",
      "              / "
    ],
    [
      "                ",
      "                ",
      "                ",
      "                ",
      "                ",
      "                ",
      "                ",
      "                ",
      "!!  !!        ! ",
      "!!!!!!''''''''! ",
      "!!  !!        ! ",
      ")333333333333!!!",
      "9$$$$$$$$$$$$!!!",
      "9$$$$$$$$$$$$!/ ",
      "9$$           / ",
      "9$$           / "
    ]
  ]
}