{
  "xsize": 16,
  "zsize": 16,
  "refpalette": "lostcities:offshore",
  "slices": [
    [
      "       !!       ",
      " !AA! !!!! !AA! ",
      " B  B  !!  B  B ",
      " B  B     .B  B ",
      " !AA!   ...!AA! ",
      "       ..       ",
      " !    ..      ! ",
      "!!!   .      !!!",
      "!!!  ..      !!!",
      " !   .        ! ",
      "     ..         ",
      " !AA!      !AA! ",
      " B  B      B  B ",
      " B  B  !!  B  B ",
      " !AA! !!!! !AA! ",
      "       !!       "
    ],
    [
      "!!!!!!!!!!!!!!!!",
      "!!!!!!!!!!!!!!!!",
      "!!!!!!!!!!!!!!!!",
      "!!!!!!!!!!!!!!!!",
      "!!!!!!!!!!!!!!!!",
      "!!!!!!!!!!!!!!!!",
      "!!!!!!!!!!!!!!!!",
      "!!!!!!!!!!!!!!!!",
      "!!!!!!!!!!!!!!!!",
      "!!!!!!!!!!!!!!!!",
      "!!!!!!!!!!!!!!!!",
      "!!!!!!!!!!!!!!!!",
      "!!!!!!!!!!!!!!!!",
      "!!!!!!!!!!!!!!!!",
      "!!!!!!!!!!!!!!!!",
      "!!!!!!!!!!!!!!!!"
    ],
    [
      "         B  B   ",
      "         !AA!   ",
      "           .    ",
      "          ...!  ",
      "        .... !  ",
      "       ..       ",
      "      ..        ",
      "      .         ",
      "     ..  !AA!   ",
      "     .   B  B   ",
      "     ..  B  B   ",
      "         !AA!   ",
      "                ",
      "                ",
      "                ",
      "                "
    ],
    [
      "         =  =   ",
      "         +((,   ",
      "           .    ",
      "          ...   ",
      "          ...!  ",
      "           . !  ",
      "                ",
      "                ",
      "         )((*   ",
      "         =  =   ",
      "         =  =   ",
      "         +((,   ",
      "                ",
      "                ",
      "                ",
      "                "
    ],
    [
      "         g  g   ",
      "          ?>    ",
      "                ",
      "          ..    ",
      "         ....   ",
      "          .. !  ",
      "             !  ",
      "                ",
      "          ?>    ",
      "         f  f   ",
      "         g  g   ",
      "          ?>    ",
      "                ",
      "                ",
      "                ",
      "                "
    ],
    [
      "         =  =   ",
      "         +((,   ",
      "                ",
      "          .     ",
      "         ...    ",
      "          .     ",
      "             !  ",
      "             !  ",
      "         )((*   ",
      "         =  =   ",
      "         =  =   ",
      "         +((,   ",
      "                ",
      "                ",
      "                ",
      "                "
    ]
  ]
}