{
  "xsize": 16,
  "zsize": 16,
  "refpalette": "lostcities:offshore",
  "slices": [
    [
      "                ",
      "                ",
      "    G    G      ",
      "                ",
      "               $",
      "$            $$ ",
      " $          $   ",
      " $          $   ",
      "  $       H$    ",
      "  $H     !I$    ",
      "  $I    !!H$!   ",
      "  $H     !!$    ",
      " $        ! $   ",
      " $          $  #",
      "$            $$!",
      "             #!$"
    ],
    [
      "                ",
      "                ",
      "    G    G      ",
      "                ",
      "               $",
      "$            $$ ",
      " $          $   ",
      " $          $   ",
      "  $       H$    ",
      "  $H     !I$    ",
      "  $I    !!H$!   ",
      "  $H     !!$!!!!",
      " $        !!$!!!",
      " $         !$!! ",
      "$          !!$$!",
      "           !! !$"
    ],
    [
      "                ",
      "                ",
      "    G    G      ",
      "              !!",
      "!            !!$",
      "$!          !$$ ",
      " $!        !$   ",
      " $!!      !!$   ",
      "  $!     !!$    ",
      "  $!    !!!$!   ",
      "  $!    !!!$!   ",
      "  $!    !!!$!   ",
      " $!!     !!!$   ",
      " $!        !$   ",
      "$!          !$$#",
      "!            !!$"
    ],
    [
      "                ",
      "                ",
      "    G    G      ",
      "              !!",
      "!            !!$",
      "$!          !$$ ",
      " $!        !$   ",
      " $!!      !!$   ",
      "  $!      !$    ",
      "  $!     !!$    ",
      "  $!    !!!$!   ",
      "  $!     !!$!   ",
      " $!!      !!$   ",
      " $!        !$   ",
      "$!          !$$!",
      "!            !!$"
    ],
    [
      "                ",
      "                ",
      "    G    G      ",
      "                ",
      "               $",
      "$            $$ ",
      " $          $   ",
      " $          $   ",
      "  $       H$    ",
      "  $H     !I$    ",
      "  $I    !!H$!   ",
      "  $H     !!$!   ",
      " $        ! $   ",
      " $          $   ",
      "$            $$!",
      "              !$"
    ],
    [
      "                ",
      "                ",
      "    G    G      ",
      "                ",
      "               $",
      "$            $$ ",
      " $          $   ",
      " $          $   ",
      "  $       H$    ",
      "  $H     !I$    ",
      "  $I    !!H$!!!!",
      "  $H     !!$    ",
      " $        ! $   ",
      " $        ! $   ",
      "$         !  $$!",
      "          !   !$"
    ]
  ]
}