{
  "xsize": 16,
  "zsize": 16,
  "refpalette": "lostcities:offshore",
  "slices": [
    [
      "                ",
      "                ",
      "                ",
      "                ",
      "   ! !!!!!!!! ! ",
      "   !!     .  !! ",
      " !!            !",
      "!               ",
      "                ",
      "  .             ",
      "  ...           ",
      "    .     .     ",
      "          .     ",
      "                ",
      "                ",
      "                "
    ],
    [
      "                ",
      "                ",
      "                ",
      "          .     ",
      "   ! !!!!!!!! ! ",
      "   !!mmmmmmmm!! ",
      ".!!mmmmmmmmmmmm!",
      "!mmmmmmmmmmmmmmm",
      "mmmmmmmmmmmmmmmm",
      "mmmmmmmmmmmmmmmm",
      "mmmmmmmmmmmmmmmm",
      "mmmmmmmmmmmmmmmm",
      "mmmmmmmmmmmmmmmm",
      "mmmmmmmmmmmmmmmm",
      "mmmmmmmmmmmmmmmm",
      "mmmmmmmmmmmmmmmm"
    ],
    [
      "                ",
      "                ",
      "                ",
      "                ",
      "   !      .   ! ",
      "     mmmmmmmm   ",
      ".  mm     .  mm ",
      ".mm            m",
      "m .             ",
      " ...      .     ",
      "  ...    ...    ",
      "   ...   ...    ",
      "    .    ...    ",
      "          .     ",
      "                ",
      "                "
    ],
    [
      "                ",
      "                ",
      "                ",
      "                ",
      "   !      .   ! ",
      "     mmmmmmmm   ",
      ".  mm     .  mm ",
      ".mm            m",
      "m...            ",
      " ....     .     ",
      "  ....   ...    ",
      "   ...   ...    ",
      "    .     .     ",
      "                ",
      "                ",
      "                "
    ],
    [
      "                ",
      "                ",
      "                ",
      "                ",
      "   !      .   ! ",
      "     mmmmmmmm   ",
      ".. mm     .  mm ",
      ".mm            m",
      "m...      .     ",
      " .. .    ...    ",
      "   ...   ...    ",
      "    .    ...    ",
      "          .     ",
      "                ",
      "                ",
      "                "
    ],
    [
      "                ",
      "                ",
      "                ",
      "                ",
      "   !      .   ! ",
      "       mmmmmm   ",
      " . mm     .  mm ",
      ".mm       .    m",
      "m..      ...    ",
      " .  .    ...    ",
      "   ...   ...    ",
      "    .     .     ",
      "                ",
      "                ",
      "                ",
      "                "
    ]
  ]
}