{
  "xsize": 16,
  "zsize": 16,
  "refpalette": "lostcities:base",
  "slices": [
    [
      "             Ͷ  ",
      "            Ͷ   ",
      "            Ͷ   ",
      "            Ͷ   ",
      "            Ͷ   ",
      "             Ͷ  ",
      "              ͶͶ",
      "                ",
      "               Ͷ",
      "              Ͷ ",
      "             Ͷ  ",
      "      ͶYYY  Ͷ   ",
      "       ͶͶY  Ͷ   ",
      " Ͷ      ͶYYͶ    ",
      "Ͷ        ͶYͶ    ",
      "Ͷ        ͶYͶ    "
    ],
    [
      "      ggg    Ͷ  ",
      "      ggg   Ͷ   ",
      "      ggg   Ͷ   ",
      "      ggg   Ͷ   ",
      "      ggg   Ͷ   ",
      "      ggg    Ͷ  ",
      "      ggg     ͶͶ",
      "      ggg       ",
      "      ggg      Ͷ",
      "      ggg     Ͷ ",
      "      ggg    Ͷ  ",
      "      ͶYYY  Ͷ   ",
      "       ͶͶY  Ͷ   ",
      " Ͷ      ͶYYͶ    ",
      "Ͷ        ͶYͶ    ",
      "Ͷ        ͶYͶ    "
    ],
    [
      "             Ͷ  ",
      "            Ͷ   ",
      "            Ͷ   ",
      "            Ͷ   ",
      "            Ͷ   ",
      "             Ͷ  ",
      "              ͶͶ",
      "                ",
      "               Ͷ",
      "              Ͷ ",
      "             Ͷ  ",
      "       YYY  Ͷ   ",
      "       ͶͶY  Ͷ   ",
      " Ͷ      ͶYYͶ    ",
      "Ͷ        ͶYͶ    ",
      "Ͷ        ͶYͶ    "
    ],
    [
      "             Ͷ  ",
      "            Ͷ   ",
      "            Ͷ   ",
      "            Ͷ   ",
      "            Ͷ   ",
      "             Ͷ  ",
      "              ͶͶ",
      "                ",
      "               Ͷ",
      "              Ͷ ",
      "             Ͷ  ",
      "        Y   Ͷ   ",
      "       ͶͶY  Ͷ   ",
      "        ͶY Ͷ    ",
      "Ͷ        ͶYͶ    ",
      "Ͷ        ͶYͶ    "
    ],
    [
      "             Ͷ  ",
      "            Ͷ   ",
      "            Ͷ   ",
      "            Ͷ   ",
      "            Ͷ   ",
      "             Ͷ  ",
      "              ͶͶ",
      "                ",
      "               Ͷ",
      "              Ͷ ",
      "             Ͷ  ",
      "            Ͷ   ",
      "      ͶͶY   Ͷ   ",
      "      ͶͶͶY Ͷ    ",
      "ͶͶ     ͶͶͶYͶ    ",
      "ͶͶ     ͶͶͶYͶ    "
    ],
    [
      "             Ͷ  ",
      "                ",
      "                ",
      "                ",
      "            Ͷ   ",
      "             Ͷ  ",
      "              ͶͶ",
      "                ",
      "               Ͷ",
      "              Ͷ ",
      "             Ͷ  ",
      "            Ͷ   ",
      "      ͶͶY   Ͷ   ",
      "   ͶͶͶͶͶͶY Ͷ    ",
      " Ͷ ͶͶͶͶͶͶͶYͶ    ",
      " ͶͶͶͶͶͶͶͶͶYͶ    "
    ]
  ]
}