{
  "xsize": 16,
  "zsize": 16,
  "refpalette": "lostcities:base",
  "slices": [
    [
      "vvvvvvvvvvvvvvvv",
      "vvvvvvvvvvvvvvvv",
      "vvvvvvvvvvvvvvvv",
      "vvvvvvvvvvvvvvvv",
      "vvvvvvvvvvvvvvvv",
      "vvvvvvvvvvvvv vv",
      "  vvvvvvvvv     ",
      "                ",
      "                ",
      "                ",
      "                ",
      "                ",
      "                ",
      "                ",
      "                ",
      "                "
    ],
    [
      "ffffffffffffffff",
      "ffffffffffffffff",
      "ffffffffffffffff",
      "ffffffffffffffff",
      "ffffffffffffffff",
      "ffffffffffffffff",
      "ffffffffffffffff",
      "ffffffffffffffff",
      "ffffffffffffffff",
      "ffffffffffffffff",
      "ffff   fffffffff",
      "ffff    ffffffff",
      "ffff   fffffffff",
      "fff     ffffffff",
      "                ",
      "                "
    ],
    [
      "                ",
      "                ",
      " n            n ",
      "                ",
      "                ",
      "       !        ",
      " n    !!!     n ",
      "       !        ",
      "                ",
      "                ",
      "                ",
      "                ",
      "                ",
      "fff       ffffff",
      "                ",
      "                "
    ],
    [
      "                ",
      "                ",
      "ʹʹ            ʹʹ",
      "ʹʹ            ʹʹ",
      "ʹʹ            ʹʹ",
      "ʹʹ     !      ʹʹ",
      "ʹʹ    !!!     ʹʹ",
      "      !!!       ",
      "       !        ",
      "                ",
      "                ",
      "                ",
      "                ",
      "fff        fffff",
      "                ",
      "                "
    ],
    [
      "                ",
      "                ",
      "fʹ            ʹf",
      " f            f ",
      "!f!           f ",
      " f            f ",
      "fʹ     !      ʹf",
      "      !!!       ",
      "       !        ",
      "                ",
      "                ",
      "                ",
      "                ",
      "fff        fffff",
      "                ",
      "                "
    ],
    [
      "                ",
      "                ",
      "fʹ            ʹf",
      " f            f ",
      "!f!           f ",
      "!f!           f ",
      "fʹ     !      ʹf",
      "      !!!       ",
      "       !        ",
      "                ",
      "                ",
      "                ",
      "!               ",
      "fff        fffff",
      "!               ",
      "                "
    ]
  ]
}