{
  "xsize": 16,
  "zsize": 16,
  "refpalette": "lostcities:base",
  "slices": [
    [
      "         !      ",
      "       f!!!!  f ",
      "ffffffffffffffff",
      "fffffff  !     f",
      "fffffff        f",
      "fffffff        f",
      "fffffff        f",
      "fffffff        f",
      "fffffff        f",
      "fffffff        f",
      "fffffff        f",
      "fffffff        f",
      "fffffff     !  f",
      "fffffff    !ffff",
      "           !!!f ",
      "            !   "
    ],
    [
      "                ",
      "       !!!      ",
      "ffffffffffffffff",
      "       !!!     f",
      "               f",
      "               f",
      "               f",
      "               f",
      "   !           f",
      "               f",
      "               f",
      "               f",
      "            !  f",
      "fffffff    fffff",
      "            !   ",
      "                "
    ],
    [
      "                ",
      "       !        ",
      "ffffffffffffffff",
      "       !    ffff",
      "              ff",
      "              ff",
      "              ff",
      "              ff",
      "   !          ff",
      "   !          ff",
      "              ff",
      "              ff",
      "            ffff",
      "ffffffffffffffff",
      "            !   ",
      "                "
    ],
    [
      "                ",
      "       !        ",
      "ffffffffff  f   ",
      "       !   ffff ",
      "              f ",
      "              f ",
      "              f ",
      "              f ",
      "              f ",
      "   !          f ",
      "              f ",
      "              f ",
      "           ffff ",
      "fffffffffffff!  ",
      "            !   ",
      "                "
    ],
    [
      "                ",
      "                ",
      "fffffffff       ",
      "           ffff ",
      "              f ",
      "              f ",
      "              f ",
      "              f ",
      "              f ",
      "   !          f ",
      "              f ",
      "            ! f ",
      "           ffff ",
      " fffffffffff!!  ",
      "           !!   ",
      "                "
    ],
    [
      "                ",
      "        !       ",
      "fffffffff!      ",
      "        !  ffff ",
      "             ff ",
      "             ff ",
      "             ff ",
      "             ff ",
      "             ff ",
      "   !         ff ",
      "             ff ",
      "            !ff ",
      "           ffff ",
      " ffffffffff!!   ",
      "                ",
      "                "
    ]
  ]
}