{
  "xsize": 16,
  "zsize": 16,
  "refpalette": "lostcities:base",
  "slices": [
    [
      "gggggggggggggggg",
      "gggggggggggggggg",
      "gggggggggggggggg",
      "gggggggggggggggg",
      "ggg gggggggggggg",
      "ggg!gggggggggggg",
      "gggggggggggggggg",
      "gggggggggggggggg",
      "gggggggggggggggg",
      "gggggggggggggggg",
      "gggggggggggggggg",
      "gggggggggggggggg",
      "gggggggg    gggg",
      "ggggggg     gggg",
      "ggggggg     gggg",
      "ggggggg    ggggg"
    ],
    [
      "!           !!  ",
      "           !!   ",
      "                ",
      "                ",
      "                ",
      "!!!             ",
      "! !!!!          ",
      "                ",
      " ggggggg        ",
      " ggggggg       !",
      " ggggggg       !",
      " ggggggg      !!",
      " ggggggg     !!!",
      " ggggggg    !!!!",
      " gggggg      !! ",
      "             !  "
    ],
    [
      "                ",
      "                ",
      "                ",
      "                ",
      "                ",
      "                ",
      "                ",
      "                ",
      " ggggggg        ",
      " ggggggg       !",
      " ggggggg       !",
      " ggggggg      !!",
      " ggggggg      !!",
      " ggggggg     !! ",
      " ggggggg        ",
      "                "
    ],
    [
      "                ",
      "                ",
      "                ",
      "                ",
      "                ",
      "                ",
      "                ",
      "                ",
      "                ",
      "  ggggg         ",
      "  ggggg         ",
      "  ggggg        !",
      "  ggggg         ",
      "  ggggg         ",
      "                ",
      "                "
    ],
    [
      "                ",
      "                ",
      "                ",
      "                ",
      "                ",
      "                ",
      "                ",
      "                ",
      "                ",
      "  ggggg         ",
      "  ggggg         ",
      "  ggggg         ",
      "  ggggg         ",
      "  ggggg         ",
      "                ",
      "                "
    ],
    [
      "                ",
      "                ",
      "                ",
      "                ",
      "                ",
      "                ",
      "                ",
      "                ",
      "                ",
      "                ",
      "                ",
      "                ",
      "                ",
      "                ",
      "                ",
      "                "
    ]
  ]
}