{
  "xsize": 16,
  "zsize": 16,
  "refpalette": "lostcities:base",
  "slices": [
    [
      "     f          ",
      "     f          ",
      "ffʹ  f          ",
      "ʹʹffffffff      ",
      "ʹʹf  f   f      ",
      "ʹʹf  f   f      ",
      "ffʹ  f   f      ",
      "  f  f   f      ",
      "  f  f   f      ",
      "  f  f   f      ",
      "  f  f   f      ",
      "  f  f  !f!     ",
      "  f  f  !f!     ",
      "ffffff   f      ",
      "  ffffffff      ",
      "                "
    ],
    [
      "     f          ",
      "     f          ",
      "ʹʹʹ  f          ",
      "ʹʹʹffffff       ",
      "ʹʹʹ  f  f       ",
      "ʹʹʹ  f  f       ",
      "ʹʹʹ  f  f       ",
      "  f  f  f       ",
      "  f  f  f       ",
      "  f  f  f       ",
      "  f  f  f!      ",
      "  f  f !f!!     ",
      "  f  f  f!      ",
      "ffffff  f       ",
      "  fffffff       ",
      "                "
    ],
    [
      "     f          ",
      "     f          ",
      "  n  f          ",
      " ffffffff       ",
      " f   f  f       ",
      " f   f  f       ",
      " fn  f  f       ",
      " f   f  f       ",
      " f   f  f       ",
      " f   f  f       ",
      " f   f !f!      ",
      " f   f !f!      ",
      " f   f  f       ",
      "ffffff  f       ",
      " ffffffff       ",
      "                "
    ],
    [
      "     f          ",
      "     f          ",
      "ʹʹʹ  f          ",
      "ʹʹʹfffff        ",
      "ʹʹʹ  f f        ",
      "ʹʹʹ  f f        ",
      "ʹʹʹ  f f        ",
      " f   f f        ",
      " f   f f        ",
      " f   f!f!       ",
      " f   f!f!!      ",
      " f   f f!       ",
      " f   f f        ",
      "ffffff f        ",
      " fffffff        ",
      "                "
    ],
    [
      "     f          ",
      "     f          ",
      "ffʹ  f          ",
      "ffffffff        ",
      "f f  f f        ",
      "ͳͳf  f f        ",
      "ffʹ  f f        ",
      "f    f f        ",
      "f    f!f!       ",
      "f    f!f!!      ",
      "f    f!f!!      ",
      "f    f f!       ",
      "f    f f        ",
      "ffffff f        ",
      "ffffffff        ",
      "                "
    ],
    [
      "     f          ",
      "     f          ",
      "ffʹ  f          ",
      "fffffff         ",
      "f f  ff         ",
      "f f  ff         ",
      "ffʹ  ff         ",
      "f    ff         ",
      "f    ff!!       ",
      "f    ff!!!      ",
      "f    ff!!       ",
      "f    ff         ",
      "f    ff         ",
      "fffffff         ",
      "fffffff         ",
      "                "
    ]
  ]
}