{
  "xsize": 16,
  "zsize": 16,
  "refpalette": "lostcities:base",
  "slices": [
    [
      "g      gg       ",
      "gYYYYYYY        ",
      "gYYYYYYYY       ",
      "gYYYYYYYY       ",
      "ggggggggg       ",
      " YYYYYY         ",
      " YYYYY!!  !     ",
      " YYYYY!! !g!    ",
      " YYYYYYYY!g!    ",
      " YYYYYYYY g     ",
      " YYYYYYYY g     ",
      "ggggggggggg     ",
      "gYYYYYYYYgg     ",
      "gYYYYYYYYg      ",
      "gYY  ! YY       ",
      "g      gg       "
    ],
    [
      "g      g        ",
      "gYYYYYY         ",
      "gYYYYYYY        ",
      "gYYYYYYYg       ",
      "ggggggggg       ",
      " YYYYYY         ",
      " YYYYY!         ",
      " YYYYY!!  !     ",
      " YYYYYY   !     ",
      " YYYYYYY        ",
      " YYYYYYY        ",
      "gggggggggg      ",
      "gYYYYYYYgg      ",
      "gYYYYYYYgg      ",
      "gYY  ! Y        ",
      "g      g        "
    ],
    [
      "g      g        ",
      "gYYYYYY         ",
      "gYYYYYYY        ",
      "gYYYYYYY        ",
      "ggggggggg       ",
      " YYYYYY         ",
      " YYYYY!         ",
      " YYYYY!!        ",
      " YYYYYY!        ",
      " YYYYYYY        ",
      " YYYYYYY        ",
      "ggggggggg       ",
      "gYYYYYYYg       ",
      "gYYYYYYYg       ",
      "gYY !!YY        ",
      "g    ! g        "
    ],
    [
      "g      g        ",
      "gYYYYYY         ",
      "gYYYYYYY        ",
      "gYYYYYYY        ",
      "ggggggggg       ",
      " YYYYYY         ",
      " YYYYY          ",
      " YYYYY!         ",
      " YYYYYY!        ",
      " YYYYYYY        ",
      " YYYYYYY        ",
      "ggggggggg       ",
      "gYYYYYYYg       ",
      "gYYYYYYYg       ",
      "gYY !!YY        ",
      "g    ! g        "
    ],
    [
      "g      g        ",
      "gYYYYYY         ",
      "gYYYYYYY        ",
      "gYYYYYYY        ",
      "ggggggggg       ",
      " YYYYYY         ",
      " YYYYYY         ",
      " YYYYYY         ",
      " YYYYYY!        ",
      " YYYYYYY        ",
      " YYYYYYY        ",
      "ggggggggg       ",
      "gYYYYYYYg       ",
      "gYYYYYYYg       ",
      "gYYY!!YY        ",
      "g   !! g        "
    ],
    [
      "g  !  gg        ",
      "gYYYYYY         ",
      "gYYYYYYY        ",
      "gYYYYYYY        ",
      "ggggggggg       ",
      " YYYYYY         ",
      " YYYYY          ",
      " YYYYYY         ",
      " YYYYYY!        ",
      " YYYYYYY        ",
      " YYYYYYY        ",
      "ggggggggg       ",
      "gYYYYYYYg       ",
      "gYYYYYYYg       ",
      "gYYYYYYY        ",
      "g   ! gg        "
    ]
  ]
}