{
  "xsize": 16,
  "zsize": 16,
  "refpalette": "lostcities:base",
  "slices": [
    [
      "   g        g   ",
      " ffffffffffffff ",
      " ffffffffffffff ",
      " ffffffffffffff ",
      " f            f ",
      " f            f ",
      "gggggggggggggggg",
      "gggggggggggggggg",
      " f            f ",
      " f            f ",
      " f           !f!",
      " f            f ",
      " f            f ",
      " f            f ",
      " f            f ",
      " f            f "
    ],
    [
      "  g          g  ",
      " ffffffffffffff ",
      " ffffffffffffff ",
      " ffffffffffffff ",
      " f            f ",
      " f            f ",
      "gggggggggggggggg",
      "gggggggggggggggg",
      " f            f ",
      " f           !f!",
      " f           !f!",
      " f            f ",
      " f            f ",
      " f            f ",
      " f            f ",
      " f            f "
    ],
    [
      "  g          g  ",
      " ffffffffffffff ",
      " ffffffffffffff ",
      " ffffffffffffff ",
      " f            f ",
      " f            f ",
      "gggggggggggggggg",
      "gggggggggggggggg",
      " f            f ",
      " f           !f!",
      " f            f ",
      " f            f ",
      " f            f ",
      " f            f ",
      " f            f ",
      " f            f "
    ],
    [
      "  g          g  ",
      " ffffffffffffff ",
      " ffffffffffffff ",
      " ffffffffffffff ",
      " f            f ",
      " f            f ",
      "gggggggggggggggg",
      "gggggggggggggggg",
      " f           !f!",
      " f           !f!",
      " f            f ",
      " f            f ",
      " f            f ",
      " f            f ",
      " f            f ",
      " f            f "
    ],
    [
      "  g          g  ",
      " ffffffffffffff ",
      " ffffffffffffff ",
      " ffffffffffffff ",
      " f            f ",
      " f            f ",
      "gggggggggggggggg",
      "gggggggggggggggg",
      "             !f!",
      "              f ",
      "              f ",
      " f            f ",
      " f            f ",
      " f              ",
      " f              ",
      " f              "
    ],
    [
      "   g        g   ",
      " ffffffffffffff ",
      " ffffffffffffff ",
      " ffffffffffffff ",
      " f            f ",
      " f            f ",
      "gggggggggggggggg",
      "   ggggggggggggg",
      "             !f!",
      "              f ",
      "              f ",
      " f            f ",
      " f              ",
      " f              ",
      " f              ",
      " f              "
    ]
  ]
}