{
  "xsize": 16,
  "zsize": 16,
  "refpalette": "lostcities:base",
  "slices": [
    [
      "                ",
      "f              f",
      "ffffff     fffff",
      "f              f",
      "f              f",
      "f              f",
      "fʹ            ʹf",
      "ʹf            fʹ",
      "ʹf            fʹ",
      "ʹf            fʹ",
      "fʹ            ʹf",
      "f              f",
      "f             !f",
      "fʹ           !ʹf",
      "ʹf           !fʹ",
      "ʹf           !fʹ"
    ],
    [
      "                ",
      "f              f",
      "fffffff     ffff",
      "f              f",
      "f              f",
      "f              f",
      "ʹʹ            ʹʹ",
      "ʹʹ            ʹʹ",
      "ʹʹ            ʹʹ",
      "ʹʹ            ʹʹ",
      "ʹʹ            ʹʹ",
      "f              f",
      "f              f",
      " ʹ            ! ",
      " ʹ           !!ʹ",
      " ʹ          !!ʹʹ"
    ],
    [
      "                ",
      "f              f",
      "fffffff      fff",
      "f              f",
      "f              f",
      "f              f",
      "f              f",
      "f              f",
      "f   !!!!!      f",
      "f       !!!! !!f",
      "f           !! f",
      "f              f",
      "f               ",
      "                ",
      "             !! ",
      "            !!! "
    ],
    [
      "                ",
      "ff            ff",
      "ffffffff    ffff",
      "ffffffff    ffff",
      "fffffffff   ffff",
      "ffffffffffffffff",
      "ffffffffffffffff",
      "ffffffffffffffff",
      "ffffffffffffffff",
      "ffffffffffffffff",
      "ffffffffffffffff",
      "fffffffffffff!  ",
      " fffffffffff    ",
      "  ffffffffff    ",
      "  fffffffffff!  ",
      "  ffffffffffffff"
    ],
    [
      "                ",
      "ff            ff",
      " f            f ",
      " f            f ",
      " f            f ",
      " f            f ",
      "!f!!!         f ",
      "!f!!!!        f!",
      " f!!!!!!!    !f!",
      " f  !   !!!! !f!",
      " f          !!f ",
      " f              ",
      " f              ",
      "                ",
      "                ",
      "            !!  "
    ],
    [
      "                ",
      "f              f",
      "f              f",
      "f              f",
      "f              f",
      "f!             f",
      "f!!            f",
      "f!!!!          f",
      "f!  !         !f",
      "f             !f",
      "f               ",
      "f               ",
      "                ",
      "                ",
      "                ",
      "                "
    ]
  ]
}