{
  "xsize": 16,
  "zsize": 16,
  "refpalette": "lostcities:base",
  "slices": [
    [
      "vvvvvvvvvvvvvvvv",
      "vvvvvvvvvvvvvvvv",
      "vvvvvvvvvvvvvvvv",
      "vvvvvvvvvvvvvvvv",
      "vvvvvvvvvvvvvvvv",
      "vvvvvvvvvvvvvvvv",
      "vvvvvvvvvvvvvvvv",
      "vvvvvvvvvvvvvvvv",
      "vvvvvvvvvvvvvvvv",
      "vvvvvvvvvvvvvvvv",
      "vvvvvvvvvvvvvvvv",
      "vvvvvvvvvvvvvvvv",
      "vvvvvvvvvvvvvvvv",
      "vvvvvvvvvvvvvvvv",
      "vvvvvvvvvvvvvvvv",
      "vvvvvvvvvvvvvvvv"
    ],
    [
      "fffffffffffffffl",
      "ffffffffffffffff",
      "ffffffffffffffff",
      "ffffffffffffffff",
      "ffffffffffffffff",
      "ffffffffffffffff",
      "ffffffffffffffff",
      "ffffffffffffffff",
      "ffffffffffffffff",
      "ffffffffffffffff",
      "ffffffffffffffff",
      "ffffffffffffffff",
      "ffffffffffffffff",
      "ffffffffffffffff",
      "ffffffffffffffff",
      "ffffffffffffffff"
    ],
    [
      "gg  gg        gg",
      "gggggggggggggggg",
      "gg  gggggggggggg",
      "             ggg",
      " ffffffffffffggg",
      " ff          gr ",
      "              r ",
      "    !!        r ",
      "   !!!!       r ",
      "   !!!        r ",
      "    !         r ",
      "              r ",
      "              r ",
      "              r ",
      "             ggg",
      "              g "
    ],
    [
      "gg  gg        gn",
      "ggggggoooooooog ",
      "gg  gg        g ",
      "             ggg",
      " ffppppppppppggg",
      " ff          gr ",
      "     !        r ",
      "    !!!       r ",
      "    !!!       r ",
      "    !!        r ",
      "              r ",
      "              r ",
      "              r ",
      "              r ",
      "             ggg",
      "              g "
    ],
    [
      "gg  gg        g ",
      "ggggggoooooooog ",
      "gg  gg        g ",
      "             ggg",
      " hi          ggg",
      " jk          gr ",
      "     !!!      r ",
      "    !!!!     !r!",
      "    !!!      !r!",
      "     !        r ",
      "              r ",
      "              r ",
      "              r ",
      "              r ",
      "             ggg",
      "              g "
    ],
    [
      "gg  gg     !  g ",
      "ggggggoooooooog ",
      "gg  gg     !  g ",
      "             ggg",
      " hi          ggg",
      " jk   !!     gr ",
      "     !!!!     r ",
      "     !!!      r ",
      "     !!      !r!",
      "              r ",
      "              r ",
      "              r ",
      "              r ",
      "              r ",
      "             ggg",
      "              g "
    ]
  ]
}