{
  "xsize": 16,
  "zsize": 16,
  "refpalette": "lostcities:base",
  "slices": [
    [
      "ggg       !ggggg",
      "gggg       !gggg",
      "gggg       ggggg",
      "ggggg      ggggg",
      "gggggggggggggggg",
      "gggggggggggggggg",
      "gggggggggggggggg",
      "gggggggggggggggg",
      "gggggggggggggggg",
      "gggggggggggggggg",
      "gggggggggggggggg",
      "gggggggggggggggg",
      "gggggggggggggggg",
      "gggggggggggggggg",
      "gggggggggggggggg",
      "gggggggggggggggg"
    ],
    [
      "  g        !!!g ",
      " ggg        !!!g",
      "gggg        YYYg",
      " ggg        !!g ",
      "  g        !!!  ",
      "  Y         !   ",
      "  Y         !   ",
      "  Y        !!!  ",
      "  Y         !   ",
      "  Y             ",
      "  Y             ",
      "  Y             ",
      " !Y!            ",
      "!!Y           !!",
      "g!Yg         !g!",
      "!gg         !!!g"
    ],
    [
      "  g             ",
      " ggg         ! g",
      "ggggg  Y   YYYYg",
      " ggg       !!!  ",
      "  g        !!!  ",
      "  Y         !   ",
      "  Y         !   ",
      "  Y        !!!  ",
      "  Y         !   ",
      "  Y             ",
      "  Y             ",
      " !Y             ",
      "!!Y!            ",
      " !Y             ",
      "!!Y!          !!",
      " gg          !!g"
    ],
    [
      "  g             ",
      " ggg         ! g",
      "gggggYYYYYYYYYYg",
      " ggg       !!!  ",
      "  g         !   ",
      "  Y         !   ",
      "  Y        !!!  ",
      "  Y        !!!  ",
      "  Y         !   ",
      "  Y             ",
      " !Y             ",
      "!!Y!            ",
      "!!Y             ",
      "!!Y!            ",
      "!!Y!            ",
      "!gg            g"
    ],
    [
      "  g          !  ",
      " ggg        !!!g",
      "gggggYYYYYYYYYYg",
      " ggg       !!!  ",
      "  g         !   ",
      "  Y         !   ",
      "  Y        !!!  ",
      "  Y         !   ",
      "  Y             ",
      "  Y             ",
      " !Y!            ",
      " !Y!            ",
      " !Y             ",
      " !Y!            ",
      " !Y             ",
      "!gg            g"
    ],
    [
      "  g          !  ",
      " ggg        !!!g",
      "gggggYYYYYYYYYYg",
      " ggg       !!!  ",
      "  g         !   ",
      "  Y         !   ",
      "  Y        !!!  ",
      "  Y         !   ",
      "  Y             ",
      "  Y             ",
      " !Y!            ",
      "  Y             ",
      "  Y             ",
      " !Y!            ",
      "  Y             ",
      " gg            g"
    ]
  ]
}