{
  "xsize": 16,
  "zsize": 16,
  "refpalette": "lostcities:base",
  "slices": [
    [
      "    gg     !   n",
      "gg gggooooooo g ",
      "gg  gg     !  g ",
      "             ggg",
      " hi    !     ggg",
      " jk   !!!    gr ",
      "     !!!!     r ",
      "     !!!      r ",
      "      !      !r!",
      "             !r!",
      "              r ",
      "              r ",
      "              r ",
      "              r ",
      "             ggg",
      "              g "
    ],
    [
      "    gg     !    ",
      "gg gggoooooo!   ",
      "gg  gg     !    ",
      "               g",
      " hi    !!    ggg",
      " jk   !!!!   gr ",
      "      !!!     r ",
      "      !!      r ",
      "              r ",
      "             !r!",
      "             !r!",
      "              r ",
      "              r ",
      "              r ",
      "             ggg",
      "              g "
    ],
    [
      "    gg     !    ",
      "gg gggoooooo!   ",
      "gg  gg     !    ",
      "        !!     g",
      " hi    !!!   ggg",
      " jk   !!!!   gr ",
      "      !!!     r ",
      "       !      r ",
      "              r ",
      "              r ",
      "             !r!",
      "              r ",
      "              r ",
      "              r ",
      "             ggg",
      "              g "
    ],
    [
      "    gg     !    ",
      "gg gggoooooo!   ",
      "gg  gg   ! !    ",
      "        !!!   gg",
      " hi    !!!!  ggg",
      " jk    !!!   gr ",
      "       !!     r ",
      "              r ",
      "              r ",
      "              r ",
      "             !r!",
      "              r ",
      "              r ",
      "              r ",
      "             ggg",
      "              g "
    ],
    [
      "    gg     !  g ",
      "gg gggooooooo   ",
      "gg  gg   !!!  g ",
      "        !!!!  gg",
      " hi    !!!!  ggg",
      " jk    !!!   gr ",
      "        !     r ",
      "              r ",
      "              r ",
      "              r ",
      "             !r!",
      "              r ",
      "              r ",
      "              r ",
      "             ggg",
      "              g "
    ],
    [
      "    gg     !! gg",
      "gg gggooooooo!g ",
      "gg  gg   !!!! g ",
      "         !!!  gg",
      " hi     !!!  ggg",
      " jk     !!   gr ",
      "              r ",
      "              r ",
      "              r ",
      "              r ",
      "             !r!",
      "             !r!",
      "              r ",
      "              r ",
      "             ggg",
      "              g "
    ]
  ]
}