{
  "xsize": 16,
  "zsize": 16,
  "refpalette": "lostcities:base",
  "slices": [
    [
      "gg     gggg     ",
      "                ",
      "                ",
      "                ",
      "                ",
      "              ! ",
      "g    g       !g!",
      "        YY    ! ",
      "        YY      ",
      "                ",
      "                ",
      "                ",
      "                ",
      "                ",
      "                ",
      "g    g        g "
    ],
    [
      "ͶͶ     ͶͶͶͶ     ",
      "                ",
      "                ",
      "                ",
      "                ",
      "              ! ",
      "g    g       !g!",
      "       YY     ! ",
      "       YY       ",
      "                ",
      "                ",
      "                ",
      "                ",
      "                ",
      "                ",
      "g    g        g "
    ],
    [
      "ͶͶ     ͶͶͶͶ     ",
      "                ",
      "                ",
      "                ",
      "                ",
      "              ! ",
      "g    g    !  !g!",
      "      YY      ! ",
      "      YY        ",
      "                ",
      "                ",
      "                ",
      "                ",
      "                ",
      "                ",
      "g    g        g "
    ],
    [
      "ͶͶ     ͶͶͶͶ     ",
      "                ",
      "                ",
      "                ",
      "                ",
      "          !   ! ",
      "g    gggggggggg!",
      "g    gY   !YYYg ",
      "g    gY    YYYg ",
      "g    gYYYYYYYYg ",
      "g    gYYYYYYYYg ",
      "g    gYYYYYYYYg ",
      "g    gYYYYYYYYg ",
      "g    gYYYYYYYYg ",
      "g    gYYYYYYYYg ",
      "g    gggggggggg "
    ],
    [
      "ͶͶ     ͶͶͶͶ     ",
      "                ",
      "                ",
      "                ",
      "                ",
      "          !   ! ",
      "g    g   !!! !g!",
      "          !YY ! ",
      "           YY   ",
      "                ",
      "                ",
      "                ",
      "                ",
      "                ",
      "                ",
      "g    g        g "
    ],
    [
      "ͶͶ     ͶͶͶͶ     ",
      "                ",
      "                ",
      "                ",
      "                ",
      "          !!  ! ",
      "g    g   !!!!!g!",
      "          YY  ! ",
      "          YY    ",
      "                ",
      "                ",
      "                ",
      "                ",
      "                ",
      "                ",
      "g    g        g "
    ]
  ]
}