{
  "xsize": 16,
  "zsize": 16,
  "refpalette": "lostcities:base",
  "slices": [
    [
      "                ",
      " gggggggggggggg ",
      " gggggggggggggg ",
      " gggggggggggggg ",
      " gggggggggggggg!",
      "!gggggggggggggg ",
      "!gggggggggggggg ",
      " gggggggggggggg ",
      " gggggggggggggg ",
      " gggggggggggggg ",
      " gggggggggggggg ",
      " gggggggggggggg ",
      " gggggggggggggg ",
      " gggggggggggggg ",
      " gggggggggggggg ",
      "!gggggggggggggg "
    ],
    [
      "                ",
      " gg          gg ",
      " g            g ",
      "                ",
      "             !! ",
      " !!          !  ",
      " ! !!       !!  ",
      "    !!!    !!   ",
      "      !!  !!    ",
      "       !!!!     ",
      "        !!!!    ",
      "      ! !!!     ",
      "     !!!!       ",
      "    !!!!        ",
      "  !!!!!         ",
      " !!             "
    ],
    [
      "                ",
      " gg          gg ",
      " g            g ",
      "                ",
      "                ",
      "                ",
      "                ",
      "                ",
      "                ",
      "                ",
      "         !!     ",
      "                ",
      "      !         ",
      "     !!         ",
      "                ",
      "                "
    ],
    [
      "                ",
      "                ",
      "                ",
      "                ",
      "                ",
      "                ",
      "                ",
      "                ",
      "                ",
      "                ",
      "                ",
      "                ",
      "                ",
      "                ",
      "                ",
      "                "
    ],
    [
      "                ",
      "                ",
      "                ",
      "                ",
      "                ",
      "                ",
      "                ",
      "                ",
      "                ",
      "                ",
      "                ",
      "                ",
      "                ",
      "                ",
      "                ",
      "                "
    ],
    [
      "                ",
      "                ",
      "                ",
      "                ",
      "                ",
      "                ",
      "                ",
      "                ",
      "                ",
      "                ",
      "                ",
      "                ",
      "                ",
      "                ",
      "                ",
      "                "
    ]
  ]
}