{
  "xsize": 16,
  "zsize": 16,
  "refpalette": "lostcities:base",
  "slices": [
    [
      "ʹʹʹʹʹʹʹʹ     ʹʹʹ",
      "ʹʹʹʹʹʹʹʹʹ    ʹ  ",
      "ʹʹʹʹʹʹʹʹ     ʹ  ",
      "ʹʹʹʹʹʹʹʹʹ ʹʹʹʹ! ",
      "ʹʹʹʹʹʹʹʹʹʹʹʹʹʹʹʹ",
      "ʹʹʹʹʹʹʹʹʹʹʹʹʹʹʹʹ",
      "ʹʹʹʹʹʹʹʹʹʹʹʹʹʹʹʹ",
      "ʹʹʹʹʹʹʹʹʹʹ  ʹʹʹʹ",
      "ʹʹʹʹʹʹʹʹʹʹʹʹʹʹʹʹ",
      "ʹʹʹʹʹʹʹʹʹʹʹʹʹʹʹʹ",
      "ʹʹʹʹʹʹʹʹʹʹʹʹʹʹʹʹ",
      "ʹʹʹʹʹʹʹʹʹʹʹʹʹʹʹʹ",
      "ʹʹʹʹʹʹʹʹʹʹʹʹʹʹʹʹ",
      " ʹʹʹʹʹʹʹʹʹʹʹʹʹʹʹ",
      " ʹʹ    ʹʹʹʹʹʹʹʹʹ",
      "      !ʹʹʹʹʹʹʹʹʹ"
    ],
    [
      "g              g",
      " fffffff        ",
      " ffffff         ",
      " fffff       !! ",
      " fffff      !!f!",
      " ffffff    !fff ",
      " ffffffff fffff ",
      " fffffffff  fff ",
      " ffffffffffffff ",
      " ffffffffffffff ",
      " ffffffffffffff ",
      " ffffffffffffff ",
      " fff ffffffffff ",
      " ff   fffffffff ",
      "       ffffffff ",
      "      !!!!     g"
    ],
    [
      "gʹʹʹʹʹʹ     ʹʹʹg",
      "ʹfffffff        ",
      "ʹf              ",
      "ʹf            ! ",
      "ʹf          !!fʹ",
      "ʹf         !!!fʹ",
      "ʹf          ! fʹ",
      "ʹf            fʹ",
      "ʹf            fʹ",
      "ʹf            fʹ",
      "ʹf            fʹ",
      "ʹf            fʹ",
      "ʹf            fʹ",
      "         !    fʹ",
      "       ffffffffʹ",
      "       ʹʹʹʹʹʹʹ g"
    ],
    [
      "g              g",
      " f  f  f        ",
      "                ",
      "                ",
      " f          ! ! ",
      "           !!!  ",
      "            !   ",
      " f            f ",
      " f            f ",
      "                ",
      "                ",
      " f            f ",
      "                ",
      "         !      ",
      "       ff!!f  f ",
      "        !!!    g"
    ],
    [
      "g              g",
      " f  f  f      f ",
      "                ",
      "                ",
      " f          !!  ",
      "           !!!! ",
      "            !!  ",
      " f            f ",
      " f            f ",
      "                ",
      "                ",
      " f            f ",
      "                ",
      "         !!     ",
      "       ff!!f  f ",
      "         !!!   g"
    ],
    [
      "g              g",
      " fffffff   ffff ",
      " fffffff   ffff ",
      " fffffff  f     ",
      " fffffffff   !  ",
      " ffffffffff !!! ",
      " fffffffffffff  ",
      " ffffffffffffff ",
      " ffffffffffffff ",
      " ffffffffffffff ",
      " ffffffffffffff ",
      " ffffffffffffff ",
      "  fffffffffffff ",
      "     !fffffffff ",
      "      fffffffff ",
      "         !!!!  g"
    ]
  ]
}