{
  "xsize": 16,
  "zsize": 16,
  "refpalette": "lostcities:base",
  "slices": [
    [
      "           !Ͷ   ",
      "            Ͷ   ",
      "            Ͷ   ",
      "           Ͷ    ",
      "           Ͷ    ",
      "          Ͷ     ",
      "         Ͷ      ",
      "Ͷ      ͶͶ       ",
      " ͶͶͶͶͶͶ         ",
      "ͶͶ     ͶͶͶ      ",
      "  Ͷ   Ͷ         ",
      "   Ͷ Ͷ          ",
      "   Ͷ Ͷ          ",
      "   Ͷ Ͷ          ",
      "   Ͷ Ͷ          ",
      "  Ͷ   Ͷ    Ͷ    "
    ],
    [
      "            Ͷ   ",
      "            Ͷ   ",
      "            Ͷ   ",
      "           Ͷ    ",
      "           Ͷ    ",
      "          Ͷ     ",
      "         Ͷ      ",
      "Ͷ      ͶͶ       ",
      " ͶͶͶͶͶͶ         ",
      "gg     ggg      ",
      "ggg   gggg      ",
      "gggg ggggg      ",
      "gggg ggggg g    ",
      "gggg ggggggg    ",
      "gggg ggggggg    ",
      "ggg   gggggg    "
    ],
    [
      "            Ͷ   ",
      "            Ͷ   ",
      "            Ͷ   ",
      "           Ͷ    ",
      "           Ͷ    ",
      "          Ͷ     ",
      "         Ͷ      ",
      "Ͷ      ͶͶ       ",
      " ͶͶͶͶͶͶ         ",
      "gg     ggg      ",
      "ggg   gggg      ",
      "gggg gggggg     ",
      "gggg ggggggg    ",
      "gggg ggggggg    ",
      "gggg ggggggg    ",
      "ggg   gggggg    "
    ],
    [
      "                ",
      "            Ͷ   ",
      "            Ͷ   ",
      "           Ͷ    ",
      "           Ͷ    ",
      "          Ͷ     ",
      "         Ͷ      ",
      "Ͷ      ͶͶ       ",
      " ͶͶͶͶͶͶ         ",
      "gg     ggg      ",
      "ggg   gggg      ",
      "gggg gggggg     ",
      "gggg ggggggg    ",
      "gggg ggggggg    ",
      "gggg ggggggg    ",
      "ggg   gggggg    "
    ],
    [
      "                ",
      "            Ͷ   ",
      "            Ͷ   ",
      "           Ͷ    ",
      "           Ͷ    ",
      "          Ͷ     ",
      "         Ͷ      ",
      "Ͷ      ͶͶ       ",
      " ͶͶͶͶͶͶ         ",
      "g       gg      ",
      " gg   gg  g     ",
      "  g   g         ",
      "   g g          ",
      "   g g          ",
      "  g   g    g    ",
      " gg   gg  gg    "
    ],
    [
      "                ",
      "            Ͷ   ",
      "            Ͷ   ",
      "           Ͷ    ",
      "           Ͷ    ",
      "          Ͷ     ",
      "         Ͷ      ",
      "Ͷ      ͶͶ       ",
      " ͶͶͶͶͶͶ         ",
      "                ",
      "gg     gggg     ",
      "  g   g         ",
      "  g   g         ",
      "  g   g    g    ",
      "  g   g    g    ",
      "gg     gggg     "
    ]
  ]
}