{
  "xsize": 16,
  "zsize": 16,
  "refpalette": "lostcities:base",
  "slices": [
    [
      "                ",
      "    fffffff     ",
      "    ff    f     ",
      "    ff    f     ",
      "    ff    f     ",
      "    ff    f     ",
      "    ff    f     ",
      "    ff    f     ",
      "    ff    f   vv",
      "    ff    f vvvv",
      "    ff    fvvvvv",
      "    ff    fvvvvv",
      "    fffffffvvvvv",
      "         vvvvvvv",
      "        vvvvvvvv",
      "        vvvvvvvv"
    ],
    [
      "                ",
      "    ffffffff    ",
      "    f     ffffff",
      "    f     ffffff",
      "    f     ffffff",
      "    f     ffffff",
      "    f     ffffff",
      "    f     ffffff",
      "    f     ffffff",
      "    f     ffffff",
      "    f     ffffff",
      "    f     ffffff",
      "    ffffffffffff",
      "          ffffff",
      "          ffffff",
      "          ffffff"
    ],
    [
      "                ",
      "     fffffff    ",
      "     f    ffffff",
      "     f    ff    ",
      "     f    ff    ",
      "     f    ff    ",
      "     f    ff n  ",
      "     f    ff    ",
      "     f    ff    ",
      "     f    ff    ",
      "     f!   ff n  ",
      "     f    ff    ",
      "     fffffff    ",
      "          f  n  ",
      "          f     ",
      "          f     "
    ],
    [
      "                ",
      "     ffffffff   ",
      "     f    ffffff",
      "     f    f f   ",
      "     f    f f   ",
      "     f    f f   ",
      "     f    f fʹʹʹ",
      "     f    f fʹʹʹ",
      "     f    f fʹʹʹ",
      "     f!   f fʹʹʹ",
      "    !f!!  f fʹʹʹ",
      "    !f!   f f   ",
      "     ffffffff   ",
      "          f  ʹʹʹ",
      "          f  ʹʹʹ",
      "          f  ʹʹʹ"
    ],
    [
      "                ",
      "      fffffff   ",
      "      f   ffffff",
      "      f   f f   ",
      "      f   f f   ",
      "      f   f f   ",
      "      f   f fʹff",
      "      f   f ff  ",
      "      f   f ff  ",
      "      f   f ffͳͳ",
      "     !f!  f fʹff",
      "     !f   f f   ",
      "      fffffff   ",
      "          f  ʹff",
      "          f  f  ",
      "          f  f  "
    ],
    [
      "                ",
      "      ffffffff  ",
      "      f   ffffff",
      "      f   f  f  ",
      "      f   f  f  ",
      "      f   f  f  ",
      "      f!  f  ʹff",
      "      f   f  f  ",
      "      f   f  f  ",
      "     !f!  f  f  ",
      "     !f!  f  ʹff",
      "      f   f  f  ",
      "      ffffffff  ",
      "          f  ʹff",
      "          f  f  ",
      "          f  f  "
    ]
  ]
}