{
  "xsize": 16,
  "zsize": 16,
  "refpalette": "lostcities:base",
  "slices": [
    [
      "             ggg",
      "            gggg",
      "            gggg",
      "            gggg",
      "            gggg",
      "             ggg",
      "       Y      gg",
      "      ͶY        ",
      "      ͶY       Ͷ",
      "     !ͶY      Ͷ ",
      "     !ͶY     Ͷ  ",
      "   ͶͶͶͶYYY  Ͷ   ",
      " ͶͶ    ͶͶY  Ͷ   ",
      " Ͷ      ͶYYͶ    ",
      "Ͷ        ͶYͶ    ",
      "Ͷ        ͶYͶ    "
    ],
    [
      "             ggg",
      "            gggg",
      "            gggg",
      "            gggg",
      "            gggg",
      "             ggg",
      "              gg",
      "       Y        ",
      "      ͶY       Ͷ",
      "      ͶY      Ͷ ",
      "     !ͶY     Ͷ  ",
      "   ͶͶͶͶYYY  Ͷ   ",
      " ͶͶ    ͶͶY  Ͷ   ",
      " Ͷ      ͶYYͶ    ",
      "Ͷ        ͶYͶ    ",
      "Ͷ        ͶYͶ    "
    ],
    [
      "             Ͷ  ",
      "            Ͷ   ",
      "            Ͷ   ",
      "            Ͷ   ",
      "            Ͷ   ",
      "             Ͷ  ",
      "              ͶͶ",
      "       Y        ",
      "      ͶY       Ͷ",
      "     !ͶY      Ͷ ",
      "    !!ͶY     Ͷ  ",
      "   ͶͶͶͶYYY  Ͷ   ",
      " ͶͶ    ͶͶY  Ͷ   ",
      " Ͷ      ͶYYͶ    ",
      "Ͷ        ͶYͶ    ",
      "Ͷ        ͶYͶ    "
    ],
    [
      "             Ͷ  ",
      "            Ͷ   ",
      "            Ͷ   ",
      "            Ͷ   ",
      "            Ͷ   ",
      "             Ͷ  ",
      "              ͶͶ",
      "                ",
      "       Y       Ͷ",
      "     !ͶY      Ͷ ",
      "    !!ͶY     Ͷ  ",
      "   ͶͶͶͶYYY  Ͷ   ",
      " ͶͶ    ͶͶY  Ͷ   ",
      " Ͷ      ͶYYͶ    ",
      "Ͷ        ͶYͶ    ",
      "Ͷ        ͶYͶ    "
    ],
    [
      "             Ͷ  ",
      "            Ͷ   ",
      "            Ͷ   ",
      "            Ͷ   ",
      "            Ͷ   ",
      "             Ͷ  ",
      "              ͶͶ",
      "                ",
      "       Y       Ͷ",
      "      ͶY      Ͷ ",
      "     !ͶY     Ͷ  ",
      "   ͶͶͶͶYYY  Ͷ   ",
      " ͶͶ    ͶͶY  Ͷ   ",
      " Ͷ      ͶYYͶ    ",
      "Ͷ        ͶYͶ    ",
      "Ͷ        ͶYͶ    "
    ],
    [
      "             Ͷ  ",
      "            Ͷ   ",
      "            Ͷ   ",
      "            Ͷ   ",
      "            Ͷ   ",
      "             Ͷ  ",
      "              ͶͶ",
      "                ",
      "               Ͷ",
      "       Y      Ͷ ",
      "       Y     Ͷ  ",
      "   ͶͶͶͶYYY  Ͷ   ",
      " ͶͶ    ͶͶY  Ͷ   ",
      " Ͷ      ͶYYͶ    ",
      "Ͷ        ͶYͶ    ",
      "Ͷ        ͶYͶ    "
    ]
  ]
}