{
  "xsize": 16,
  "zsize": 16,
  "refpalette": "lostcities:base",
  "slices": [
    [
      "ffffffffffffffff",
      "ffffffffffffffff",
      "ffffffffffffffff",
      "gggggggggggggfff",
      "gggggggggggggfff",
      "gggggggggggggfff",
      "gggggggggggggfff",
      "gggggggggggggfff",
      "gggggggggggggfff",
      "gggggggggggggfff",
      "gggggggggggggfff",
      "gggggggggggggfff",
      "gggggggggggggfff",
      "gggggggggggggfff",
      "gggggggggggggfff",
      "gggggggggggggfff"
    ],
    [
      "              ff",
      "              ff",
      "                ",
      "                ",
      "                ",
      "                ",
      "                ",
      "  !             ",
      "  !             ",
      " !!             ",
      " !              ",
      "!!              ",
      "!               ",
      "!               ",
      "!               ",
      "!               "
    ],
    [
      "              ff",
      "              ff",
      "                ",
      "                ",
      "                ",
      "                ",
      "                ",
      "                ",
      "                ",
      "!               ",
      "!               ",
      "                ",
      "!               ",
      "!               ",
      "!               ",
      "                "
    ],
    [
      "              hi",
      "              jk",
      "                ",
      "                ",
      "                ",
      "                ",
      "                ",
      "                ",
      "!               ",
      "!!              ",
      "!!              ",
      "!               ",
      "!               ",
      "                ",
      "                ",
      "                "
    ],
    [
      "              hi",
      "              jk",
      "                ",
      "                ",
      "                ",
      "                ",
      "(               ",
      "(               ",
      "(!              ",
      "(!              ",
      "(               ",
      "()              ",
      "(*              ",
      "('              ",
      "('              ",
      "('              "
    ],
    [
      "              hi",
      "              jk",
      "                ",
      ",               ",
      "'               ",
      "'               ",
      "'               ",
      "'!              ",
      "'9              ",
      "'(              ",
      "'*              ",
      "'*              ",
      "''              ",
      "''-             ",
      "'''             ",
      "'''(            "
    ]
  ]
}