{
  "xsize": 16,
  "zsize": 16,
  "refpalette": "lostcities:base",
  "slices": [
    [
      "              gY",
      "gggggggggggggggY",
      "             YYY",
      "                ",
      "                ",
      "              ! ",
      "g    gggggggggg!",
      "g    g        g ",
      "g    g        g ",
      "g    g        g ",
      "g    g        g ",
      "g    g        g ",
      "g    g        g ",
      "g    g      ggg ",
      "g    g      ggg ",
      "g    gggggggggg "
    ],
    [
      "              gY",
      "ggggggggggggggg ",
      "             Y Y",
      "                ",
      "                ",
      "              ! ",
      "g    gggggggggg!",
      "g    g        g ",
      "g    g        g ",
      "g    g        g ",
      "g    g        g ",
      "g    g        g ",
      "g    g        g ",
      "g    g       gg ",
      "g    g       gg ",
      "g    gggggggggg "
    ],
    [
      "gggggggggggggggY",
      "ggggggggggggggg ",
      "             Y Y",
      "                ",
      "                ",
      "              ! ",
      "g    gggggggggg!",
      "g    gYYYYYYYYg ",
      "g    gYYYYYYYYg ",
      "g    gYYYYYYYYg ",
      "g    gYYYYYYYYg ",
      "g    gYYYYYYYYg ",
      "g    gYYYYYYYYg ",
      "g    gYYYY    g ",
      "g    gYYYY    g ",
      "g    gggggggggg "
    ],
    [
      "             Y Y",
      "                ",
      "             Y Y",
      "                ",
      "                ",
      "              ! ",
      "g    g       !g!",
      "           YY ! ",
      "           YY   ",
      "                ",
      "                ",
      "                ",
      "                ",
      "                ",
      "                ",
      "g    g        g "
    ],
    [
      "             YYY",
      "             Y Y",
      "             YYY",
      "                ",
      "                ",
      "              ! ",
      "g    g       !g!",
      "          YY  ! ",
      "          YY    ",
      "                ",
      "                ",
      "                ",
      "                ",
      "                ",
      "                ",
      "g    g        g "
    ],
    [
      "gg     gggg     ",
      "                ",
      "                ",
      "                ",
      "                ",
      "              ! ",
      "g    g       !g!",
      "         YY   ! ",
      "         YY     ",
      "                ",
      "                ",
      "                ",
      "                ",
      "                ",
      "                ",
      "g    g        g "
    ]
  ]
}