{
  "xsize": 16,
  "zsize": 16,
  "refpalette": "lostcities:base",
  "slices": [
    [
      "gg              ",
      " m              ",
      " m              ",
      " m              ",
      " m           !  ",
      " m          !!! ",
      " m           !  ",
      " m           ff ",
      " m           ff ",
      " m              ",
      " m              ",
      " m              ",
      " m              ",
      " m              ",
      " m              ",
      "gg              "
    ],
    [
      "gg           ffu",
      " m           ffu",
      " m           ffu",
      " m           ffu",
      " m           ffu",
      " m          !ffu",
      " mtttttttttttffu",
      " mfffffffffffffu",
      " mfffffffffffffu",
      " mjyyyyyyyyyyffu",
      " m           ffu",
      " m           ffu",
      " m           ffu",
      " m           ffu",
      " m           ffu",
      "gg           ffu"
    ],
    [
      "gg             z",
      " m             z",
      " m             z",
      " m             z",
      " m             z",
      " m           ! z",
      " mpppppppppp{p!z",
      " m          !htu",
      " m           jyu",
      " m|ppppppppp{p z",
      " m             z",
      " m             z",
      " m             z",
      " m             z",
      " m             z",
      "gg             z"
    ],
    [
      "gg              ",
      " m              ",
      " m              ",
      " m              ",
      " m              ",
      " m              ",
      " m           !  ",
      " m          !hi ",
      " m           jk ",
      " m              ",
      " m              ",
      " m              ",
      " m              ",
      " m              ",
      " m              ",
      "gg              "
    ],
    [
      "gg              ",
      " m              ",
      " m              ",
      " m              ",
      " m              ",
      " m              ",
      " m              ",
      " m           hi ",
      " m           jk ",
      " m              ",
      " m              ",
      " m              ",
      " m              ",
      " m              ",
      " m              ",
      "gg              "
    ],
    [
      "gg              ",
      " m              ",
      " m              ",
      " m              ",
      " m              ",
      " m              ",
      " m              ",
      " m           hi ",
      " m           jk ",
      " m              ",
      " m              ",
      " m              ",
      " m              ",
      " m              ",
      " m              ",
      "gg              "
    ]
  ]
}