{
  "xsize": 16,
  "zsize": 16,
  "refpalette": "lostcities:base",
  "slices": [
    [
      "g  ! g          ",
      "gYYYYY          ",
      "gYYYYY          ",
      "gYYYYYg         ",
      "gggggg          ",
      " YYYY           ",
      " YYYY           ",
      " YYYY           ",
      " YYYYY g        ",
      " YYYYY!g        ",
      " YYYYY!g!       ",
      "gggggggg        ",
      "gYYYYYgg        ",
      "gYYYYYg         ",
      "gYYYYY          ",
      "g  ! g          "
    ],
    [
      "g  ! g          ",
      "gYYYYY          ",
      "gYYYYYg         ",
      "gYYYYYg         ",
      "gggggg          ",
      " YYYY           ",
      " YYYY           ",
      " YYYY           ",
      " YYYYY          ",
      " YYYYY!         ",
      " YYYYY!!        ",
      "ggggggg         ",
      "gYYYYYg         ",
      "gYYYYYg         ",
      "gYYYYY          ",
      "g  ! g          "
    ],
    [
      "g  !gg          ",
      "gYYYYY          ",
      "gYYYYYg         ",
      "gYYYYYg         ",
      "ggggggg         ",
      " YYYY           ",
      " YYYY           ",
      " YYYYY          ",
      " YYYYY          ",
      " YYYYY!         ",
      " YYYYY!         ",
      "ggggggg         ",
      "gYYYYYg         ",
      "gYYYYYg         ",
      "gYYYYY          ",
      "g  !gg          "
    ],
    [
      "g  !g           ",
      "gYYYY           ",
      "gYYYYgg         ",
      "gYYYYgg         ",
      "ggggggg         ",
      " YYYY           ",
      " YYYY           ",
      " YYYY           ",
      " YYYY           ",
      " YYYY!          ",
      " YYYY!!         ",
      "ggggggg         ",
      "gYYYYgg         ",
      "gYYYYgg         ",
      "gYYYY           ",
      "g  !g           "
    ],
    [
      "g  !g           ",
      "gYYYY           ",
      "gYYYYg          ",
      "gYYYYg          ",
      "gggggg          ",
      " YYYY           ",
      " YYYY           ",
      " YYYY           ",
      " YYYY           ",
      " YYYY!          ",
      " YYYY!!         ",
      "gggggg!         ",
      "gYYYYg          ",
      "gYYYYg          ",
      "gYYYY           ",
      "g !!g           "
    ],
    [
      "g   g           ",
      "gYYYY           ",
      "gYYYYg          ",
      "gYYYYg          ",
      "gggggg          ",
      " YYYY           ",
      " YYYY           ",
      " YYYY           ",
      " YYYY           ",
      " YYYY           ",
      " YYYY!          ",
      "gggggg!         ",
      "gYYYYg          ",
      "gYYYYg          ",
      "gYYYY           ",
      "g!!!g           "
    ]
  ]
}