{
  "xsize": 16,
  "zsize": 16,
  "refpalette": "lostcities:base",
  "slices": [
    [
      "                ",
      "                ",
      "                ",
      "              r ",
      "  !           r ",
      " !!!          r ",
      " !!!          r ",
      " ff           r ",
      " ff           r ",
      "              r ",
      "              r ",
      "              r ",
      "              r ",
      "                ",
      "                ",
      "                "
    ],
    [
      "wff             ",
      "wff             ",
      "wff             ",
      "wff           r ",
      "wff           r ",
      "wff!          r ",
      "wfftttttttttttr ",
      "wfffffffffffffr ",
      "wfffffffffffffr ",
      "wffyyyyyyyyyykr ",
      "wff           r ",
      "wff           r ",
      "wff           r ",
      "wff           r ",
      "wff             ",
      "wff             "
    ],
    [
      "z               ",
      "z               ",
      "z             r ",
      "z             r ",
      "z             r ",
      "z !           r ",
      "z p|ppppppppppr ",
      "wti           r ",
      "wyk           r ",
      "z p|ppppppppp{r ",
      "z             r ",
      "z             r ",
      "z             r ",
      "z             r ",
      "z             r ",
      "z             g "
    ],
    [
      "                ",
      "                ",
      "              r ",
      "              r ",
      "              r ",
      "              r ",
      "              r ",
      " hi           r ",
      " jk           r ",
      "              r ",
      "              r ",
      "              r ",
      "              r ",
      "              r ",
      "              r ",
      "              gg"
    ],
    [
      "              g ",
      "              r ",
      "              r ",
      "              r ",
      "              r ",
      "              r ",
      "              r ",
      " hi           r ",
      " jk           r ",
      "              r ",
      "              r ",
      "              r ",
      "              r ",
      "              r ",
      "              r ",
      "              gg"
    ],
    [
      "              gg",
      "              r ",
      "              r ",
      "              r ",
      "              r ",
      "              r ",
      "              r ",
      " hi           r ",
      " jk           r ",
      "              r ",
      "              r ",
      "              r ",
      "              r ",
      "              r ",
      "              r ",
      "              gg"
    ]
  ]
}