{
  "xsize": 16,
  "zsize": 16,
  "refpalette": "lostcities:base",
  "slices": [
    [
      "                ",
      "                ",
      "                ",
      "                ",
      "                ",
      "                ",
      "                ",
      "                ",
      "                ",
      "                ",
      "                ",
      "                ",
      "                ",
      "                ",
      "                ",
      "                "
    ],
    [
      "                ",
      "                ",
      "!!!             ",
      "  !!!           ",
      "   !!!!         ",
      "                ",
      "                ",
      "                ",
      "                ",
      "                ",
      "                ",
      "                ",
      "                ",
      "                ",
      "                ",
      "                "
    ],
    [
      "gggggggggggggggg",
      "gggggggggggggggg",
      "gggggggggggggggg",
      "gggggggggggggggg",
      "gggggggggggggggg",
      "gggggggggggggggg",
      "gggggggggggggggg",
      "gggggggggggggggg",
      "gggggggggggggggg",
      "gggggggggggggggg",
      "gggggggggggggggg",
      "gggggggggggggggg",
      "gggggggggggggggg",
      "gggggggggggggggg",
      "gggggggggggggggg",
      "gggggggggggggggg"
    ],
    [
      "             Y  ",
      "            Y Y ",
      "!!!          Y  ",
      "  !!! !      Y  ",
      "   !!!!!    Y Y ",
      "      !      Y  ",
      "                ",
      "                ",
      "                ",
      "                ",
      "             YY ",
      "            Y  Y",
      "    YY      Y  Y",
      "   Y  Y      YY ",
      "   Y  Y         ",
      "    YY         Y"
    ],
    [
      "             Y  ",
      "            Y Y ",
      "             Y  ",
      "      !      Y  ",
      "     !!!    Y Y ",
      "     !!!     Y  ",
      "      !         ",
      "                ",
      "                ",
      "                ",
      "             YY ",
      "            YYYY",
      "    YY      YYYY",
      "   YYYY      YY ",
      "   Y YY         ",
      "    YY         Y"
    ],
    [
      "             ggg",
      "            gggg",
      "            gggg",
      "            gggg",
      "      !     gggg",
      "     !!!     ggg",
      "      !       gg",
      "                ",
      "               g",
      "              gg",
      "             ggg",
      "            gggg",
      "   ͶͶͶͶ     gggg",
      "  ͶͶͶͶͶͶ   ggggg",
      " ͶͶͶͶͶͶͶͶ  ggggg",
      " ͶͶͶͶͶͶͶͶ  ggggg"
    ]
  ]
}