{
  "xsize": 16,
  "zsize": 16,
  "refpalette": "lostcities:base",
  "slices": [
    [
      "            Ͷ   ",
      "            Ͷ   ",
      "            Ͷ   ",
      "           Ͷ    ",
      "           Ͷ    ",
      "          Ͷ     ",
      "         Ͷ      ",
      "Ͷ      ͶͶ       ",
      " ͶͶͶͶͶͶ         ",
      "                ",
      "                ",
      "                ",
      "                ",
      "                ",
      "                ",
      "                "
    ],
    [
      "            Ͷ   ",
      "            Ͷ   ",
      "            Ͷ   ",
      "           Ͷ    ",
      "           Ͷ    ",
      "          Ͷ     ",
      "         Ͷ      ",
      "Ͷ      ͶͶ       ",
      " ͶͶͶͶͶͶ         ",
      "                ",
      "                ",
      "                ",
      "                ",
      "                ",
      "                ",
      "                "
    ],
    [
      "ͶͶͶͶͶͶͶͶͶͶͶͶͶ   ",
      "ͶͶͶͶͶͶͶͶͶͶͶͶͶ   ",
      "ͶͶͶͶͶͶͶͶͶͶͶͶͶ   ",
      "ͶͶͶͶͶͶͶͶͶͶͶͶ    ",
      "ͶͶͶͶͶͶͶͶͶͶͶͶ    ",
      "ͶͶͶͶͶͶͶͶͶͶͶ     ",
      "ͶͶͶͶͶͶͶͶͶͶ      ",
      "ͶͶͶͶͶͶͶͶͶ       ",
      " ͶͶͶͶͶͶ         ",
      "                ",
      "                ",
      "                ",
      "                ",
      "                ",
      "                ",
      "                "
    ],
    [
      "ͶͶͶͶͶͶͶͶͶͶͶͶͶ   ",
      "ͶͶͶͶͶͶͶͶͶͶͶͶͶ   ",
      "ͶͶͶͶͶͶͶͶͶͶͶͶͶ   ",
      "ͶͶͶͶͶͶͶͶͶͶͶͶ    ",
      "ͶͶͶͶͶͶͶͶͶͶͶͶ    ",
      "ͶͶͶͶͶͶͶͶͶͶͶ     ",
      "ͶͶͶͶͶͶͶͶͶͶ      ",
      "ͶͶͶͶͶͶͶͶͶ       ",
      " ͶͶͶͶͶͶ         ",
      "                ",
      "                ",
      "                ",
      "                ",
      "                ",
      "                ",
      "                "
    ],
    [
      "           Ͷ    ",
      "           Ͷ    ",
      "           Ͷ    ",
      "           Ͷ    ",
      "          Ͷ     ",
      "         Ͷ      ",
      "        Ͷ       ",
      "ͶͶͶͶͶͶͶͶ        ",
      "                ",
      "                ",
      "                ",
      "                ",
      "                ",
      "                ",
      "                ",
      "                "
    ],
    [
      "           Ͷ    ",
      "           Ͷ    ",
      "           Ͷ    ",
      "          Ͷ     ",
      "          Ͷ     ",
      "         Ͷ      ",
      "Ͷ      ͶͶ       ",
      " ͶͶͶͶͶͶ         ",
      "                ",
      "                ",
      "                ",
      "                ",
      "                ",
      "                ",
      "                ",
      "                "
    ]
  ]
}