{
  "xsize": 16,
  "zsize": 16,
  "refpalette": "lostcities:base",
  "slices": [
    [
      "       ggggggggg",
      "       g      gg",
      "       g      gg",
      "       g        ",
      "       g        ",
      "       g        ",
      "       g        ",
      "      !g!       ",
      "       g        ",
      "       ggggggggg",
      "                ",
      "                ",
      "                ",
      "                ",
      "gggggggggggggggg",
      "                "
    ],
    [
      "       ggggggggg",
      "       g       g",
      "       g       g",
      "       g        ",
      "       g        ",
      "       g        ",
      "      !g!       ",
      "      !g!       ",
      "       g        ",
      "       ggggggggg",
      "                ",
      "                ",
      "                ",
      "                ",
      "gggggggggggggggg",
      "                "
    ],
    [
      "       ggggggggg",
      "       gYYYY    ",
      "       gYYYY    ",
      "       gYYYYYYYY",
      "       gYYYYYYYY",
      "       gYYYYYYYY",
      "      !gYYYYYYYY",
      "       gYYYYYYYY",
      "       gYYYYYYYY",
      "       ggggggggg",
      "                ",
      "                ",
      "                ",
      "                ",
      "gggggggggggggggg",
      "gggggggggggggggg"
    ],
    [
      "       g        ",
      "                ",
      "                ",
      "                ",
      "                ",
      "                ",
      "       !        ",
      "             YY ",
      "             YY ",
      "       g        ",
      "                ",
      "                ",
      "                ",
      "                ",
      "                ",
      "                "
    ],
    [
      "       g        ",
      "                ",
      "                ",
      "                ",
      "                ",
      "                ",
      "                ",
      "            YY  ",
      "            YY  ",
      "       g        ",
      "                ",
      "                ",
      "                ",
      "                ",
      "                ",
      "                "
    ],
    [
      "       g        ",
      "                ",
      "                ",
      "                ",
      "                ",
      "                ",
      "                ",
      "           YY   ",
      "           YY   ",
      "       g        ",
      "                ",
      "                ",
      "                ",
      "                ",
      "                ",
      "              gg"
    ]
  ]
}