{
  "xsize": 16,
  "zsize": 16,
  "refpalette": "lostcities:base",
  "slices": [
    [
      "  Ͷ   Ͷ    Ͷ    ",
      "   Ͷ Ͷ      Ͷ   ",
      "   Ͷ Ͷ     !Ͷ!  ",
      "   Ͷ Ͷ      Ͷ   ",
      "   Ͷ Ͷ      Ͷ   ",
      "  Ͷ   Ͷ    Ͷ    ",
      "ͶͶ     ͶͶͶͶ     ",
      " ͶͶͶͶͶͶ         ",
      "Ͷ      ͶͶ       ",
      "         Ͷ      ",
      "          Ͷ     ",
      "           Ͷ    ",
      "           Ͷ    ",
      "            Ͷ   ",
      "            Ͷ   ",
      "            Ͷ   "
    ],
    [
      "  Ͷ   Ͷ    Ͷ    ",
      "   Ͷ Ͷ      Ͷ   ",
      "   Ͷ Ͷ     !Ͷ!  ",
      "   Ͷ Ͷ      Ͷ   ",
      "   Ͷ Ͷ      Ͷ   ",
      "  Ͷ   Ͷ    Ͷ    ",
      "ͶͶ     ͶͶͶͶ     ",
      " ͶͶͶͶͶͶ         ",
      "Ͷ      ͶͶ       ",
      "         Ͷ      ",
      "          Ͷ     ",
      "           Ͷ    ",
      "           Ͷ    ",
      "            Ͷ   ",
      "            Ͷ   ",
      "            Ͷ   "
    ],
    [
      "  Ͷ   Ͷ    Ͷ!   ",
      "   Ͷ Ͷ     !Ͷ!  ",
      "   Ͷ Ͷ     !Ͷ!  ",
      "   Ͷ Ͷ      Ͷ   ",
      "   Ͷ Ͷ      Ͷ   ",
      "  Ͷ   Ͷ    Ͷ    ",
      "ͶͶ     ͶͶͶͶ     ",
      " ͶͶͶͶͶͶ         ",
      "Ͷ      ͶͶ       ",
      "         Ͷ      ",
      "          Ͷ     ",
      "           Ͷ    ",
      "           Ͷ    ",
      "            Ͷ   ",
      "            Ͷ   ",
      "            Ͷ   "
    ],
    [
      "  Ͷ   Ͷ    Ͷ!   ",
      "   Ͷ Ͷ     !Ͷ!  ",
      "   Ͷ Ͷ      Ͷ   ",
      "   Ͷ Ͷ      Ͷ   ",
      "   Ͷ Ͷ      Ͷ   ",
      "  Ͷ   Ͷ    Ͷ    ",
      "ͶͶ     ͶͶͶͶ     ",
      " gggggg         ",
      "ggggggggg       ",
      "gggggggggg      ",
      "ggggggggggg     ",
      "gggggggggggg    ",
      "gggggggggggg    ",
      "ggggggggggggg   ",
      "ggggggggggggg   ",
      "ggggggggggggg   "
    ],
    [
      "  Ͷ   Ͷ   !Ͷ!   ",
      "   Ͷ Ͷ    !!Ͷ!  ",
      "   Ͷ Ͷ!    !Ͷ   ",
      "   Ͷ Ͷ      Ͷ   ",
      "   Ͷ Ͷ      Ͷ   ",
      "  Ͷ   Ͷ    Ͷ    ",
      "ͶͶ     ͶͶͶͶ     ",
      " gggggg         ",
      "ggggggggg       ",
      "gggggggggg      ",
      "ggggggggggg     ",
      "gggggggggggg    ",
      "gggggggggggg    ",
      "ggggggggggggg   ",
      "ggggggggggggg   ",
      "ggggggggggggg   "
    ],
    [
      "  Ͷ   Ͷ   !Ͷ!   ",
      "   Ͷ Ͷ!!   !Ͷ   ",
      "   Ͷ!Ͷ!!    Ͷ   ",
      "   Ͷ Ͷ!     Ͷ   ",
      "   Ͷ Ͷ      Ͷ   ",
      "  Ͷ   Ͷ    Ͷ    ",
      "ͶͶ     ͶͶͶͶ     ",
      " ͶͶͶͶͶͶ         ",
      "Ͷ      ͶͶ       ",
      "         Ͷ      ",
      "          Ͷ     ",
      "           Ͷ    ",
      "           Ͷ    ",
      "            Ͷ   ",
      "            Ͷ   ",
      "            Ͷ   "
    ]
  ]
}