{
  "xsize": 16,
  "zsize": 16,
  "refpalette": "lostcities:base",
  "slices": [
    [
      "          g    g",
      "          YYYYYg",
      "          YYYYYg",
      "          YYYYYg",
      "           ggggg",
      "           YYYY ",
      "           YYYY ",
      "        g  YYYY ",
      "        g!YYYYY ",
      "       !g!YYYYY ",
      "        !!!YYYY ",
      "          gggggg",
      "         gYYYYYg",
      "         gYYYYYg",
      "          YYYYYg",
      "          g    g"
    ],
    [
      "          g    g",
      "          YYYYYg",
      "          YYYYYg",
      "          YYYYYg",
      "           ggggg",
      "           YYYY ",
      "          !YYYY ",
      "          !YYYY ",
      "         !YYYYY ",
      "        !!YYYYY ",
      "          !YYYY ",
      "          gggggg",
      "          YYYYYg",
      "         gYYYYYg",
      "          YYYYYg",
      "          g    g"
    ],
    [
      "          gg   g",
      "          YYYYYg",
      "          YYYYYg",
      "          YYYYYg",
      "           ggggg",
      "           !YYY ",
      "          !!YYY ",
      "           YYYY ",
      "          YYYYY ",
      "          YYYYY ",
      "          YYYYY ",
      "          gggggg",
      "         gYYYYYg",
      "         gYYYYYg",
      "          YYYYYg",
      "          gg   g"
    ],
    [
      "           g   g",
      "           YYYYg",
      "          gYYYYg",
      "           YYYYg",
      "            gggg",
      "           !YYY ",
      "           !YYY ",
      "            YYY ",
      "           YYYY ",
      "           YYYY ",
      "           YYYY ",
      "         ggggggg",
      "         ggYYYYg",
      "         ggYYYYg",
      "           YYYYg",
      "           g   g"
    ],
    [
      "           g   g",
      "           YYYYg",
      "           YYYYg",
      "           YYYYg",
      "            gggg",
      "           !YYY ",
      "            YYY ",
      "            YYY ",
      "           YYYY ",
      "           YYYY ",
      "           YYYY ",
      "          gggggg",
      "          gYYYYg",
      "          gYYYYg",
      "           YYYYg",
      "           g   g"
    ],
    [
      "               g",
      "            YYYg",
      "           YYYYg",
      "           YYYYg",
      "           !gggg",
      "           !YYY ",
      "            YYY ",
      "            YYY ",
      "           YYYY ",
      "           YYYY ",
      "           YYYY ",
      "          gggggg",
      "          gYYYYg",
      "          gYYYYg",
      "           YYYYg",
      "           g   g"
    ]
  ]
}