{
  "xsize": 16,
  "zsize": 16,
  "refpalette": "lostcities:base",
  "slices": [
    [
      "gggggggggggggggg",
      "gggggggggggggggg",
      "gggggggggggggggg",
      "gggggggggggggggg",
      "gggggggggggg ggg",
      "  gggggggggg   g",
      "   !!ggggg g    ",
      "      gggg      ",
      "   ggggg g g    ",
      "   ggggggg΅ggggg",
      "    ggggͿ΀Ͳggggg",
      "ggggggggggggg gg",
      "gggggggggg!g! gg",
      "gggggggggg ! ggg",
      "ggggggggg    ggg",
      "gggggggg     ggg"
    ],
    [
      "nnn          nnn",
      "ngn          ngn",
      "nngg gg gg ggnnn",
      "  gg gg gg gg   ",
      "   !            ",
      "  !g!gg gg g    ",
      "   ! gg΂gg      ",
      "       ggg      ",
      "   g ggzgg g    ",
      "   g ggggg!gg   ",
      "        !!!     ",
      "  gg gg gg!!g   ",
      "   g gg g!!!    ",
      "              nn",
      "ngn          ngn",
      "nnn          nnn"
    ],
    [
      " n            n ",
      "ngn          ngn",
      " nͳͳ ͳͳ ͳͳ ͳͳ n ",
      "  ͳͳ ͳͳ ͳͳ ͳͳ   ",
      "   !!!          ",
      "  !ͳ!ͳͳ ͳͳ ͳͳ   ",
      "   !!ͳͳ ͳͳ ͳ    ",
      "       hpi      ",
      "      ͳzͳͳ ͳͳ   ",
      "  ͳͳ ͳͳjͳͳ!ͳͳ   ",
      "         !      ",
      "   ͳ ͳͳ ͳ!! ͳ   ",
      "   ͳ ͳͳ ͳ       ",
      "              n ",
      "ng           ngn",
      " n            n "
    ],
    [
      "                ",
      " g            g ",
      "  ͳͳ ͳͳ ͳͳ ͳͳ   ",
      "  ͳͳ ͳͳ ͳͳ ͳͳ   ",
      "     !          ",
      "   !!ͳͳ ͳͳ ͳͳ   ",
      "     !ͳ ͳͳͲͳͳ   ",
      "       hpi;     ",
      "      ͳzͳͳ ͳͳ   ",
      "      ͳͽͳͳ!ͳͳ   ",
      "         !      ",
      "   ͳ ͳͳ ͳ   ͳ   ",
      "   ͳ ͳͳ         ",
      "                ",
      "              g ",
      "                "
    ],
    [
      "                ",
      " g            g ",
      "  ͳͳ ͳͳ ͳͳ ͳͳ   ",
      "  ͳͳ ͳͳ ͳͳ ͳͳ   ",
      "     !          ",
      "    !ͳͳ ͳͳ ͳͳ   ",
      "     !ͳ ͳͳ ͳͳ   ",
      "       hpi΅     ",
      "      ͳzͳͳ;ͳͳ   ",
      "      ͳjͳͳ!ͳͳ   ",
      "        !!      ",
      "   ͳ ͳͳ ͳ   ͳ   ",
      "   ͳ ͳͳ     ͳ   ",
      "                ",
      " g            g ",
      "                "
    ],
    [
      " n            n ",
      "ngn          ngn",
      " nͳͳ ͳͳ ͳͳ ͳͳ n ",
      "  ͳͳ ͳͳ ͳͳ ͳͳ   ",
      "                ",
      "     ͳͳ ͳͳ ͳͳ   ",
      "      ͳ ͳͳ ͳͳ   ",
      "       hpi      ",
      "      ͳzͳͳ΅ͳͳ   ",
      "  ͳͳ ͳͳjͳͳ;ͳͳ   ",
      "        !       ",
      "   ͳ ͳͳ     ͳ   ",
      "   ͳ ͳͳ     ͳ   ",
      " n            n ",
      "ngn          ngn",
      " n            n "
    ]
  ]
}