{
  "xsize": 16,
  "zsize": 16,
  "refpalette": "lostcities:base",
  "slices": [
    [
      "   g        g   ",
      "  ffffffffffff  ",
      "  ffffffffffff  ",
      "  ffffffffffff  ",
      "  f          f  ",
      "  f          f  ",
      "gggggggggggggggg",
      "   ggggggggggggg",
      "            !f!!",
      "            !f!!",
      "            !f  ",
      "  f          f  ",
      "  f             ",
      "  f             ",
      "  f             ",
      "  f             "
    ],
    [
      "    gg    gg    ",
      "   ffffffffff   ",
      "   ffffffffff   ",
      "   ffffffffff   ",
      "   f        f   ",
      "   f        f   ",
      " ggggggggggggggg",
      "   ggggggggggggg",
      "           !f!!!",
      "   f       !f!  ",
      "   f       !f!  ",
      "   f       !f   ",
      "   f       !f   ",
      "   f        f   ",
      "   f        f   ",
      "   f        f   "
    ],
    [
      "      gggg      ",
      "    ffffffff    ",
      "    ffffffff    ",
      "    ffffffff    ",
      "    f      f    ",
      "    f      f    ",
      " ggggggggggggggg",
      "   ggggggggggggg",
      "    f      f!!!!",
      "    f      f!!  ",
      "    f     !f!!  ",
      "    f     !f!   ",
      "    f     !f!   ",
      "    f     !f    ",
      "    f     !f    ",
      "    f    !!f    "
    ],
    [
      "                ",
      "     ffffff     ",
      "     ffffff     ",
      "     ffffff     ",
      "     ffffff     ",
      "     ffffff     ",
      " ggggggggggggggg",
      "   ggggggggggggg",
      "     ffffff !!!!",
      "     ffffff  !  ",
      "     ffffff!!   ",
      "     ffffff!    ",
      "     ffffff!!   ",
      "     ffffff!    ",
      "     ffffff!    ",
      "     ffffff!    "
    ],
    [
      "                ",
      "                ",
      "                ",
      "                ",
      "                ",
      "                ",
      " ggggg ggggggggg",
      "     ggggggggggg",
      "             !!!",
      "                ",
      "                ",
      "                ",
      "          !!    ",
      "          !     ",
      "          !     ",
      "         !!!    "
    ],
    [
      "                ",
      "                ",
      "                ",
      "                ",
      "                ",
      "               !",
      "        gggggggg",
      "        gggggggg",
      "              !!",
      "                ",
      "                ",
      "                ",
      "                ",
      "                ",
      "                ",
      "          !     "
    ]
  ]
}