{
  "xsize": 16,
  "zsize": 16,
  "refpalette": "lostcities:base",
  "slices": [
    [
      "vvvvvvvvvvvvvvvv",
      "vvvvvvvvvvvvvvvv",
      "vvvvvvvvvvvvvvvv",
      "vvvvvvvvvvvvvvvv",
      "vvvvvvvvvvvvvvvv",
      "vvvvvvvvvvvvvvvv",
      "vvvvvvvvvvvvvvvv",
      "vvvvvvvvvvvvvvvv",
      "vvvvvvvvvvvvvvvv",
      "vvvvvvvvvvvvvvvv",
      "vvvvvvvvvvvvvvvv",
      "vvvvvvvvvvvvvvvv",
      "vvvvvvvvvvvvvvvv",
      "vvvvvvvvvvvvvvvv",
      "vvvvvvvvvvvvvvvv",
      "vvvvvvvvvvvvvvvv"
    ],
    [
      "                ",
      "                ",
      "        Ͳ       ",
      "                ",
      "      n  n !!   ",
      "        !!!!    ",
      "    n    ! n    ",
      "  Ͳ             ",
      "             Ͳ  ",
      "    n      n    ",
      "                ",
      "      n  n      ",
      "                ",
      "       Ͳ        ",
      "                ",
      "                "
    ],
    [
      "                ",
      "                ",
      "        Ͳ       ",
      "                ",
      "      n  n!     ",
      "        !!!!    ",
      "    n    !!n    ",
      "  Ͳ             ",
      "     !!      Ͳ  ",
      "    n!     n    ",
      "                ",
      "      n  n      ",
      "                ",
      "       Ͳ        ",
      "                ",
      "                "
    ],
    [
      "                ",
      "                ",
      "        Ͳ       ",
      "                ",
      "      ffff!     ",
      "     ffffff!    ",
      "    ffffffff    ",
      "  Ͳ ffffffff    ",
      "    ffffffff Ͳ  ",
      "   !ffffffff    ",
      "    !ffffff     ",
      "      ffff      ",
      "                ",
      "       Ͳ        ",
      "                ",
      "                "
    ],
    [
      "                ",
      "                ",
      "        Ͳ       ",
      "                ",
      "      ffff!     ",
      "     f   !f!    ",
      "    f !!! !f    ",
      "  Ͳ f!!!!  f    ",
      "    f!!!   f Ͳ  ",
      "   !f!!    f    ",
      "    !f    f     ",
      "      ffff      ",
      "                ",
      "       Ͳ        ",
      "                ",
      "                "
    ],
    [
      "                ",
      "                ",
      "        Ͳ       ",
      "                ",
      "      ffff!     ",
      "     f  !!f!    ",
      "    f  !!!!f    ",
      "  Ͳ f !!!! f    ",
      "    f !!!  f Ͳ  ",
      "   !f!     f    ",
      "    !f    f     ",
      "      ffff      ",
      "                ",
      "       Ͳ        ",
      "                ",
      "                "
    ]
  ]
}