{
  "xsize": 16,
  "zsize": 16,
  "refpalette": "lostcities:base",
  "slices": [
    [
      "gggggggggggggggg",
      "gggggggggggggggg",
      "gggggggggggggggg",
      "gggggggggggggggg",
      "gggggggggggggggg",
      "gggggggggggggggg",
      "gggggggggggggggg",
      "gggggggggggggggg",
      "gggggggggggggggg",
      "gggggggggggggggg",
      "ggggggggͿggggggg",
      "gggggggggggggggg",
      "gggggggggggggggg",
      "gggggggggggggggg",
      "gggggggggggggggg",
      "gggggggggggggggg"
    ],
    [
      "nnn          nnn",
      "ngn          ngn",
      "nnn          nnn",
      "                ",
      "                ",
      "                ",
      "       ΂΃ n     ",
      " !     ggg      ",
      "!!!      g      ",
      " !     g g      ",
      "                ",
      "                ",
      "                ",
      "nnn          nnn",
      "ngn          ngn",
      "nnn          nnn"
    ],
    [
      " n            n ",
      "ngn          ngn",
      " n            n ",
      "                ",
      "                ",
      "                ",
      "        ΂΄n     ",
      "!!     hpi      ",
      "!!!    z z      ",
      " !     jpk      ",
      "                ",
      "                ",
      "                ",
      " n            n ",
      "ngn          ngn",
      " n            n "
    ],
    [
      "                ",
      " g            g ",
      "                ",
      "                ",
      "                ",
      "                ",
      "!!       ΂Ͳ     ",
      "!!!    hpi;     ",
      "!!!    z z      ",
      " !     ͽ ͽ      ",
      "                ",
      "                ",
      "                ",
      "                ",
      " g            g ",
      "                "
    ],
    [
      "                ",
      " g            g ",
      "                ",
      "                ",
      "                ",
      "                ",
      "!               ",
      "!!     hpi΅     ",
      "!!     z z;     ",
      "       jpk      ",
      "          n     ",
      "                ",
      "                ",
      "                ",
      " g            g ",
      "                "
    ],
    [
      "                ",
      " g            g ",
      "                ",
      "                ",
      "                ",
      "                ",
      "!               ",
      "!!!!   hpi      ",
      "!      z z΅     ",
      "       jpk;     ",
      "          n!    ",
      "                ",
      "                ",
      "                ",
      " g            g ",
      "                "
    ]
  ]
}