{
  "xsize": 16,
  "zsize": 16,
  "refpalette": "lostcities:base",
  "slices": [
    [
      "                ",
      " ʹʹʹʹʹʹʹʹʹʹʹʹʹʹ ",
      " ʹʹʹʹʹʹʹʹʹʹʹʹʹʹ ",
      " ʹʹʹʹʹʹʹʹʹʹʹʹʹʹ ",
      " ʹʹʹʹʹʹʹʹʹʹʹʹʹʹ ",
      " ʹʹʹʹʹʹʹʹʹʹʹʹʹʹ!",
      " ʹʹ ʹʹʹʹʹʹʹʹʹʹʹ!",
      "     ʹʹʹʹʹʹʹʹʹʹ!",
      "     ʹʹʹʹʹʹʹʹʹʹ ",
      " ʹ   ʹʹʹʹʹʹʹʹʹʹ ",
      " ʹʹʹʹʹʹʹʹʹʹʹʹʹʹ ",
      " ʹʹʹ ʹ!! ʹʹʹʹʹʹ ",
      " ʹʹʹ!     ʹʹʹʹʹ ",
      " ʹʹʹ!!   ʹʹʹʹʹʹ ",
      " ʹʹʹʹ! ʹʹʹʹʹʹʹʹ ",
      "   !!           "
    ],
    [
      "                ",
      " fppppppppppppf ",
      " z            z ",
      " z   ʹʹ  ʹʹ   z ",
      " z  fff  fff  z ",
      " z ʹfff  fffʹ z ",
      " z ʹffffffffʹ!z!",
      " z  ffffffff !z!",
      " z  ffffffff!!z ",
      " z  ffffffffʹ!z ",
      " z ʹffffffffʹ z ",
      " z    !! fff  z ",
      " z        ʹ   z ",
      " z !!         z ",
      " fpp!   ppppppf ",
      "   !            "
    ],
    [
      "                ",
      "                ",
      "                ",
      "     ʹʹ  ʹʹ     ",
      "    fff  fff    ",
      "   ʹf      fʹ   ",
      "   ʹf      fʹ ! ",
      "    f      f !! ",
      "    f !!   f!!! ",
      "   ʹf!!!!  fʹ!  ",
      "   ʹ  !!   fʹ   ",
      "         fff    ",
      "          ʹ     ",
      "                ",
      "   !            ",
      "                "
    ],
    [
      "                ",
      "                ",
      "                ",
      "      ʹ  ʹ      ",
      "    f      f    ",
      "                ",
      "              ! ",
      "    f      f !!!",
      "    f !    f!!!!",
      "     !!!     !! ",
      "     !!!        ",
      "      !    f    ",
      "                ",
      "                ",
      "                ",
      "                "
    ],
    [
      "                ",
      "                ",
      "                ",
      "    ʹʹʹʹʹʹʹʹ    ",
      "   ʹffffffffʹ   ",
      "   ʹf      fʹ   ",
      "   ʹf      fʹ ! ",
      "   ʹf      fʹ!!!",
      "   ʹf      fʹ!! ",
      "   ʹf!!    fʹ   ",
      "   ʹf!!!   fʹ   ",
      "     !!fffffʹ   ",
      "         ʹʹʹ    ",
      "                ",
      "                ",
      "                "
    ],
    [
      "                ",
      "                ",
      "                ",
      "     ʹ    ʹ     ",
      "    ffffffff    ",
      "   ʹffffffffʹ   ",
      "    ffffffff  ! ",
      "    ffffffff !!!",
      "    ffffffff !! ",
      "    ffffffff    ",
      "   ʹffffffffʹ   ",
      "     !ffffff    ",
      "          ʹ     ",
      "                ",
      "                ",
      "                "
    ]
  ]
}