{
  "xsize": 16,
  "zsize": 16,
  "refpalette": "lostcities:base",
  "slices": [
    [
      "ng        gg  gg",
      " goooooooogggggg",
      " g        gg  gg",
      "ggg             ",
      "ggg          hi ",
      "!mg          jk ",
      " m              ",
      " m              ",
      " m              ",
      " m              ",
      " m              ",
      " m              ",
      "                ",
      "                ",
      "  g             ",
      "                "
    ],
    [
      " g    !   gg  gg",
      " goooooooogggggg",
      " g    !   gg  gg",
      "ggg             ",
      "ggg          hi ",
      "!mg          jk ",
      " m              ",
      " m              ",
      " m              ",
      " m              ",
      " m              ",
      " m              ",
      " m              ",
      " m              ",
      "ggg             ",
      " g              "
    ],
    [
      "gg    !   gg  gg",
      " goooooooogggggg",
      " g    !   gg  gg",
      "ggg             ",
      "ggg          hi ",
      "!mg          jk ",
      " m              ",
      " m              ",
      " m              ",
      " m              ",
      " m              ",
      " m              ",
      " m              ",
      " m              ",
      "ggg             ",
      " g              "
    ],
    [
      " g   !!   gg  gg",
      " goooooooogggggg",
      " g   !!   gg  gg",
      "ggg             ",
      "ggg          hi ",
      "!mg          jk ",
      "!m!             ",
      " m              ",
      " m              ",
      " m              ",
      " m              ",
      " m              ",
      " m              ",
      " m              ",
      "ggg             ",
      " g              "
    ],
    [
      " g  !!    gg  gg",
      " goooooooogggggg",
      " g  !!    gg  gg",
      "ggg             ",
      "ggg          hi ",
      " mg          jk ",
      "!m!             ",
      "!m!             ",
      " m              ",
      " m              ",
      " m              ",
      " m              ",
      " m              ",
      " m              ",
      "ggg             ",
      " g              "
    ],
    [
      "gg  !     gg  gg",
      " goooooooogggggg",
      " g  !     gg  gg",
      "ggg             ",
      "ggg          hi ",
      " mg          jk ",
      " m              ",
      "!m!             ",
      "!m!             ",
      " m              ",
      " m              ",
      " m              ",
      " m              ",
      " m              ",
      "ggg             ",
      " g              "
    ]
  ]
}