{
  "xsize": 16,
  "zsize": 16,
  "refpalette": "lostcities:base",
  "slices": [
    [
      "ggg             ",
      "ggg             ",
      "ggg             ",
      "ggg             ",
      "ggg             ",
      "ggg             ",
      "ggg             ",
      "ggg          hi ",
      "ggg          jk ",
      "ggg             ",
      "ggg             ",
      "ggg             ",
      "ggg             ",
      "ggg             ",
      "ggg             ",
      "ggg             "
    ],
    [
      "ggg             ",
      "ggg             ",
      "ggg             ",
      "ggg             ",
      "ggg             ",
      "ggg             ",
      "ggg             ",
      "ggg          hi ",
      "ggg          jk ",
      "ggg             ",
      "ggg             ",
      "ggg             ",
      "ggg             ",
      "ggg             ",
      "ggg             ",
      "ggg             "
    ],
    [
      "ggg             ",
      " m              ",
      " m              ",
      " m              ",
      " m              ",
      " m              ",
      " m              ",
      " m           hi ",
      " m           jk ",
      " m              ",
      " m              ",
      " m              ",
      " m              ",
      " m              ",
      " m              ",
      "ggg             "
    ],
    [
      "ggg             ",
      "                ",
      "                ",
      "                ",
      "                ",
      "                ",
      "                ",
      "             ff ",
      "             ff ",
      "                ",
      "                ",
      "                ",
      "                ",
      "                ",
      "                ",
      "ggg             "
    ],
    [
      "ggg          ff ",
      "  f          ff ",
      "  f          ff ",
      "  f          ff ",
      "  f          ff ",
      "  f          ff ",
      "  f         ffff",
      "  fffffffffffxxf",
      "  f fffffffffxxf",
      "  f         ffff",
      "  f          ff ",
      "  f          ff ",
      "  f          ff ",
      "  f          ff ",
      "  f          ff ",
      "ggg          ff "
    ],
    [
      "ggggͱͱͱͱͱͱͱggggg",
      "ggggͱͱͱͱͱͱͱggggg",
      "ggggͱͱͱͱͱͱͱggggg",
      "ggggͱͱͱͱͱͱͱggggg",
      "ggggͱͱͱͱͱͱͱggggg",
      "gggggggggggggggg",
      "gggggggggggggggg",
      "gggggggggggggggg",
      "gggggggggggggggg",
      "gggggggggggggggg",
      "gggggggggggggggg",
      "ggggͱͱͱͱͱͱͱggggg",
      "ggggͱͱͱͱͱͱͱggggg",
      "ggggͱͱͱͱͱͱͱggggg",
      "ggggͱͱͱͱͱͱͱggggg",
      "ggggͱͱͱͱͱͱͱggggg"
    ]
  ]
}