{
  "xsize": 16,
  "zsize": 16,
  "refpalette": "lostcities:base",
  "slices": [
    [
      "  ͶͶͶͶͶͶͶͶYͶ    ",
      " ͱͱͶͶͶͶͶͶͶYͶ    ",
      " ͱͱͶͶͶͶͶͶY!Ͷ!   ",
      "    ͶͶͶͶY !!Ͷ!  ",
      "           !Ͷ!  ",
      "            !Ͷ  ",
      "              Ͷ ",
      "               Ͷ",
      "                ",
      "              ͶͶ",
      "             Ͷ  ",
      "            Ͷ   ",
      "            Ͷ   ",
      "            Ͷ   ",
      "            Ͷ   ",
      "             Ͷ  "
    ],
    [
      "   ͶͶͶͶͶͶͶYͶ    ",
      "  ͱͶͶͶͶͶͶͶYͶ    ",
      "  ͱͶͶͶͶͶͶY!Ͷ!   ",
      "     ͶͶͶY  !Ͷ   ",
      "            Ͷ   ",
      "             Ͷ  ",
      "              Ͷ ",
      "               Ͷ",
      "                ",
      "              gg",
      "             ggg",
      "            gggg",
      "            gggg",
      "            gggg",
      "            gggg",
      "             ggg"
    ],
    [
      "   ͶͶͶͶͶͶͶYͶ    ",
      "   ͶͶͶͶͶͶͶYͶ    ",
      "    ͶͶͶͶͶY!Ͷ!   ",
      "       YY  !Ͷ   ",
      "            Ͷ   ",
      "             Ͷ  ",
      "              Ͷ ",
      "               Ͷ",
      "                ",
      "              gg",
      "             ggg",
      "            gggg",
      "            gggg",
      "            gggg",
      "            gggg",
      "             ggg"
    ],
    [
      "    ͶͶͶͶͶͶYͶ    ",
      "    ͶͶͶͶͶͶYͶ    ",
      "     ͶͶͶͶY!Ͷ!   ",
      "       YY  !Ͷ   ",
      "            Ͷ   ",
      "             Ͷ  ",
      "              Ͷ ",
      "               Ͷ",
      "                ",
      "              gg",
      "             ggg",
      "            gggg",
      "            gggg",
      "            gggg",
      "            gggg",
      "             ggg"
    ],
    [
      "    ͶͶͶͶͶͶYͶ    ",
      "     ͶͶͶͶͶYͶ    ",
      "      ͶͶͶY!Ͷ!   ",
      "       YY  !Ͷ   ",
      "            Ͷ   ",
      "             Ͷ  ",
      "              Ͷ ",
      "               Ͷ",
      "                ",
      "               g",
      "             gg ",
      "             g  ",
      "            g   ",
      "            g   ",
      "             g  ",
      "             gg "
    ],
    [
      "     ͶͶͶͶͶYͶ    ",
      "      ͶͶͶͶYͶ    ",
      "       ͶͶY!Ͷ!   ",
      "       YY  !Ͷ   ",
      "            Ͷ   ",
      "             Ͷ  ",
      "              Ͷ ",
      "               Ͷ",
      "                ",
      "                ",
      "              gg",
      "             g  ",
      "             g  ",
      "             g  ",
      "             g  ",
      "              gg"
    ]
  ]
}