{
  "xsize": 16,
  "zsize": 16,
  "refpalette": "lostcities:base",
  "slices": [
    [
      "gggggggggggggggg",
      "gggggggggggggggg",
      "gggggggggggggggg",
      "gggggggggggggggg",
      "gggggggggggggggg",
      "gggggggggggggggg",
      "gggggggggggggggg",
      "gggggggggggggggg",
      "gg ggggg ggggggg",
      "     ggggggggggg",
      "     gg   gggggg",
      "     ggggggggggg",
      "g    ggggggggggg",
      "ggg ggggggg  ggg",
      "gggggggggggg  gg",
      "ggggggggggg!   g"
    ],
    [
      "nnn          nnn",
      "ngnYYYYYYYYYYngn",
      "nn           nnn",
      " Y            Y ",
      " Y            Y ",
      " Y            Y ",
      " Y     gg     Y ",
      " Y     ggg    Y ",
      "       z      Y ",
      "              Y ",
      "      !       Y ",
      "     !!!      Y ",
      "     !!!      Y ",
      "nn   !!! !    nn",
      "ngnYYYYYYY!   gn",
      "nnn   !! !!    n"
    ],
    [
      " n            n ",
      "ngnYY      YYngn",
      " n            n ",
      " Y            Y ",
      " Y            Y ",
      "                ",
      "        gg    Y ",
      "        yu      ",
      "              Y ",
      "                ",
      "              Y ",
      "      !         ",
      " Y   !!!      Y ",
      " n   !!! !    n ",
      "ngnY Y!Y!Y!   gn",
      " n       !    n "
    ],
    [
      "                ",
      " g YYYYYYYYYY g ",
      "                ",
      " Y            Y ",
      " Y            Y ",
      " Y              ",
      " Y       gg   Y ",
      "        pu;     ",
      "              Y ",
      "                ",
      "              Y ",
      "                ",
      " Y    !       Y ",
      "     !!!!!      ",
      " g Y Y!Y!Y!   g ",
      "      ! !!      "
    ],
    [
      "                ",
      " g YYYYYYYYYY g ",
      "                ",
      " Y!!!!        Y ",
      " Y!           Y ",
      " Y            Y ",
      " Y            Y ",
      "        ptg   Y ",
      "          ;   Y ",
      "              Y ",
      "              Y ",
      " Y            Y ",
      " Y            Y ",
      "      ! !!      ",
      " g YYYYYY!!   g ",
      "     !!!!!      "
    ],
    [
      "gggggggggggggggg",
      "gggggggggggggggg",
      "gggggggggggggggg",
      "gggggggggggggggg",
      "gggggggggggggggg",
      "gggggggggg ggggg",
      " ggggggg   ggggg",
      " g ggggggg ggggg",
      " g ggggg ggggggg",
      " g ggggggggggggg",
      "ggggggggͿ΀Ͳggggg",
      "gggggggggggggggg",
      "gggggggggggggggg",
      "gggggggggg  gggg",
      "gggggggggg! gggg",
      "ggggggggg!   ggg"
    ]
  ]
}