{
  "xsize": 16,
  "zsize": 16,
  "refpalette": "lostcities:base",
  "slices": [
    [
      "ggg   gggggg    ",
      "gggg gggggggg   ",
      "gggg gggggggg!  ",
      "gggg gggggggg   ",
      "gggg gggggggg   ",
      "ggg   gggggg    ",
      "gg     gggg     ",
      " ͶͶͶͶͶͶ         ",
      "Ͷ      ͶͶ       ",
      "         Ͷ      ",
      "          Ͷ     ",
      "           Ͷ    ",
      "           Ͷ    ",
      "            Ͷ   ",
      "            Ͷ   ",
      "            Ͷ   "
    ],
    [
      "ggg   gggggg    ",
      "gggg gggggggg   ",
      "gggg gggggggg!  ",
      "gggg gggggggg   ",
      "gggg gggggggg   ",
      "ggg   gggggg    ",
      "gg     gggg     ",
      " ͶͶͶͶͶͶ         ",
      "Ͷ      ͶͶ       ",
      "         Ͷ      ",
      "          Ͷ     ",
      "           Ͷ    ",
      "           Ͷ    ",
      "            Ͷ   ",
      "            Ͷ   ",
      "            Ͷ   "
    ],
    [
      "  Ͷ   Ͷ    Ͷ    ",
      "   Ͷ Ͷ      Ͷ   ",
      "   Ͷ Ͷ     !Ͷ!  ",
      "   Ͷ Ͷ      Ͷ   ",
      "   Ͷ Ͷ      Ͷ   ",
      "  Ͷ   Ͷ    Ͷ    ",
      "ͶͶ     ͶͶͶͶ     ",
      " ͶͶͶͶͶͶ         ",
      "Ͷ      ͶͶ       ",
      "         Ͷ      ",
      "          Ͷ     ",
      "           Ͷ    ",
      "           Ͷ    ",
      "            Ͷ   ",
      "            Ͷ   ",
      "            Ͷ   "
    ],
    [
      "  Ͷ   Ͷ    Ͷ    ",
      "   Ͷ Ͷ      Ͷ   ",
      "   Ͷ Ͷ     !Ͷ!  ",
      "   Ͷ Ͷ      Ͷ   ",
      "   Ͷ Ͷ      Ͷ   ",
      "  Ͷ   Ͷ    Ͷ    ",
      "ͶͶ     ͶͶͶͶ     ",
      " ͶͶͶͶͶͶ         ",
      "Ͷ      ͶͶ       ",
      "         Ͷ      ",
      "          Ͷ     ",
      "           Ͷ    ",
      "           Ͷ    ",
      "            Ͷ   ",
      "            Ͷ   ",
      "            Ͷ   "
    ],
    [
      "  Ͷ   Ͷ    Ͷ    ",
      "   Ͷ Ͷ      Ͷ   ",
      "   Ͷ Ͷ     !Ͷ!  ",
      "   Ͷ Ͷ      Ͷ   ",
      "   Ͷ Ͷ      Ͷ   ",
      "  Ͷ   Ͷ    Ͷ    ",
      "ͶͶ     ͶͶͶͶ     ",
      " ͶͶͶͶͶͶ         ",
      "Ͷ      ͶͶ       ",
      "         Ͷ      ",
      "          Ͷ     ",
      "           Ͷ    ",
      "           Ͷ    ",
      "            Ͷ   ",
      "            Ͷ   ",
      "            Ͷ   "
    ],
    [
      "  Ͷ   Ͷ    Ͷ    ",
      "   Ͷ Ͷ      Ͷ   ",
      "   Ͷ Ͷ     !Ͷ!  ",
      "   Ͷ Ͷ      Ͷ   ",
      "   Ͷ Ͷ      Ͷ   ",
      "  Ͷ   Ͷ    Ͷ    ",
      "ͶͶ     ͶͶͶͶ     ",
      " ͶͶͶͶͶͶ         ",
      "Ͷ      ͶͶ       ",
      "         Ͷ      ",
      "          Ͷ     ",
      "           Ͷ    ",
      "           Ͷ    ",
      "            Ͷ   ",
      "            Ͷ   ",
      "            Ͷ   "
    ]
  ]
}