{
  "xsize": 16,
  "zsize": 16,
  "refpalette": "lostcities:base",
  "slices": [
    [
      "vvvvvvvvvvvvvvvv",
      "vvvvvvvvvvvvvvvv",
      "vvvvvvvvvvvvvvvv",
      "vvvvvvvvvvvvvvvv",
      "vvvvvvvvvvvvvvvv",
      "vvvvvvvvvvvvvvvv",
      "vvvvvvvvvvvvvvvv",
      "vvvvvvvvvvvvvvvv",
      "vvvvvvvvvvvvvvvv",
      "vvvvvvvvvvvvvvvv",
      "vvvvvvvvvvvvvvvv",
      "vvvvvvvvvvvvvvvv",
      "vvvvvvvvvvvvvvvv",
      "vvvvvvvvvvvvvvvv",
      "vvvvvvvvvvvvvvvv",
      "vvvvvvvvvvvvvvvv"
    ],
    [
      "    ggg   gggggg",
      "    gggggggggggg",
      "    gggggggggggg",
      "   ggggggggggggg",
      "   ggggggggggggg",
      "   ggggggggggggg",
      "   ggggggggggggg",
      "   ggggggggggggg",
      "   ggggggggggggg",
      "   Ygggggggggggg",
      "   Ygggggggggggg",
      "   Ygggggggggggg",
      "   Ygggggggggggg",
      "   ggggggggggggg",
      "   ggggggggggggg",
      "   ggggggggggggg"
    ],
    [
      "    gg          ",
      "    ggg         ",
      "    ggg         ",
      "    ggg         ",
      "   gggg         ",
      "   gggg         ",
      "   gggg         ",
      "   gggg         ",
      "   gggg         ",
      "    Y           ",
      "    Y           ",
      "    Y           ",
      "    Y        !! ",
      "   gggg     !!!!",
      "   gggg    !!!! ",
      "   gggg   !!!!  "
    ],
    [
      "                ",
      "    ggg         ",
      "    ggg         ",
      "    ggg         ",
      "   gggg         ",
      "   gggg         ",
      "   gggg         ",
      "   gggg         ",
      "   gggg         ",
      "     Y          ",
      "     Y          ",
      "     Y        ! ",
      "     Y       !! ",
      "   gggg     !!! ",
      "   gggg   !!!!  ",
      "   gggg  !!!!   "
    ],
    [
      "              gg",
      "         ggggggg",
      "       ggggggggg",
      "      gggggggggg",
      "   ggggggggggggg",
      "   ggggggggggggg",
      "   ggggggggggggg",
      "   ggggggggggggg",
      "   ggggggggggggg",
      "      gggggggggg",
      "      gggggggggg",
      "      gggggggggg",
      "      ggggg gggg",
      "   gggggggg !ggg",
      "   gggggggg  ggg",
      "   ggggggggggggg"
    ],
    [
      "             ggg",
      "            gggg",
      "            gggg",
      "            gggg",
      "            gggg",
      "            gggg",
      "            gggg",
      "            gggg",
      "            gggg",
      "           Ygggg",
      "           Ygggg",
      "             !!g",
      "             !!!",
      "             !  ",
      "                ",
      "         !!    g"
    ]
  ]
}