{
  "xsize": 16,
  "zsize": 16,
  "refpalette": "lostcities:base",
  "slices": [
    [
      "Ͷ        ͶYͶ    ",
      "Ͷ        ͶYͶ    ",
      " Ͷ      ͶYYͶ    ",
      " ͶͶ    ͶͶY  Ͷ   ",
      "   ͶͶͶͶYYY  Ͷ!  ",
      "            !Ͷ! ",
      "             !Ͷ ",
      "               Ͷ",
      "                ",
      "              ͶͶ",
      "             Ͷ  ",
      "            Ͷ   ",
      "            Ͷ   ",
      "            Ͷ   ",
      "            Ͷ   ",
      "             Ͷ  "
    ],
    [
      "Ͷ        ͶYͶ    ",
      "Ͷ        ͶYͶ    ",
      " Ͷ      ͶYYͶ    ",
      " ͶͶ    ͶͶY  Ͷ   ",
      "   ͶͶͶͶYYY  Ͷ!  ",
      "            !Ͷ! ",
      "             !Ͷ ",
      "               Ͷ",
      "                ",
      "              ͶͶ",
      "             Ͷ  ",
      "            Ͷ   ",
      "            Ͷ   ",
      "            Ͷ   ",
      "            Ͷ   ",
      "             Ͷ  "
    ],
    [
      "Ͷ        ͶYͶ    ",
      "Ͷ        ͶYͶ    ",
      " Ͷ      ͶYYͶ    ",
      " ͶͶ    ͶͶY  Ͷ   ",
      "   ͶͶͶͶYYY  Ͷ!  ",
      "            !Ͷ! ",
      "             !Ͷ ",
      "               Ͷ",
      "                ",
      "              ͶͶ",
      "             Ͷ  ",
      "            Ͷ   ",
      "            Ͷ   ",
      "            Ͷ   ",
      "            Ͷ   ",
      "             Ͷ  "
    ],
    [
      "Ͷ        ͶYggggg",
      "Ͷ        ͶYggggg",
      " Ͷ      ͶYYggggg",
      " ͶͶ    ͶͶY  gggg",
      "   ͶͶͶͶYYY  gggg",
      "            !ggg",
      "             !gg",
      "               g",
      "                ",
      "              ͶͶ",
      "             Ͷ  ",
      "            Ͷ   ",
      "            Ͷ   ",
      "            Ͷ   ",
      "            Ͷ   ",
      "             Ͷ  "
    ],
    [
      "Ͷ        ͶYggggg",
      "Ͷ        ͶYggggg",
      " Ͷ      ͶYYggggg",
      " ͶͶ    ͶͶY  gggg",
      "   ͶͶͶͶYYY  gggg",
      "            !ggg",
      "             !gg",
      "               g",
      "                ",
      "              ͶͶ",
      "             Ͷ  ",
      "            Ͷ   ",
      "            Ͷ   ",
      "            Ͷ   ",
      "            Ͷ   ",
      "             Ͷ  "
    ],
    [
      "Ͷ        ͶYͶ    ",
      "Ͷ        ͶYͶ    ",
      " Ͷ      ͶYYͶ    ",
      " ͶͶ    ͶͶY  Ͷ   ",
      "   ͶͶͶͶYYY  Ͷ!  ",
      "            !Ͷ! ",
      "             !Ͷ ",
      "               Ͷ",
      "                ",
      "              ͶͶ",
      "             Ͷ  ",
      "            Ͷ   ",
      "            Ͷ   ",
      "            Ͷ   ",
      "            Ͷ   ",
      "             Ͷ  "
    ]
  ]
}