{
  "xsize": 16,
  "zsize": 16,
  "refpalette": "lostcities:base",
  "slices": [
    [
      "            Ͷ   ",
      "            Ͷ   ",
      "           !Ͷ!  ",
      "           Ͷ!   ",
      "           Ͷ    ",
      "          Ͷ     ",
      "         Ͷ      ",
      "Ͷ      ͶͶ       ",
      " ͶͶͶͶͶͶ         ",
      "ͶͶ     ͶͶͶͶ     ",
      "  Ͷ   Ͷ    Ͷ    ",
      "   Ͷ Ͷ      Ͷ   ",
      "   Ͷ Ͷ      Ͷ   ",
      "   Ͷ Ͷ      Ͷ   ",
      "   Ͷ Ͷ      Ͷ   ",
      "  Ͷ   Ͷ    Ͷ    "
    ],
    [
      "            Ͷ   ",
      "            Ͷ   ",
      "           !Ͷ!  ",
      "           Ͷ!   ",
      "           Ͷ    ",
      "          Ͷ     ",
      "         Ͷ      ",
      "Ͷ      ͶͶ       ",
      " ͶͶͶͶͶͶ         ",
      "ͶͶ     ͶͶͶͶ     ",
      "  Ͷ   Ͷ    Ͷ    ",
      "   Ͷ Ͷ      Ͷ   ",
      "   Ͷ Ͷ      Ͷ   ",
      "   Ͷ Ͷ      Ͷ   ",
      "   Ͷ Ͷ      Ͷ   ",
      "  Ͷ   Ͷ    Ͷ    "
    ],
    [
      "            Ͷ   ",
      "            Ͷ   ",
      "           !Ͷ!  ",
      "           Ͷ!   ",
      "           Ͷ    ",
      "          Ͷ     ",
      "         Ͷ      ",
      "Ͷ      ͶͶ       ",
      " ͶͶͶͶͶͶ         ",
      "ͶͶ     ͶͶͶͶ     ",
      "  Ͷ   Ͷ    Ͷ    ",
      "   Ͷ Ͷ      Ͷ   ",
      "   Ͷ Ͷ      Ͷ   ",
      "   Ͷ Ͷ      Ͷ   ",
      "   Ͷ Ͷ      Ͷ   ",
      "  Ͷ   Ͷ    Ͷ    "
    ],
    [
      "ggggggggggggg   ",
      "ggggggggggggg!  ",
      "ggggggggggggg!  ",
      "gggggggggggg!   ",
      "gggggggggggg    ",
      "ggggggggggg     ",
      "gggggggggg      ",
      "ggggggggg       ",
      " gggggg         ",
      "ͶͶ     ͶͶͶͶ     ",
      "  Ͷ   Ͷ    Ͷ    ",
      "   Ͷ Ͷ      Ͷ   ",
      "   Ͷ Ͷ      Ͷ   ",
      "   Ͷ Ͷ      Ͷ   ",
      "   Ͷ Ͷ      Ͷ   ",
      "  Ͷ   Ͷ    Ͷ    "
    ],
    [
      "ggggggggggggg   ",
      "ggggggggggggg!  ",
      "ggggggggggggg   ",
      "gggggggggggg    ",
      "gggggggggggg    ",
      "ggggggggggg     ",
      "gggggggggg      ",
      "ggggggggg       ",
      " gggggg         ",
      "ͶͶ     ͶͶͶͶ     ",
      "  Ͷ   Ͷ    Ͷ    ",
      "   Ͷ Ͷ      Ͷ   ",
      "   Ͷ Ͷ      Ͷ   ",
      "   Ͷ Ͷ      Ͷ   ",
      "   Ͷ Ͷ      Ͷ   ",
      "  Ͷ   Ͷ    Ͷ    "
    ],
    [
      "            Ͷ   ",
      "           !Ͷ!  ",
      "            Ͷ   ",
      "           Ͷ    ",
      "           Ͷ    ",
      "          Ͷ     ",
      "         Ͷ      ",
      "Ͷ      ͶͶ       ",
      " ͶͶͶͶͶͶ         ",
      "ͶͶ     ͶͶͶͶ     ",
      "  Ͷ   Ͷ    Ͷ    ",
      "   Ͷ Ͷ      Ͷ   ",
      "   Ͷ Ͷ      Ͷ   ",
      "   Ͷ Ͷ      Ͷ   ",
      "   Ͷ Ͷ      Ͷ   ",
      "  Ͷ   Ͷ    Ͷ    "
    ]
  ]
}