{
  "xsize": 16,
  "zsize": 16,
  "refpalette": "lostcities:base",
  "slices": [
    [
      "      ͳY     ggg",
      "            gggg",
      "            gggg",
      "            gggg",
      "      !     gggg",
      "     !!!     ggg",
      "      !       gg",
      "                ",
      "               g",
      "              g ",
      "             g  ",
      "   ͶͶͶͶYY   g   ",
      " ͶͶ   ͶͶͶY  g   ",
      " Ͷ      ͶY g    ",
      "Ͷ        ͶYg    ",
      "Ͷ        ͶYg    "
    ],
    [
      "      ͶY     Ͷ  ",
      "      ͶY    Ͷ   ",
      "      ͶY    Ͷ   ",
      "      ͶY    Ͷ   ",
      "      ͶY    Ͷ   ",
      "     !ͶY     Ͷ  ",
      "      ͶY      ͶͶ",
      "      ͶY        ",
      "      ͶY       g",
      "      ͶY      g ",
      "      ͶY     g  ",
      "   ͶͶͶͶYYY  g   ",
      " ͶͶ    ͶͶY  g   ",
      " Ͷ      ͶYYg    ",
      "Ͷ        ͶYg    ",
      "Ͷ        ͶYg    "
    ],
    [
      "      ͶY     Ͷ  ",
      "      ͶY    Ͷ   ",
      "      ͶY    Ͷ   ",
      "      ͶY    Ͷ   ",
      "      ͶY    Ͷ   ",
      "     !ͶY     Ͷ  ",
      "      ͶY      ͶͶ",
      "      ͶY        ",
      "      ͶY       g",
      "      ͶY      g ",
      "      ͶY     g  ",
      "   ͶͶͶͶYYY  g   ",
      " ͶͶ    ͶͶY  g   ",
      " Ͷ      ͶYYg    ",
      "Ͷ        ͶYg    ",
      "Ͷ        ͶYg    "
    ],
    [
      "      ͶY     Ͷ  ",
      "      ͶY    Ͷ   ",
      "      ͶY    Ͷ   ",
      "      ͶY    Ͷ   ",
      "      ͶY    Ͷ   ",
      "     !ͶY     Ͷ  ",
      "     !ͶY      ͶͶ",
      "      ͶY        ",
      "      ͶY       g",
      "      ͶY      gg",
      "      ͶY     ggg",
      "   ͶͶͶͶYYY  gggg",
      " ͶͶ    ͶͶY  gggg",
      " Ͷ      ͶYYggggg",
      "Ͷ        ͶYggggg",
      "Ͷ        ͶYggggg"
    ],
    [
      "      ͶY     Ͷ  ",
      "      ͶY    Ͷ   ",
      "      ͶY    Ͷ   ",
      "      ͶY    Ͷ   ",
      "      ͶY    Ͷ   ",
      "      ͶY     Ͷ  ",
      "     !ͶY      ͶͶ",
      "      ͶY        ",
      "      ͶY       Ͷ",
      "      ͶY      Ͷ ",
      "      ͶY     Ͷ  ",
      "   ͶͶͶͶYYY  Ͷ   ",
      " ͶͶ    ͶͶY  Ͷ   ",
      " Ͷ      ͶYYͶ    ",
      "Ͷ        ͶYͶ    ",
      "Ͷ        ͶYͶ    "
    ],
    [
      "      ͶY     Ͷ  ",
      "      ͶY    Ͷ   ",
      "      ͶY    Ͷ   ",
      "      ͶY    Ͷ   ",
      "      ͶY    Ͷ   ",
      "      ͶY     Ͷ  ",
      "     !ͶY      ͶͶ",
      "      ͶY        ",
      "      ͶY       Ͷ",
      "      ͶY      Ͷ ",
      "      ͶY     Ͷ  ",
      "   ͶͶͶͶYYY  Ͷ   ",
      " ͶͶ    ͶͶY  Ͷ   ",
      " Ͷ      ͶYYͶ    ",
      "Ͷ        ͶYͶ    ",
      "Ͷ        ͶYͶ    "
    ]
  ]
}