{
  "xsize": 16,
  "zsize": 16,
  "refpalette": "lostcities:base",
  "slices": [
    [
      "g    g        g ",
      "                ",
      "                ",
      "                ",
      "                ",
      "                ",
      "                ",
      "        YY      ",
      "        YY      ",
      "g    g        g ",
      "                ",
      "                ",
      "                ",
      "                ",
      "                ",
      "gg     gggg     "
    ],
    [
      "g    g        g ",
      "                ",
      "                ",
      "                ",
      "                ",
      "                ",
      "                ",
      "       YY       ",
      "       YY       ",
      "g    g        g ",
      "                ",
      "                ",
      "                ",
      "                ",
      "          !     ",
      "ͶͶ     ͶͶͶͶ!    "
    ],
    [
      "g    g        g ",
      "                ",
      "                ",
      "                ",
      "                ",
      "                ",
      "                ",
      "      YY        ",
      "      YY        ",
      "g    g        g ",
      "                ",
      "                ",
      "                ",
      "                ",
      "          !     ",
      "ͶͶ     ͶͶͶͶ!    "
    ],
    [
      "g    gggggggggg ",
      "g    gYYYYYYYYg ",
      "g    gYYYYYYYYg ",
      "g    gYYYYYYYYg ",
      "g    gYYYYYYYYg ",
      "g    gYYYYYYYYg ",
      "g    gYYYYYYYYg ",
      "g    gY    YYYg ",
      "g    gY    YYYg ",
      "g    gggggggggg ",
      "                ",
      "                ",
      "                ",
      "                ",
      "          !     ",
      "ͶͶ     ͶͶͶͶ!    "
    ],
    [
      "g    g        g ",
      "                ",
      "                ",
      "                ",
      "                ",
      "                ",
      "                ",
      "           YY   ",
      "           YY   ",
      "g    g        g ",
      "                ",
      "                ",
      "                ",
      "                ",
      "          !     ",
      "ͶͶ     ͶͶͶͶ!    "
    ],
    [
      "g    g        g ",
      "                ",
      "                ",
      "                ",
      "                ",
      "                ",
      "                ",
      "          YY    ",
      "          YY    ",
      "g    g        g ",
      "                ",
      "                ",
      "                ",
      "                ",
      "          !!    ",
      "ͶͶ     ͶͶͶͶ!!   "
    ]
  ]
}