{
  "xsize": 16,
  "zsize": 16,
  "refpalette": "lostcities:base",
  "slices": [
    [
      "      g   !!!!gg",
      "          YYYYYg",
      "      YYYYYYYYYg",
      "      YYYYYYYYYg",
      "     ggggggggggg",
      "     !YYYYYYYYY ",
      "      YYYYYYYYY ",
      "      YYYYYYYYY ",
      "      YYYYYYYYY ",
      "      YYYYYYYYY ",
      "      YYYYYYYYY ",
      "      gggggggggg",
      "      YYYYYYYYYg",
      "      YYYYYYYYYg",
      "      YYYYY   Yg",
      "      g        g"
    ],
    [
      "      gg   !gggg",
      "       Y   YYYYg",
      "      YYYYYYYYYg",
      "      YYYYYYYYYg",
      "     ggggggggggg",
      "     !YYYYYYYYY ",
      "      YYYYYYYYY ",
      "      YYYYYYYYY ",
      "      YYYYYYYYY ",
      "      YYYYYYYYY ",
      "      YYYYYYYYY ",
      "      gggggggggg",
      "      YYYYYYYYYg",
      "      YYYYYYYYYg",
      "      YYYYY  YYg",
      "      gg       g"
    ],
    [
      "       g   ggggg",
      "           YYYYg",
      "       YYYYYYYYg",
      "      gYYYYYYYYg",
      "     ggggggggggg",
      "     !!YYYYYYYY ",
      "      !YYYYYYYY ",
      "       YYYYYYYY ",
      "       YYYYYYYY ",
      "       YYYYYYYY ",
      "       YYYYYYYY ",
      "      gggggggggg",
      "      gYYYYYYYYg",
      "      gYYYYYYYYg",
      "       YYYYYYYYg",
      "       g       g"
    ],
    [
      "       g   gg! g",
      "          YYYYYg",
      "       YYYYYYYYg",
      "       YYYYYYYYg",
      "       ggggggggg",
      "      !YYYYYYYY ",
      "       YYYYYYYY ",
      "       YYYYYYYY ",
      "       YYYYYYYY ",
      "       YYYYYYYY ",
      "       YYYYYYYY ",
      "       ggggggggg",
      "       YYYYYYYYg",
      "       YYYYYYYYg",
      "       YYYYYY  g",
      "       g ggg   g"
    ],
    [
      "       g   !!! g",
      "       YYYYYYYYg",
      "       YYYYYYYYg",
      "       YYYYYYYYg",
      "      gggggggggg",
      "     !!YYYYYYYY ",
      "     g!YYYYYYYY ",
      "     g YYYYYYYY ",
      "     g YYYYYYYY ",
      "     g YYYYYYYY ",
      "     g YYYYYYYY ",
      "      gggggggggg",
      "      gYYYYYYYYg",
      "       YYYYYYYYg",
      "       YYYYYYYYg",
      "       gggg    g"
    ],
    [
      "       g    !! g",
      "       YY  YYYYg",
      "       YYYYYYYYg",
      "      gYYYYYYYYg",
      "      gggggggggg",
      "     !!YYYYYYYY ",
      "    !g!YYYYYYYY ",
      "     g!YYYYYYYY ",
      "     g YYYYYYYY ",
      "     g YYYYYYYY ",
      "     g YYYYYYYY ",
      "      gggggggggg",
      "      gYYYYYYYYg",
      "       YYYYYYYYg",
      "       YYYYYYYYg",
      "       ggg     g"
    ]
  ]
}