{
  "xsize": 16,
  "zsize": 16,
  "refpalette": "lostcities:base",
  "slices": [
    [
      "nnnggggggggggnnn",
      "ngnYYYYYYYYYYngn",
      "nngggggggggggnnn",
      "gY!!!gggggggggYg",
      "  !  !ggggggggYg",
      "      gggg gggYg",
      "     ggggg gggYg",
      "   ggggggg gggYg",
      " Ygggggggg gggYg",
      " Ygggggggg gggYg",
      "gYggggggggggggYg",
      "gYggggggggggggYg",
      "gYggggggggggggYg",
      "nnnggggg   ggnnn",
      "ngnYYYYYYY  Yngn",
      "nnnggggg    gnnn"
    ],
    [
      " n            n ",
      "ngnYYYYYYYYYYngn",
      " n    !!!!!   n ",
      "     !!!!!!   Y ",
      "        !!g   Y ",
      "              Y ",
      "              Y ",
      "        pi    Y ",
      " Y            Y ",
      " Y  !         Y ",
      " Y !!!        Y ",
      " Y !!!        Y ",
      " Y !!!!       Y ",
      " n  !!!       n ",
      "ngnYYYYY    Yngn",
      " n   !!       n "
    ],
    [
      "                ",
      " g YY      YY g ",
      "       !!!      ",
      "      !!!!    Y ",
      "       !!     Y ",
      "          g     ",
      "          g   Y ",
      "        pi      ",
      "              Y ",
      "                ",
      "    !         Y ",
      " Y !!!          ",
      " Y !!!        Y ",
      "   !!!!         ",
      " g Y!Y!     Y g ",
      "     !          "
    ],
    [
      "                ",
      " g YYYYYYYYYY g ",
      "      !!        ",
      "     !!!!     Y ",
      "     !!!      Y ",
      "                ",
      "          g   Y ",
      " Y       tg     ",
      " Y            Y ",
      " Y              ",
      " Y            Y ",
      " Y  !           ",
      " Y !!!        Y ",
      "   !!!          ",
      " g Y!!     YY g ",
      "    !           "
    ],
    [
      " n            n ",
      "ngnYYYYYYYYYYngn",
      "      !       n ",
      "     !!!      Y ",
      "    !!!!      Y ",
      "     !!       Y ",
      "              Y ",
      " Y       tg   Y ",
      " Y        g   Y ",
      " Y        g   Y ",
      " Y        ΁   Y ",
      " Y            Y ",
      " Y  !         Y ",
      " n !!!        n ",
      "ngnYY!     YYngn",
      " n  !         n "
    ],
    [
      "gggggggggggggggg",
      "gggggggggggggggg",
      "  gggggggggggggg",
      "    gggggggggggg",
      "   !gggggggggggg",
      "    gggggg ggggg",
      " gggggg  g ggggg",
      "ggggg    g ggggg",
      "gggg     ggggggg",
      "ggg      ggggggg",
      "ggg      ggggggg",
      "gggg    gggggggg",
      "gggggggggggggggg",
      "gggggg    gggggg",
      "ggggg     gggggg",
      "gggg      gggggg"
    ]
  ]
}