{
  "xsize": 16,
  "zsize": 16,
  "refpalette": "lostcities:base",
  "slices": [
    [
      "          f  fʹʹ",
      "          f  ʹff",
      "      !   f     ",
      "     !ffffffff  ",
      "      f   f  ʹff",
      "      f   f  fʹʹ",
      "      f   f  fʹʹ",
      "      f   f  fʹʹ",
      "      f   f  ʹff",
      "      f   f  f  ",
      "      f   f  f  ",
      "      f   f  ʹff",
      "      f   f  fʹʹ",
      "      f   f  fʹʹ",
      "      ffffffffʹʹ",
      "          f  ʹff"
    ],
    [
      "          f  ʹʹʹ",
      "          f  ʹʹʹ",
      "      !!  f     ",
      "     !!fffffff  ",
      "      !f  f  ʹʹʹ",
      "       f  f  ʹʹʹ",
      "       f  f  ʹʹʹ",
      "       f  f  ʹʹʹ",
      "       f  f  ʹʹʹ",
      "       f  f  f  ",
      "       f  f  f  ",
      "       f  f  ʹʹʹ",
      "       f  f  ʹʹʹ",
      "       f  f  ʹʹʹ",
      "       ffffffʹʹʹ",
      "          f  ʹʹʹ"
    ],
    [
      "          f     ",
      "          f  n  ",
      "       !  f     ",
      "      !ffffffff ",
      "      !f! f  nf ",
      "      !f! f   f ",
      "       f  f   f ",
      "       f  f   f ",
      "       f  f  nf ",
      "       f  f   f ",
      "       f  f   f ",
      "       f  f  nf ",
      "       f  f   f ",
      "       f  f   f ",
      "       ffffffff ",
      "          f  n  "
    ],
    [
      "          f  ʹʹʹ",
      "          f  ʹʹʹ",
      "          f     ",
      "       !fffffff ",
      "       !f f  ʹʹʹ",
      "      !!f!f  ʹʹʹ",
      "       !f f  ʹʹʹ",
      "        f f  ʹʹʹ",
      "        f f  ʹʹʹ",
      "        f f   f ",
      "        f f   f ",
      "        f f  ʹʹʹ",
      "        f f  ʹʹʹ",
      "        f f  ʹʹʹ",
      "        fffffʹʹʹ",
      "          f  ʹʹʹ"
    ],
    [
      "          f  fͳͳ",
      "          f  ʹff",
      "          f     ",
      "        ffffffff",
      "        f f  ʹff",
      "       !f!f  f f",
      "       !f!f  f f",
      "       !f!f  fͳͳ",
      "        f f  ʹff",
      "        f f    f",
      "        f f    f",
      "        f f  ʹff",
      "        f f  f f",
      "        f f  f f",
      "        ffffffͳͳ",
      "          f  ʹff"
    ],
    [
      "          f  f  ",
      "          f  ʹff",
      "          f     ",
      "         fffffff",
      "         ff  ʹff",
      "        !ff  f f",
      "        !ff  f f",
      "       !!ff  f f",
      "        !ff  ʹff",
      "         ff    f",
      "         ff    f",
      "         ff  ʹff",
      "         ff  f f",
      "         ff  f f",
      "         fffffff",
      "          f  ʹff"
    ]
  ]
}