{
  "xsize": 16,
  "zsize": 16,
  "refpalette": "lostcities:base",
  "slices": [
    [
      "                ",
      "       f    ! f ",
      "      ffffffffff",
      "      f     !  f",
      "     ff        f",
      "      f        f",
      "      f        f",
      "      f        f",
      "      f        f",
      "      f        f",
      "      f        f",
      "     ff        f",
      "      f!!      f",
      "     !ffffffffff",
      "      !f!     f ",
      "       !        "
    ],
    [
      "                ",
      "       f    ! f ",
      "      ffffffffff",
      "      f     !  f",
      "     ff        f",
      "      f        f",
      "      f        f",
      "      f        f",
      "      f        f",
      "      f        f",
      "      f        f",
      "     ff        f",
      "      f !!!!   f",
      "      ffffffffff",
      "      !f!!!!  f ",
      "       !!       "
    ],
    [
      "                ",
      "       f    ! f ",
      "      ffffffffff",
      "     ff     !  f",
      "     ff        f",
      "     ff        f",
      "     ff        f",
      "     ff        f",
      "     ff        f",
      "     ff        f",
      "     ff        f",
      "     ff        f",
      "     ff    !   f",
      "      ffffffffff",
      "      !f!  !  f ",
      "       !        "
    ],
    [
      "                ",
      "       f   !! f ",
      "      ffffffffff",
      "     ff    !!  f",
      "     ff        f",
      "     ff        f",
      "     ff        f",
      "     ff        f",
      "     ff        f",
      "     ff        f",
      "     ff        f",
      "     ff        f",
      "     ff    !!  f",
      "      fff !!ffff",
      "       f   !! f ",
      "                "
    ],
    [
      "           !    ",
      "       f !!!! f ",
      "      ffffffffff",
      "    fff    !   f",
      "    fff        f",
      "    fff        f",
      "    fff        f",
      "    fff        f",
      "    fff        f",
      "    fff        f",
      "    fff        f",
      "    fff        f",
      "    fff     !  f",
      "      ff   !!fff",
      "       f   !!!f ",
      "            !   "
    ],
    [
      "         !!!    ",
      "       ffffffff ",
      "     fffffffffff",
      "  fffff        f",
      "  fffff        f",
      "  fffff        f",
      "  fffff        f",
      "  fffff        f",
      " !fffff        f",
      " !fffff        f",
      "  fffff        f",
      "  fffff        f",
      "  fffff        f",
      "     fff    ffff",
      "       f   !fff ",
      "            !   "
    ]
  ]
}