{
  "xsize": 16,
  "zsize": 16,
  "refpalette": "lostcities:base",
  "slices": [
    [
      "Ͷ        ͶYͶ    ",
      "Ͷ        ͶYͶ    ",
      " Ͷ      ͶYYͶ    ",
      " ͶͶ    ͶͶY  Ͷ   ",
      "   ͶͶͶͶYYY  Ͷ   ",
      "      ͶY     Ͷ  ",
      "      ͶY      Ͷ ",
      "      ͶY       Ͷ",
      "      ͶY        ",
      "       Y      gg",
      "             ggg",
      "            gggg",
      "            gggg",
      "            gggg",
      "            gggg",
      "             ggg"
    ],
    [
      "Ͷ        ͶYͶ    ",
      "Ͷ        ͶYͶ    ",
      " Ͷ      ͶYYͶ    ",
      " ͶͶ    ͶͶY  Ͷ   ",
      "   ͶͶͶͶYYY  Ͷ   ",
      "      ͶY     Ͷ  ",
      "      ͶY      Ͷ ",
      "      ͶY       Ͷ",
      "       Y        ",
      "              gg",
      "             ggg",
      "            gggg",
      "            gggg",
      "            gggg",
      "            gggg",
      "             ggg"
    ],
    [
      "Ͷ        ͶYͶ    ",
      "Ͷ        ͶYͶ    ",
      " Ͷ      ͶYYͶ    ",
      " ͶͶ    ͶͶY  Ͷ   ",
      "   ͶͶͶͶYYY  Ͷ   ",
      "      ͶY     Ͷ  ",
      "      ͶY      Ͷ ",
      "      ͶY       Ͷ",
      "       Y        ",
      "              ͶͶ",
      "             Ͷ  ",
      "            Ͷ   ",
      "            Ͷ   ",
      "            Ͷ   ",
      "            Ͷ   ",
      "             Ͷ  "
    ],
    [
      "Ͷ        ͶYͶ    ",
      "Ͷ        ͶYͶ    ",
      " Ͷ      ͶYYͶ    ",
      " ͶͶ    ͶͶY  Ͷ   ",
      "   ͶͶͶͶYYY  Ͷ   ",
      "      ͶY     Ͷ  ",
      "      ͶY      Ͷ ",
      "       Y       Ͷ",
      "                ",
      "              ͶͶ",
      "             Ͷ  ",
      "            Ͷ   ",
      "            Ͷ   ",
      "            Ͷ   ",
      "            Ͷ   ",
      "             Ͷ  "
    ],
    [
      "Ͷ        ͶYͶ    ",
      "Ͷ        ͶYͶ    ",
      " Ͷ      ͶYYͶ    ",
      " ͶͶ    ͶͶY  Ͷ   ",
      "   ͶͶͶͶYYY  Ͷ   ",
      "      ͶY     Ͷ! ",
      "      ͶY     !Ͷ!",
      "       Y      !Ͷ",
      "                ",
      "              ͶͶ",
      "             Ͷ  ",
      "            Ͷ   ",
      "            Ͷ   ",
      "            Ͷ   ",
      "            Ͷ   ",
      "             Ͷ  "
    ],
    [
      "Ͷ        ͶYͶ    ",
      "Ͷ        ͶYͶ    ",
      " Ͷ      ͶYYͶ    ",
      " ͶͶ    ͶͶY  Ͷ   ",
      "   ͶͶͶͶYYY  Ͷ!  ",
      "       Y    !Ͷ! ",
      "       Y    !!Ͷ!",
      "             !!Ͷ",
      "                ",
      "              ͶͶ",
      "             Ͷ  ",
      "            Ͷ   ",
      "            Ͷ   ",
      "            Ͷ   ",
      "            Ͷ   ",
      "             Ͷ  "
    ]
  ]
}