{
  "xsize": 16,
  "zsize": 16,
  "refpalette": "lostcities:base",
  "slices": [
    [
      "vvvvvvvvvvvvvvvv",
      "vvvvvvvvvvvvvvvv",
      "vvvvvvvvvvvvvvvv",
      "vvvvvvvvvvvvvvvv",
      "vvvvvvvvvvvvvvvv",
      "vvvvvvvvvvvvvvvv",
      "vvvvvvvvvvvvvvvv",
      "vvvvvvvvvvvvvvvv",
      "vvvvvvvvvvvvvvvv",
      "vvvvvvvvvvvvvvvv",
      "vvvvvvvvvvvvvvvv",
      "vvvvvvvvvvvvvvvv",
      "vvvvvvvvvvvvvvvv",
      "vvvvvvvvvvvvvvvv",
      "vvvvvvvvvvvvvvvv",
      "vvvvvvvvvvvvvvvv"
    ],
    [
      "                ",
      "                ",
      "               #",
      "                ",
      "                ",
      "                ",
      "                ",
      "                ",
      "                ",
      "                ",
      "                ",
      "                ",
      "                ",
      "                ",
      "                ",
      "                "
    ],
    [
      "              @A",
      "               @",
      "               K",
      "                ",
      "                ",
      "                ",
      "                ",
      "                ",
      "                ",
      "                ",
      "                ",
      "                ",
      "                ",
      "                ",
      "                ",
      "                "
    ],
    [
      "             LAA",
      "              MA",
      "               A",
      "               A",
      "               A",
      "               A",
      "               A",
      "               A",
      "               @",
      "                ",
      "                ",
      "                ",
      "                ",
      "                ",
      "                ",
      "                "
    ],
    [
      "             NAA",
      "              OA",
      "               A",
      "               A",
      "               A",
      "               A",
      "               A",
      "            @@@A",
      "               A",
      "               A",
      "               A",
      "                ",
      "                ",
      "                ",
      "                ",
      "                "
    ],
    [
      "               O",
      "                ",
      "                ",
      "                ",
      "                ",
      "                ",
      "                ",
      "               P",
      "               A",
      "               A",
      "               A",
      "               M",
      "                ",
      "                ",
      "                ",
      "                "
    ]
  ]
}