{
  "xsize": 16,
  "zsize": 16,
  "refpalette": "lostcities:base",
  "slices": [
    [
      " g              ",
      "ggg             ",
      " m              ",
      " m              ",
      " m              ",
      " m              ",
      " m              ",
      " m              ",
      " m!             ",
      " m              ",
      "!mg          hi ",
      "ggg          jk ",
      "ggg             ",
      " g        gg! gg",
      " gqqqqqqqqgggggg",
      "ng        gg! gg"
    ],
    [
      "                ",
      "ggg             ",
      " m              ",
      " m              ",
      " m              ",
      " m              ",
      " m              ",
      " m!             ",
      "!m!!            ",
      "!m!!            ",
      "!mg          hi ",
      "ggg          jk ",
      "ggg             ",
      " g        gg! gg",
      " gqqqqqqqqgggggg",
      " g        gg!!gg"
    ],
    [
      "                ",
      "  g             ",
      "                ",
      " m              ",
      " m              ",
      " m              ",
      " m              ",
      " m!             ",
      " m!!            ",
      "!m!!!           ",
      "!mg!!!       hi ",
      "ggg          jk ",
      "g               ",
      "       !  gg  gg",
      "    qqqqqqgggggg",
      "       !  gg! gg"
    ],
    [
      "                ",
      "                ",
      "                ",
      "                ",
      " m              ",
      " m              ",
      " m              ",
      " m              ",
      " m!!            ",
      "!m!!!!          ",
      "!mg!!!!      hi ",
      "ggg!!!!      jk ",
      "g               ",
      "       !  gg  gg",
      "    qqqqqqgggggg",
      "       !  gg! gg"
    ],
    [
      "                ",
      "                ",
      "                ",
      "                ",
      " m              ",
      " m              ",
      " m              ",
      " m              ",
      " m              ",
      " m!! !          ",
      "!mg!!!!      hi ",
      "ggg!!!!!     jk ",
      "gg   !!!!       ",
      "       !  gg  gg",
      "    qqqqqqgggggg",
      "       !  gg! gg"
    ],
    [
      "                ",
      " g              ",
      "                ",
      "                ",
      " m              ",
      " m              ",
      " m              ",
      " m              ",
      " m              ",
      "!m!!            ",
      "!mg!!!!      hi ",
      "ggg!!!!!!    jk ",
      "ggg!!!!!!!      ",
      " g    !!!!gg  gg",
      " gqqqqqqqqgggggg",
      "gg     !  gg! gg"
    ]
  ]
}