{
  "xsize": 16,
  "zsize": 16,
  "refpalette": "lostcities:base",
  "slices": [
    [
      "vvvvvvvvvvvvvvvv",
      "vvvvvvvvvvvvvvvv",
      "vvvvvvvvvvvvvvvv",
      "vvvvvvvvvvvvvvvv",
      "vvvvvvvvvvvvvvvv",
      "vvvvvvvvvvvvvvvv",
      "vvvvvvvvvvvvvvvv",
      "vvvvvvvvvvvvvvvv",
      "vvvvvvvvvvvvvvvv",
      "vvvvvvvvvvvvvvvv",
      "vvvvvvvvvvvvvvvv",
      "vvvvvvvvvvvvvvvv",
      "vvvvvvvvvvvvvvvv",
      "vvvvvvvvvvvvvvvv",
      "vvvvvvvvvvvvvvvv",
      "vvvvvvvvvvvvvvvv"
    ],
    [
      "ggggggggggggggg ",
      "ggggggggggggggg ",
      "ggggggggggggggg ",
      "ggggggggggggggg ",
      "ggggggggggggggg ",
      "ggggggggggggggg ",
      "ggggggggggggggg ",
      "ggggggggggggggg ",
      "ggggggggggggggg ",
      "ggggggggggggggg ",
      "ggggggggggggggg ",
      "ggggggggggggggg ",
      "ggggggggggggggg ",
      "ggggggggggggggg ",
      "ggggggggggggggg ",
      "ggggggggggggggg "
    ],
    [
      "         gggggg ",
      "         gggggg ",
      "         gggggg ",
      "         gggggg ",
      "         gggggg ",
      "         gggggg ",
      "         gggggg ",
      "         gggggg ",
      "         gggggg ",
      "         gggggg ",
      "         gggggg ",
      "         gggggg ",
      "         gggggg ",
      "         gggggg ",
      "         gggggg ",
      "         gggggg "
    ],
    [
      "         gggggg ",
      "         gggggg ",
      "         gggggg ",
      "         gggggg ",
      "         gggggg ",
      "         gggggg ",
      "         gggggg ",
      "         gggggg ",
      "         gggggg ",
      "         gggggg ",
      "         gggggg ",
      "         gggggg ",
      "         gggggg ",
      "         gggggg ",
      "         gggggg ",
      "         gggggg "
    ],
    [
      "ggggggggggggggg ",
      "ggggggggggggggg ",
      "ggggggggggggggg ",
      "ggggggggggggggg ",
      "ggggggggggggggg ",
      "ggggggggggggggg ",
      "ggggggggggggggg ",
      "ggggggggggggggg ",
      "ggggggggggggggg ",
      "ggggggggggggggg ",
      "ggggggggggggggg ",
      "ggggggggggggggg ",
      "ggggggggggggggg ",
      "ggggggggggggggg ",
      "ggggggggggggggg ",
      "ggggggggggggggg "
    ],
    [
      "ggggggggggggggg ",
      "ggggggggggggggg ",
      "ggggggggggggggg ",
      "ggggggggggggggg ",
      "ggggggggggggggg ",
      "ggggggggggggggg ",
      "ggggggggggggggg ",
      "ggggggggggggggg ",
      "ggggggggggggggg ",
      "ggggggggggggggg ",
      "ggggggggggggggg ",
      "ggggggggggggggg ",
      "ggggggggggggggg ",
      "ggggggggggggggg ",
      "ggggggggggggggg ",
      "ggggggggggggggg "
    ]
  ]
}