{
  "xsize": 16,
  "zsize": 16,
  "refpalette": "lostcities:base",
  "slices": [
    [
      "gggggggggggggggg",
      "gggggggggggggggg",
      "gggggggggggggggg",
      "gggggggggggggggg",
      "gggggggggggggggg",
      "gggggggggggggggg",
      "gggggggggggggggg",
      "gggggggggggggggg",
      "gggggggggggggggg",
      "gggggggggggggggg",
      "gggggggggggggggg",
      "gggggggggggggggg",
      "gggggggggggggggg",
      "gggggggggggggggg",
      "gggggggggggggggg",
      "gggggggggggggggg"
    ],
    [
      "!      !!!      ",
      "!!!!!!!!Ͳ!!     ",
      "       !!!!!    ",
      "      n  n!!!   ",
      "          !!    ",
      "    n      n    ",
      "  Ͳ             ",
      "        !    Ͳ  ",
      "    n  !!! n    ",
      "     !!!!!      ",
      "  !!!!n!!n      ",
      "!!!! !          ",
      "!!!!   Ͳ        ",
      "!!!             ",
      "!             !!",
      "!            !! "
    ],
    [
      "       !!!      ",
      "      !!g!!     ",
      "       !!!!     ",
      "      n !n!!    ",
      "         !!     ",
      "    n      n    ",
      "  g             ",
      "             g  ",
      "    n  !!  n    ",
      "     !!!!       ",
      "    !!n!!n      ",
      "  !  !!!        ",
      "!!!    g        ",
      "!               ",
      "                ",
      "                "
    ],
    [
      "        !       ",
      "       !g!      ",
      "        !!      ",
      "      ffff!     ",
      "     ffffff     ",
      "    ffffffff    ",
      "  g ffffffff    ",
      "    ffffffff g  ",
      "    ffffffff    ",
      "     ffffff     ",
      "    !!ffff      ",
      "     !!         ",
      "       g        ",
      "                ",
      "                ",
      "                "
    ],
    [
      "                ",
      "        g       ",
      "        !!      ",
      "      ffff!     ",
      "     f  !!f     ",
      "    f      f    ",
      "  g f      f    ",
      "    f      f g  ",
      "    f      f    ",
      "     f!   f     ",
      "    !!ffff      ",
      "     !!         ",
      "       g        ",
      "                ",
      "                ",
      "                "
    ],
    [
      "                ",
      "        g       ",
      "       !!       ",
      "      ffff      ",
      "     f !! f     ",
      "    f      f    ",
      "  g f      f    ",
      "    f      f g  ",
      "    f!!    f    ",
      "    !f!!  f     ",
      "     !ffff      ",
      "      !         ",
      "       g        ",
      "                ",
      "                ",
      "                "
    ]
  ]
}