{
  "xsize": 16,
  "zsize": 16,
  "refpalette": "lostcities:base",
  "slices": [
    [
      "            ggg ",
      "g          ggggg",
      "gYYYYYYYYYYggggg",
      "           ggggg",
      "            ggg!",
      "             Y!!",
      "             Y! ",
      "             Y  ",
      "             Y  ",
      "             Y  ",
      "            !Y! ",
      "            !Y! ",
      "             Y  ",
      "             Y  ",
      "             Y  ",
      "g            gg "
    ],
    [
      "             g  ",
      "g           ggg ",
      "gYYYYYYYYYYggggg",
      "            ggg!",
      "             g!!",
      "             Y! ",
      "             Y  ",
      "             Y  ",
      "             Y  ",
      "             Y  ",
      "             Y  ",
      "            !Y! ",
      "            !Y! ",
      "             Y  ",
      "             Y  ",
      "g            gg "
    ],
    [
      "             g  ",
      "g           ggg!",
      "gYYYYYYYYYYggggg",
      "            ggg!",
      "             g!!",
      "             Y  ",
      "             Y  ",
      "             Y  ",
      "             Y  ",
      "             Y  ",
      "             Y  ",
      "             Y  ",
      "            !Y! ",
      "            !Y! ",
      "             Y  ",
      "g            gg "
    ],
    [
      "             g  ",
      "g           ggg!",
      "gYYYYYYYYYYggggg",
      "            ggg!",
      "             g  ",
      "             Y  ",
      "             Y  ",
      "             Y  ",
      "             Y  ",
      "             Y  ",
      "             Y  ",
      "             Y  ",
      "             Y  ",
      "            !Y! ",
      "             Y!!",
      "g            gg "
    ],
    [
      "             g  ",
      "g           ggg!",
      "gYYYYY   YYggggg",
      "            ggg!",
      "             g  ",
      "             Y  ",
      "             Y  ",
      "             Y  ",
      "             Y  ",
      "             Y  ",
      "             Y  ",
      "             Y  ",
      "             Y! ",
      "            !Y!!",
      "             Y!!",
      "g            gg!"
    ],
    [
      "             g !",
      "            ggg!",
      "gYYYYY    Yggggg",
      " g          ggg!",
      "      !!     g  ",
      "             Y  ",
      "             Y  ",
      "             Y  ",
      "             Y  ",
      "             Y  ",
      "             Y  ",
      "             Y  ",
      "             Y  ",
      "             Y!!",
      "!g          gY!g",
      "g !!         gg!"
    ]
  ]
}