{
  "xsize": 16,
  "zsize": 16,
  "refpalette": "lostcities:base",
  "slices": [
    [
      "  f             ",
      "  f             ",
      "  f   !         ",
      "  f  !!!        ",
      "  f   !      f  ",
      "  f          f  ",
      "             f  ",
      "             f  ",
      "ggg  ggggggggggg",
      "gggggggggggggggg",
      "  f        !!f! ",
      "  f         !f  ",
      "  ffffffffffff  ",
      "  ffffffffffff  ",
      "  ffffffffffff  ",
      "   g        g   "
    ],
    [
      "   f        f   ",
      "   f        f   ",
      "   f !!     f   ",
      "   f!!!!    f   ",
      "   f !!     f   ",
      "            f   ",
      "            f   ",
      "            f   ",
      "g     gggggggggg",
      "gggggggggggggggg",
      "   f      !!f!  ",
      "   f       !f   ",
      "   ffffffffff   ",
      "   ffffffffff   ",
      "   ffffffffff   ",
      "    gg    gg    "
    ],
    [
      "    f  !!!!f    ",
      "    f!!!  !f    ",
      "    f!!    f    ",
      "    f!!    f    ",
      "     !  !  f    ",
      "        !! f    ",
      "         ! f    ",
      "         !!f    ",
      "g     ggggggg   ",
      "ggggggggggggggg ",
      "    f     !f!!  ",
      "    f      f!   ",
      "    ffffffff    ",
      "    ffffffff    ",
      "    ffffffff    ",
      "      gggg      "
    ],
    [
      "     ffffff!    ",
      "    !ffffff!    ",
      "    !ffffff     ",
      "     ! ffff     ",
      "       !fff     ",
      "       !fff     ",
      "       ffff     ",
      "       ffff!    ",
      "     gggggggg!  ",
      "ggggggggggggggg ",
      "     ffffff!!!  ",
      "     ffffff !   ",
      "     ffffff     ",
      "     ffffff     ",
      "     ffffff     ",
      "                "
    ],
    [
      "       !!!!     ",
      "     !!!  !     ",
      "     !          ",
      "                ",
      "        !       ",
      "        !!      ",
      "         !!!    ",
      "         !!!!   ",
      "    ggggggggg!! ",
      " ggggggggggggggg",
      "            !!! ",
      "                ",
      "                ",
      "                ",
      "                ",
      "                "
    ],
    [
      "                ",
      "                ",
      "                ",
      "                ",
      "                ",
      "                ",
      "                ",
      "          !!!!  ",
      "   ggggggggggggg",
      "   ggggggggggggg",
      "             !! ",
      "                ",
      "                ",
      "                ",
      "                ",
      "                "
    ]
  ]
}