{
  "xsize": 16,
  "zsize": 16,
  "refpalette": "lostcities:base",
  "slices": [
    [
      "gggggggggggggggg",
      "gggggggggggggggg",
      "gggggggggggggggg",
      "gggggggggggggggg",
      "gggggggggggggggg",
      "gggggggggggggggg",
      "gggggggggggggggg",
      "gggggggggggggggg",
      "gggggggggggggggg",
      "gggggggggggggggg",
      "gggggggggggggggg",
      "gggggggggggggggg",
      "gggggggggggggggg",
      "gggggggggggggggg",
      "gggggggggggggggg",
      "gggggggggggggggg"
    ],
    [
      "g            gg!",
      " g          gY g",
      "             Y  ",
      "             Y  ",
      "             Y! ",
      "             Y! ",
      "             Y  ",
      "             Y  ",
      "             Y  ",
      "             Y  ",
      "             Y  ",
      "             Y  ",
      "             Y  ",
      "!            Y  ",
      "!g          gY g",
      "g!           gg "
    ],
    [
      "g            gg ",
      "             Y  ",
      "             Y  ",
      "             Y  ",
      "             Y  ",
      "             Y  ",
      "             Y  ",
      "             Y  ",
      "             Y  ",
      "             Y  ",
      "             Y  ",
      "             Y  ",
      "             Y  ",
      "             Y  ",
      "!            Y  ",
      "g            gg "
    ],
    [
      "g            gg ",
      "             Y  ",
      "             Y  ",
      "             Y  ",
      "             Y  ",
      "             Y! ",
      "             Y  ",
      "             Y  ",
      "             Y  ",
      "             Y  ",
      "             Y  ",
      "             Y  ",
      "             Y  ",
      "             Y  ",
      "             Y  ",
      "g            gg "
    ],
    [
      "g            gg ",
      "             Y  ",
      "             Y  ",
      "             Y  ",
      "             Y! ",
      "             Y! ",
      "             Y  ",
      "             Y  ",
      "             Y  ",
      "             Y  ",
      "             Y  ",
      "             Y  ",
      "             Y  ",
      "             Y  ",
      "             Y  ",
      "g            gg "
    ],
    [
      "g            gg ",
      "             Y  ",
      "             Y  ",
      "             Y  ",
      "             Y! ",
      "             Y  ",
      "             Y  ",
      "             Y  ",
      "             Y  ",
      "             Y  ",
      "             Y  ",
      "             Y  ",
      "             Y  ",
      "             Y  ",
      "             Y  ",
      "g            gg "
    ]
  ]
}