{
  "xsize": 16,
  "zsize": 16,
  "refpalette": "lcmt:streets",
  "slices": [
    [
      "~~~~ASSSSSSA~~~~",
      "~~~~ASSSSSSA~A~~",
      "~~A~ASSSSSSA~A~~",
      "~~~~ASSSSSSA~~~~",
      "AAAAASSSSSSA~~~~",
      "SSSSSSSSSSSA~~~~",
      "SSSSSSSSSSSA~~~~",
      "SSSSSSSSSSSA~~~~",
      "SSSSSSSSSSSA~~~~",
      "SSSSSSSSSSSA~~~~",
      "SSSSSSSSSSSA~~~~",
      "AAAAAAAAAAAA~~~~",
      "~~~~~~~~~~~~~~~~",
      "~AA~~~~~~~~~~A~~",
      "~~~~~~~~~~~~~~~~",
      "~~~~~~~~~~~~~~~~"
    ],
    [
      "~~~~~~~~~~~~~~~~",
      "~~o~~~~~~~~~~k~~",
      "~qrs~~~~~~~~~k~~",
      "~~H~~~~~~~~~~~~~",
      "~~~~~~~~~~~~~~~~",
      "~~~~~~~~~~~~~~~~",
      "~~~~~~~~~~~~~~~~",
      "~~~~~~~~~~~~~~~~",
      "~~~~~~~~~~~~~~~~",
      "~~~~~~~~~~~~~~~~",
      "~~~~~~~~~~~~~~~~",
      "~~~~~~~~~~~~~~~~",
      "~~~~~~~~~~~~~~~~",
      "~mm~~~~~~~~~~|~~",
      "~~~~~~~~~~~~~~~~",
      "~~~~~~~~~~~~~~~~"
    ],
    [
      "~~~~~~~~~~~~~~~~",
      "~~~~~~~~~~~~~~~~",
      "~~~~~~~~~~~~~~~~",
      "~~~~~~~~~~~~~~~~",
      "~~~~~~~~~~~~~~~~",
      "~~~~~~~~~~~~~~~~",
      "~~~~~~~~~~~~~~~~",
      "~~~~~~~~~~~~~~~~",
      "~~~~~~~~~~~~~~~~",
      "~~~~~~~~~~~~~~~~",
      "~~~~~~~~~~~~~~~~",
      "~~~~~~~~~~~~~~~~",
      "~~~~~~~~~~~~~~~~",
      "~~~~~~~~~~~~~i~~",
      "~~~~~~~~~~~~~~~~",
      "~~~~~~~~~~~~~~~~"
    ],
    [
      "~~~~~~~~~~~~~~~~",
      "~~~~~~~~~~~~~~~~",
      "~~~~~~~~~~~~~~~~",
      "~~~~~~~~~~~~~~~~",
      "~~~~~~~~~~~~~~~~",
      "~~~~~~~~~~~~~~~~",
      "~~~~~~~~~~~~~~~~",
      "~~~~~~~~~~~~~~~~",
      "~~~~~~~~~~~~~~~~",
      "~~~~~~~~~~~~~~~~",
      "~~~~~~~~~~~~~~~~",
      "~~~~~~~~~~~~~~~~",
      "~~~~~~~~~~~~~~~~",
      "~~~~~~~~~~~~~i~~",
      "~~~~~~~~~~~~~~~~",
      "~~~~~~~~~~~~~~~~"
    ],
    [
      "~~~~~~~~~~~~~~~~",
      "~~~~~~~~~~~~~~~~",
      "~~~~~~~~~~~~~~~~",
      "~~~~~~~~~~~~~~~~",
      "~~~~~~~~~~~~~~~~",
      "~~~~~~~~~~~~~~~~",
      "~~~~~~~~~~~~~~~~",
      "~~~~~~~~~~~~~~~~",
      "~~~~~~~~~~~~~~~~",
      "~~~~~~~~~~~~~~~~",
      "~~~~~~~~~~~~~~~~",
      "~~~~~~~~~~~~~~~~",
      "~~~~~~~~~~~~~~~~",
      "~~~~~~~~~~~~~~~~",
      "~~~~~~~~~~~~~~~~",
      "~~~~~~~~~~~~~~~~"
    ]
  ]
}
