{
  "refpalette": "lcmt:streets",
  "xsize": 16,
  "zsize": 16,
  "slices": [
    [
      "~~~~ASSSSSSA~~~~",
      "~~~~ASSSSSSA~~~~",
      "~~A~ASSSSSSA~A~~",
      "~~~~ASSSSSSA~~~~",
      "AAAAASSSSSSAAAAA",
      "SSSSSSSSSSSSSSSS",
      "SSSSSSSSSSSSSSSS",
      "SSSSSSSSSSSSSSSS",
      "SSSSSSSSSSSSSSSS",
      "SSSSSSSSSSSSSSSS",
      "SSSSSSSSSSSSSSSS",
      "AAAAASSSSSSAAAAA",
      "~~~~ASSSSSSA~~~~",
      "~~A~ASSSSSSA~A~~",
      "~~~~ASSSSSSA~~~~",
      "~~~~ASSSSSSA~~~~"
    ],
    [
      "~~~~~~~~~~~~~~~~",
      "~~~~~~~~~~~~~~~~",
      "~~|~~~~~~~~~~|~~",
      "~~~~~~~~~~~~~~~~",
      "~~~~a~~~~~~a~~~~",
      "~~~~~~~~~~~~~~~~",
      "~~~~~~~~~~~~~~~~",
      "~~~~~~~~~~~~~~~~",
      "~~~~~~~~~~~~~~~~",
      "~~~~~~~~~~~~~~~~",
      "~~~~~~~~~~~~~~~~",
      "~~~~a~~~~~~a~~~~",
      "~~~~~~~~~~~~~~~~",
      "~~|~~~~~~~~~~|~~",
      "~~~~~~~~~~~~~~~~",
      "~~~~~~~~~~~~~~~~"
    ],
    [
      "~~~~~~~~~~~~~~~~",
      "~~~~~~~~~~~~~~~~",
      "~~i~~~~~~~~~~i~~",
      "~~~~~~~~~~~~~~~~",
      "~~~~P~~~~~~P~~~~",
      "~~~~~~~~~~~~~~~~",
      "~~~~~~~~~~~~~~~~",
      "~~~~~~~~~~~~~~~~",
      "~~~~~~~~~~~~~~~~",
      "~~~~~~~~~~~~~~~~",
      "~~~~~~~~~~~~~~~~",
      "~~~~P~~~~~~P~~~~",
      "~~~~~~~~~~~~~~~~",
      "~~i~~~~~~~~~~i~~",
      "~~~~~~~~~~~~~~~~",
      "~~~~~~~~~~~~~~~~"
    ],
    [
      "~~~~~~~~~~~~~~~~",
      "~~~~~~~~~~~~~~~~",
      "~~i~~~~~~~~~~i~~",
      "~~~~~~~~~~~~~~~~",
      "~~~~Q~~~~~~Q~~~~",
      "~~~~~~~~~~~~~~~~",
      "~~~~~~~~~~~~~~~~",
      "~~~~~~~~~~~~~~~~",
      "~~~~~~~~~~~~~~~~",
      "~~~~~~~~~~~~~~~~",
      "~~~~~~~~~~~~~~~~",
      "~~~~Q~~~~~~Q~~~~",
      "~~~~~~~~~~~~~~~~",
      "~~i~~~~~~~~~~i~~",
      "~~~~~~~~~~~~~~~~",
      "~~~~~~~~~~~~~~~~"
    ],
    [
      "~~~~~~~~~~~~~~~~",
      "~~~~~~~~~~~~~~~~",
      "~~~~~~~~~~~~~~~~",
      "~~~~~~~~~~~~~~~~",
      "~~~~e~~~~~~e~~~~",
      "~~~~~~~~~~~~~~~~",
      "~~~~~~~~~~~~~~~~",
      "~~~~~~~~~~~~~~~~",
      "~~~~~~~~~~~~~~~~",
      "~~~~~~~~~~~~~~~~",
      "~~~~~~~~~~~~~~~~",
      "~~~~e~~~~~~e~~~~",
      "~~~~~~~~~~~~~~~~",
      "~~~~~~~~~~~~~~~~",
      "~~~~~~~~~~~~~~~~",
      "~~~~~~~~~~~~~~~~"
    ]
  ]
}
