{
  "xsize": 16,
  "zsize": 16,
  "refpalette": "lcmt:top_decorations",
  "slices": [
    [
      "################",
      "################",
      "################",
      "################",
      "################",
      "################",
      "################",
      "################",
      "################",
      "#######l########",
      "################",
      "################",
      "################",
      "################",
      "################",
      "################"
    ],
    [
      "                ",
      "                ",
      "                ",
      "   :  :  :  :   ",
      "                ",
      "                ",
      "   :  :  :  :   ",
      "                ",
      "                ",
      "                ",
      "                ",
      "                ",
      "                ",
      "                ",
      "                ",
      "                "
    ],
    [
      "                ",
      "                ",
      "                ",
      "   _uu_  _uu_   ",
      "   uuuu  uuuu   ",
      "   uuuu  uuuu   ",
      "   _uu_  _uu_   ",
      "                ",
      "                ",
      "                ",
      "                ",
      "                ",
      "                ",
      "                ",
      "                ",
      "                "
    ],
    [
      "                ",
      "                ",
      "                ",
      "    oo    oo    ",
      "   o  o  o  o   ",
      "   o  o  o  o   ",
      "    oo    oo    ",
      "                ",
      "                ",
      "                ",
      "                ",
      "                ",
      "                ",
      "                ",
      "                ",
      "                "
    ],
    [
      "                ",
      "                ",
      "                ",
      "    uu    uu    ",
      "   u  u  u  u   ",
      "   u  u  u  u   ",
      "    uu    uu    ",
      "                ",
      "                ",
      "                ",
      "                ",
      "                ",
      "                ",
      "                ",
      "                ",
      "                "
    ],
    [
      "                ",
      "                ",
      "                ",
      "    cc    cc    ",
      "   t  A  t  A   ",
      "   t  A  t  A   ",
      "    zz    zz    ",
      "                ",
      "                ",
      "                ",
      "                ",
      "                ",
      "                ",
      "                ",
      "                ",
      "                "
    ],
    [
      "                ",
      "                ",
      "                ",
      "                ",
      "    __    __    ",
      "    __    __    ",
      "                ",
      "                ",
      "                ",
      "                ",
      "                ",
      "                ",
      "                ",
      "                ",
      "                ",
      "                "
    ]
  ]
}
