{
  "xsize": 16,
  "zsize": 16,
  "refpalette": "lostcities:top_decorations",
  "slices": [
    [
      "################",
      "################",
      "################",
      "################",
      "################",
      "################",
      "################",
      "################",
      "################",
      "#######l########",
      "################",
      "################",
      "################",
      "################",
      "################",
      "################"
    ],
    [
      "                ",
      "                ",
      "    +++ +++     ",
      "    +++ +++     ",
      "                ",
      "                ",
      "    aaaaaaa     ",
      "    a:   :a     ",
      "                ",
      "                ",
      "                ",
      "    a:   :a     ",
      "    aaaaaaa     ",
      "                ",
      "                ",
      "                "
    ],
    [
      "                ",
      "                ",
      "    ### ###     ",
      "    ### ###     ",
      "                ",
      "                ",
      "    aaaaaaa     ",
      "    a:   :a     ",
      "                ",
      "                ",
      "                ",
      "    a:   :a     ",
      "    aaaaaaa     ",
      "                ",
      "                ",
      "                "
    ],
    [
      "                ",
      "                ",
      "                ",
      "                ",
      "                ",
      "                ",
      "    #######     ",
      "    #######     ",
      "    #######     ",
      "    #######     ",
      "    #######     ",
      "    #######     ",
      "    #######     ",
      "                ",
      "                ",
      "                "
    ],
    [
      "                ",
      "                ",
      "                ",
      "                ",
      "                ",
      "                ",
      "                ",
      "                ",
      "                ",
      "                ",
      "                ",
      "         :      ",
      "                ",
      "                ",
      "                ",
      "                "
    ],
    [
      "                ",
      "                ",
      "                ",
      "                ",
      "                ",
      "                ",
      "                ",
      "                ",
      "                ",
      "                ",
      "                ",
      "         :      ",
      "                ",
      "                ",
      "                ",
      "                "
    ]
  ]
}
