{
  "xsize": 16,
  "zsize": 16,
  "refpalette": "lostcities:top_decorations",
  "slices": [
    [
      "################",
      "################",
      "################",
      "################",
      "################",
      "################",
      "################",
      "################",
      "################",
      "#######l########",
      "################",
      "################",
      "################",
      "################",
      "################",
      "################"
    ],
    [
      "                ",
      "                ",
      "  ###     ####  ",
      "  #G#     #GG#  ",
      "  ###     ####  ",
      "                ",
      "                ",
      "     QQ QQ      ",
      "     Q   Q      ",
      "                ",
      "     Q   Q      ",
      "     QQ QQ      ",
      "                ",
      "                ",
      "                ",
      "                "
    ],
    [
      "                ",
      "                ",
      "                ",
      "   p       pp   ",
      "                ",
      "                ",
      "                ",
      "     QQ QQ      ",
      "     Q   Q      ",
      "                ",
      "     Q   Q      ",
      "     QQ QQ      ",
      "                ",
      "                ",
      "                ",
      "                "
    ],
    [
      "                ",
      "                ",
      "                ",
      "                ",
      "                ",
      "                ",
      "                ",
      "    #######     ",
      "    #######     ",
      "    #######     ",
      "    #######     ",
      "    #######     ",
      "                ",
      "                ",
      "                ",
      "                "
    ],
    [
      "                ",
      "                ",
      "                ",
      "                ",
      "                ",
      "                ",
      "                ",
      "                ",
      "                ",
      "                ",
      "                ",
      "                ",
      "                ",
      "                ",
      "                ",
      "                "
    ],
    [
      "                ",
      "                ",
      "                ",
      "                ",
      "                ",
      "                ",
      "                ",
      "                ",
      "                ",
      "                ",
      "                ",
      "                ",
      "                ",
      "                ",
      "                ",
      "                "
    ]
  ]
}
