{
  "xsize": 16,
  "zsize": 16,
  "slices": [
    [
      "################",
      "################",
      "################",
      "################",
      "################",
      "################",
      "################",
      "################",
      "################",
      "#######l########",
      "################",
      "################",
      "################",
      "################",
      "################",
      "################"
    ],
    [
      "                ",
      "                ",
      "            w   ",
      "                ",
      "                ",
      "                ",
      "                ",
      "     :: ::      ",
      "     :   :      ",
      "                ",
      "     :   :      ",
      "     :: ::      ",
      "                ",
      "                ",
      "                ",
      "                "
    ],
    [
      "                ",
      "                ",
      "            :   ",
      "                ",
      "                ",
      "                ",
      "                ",
      "     :: ::      ",
      "     :   :      ",
      "                ",
      "     :   :      ",
      "     :: ::      ",
      "                ",
      "                ",
      "                ",
      "                "
    ],
    [
      "                ",
      "            :   ",
      "           :::  ",
      "            :   ",
      "                ",
      "                ",
      "                ",
      "     #####      ",
      "     #####      ",
      "     #####      ",
      "     #####      ",
      "     #####      ",
      "                ",
      "                ",
      "                ",
      "                "
    ],
    [
      "                ",
      "                ",
      "            :   ",
      "                ",
      "                ",
      "                ",
      "                ",
      "                ",
      "                ",
      "                ",
      "                ",
      "                ",
      "                ",
      "                ",
      "                ",
      "                "
    ],
    [
      "                ",
      "                ",
      "            :   ",
      "                ",
      "                ",
      "                ",
      "                ",
      "                ",
      "                ",
      "                ",
      "                ",
      "                ",
      "                ",
      "                ",
      "                ",
      "                "
    ],
    [
      "                ",
      "                ",
      "            g   ",
      "                ",
      "                ",
      "                ",
      "                ",
      "                ",
      "                ",
      "                ",
      "                ",
      "                ",
      "                ",
      "                ",
      "                ",
      "                "
    ]
  ]
}