{
  "xsize": 16,
  "zsize": 16,
  "refpalette": "lcmt:top_decorations",
  "slices": [
    [
      "################",
      "################",
      "################",
      "################",
      "################",
      "################",
      "################",
      "################",
      "################",
      "#######l########",
      "################",
      "################",
      "################",
      "################",
      "################",
      "################"
    ],
    [
      "                ",
      "                ",
      "     :          ",
      "   : : :        ",
      "                ",
      "  :: u ::       ",
      "                ",
      "   : : :        ",
      "     :          ",
      "                ",
      "                ",
      "                ",
      "                ",
      "                ",
      "                ",
      "                "
    ],
    [
      "                ",
      "                ",
      "                ",
      "   : : :        ",
      "                ",
      "   : u :        ",
      "                ",
      "   : : :        ",
      "                ",
      "                ",
      "                ",
      "                ",
      "                ",
      "                ",
      "                ",
      "                "
    ],
    [
      "                ",
      "                ",
      "                ",
      "   : : :        ",
      "                ",
      "   : u :        ",
      "                ",
      "   : : :        ",
      "                ",
      "                ",
      "                ",
      "                ",
      "                ",
      "                ",
      "                ",
      "                "
    ],
    [
      "                ",
      "                ",
      "                ",
      "   _uuu_        ",
      "   uuuuu        ",
      "   uuuuu        ",
      "   uuuuu        ",
      "   _uuu_        ",
      "                ",
      "                ",
      "                ",
      "                ",
      "                ",
      "                ",
      "                ",
      "                "
    ],
    [
      "                ",
      "                ",
      "                ",
      "    ooo         ",
      "   o   o        ",
      "   o   o        ",
      "   o   o        ",
      "    ooo         ",
      "                ",
      "                ",
      "                ",
      "                ",
      "                ",
      "                ",
      "                ",
      "                "
    ],
    [
      "                ",
      "                ",
      "                ",
      "    uuu         ",
      "   u   u        ",
      "   u   u        ",
      "   u   u        ",
      "    uuu         ",
      "                ",
      "                ",
      "                ",
      "                ",
      "                ",
      "                ",
      "                ",
      "                "
    ],
    [
      "                ",
      "                ",
      "                ",
      "    ccc         ",
      "   t   A        ",
      "   t   A        ",
      "   t   A        ",
      "    zzz         ",
      "                ",
      "                ",
      "                ",
      "                ",
      "                ",
      "                ",
      "                ",
      "                "
    ],
    [
      "                ",
      "                ",
      "                ",
      "                ",
      "    tcA         ",
      "    tuA         ",
      "    tzA         ",
      "                ",
      "                ",
      "                ",
      "                ",
      "                ",
      "                ",
      "                ",
      "                ",
      "                "
    ]
  ]
}