{
  "xsize": 16,
  "zsize": 16,
  "slices": [
    [
      "################",
      "################",
      "################",
      "################",
      "################",
      "################",
      "################",
      "################",
      "################",
      "################",
      "################",
      "################",
      "################",
      "################",
      "################",
      "################"
    ],
    [
      "                ",
      "                ",
      "  :::::      :  ",
      "  :___:         ",
      "  :::::      :  ",
      "                ",
      "             :  ",
      "                ",
      "                ",
      "                ",
      "                ",
      "   :u           ",
      "   ::           ",
      "                ",
      "                ",
      "                "
    ],
    [
      "                ",
      "                ",
      "             :  ",
      "                ",
      "             :  ",
      "                ",
      "             :  ",
      "                ",
      "                ",
      "                ",
      "                ",
      "    :           ",
      "                ",
      "                ",
      "                ",
      "                "
    ],
    [
      "                ",
      "                ",
      "             :  ",
      "                ",
      "             :  ",
      "                ",
      "             :  ",
      "                ",
      "                ",
      "                ",
      "    :           ",
      "   :::          ",
      "    :           ",
      "                ",
      "                ",
      "                "
    ],
    [
      "                ",
      "                ",
      "                ",
      "                ",
      "                ",
      "                ",
      "                ",
      "                ",
      "                ",
      "                ",
      "                ",
      "    :           ",
      "                ",
      "                ",
      "                ",
      "                "
    ],
    [
      "                ",
      "                ",
      "                ",
      "                ",
      "                ",
      "                ",
      "                ",
      "                ",
      "                ",
      "                ",
      "                ",
      "    g           ",
      "                ",
      "                ",
      "                ",
      "                "
    ]
  ]
}
