{
  "xsize": 16,
  "zsize": 16,
  "slices": [
    [
      "################",
      "################",
      "################",
      "################",
      "################",
      "################",
      "################",
      "################",
      "################",
      "################",
      "################",
      "################",
      "################",
      "################",
      "################",
      "################"
    ],
    [
      "                ",
      "                ",
      "                ",
      "                ",
      "    #aaaaaa#    ",
      "    a**  * a    ",
      "    a     *a    ",
      "           a    ",
      "    a     *a    ",
      "    a* * **a    ",
      "    #aaaaaa#    ",
      "                ",
      "                ",
      "                ",
      "                ",
      "                "
    ],
    [
      "                ",
      "                ",
      "                ",
      "                ",
      "    #aaaaaa#    ",
      "    a      a    ",
      "    a      a    ",
      "           a    ",
      "    a      a    ",
      "    a      a    ",
      "    #aaaaaa#    ",
      "                ",
      "                ",
      "                ",
      "                ",
      "                "
    ],
    [
      "                ",
      "                ",
      "                ",
      "                ",
      "    ________    ",
      "    _++++++_    ",
      "    _++++++_    ",
      "    _++++++_    ",
      "    _++++++_    ",
      "    _++++++_    ",
      "    ________    ",
      "                ",
      "                ",
      "                ",
      "                ",
      "                "
    ]
  ]
}