{
  "refpalette": "lostcities:top_decorations",
  "xsize": 16,
  "zsize": 16,
  "slices": [
    [
      "################",
      "################",
      "################",
      "################",
      "################",
      "################",
      "################",
      "################",
      "################",
      "################",
      "################",
      "################",
      "################",
      "################",
      "################",
      "################"
    ],
    [
      "                ",
      "                ",
      "                ",
      "                ",
      "   uu       #   ",
      "   uu           ",
      "            #   ",
      "                ",
      "                ",
      "                ",
      "                ",
      "        #   #   ",
      "                ",
      "                ",
      "                ",
      "                "
    ],
    [
      "                ",
      "                ",
      "                ",
      "                ",
      "   kk       w   ",
      "   kk           ",
      "            w   ",
      "                ",
      "                ",
      "                ",
      "                ",
      "        w   w   ",
      "                ",
      "                ",
      "                ",
      "                "
    ],
    [
      "                ",
      "                ",
      "                ",
      "                ",
      "            j   ",
      "                ",
      "            j   ",
      "                ",
      "                ",
      "                ",
      "                ",
      "        j   j   ",
      "                ",
      "                ",
      "                ",
      "                "
    ]
  ]
}
