{
  "xsize": 16,
  "zsize": 16,
  "refpalette": "lostcities:megasolar",
  "slices": [
    [
      "vvvvvvvvvvvvvvvv",
      "vvvvvvvvvvvvvvvv",
      "vvvvvvvvvvvvvvvv",
      "vvvvvvvvvvvvvvvv",
      "vvvvvvvvvvvvvvvv",
      "vvvvvvvvvvvvvvvv",
      "vvvvvvvvvvvvvvvv",
      "vvvvvvvvvvvvvvvv",
      "vvvvvvvvvvvvvvvv",
      "vvvvvvvvvvvvvvvv",
      "vvvvvvvvvvvvvvvv",
      "vvvvvvvvvvvvvvvv",
      "vvvvvvvvvvvvvvvv",
      "vvvvvvvvvvvvvvvv",
      "vvvvvvvvvvvvvvvv",
      "vvvvvvvvvvvvvvvv"
    ],
    [
      "                ",
      " ! !        ! ! ",
      "  !          !  ",
      " ! !        ! ! ",
      "                ",
      "                ",
      "                ",
      "                ",
      "                ",
      "                ",
      "                ",
      "                ",
      " ! !        ! ! ",
      "  !          !  ",
      " ! !        ! ! ",
      "                "
    ],
    [
      "                ",
      "                ",
      "  !          !  ",
      "                ",
      "                ",
      "                ",
      "                ",
      "                ",
      "                ",
      "                ",
      "                ",
      "                ",
      "                ",
      "  !          !  ",
      "                ",
      "                "
    ],
    [
      "                ",
      " !!!!!!!!!!!!!! ",
      " !!!!!!!!!!!!!! ",
      " !!!!!!!!!!!!!! ",
      " !!!!!!!!!!!!!! ",
      " !!!!!!!!!!!!!! ",
      " !!!!!!!!!!!!!! ",
      " !!!!!!!!!!!!!! ",
      " !!!!!!!!!!!!!! ",
      " !!!!!!!!!!!!!! ",
      " !!!!!!!!!!!!!! ",
      " !!!!!!!!!!!!!! ",
      " !!!!!!!!!!!!!! ",
      " !!!!!!!!!!!!!! ",
      " !!!!!!!!!!!!!! ",
      "                "
    ],
    [
      "                ",
      " !++++++++++++! ",
      " ,            , ",
      " ,            , ",
      " ,            , ",
      " ,            , ",
      " ,            , ",
      " ,            , ",
      " ,            , ",
      " ,            , ",
      " ,            , ",
      " ,            , ",
      " ,            , ",
      " ,            , ",
      " !++++++++++++! ",
      "                "
    ],
    [
      "                ",
      " !++++++++++++! ",
      " ,            , ",
      " ,            , ",
      " ,            , ",
      " ,            , ",
      " ,            , ",
      " ,            , ",
      " ,            , ",
      " ,            , ",
      " ,            , ",
      " ,            , ",
      " ,            , ",
      " ,            , ",
      " !++++++++++++! ",
      "                "
    ]
  ]
}