{
  "xsize": 16,
  "zsize": 16,
  "refpalette": "pomkotsmechs:megasolar",
  "slices": [
    [
      "vvvvvvvvvvvvvvvv",
      "vvvvvvvvvvvvvvvv",
      "vvvvvvvvvvvvvvvv",
      "vvvvvvvvvvvvvvvv",
      "vvvvvvvvvvvvvvvv",
      "vvvvvvvvvvvvvvvv",
      "vvvvvvvvvvvvvvvv",
      "vvvvvvvvvvvvvvvv",
      "vvvvvvvvvvvvvvvv",
      "vvvvvvvvvvvvvvvv",
      "vvvvvvvvvvvvvvvv",
      "vvvvvvvvvvvvvvvv",
      "vvvvvvvvvvvvvvvv",
      "vvvvvvvvvvvvvvvv",
      "vvvvvvvvvvvvvvvv",
      "vvvvvvvvvvvvvvvv"
    ],
    [
      "                ",
      "  !          !  ",
      " !!!        !!! ",
      "  !  ##      !  ",
      "    ##          ",
      "    #           ",
      "   ##           ",
      "   #            ",
      "                ",
      "                ",
      "                ",
      "                ",
      "  !##        !  ",
      " !!!###     !!! ",
      "  !          !  ",
      "                "
    ],
    [
      "                ",
      "                ",
      "  !          !  ",
      "                ",
      "                ",
      "                ",
      "                ",
      "                ",
      "                ",
      "                ",
      "                ",
      "                ",
      "                ",
      "  !          !  ",
      "                ",
      "                "
    ],
    [
      "                ",
      " $$$$$$$$$$$$$$ ",
      " $!$$$$$$$$$$!$ ",
      "                ",
      "                ",
      "                ",
      "                ",
      "                ",
      "                ",
      "                ",
      "                ",
      "                ",
      "                ",
      "  !          !  ",
      "                ",
      "                "
    ],
    [
      "                ",
      " &''''''''''''& ",
      " &''''''''''''& ",
      " $$$$$$$$$$$$$$ ",
      " $$$$$$$$$$$$$$ ",
      "                ",
      "                ",
      "                ",
      "                ",
      "                ",
      "                ",
      "                ",
      "                ",
      "  !          !  ",
      "                ",
      "                "
    ],
    [
      "                ",
      "                ",
      "                ",
      " &''''''''''''& ",
      " &''''''''''''& ",
      " $$$$$$$$$$$$$$ ",
      " $$$$$$$$$$$$$$ ",
      "                ",
      "                ",
      "                ",
      "                ",
      "                ",
      "                ",
      "  !          !  ",
      "                ",
      "                "
    ]
  ]
}