{
  "xsize": 16,
  "zsize": 16,
  "refpalette": "pomkotsmechs:megasolar",
  "slices": [
    [
      "vvvvvvvvvvvvvvvv",
      "vvvvvvvvvvvvvvvv",
      "vvvvvvvvvvvvvvvv",
      "vvv$$$$$$$$$$$$$",
      "vvv$$$$$$$$$$$$$",
      "vvv$$$$$$$$$$$$$",
      "vvv$$$$$$$$$$$$$",
      "vvv$$$$$$$$$$$$$",
      "vvv$$$$$$$$$$$$$",
      "vvv$$$$$$$$$$$$$",
      "vvv$$$$$$$$$$$$$",
      "vvv$$$$$$$$$$$$$",
      "vvv$$$$$$$$$$$$$",
      "vvv$$$$$$$$$$$$$",
      "vvv$$$$$$$$$$$$$",
      "vvv$$$$$$$$$$$$$"
    ],
    [
      "!!!!!   ### !!!!",
      "!!!!!   !#  !!!!",
      "!!!!!!!!!!!!!!!!",
      "!!!!!       !!!!",
      "!!!!!       !!!!",
      "  !             ",
      "  !   $$$$$$   (",
      "  !   $!$$!$    ",
      " !!   $$))$$   (",
      "  !   $$))$$    ",
      "  !   $!$$!$    ",
      "  !   $$$$$$   (",
      "!!!!!           ",
      "!!!!!          (",
      "!!!!!        !!!",
      "!!!!!       !!!!"
    ],
    [
      "  !     ###   ! ",
      " !!!  ##!##  !!!",
      "!!!!!$$$$$$$!!!!",
      " !!!  ####   !!!",
      "  !           ! ",
      "  $             ",
      "  $            (",
      "  $    !$$!     ",
      " !$    $))$    (",
      "  $    $))$     ",
      "  $    !$$!     ",
      "  $            (",
      "  !             ",
      " !!!           (",
      "!!!!!           ",
      " !!!         !!!"
    ],
    [
      "  !      #    ! ",
      " !!!    !##  !!!",
      "!!!!!$$$$$$$!!!!",
      " !!!     #   !!!",
      "  !           ! ",
      "  $             ",
      "  $            (",
      "  $    !  !     ",
      " !$     ))     (",
      "  $     ))      ",
      "  $    !  !     ",
      "  $            (",
      "  !             ",
      " !!!           (",
      "!!!!!        !!!",
      " !!!        !!!!"
    ],
    [
      "  !      #    ! ",
      " !!!    !##  !!!",
      "!!!!!!!!!!!!!!!!",
      " !!!     #   !!!",
      "  !           ! ",
      "  !             ",
      "  !            (",
      "  !    !  !     ",
      " !!     ))     (",
      " #!#    ))      ",
      "  !    !  !     ",
      "  !            (",
      "  !             ",
      " !!!           (",
      "!!!!!           ",
      " !!!         !!!"
    ],
    [
      "  !      #    ! ",
      " !!!    !##  !!!",
      "!!!!!$$$$$$$!!!!",
      " !!!     #   !!!",
      "  !           ! ",
      "  $             ",
      "  $            &",
      "  $    !  !    &",
      " !$     ))     &",
      " #$#    ))      ",
      "  $    !  !     ",
      "  $            &",
      "  !            &",
      " !!!           &",
      "!!!!!           ",
      " !!!         !!!"
    ]
  ]
}