{
  "xsize": 16,
  "zsize": 16,
  "refpalette": "pomkotsmechs:megasolar",
  "slices": [
    [
      "$$$$$$$$$$$$vvvv",
      "$$$$$$$$$$$$vvvv",
      "$$$$$$$$$$$$vvvv",
      "$$$$$$$$$$$$vvvv",
      "$$$$$$$$$$$$vvvv",
      "$$$$$$$$$$$$vvvv",
      "$$$$$$$$$$$$vvvv",
      "$$$$$$$$$$$$vvvv",
      "$$$$$$$$$$$$vvvv",
      "$$$$$$$$$$$$vvvv",
      "$$$$$$$$$$$$vvvv",
      "$$$$$$$$$$$$vvvv",
      "vvvvvvvvvvvvvvvv",
      "vvvvvvvvvvvvvvvv",
      "vvvvvvvvvvvvvvvv",
      "vvvvvvvvvvvvvvvv"
    ],
    [
      "!          !!!!!",
      "           !!!!!",
      "  $$$$$$   !!!!!",
      "  $!$$!$   !!!!!",
      "  $$))$$     !  ",
      "  $$))$$     !  ",
      "  $!$$!$     !  ",
      "  $$$$$$     !! ",
      "             !  ",
      "             !  ",
      "             !  ",
      "!!!!       !!!!!",
      "!!!!       !!!!!",
      "!!!!!!!!!!!!!!!!",
      "!!!!   !   !!!!!",
      "!!!!       !!!!!"
    ],
    [
      "!           !!! ",
      "           !!!!!",
      "            !!! ",
      "   !$$!      !  ",
      "   $))$      $  ",
      "   $))$      $  ",
      "   !$$!      $  ",
      "             $! ",
      "             $  ",
      "             $  ",
      "             $  ",
      " !           !  ",
      "!!!         !!! ",
      "!!!!$$$$$$$!!!!!",
      "!!!    !    !!! ",
      " !           !  "
    ],
    [
      "!           !!! ",
      "           !!!!!",
      "            !!! ",
      "   !  !      !  ",
      "    ))       $  ",
      "    ))       $  ",
      "   !  !      $  ",
      "             $! ",
      "             $  ",
      "             $  ",
      "             $  ",
      " !           !  ",
      "!!!         !!! ",
      "!!!!$$$$$$$!!!!!",
      "!!!    !    !!! ",
      " !           !  "
    ],
    [
      "!           !!! ",
      "           !!!!!",
      "            !!! ",
      "   !  !      !  ",
      "    ))       !  ",
      "    ))       !  ",
      "   !  !      !  ",
      "             !! ",
      "             !  ",
      "             !  ",
      "             !  ",
      " !           !  ",
      "!!!         !!! ",
      "!!!!!!!!!!!!!!!!",
      "!!!    !    !!! ",
      " !           !  "
    ],
    [
      "!           !!! ",
      "           !!!!!",
      "            !!! ",
      "   !  !      !  ",
      "    ))       $  ",
      "    ))       $  ",
      "   !  !     #$# ",
      "             $! ",
      "             $  ",
      "             $  ",
      "             $  ",
      " !           !  ",
      "!!!         !!! ",
      "!!!!$$$$$$$!!!!!",
      "!!!    !    !!! ",
      " !           !  "
    ]
  ]
}