{
  "xsize": 16,
  "zsize": 16,
  "refpalette": "pomkotsmechs:megasolar",
  "slices": [
    [
      "vvv$$$$$$$$$$$$$",
      "vvv$$$$$$$$$$$$$",
      "vvv$$$$$$$$$$$$$",
      "vvv$$$$$$$$$$$$$",
      "vvv$$$$$$$$$$$$$",
      "vvv$$$$$$$$$$$$$",
      "vvv$$$$$$$$$$$$$",
      "vvv$$$$$$$$$$$$$",
      "vvv$$$$$$$$$$$$$",
      "vvv$$$$$$$$$$$$$",
      "vvv$$$$$$$$$$$$$",
      "vvv$$$$$$$$$$$$$",
      "vvv$$$$$$$$$$$$$",
      "vvv$$$$$$$$$$$$$",
      "vvv$$$$$$$$$$$$$",
      "vvv$$$$$$$$$$$$$"
    ],
    [
      "!!!!( (  ( (!!!!",
      "            !!!!",
      "    ( (  ( ( !!!",
      "                ",
      "                ",
      "                ",
      "                ",
      "                ",
      "                ",
      "                ",
      "                ",
      "                ",
      "                ",
      "    ( (  ( (    ",
      "             !!!",
      "!!!!( (  ( ( ! !"
    ],
    [
      "  ! ( (  ( ( !!!",
      "             !!!",
      "    ( (  ( (    ",
      "                ",
      "                ",
      "                ",
      "                ",
      "                ",
      "                ",
      "                ",
      "                ",
      "                ",
      "                ",
      "    ( (  ( (    ",
      "             !!!",
      "  ! ( (  ( ( ! !"
    ],
    [
      "  ! ( (  ( (!!!!",
      "            !!!!",
      "    ( (  ( ( !!!",
      "                ",
      "                ",
      "                ",
      "                ",
      "                ",
      "                ",
      "                ",
      "                ",
      "                ",
      "                ",
      "    ( (  ( (    ",
      "             !!!",
      "  ! ( (  ( ( ! !"
    ],
    [
      "  ! ( (  ( ( !!!",
      "             !!!",
      "    ( (  ( (    ",
      "                ",
      "                ",
      "                ",
      "                ",
      "                ",
      "                ",
      "                ",
      "                ",
      "                ",
      "                ",
      "    ( (  ( (    ",
      "             !!!",
      "  ! ( (  ( ( ! !"
    ],
    [
      "  ! &&&  &&& !!!",
      "    &&&  &&& !!!",
      "    &&&  &&&    ",
      "                ",
      "                ",
      "                ",
      "                ",
      "                ",
      "                ",
      "                ",
      "                ",
      "                ",
      "                ",
      "    &&&  &&&    ",
      "    &&&  &&& !!!",
      "  ! &&&  &&& ! !"
    ]
  ]
}