{
  "xsize": 16,
  "zsize": 16,
  "refpalette": "lcmt:top_decorations",
  "slices": [
    [
      "################",
      "################",
      "################",
      "################",
      "################",
      "################",
      "################",
      "################",
      "################",
      "################",
      "##########  ####",
      "##########  ####",
      "##########  ####",
      "##########cc####",
      "################",
      "################"
    ],
    [
      "                ",
      "                ",
      "                ",
      "   uu           ",
      "   uu           ",
      "    k           ",
      "    k           ",
      "    k           ",
      "   kk           ",
      "   k     ::::   ",
      "   k     :  :   ",
      "   uu    :  :   ",
      "   uu    :  :   ",
      "         :  :   ",
      "                ",
      "                "
    ],
    [
      "                ",
      "                ",
      "                ",
      "   mn           ",
      "   qr           ",
      "                ",
      "                ",
      "                ",
      "                ",
      "                ",
      "                ",
      "   mn           ",
      "   qr           ",
      "                ",
      "                ",
      "                "
    ]
  ]
}
