{
  "xsize": 16,
  "zsize": 16,
  "slices": [
    [
      "#@#@#@#@@#@#@#@#",
      "@##############@",
      "################",
      "@##############@",
      "################",
      "@##############@",
      "################",
      "@##############@",
      "@##############@",
      "################",
      "@#########  ###@",
      "##########  ####",
      "@#########  ###@",
      "##########cc####",
      "@##############@",
      "#@#@#@#@@#@#@#@#"
    ],
    [
      "#`#`#`#``#`#`#`#",
      "`              `",
      "#              #",
      "`              `",
      "#              #",
      "`              `",
      "#              #",
      "`              `",
      "`         cc   `",
      "#        :dd:  #",
      "`        :  :  `",
      "#        :  :  #",
      "`        :  :  `",
      "#              #",
      "`              `",
      "#`#`#`#``#`#`#`#"
    ],
    [
      "#`#`#`#``#`#`#`#",
      "`              `",
      "#              #",
      "`              `",
      "#              #",
      "`              `",
      "#              #",
      "`              `",
      "`              `",
      "#         cc   #",
      "`         dd   `",
      "#              #",
      "`              `",
      "#              #",
      "`              `",
      "#`#`#`#``#`#`#`#"
    ],
    [
      "#`#`#`#``#`#`#`#",
      "`              `",
      "#              #",
      "`              `",
      "#              #",
      "`              `",
      "#              #",
      "`              `",
      "`              `",
      "#              #",
      "`         cc   `",
      "#         dd   #",
      "`              `",
      "#              #",
      "`              `",
      "#`#`#`#``#`#`#`#"
    ],
    [
      "#`#`#`#``#`#`#`#",
      "`              `",
      "#              #",
      "`              `",
      "#              #",
      "`              `",
      "#              #",
      "`              `",
      "`              `",
      "#              #",
      "`              `",
      "#         cc   #",
      "`         dd   `",
      "#              #",
      "`              `",
      "#`#`#`#``#`#`#`#"
    ],
    [
      "#`#`#`#``#`#`#`#",
      "`              `",
      "#              #",
      "`              `",
      "#              #",
      "`              `",
      "#              #",
      "`              `",
      "`              `",
      "#              #",
      "`              `",
      "#              #",
      "`         cc   `",
      "#         dd   #",
      "`              `",
      "#`#`#`#``#`#`#`#"
    ]
  ]
}
