{
  "refpalette": "lcmt:top_decorations",
  "xsize": 16,
  "zsize": 16,
  "slices": [
    [
      "################",
      "################",
      "################",
      "################",
      "################",
      "################",
      "################",
      "################",
      "################",
      "################",
      "##########  ####",
      "##########  ####",
      "##########  ####",
      "##########cc####",
      "################",
      "################"
    ],
    [
      "                ",
      "                ",
      "                ",
      "                ",
      "                ",
      "                ",
      "                ",
      "                ",
      "                ",
      "         ####   ",
      "         #  #   ",
      "         #  #   ",
      "         #  #   ",
      "         #  #   ",
      "                ",
      "                "
    ],
    [
      "                ",
      "                ",
      "                ",
      "                ",
      "                ",
      "                ",
      "                ",
      "                ",
      "                ",
      "         #aa#   ",
      "         a  a   ",
      "         a  a   ",
      "         a  a   ",
      "         #  #   ",
      "                ",
      "                "
    ],
    [
      "                ",
      "                ",
      "                ",
      "                ",
      "                ",
      "                ",
      "                ",
      "                ",
      "                ",
      "         ####   ",
      "         ####   ",
      "         ####   ",
      "         ####   ",
      "         ####   ",
      "                ",
      "                "
    ]
  ]
}
