{
  "xsize": 16,
  "zsize": 16,
  "slices": [
    [
      "################",
      "################",
      "################",
      "################",
      "################",
      "################",
      "################",
      "################",
      "################",
      "################",
      "##########  ####",
      "##########  ####",
      "##########  ####",
      "##########cc####",
      "################",
      "################"
    ],
    [
      "                ",
      "                ",
      "  ###           ",
      "  ###           ",
      "  ###           ",
      "                ",
      "                ",
      "                ",
      "                ",
      "                ",
      "   :            ",
      "                ",
      "   :            ",
      "                ",
      "                ",
      "                "
    ],
    [
      "                ",
      "                ",
      "                ",
      "   :            ",
      "                ",
      "                ",
      "                ",
      "                ",
      "                ",
      "                ",
      "   :            ",
      "                ",
      "   :            ",
      "                ",
      "                ",
      "                "
    ],
    [
      "                ",
      "                ",
      "                ",
      "   :            ",
      "                ",
      "                ",
      "                ",
      "                ",
      "                ",
      "                ",
      "   :            ",
      "                ",
      "   :            ",
      "                ",
      "                ",
      "                "
    ],
    [
      "                ",
      "                ",
      "   :            ",
      "  :::           ",
      "   :            ",
      "                ",
      "                ",
      "                ",
      "                ",
      "                ",
      "                ",
      "                ",
      "                ",
      "                ",
      "                ",
      "                "
    ]
  ]
}