{
  "xsize": 16,
  "zsize": 16,
  "refpalette": "lcmt:top_decorations",
  "slices": [
    [
      "################",
      "################",
      "################",
      "################",
      "################",
      "################",
      "################",
      "################",
      "################",
      "################",
      "##########  ####",
      "##########  ####",
      "##########  ####",
      "##########cc####",
      "################",
      "################"
    ],
    [
      "                ",
      "                ",
      "                ",
      "                ",
      "                ",
      "                ",
      "                ",
      "                ",
      "                ",
      "                ",
      "         a  a   ",
      "         a  a   ",
      "         a  a   ",
      "         a  a   ",
      "                ",
      "                "
    ],
    [
      "                ",
      "                ",
      "                ",
      "                ",
      "                ",
      "                ",
      "                ",
      "                ",
      "                ",
      "                ",
      "         a  a   ",
      "         a  a   ",
      "         a  a   ",
      "         a  a   ",
      "                ",
      "                "
    ],
    [
      "                ",
      "                ",
      "                ",
      "                ",
      "                ",
      "                ",
      "                ",
      "                ",
      "                ",
      "                ",
      "         ####   ",
      "         ####   ",
      "         ####   ",
      "         ####   ",
      "                ",
      "                "
    ]
  ]
}
