{
  "xsize": 16,
  "zsize": 16,
  "palette": {
    "palette": [
      {
        "char": "D",
        "block": "minecraft:iron_door[half=lower]"
      },
      {
        "char": "d",
        "block": "minecraft:iron_door[half=upper]"
      },
      {
        "char": "P",
        "blocks": [
          {
            "random": 32,
            "block": "minecraft:quartz_bricks"
          },
          {
            "random": 1000,
            "block": "minecraft:quartz_block"
          }
        ]
      },
      {
        "char": "B",
        "block": "minecraft:barrel[facing=north]"
      },
      {
        "char": "c",
        "blocks": [
          {
            "random": 32,
            "block": "minecraft:exposed_cut_copper"
          },
          {
            "random": 1000,
            "block": "minecraft:exposed_copper"
          }
        ]
      },
      {
        "char": "1",
        "blocks": [
          {
            "random": 32,
            "block": "minecraft:weathered_cut_copper_stairs[facing=north]"
          },
          {
            "random": 1000,
            "block": "minecraft:exposed_cut_copper_stairs[facing=north]"
          }
        ]
      },
      {
        "char": "2",
        "blocks": [
          {
            "random": 32,
            "block": "minecraft:weathered_cut_copper_stairs[facing=west]"
          },
          {
            "random": 1000,
            "block": "minecraft:exposed_cut_copper_stairs[facing=west]"
          }
        ]
      },
      {
        "char": "3",
        "blocks": [
          {
            "random": 32,
            "block": "minecraft:weathered_cut_copper_stairs[facing=south]"
          },
          {
            "random": 1000,
            "block": "minecraft:exposed_cut_copper_stairs[facing=south]"
          }
        ]
      },
      {
        "char": "4",
        "blocks": [
          {
            "random": 32,
            "block": "minecraft:weathered_cut_copper_stairs[facing=east]"
          },
          {
            "random": 1000,
            "block": "minecraft:exposed_cut_copper_stairs[facing=east]"
          }
        ]
      }
    ]
  },
  "slices": [
    [
      "                ",
      "                ",
      "                ",
      "   ############ ",
      "   ############ ",
      "   ############ ",
      "   ##########   ",
      "   ##########   ",
      "   ##########   ",
      "   ##########   ",
      "   ##########   ",
      "   ##########   ",
      "   ##########   ",
      "                ",
      "                ",
      "                "
    ],
    [
      "                ",
      "                ",
      "                ",
      "   ############ ",
      "   ############ ",
      "   ############ ",
      "   ##########   ",
      "   ##########   ",
      "   ##########   ",
      "   ##########   ",
      "   ##########   ",
      "   ##########   ",
      "   ##########   ",
      "                ",
      "                ",
      "                "
    ],
    [
      "                ",
      "                ",
      "                ",
      "   ############ ",
      "   ############ ",
      "   ############ ",
      "   ##########   ",
      "   ##########   ",
      "   ##########   ",
      "   ##########   ",
      "   ##########   ",
      "   ##########   ",
      "   ##########   ",
      "                ",
      "                ",
      "                "
    ],
    [
      "                ",
      "                ",
      "                ",
      "   cPPPPPPPPc   ",
      "   P    B   P:  ",
      "   P        P   ",
      "   P        P   ",
      "   PC       P   ",
      "   P        P   ",
      "   P        P   ",
      "   P        P   ",
      "   P        P   ",
      "   cPDPPPPPPc   ",
      "                ",
      "                ",
      "                "
    ],
    [
      "                ",
      "                ",
      "                ",
      "   cPPPPPPPPc   ",
      "   P        P:  ",
      "   P        P   ",
      "   P        P   ",
      "   P        P   ",
      "   P        :   ",
      "   P        :   ",
      "   P        P   ",
      "   P        P   ",
      "   cPdPPP:PPc   ",
      "                ",
      "                ",
      "                "
    ],
    [
      "                ",
      "                ",
      "                ",
      "   cPPPPPPPPc   ",
      "   P        P:  ",
      "   P        P   ",
      "   P        P   ",
      "   P        P   ",
      "   P        P   ",
      "   P        P   ",
      "   P        P   ",
      "   P        P   ",
      "   cPPPPPPPPc   ",
      "                ",
      "                ",
      "                "
    ],
    [
      "                ",
      "                ",
      "                ",
      "   c11111111c   ",
      "   2########cc  ",
      "   2########4   ",
      "   2########4   ",
      "   2########4   ",
      "   2########4   ",
      "   2########4   ",
      "   2########4   ",
      "   2########4   ",
      "   c33333333c   ",
      "                ",
      "                ",
      "                "
    ],
    [
      "                ",
      "                ",
      "                ",
      "                ",
      "                ",
      "     :    :     ",
      "                ",
      "                ",
      "                ",
      "                ",
      "     :    :     ",
      "                ",
      "                ",
      "                ",
      "                ",
      "                "
    ]
  ]
}