{
  "meta": [
    {
      "key": "support",
      "char": "v"
    }
  ],
  "xsize": 16,
  "zsize": 16,
  "refpalette": "lcmt:highway",
  "slices": [
    [
      "vuRuRuRuRuRuRuRv",
      "RRRRRRRRRRRRRRRu",
      "uRRRRRRRRRRRRRRR",
      "RRRRRRRRRRRRRRRu",
      "uRRRRRRRRRRRRRRR",
      "RRRRRRRRRRRRRRRu",
      "uRRRRRRRRRRRRRRR",
      "RRRRRRRRRRRRRRRu",
      "uRRRRRRRRRRRRRRR",
      "RRRRRRRRRRRRRRRu",
      "uRRRRRRRRRRRRRRR",
      "RRRRRRRRRRRRRRRu",
      "uRRRRRRRRRRRRRRR",
      "RRRRRRRRRRRRRRRu",
      "uRRRRRRRRRRRRRRR",
      "vRuRuRuRuRuRuRuv"
    ],
    [
      "v~~~~~~~~~~~~~~v",
      "~~~~~~~~~~~~~~~~",
      "~~~~~~~~~~~~~~~~",
      "~~~~~~~~~~~~~~~~",
      "~~~~~~~~~~~~~~~~",
      "~~~~~~~~~~~~~~~~",
      "~~~~~~~~~~~~~~~~",
      "~~~~~~~~~~~~~~~~",
      "~~~~~~~~~~~~~~~~",
      "~~~~~~~~~~~~~~~~",
      "~~~~~~~~~~~~~~~~",
      "~~~~~~~~~~~~~~~~",
      "~~~~~~~~~~~~~~~~",
      "~~~~~~~~~~~~~~~~",
      "~~~~~~~~~~~~~~~~",
      "v~~~~~~~~~~~~~~v"
    ],
    [
      "v~~~~~~~~~~~~~~v",
      "~~~~~~~~~~~~~~~~",
      "~~~~~~~~~~~~~~~~",
      "~~~~~~~~~~~~~~~~",
      "~~~~~~~~~~~~~~~~",
      "~~~~~~~~~~~~~~~~",
      "~~~~~~~~~~~~~~~~",
      "~~~~~~~~~~~~~~~~",
      "~~~~~~~~~~~~~~~~",
      "~~~~~~~~~~~~~~~~",
      "~~~~~~~~~~~~~~~~",
      "~~~~~~~~~~~~~~~~",
      "~~~~~~~~~~~~~~~~",
      "~~~~~~~~~~~~~~~~",
      "~~~~~~~~~~~~~~~~",
      "v~~~~~~~~~~~~~~v"
    ],
    [
      "v~~~~~~~~~~~~~~v",
      "~~~~~~~~~~~~~~~~",
      "~~~~~~~~~~~~~~~~",
      "~~~~~~~~~~~~~~~~",
      "~~~~~~~~~~~~~~~~",
      "~~~~~~~~~~~~~~~~",
      "~~~~~~~~~~~~~~~~",
      "~~~~~~~~~~~~~~~~",
      "~~~~~~~~~~~~~~~~",
      "~~~~~~~~~~~~~~~~",
      "~~~~~~~~~~~~~~~~",
      "~~~~~~~~~~~~~~~~",
      "~~~~~~~~~~~~~~~~",
      "~~~~~~~~~~~~~~~~",
      "~~~~~~~~~~~~~~~~",
      "v~~~~~~~~~~~~~~v"
    ],
    [
      " v~~~~~~~~~~~~v ",
      "vE~~~~~~~~~~~~Ev",
      "~~~~~~~~~~~~~~~~",
      "~~~~~~~~~~~~~~~~",
      "~~~~~~~~~~~~~~~~",
      "~~~~~~~~~~~~~~~~",
      "~~~~~~~~~~~~~~~~",
      "~~~~~~~~~~~~~~~~",
      "~~~~~~~~~~~~~~~~",
      "~~~~~~~~~~~~~~~~",
      "~~~~~~~~~~~~~~~~",
      "~~~~~~~~~~~~~~~~",
      "~~~~~~~~~~~~~~~~",
      "~~~~~~~~~~~~~~~~",
      "vE~~~~~~~~~~~~Ev",
      " v~~~~~~~~~~~~v "
    ],
    [
      "  vvvvvvvvvvvv  ",
      " avvvvvvvvvvvva ",
      "vvvvvvvvvvvvvvvv",
      "vvvvvvvvvvvvvvvv",
      "vvvvvvvvvvvvvvvv",
      "vvvvvvvvvvvvvvvv",
      "vvvvvvvvvvvvvvvv",
      "vvvvvvvvvvvvvvvv",
      "vvvvvvvvvvvvvvvv",
      "vvvvvvvvvvvvvvvv",
      "vvvvvvvvvvvvvvvv",
      "vvvvvvvvvvvvvvvv",
      "vvvvvvvvvvvvvvvv",
      "vvvvvvvvvvvvvvvv",
      " avvvvvvvvvvvva ",
      "  vvvvvvvvvvvv  "
    ]
  ]
}