{
  "xsize": 16,
  "zsize": 16,
  "refpalette": "pomkotsmechs:ships",
  "slices": [
    [
      "                ",
      "ΣΣΣΣ            ",
      "HHHHHH          ",
      "     HH         ",
      "     ΃HH        ",
      "μμμμ΃΃΃HH##     ",
      "    #΃΃΃HHH#    ",
      "    #΃΃΃΃΃H     ",
      "    $΃΃΃΃΃HH    ",
      "     ΃΃΃΃΃΃H    ",
      "       ΃΃΃΃H    ",
      "       ΃΃΃΃H    ",
      "        ΃΃΃H    ",
      "$$$$$$$$$$$H    ",
      "        $  H    ",
      "        $  H    "
    ],
    [
      "iiii;           ",
      "    ϡ           ",
      "HHHHH;          ",
      "    He;         ",
      "HHHHH m;        ",
      "    ϳ  m;       ",
      "HHHHH###mi;     ",
      "   #H/### j     ",
      "    HHH   m;    ",
      "II   HHH   j    ",
      "II     HHΣ j    ",
      "        HH j    ",
      "         HHf    ",
      "$$$$$$$$$$$f    ",
      "        $  H    ",
      "        $  H    "
    ],
    [
      "                ",
      "                ",
      "HHHH            ",
      "`΃΃HH           ",
      "  ΃΃H           ",
      "   3ϴ#          ",
      "  ΃΃H## #       ",
      "΃΃΃΃H##         ",
      "΃΃΃ H/HΑ        ",
      "$$$$$HHH #      ",
      "$$$$$$$HHϵ#     ",
      "$$$$$$$$HH#     ",
      "$$$$$$$$$HH     ",
      "$$$$$$$$$$H     ",
      "$$$$$$$$$$$H    ",
      "$$$$$$$$$$$H    "
    ],
    [
      "                ",
      "                ",
      "HHHͿ            ",
      "%  H            ",
      "μμ HͿ           ",
      "μμ%HͿ#          ",
      "μμ HͿ#          ",
      "%  H#           ",
      "%  H            ",
      "HHHHH H  #      ",
      "   '  'H#Ϳ#     ",
      "   '  ' H##     ",
      "''''  ' #H#     ",
      "      '  #H     ",
      "      '''''H    ",
      "           H    "
    ],
    [
      "                ",
      "                ",
      "                ",
      "                ",
      "Z&              ",
      "&&  #           ",
      "Z&  #           ",
      "                ",
      "                ",
      "HHHHH H         ",
      "   '  'H #      ",
      "   '  ' ϛ#      ",
      "''''  ' #ϛ#     ",
      "      ' ##H     ",
      "      '''''H    ",
      "           H    "
    ],
    [
      "                ",
      "                ",
      "                ",
      "                ",
      "                ",
      "                ",
      "                ",
      "                ",
      "                ",
      "HHHHHH          ",
      "''''''H         ",
      "'''''''ϛ##      ",
      "'''''''#ϛ##     ",
      "      '##ϛ      ",
      "      ''''H     ",
      "        #  H    "
    ]
  ]
}