{
  "xsize": 16,
  "zsize": 16,
  "refpalette": "lostcities:ships",
  "slices": [
    [
      "      !$$ & & & ",
      "      !$$       ",
      "      !$$ & & & ",
      "       !$       ",
      "       !$ & & & ",
      "       !$       ",
      "       !$ & & & ",
      "       !$       ",
      "       !$       ",
      "       !$$$$$$$$",
      "       !$       ",
      "       !$       ",
      "       !$ p  p p",
      "       !$       ",
      "       !$       ",
      "       !$       "
    ],
    [
      "      !$$ & & & ",
      "      !$$       ",
      "      !$$ & & & ",
      "      !$$       ",
      "      !$$ & & & ",
      "      !$$       ",
      "       !$ & & & ",
      "       !$       ",
      "       !$       ",
      "       !$'''''''",
      "       !$       ",
      "       !$       ",
      "       !$ &&&& &",
      "       !$ &qq& &",
      "       !$ &qq& &",
      "       !$ &qq& &"
    ],
    [
      "      !$$ < < < ",
      "      !$$       ",
      "      !$$ < < < ",
      "      !$$       ",
      "      !$$ < < < ",
      "      !$$       ",
      "      !$$ < < < ",
      "      !$$       ",
      "       !$       ",
      "       !$'''''''",
      "       !$       ",
      "       !$       ",
      "       !$ &//& &",
      "       !$ 9  E 9",
      "       !$ 9  E 9",
      "       !$ 9  E 9"
    ],
    [
      "      &$$ < < < ",
      "      &$$       ",
      "      &$$ < < < ",
      "      &$$       ",
      "      &$$ < < < ",
      "      &$$       ",
      "      &$$ < < < ",
      "      &$$       ",
      "       &$       ",
      "       &$''''''$",
      "       &$      $",
      "       &$       ",
      "       &$ &//& &",
      "       &$ 9  E 9",
      "       &$ 9  E 9",
      "       &$ 9  E 9"
    ],
    [
      "      H$$ < < < ",
      "      H$$       ",
      "      H$$ < < < ",
      "      H$$       ",
      "      H$$ < < < ",
      "      H$$       ",
      "      H$$ < < < ",
      "      H$$       ",
      "      H$$       ",
      "       H$''''''$",
      "       H$       ",
      "       H$       ",
      "       H$ &&&& &",
      "       H$ &rr& &",
      "       H$ &rr& &",
      "       H$ &rr& &"
    ],
    [
      "      H$$ < < < ",
      "      H$$       ",
      "      H$$ < < < ",
      "      H$$       ",
      "      H$$ < < < ",
      "      H$$       ",
      "      H$$ < < < ",
      "      H$$       ",
      "      H$$       ",
      "      H$$''''''$",
      "       H$       ",
      "       H$       ",
      "       H$       ",
      "       H$    #  ",
      "       H$    #  ",
      "       H$    #  "
    ]
  ]
}