{
  "xsize": 16,
  "zsize": 16,
  "refpalette": "pomkotsmechs:ships",
  "slices": [
    [
      "΃΃΃΃΃΃΃΃΃HH     ",
      "΃΃΃΃΃΃΃΃HH      ",
      "΃΃΃΃΃΃΃HH=o     ",
      "΃΃΃΃΃΃HHf j     ",
      "HHHHHHH Ή Ή     ",
      "                ",
      "  *Ρ%           ",
      "                ",
      "  *Ρ%           ",
      "                ",
      "HHHHHH          ",
      "     H          ",
      "      H         ",
      "HHHH  H         ",
      "      H         ",
      "---   H         "
    ],
    [
      "HHHH      j     ",
      "        o j     ",
      "H      nf j     ",
      "      neͽ Ή     ",
      "iiiiiiͽ         ",
      "                ",
      "  %             ",
      "                ",
      "  %             ",
      "                ",
      "HHHHHH          ",
      "΃΃΃΃΃H          ",
      "΃΃΃΃΃HH         ",
      "΃΃΃΃΃΃H         ",
      "HHHH΃΃H         ",
      "---H΃΃H         "
    ],
    [
      "HHHH            ",
      "                ",
      "H               ",
      "                ",
      "                ",
      "                ",
      "                ",
      "                ",
      "                ",
      "                ",
      "iiiii;          ",
      "     j          ",
      "H    m;         ",
      "      j         ",
      "HHHH  j         ",
      "---H  j         "
    ],
    [
      "HHHH            ",
      "                ",
      "H               ",
      "Σ               ",
      "Σ               ",
      "                ",
      "                ",
      "                ",
      "                ",
      "                ",
      "                ",
      "                ",
      "H               ",
      "                ",
      "HHHH            ",
      "   H            "
    ],
    [
      "ͿͿͿͿ            ",
      "                ",
      "H               ",
      "                ",
      "Ϳ               ",
      "Ϳ               ",
      "ϼ               ",
      "Σ               ",
      "Σ               ",
      "                ",
      "                ",
      "                ",
      "H               ",
      "                ",
      "HHHH            ",
      "   H            "
    ],
    [
      "                ",
      "                ",
      ">               ",
      "                ",
      "                ",
      "                ",
      "                ",
      "                ",
      "Ϳ               ",
      "Ϳ               ",
      "ϼ               ",
      "Σ               ",
      "H               ",
      "                ",
      "HHHH            ",
      "   H            "
    ]
  ]
}