{
  "xsize": 16,
  "zsize": 16,
  "refpalette": "pomkotsmechs:ships",
  "slices": [
    [
      "  < < < $$H     ",
      "        $$H     ",
      "  < < < $$H     ",
      "        $$H     ",
      "  < < < $$H     ",
      "        $$H     ",
      "  < < < $$H     ",
      "        $$H     ",
      "        $$H     ",
      "$$''''  $$H     ",
      "$$$$#    H      ",
      "$$$#    ΃H      ",
      "$$$    ΃΃H      ",
      "΃΃΃    ΃΃H      ",
      "΃΃΃΃  ΃΃΃H#     ",
      "΃΃΃΃΃΃΃΃ Hΰ#    "
    ],
    [
      "  p p p $$H     ",
      "        $$H     ",
      "  p p p $$H     ",
      "        $$H     ",
      "  p p p $$H     ",
      "        $$H     ",
      "  p p p $$H     ",
      "        $$H     ",
      "         $H     ",
      "''''     $H     ",
      " ####     H     ",
      "  ##     H      ",
      "HHH      H      ",
      "  Σ      H      ",
      "         H      ",
      "          #     "
    ],
    [
      "        $$H     ",
      "I       $$H     ",
      "I       $$H     ",
      "I       $$H     ",
      "I       $$H     ",
      "        $$H     ",
      "        $$H     ",
      "                ",
      "          H     ",
      "''''      H     ",
      "####            ",
      "  #             ",
      "HHH      H      ",
      "  ϕ             ",
      "                ",
      "                "
    ],
    [
      "HHHHHH΃΃΃΃H     ",
      "H&&&&H΃΃΃΃H     ",
      "H&&&&H΃΃΃΃H     ",
      "HHHHHH΃΃΃΃H     ",
      "H&&&&H΃΃΃΃H     ",
      "H&&&&H΃΃΃΃      ",
      "HHHHHH΃΃        ",
      "΃΃΃΃΃΃          ",
      "΃΃΃΃΃           ",
      "΃΃΃΃            ",
      "΃΃΃#            ",
      "΃΃΃             ",
      "HHH             ",
      "  Ϳ             ",
      "                ",
      "                "
    ],
    [
      "          j     ",
      "          j     ",
      "          j     ",
      "          j     ",
      "                ",
      "        ϖ       ",
      "                ",
      "                ",
      "                ",
      "###             ",
      "####            ",
      "#η#             ",
      "iv              ",
      "                ",
      "                ",
      "                "
    ],
    [
      "                ",
      "                ",
      "                ",
      "                ",
      "        =       ",
      "        ά       ",
      "                ",
      "                ",
      "                ",
      "ΰ#              ",
      "###             ",
      "##              ",
      "ϗvϘ             ",
      "                ",
      "                ",
      "                "
    ]
  ]
}