{
  "xsize": 16,
  "zsize": 16,
  "refpalette": "lostcities:ships",
  "slices": [
    [
      "  & & & '$!     ",
      "        '$!     ",
      "  & & & '$!     ",
      "        '!      ",
      "  & & & $!      ",
      "        $!      ",
      "  & & & $!      ",
      "        $!      ",
      "        $!      ",
      "$$$$$$$$$!      ",
      "    #   $!      ",
      "   #####$!      ",
      "  p p  p$!      ",
      "        $!      ",
      "        $!      ",
      "        $!      "
    ],
    [
      "  & & & $$!     ",
      "        $$!     ",
      "  & & & $$!     ",
      "        $$!     ",
      "  & & & $$!     ",
      "        $$!     ",
      "  & & & $!      ",
      "        $!      ",
      "        $!      ",
      " '''''''$!      ",
      "    #   $!      ",
      "   ###  $!      ",
      "&&& &&&&$!      ",
      "qq& &qq&$!      ",
      "qq& &qq&$!#     ",
      "qq& &qq&$!      "
    ],
    [
      "  < < < $$!     ",
      "        $$!     ",
      "  < < < $$!     ",
      "        $$!     ",
      "  < < < $$!     ",
      "        $$!     ",
      "  < < < $$!     ",
      "        $$!     ",
      "        $!      ",
      " '''''''$!      ",
      "   ##   $!      ",
      "   ###  $!      ",
      "//& &//&$!      ",
      "  E 9  E$!      ",
      "  E 9  E$!#     ",
      "  E 9  E$!      "
    ],
    [
      "$ < < < $$&     ",
      "$       $$&     ",
      "$ < < < $$&     ",
      "$       $$&     ",
      "$ < < < $$&     ",
      "$       $$&     ",
      "$ < < < $$&     ",
      "$       $$&     ",
      "$       $&      ",
      "$$''''''$&      ",
      "$$###   $&      ",
      "  ####  $&      ",
      "//&#&//&$&      ",
      "  E 9  E$&      ",
      "  E 9  E$&#     ",
      "  E 9  E$&#     "
    ],
    [
      "  < < < $$H     ",
      "        $$H     ",
      "  < < < $$H     ",
      "        $$H     ",
      "  < < < $$H     ",
      "        $$H     ",
      "  < < < $$H     ",
      "        $$H     ",
      "        $$H     ",
      " $''''''$H      ",
      "  ###   $H      ",
      "   ##   $H      ",
      "&&&   &&$H      ",
      "rr&   r&$H      ",
      "rr& &rr&$H      ",
      "rr& &rr&$H#     "
    ],
    [
      "  < < < $$H     ",
      "        $$H     ",
      "  < < < $$H     ",
      "        $$H     ",
      "  < < < $$H     ",
      "        $$H     ",
      "  < < < $$H     ",
      "        $$H     ",
      "        $$H     ",
      " $''''''$$H     ",
      "  ###   $H      ",
      "   #    $H      ",
      "        $H      ",
      "        $H      ",
      "        $H#     ",
      "        $H##    "
    ]
  ]
}