{
  "xsize": 16,
  "zsize": 16,
  "refpalette": "pomkotsmechs:ships",
  "slices": [
    [
      "       !$       ",
      "       !$ p  p p",
      "        !       ",
      "        !$$$$$$$",
      "        !$      ",
      "        !$      ",
      "        !$      ",
      "        !!      ",
      "        !!      ",
      "        !!!$$$$$",
      "         !!!!$$$",
      "         !!!!!!!",
      "          !!!!!!",
      "           !!!!!",
      "             !!!",
      "                "
    ],
    [
      "       !$ &qq& &",
      "       !$ &&&& &",
      "       !$       ",
      "       !$$$$$$$$",
      "        !$      ",
      "        !$      ",
      "        !$      ",
      "        !$      ",
      "        !$      ",
      "        !$$$$$$$",
      "        !$$$$$$$",
      "        !!      ",
      "        !!      ",
      "         !!     ",
      "         !!!!   ",
      "         !!!!!!!"
    ],
    [
      "       !$ 9  E 9",
      "       !$ &66& &",
      "       !$       ",
      "       !$$$$$$$$",
      "        !$      ",
      "        !$      ",
      "        !$      ",
      "        !$      ",
      "        !$      ",
      "        !$$$$$$$",
      "        !$$$$$$$",
      "        !       ",
      "        !       ",
      "        !       ",
      "        !!      ",
      "         !      "
    ],
    [
      "       &$ 9  E 9",
      "       &$ &66& &",
      "       &$       ",
      "       &&$$$$$$$",
      "        &$      ",
      "        &$      ",
      "        &$      ",
      "        &$      ",
      "        &$      ",
      "        &$$$$$$$",
      "        &$$$$$$$",
      "        &       ",
      "        &       ",
      "        &       ",
      "        &&      ",
      "         &      "
    ],
    [
      "       H$ &rr& &",
      "       H$ &&&& &",
      "       H$       ",
      "       H$$$$$$$$",
      "       HH$      ",
      "        H       ",
      "        H       ",
      "        H       ",
      "        H       ",
      "        H$ $$$$$",
      "        H$$$$$$$",
      "        H       ",
      "        H       ",
      "        H       ",
      "        H       ",
      "        H       "
    ],
    [
      "       H$       ",
      "       H$       ",
      "       H$       ",
      "       H$$$$$$$$",
      "       H$$      ",
      "       H$       ",
      "        H       ",
      "        H       ",
      "        H       ",
      "         $$$$$$$",
      "        H$$$$$$$",
      "        H       ",
      "        H       ",
      "        H       ",
      "        H       ",
      "        H       "
    ]
  ]
}