{
  "xsize": 16,
  "zsize": 16,
  "refpalette": "pomkotsmechs:ships",
  "slices": [
    [
      "                ",
      "             ΣΣΣ",
      "           HHHHH",
      "          HH    ",
      "         HH΃    ",
      "        HH΃΃΃μμμ",
      "      HHH΃΃΃    ",
      "      H΃΃΃΃΃    ",
      "     HH΃΃΃΃΃$   ",
      "     H΃΃΃΃΃΃    ",
      "     H΃΃΃΃      ",
      "     H΃΃΃΃      ",
      "     H΃΃΃       ",
      "     H$$$$$$$$$$",
      "     H  $       ",
      "     H  $       "
    ],
    [
      "            niii",
      "            ϡ   ",
      "           nHHHH",
      "          neH   ",
      "         nͽ HHHH",
      "        nͽ  Ϣ   ",
      "      niͽ   HHHH",
      "      j    /H   ",
      "     nͽ   HHH   ",
      "     j   HHH    ",
      "     j ΣHH      ",
      "     j HH       ",
      "     hHH        ",
      "     hH$$$$$$$$$",
      "     H``$       ",
      "     H  $       "
    ],
    [
      "                ",
      "                ",
      "             HHH",
      "            HH΃΃",
      "            HH΃ ",
      "            ϣ3  ",
      "           xHH΃ ",
      "          Α H΃΃΃",
      "          H/H ΃΃",
      "         HHH$$$$",
      "       ΂HH$$$$$$",
      "       HH $$$$$$",
      "      HH$ $$$$$$",
      "      H$$$$$$$$$",
      "     H$$$$$$$$$$",
      "     H$$$$$$$$$$"
    ],
    [
      "                ",
      "                ",
      "             ͿHH",
      "             H  ",
      "            ͿH μ",
      "            ͿH%μ",
      "            ͿH μ",
      "             H  ",
      "             H  ",
      "          H HHHH",
      "       Ϳ  '  '  ",
      "             '  ",
      "       H     '''",
      "      H   '     ",
      "     H'''''     ",
      "     H          "
    ],
    [
      "                ",
      "                ",
      "                ",
      "                ",
      "               &",
      "               &",
      "               &",
      "                ",
      "                ",
      "          H HHHH",
      "          '  '  ",
      "          '  '  ",
      "          '  '''",
      "      H   '     ",
      "     H'''''     ",
      "     H          "
    ],
    [
      "                ",
      "                ",
      "                ",
      "                ",
      "                ",
      "                ",
      "                ",
      "                ",
      "                ",
      "           HHHHH",
      "          H'''''",
      "          ''''''",
      "          ''''''",
      "       ϛ  '     ",
      "      HH'''     ",
      "     H          "
    ]
  ]
}