{
  "xsize": 16,
  "zsize": 16,
  "refpalette": "pomkotsmechs:ships",
  "slices": [
    [
      "                ",
      "                ",
      "                ",
      "                ",
      "                ",
      "                ",
      "                ",
      "                ",
      "                ",
      "                ",
      "                ",
      "                ",
      "                ",
      "                ",
      "                ",
      "                "
    ],
    [
      "                ",
      "                ",
      "                ",
      "                ",
      "                ",
      "                ",
      "                ",
      "                ",
      "                ",
      "                ",
      "                ",
      "                ",
      "                ",
      "                ",
      "                ",
      "                "
    ],
    [
      "!!!!!!!         ",
      "!!!!!!!         ",
      "!!!!!!!         ",
      "!!!!!!!         ",
      "!!!!!!!         ",
      "!!!!!!!         ",
      "!!!!!!!         ",
      "!!!!!!!         ",
      "!!!!!!!         ",
      "!!!!!!!         ",
      "!!!!!!!         ",
      "!!!!!!!         ",
      "!!!!!!!         ",
      "!!!!!!!         ",
      "!!!!!!!         ",
      "!!!!!!!         "
    ],
    [
      "$$$$$$$!        ",
      "$$$''''!        ",
      "$$$%%%%!        ",
      "--$%%%%!        ",
      "--$.%%%!        ",
      "--$%%%%!        ",
      "--$.%%%!        ",
      "--$%%%%!        ",
      "--$.%%%!        ",
      "--$%%%%!        ",
      "--$.%%%!        ",
      "--$%%%%!        ",
      "--..%%%!        ",
      "--$%%%%!        ",
      "--$%%%/!        ",
      "$$$%%%%!        "
    ],
    [
      "    9 '$!       ",
      "A''''''$!       ",
      "       $!       ",
      "---    $!       ",
      "  -.   $!       ",
      "  -    $!       ",
      "  -.   $!       ",
      "  -    $!       ",
      "  -.   $!       ",
      "  -    $!       ",
      "  -.   $!       ",
      "  -    $!       ",
      "  -.   $!       ",
      "  -    $!       ",
      "---    $!       ",
      "      /$!       "
    ],
    [
      "     9'$ !      ",
      "B'''''''$!      ",
      "        $!      ",
      "----    $!      ",
      "  --    $!      ",
      "  --    $!      ",
      "  --    $!      ",
      "  --    $!      ",
      "  --    $!      ",
      "  --    $!      ",
      "  --    $!      ",
      "  --    $!      ",
      "  --    $!      ",
      "  --    $!      ",
      "----    $!      ",
      "        $!      "
    ]
  ]
}