{
  "xsize": 16,
  "zsize": 16,
  "refpalette": "lostcities:ships",
  "slices": [
    [
      "      !$        ",
      "      !$        ",
      "      !$        ",
      "      !$        ",
      "      !$        ",
      "      !$        ",
      "      !$        ",
      "      !$        ",
      "      !$        ",
      "      !$        ",
      "      !$        ",
      "      !$        ",
      "      !$        ",
      "      !$        ",
      "      !$''''''''",
      "      !$$       "
    ],
    [
      "      !$        ",
      "      !$        ",
      "      !$        ",
      "      !$        ",
      "      !$        ",
      "      !$        ",
      "      !$        ",
      "      !$        ",
      "      !$        ",
      "      !$        ",
      "      !$        ",
      "      !$        ",
      "      !$        ",
      "      !$        ",
      "      !$''''''''",
      "      !$$       "
    ],
    [
      "      !$        ",
      "      !$        ",
      "      !$        ",
      "      !$        ",
      "      !$        ",
      "      !$        ",
      "      !$        ",
      "      !$        ",
      "      !$        ",
      "      !$        ",
      "      !$        ",
      "      !$        ",
      "      !$        ",
      "      !$        ",
      "      !$''''''''",
      "      !$$       "
    ],
    [
      "      &$$$$$$$$$",
      "      &$$$$$$$$$",
      "      &$$$$$$$$$",
      "      &$$$$$$$$$",
      "      &$$$$$$$$$",
      "      &$$$$$$$$$",
      "      &$$$$$$$$$",
      "      &$$$$$$$$$",
      "      &$$$$$$$$$",
      "      &$$$$$$$$$",
      "      &$$$$$$$$$",
      "      &$$$$$$$$$",
      "      &$$$$$$$$$",
      "      &$$$$$$$$$",
      "      &$'''''''$",
      "      &$$       "
    ],
    [
      "      H$        ",
      "      H$        ",
      "      H$ p    p ",
      "      H$        ",
      "      H$ p    p ",
      "      H$        ",
      "      H$        ",
      "      H$ p    p ",
      "      H$        ",
      "      H$ p    p ",
      "      H$        ",
      "      H$        ",
      "      H$ p    p ",
      "      H$        ",
      "      H$'''''''$",
      "      H$$       "
    ],
    [
      "      H$ &7777& ",
      "      H$ &7777& ",
      "      H$ &&&&&& ",
      "      H$        ",
      "      H$ &&&&&& ",
      "      H$ &7777& ",
      "      H$ &7777& ",
      "      H$ &&&&&& ",
      "      H$        ",
      "      H$ &&&&&& ",
      "      H$ &7777& ",
      "      H$ &7777& ",
      "      H$ &&&&&& ",
      "      H$        ",
      "      H$'''''''$",
      "      H$$       "
    ]
  ]
}