{
  "xsize": 16,
  "zsize": 16,
  "refpalette": "pomkotsmechs:ships",
  "slices": [
    [
      "         !$     ",
      "         !$ < < ",
      "         !$     ",
      "        ! $ < < ",
      "        ! $     ",
      "        !$$ < < ",
      "        !$$     ",
      "        !$$ < < ",
      "        !$$     ",
      "        !$$     ",
      "       ! $''''''",
      "       ! $ ) )$ ",
      "       ! $ ) )$ ",
      "       ! $    $ ",
      "       ! $    $ ",
      "       ! $    $ "
    ],
    [
      "         !$     ",
      "         !$ < < ",
      "        ! $     ",
      "        ! $ < < ",
      "        ! $     ",
      "        !$$ < < ",
      "        !$$     ",
      "        !$$ < < ",
      "        !$$     ",
      "       ! $$     ",
      "       ! $''''''",
      "       ! $    $ ",
      "       ! $    $ ",
      "       ! $    $ ",
      "       ! $    $ ",
      "       ! $    $ "
    ],
    [
      "         !$     ",
      "         !$ < < ",
      "        ! $     ",
      "        ! $ < < ",
      "        ! $     ",
      "        !$$ < < ",
      "        !$$     ",
      "        !$$ < < ",
      "        !$$     ",
      "       ! $$     ",
      "       ! $''''''",
      "       ! $    $ ",
      "       ! $    $ ",
      "       ! $    $ ",
      "       ! $    $ ",
      "       !&$ II $ "
    ],
    [
      "         &$     ",
      "         &$ < < ",
      "        & $     ",
      "        & $ < < ",
      "        & $     ",
      "        &$$ < < ",
      "        &$$     ",
      "        &$$ < < ",
      "        &$$     ",
      "       & $$     ",
      "       & $''''''",
      "       & $$$$$$$",
      "       & &&&&&&&",
      "       & &&&&&&&",
      "       & &&&&&&&",
      "       & &&&&&&&"
    ],
    [
      "         H$     ",
      "        H $ < < ",
      "        H $     ",
      "        H $ < < ",
      "        H $     ",
      "        H$$ < < ",
      "        H$$     ",
      "        H$$ < < ",
      "       H $$     ",
      "       H $$     ",
      "       H $''''''",
      "       H&&&&&&&&",
      "       H&       ",
      "       H&       ",
      "       H&   JKKL",
      "      H$&   MNNN"
    ],
    [
      "        H $     ",
      "        H $ < < ",
      "        H $     ",
      "        H $ < < ",
      "        H $     ",
      "        H$$ < < ",
      "       H $$     ",
      "       H $$ < < ",
      "       H $$     ",
      "       H $$     ",
      "       H $''''''",
      "       H&&&&&&&&",
      "       H&       ",
      "      H$&       ",
      "      H$&      O",
      "      H$&      P"
    ]
  ]
}