{
  "xsize": 16,
  "zsize": 16,
  "refpalette": "pomkotsmechs:ships",
  "slices": [
    [
      "    $           ",
      " '''$           ",
      "    $H          ",
      "    $$H         ",
      "    $$H         ",
      "    $$H         ",
      "    $$H         ",
      "$$$$$$$H        ",
      "      $H        ",
      "  < < $H        ",
      "      $H        ",
      "  < < $H        ",
      "      $H        ",
      "  < < $ H       ",
      "      $ H       ",
      "  < < $ H       "
    ],
    [
      "   #$           ",
      "    $$          ",
      "    $$          ",
      "    $$H         ",
      "    $$H         ",
      "    $$ H        ",
      "    $$ H        ",
      "$$$$$$$H        ",
      "      $H        ",
      "  p p $H        ",
      "      $H        ",
      "  p p $ H       ",
      "      $ H       ",
      "  p p $ H       ",
      "      $ H       ",
      "  p p $ H       "
    ],
    [
      "   #$$          ",
      "    $$          ",
      "    $$H         ",
      "    $$ H        ",
      "    $$ H        ",
      "    $$ H        ",
      "    $$ H        ",
      "$$$$$$$H        ",
      "      $H        ",
      "      $ H       ",
      "      $ H       ",
      "I     $ H       ",
      "I     $ H       ",
      "I     $ H       ",
      "      $ H       ",
      "      $  H      "
    ],
    [
      "$$$$#           ",
      "$$$$   H        ",
      "II$$   H        ",
      "II$$   H        ",
      "$$$$   H        ",
      "$$$$   H        ",
      "$$$$   H        ",
      "        H       ",
      "HH΃HHH  H       ",
      "H&&&&H΃ H       ",
      "H&&&&H΃ H       ",
      "HHHHHH΃΃H       ",
      "H&&&&H΃΃ H      ",
      "H&&&&H΃΃΃H      ",
      "HHHHHH΃΃΃H      ",
      "΃΃΃΃΃΃΃΃΃H      "
    ],
    [
      "΃΃΃΃΄  H        ",
      "??΃΃΄΃ H        ",
      "΄΄?΄΄΃ H        ",
      "΃΃΃?΃΃΃H        ",
      "΃΃΃΃?΃΃H        ",
      "΃΃΃΃?΃΃ H       ",
      "΃΃΃΃?΃΃΃H       ",
      "΃΃΃?΃΃΃΃H       ",
      "  ΅   ΃΃H       ",
      "       ΃HH      ",
      "       ΃΃H      ",
      "        ΃H      ",
      "        ΃H      ",
      "         j      ",
      "         j      ",
      "         j      "
    ],
    [
      "     ΃΃H        ",
      "      ΃HH       ",
      "      ΃΃H       ",
      "       ΃H       ",
      "κλ     ΃H       ",
      "μν     ΃H       ",
      "ξο      j       ",
      "        j       ",
      "        j       ",
      "        m;      ",
      "         j      ",
      "         j      ",
      "         j      ",
      "         Ή      ",
      "                ",
      "                "
    ]
  ]
}