{
  "xsize": 16,
  "zsize": 16,
  "refpalette": "pomkotsmechs:ships",
  "slices": [
    [
      "      $!        ",
      "  < < $!        ",
      "      $!        ",
      "  < < $ !       ",
      "      $$!       ",
      "  < < $$!       ",
      "      $$!       ",
      "  < < $$!       ",
      "      $$!       ",
      "      $$!#      ",
      "'''''''$ !      ",
      "  $) ) $ !      ",
      "  $) ) $ !      ",
      "  $    $ !      ",
      "  $    $ !      ",
      "  $    $ !      "
    ],
    [
      "      $!        ",
      "  < < $!        ",
      "      $ !       ",
      "  < < $ !       ",
      "      $$!       ",
      "  < < $$!       ",
      "      $$!       ",
      "  < < $$!       ",
      "      $$!#      ",
      "      $$#!#     ",
      "'''''''$ !      ",
      "  $    $ !      ",
      "  $    $ !      ",
      "  $    $ !      ",
      "  $    $ !      ",
      "  $    $ !      "
    ],
    [
      "      $!        ",
      "  < < $!        ",
      "      $ !       ",
      "  < < $ !       ",
      "      $$!       ",
      "  < < $$!       ",
      "      $$!       ",
      "  < < $$!       ",
      "      $$!#      ",
      "      $$#!#     ",
      "'''''''$ !      ",
      "  $    $ !      ",
      "  $    $ !      ",
      "  $    $ !      ",
      "  $    $ !      ",
      "  $ II $ !      "
    ],
    [
      "$     $&        ",
      "$ < < $&        ",
      "$     $ &       ",
      "$ < < $ &       ",
      "$     $$&       ",
      "$ < < $$&       ",
      "$     $$&       ",
      "$ < < $$&       ",
      "$     $$&#      ",
      "$     $$#&#     ",
      "'''''''$ &      ",
      "&$$$$$$$ &      ",
      "&&&&&&&& &      ",
      "&&&&&&&& &      ",
      "&&&&&&&& &      ",
      "&&&&&&&& &      "
    ],
    [
      "      $H        ",
      "  < < $ H       ",
      "      $ H       ",
      "  < < $ H       ",
      "      $$H       ",
      "  < < $$H       ",
      "      $$H       ",
      "  < < $$H#      ",
      "      $$#H#     ",
      "      $$#H#     ",
      "s''''''$ H      ",
      " &&&&&&&&H      ",
      "        &H      ",
      "        &H      ",
      "ttLKu   &H      ",
      "&&NNM   &$H     "
    ],
    [
      "      $ H       ",
      "  < < $ H       ",
      "      $ H       ",
      "  < < $ H       ",
      "      $$H       ",
      "  < < $$H       ",
      "      $$ H      ",
      "  < < $$ H#     ",
      "      $$#H#     ",
      " 3    $$ H      ",
      "w''''''$ H      ",
      "x&&&&&&&&H      ",
      "        &H      ",
      "        &$H     ",
      "  O     &$H     ",
      "PSS     &$H     "
    ]
  ]
}