{
  "xsize": 16,
  "zsize": 16,
  "refpalette": "pomkotsmechs:ships",
  "slices": [
    [
      "      H$$ < < < ",
      "      H$$       ",
      "      H$$ < < < ",
      "      H$$       ",
      "      H$$ < < < ",
      "      H$$       ",
      "      H$$ < < < ",
      "      H$$       ",
      "      H$$       ",
      "      H$$''''''$",
      "       H΃΃΃$$$$$",
      "       H΃΃΃΃$$$$",
      "       H΃΃΃΃$΃$$",
      "       H΃΃΃΃΃΃΃΃",
      "       H΃΃΃΃΃΃΃΃",
      "      ΤH΃΃΃΃΃΃΃΃"
    ],
    [
      "      H$$ p p p ",
      "      H$$       ",
      "      H$$ p p p ",
      "      H$$       ",
      "      H$$ p p p ",
      "      H$$       ",
      "      H$$ p p p ",
      "      H$$       ",
      "      H$$       ",
      "      H$$'''''''",
      "      H$HHHHH   ",
      "       H Υ  H # ",
      "       H Φ  HΧHH",
      "       H    ####",
      "       H     ## ",
      "      ΨH     #  "
    ],
    [
      "      H$$       ",
      "      H$$       ",
      "      H$$       ",
      "      H$$       ",
      "      H$$       ",
      "      H$$       ",
      "      H$$       ",
      "      H$$       ",
      "      H$$       ",
      "      H$$'''''''",
      "       $ HHHH   ",
      "          ΥHH###",
      "       H ΩΪ HΧHH",
      "             ## ",
      "                ",
      "                "
    ],
    [
      "      H΃΃΃΃HHHHH",
      "      H΃΃΃΃H&&&&",
      "      H΃΃΃΃H&&&&",
      "      H΃΃΃΃HHHHH",
      "      H΃΃΃΃H&&&&",
      "      H΃΃΃΃H&&&&",
      "      H   ΃HHHHH",
      "      H   ΃΃΃΃΃΃",
      "          ΃΃΃΃΃΃",
      "      H   ΃΃΃΃΃΃",
      "          H=H΃΃΃",
      "            H΃΃΃",
      "          ΩiHHHH",
      "             #  ",
      "                ",
      "                "
    ],
    [
      "      j         ",
      "      j         ",
      "      j         ",
      "      j         ",
      "      j         ",
      "      jΆΫ       ",
      "      j         ",
      "                ",
      "                ",
      "             HHH",
      "          Ϊ nHHH",
      "            j###",
      "           Ωeiii",
      "             #  ",
      "                ",
      "                "
    ],
    [
      "                ",
      "                ",
      "                ",
      "                ",
      "       ==       ",
      "       άέ       ",
      "                ",
      "                ",
      "              # ",
      "             HHH",
      "             HHH",
      "              #ή",
      "             # #",
      "                ",
      "                ",
      "                "
    ]
  ]
}