{
  "xsize": 16,
  "zsize": 16,
  "refpalette": "lostcities:ships",
  "slices": [
    [
      "     H  $       ",
      "    HH  $       ",
      "   HHH  $       ",
      "  ϤHHH6 $       ",
      "   ϥHH  $       ",
      "    ϤH  $       ",
      "     H  $       ",
      "     H  $       ",
      "     H  $       ",
      "     H  $       ",
      "     H  $       ",
      "     H  $       ",
      "     H  $       ",
      "     H  $$$$$$$ ",
      "     H          ",
      "                "
    ],
    [
      "   ϦHH  $       ",
      "   HHH  $       ",
      "  HHHH6 $  II   ",
      "  HHHH  $  II   ",
      "  HHHH  $       ",
      "   HHH  $       ",
      "   ϧHH  $       ",
      "     H  $       ",
      "     HII$  I^   ",
      "     H  $  I^   ",
      "     H  $       ",
      "     H  $       ",
      "     H  $       ",
      "        $$$$$$$$",
      "                ",
      "                "
    ],
    [
      "   niH$$$$$$$$$$",
      "  nͽ H6$$$$$$$$$",
      "  j    $$$$$$$$$",
      "  h  H $$$$$$$$$",
      "  j  H $$$$$$$$$",
      "  m; H $$$$$$$$$",
      "   miH$$$$$$$$$$",
      "     HH$$$$$$$$$",
      "     HH$$$$$$$$$",
      "     H΃΃$$$$$$$$",
      "     H΃΃΃$$$$$$$",
      "     H΃΃΃HHHHHHH",
      "     H΃΃΃΃H     ",
      "        ΃΃΃΃΃΃΃΃",
      "        ΃΃΃΃΃΃΃΃",
      "        ΃΃΃΃΃΃΃΃"
    ],
    [
      "     H          ",
      "     H /  ''''''",
      "       '  'Ϗϐ   ",
      "     H '  'Ϗϐ   ",
      "     H '  '     ",
      "     H '  '     ",
      "     H''  '     ",
      "     hH'  'ϨϨϩϪ0",
      "     hHH '''''''",
      "     j H '      ",
      "     j   H      ",
      "     j   HHHHHHH",
      "          HHHHHH",
      "                ",
      "                ",
      "                "
    ],
    [
      "     H          ",
      "     H    ''''''",
      "     H /  '    5",
      "     H '  '     ",
      "     H '  '     ",
      "     H '  '     ",
      "     H''  '     ",
      "      H'  'ϨϨϩϪ ",
      "      HH '''''''",
      "       H '      ",
      "         H      ",
      "         HHHHHHH",
      "          HHHHHH",
      "                ",
      "                ",
      "                "
    ],
    [
      "     H          ",
      "     H    ''''''",
      "     H    '     ",
      "     H /  '     ",
      "     H '  '     ",
      "     H '  '     ",
      "      H'  '     ",
      "      H'  '     ",
      "       ϛ''''''''",
      "        ϛH      ",
      "         ϛHH    ",
      "          HHHHHH",
      "                ",
      "                ",
      "                ",
      "                "
    ]
  ]
}