{
  "xsize": 16,
  "zsize": 16,
  "refpalette": "pomkotsmechs:ships",
  "slices": [
    [
      "ϋϋό    &&$H     ",
      "       &&$H     ",
      "       &&$H     ",
      "       &&$H     ",
      "        &$H     ",
      "       &&$H     ",
      "       &&$H     ",
      "       &&$H     ",
      "       &&$H     ",
      "        &$H     ",
      "       &&$H     ",
      "       &&$H     ",
      "       &&$H     ",
      "       &&$      ",
      "$$&&&&&&&$      ",
      "       $$$      "
    ],
    [
      "ύύΓ     &$ H    ",
      "        &$ H    ",
      "        &$ H    ",
      "        &$ H    ",
      "        &$ H    ",
      "        &$ H    ",
      "        &$ H    ",
      "        &$ H    ",
      "        &$ H    ",
      "        &$ H    ",
      "        &$ H    ",
      "        &$ H    ",
      "        &$ H    ",
      "        &       ",
      "&&&&&&&&&       ",
      "I      $$       "
    ],
    [
      "        &$ H    ",
      "        &$ H    ",
      "        &$ H    ",
      "        &$ H    ",
      "        &$ H    ",
      "        &$ H    ",
      "        &$ H    ",
      "        &$ H    ",
      "        &$ H    ",
      "        &$ H    ",
      "        &$ H    ",
      "        &$ H    ",
      "        &$ H    ",
      "        &       ",
      "&&&&&&&&&       ",
      "&&      $       "
    ],
    [
      "΃΃΃΃΃΃΃΃΃΃΃H    ",
      "΃΃΃΃΃΃΃΃΃΃΃H    ",
      "΃΃΃΃΃΃΃΃΃΃΃H    ",
      "΃΃΃΃΃΃΃΃΃΃΃H    ",
      "΃΃΃΃΃΃΃΃΃΃΃H    ",
      "΃΃΃΃΃΃΃΃΃΃΃H    ",
      "΃΃΃΃΃΃΃΃΃΃΃H    ",
      "΃΃΃΃΃΃΃΃΃΃΃H    ",
      "΃΃΃΃΃΃΃΃΃΃΃H    ",
      "΃΃΃΃΃΃΃΃΃΃΃H    ",
      "΃΃΃΃΃΃΃΃΃΃΃     ",
      "΃΃΃΃΃΃΃΃΃΃΃H    ",
      "΃΃΃΃΃΃΃΃΃΃΃H    ",
      "΃΃΃΃΃΃΃΃΃΃΃H    ",
      "΃΃΃΃΃΃΃΃΃       ",
      "΃΃΃΃΃΃΃΃΃       "
    ],
    [
      "        $  H    ",
      "  ΔΕ ΔΕ $  H    ",
      "  ΖΗ ΖΗ $  H    ",
      "  ΖΗ ΖΗ $  H    ",
      "  ΘΙ ΘΙ $  H    ",
      "        $ 6H    ",
      "        $  H    ",
      "  ΔΕ ΔΕ $  H    ",
      "  ΖΗ ΖΗ $  H    ",
      "  ΖΗ ΖΗ $       ",
      "  ΘΙ ΘΙ $       ",
      "        $       ",
      "        $  H    ",
      "  $$$$$$$  H    ",
      "                ",
      "                "
    ],
    [
      "        $  H    ",
      "        $  H    ",
      "        $  H    ",
      "        $  H    ",
      "        $ 6H    ",
      "        $  H    ",
      "        $  H    ",
      "        $  H    ",
      "        $  H    ",
      "        $       ",
      "        $       ",
      "        $       ",
      "        $       ",
      "  $$$$$$$  H    ",
      "           H    ",
      "                "
    ]
  ]
}