{
  "xsize": 16,
  "zsize": 16,
  "refpalette": "pomkotsmechs:ships",
  "slices": [
    [
      "         $!     ",
      "         $!     ",
      "         $!     ",
      "         $!     ",
      "         $!     ",
      "         $!     ",
      "         $!     ",
      "         $!     ",
      "         $!     ",
      "         $!     ",
      "         $!     ",
      "         $!     ",
      "         $!     ",
      "         $!     ",
      "'''''''''$!     ",
      "        '$!     "
    ],
    [
      "         $!     ",
      "         $!     ",
      "         $!     ",
      "         $!     ",
      "         $!     ",
      "         $!     ",
      "         $!     ",
      "         $!     ",
      "         $!     ",
      "         $!     ",
      "         $!     ",
      "         $!     ",
      "         $!     ",
      "         $!     ",
      "'''''''''$!     ",
      "        $$!     "
    ],
    [
      "         $!     ",
      "         $!     ",
      "         $!     ",
      "         $!     ",
      "         $!     ",
      "         $!     ",
      "         $!     ",
      "         $!     ",
      "         $!     ",
      "         $!     ",
      "         $!     ",
      "         $!     ",
      "         $!     ",
      "         $!     ",
      "'''''''''$!     ",
      "        $$!     "
    ],
    [
      "$$$$$$$$$$&     ",
      "$$$$$$$$$$&     ",
      "$$$$$$$$$$&     ",
      "$$$$$$$$$$&     ",
      "$$$$$$$$$$&     ",
      "$$$$$$$$$$&     ",
      "$$$$$$$$$$&     ",
      "$$$$$$$$$$&     ",
      "$$$$$$$$$$&     ",
      "$$$$$$$$$$&     ",
      "$$$$$$$$$$&     ",
      "$$$$$$$$$$&     ",
      "$$$$$$$$$$&     ",
      "$$$$$$$$$$&     ",
      "'$'''''''$&     ",
      "$       $$&     "
    ],
    [
      "         $H     ",
      "         $H     ",
      "  p    p $H     ",
      "         $H     ",
      "  p    p $H     ",
      "         $H     ",
      "         $H     ",
      "  p    p $H     ",
      "         $H     ",
      "  p    p $H     ",
      "         $H     ",
      "         $H     ",
      "  p    p $H     ",
      "         $H     ",
      " $'''''''$H     ",
      "        $$H     "
    ],
    [
      "  &7777& $H     ",
      "  &7777& $H     ",
      "  &&&&&& $H     ",
      "         $H     ",
      "  &&&&&& $H     ",
      "  &7777& $      ",
      "  &7777& $H     ",
      "  &&&&&& $H     ",
      "         $H     ",
      "  &&&&&& $H     ",
      "  &7777& $H     ",
      "  &7777& $H     ",
      "  &&&&&& $H     ",
      "         $H     ",
      " $'''''''$H     ",
      "        $$H     "
    ]
  ]
}