{
  "xsize": 16,
  "zsize": 16,
  "refpalette": "pomkotsmechs:ships",
  "slices": [
    [
      "                ",
      "ͿͿͿͿ            ",
      "HHHH            ",
      "#  H            ",
      "&ͻ Z            ",
      " & Z            ",
      "&ͺ Z            ",
      "HHHH            ",
      "HHHZ            ",
      "HHHZ            ",
      "HHHH            ",
      "HHHH#           ",
      "#HHH            ",
      "HHHH            ",
      "#  H            ",
      "HHHH            "
    ],
    [
      "                ",
      "                ",
      "HHHH            ",
      "HHHH            ",
      "HHHZ            ",
      " HHZ            ",
      "HHHZ            ",
      "HHHH            ",
      "&  H            ",
      "&  H            ",
      "&  H            ",
      "&ͻ#H#           ",
      "#&#H            ",
      "&ͺ#H            ",
      "   H            ",
      "HHHH            "
    ],
    [
      "                ",
      "                ",
      "HHHH            ",
      "## H            ",
      "&ͻ H            ",
      " & H            ",
      "&ͺ H            ",
      "   H            ",
      "&  H            ",
      "&  H            ",
      "#  H            ",
      "&ͻ#Ϳ#           ",
      "###Ϳ#           ",
      "&ͺ#Ϳ            ",
      "                ",
      "                "
    ],
    [
      "                ",
      "                ",
      "HHHH            ",
      "## H            ",
      "&ͻ H            ",
      " & Ϳ            ",
      "&ͺ Ϳ            ",
      "   Ϳ            ",
      "&               ",
      "&               ",
      "#               ",
      "&ͻ #            ",
      "####            ",
      "&ͺ              ",
      "                ",
      "                "
    ],
    [
      "                ",
      "                ",
      "#               ",
      "##              ",
      "&ͻ              ",
      " &              ",
      "&ͺ              ",
      "                ",
      "&               ",
      "&               ",
      "#               ",
      "&ͻ              ",
      "##              ",
      "&ͺ              ",
      "                ",
      "                "
    ],
    [
      "                ",
      "                ",
      "                ",
      "#               ",
      "&ͻ              ",
      " &              ",
      "&ͺ              ",
      "                ",
      "&               ",
      "&               ",
      "                ",
      "&ͻ              ",
      "##              ",
      "&ͺ              ",
      "                ",
      "                "
    ]
  ]
}