{
  "xsize": 16,
  "zsize": 16,
  "refpalette": "lostcities:ships",
  "slices": [
    [
      "    9$ $$$      ",
      "$$'''''''$      ",
      "         $      ",
      "         $H     ",
      "&ͻ       $H     ",
      " &       $H     ",
      "&ͺ       $H     ",
      "         $H     ",
      "&        $H     ",
      "&        $H     ",
      "         $H     ",
      "&ͻ       $H     ",
      " &       $H     ",
      "&ͺ       $H#    ",
      "         $H##   ",
      "         $H#    "
    ],
    [
      "I    9$$$       ",
      "'''''''''       ",
      "                ",
      "                ",
      "&ͻ       $ H    ",
      " &       $ H    ",
      "&ͺ       $ H    ",
      "         $ H    ",
      "&        $ H    ",
      "&        $ H    ",
      "         $ H    ",
      "&ͻ       $ H    ",
      " &       $ H    ",
      "&ͺ       $ H    ",
      "         $#H#   ",
      "         $ H    "
    ],
    [
      "&&    9$$       ",
      "''''''''        ",
      "                ",
      "                ",
      "&ͻ       $      ",
      " &       $ H    ",
      "&ͺ I     $ H    ",
      "   I     $ H    ",
      "&  I     $ H    ",
      "&  I     $ H    ",
      "   I     $ H    ",
      "&ͻ I     $ H    ",
      " &       $ H    ",
      "&ͺ       $ H    ",
      "         $#H#   ",
      "         $ H    "
    ],
    [
      "΃΃΃΃   9΃       ",
      "΃΃΃΃΃΃΃΃΃       ",
      "΃΃΃΃΃΃΃΃΃       ",
      "΃΃΃΃΃΃΃΃΃       ",
      "΃΃΃΃΃΃΃΃΃΃΃     ",
      " ΃΃΃΃΃΃΃΃΃΃H    ",
      "΃΃΃΃΃΃΃΃΃΃΃H    ",
      "΃΃΃΃΃΃΃΃΃΃΃H    ",
      "΃΃΃΃΃΃΃΃΃΃΃H    ",
      "΃΃΃΃΃΃΃΃΃΃΃H    ",
      "΃΃΃΃΃΃΃΃΃΃΃H    ",
      "΃΃΃΃΃΃΃΃΃΃΃H    ",
      " ΃΃΃΃΃΃΃΃΃΃H    ",
      "΃΃΃΃΃΃΃΃΃΃΃H    ",
      "΃΃΃΃΃΃΃΃΃΃΃H#   ",
      "΃΃΃΃΃΃΃΃΃΃΃H    "
    ],
    [
      "                ",
      "                ",
      "$$$$$$s$$       ",
      "   H,   H       ",
      "HHHH+   H       ",
      " & Hώ  (H  H    ",
      "&ͺ HΝ  (H  H    ",
      "   H Ϗϐ(H  H    ",
      "&  HHHHHH  H    ",
      "& /H       H    ",
      "   H            ",
      "&ͻ H            ",
      " & H       H    ",
      "&ͺ H       H    ",
      "   H      #H#   ",
      "'''H      HH    "
    ],
    [
      "                ",
      "       3        ",
      "$$$$$$w$$       ",
      "   H   5H       ",
      "HHHH    H  H    ",
      " & H    H  H    ",
      "&ͺ H    H  H    ",
      "   H    H  H    ",
      "&  HHHHHH       ",
      "&  H            ",
      "  /H            ",
      "&ͻ H#           ",
      " & H####   H    ",
      "&ͺ I   ####H#   ",
      "   I      #H#   ",
      "'''H       H    "
    ]
  ]
}