{
  "xsize": 16,
  "zsize": 16,
  "refpalette": "pomkotsmechs:ships",
  "slices": [
    [
      "  9    E $H     ",
      "  9    E $H     ",
      "  &6666& $H     ",
      "         $      ",
      "  &////& $      ",
      "  9    E $      ",
      "  9    E $      ",
      "  &6666& $      ",
      "         $      ",
      "  &////& $      ",
      "  9    E $      ",
      "  9    E $H     ",
      "  &6666& $H     ",
      "         $H     ",
      "$$'''''''$H     ",
      "        $$H     "
    ],
    [
      "  9    E $ H    ",
      "  9    E $ H    ",
      "  &6666& $      ",
      "                ",
      "  &////&        ",
      "  9    E        ",
      "  9    E        ",
      "  &6666&        ",
      "                ",
      "  &////&        ",
      "  9    E        ",
      "  9    E $      ",
      "  &6666& $H     ",
      "         $H     ",
      "'''''''''$H     ",
      "        $$H     "
    ],
    [
      "I &DDDD& $ H    ",
      "I &DDDD& $ H    ",
      "I &&&&&& $ H    ",
      "`               ",
      "I &&&&&&        ",
      "I &DDDD&        ",
      "` &DDDD&        ",
      "I &&&&&&        ",
      "                ",
      "  &&&&&&        ",
      "  &DDDD&        ",
      "  &DDDD&        ",
      "  &&&&&& $      ",
      "         $H     ",
      "'''''''''$H     ",
      "        $$H     "
    ],
    [
      "΃΃΃΃΃H΃΃΃΃΃H    ",
      "΃΃΃΃΃HH΃΃΃΃H    ",
      "΃΃΃΃΃HH΃΃΃΃H    ",
      "΃΃΃΃΃HH΃΃΃΃H    ",
      "΃΃΃΃΃HH΃΃΃΃     ",
      "΃΃΃΃΃HH΃΃ ΃     ",
      "΃΃΃΃΃HH΃΃       ",
      "΃΃΃΃΃HH΃΃       ",
      "΃΃΃΃΃HH΃΃       ",
      "΃΃΃΃΃HH΃΃       ",
      "΃΃΃΃΃HH΃΃       ",
      "΃΃΃΃΃HH΃΃΃      ",
      "΃΃΃΃΃΃΃΃΃΃΃     ",
      "΃΃΃΃΃΃΃΃΃΃HH    ",
      "΃΃΃΃΃΃΃΃΃΃H     ",
      "΃΃΃΃΃΃΃΃΃΃H     "
    ],
    [
      "         j j    ",
      " 9'E HH    j    ",
      "HHHHHHH    j    ",
      "     HH    j    ",
      "     HH    j    ",
      "     HH    j    ",
      "     HH         ",
      "     HH         ",
      "     HH         ",
      "     HH         ",
      "HHHH HH         ",
      "H   HHH         ",
      "           j    ",
      "          nͽ    ",
      "          j     ",
      "          j     "
    ],
    [
      "                ",
      "     HH         ",
      "HH/HHHHϔ        ",
      "HHHH HH         ",
      "HHHH ΃H         ",
      "HHHH ΃H         ",
      "HHHH ΃H         ",
      "HHHH ΃H         ",
      "HHHHH΃H         ",
      "HHHH ΃H         ",
      "HHHH ΃H         ",
      "HΣΣΣHHH         ",
      "                ",
      "                ",
      "                ",
      "                "
    ]
  ]
}