{
  "xsize": 16,
  "zsize": 16,
  "refpalette": "lostcities:ships",
  "slices": [
    [
      "       ''$H     ",
      "$$'''''  $H     ",
      "         $H     ",
      "         $H     ",
      "         $H     ",
      "     8   $H     ",
      "     8   $H     ",
      "         $H     ",
      "         $H     ",
      "     8   $H     ",
      "     8   $H     ",
      "         $H     ",
      "         $H     ",
      "     8   $H     ",
      "     8   $H     ",
      "         $H     "
    ],
    [
      "       ''$ H    ",
      "'''''''  $ H    ",
      "         $ H    ",
      "         $ H    ",
      "         $ H    ",
      "         $ H    ",
      "         $ H    ",
      "         $ H    ",
      "         $ H    ",
      "         $ H    ",
      "         $      ",
      "         $      ",
      "         $ H    ",
      "         $ H    ",
      "         $ H    ",
      "         $ H    "
    ],
    [
      "       ''$ H    ",
      "'''''''  $ H    ",
      "         $ H    ",
      "         $ H    ",
      "         $ H    ",
      "           H    ",
      "           H    ",
      "                ",
      "                ",
      "         $      ",
      "`               ",
      "`               ",
      "I        $      ",
      "I        $      ",
      "I        $ H    ",
      "I        $ H    "
    ],
    [
      "΃΃΃΃΃΃΃΃΃΃΃H    ",
      "΃΃΃΃΃΃΃΃΃΃΃H    ",
      "΃΃΃΃΃΃΃΃΃΃΃H    ",
      "΃΃΃΃΃΃΃΃΃΃΃H    ",
      "΃΃΃΃΃΃΃΃΃΃΃H    ",
      "΃΃΃΃΃΃΃΃΃ ΃H    ",
      "΃΃΃΃΃΃΃΃   H    ",
      "΃΃΃΃΃΃΃΃        ",
      "΃΃΃΃΃΃΃΃        ",
      "΃΃΃΃΃΃΃΃΃       ",
      "΃΃΃΃΃΃΃΃΃       ",
      "΃΃΃΃΃΃΃΃΃       ",
      "΃΃΃΃΃΃΃΃΃       ",
      "΃΃΃΃΃΃΃΃΃       ",
      "΃΃΃΃΃΃΃΃΃΃      ",
      "΃΃΃΃΃΃΃΃΃΃΃H    "
    ],
    [
      "         HHf    ",
      "         H j    ",
      "        H  j    ",
      "       ϑHΠ j    ",
      "HHHHHHH  = j    ",
      "           f    ",
      "   > >*         ",
      "                ",
      "   > >*         ",
      "                ",
      "HHHHHH          ",
      "     H          ",
      "      H         ",
      "HHHH  H$        ",
      "      H$        ",
      "  .   H         "
    ],
    [
      "          H     ",
      "         H      ",
      "        HΠ      ",
      "      3ϒH=      ",
      "HHHHHHHϓj o     ",
      "        Ή Ή     ",
      "   >*Ρ%         ",
      "                ",
      "   >*Ρ%         ",
      "                ",
      "HHHHHH          ",
      "     H          ",
      "      H         ",
      "HHHH  H%        ",
      "      H%        ",
      "---   H         "
    ]
  ]
}