{
  "xsize": 16,
  "zsize": 16,
  "refpalette": "pomkotsmechs:ships",
  "slices": [
    [
      "    !           ",
      "    !           ",
      "     !          ",
      "$$$$$!          ",
      "    $!          ",
      "    $!          ",
      "    $!          ",
      "    $$!         ",
      "      !         ",
      "  < < !         ",
      "      !         ",
      "  < < !         ",
      "      $!        ",
      "  < < $!        ",
      "      $!        ",
      "  < < $!        "
    ],
    [
      "    !           ",
      "     !          ",
      "     !          ",
      "$$$$$!          ",
      "    $!          ",
      "    $!          ",
      "    $$!         ",
      "    $$!         ",
      "      !         ",
      "  < < !         ",
      "      !         ",
      "  < < $!        ",
      "      $!        ",
      "  < < $!        ",
      "      $!        ",
      "  < < $!        "
    ],
    [
      "    !           ",
      "     !          ",
      "     !          ",
      "$$$$$!          ",
      "    $!          ",
      "    $!          ",
      "    $$!         ",
      "    $$!         ",
      "      !         ",
      "  < < !         ",
      "      !         ",
      "  < < $!        ",
      "      $!        ",
      "  < < $!        ",
      "      $!        ",
      "  < < $!        "
    ],
    [
      "$$$$&           ",
      "$$$$$&          ",
      "$$$$$&          ",
      "$$$$$&          ",
      "$$$$$&          ",
      "$$$$$&          ",
      "$$$$$$&         ",
      "'$$$$$&         ",
      "$     &         ",
      "$ < < &         ",
      "$     &         ",
      "$ < < $&        ",
      "$     $&        ",
      "$ < < $&        ",
      "$     $&        ",
      "$ < < $&        "
    ],
    [
      "    $H          ",
      " '''$H          ",
      " '*'$H          ",
      "    $H          ",
      "    $H          ",
      "    $$H         ",
      "    $$H         ",
      " $$$$$H         ",
      "      H         ",
      "  < < H         ",
      "      $H        ",
      "  < < $H        ",
      "      $H        ",
      "  < < $H        ",
      "      $H        ",
      "  < < $H        "
    ],
    [
      "  ' $H          ",
      " 'X'$H          ",
      " ' '$H          ",
      "    $H          ",
      "    $$H         ",
      "    $$H         ",
      "    $$H         ",
      " $$$$$H         ",
      "      H         ",
      "  < < $H        ",
      "      $H        ",
      "  < < $H        ",
      "      $H        ",
      "  < < $H        ",
      "      $H        ",
      "  < < $ H       "
    ]
  ]
}