{
  "xsize": 16,
  "zsize": 16,
  "refpalette": "pomkotsmechs:ships",
  "slices": [
    [
      "         $!     ",
      "   ; 8 ; $!     ",
      "   ; 8 ; $!     ",
      "         $!     ",
      "         $!     ",
      "   ; 8 ; $!     ",
      "   ; 8 ; $!     ",
      "         $!     ",
      "         $!     ",
      "     <   $!     ",
      "     <   $!     ",
      "'''''''''$!     ",
      "         $!     ",
      "         $!     ",
      "         $!     ",
      "         $!     "
    ],
    [
      "         $!     ",
      "   ;   < $!     ",
      "   ;   < $!     ",
      "         $!     ",
      "         $!     ",
      "   ;   < $!     ",
      "   ;   < $!     ",
      "         $!     ",
      "         $!     ",
      "         $!     ",
      "         $!     ",
      "'''''''''$!     ",
      "         $!     ",
      "         $!     ",
      "         $!     ",
      "         $!     "
    ],
    [
      "         $!     ",
      "   < 8 < $!     ",
      "   < 8 < $!     ",
      "         $!     ",
      "         $!     ",
      "   < 8 < $!     ",
      "   < 8 < $!     ",
      "         $!     ",
      "         $!     ",
      "         $!     ",
      "         $!     ",
      "'''''''''$!     ",
      "         $!     ",
      "         $!     ",
      "         $!     ",
      "         $!     "
    ],
    [
      "$f   8   $&     ",
      "$f <888< $&     ",
      "$f <888< $&     ",
      "$f   8   $&     ",
      "$f   8   $&     ",
      "$f <888< $&     ",
      "$f <888< $&     ",
      "$f   8   $&     ",
      "$f   8   $&     ",
      "$f   8   $&     ",
      "$$   8   $&     ",
      "'$'''''''$&     ",
      "$$$$$$$$$$&     ",
      "$$$$$$$$$$&     ",
      "$$$$$$$$$$&     ",
      "$$$$$$$$$$&     "
    ],
    [
      " j  888  $H     ",
      " j 88888 $H     ",
      " j 88888 $H     ",
      " j  888  $H     ",
      " j  888  $H     ",
      " j 88888 $H     ",
      " j 88888 $H     ",
      " j  888  $H     ",
      " j  888  $H     ",
      " j  888  $H     ",
      " $  888  $H     ",
      " $'''''''$H#    ",
      " $       $H     ",
      "         $H     ",
      "         $H     ",
      "  p    p $H     "
    ],
    [
      "     8   $H     ",
      "    888  $H     ",
      "    888  $H     ",
      "     8   $H     ",
      "     8   $H     ",
      "    888  $H     ",
      "    888  $H     ",
      "     8   $H     ",
      "     8   $H     ",
      "     8   $H     ",
      " $   8   $H#    ",
      " $'''''''$H#    ",
      " $       $H     ",
      "         $H     ",
      "         $H     ",
      "  &&&&&& $H     "
    ]
  ]
}