{
  "xsize": 16,
  "zsize": 16,
  "refpalette": "pomkotsmechs:ships",
  "slices": [
    [
      "      H$        ",
      "      H$'''''''$",
      "      H$        ",
      "      H$        ",
      "      H$       a",
      "      H$       &",
      "      H$       b",
      "      H$        ",
      "      H$       &",
      "      H$       &",
      "      H$        ",
      "      H$       a",
      "      H$       &",
      "      H$       b",
      "      H$        ",
      "      H$        "
    ],
    [
      "     H $        ",
      "     H $''''''''",
      "     H $        ",
      "     H $        ",
      "     H $       a",
      "     H $       &",
      "     H $       b",
      "     H $        ",
      "     H $       &",
      "     H $       &",
      "     H $        ",
      "     H $       a",
      "     H $       &",
      "     H $       b",
      "     H $        ",
      "     H $        "
    ],
    [
      "     H $       &",
      "     H $''''''''",
      "     H $        ",
      "     H $        ",
      "     H $       a",
      "     H $       &",
      "     H $     I b",
      "     H $     I  ",
      "     H $     I &",
      "     H $     I &",
      "     H $     I  ",
      "     H $     ` a",
      "     H $       &",
      "     H $       b",
      "     H $        ",
      "     H $        "
    ],
    [
      "     H΃΃΃΃΃΃΃΃΃΃",
      "     H΃΃΃΃΃΃΃΃΃΃",
      "     H΃΃΃΃΃΃΃΃΃΃",
      "     H΃΃΃΃΃΃΃΃΃΃",
      "     H΃΃΃΃΃΃΃΃΃΃",
      "     H΃΃΃΃΃΃΃΃΃΃",
      "     H΃΃΃΃΃΃΃΃΃΃",
      "     H΃΃΃΃΃΃΃΃΃΃",
      "     H΃΃΃΃΃΃΃΃΃΃",
      "     H΃΃΃΃΃΃΃΃΃΃",
      "     H΃΃΃΃΃΃΃΃΃΃",
      "     H΃΃΃΃΃΃΃΃΃΃",
      "     H΃΃΃΃΃΃΃΃΃΃",
      "     H΃΃΃΃΃΃΃΃΃΃",
      "     H΃΃΃΃΃΃΃΃΃΃",
      "     H΃΃΃΃΃΃΃΃΃΃"
    ],
    [
      "     H          ",
      "                ",
      "        $$A$$$$$",
      "     H  H(  ΚH  ",
      "     H  H(  ΛHHH",
      "     H  H(  ΜH &",
      "     H  H(  ΝH b",
      "     H  H(ΞΟ H  ",
      "     H  HHHHHH &",
      "             H/&",
      "             H  ",
      "     H       H a",
      "     H       H &",
      "     H       H b",
      "     H       H  ",
      "     HH      H''"
    ],
    [
      "     H          ",
      "           3    ",
      "        $$B$$$$$",
      "     H  H5   H  ",
      "     H  H    HHH",
      "     H  H    H &",
      "     H  H    H b",
      "     H  H    H  ",
      "        HHHHHH &",
      "             H &",
      "             H/ ",
      "     H       H a",
      "     H       H &",
      "     H       ` b",
      "     H       I  ",
      "     HH      H''"
    ]
  ]
}