{
  "xsize": 16,
  "zsize": 16,
  "refpalette": "lostcities:ships",
  "slices": [
    [
      "                ",
      "                ",
      "                ",
      "                ",
      "                ",
      "                ",
      "                ",
      "                ",
      "                ",
      "                ",
      "                ",
      "                ",
      "                ",
      "                ",
      "                ",
      "                "
    ],
    [
      "                ",
      "                ",
      "                ",
      "                ",
      "                ",
      "                ",
      "                ",
      "                ",
      "                ",
      "                ",
      "                ",
      "                ",
      "                ",
      "                ",
      "                ",
      "                "
    ],
    [
      "          !!!!!!",
      "          !!!!!!",
      "          !!!!!!",
      "          !!!!!!",
      "          !!!!!!",
      "          !!!!!!",
      "          !!!!!!",
      "          !!!!!!",
      "          !!!!!!",
      "          !!!!!!",
      "          !!!!!!",
      "          !!!!!!",
      "          !!!!!!",
      "          !!!!!!",
      "          !!!!!!",
      "          !!!!!!"
    ],
    [
      "         !$$$$$$",
      "         !$$$$$$",
      "         !$$$$$$",
      "         !$$$$$$",
      "         !$$$$$$",
      "         !$$$$$$",
      "         !$$$$$$",
      "         !$$$$$$",
      "         !$$$$$$",
      "         !$$$$$$",
      "         !$$$$$$",
      "         !$$$$$$",
      "         !$$$$$$",
      "         !$$$$$$",
      "         !$$$$$$",
      "         !$$$$$$"
    ],
    [
      "        !$    $ ",
      "        !$    $ ",
      "        !$    $ ",
      "        !$ ) )$ ",
      "        !$()()$ ",
      "        !$$$$$$ ",
      "        !$))))$ ",
      "        !$))))$ ",
      "        !$    $ ",
      "        !$    $ ",
      "        !$    $ ",
      "        !$      ",
      "        !$    $ ",
      "        !$    $ ",
      "        !F    $ ",
      "        !F    $ "
    ],
    [
      "       !$$    $ ",
      "       !$$    $ ",
      "       !$$    $ ",
      "       !$$ * *$ ",
      "       !$$ * *$ ",
      "       !$$$$$$$ ",
      "       !$     $ ",
      "       !$+    $ ",
      "       !$,    $ ",
      "       !$+    $ ",
      "       !$,    $ ",
      "       !$       ",
      "       !$     $ ",
      "       !$     $ ",
      "       !$     $ ",
      "       !$     $ "
    ]
  ]
}