{
  "xsize": 16,
  "zsize": 16,
  "refpalette": "pomkotsmechs:ships",
  "slices": [
    [
      "       $ $!     ",
      "'''''''''$!     ",
      "         $!     ",
      "----     $!     ",
      "  --     $!     ",
      "  --     $!     ",
      "  --     $!     ",
      "  --     $!     ",
      "  --     $!     ",
      "  --     $!     ",
      "  --     $!     ",
      "  --     $!     ",
      "  --     $!     ",
      "  --     $!     ",
      "----     $!     ",
      "         $!     "
    ],
    [
      "       $$$!     ",
      "'''''''''$!     ",
      "         $!     ",
      "----     $!     ",
      "  --     $!     ",
      "  --     $!     ",
      "  --     $!     ",
      "  --     $!     ",
      "  --     $!     ",
      "  --     $!     ",
      "  --     $!     ",
      "  --     $!     ",
      "  --     $!     ",
      "  --     $!     ",
      "----     $!     ",
      "         $!     "
    ],
    [
      "  $    $$$!     ",
      "'''''''''$!     ",
      "         $!     ",
      "---      $!     ",
      "&Ͷ-      $!     ",
      " &-      $!     ",
      "&ͷ-      $!     ",
      "---      $!     ",
      "---      $!     ",
      "---      $!     ",
      "---      $!     ",
      "&͸-      $!     ",
      " &-      $!     ",
      "&͹-      $!     ",
      "---      $!     ",
      "         $!     "
    ],
    [
      "$$$$   $$$&     ",
      "'$'''''''$&     ",
      "$$$$$$$$$$&     ",
      "ddeeeeed$$&     ",
      "&Ͷ     h$$&     ",
      " &     h$$&     ",
      "&ͺ     h$$&     ",
      "       h$$&     ",
      "&      h$$&     ",
      "&      h$$&     ",
      "       h$$&     ",
      "&ͻ     h$$&     ",
      " &     h$$&     ",
      "&Ͷ     h$$&     ",
      "ddgggggd$$&     ",
      "$$$$$$$$$$&#    "
    ],
    [
      "  9$   $$$H     ",
      " $'''''''$H     ",
      "         $H     ",
      "ggiiiiif $H     ",
      "&ͼ     j $H     ",
      " &     j $H     ",
      "&ͺ     j $H     ",
      "&      j $H     ",
      "&      j $H     ",
      "&      j $H     ",
      "&      j $H     ",
      "&ͻ     j $H     ",
      " &     j $H     ",
      "&ͷ     j $H     ",
      "eeiiiiiͽ $H#    ",
      "         $H#    "
    ],
    [
      "   9$  $$$      ",
      " $'''''''$H     ",
      "         $H     ",
      "         $H     ",
      "&ͻ       $H     ",
      " &       $H     ",
      "&ͺ       $H     ",
      "         $H     ",
      "&        $H     ",
      "&        $H     ",
      "         $H     ",
      "&ͻ       $H     ",
      " &       $H     ",
      "&ͺ       $H#    ",
      "         $H##   ",
      "         $H#    "
    ]
  ]
}