{
  "xsize": 16,
  "zsize": 16,
  "refpalette": "lostcities:ships",
  "slices": [
    [
      "      H$''      ",
      "      H$  '''''$",
      "      H$        ",
      "      H$        ",
      "      H$        ",
      "      H$   8    ",
      "      H$   8    ",
      "      H$        ",
      "      H$        ",
      "      H$   8    ",
      "      H$   8    ",
      "      H$        ",
      "      H$        ",
      "      H$   8    ",
      "      H$   8    ",
      "      H$        "
    ],
    [
      "     H $''      ",
      "     H $  ''''''",
      "     H $        ",
      "     H $        ",
      "     H $        ",
      "     H $        ",
      "     H $        ",
      "     H $        ",
      "     H $        ",
      "     H $        ",
      "     H $        ",
      "     H $        ",
      "     H $        ",
      "     H $        ",
      "     H $        ",
      "       $        "
    ],
    [
      "     H $''      ",
      "     H $  ''''''",
      "     H $        ",
      "     H $        ",
      "     H $        ",
      "     H $      # ",
      "     H $        ",
      "     H $      # ",
      "     H $        ",
      "     H $        ",
      "     H $        ",
      "     H $        ",
      "     H $        ",
      "     H $        ",
      "     H $        ",
      "                "
    ],
    [
      "     H΃΃΃΃΃΃΃΃΃΃",
      "     H΃΃΃΃΃΃΃΃΃΃",
      "     H΃΃΃΃΃΃΃΃΃΃",
      "     H΃΃΃΃΃΃΃΃΃΃",
      "     H΃΃΃΃΃΃΃΃΃΃",
      "     H΃΃΃΃΃΃΃΃΃΃",
      "     H΃΃΃΃΃΃΃΃΃΃",
      "     H΃΃΃΃΃΃΃΃΃΃",
      "     H΃΃΃΃΃΃΃΃΃΃",
      "     H΃΃΃΃΃΃΃΃΃΃",
      "     H΃΃΃΃΃΃΃΃΃΃",
      "     H΃΃΃΃΃΃΃΃΃΃",
      "     H΃΃΃΃΃΃΃΃΃΃",
      "     H΃΃΃΃΃΃΃΃΃΃",
      "        ΃΃΃΃΃΃΃΃",
      "        ΃΃΃΃΃΃΃΃"
    ],
    [
      "     hHH        ",
      "     j HH       ",
      "     j  HͰ      ",
      "     j Π  H   # ",
      "     h;=o HHHHHH",
      "     hͽ Ή    ###",
      "     j    *> ># ",
      "     j       ###",
      "     j    *> ># ",
      "     j          ",
      "     j      HHHH",
      "     j     H    ",
      "     j    $H    ",
      "     j    $H HHH",
      "           H    ",
      "          HH  . "
    ],
    [
      "      HH        ",
      "       HH       ",
      "       ΠH͵3   # ",
      "      o=jxH   # ",
      "      Ή Ή HHHHHH",
      "             ###",
      "          %Ρ*>##",
      "             ###",
      "          %Ρ*># ",
      "                ",
      "            HHHH",
      "                ",
      "          %     ",
      "          %H HHH",
      "           H    ",
      "          HH  --"
    ]
  ]
}