{
  "xsize": 16,
  "zsize": 16,
  "refpalette": "pomkotsmechs:ships",
  "slices": [
    [
      "         H    - ",
      "         H    - ",
      "              - ",
      "              - ",
      "              - ",
      "              - ",
      "              - ",
      "              - ",
      "              - ",
      "              --",
      "         H  #   ",
      "         H ##   ",
      "        #HHHHHHH",
      "       ##H#< < <",
      "        #H      ",
      "         H      "
    ],
    [
      "         HH΃΃H- ",
      "         H΃΃΃H- ",
      "          ΃΃΃H- ",
      "          ΃΃΃H- ",
      "          ΃΃΃H- ",
      "          ΃΃΃H- ",
      "          ΃΃΃H- ",
      "          ΃΃΃H- ",
      "          ΃΃΃H- ",
      "          ΃΃΃H--",
      "         H΃΃΃H  ",
      "         H΃΃΃Hgg",
      "         H΃΃΃΃HH",
      "        #H΃΃΃Hee",
      "         H΃΃΃H  ",
      "         H΃΃΃H  "
    ],
    [
      "         nͽ  H-a",
      "         j   H-&",
      "         j   H-b",
      "         j  $H--",
      "         f  $H--",
      "         f   H--",
      "         f   H--",
      "         f   H-a",
      "         j   H-&",
      "         j  #H-c",
      "         j ##H# ",
      "         j ##Hii",
      "         j##    ",
      "        #j#  Hii",
      "         j   H  ",
      "         j   H #"
    ],
    [
      "            ΢H c",
      "             H &",
      "             H b",
      "            %H  ",
      "            %H &",
      "             H &",
      "             H  ",
      "             H a",
      "             H &",
      "             H c",
      "            #H# ",
      "             H  ",
      "                ",
      "         #   H  ",
      "             HII",
      "             HHH"
    ],
    [
      "             H k",
      "             H &",
      "             H b",
      "             H  ",
      "             H &",
      "             H &",
      "             Z  ",
      "             Z a",
      "             Z &",
      "             H l",
      "            #H# ",
      "             HHH",
      "             H  ",
      "             H #",
      "             HHH",
      "             j##"
    ],
    [
      "             H  ",
      "             H  ",
      "             H  ",
      "             H  ",
      "             Z  ",
      "             H  ",
      "             Z  ",
      "             Z  ",
      "             Z# ",
      "             H #",
      "            #HHH",
      "             HHH",
      "             H##",
      "             H##",
      "             HHH",
      "              ##"
    ]
  ]
}