{
  "xsize": 16,
  "zsize": 16,
  "refpalette": "pomkotsmechs:ships",
  "slices": [
    [
      "                ",
      "                ",
      "                ",
      "                ",
      "                ",
      "                ",
      "                ",
      "                ",
      "                ",
      "                ",
      "                ",
      "                ",
      "                ",
      "                ",
      "                ",
      "                "
    ],
    [
      "                ",
      "                ",
      "                ",
      "                ",
      "                ",
      "                ",
      "                ",
      "                ",
      "                ",
      "                ",
      "                ",
      "                ",
      "                ",
      "                ",
      "                ",
      "                "
    ],
    [
      "          !!!!!!",
      "          !!!!!!",
      "          !!!!!!",
      "          !!!!!!",
      "          !!!!!!",
      "          !!!!!!",
      "          !!!!!!",
      "          !!!!!!",
      "          !!!!!!",
      "          !!!!!!",
      "          !!!!!!",
      "          !!!!!!",
      "          !!!!!!",
      "          !!!!!!",
      "          !!!!!!",
      "          !!!!!!"
    ],
    [
      "         !%%%%$$",
      "         !''''$$",
      "         !'%%%$$",
      "         !'%%%$$",
      "         !6%%%$$",
      "         !%%%%$$",
      "         !%%%%$$",
      "         !%%%%$$",
      "         !%%%%$$",
      "         !%%%%$$",
      "         !%%%%$$",
      "         !%%%%$$",
      "         !%%%%$$",
      "         !%%%%$$",
      "         !%%%%$$",
      "         !%%%%$$"
    ],
    [
      "        !$'7    ",
      "        !$''''''",
      "        !$'7    ",
      "        !$6     ",
      "        !$ .    ",
      "        !88.88  ",
      "        !88.88  ",
      "        !$ .    ",
      "        !$ .    ",
      "        !88.88  ",
      "        !88.88  ",
      "        !$ .    ",
      "        !$ .    ",
      "        !88.88  ",
      "        !88.88  ",
      "        !$ .    "
    ],
    [
      "       !$' 97   ",
      "       !$ ''''''",
      "       !$  97   ",
      "       !$       ",
      "       !$       ",
      "       !$;888;  ",
      "       !$;888;  ",
      "       !$       ",
      "       !$       ",
      "       !$;888;  ",
      "       !$;888;  ",
      "       !$       ",
      "       !$       ",
      "       !$;888;  ",
      "       !$;888;  ",
      "       !$       "
    ]
  ]
}