{
  "xsize": 16,
  "zsize": 16,
  "refpalette": "pomkotsmechs:ships",
  "slices": [
    [
      "  $    $ !      ",
      "  $    $$$!     ",
      "  $    $$$!     ",
      "  $) ) $$$!     ",
      "  $) ) $$$!     ",
      "  $$$$$$$$!     ",
      "  $     $$!     ",
      "  $)) ***$!     ",
      "  $     $$!     ",
      "  $)) ***$!     ",
      "  $     $$!     ",
      "  $   ***$!     ",
      "  $     $$!     ",
      "  $)) ***$!     ",
      "  $$$$$$$$!     ",
      "  $$E  $ $!     "
    ],
    [
      "  $    $ $!     ",
      "  $    $$$!     ",
      "  $    $$$!     ",
      "  $    $$$!     ",
      "  $    $$$!     ",
      "  $$$$$$$$!     ",
      "  $     $$!     ",
      "  $   ))$$!     ",
      "  $     $$!     ",
      "  $   ))$$!     ",
      "  $     $$!     ",
      "  $   ))$$!     ",
      "  $     $$!     ",
      "  $   ))$$!     ",
      "  $$$$$$$$!     ",
      "  $E   $$$!     "
    ],
    [
      "I $ II $ $!     ",
      "I $    $$$!     ",
      "I $    $$$!     ",
      "I $    $$$!     ",
      "I $    $$$!     ",
      "I $$$$$$$$!     ",
      "I $     $$!     ",
      "I $     $$!     ",
      "` $     $$!     ",
      "I $     $$!     ",
      "I $ II  $$!     ",
      "I $ II  $$!     ",
      "I $     $$!     ",
      "I $     $$!     ",
      "I $$$$$$$$!     ",
      "I E    $$$!     "
    ],
    [
      "&&&&&&&& $&     ",
      "&&&&&&&&$$&     ",
      "&&&&&&&&$$&     ",
      "&&&&&&&&$$&     ",
      "&&&&&&&&$$&     ",
      "&&&&&&&&$$&     ",
      "&&&&&&&&$$&     ",
      "&&&&&&&&$$&     ",
      "&&&&&&&&$$&     ",
      "&&&&&&&&$$&     ",
      "&&&&&&&&$$&     ",
      "&&&&&&&&$$&     ",
      "&&&&&&&&$$&     ",
      "&&&&&&&&$$&     ",
      "$&&&&&&&$$&     ",
      "$E     $$$&     "
    ],
    [
      "NNNNM  &&$H     ",
      "NNNNR  &&$H     ",
      "NNNN   &&$H     ",
      "NNNN   &&$H     ",
      "VVyNT   &$H     ",
      "XXzNM  &&$H     ",
      "XXzNM  &&$H     ",
      "XXzNR  &&$H     ",
      "ZZ{N   &&$H     ",
      "NNNN    &$H     ",
      "NNNNT  &&$H     ",
      "NNNNM  &&$H     ",
      " |KK}  &&$H     ",
      "       &&$H     ",
      "Ͱ$&&&&&&&$H     ",
      "       $$$H     "
    ],
    [
      "ͱͲͳ    &&$H     ",
      "       ʹ^$H     ",
      "       ʹ^$H     ",
      "       &&$H     ",
      "        &$H     ",
      "       &&$H     ",
      "       ʹ^$H     ",
      "       ʹ^$H     ",
      "       &&$H     ",
      "        &$H     ",
      "       &&$H     ",
      "       ʹ^$H     ",
      "       ʹ^$H     ",
      " 3     &&$      ",
      "͵$&&&&&&&$      ",
      "       $$$      "
    ]
  ]
}