{
  "xsize": 16,
  "zsize": 16,
  "refpalette": "pomkotsmechs:ships",
  "slices": [
    [
      "        $  H    ",
      "        $  HH   ",
      "        $  HHH  ",
      "        $ 6HHH϶ ",
      "        $  HHϥ  ",
      "        $  H϶   ",
      "        $  H    ",
      "        $  H    ",
      "        $  H    ",
      "        $       ",
      "        $       ",
      "        $       ",
      "        $       ",
      "  $$$$$$        ",
      "           H    ",
      "           H    "
    ],
    [
      "        $  HHϷ  ",
      "        $  HHH  ",
      "   II   $ 6HHHH ",
      "   II   $  HHHH ",
      "        $  HHHH ",
      "        $  HHH  ",
      "        $  HHϸ  ",
      "   II   $  H    ",
      "   II   $  H    ",
      "        $I      ",
      "        $       ",
      "                ",
      "                ",
      "$$$$$$$$$       ",
      "           H    ",
      "           H    "
    ],
    [
      "$$$$$$$$$$$Hi;  ",
      "$$$$$$$$$$6H m; ",
      "$$$$$$$$$$    j ",
      "$$$$$$$$$$ H  f ",
      "$$$$$$$$$$ H  j ",
      "$$$$$$$$$$ H nͽ ",
      "$$$$$$$$$$$Hiͽ  ",
      "$$$$$$$$$$HH    ",
      "$$$$$$$$$$HH    ",
      "$$$$$$$$$H΃H    ",
      "$$$$$$$$H       ",
      "HHHHHHHH΃       ",
      "                ",
      "΃΃΃΃΃΃΃         ",
      "΃΃΃΃΃΃΃΃   H    ",
      "΃΃΃΃΃΃΃΃΃΃΃H    "
    ],
    [
      "           H    ",
      "A''''''  / H    ",
      "    F('  '      ",
      "     ('  ' H    ",
      "     ('  ' H    ",
      "     ('  ' H    ",
      "     ('  ''H    ",
      "ΝΝ   ('  'Hf    ",
      "'''''''' HHf    ",
      "      '' H j    ",
      "      'H        ",
      "HHHHHHHH        ",
      "HHHHHHH         ",
      "                ",
      "           j    ",
      "           j    "
    ],
    [
      " 3         H    ",
      "B''''''    H    ",
      "      '  / H    ",
      "      '  ' H    ",
      "      '  ' H    ",
      "      '  ' H    ",
      "      '  'HH    ",
      "     2'  'H     ",
      "'''''''' HH     ",
      "      '' H      ",
      "      'H        ",
      "HHHHHHHH        ",
      "HHHHHHH         ",
      "                ",
      "                ",
      "                "
    ],
    [
      "           H    ",
      "'''''''    H    ",
      "      '    H    ",
      "      '  / H    ",
      "      '  ' H    ",
      "      '  ' H    ",
      "      '  'H     ",
      "      '  'H     ",
      "'''''''''ϛ      ",
      "      'Hϛ       ",
      "     HHϛ        ",
      "HHHHHHH         ",
      "                ",
      "                ",
      "                ",
      "                "
    ]
  ]
}