{
  "xsize": 16,
  "zsize": 16,
  "refpalette": "pomkotsmechs:ships",
  "slices": [
    [
      "                ",
      "                ",
      "                ",
      "                ",
      "                ",
      "                ",
      "                ",
      "                ",
      "                ",
      "                ",
      "                ",
      "                ",
      "                ",
      "                ",
      "                ",
      "                "
    ],
    [
      "                ",
      "                ",
      "                ",
      "                ",
      "                ",
      "                ",
      "                ",
      "                ",
      "                ",
      "                ",
      "                ",
      "                ",
      "                ",
      "                ",
      "                ",
      "                "
    ],
    [
      "!!!!!!!         ",
      "!!!!!!!         ",
      "!!!!!!!         ",
      "!!!!!!!         ",
      "!!!!!!!         ",
      "!!!!!!!         ",
      "!!!!!!!         ",
      "!!!!!!!         ",
      "!!!!!!!         ",
      "!!!!!!!         ",
      "!!!!!!!         ",
      "!!!!!!!         ",
      "!!!!!!!         ",
      "!!!!!!!         ",
      "!!!!!!!         ",
      "!!!!!!!         "
    ],
    [
      "$$$%%%%!        ",
      "$$$%888!        ",
      "$$$%888!        ",
      "$$$%%%%!        ",
      "$$$%%%%!        ",
      "$$$%888!        ",
      "$$$%888!        ",
      "$$$%%%%!        ",
      "$$$%%%%!        ",
      "$$$%<<<!        ",
      "$$$%<<<!        ",
      "$$$' <<!        ",
      "$$$$ <<!        ",
      "$$$$ <<!        ",
      "$$$$%%%!        ",
      "$$$$%%%!        "
    ],
    [
      "     . $!       ",
      "   88.88!       ",
      "   88.88!       ",
      "     . $!       ",
      "     . $!       ",
      "   88.88!       ",
      "   88.88!       ",
      "     . $!       ",
      "     . $!       ",
      "   <<.<<!       ",
      "   <<.<<!       ",
      "$''' .<$!       ",
      "    $.<<!       ",
      "    $.<<!       ",
      "    $. $!       ",
      "    $. $!       "
    ],
    [
      "        $!      ",
      "   ;888;$!      ",
      "   ;888;$!      ",
      "        $!      ",
      "        $!      ",
      "   ;888;$!      ",
      "   ;888;$!      ",
      "        $!      ",
      "        $!      ",
      "    <<< $!      ",
      "    <<< $!      ",
      "$'''<<<'$!      ",
      "    $$$$$!      ",
      "    $$$$$!      ",
      "    $$$$$!      ",
      "    $$$$$!      "
    ]
  ]
}