{
  "xsize": 16,
  "zsize": 16,
  "refpalette": "pomkotsmechs:ships",
  "slices": [
    [
      "      $         ",
      "  < <           ",
      "      $         ",
      "  < < $ H       ",
      "      $$ H      ",
      "  < < $$ H      ",
      "      $$ H#     ",
      "  < < $$ H##    ",
      "      $$#H##    ",
      "      $$ H#     ",
      "'''''''$ H      ",
      "&&&&&&&&&$H     ",
      "        &$H     ",
      "        &$H     ",
      "ππρ     &$H     ",
      "``ς     &$H     "
    ],
    [
      "                ",
      "  p p           ",
      "                ",
      "  p p $         ",
      "      $$        ",
      "  p p $$ H#     ",
      "      $$ H##    ",
      "  p p $$ H##    ",
      "      $$ $H     ",
      "      $$ $H     ",
      "'''''''$ $H     ",
      "&&&&&&&&&$H     ",
      "        &$H     ",
      "        &$ H    ",
      "σστ     &$ H    ",
      "υυφ     &$ H    "
    ],
    [
      "                ",
      "                ",
      "                ",
      "I     $         ",
      "I     $$        ",
      "I     $$ $#     ",
      "      $$ $H#    ",
      "      $$ $H     ",
      "      $$ $H     ",
      "      $$ $H     ",
      "'''''''$ $H     ",
      "&&&&&&&&&$ H    ",
      "        &$ H    ",
      "        &$ H    ",
      "        &$ H    ",
      "        &$ H    "
    ],
    [
      "΃΃΃΃΃΃΃         ",
      "΃΃΃΃΃΃          ",
      "΃΃΃΃΃΃΃         ",
      "΃΃΃΃΃΃΃         ",
      "΃΃΃΃΃΃΃΃        ",
      "΃΃΃΃΃΃΃΃΃΃#     ",
      "΃΃΃΃΃΃΃΃΃΃##    ",
      "΃΃΃΃΃΃΃΃΃΃H     ",
      "΃΃΃΃΃΃΃΃΃΃HH    ",
      "΃΃΃΃΃΃΃΃΃΃΃H    ",
      "΃΃΃΃΃΃΃΃΃΃΃H    ",
      "΃΃΃΃΃΃΃΃΃΃΃H    ",
      "΃΃΃΃΃΃΃΃΃΃΃H    ",
      "΃΃΃΃΃΃΃΃΃΃΃H    ",
      "΃΃΃΃΃΃΃΃΃΃΃H    ",
      "΃΃΃΃΃΃΃΃΃΃΃H    "
    ],
    [
      "         j      ",
      "  $$   Ύ        ",
      "HHHHHH          ",
      "ΏχψψψHH         ",
      "     ωHH        ",
      "<<<  ϊ H  #     ",
      "F<F  ϊ $H###    ",
      "<<<  ϊ $  H     ",
      "    $ΐΐ$  HH    ",
      "<<<    $   H    ",
      "<<<    $   H    ",
      "       $   H    ",
      "       $   H    ",
      "$$$$$$$$$  H    ",
      "        $  H    ",
      "        $  H    "
    ],
    [
      "                ",
      "Α %%            ",
      " HHHHH          ",
      "     HHΑ        ",
      "      HH        ",
      "       HH #     ",
      "      #$H#H#    ",
      "      #$  H     ",
      "    $ΐΐ$  HH    ",
      "       $   H    ",
      "       $   H    ",
      "       $   H    ",
      "       $   H    ",
      "       $$  H    ",
      "        $  H    ",
      "        $  H    "
    ]
  ]
}