{
  "xsize": 16,
  "zsize": 16,
  "refpalette": "pomkotsmechs:ships",
  "slices": [
    [
      "        $!      ",
      "  p p  p$!      ",
      "        !       ",
      "$$$$$$$$!       ",
      "       $!       ",
      "       $!       ",
      "       $!       ",
      "       !!       ",
      "       !!       ",
      "$$$$$$!!!       ",
      "$$$$!!!!        ",
      "!!!!!!!!        ",
      "!!!!!!!         ",
      "!!!!!!          ",
      "!!!!##          ",
      "  ####          "
    ],
    [
      "qq& &qq&$!      ",
      "&&& &&&&$!      ",
      "        $!      ",
      "$$$$$$$$$!      ",
      "       $!       ",
      "       $!       ",
      "       $!       ",
      "       $!       ",
      "       $!       ",
      "$$$$$$$$!       ",
      "$$$$$$$$!       ",
      "       !!       ",
      "  ##   !!       ",
      " #### !!        ",
      "  ##!!!!        ",
      "!!!!!!!!        "
    ],
    [
      "  E 9  E$!      ",
      "66& &66&$!      ",
      "        $!      ",
      "$$$$$$$$$!      ",
      "       $!       ",
      "       $!       ",
      "       $!       ",
      "       $!       ",
      "       $!       ",
      "$$$$$$$$!       ",
      "$$$$$$$$!       ",
      "        !       ",
      "   #    !       ",
      "  ###   !       ",
      "   ##  !!       ",
      "    ###!        "
    ],
    [
      "  E 9  E$&      ",
      "66& &66&$&      ",
      "        $&      ",
      "$$$$$$$$&&      ",
      "       $&       ",
      "       $&       ",
      "       $&       ",
      "       $&       ",
      "       $&       ",
      "$$$$$$$$&       ",
      "$$$$$$$$&       ",
      "        &       ",
      "   ##   &       ",
      "  ####  &       ",
      "   ### &&       ",
      "    #  &        "
    ],
    [
      "rr& &rr&$H      ",
      "&&& &&&&$H      ",
      "        $H      ",
      "$$$$$$$$$H      ",
      "       $HH      ",
      "       $H       ",
      "       $H       ",
      "       $H       ",
      "       $H       ",
      "$$$$$$$$H       ",
      "$$$$$$$$H       ",
      "        H       ",
      "        H       ",
      "   ##   H       ",
      "   ###          ",
      "    #           "
    ],
    [
      "       #$H#     ",
      "      ##$H      ",
      "      ##$H      ",
      "$$$$$$$$$H      ",
      "     # $$H      ",
      "     ##$$H      ",
      "      #$H       ",
      "      #$H       ",
      "      #$H       ",
      "$$$$$$$$H       ",
      "$$$$$$$$H       ",
      "     #  H       ",
      "        H       ",
      "    ### H       ",
      "   ####         ",
      "    ##          "
    ]
  ]
}