{
  "xsize": 16,
  "zsize": 16,
  "refpalette": "pomkotsmechs:ships",
  "slices": [
    [
      "      H$        ",
      "       $   8    ",
      "       $   8    ",
      "       $        ",
      "       $        ",
      "      H$   8    ",
      "      H$   8    ",
      "      H$        ",
      "      H$        ",
      "      H$        ",
      "      H$       $",
      "      H$'''''''$",
      "      H$       $",
      "      H$        ",
      "      H$        ",
      "      H$ &////& "
    ],
    [
      "                ",
      "                ",
      "                ",
      "                ",
      "                ",
      "       $        ",
      "      H$        ",
      "     HH$        ",
      "     HH$        ",
      "     H $        ",
      "     H $        ",
      "     H $''''''''",
      "     H $        ",
      "     H $        ",
      "     H $        ",
      "     H $ &////& "
    ],
    [
      "                ",
      "                ",
      "                ",
      "                ",
      "                ",
      "                ",
      "                ",
      "                ",
      "      H         ",
      "                ",
      "     H $        ",
      "     H $''''''''",
      "     H $        ",
      "     H $        ",
      "     H $#       ",
      "     H $ &&&&&& "
    ],
    [
      "        ΃΃΃΃΃΃΃΃",
      "        ΃΃΃΃΃΃΃΃",
      "          ΃΃΃΃΃΃",
      "           ΃΃΃΃΃",
      "          ΃΃΃΃΃΃",
      "         ΃΃΃΃΃΃΃",
      "         ΃΃΃΃΃΃΃",
      "          ΃΃΃΃΃΃",
      "          HH΃΃΃΃",
      "         ΃HH΃΃΃΃",
      "     H΃΃΃΃HH΃΃΃΃",
      "     H΃΃΃΃HH΃΃΃΃",
      "     H΃΃΃΃HH΃΃΃΃",
      "     H΃΃΃΃HH΃΃΃΃",
      "     H΃΃΃΃HH΃΃΃΃",
      "     H΃΃΃΃HH΃΃΃΃"
    ],
    [
      "         H      ",
      "         H      ",
      "                ",
      "                ",
      "              . ",
      "                ",
      "                ",
      "                ",
      "                ",
      "         H    . ",
      "        $H      ",
      "     j   H      ",
      "     j  #HHHHHHH",
      "     j ##H < < <",
      "     j ##H      ",
      "     j  #       "
    ],
    [
      "         H    --",
      "         H    --",
      "              --",
      "              --",
      "              --",
      "              --",
      "              --",
      "              --",
      "              --",
      "              --",
      "        %H      ",
      "         H      ",
      "        #HHHHHHH",
      "       #΢H      ",
      "        #H      ",
      "                "
    ]
  ]
}