{
  "xsize": 16,
  "zsize": 16,
  "refpalette": "lostcities:ships",
  "slices": [
    [
      "         $H     ",
      "     8   $H     ",
      "     8   $H     ",
      "         $H     ",
      "         $H     ",
      "     8   $H     ",
      "     8   $H     ",
      "         $H     ",
      "         $H     ",
      "         $H#    ",
      "$$       $H##   ",
      "$$'''''''$H##   ",
      "$$       $H#    ",
      "         $H     ",
      "         $H     ",
      "  &////& $H     "
    ],
    [
      "         $ H    ",
      "         $ H    ",
      "         $ H    ",
      "         $ H    ",
      "         $ H    ",
      "         $ H    ",
      "         $ H    ",
      "         $ H    ",
      "         $ H    ",
      "         $ H    ",
      "         $#H#   ",
      "'''''''''$#H    ",
      "         $ H    ",
      "         $ H    ",
      "         $ H    ",
      "  &////& $ H    "
    ],
    [
      "I        $ H    ",
      "`        $ H    ",
      "`        $ H    ",
      "`        $ H    ",
      "         $ H    ",
      "         $ H    ",
      "         $ H    ",
      "       # $ H    ",
      "       ##$#H    ",
      "         $#H    ",
      "         $#H#   ",
      "'''''''''$ H    ",
      "         $ H    ",
      "         $HH    ",
      "         $HH    ",
      "  &&&&&& $HH    "
    ],
    [
      "΃΃΃΃΃΃΃΃΃΃΃H    ",
      "΃΃΃΃΃΃΃΃΃΃΃H    ",
      "΃΃΃΃΃΃΃΃΃΃΃H    ",
      "΃΃΃΃΃΃΃΃΃΃΃H    ",
      "΃΃΃΃΃΃΃΃΃΃΃H    ",
      "΃΃΃΃΃΃΃΃΃΃΃H    ",
      "΃΃΃΃΃΃΃΃΃΃΃H    ",
      "΃΃΃΃΃΃΃΃΃΃΃H    ",
      "΃΃΃΃΃HH΃΃΃΃H#   ",
      "΃΃΃΃΃HH΃΃΃΃H#   ",
      "΃΃΃΃΃HH΃΃΃΃H#   ",
      "΃΃΃΃΃HH΃΃΃΃H    ",
      "΃΃΃΃΃HH΃΃΃΃H    ",
      "΃΃΃΃΃HH΃΃΃΃H    ",
      "΃΃΃΃΃HH΃΃΃΃H    ",
      "΃΃΃΃΃HH΃΃΃΃H    "
    ],
    [
      "      H    j    ",
      "      H    j    ",
      "      H    j    ",
      "  .   H    j    ",
      "      H    j    ",
      "      H    j    ",
      "      H#   j    ",
      "     #H####j    ",
      "      H##j#j#   ",
      "  .   H  Ή#j#   ",
      "      H    j    ",
      "     HH  HHH    ",
      "HHH HHH  HHH    ",
      " <   HH  HHH    ",
      "     HH    j    ",
      "     HH  o j    "
    ],
    [
      "---   Hϔ        ",
      "---   H         ",
      "---   H         ",
      "---   H         ",
      "---   H         ",
      "---   H         ",
      "---   H         ",
      "---  #H#        ",
      "---   H  ###    ",
      "---   H    #    ",
      "      Hϔ        ",
      "     HH  HHH    ",
      "HHH HHH  HHH    ",
      "     HH  HHH    ",
      "     HH         ",
      "     HH         "
    ]
  ]
}