{
  "xsize": 16,
  "zsize": 16,
  "refpalette": "pomkotsmechs:ships",
  "slices": [
    [
      "           H$   ",
      "           H$'' ",
      "           H  & ",
      "          H$  & ",
      "         #H$  & ",
      "          H$$'' ",
      "           $$   ",
      "            $$$$",
      "            #   ",
      "           #<#< ",
      "          $ ##  ",
      "          $ <#< ",
      "          $  #  ",
      "            < < ",
      "                ",
      "          $ < < "
    ],
    [
      "           H$   ",
      "          H$$'' ",
      "          H$$'' ",
      "         #H$$'' ",
      "        ##H$$'' ",
      "         H#$$'' ",
      "           $$   ",
      "            $$$$",
      "                ",
      "            p p ",
      "             #  ",
      "            p#p ",
      "             #  ",
      "            p p ",
      "                ",
      "        H $ p p "
    ],
    [
      "          H$$   ",
      "          H$$   ",
      "          H$$   ",
      "         H $$   ",
      "        #H#$$   ",
      "         H $$&  ",
      "           $$   ",
      "            $$$$",
      "                ",
      "                ",
      "            ##  ",
      "        H $#### ",
      "        H $ ##  ",
      "        H $  #  ",
      "        H $     ",
      "       H  $     "
    ],
    [
      "             $$$",
      "             $$$",
      "             $$$",
      "         H## $$$",
      "        #H###$$$",
      "         ### $$$",
      "             $$$",
      "                ",
      "             H΃H",
      "             &&&",
      "            #&&&",
      "        H  #HHHH",
      "       H ΃΃H&&&&",
      "       H΃΃΃H&&&&",
      "       H΃΃΃HHHHH",
      "       H΃΃΃΃΃΃΃΃"
    ],
    [
      "            ΄΃΃΃",
      "            ΄΃΃?",
      "           ΃΄΄?΄",
      "         #΃΃΃?΃΃",
      "        #H#΃?΃΃΃",
      "        H##΃?΃΃΃",
      "            ?΃΃΃",
      "            ΃?΃΃",
      "              ΅ ",
      "        H       ",
      "       H΃       ",
      "       H΃   ##  ",
      "       H΃    #  ",
      "       j     #  ",
      "       j        ",
      "       j        "
    ],
    [
      "                ",
      "                ",
      "         ΃      ",
      "        #΃      ",
      "       ########Ά",
      "        H#   ##·",
      "        j     #Έ",
      "                ",
      "        j       ",
      "       nͽ       ",
      "       j        ",
      "       j        ",
      "       j        ",
      "       Ή        ",
      "                ",
      "                "
    ]
  ]
}