{
  "xsize": 16,
  "zsize": 16,
  "refpalette": "pomkotsmechs:ships",
  "slices": [
    [
      "      !$(     $ ",
      "      !$''''''''",
      "      !$        ",
      "      !$     ---",
      "      !$     -- ",
      "      !$     -- ",
      "      !$     -- ",
      "      !$     -- ",
      "      !$     -- ",
      "      !$     -- ",
      "      !$     -- ",
      "      !$     -- ",
      "      !$     -- ",
      "      !$     -- ",
      "      !$     ---",
      "      !$        "
    ],
    [
      "      !$(     $ ",
      "      !$''''''''",
      "      !$        ",
      "      !$     ---",
      "      !$     -- ",
      "      !$     -- ",
      "      !$     -- ",
      "      !$     -- ",
      "      !$     -- ",
      "      !$     -- ",
      "      !$     -- ",
      "      !$     -- ",
      "      !$     -- ",
      "      !$     -- ",
      "      !$     ---",
      "      !$        "
    ],
    [
      "      !$      $ ",
      "      !$''''''''",
      "      !$        ",
      "      !$      --",
      "      !$      -a",
      "      !$      -&",
      "      !$      -b",
      "      !$      --",
      "      !$      --",
      "      !$      --",
      "      !$      --",
      "      !$      -a",
      "      !$      -&",
      "      !$      -c",
      "      !$      --",
      "      !$        "
    ],
    [
      "      &$$$$$$$$$",
      "      &$'''''''$",
      "      &$$$$$$$$$",
      "      &$$deeeeed",
      "      &$$f     c",
      "      &$$f     &",
      "      &$$f     b",
      "      &$$f      ",
      "      &$$f     &",
      "      &$$f     &",
      "      &$$f      ",
      "      &$$f     a",
      "      &$$f     &",
      "      &$$f     c",
      "      &$$dgggggd",
      "      &$$$$$$$$$"
    ],
    [
      "      H$        ",
      "      H$'''''''$",
      "      H$        ",
      "      H$ hiiiiig",
      "      H$ j     k",
      "      H$ j     &",
      "      H$ j     b",
      "      H$ j      ",
      "      H$ j     &",
      "      H$ j     &",
      "      H$ j      ",
      "      H$ j     a",
      "      H$ j     &",
      "      H$ j     l",
      "      H$ miiiiie",
      "      H$        "
    ],
    [
      "      H$        ",
      "      H$'''''''$",
      "      H$        ",
      "      H$        ",
      "      H$       a",
      "      H$       &",
      "      H$       b",
      "      H$        ",
      "      H$       &",
      "      H$       &",
      "      H$        ",
      "      H$       a",
      "      H$       &",
      "      H$       b",
      "      H$        ",
      "      H$        "
    ]
  ]
}