{
  "xsize": 16,
  "zsize": 16,
  "refpalette": "lostcities:ships",
  "slices": [
    [
      "      !$        ",
      "      !$ ; 8 ;  ",
      "      !$ ; 8 ;  ",
      "      !$        ",
      "      !$        ",
      "      !$ ; 8 ;  ",
      "      !$ ; 8 ;  ",
      "      !$        ",
      "      !$        ",
      "      !$   <    ",
      "      !$   <    ",
      "      !$''''''''",
      "      !$        ",
      "      !$        ",
      "      !$        ",
      "      !$        "
    ],
    [
      "      !$        ",
      "      !$ <   ;  ",
      "      !$ <   ;  ",
      "      !$        ",
      "      !$        ",
      "      !$ <   ;  ",
      "      !$ <   ;  ",
      "      !$        ",
      "      !$        ",
      "      !$        ",
      "      !$        ",
      "      !$''''''''",
      "      !$        ",
      "      !$        ",
      "      !$        ",
      "      !$        "
    ],
    [
      "      !$        ",
      "      !$ < 8 <  ",
      "      !$ < 8 <  ",
      "      !$        ",
      "      !$        ",
      "      !$ < 8 <  ",
      "      !$ < 8 <  ",
      "      !$        ",
      "      !$        ",
      "      !$        ",
      "      !$        ",
      "      !$''''''''",
      "      !$        ",
      "      !$        ",
      "      !$        ",
      "      !$        "
    ],
    [
      "      &$   8   h",
      "      &$ <888< h",
      "      &$ <888< h",
      "      &$   8   h",
      "      &$   8   h",
      "      &$ <888< h",
      "      &$ <888< h",
      "      &$   8   h",
      "      &$   8   h",
      "      &$   8   h",
      "      &$   8   $",
      "      &$'''''''$",
      "      &$$$$$$$$$",
      "      &$$$$$$$$$",
      "      &$$$$$$$$$",
      "      &$$$$$$$$$"
    ],
    [
      "      H$  888  j",
      "      H$ 88888 j",
      "      H$ 88888 j",
      "      H$  888  j",
      "      H$  888  j",
      "      H$ 88888 j",
      "      H$ 88888 j",
      "      H$  888  j",
      "      H$  888  j",
      "      H$  888  j",
      "      H$  888  $",
      "      H$'''''''$",
      "      H$       $",
      "      H$        ",
      "      H$        ",
      "      H$ p    p "
    ],
    [
      "      H$   8    ",
      "      H$  888   ",
      "      H$  888   ",
      "      H$   8    ",
      "      H$   8    ",
      "      H$  888   ",
      "      H$  888   ",
      "      H$   8    ",
      "      H$   8    ",
      "      H$   8    ",
      "      H$   8   $",
      "      H$'''''''$",
      "      H$       $",
      "      H$        ",
      "      H$        ",
      "      H$ &&&&&& "
    ]
  ]
}