{
  "xsize": 16,
  "zsize": 16,
  "refpalette": "pomkotsmechs:ships",
  "slices": [
    [
      "      H$ 9    E ",
      "      H$ 9    E ",
      "      H$ &6666& ",
      "      H$        ",
      "      H$ &////& ",
      "      H$ 9    E ",
      "      H$ 9    E ",
      "      H$ &6666& ",
      "       $        ",
      "      H$ &////& ",
      "      H$ 9    E ",
      "      H$ 9    E ",
      "      H$ &6666& ",
      "      H$        ",
      "       $'''''''$",
      "       $$       "
    ],
    [
      "     H $ 9    E ",
      "     H $ 9    E ",
      "     H $ &6666& ",
      "     H $        ",
      "     H $ &////& ",
      "     H $ 9    E ",
      "     H $ 9    E ",
      "     H   &6666& ",
      "                ",
      "         &////& ",
      "       $ 9    E ",
      "       $ 9    E ",
      "       $ &6666& ",
      "       $        ",
      "       $''''''''",
      "       $$       "
    ],
    [
      "     H $ &DDDD& ",
      "     H $ &DDDD& ",
      "     H $ &&&&&& ",
      "     H $        ",
      "     H $ &&&&&& ",
      "     H $ &DDDD& ",
      "     H $ &DDDD& ",
      "         &&&&&& ",
      "                ",
      "         &&&&&& ",
      "         &DDDD& ",
      "         &DDDD& ",
      "       $ &&&&&& ",
      "       $        ",
      "       $''''''''",
      "       $$       "
    ],
    [
      "     H΃΃΃΃΃H΃΃΃΃",
      "     H΃΃΃΃΃H΃΃΃΃",
      "     H΃΃΃΃΃H΃΃΃΃",
      "     H΃΃΃΃΃΃΃΃΃΃",
      "     H΃΃΃΃΃΃΃΃΃΃",
      "     H΃΃΃΃΃΃΃΃΃΃",
      "     H   ΃΃΃΃΃΃΃",
      "          ΃΃΃΃΃΃",
      "          ΃΃΃΃΃΃",
      "         ΃΃΃΃΃΃΃",
      "         ΃΃΃΃΃΃΃",
      "        ΃΃΃΃΃΃΃΃",
      "        ΃΃΃΃΃΃΃΃",
      "         ΃΃΃΃΃΃΃",
      "         ΃΃΃΃΃΃΃",
      "       ΃΃΃΃΃΃΃΃΃"
    ],
    [
      "     j   H      ",
      "     j   H & & &",
      "     j   HHHHHHH",
      "     j      H   ",
      "     j      H   ",
      "     j     ΠH   ",
      "     j    o=H   ",
      "          Ή H   ",
      "            H   ",
      "            H HH",
      "            HHH ",
      "              H ",
      "                ",
      "                ",
      "                ",
      "                "
    ],
    [
      "         H      ",
      "         H      ",
      "         HHHHHHH",
      "            HHHH",
      "           ΠHHHH",
      "          o=HHHH",
      "          Ή HHHH",
      "            HHHH",
      "            HHHH",
      "            HHHH",
      "            HHHΣ",
      "            ΣΣH ",
      "                ",
      "                ",
      "                ",
      "                "
    ]
  ]
}