{
  "xsize": 16,
  "zsize": 16,
  "slices": [
    [
      "################",
      "################",
      "################",
      "################",
      "################",
      "################",
      "################",
      "################",
      "################",
      "#######l########",
      "################",
      "################",
      "################",
      "################",
      "################",
      "################"
    ],
    [
      "``````####``````",
      "`              `",
      "` $$$      $$$ `",
      "` $D$      $D$ `",
      "` $$$      $$$ `",
      "`              `",
      "#              #",
      "#              #",
      "#              #",
      "###### l #     #",
      "` FFC#####  .  `",
      "`              `",
      "`           .  `",
      "`              `",
      "`              `",
      "``````####``````"
    ],
    [
      "``````####``````",
      "`              `",
      "`              `",
      "`  K        K  `",
      "`              `",
      "`              `",
      "#              #",
      "#              #",
      "#              #",
      "###### l #     #",
      "`    #####  -  `",
      "`              `",
      "`           -  `",
      "`              `",
      "`              `",
      "``````####``````"
    ],
    [
      "################",
      "#              #",
      "#              #",
      "#              #",
      "#              #",
      "#              #",
      "#              #",
      "#              #",
      "#              #",
      "###### l #     #",
      "#    #####     #",
      "#              #",
      "#              #",
      "#              #",
      "#              #",
      "################"
    ],
    [
      "``````####``````",
      "`              `",
      "`              `",
      "`  E        E  `",
      "`              `",
      "`              `",
      "#              #",
      "#              #",
      "#              #",
      "###### l #     #",
      "`    #####     `",
      "`              `",
      "`           E  `",
      "`              `",
      "`              `",
      "``````####``````"
    ],
    [
      "``````####``````",
      "`              `",
      "`              `",
      "`  {        {  `",
      "`              `",
      "`              `",
      "#              #",
      "#              #",
      "#              #",
      "###### l #     #",
      "`    #####     `",
      "`              `",
      "`           {  `",
      "`              `",
      "`              `",
      "``````####``````"
    ]
  ]
}