{
  "xsize": 16,
  "zsize": 16,
  "slices": [
    [
      "################",
      "################",
      "################",
      "################",
      "################",
      "################",
      "################",
      "################",
      "################",
      "#######l########",
      "################",
      "################",
      "################",
      "################",
      "################",
      "################"
    ],
    [
      "``````####``````",
      "`              `",
      "`              `",
      "`              `",
      "`              `",
      "`              `",
      "#              #",
      "#              #",
      "#              #",
      "#      l       #",
      "``# #`###``# #``",
      "`     *FF      `",
      "`              `",
      "`              `",
      "`*            *`",
      "``````####``````"
    ],
    [
      "``````####``````",
      "`              `",
      "`              `",
      "`              `",
      "`              `",
      "`              `",
      "#              #",
      "#              #",
      "#              #",
      "#      l       #",
      "``# #`###``# #``",
      "`              `",
      "`              `",
      "`              `",
      "`              `",
      "``````####``````"
    ],
    [
      "################",
      "#              #",
      "#              #",
      "#              #",
      "#              #",
      "#              #",
      "#              #",
      "#              #",
      "#              #",
      "#      l       #",
      "#`###`###``###`#",
      "#              #",
      "#              #",
      "#              #",
      "#              #",
      "################"
    ],
    [
      "``````####``````",
      "`              `",
      "`              `",
      "`  E        E  `",
      "`              `",
      "`              `",
      "#              #",
      "#              #",
      "#              #",
      "#      l       #",
      "``````###```````",
      "`              `",
      "`              `",
      "`              `",
      "`              `",
      "``````####``````"
    ],
    [
      "``````####``````",
      "`              `",
      "`              `",
      "`  {        {  `",
      "`              `",
      "`              `",
      "#              #",
      "#              #",
      "#              #",
      "#      l       #",
      "``````###```````",
      "`              `",
      "`              `",
      "`              `",
      "`              `",
      "``````####``````"
    ]
  ]
}
