{
  "xsize": 16,
  "zsize": 16,
  "refpalette": "pomkotsmechs:offshore",
  "slices": [
    [
      "       !!       ",
      " !AA! !!!! !AA! ",
      " B  B  !!  B  B ",
      " B  B      B  B ",
      " !AA!      !AA! ",
      "                ",
      " !            ! ",
      "!!!          !!!",
      "!!!          !!!",
      " !            ! ",
      "                ",
      " !AA!      !AA! ",
      " B  B      B  B ",
      " B  B  !!  B  B ",
      " !AA! !!!! !AA! ",
      "       !!       "
    ],
    [
      "!!!!!!!!!!!!!!!!",
      "!!!!!!!!!!!!!!!!",
      "!!!!!!!!!!!!!!!!",
      "!!!!!!!!!!!!!!!!",
      "!!!!!!!!!!!!!!!!",
      "!!!!!!!!!!!!!!!!",
      "!!!!!!!!!!!!!!!!",
      "!!!!!!!!!!!!!!!!",
      "!!!!!!!!!!!!!!!!",
      "!!!!!!!!!!!!!!!!",
      "!!!!!!!!!!!!!!!!",
      "!!!!!!!!!!!!!!!!",
      "!!!!!!!!!!!!!!!!",
      "!!!!!!!!!!!!!!!!",
      "!!!!!!!!!!!!!!!!",
      "!!!!!!!!!!!!!!!!"
    ],
    [
      "$$$$$$$$$$$$$$!!",
      "$$$$$$$$$$$$$$!!",
      "$$$$$$$$$$$$$$!!",
      "$$$$$$$$$$$$$$!!",
      "$$$$$$$$$$$$$$!!",
      "$$$$$$$$$$$$$$!!",
      "$$$$$$$$$$$$$$!!",
      "$$$$$$$$$$$$$$!!",
      "$$$$$$$$$$$$$$!!",
      "$$$$$$$$$$$$$$!!",
      "$$$$$$$$$$$$$$!!",
      "$$$$$$$$$$$$$$!!",
      "$$$$$$$$$$$$$$!!",
      "$$$$$$$$$$$$$$!!",
      "$$$$$$$$$$$$$$!!",
      "$$$$$$$$$$$$$$!!"
    ],
    [
      "                ",
      "  EE EE  EE EE  ",
      "  EE EE  EE EE  ",
      " e;     &     & ",
      "                ",
      "  &   &  &   &  ",
      "             . .",
      "            ....",
      "             .  ",
      "  &   &  &   &  ",
      "                ",
      "                ",
      "  &   &  &   &  ",
      "                ",
      "                ",
      "                "
    ],
    [
      "                ",
      "  EE EE  EE EE  ",
      "  EE EE  EE EE  ",
      " &      &     & ",
      "                ",
      "  DDDDD  DDDDD  ",
      "  DDDDD  DDDDD  ",
      "  DDDDD  DDDDD. ",
      "  DDDDD  DDDDD  ",
      "  DDDDD  DDDDD  ",
      "                ",
      "                ",
      "  DDDDD  DDDDD  ",
      "  DDDDD  DDDDD  ",
      "  DDDDD  DDDDD  ",
      "  DDDDD  DDDDD  "
    ],
    [
      "                ",
      "                ",
      "                ",
      " &      &     & ",
      "                ",
      "  D$$$D  D$$$D  ",
      "  $EE$$  $EE$$  ",
      "  $EE $  $EE.$. ",
      "  $   $  $   $  ",
      "  D$$$D  D$$$D  ",
      "                ",
      "                ",
      "  D$$$D  D$$$D  ",
      "  $EE $  $EE $  ",
      "  $   $  $   $  ",
      "  $   $  $   $  "
    ]
  ]
}