{
  "xsize": 16,
  "zsize": 16,
  "refpalette": "pomkotsmechs:offshore",
  "slices": [
    [
      " D$$$D  D$$$D  D",
      "                ",
      "                ",
      " D$$$D  D$$$D  D",
      " $   $  $   $  $",
      " $   $  $   $  $",
      " $   $  $   $  $",
      " D$$$D  D$$$D  D",
      "                ",
      "                ",
      " D$$$D  D$$$D  D",
      " $$$$$  $$$$$  $",
      " $   $  $   $  $",
      " $   $  $   $  $",
      " D$$$D  D$$$D  D",
      "                "
    ],
    [
      " D$$$D  D$$$D  D",
      "                ",
      "                ",
      " D$$$D  D$$$D  D",
      " $DDD$  $DDD$  $",
      " $DDD$  $DDD$  $",
      " $DDD$  $DDD$  $",
      " D$$$D  D$$$D  D",
      "                ",
      "                ",
      " D$$$D  D$$$D  D",
      " $DDD$  $DDD$  $",
      " $DDD$  $DDD$  $",
      " $DDD$  $DDD$  $",
      " D$$$D  D$$$D  D",
      "                "
    ],
    [
      " DDDDD  DDDDD  D",
      "                ",
      "                ",
      " DDDDD  DDDDD  D",
      " DDDDD  DDDDD  D",
      " DDDDD  DDDDD  D",
      " DDDDD  DDDDD  D",
      " DDDDD  DDDDD  D",
      "                ",
      "                ",
      " DDDDD  DDDDD  D",
      " DDDDD  DDDDD  D",
      " DDDDD  DDDDD  D",
      " DDDDD  DDDDD  D",
      " DDDDD  DDDDD  D",
      "                "
    ],
    [
      " &   &  &   &  &",
      "                ",
      "                ",
      " &   &  &   &  &",
      "                ",
      "                ",
      "                ",
      " &   &  &   &  &",
      "                ",
      "                ",
      " &   &  &   &  &",
      "                ",
      "                ",
      "                ",
      " &   &  &   &  &",
      "                "
    ],
    [
      " DDDDD  DDDDD  D",
      "                ",
      "                ",
      " DDDDD  DDDDD  D",
      " DDDDD  DDDDD  D",
      " DDDDD  DDDDD  D",
      " DDDDD  DDDDD  D",
      " DDDDD  DDDDD  D",
      "                ",
      "                ",
      " DDDDD  DDDDD  D",
      " DDDDD  DDDDD  D",
      " DDDDD  DDDDD  D",
      " DDDDD  DDDDD  D",
      " DDDDD  DDDDD  D",
      "                "
    ],
    [
      " D$$$D  D$$$D  D",
      "                ",
      "                ",
      " D$$$D  D$$$D  D",
      " $EE $  $EE $  $",
      " $   $  $   $  $",
      " $   $  $   $  $",
      " D$$$D  D$$$D  D",
      "                ",
      "                ",
      " D$$$D  D$$$D  D",
      " $EE$$  $EE$$  $",
      " $EE $  $EE $  $",
      " $   $  $   $  $",
      " D$$$D  D$$$D  D",
      "                "
    ]
  ]
}