{
  "xsize": 16,
  "zsize": 16,
  "refpalette": "lostcities:offshore",
  "slices": [
    [
      ".. E  )(*iE     ",
      ".EEEEE=EElEE    ",
      " EEEEE+EE EE    ",
      "   E!    !E     ",
      " EE!EEEEEEEE    ",
      " EE EE EE EE    ",
      "                ",
      "!            !  ",
      "                ",
      "                ",
      "                ",
      "                ",
      "!            !  ",
      " EE EE EE EE    ",
      " EE EE EE EE    ",
      "   !EEEEEE!     "
    ],
    [
      "!!!!!!!!!E!!!!! ",
      "!!!!!!!!!i!!!!! ",
      "!!!!!!!!!l!!!!! ",
      "!!!!!!!!!i!!!!! ",
      "!!!!!!!!!!!!!!! ",
      "!!!!!!!!!!!!!!! ",
      "!!!!!!!!!!!!!!! ",
      "!!!!!!!!!!!!!!! ",
      "!!!!!!!!!!!!!!! ",
      "                ",
      "                ",
      "!!!!!!!!!!!!!!! ",
      "!!!!!!!!!!!!!!! ",
      "!!!!!!!!!!!!!!! ",
      "!!!!!!!!!!!!!!! ",
      "!!!!!!!!!!!!!!! "
    ],
    [
      "...D   .. D     ",
      "  .D      D     ",
      "   !      !     ",
      "    D    D      ",
      "     !DD!       ",
      "                ",
      "                ",
      "                ",
      "                ",
      "                ",
      "                ",
      "                ",
      "                ",
      "                ",
      "                ",
      "    .!DD!       "
    ],
    [
      " ..D      D     ",
      "  .D      D     ",
      "   !      !     ",
      "    D    D      ",
      "     !DD!       ",
      "                ",
      "                ",
      "                ",
      "                ",
      "                ",
      "                ",
      "                ",
      "                ",
      "                ",
      "                ",
      "    .!DD!       "
    ],
    [
      " ..D      D     ",
      "  .D      D     ",
      "   !      !     ",
      "    D    D      ",
      "     !DD!       ",
      "                ",
      "                ",
      "                ",
      "                ",
      "                ",
      "                ",
      "                ",
      "                ",
      "                ",
      "                ",
      "     !DD!       "
    ],
    [
      " ..D      D     ",
      "  .D      D     ",
      "   !      !     ",
      "    D    D      ",
      "     !DD!       ",
      "                ",
      "                ",
      "                ",
      "                ",
      "                ",
      "                ",
      "                ",
      "                ",
      "                ",
      "                ",
      "     !DD!       "
    ]
  ]
}