{
  "xsize": 16,
  "zsize": 16,
  "refpalette": "lostcities:offshore",
  "slices": [
    [
      "                ",
      "                ",
      "    G    G      ",
      "                ",
      "               $",
      "$            $$ ",
      " $          $   ",
      " $          $   ",
      "  $       H$    ",
      "  $H     !I$    ",
      "  $I    !!H$!   ",
      "  $H     !!$    ",
      " $        ! $   ",
      " $          $  #",
      "$            $$!",
      "             #!$"
    ],
    [
      "                ",
      "                ",
      "    G    G      ",
      "                ",
      "               $",
      "$            $$ ",
      " $          $   ",
      " $          $   ",
      "  $       H$    ",
      "  $H     !I$    ",
      "  $I    !!H$!   ",
      "  $H     !!$!!!!",
      " $        !!$!!!",
      " $         !$!! ",
      "$          !!$$!",
      "           !! !$"
    ],
    [
      "!!!!!!!!!!!!!!!!",
      "!!!!!!!!!!!!!!!!",
      "!!!!G!!!!G!!!!!!",
      "!!!!!!!!!!!!!!!!",
      "!!!!!!!!!!!!!!!$",
      "$!!!!!!!!!!!!$$!",
      "!$!!!!!!!!!!$!!!",
      "!$!!!!!!!!!!$!!!",
      "!!$!!!!!!!!$!!!!",
      "!!$!!!!!!!!$!!!!",
      "!!$!!!!!!!!$!!!!",
      "!!$!!!!!!!!$!!!!",
      "!$!!!!!!!!!!$!!!",
      "!$!!!!!!!!!!$!!!",
      "$!!!!!!!!!!!!$$!",
      "!!!!!!!!!!!!!!!$"
    ],
    [
      "       !!       ",
      " !AA! !!!! !AA! ",
      " B  G  !!G B  B ",
      " B  B      B  !!",
      "!!AA!      !A!!$",
      "$!          !$$ ",
      " $!        !$ ! ",
      "!$!!      !!$!!!",
      "!!$!      !$ !!!",
      " !$!      !$  ! ",
      "  $!      !$    ",
      " !$!!     !$AA! ",
      " $!!B     !!$ B ",
      " $! B  !!  !$ B ",
      "$!AA! !!!! !!$$ ",
      "!      !!    !!$"
    ],
    [
      "                ",
      " )((*  !!  )((* ",
      " =  G    G =  = ",
      " =  =      =  = ",
      " +((,      +((,$",
      "$            $$ ",
      " $          $   ",
      " $          $ ! ",
      " !$       H$  ! ",
      "  $H      I$    ",
      "  $I      H$    ",
      " )$H*      $((* ",
      " $  =      =$ = ",
      " $  =      =$ = ",
      "$+((,  !!  +($$ ",
      "               $"
    ],
    [
      "                ",
      " )((*  !!  )((* ",
      " =  G    G =  = ",
      " =  =      =  = ",
      " +((,      +((,$",
      "$            $$ ",
      " $          $   ",
      " $          $ ! ",
      " !$       H$  ! ",
      "  $H      I$    ",
      "  $I      H$    ",
      " )$H*      $((* ",
      " $  =      =$ = ",
      " $  =      =$ = ",
      "$+((,  !!  +($$ ",
      "               $"
    ]
  ]
}