{
  "xsize": 16,
  "zsize": 16,
  "refpalette": "pomkotsmechs:offshore",
  "slices": [
    [
      "                ",
      "                ",
      "                ",
      "                ",
      "                ",
      "                ",
      "                ",
      "                ",
      "          !     ",
      "         !!!    ",
      "        !!!!!   ",
      "         !!!    ",
      "          !     ",
      "    !           ",
      "     $  $      $",
      "                "
    ],
    [
      "                ",
      "                ",
      "                ",
      "                ",
      "                ",
      "                ",
      "                ",
      "                ",
      "          !     ",
      "         !!!    ",
      "        !!!!!   ",
      "         !!!!!!!",
      "          !!!!!!",
      "    !           ",
      "     $$$$$$$$$$$",
      "     $          "
    ],
    [
      "                ",
      "                ",
      "                ",
      "                ",
      "                ",
      "                ",
      "                ",
      "                ",
      "         !!!    ",
      "        !!!!!   ",
      "        !!!!!   ",
      "        !!!!!   ",
      "         !!!!   ",
      "    DDDDDDDDDDDD",
      "    DDDDDDDDDDDD",
      "    DDDDDDDDDDDD"
    ],
    [
      "                ",
      "                ",
      "                ",
      "                ",
      "                ",
      "                ",
      "                ",
      "                ",
      "          !     ",
      "         !!!    ",
      "        !!!!!   ",
      "         !!!!   ",
      "          !     ",
      "    !           ",
      "     $$$$$$$$$$$",
      "     $$$$$$$$$$$"
    ],
    [
      "                ",
      "                ",
      "                ",
      "                ",
      "                ",
      "                ",
      "                ",
      "                ",
      "          !     ",
      "         !!!    ",
      "        !!!!!   ",
      "         !!!!   ",
      "          !     ",
      "    !DDDDDDDDDDD",
      "    D$$$$$$$$$$$",
      "    D$          "
    ],
    [
      "                ",
      "                ",
      "                ",
      "                ",
      "                ",
      "                ",
      "                ",
      "                ",
      "          !     ",
      "         !!!    ",
      "        !!!!!!!!",
      "         !!!    ",
      "          !     ",
      "    !           ",
      "     $  $  $$  $",
      "                "
    ]
  ]
}