{
  "xsize": 16,
  "zsize": 16,
  "refpalette": "lostcities:offshore",
  "slices": [
    [
      "       !!       ",
      " !AA! !!!! !AA! ",
      " B  B  !!  B  B ",
      " B  B      B  B ",
      " !AA!      !AA! ",
      "                ",
      " !            ! ",
      "!!!          !!!",
      "!!!          !!!",
      " !            ! ",
      "                ",
      " !AA!      !AA! ",
      " B  B      B  B ",
      " B  B  !!  B  B ",
      " !AA! !!!! !AA! ",
      "       !!       "
    ],
    [
      "!!!!!!!!!!!!!!!!",
      "!!!!!!!!!!!!!!!!",
      "!!!!!!!!!!!!!!!!",
      "!!!!!!!!!!!!!!!!",
      "!!!!!!!!!!!!!!!!",
      "!!!!!!!!!!!!!!!!",
      "!!!!!!!!!!!!!!!!",
      "!!!!!!!!!!!!!!!!",
      "!!!!!!!!!!!!!!!!",
      "!!!!!!!!!!!!!!!!",
      "!!!!!!!!!!!!!!!!",
      "!!!!!!!!!!!!!!!!",
      "!!!!!!!!!!!!!!!!",
      "!!!!!!!!!!!!!!!!",
      "!!!!!!!!!!!!!!!!",
      "!!!!!!!!!!!!!!!!"
    ],
    [
      "EE EE  &   &  & ",
      "EE EE           ",
      "                ",
      "EE EE           ",
      "EE EE  &   &  & ",
      "     &          ",
      "                ",
      "EE EE  &   &  & ",
      "EE EE           ",
      "                ",
      "EE EE           ",
      "EE EE8 &   &  & ",
      "                ",
      "                ",
      "                ",
      "                "
    ],
    [
      "EE EE  DDDDD  DD",
      "EE EE  DDDDD  DD",
      "       DDDDD  DD",
      "EE EE  DDDDD  DD",
      "EE EE  DDDDD  DD",
      "     &          ",
      "                ",
      "EE EE  DDDDD  DD",
      "EE EE  DDDDD  DD",
      "       DDDDD  DD",
      "EE EE  DDDDD  DD",
      "EE EE  DDDDD  DD",
      "                ",
      "                ",
      "                ",
      "                "
    ],
    [
      "       D$$$D  D$",
      "       $$  $  $ ",
      "       $EE $  $E",
      "       $EE $  $E",
      "       D$$$D  D$",
      "     &          ",
      "                ",
      "       D$$$D  D$",
      "       $$  $  $ ",
      "       $EE $  $E",
      "       $EE $  $E",
      "       D$$$D  D$",
      "                ",
      "                ",
      "                ",
      "                "
    ],
    [
      "!!!!!! D$$$D  D$",
      "!!!!!! $$  $  $ ",
      "!!!!!! $$  $  $ ",
      "!!!!!! $$  $  $ ",
      "!!!!!! D$$$D  D$",
      "!!!!!!          ",
      "!!!!!!          ",
      "!!!!!! D$$$D  D$",
      "!!!!!! $$  $  $ ",
      "!!!!!! $$  $  $ ",
      "!!!!!! $$  $  $ ",
      "!!!!!! D$$$D  D$",
      "                ",
      "                ",
      "                ",
      "                "
    ]
  ]
}