{
  "xsize": 16,
  "zsize": 16,
  "refpalette": "pomkotsmechs:offshore",
  "slices": [
    [
      "$$D .D$$$D  D$$$",
      "DD$ .$DDD$  $DDD",
      "DD$  $DDD$  $DDD",
      "DD$  $DDD$  $DDD",
      "$$D  D$$$D. D$$$",
      "         .      ",
      "                ",
      "$$D  D$$$D  D$$$",
      "DD$  $DDD$  $DDD",
      "DD$  $DDD$   DDD",
      "DD$  $DDD       ",
      "$$D  D$$        ",
      "                ",
      "                ",
      "                ",
      "                "
    ],
    [
      "DDD  DDDDD  DDDD",
      "DDD .DDDDD  DDDD",
      "DDD .DDDDD  DDDD",
      "DDD  DDDDD  DDDD",
      "DDD  DDDDD. DDDD",
      "       ...      ",
      "                ",
      "DDD  DDDDD  DDDD",
      "DDD  DD DD  DDDD",
      "DDD  D          ",
      "DDD  D          ",
      "DDD  DD         ",
      "                ",
      "                ",
      "                ",
      "                "
    ],
    [
      "                ",
      "     .          ",
      "     ..         ",
      "      ..        ",
      "       ...      ",
      "                ",
      "                ",
      "                ",
      "                ",
      "                ",
      "                ",
      "                ",
      "                ",
      "                ",
      "                ",
      "                "
    ],
    [
      "                ",
      "                ",
      "                ",
      "                ",
      "                ",
      "                ",
      "                ",
      "                ",
      "                ",
      "                ",
      "                ",
      "                ",
      "                ",
      "                ",
      "                ",
      "                "
    ],
    [
      "                ",
      "                ",
      "                ",
      "                ",
      "                ",
      "                ",
      "                ",
      "                ",
      "                ",
      "                ",
      "                ",
      "                ",
      "                ",
      "                ",
      "                ",
      "                "
    ],
    [
      "                ",
      "                ",
      "                ",
      "                ",
      "                ",
      "                ",
      "                ",
      "                ",
      "                ",
      "                ",
      "                ",
      "                ",
      "                ",
      "                ",
      "                ",
      "                "
    ]
  ]
}