{
  "xsize": 16,
  "zsize": 16,
  "refpalette": "pomkotsmechs:offshore",
  "slices": [
    [
      "                ",
      "                ",
      "                ",
      "                ",
      "                ",
      "  D   D  D$$$D  ",
      "  $$$$$  $$$$$. ",
      "  $   $  $   $  ",
      "  $   $  $   $  ",
      "  D$$$D .D$$$D  ",
      "       ...      ",
      "       ..       ",
      "  D$$$D  D$$$D  ",
      "  $   $  $   $  ",
      "  $   $  $      ",
      "  $   $  $ ..   "
    ],
    [
      "                ",
      "                ",
      "                ",
      "                ",
      "             .  ",
      "  D   D  D$$$D. ",
      "  $DDD$  $DDD$. ",
      "  $DDD$  $DDD$  ",
      "  $DDD$  $DDD$  ",
      "  D $$D .D$$$D  ",
      "       ....     ",
      "        ..      ",
      "  D $$D  D$$$D  ",
      "  $DDD$  $DDD$  ",
      "  $DDD$  $DDD$  ",
      "  $DDD$  $DDD$  "
    ],
    [
      "                ",
      "                ",
      "                ",
      "                ",
      "             .  ",
      "  D   D  DDDDD. ",
      "     DD  DDDDD. ",
      "     DD  DDDDD  ",
      "     DD .DDDDD  ",
      "     DD .DDDDD  ",
      "        ..      ",
      "                ",
      "     DD  DDDDD  ",
      "     DD  DDDDD  ",
      "     DD  DDDDD  ",
      "     DD  DDDDD  "
    ],
    [
      "                ",
      "                ",
      "                ",
      "                ",
      "                ",
      "             .  ",
      "            ..  ",
      "           ..   ",
      "         ...    ",
      "         .      ",
      "                ",
      "                ",
      "                ",
      "                ",
      "                ",
      "          ..    "
    ],
    [
      "                ",
      "                ",
      "                ",
      "                ",
      "                ",
      "                ",
      "                ",
      "                ",
      "                ",
      "                ",
      "                ",
      "                ",
      "                ",
      "                ",
      "                ",
      "                "
    ],
    [
      "                ",
      "                ",
      "                ",
      "                ",
      "                ",
      "                ",
      "                ",
      "                ",
      "                ",
      "                ",
      "                ",
      "                ",
      "                ",
      "                ",
      "                ",
      "                "
    ]
  ]
}