{
  "xsize": 16,
  "zsize": 16,
  "refpalette": "pomkotsmechs:offshore",
  "slices": [
    [
      "                ",
      "     $          ",
      "                ",
      "                ",
      "     $          ",
      "     $          ",
      "                ",
      "              DD",
      "     $        DD",
      "                ",
      "                ",
      "     $  $  $$  $",
      "    !           ",
      "                ",
      "                ",
      "                "
    ],
    [
      "     $          ",
      "     $          ",
      "     $          ",
      "     $          ",
      "     $          ",
      "     $          ",
      "     $          ",
      "     $          ",
      "     $        DD",
      "     $          ",
      "     $          ",
      "     $$$$$$$$$$$",
      "    !           ",
      "                ",
      "                ",
      "                "
    ],
    [
      "    DDDDDDDDDDDD",
      "    DDDDDDDDDDDD",
      "    DDDDDDDDDDDD",
      "    DDDDDDDDDDDD",
      "    DDDDDDDDDD  ",
      "    DDDDDDDDDD  ",
      "    DDDDDDDDDD  ",
      "    DDDDDDDDDD  ",
      "    DDDDDDDDDD  ",
      "    DDDDDDDDDDDD",
      "    DDDDDDDDDDDD",
      "    DDDDDDDDDDDD",
      "    DDDDDDDDDDDD",
      "                ",
      "                ",
      "                "
    ],
    [
      "     $$$$$$$$$$$",
      "     $$$$$$$$$$$",
      "     $$$$$$$$$$$",
      "     $$$$$$$$$$$",
      "     $$$$$$$$$  ",
      "     $$$$$$$$$  ",
      "     $$$$$$$$$  ",
      "     $$$$$$$$$  ",
      "     $$$$$$$$$  ",
      "     $$$$$$$$$  ",
      "     $$$$$$$$$$$",
      "     $$$$$$$$$$$",
      "    !           ",
      "                ",
      "                ",
      "                "
    ],
    [
      "    D$          ",
      "    D$          ",
      "    D$          ",
      "    D$          ",
      "    D$          ",
      "    D$          ",
      "    D$          ",
      "    D$          ",
      "    D$          ",
      "    D$          ",
      "    D$          ",
      "    D$$$$$$$$$$$",
      "    !DDDDDDDDDDD",
      "                ",
      "                ",
      "                "
    ],
    [
      "                ",
      "     $          ",
      "                ",
      "                ",
      "     $          ",
      "     $          ",
      "                ",
      "                ",
      "     $          ",
      "                ",
      "                ",
      "     $  $  $$  $",
      "    !           ",
      "                ",
      "                ",
      "                "
    ]
  ]
}