{
  "xsize": 16,
  "zsize": 16,
  "refpalette": "pomkotsmechs:offshore",
  "slices": [
    [
      "                ",
      "                ",
      "    G    G      ",
      "                ",
      "               $",
      "$            $$ ",
      " $          $   ",
      " $          $   ",
      "  $       H$    ",
      "  $H      I$    ",
      "  $I      H$    ",
      "  $H       $    ",
      " $          $   ",
      " $          $   ",
      "$            $$ ",
      "               $"
    ],
    [
      "                ",
      "                ",
      "    G    G      ",
      "              !!",
      "!            !!$",
      "$!          !$$ ",
      " $!        !$   ",
      " $!!      !!$   ",
      "  $!      !$    ",
      "  $!      !$    ",
      "  $!      !$    ",
      "  $!      !$    ",
      " $!!      !!$   ",
      " $!        !$   ",
      "$!          !$$ ",
      "!            !!$"
    ],
    [
      "                ",
      "                ",
      "    G    G      ",
      "              !!",
      "!            !!$",
      "$!          !$$ ",
      " $!        !$   ",
      " $!!      !!$   ",
      "  $!      !$    ",
      "  $!      !$    ",
      "  $!      !$    ",
      "  $!      !$    ",
      " $!!      !!$   ",
      " $!        !$   ",
      "$!          !$$ ",
      "!            !!$"
    ],
    [
      "                ",
      "                ",
      "    G    G      ",
      "                ",
      "               $",
      "$            $$ ",
      " $          $   ",
      " $          $   ",
      "  $        $    ",
      "  $       I$    ",
      "  $I       $    ",
      "  $        $    ",
      " $          $   ",
      " $          $   ",
      "$            $$ ",
      "               $"
    ],
    [
      "                ",
      "                ",
      "    G    G      ",
      "                ",
      "               $",
      "$            $$ ",
      " $          $   ",
      " $          $   ",
      "  $        $    ",
      "  $       I$    ",
      "  $I       $    ",
      "  $        $    ",
      " $          $   ",
      " $          $   ",
      "$            $$ ",
      "               $"
    ],
    [
      "                ",
      "                ",
      "    G    G      ",
      "                ",
      "               $",
      "$            $$ ",
      " $          $   ",
      " $          $   ",
      "  $        $    ",
      "  $       I$    ",
      "  $I       $    ",
      "  $        $    ",
      " $          $   ",
      " $          $   ",
      "$            $$ ",
      "               $"
    ]
  ]
}