{
  "xsize": 16,
  "zsize": 16,
  "refpalette": "pomkotsmechs:offshore",
  "slices": [
    [
      "       !! ...   ",
      " !AA! !!!! !AA! ",
      " B  BG !!  B. B ",
      " B  B      BHIH ",
      " !AA!      $$$$ ",
      "         $$    $",
      " !      $     ! ",
      "!!!     $    !!!",
      "!!!   H$     !!!",
      " !    I$      ! ",
      "      H$        ",
      " !AA!  $   !AA! ",
      " B  B   $  B  B ",
      " B  B  !$  B  B ",
      " !AA! !!!$$!AA!$",
      "       !!  $$$$ "
    ],
    [
      "!!!!!!!!!!!!!!!!",
      "!!!!!!!!!!!!!!!!",
      "!!!!!G!!!!!!!!!!",
      "!!!!!!!!!!!!HIH!",
      "!!!!!!!!!!!$$$$!",
      "!!!!!!!!!$$!!!!$",
      "!!!!!!!!$!!!!!!!",
      "!!!!!!!!$!!!!!!!",
      "!!!!!!H$!!!!!!!!",
      "!!!!!!I$!!!!!!!!",
      "!!!!!!H$!!!!!!!!",
      "!!!!!!!$!!!!!!!!",
      "!!!!!!!!$!!!!!!!",
      "!!!!!!!!$!!!!!!!",
      "!!!!!!!!!$$!!!!$",
      "!!!!!!!!!!!$$$$!"
    ],
    [
      "           ..   ",
      "            .   ",
      "     G     ...  ",
      "            HIH ",
      "           $$$$ ",
      "         $$    $",
      "        $       ",
      "        $       ",
      "      H$        ",
      "I     I$        ",
      "      H$        ",
      "       $        ",
      "        $       ",
      "        $       ",
      "         $$    $",
      "           $$$$ "
    ],
    [
      "                ",
      "            ..  ",
      "     GGGGGGGGGGG",
      "     G      HIH ",
      "     G     $$$$ ",
      "     G   $$    $",
      "     G  $       ",
      "     G  $       ",
      "     GH$        ",
      "I    GI$        ",
      "     GH$        ",
      "     G $        ",
      "     G  $       ",
      "     G  $       ",
      "     G   $$    $",
      "     G     $$$$ "
    ],
    [
      "                ",
      "                ",
      "     G      ..  ",
      "            HIH ",
      "           $$$$ ",
      "         $$    $",
      "        $       ",
      "        $       ",
      "      H$        ",
      "I     I$        ",
      "      H$        ",
      "       $        ",
      "        $       ",
      "        $       ",
      "         $$    $",
      "           $$$$ "
    ],
    [
      "                ",
      "                ",
      "     G       .  ",
      "            HIH ",
      "           $$$$ ",
      "         $$    $",
      "        $       ",
      "        $       ",
      "      H$        ",
      "I     I$        ",
      "      H$        ",
      "       $        ",
      "        $       ",
      "        $       ",
      "         $$    $",
      "           $$$$ "
    ]
  ]
}