{
  "xsize": 16,
  "zsize": 16,
  "refpalette": "pomkotsmechs:offshore",
  "slices": [
    [
      "     $          ",
      "     $          ",
      "     $          ",
      "     $          ",
      "     $          ",
      "     $          ",
      "$$$$$$          ",
      "    $           ",
      "     !          ",
      "    !!!         ",
      "   !!!!!        ",
      "    !!!         ",
      "     !          ",
      "#               ",
      "!#              ",
      "#!#             "
    ],
    [
      "     $          ",
      "     $          ",
      "     $          ",
      "     $          ",
      "     $          ",
      "     $          ",
      "$$$$$$          ",
      "    $           ",
      "     !          ",
      "    !!!         ",
      "   !!!!!        ",
      "!!!!!!!         ",
      "!!!!!!          ",
      " !!!!           ",
      "! !!!           ",
      " ! !!           "
    ],
    [
      "     $!!!!!!!!!!",
      "     $!!!!!!!!!!",
      "     $!!!!!!!!!!",
      "     $!!!!!!!!!!",
      "     $!!!!!!!!!!",
      "     $!!!!!!!!!!",
      "$$$$$$!!!!!!!!!!",
      "!!!!$ !!!!!!!!!!",
      "!!!!!!!!!!!!!!!!",
      "!!!!!!!!!!!!!!!!",
      "!!!!!!!!!!!!!!!!",
      "!!!!!!!!!!!!!!!!",
      "!!!!!!!!!!!!!!!!",
      "!!!!!!!!!!!!!!!!",
      "!!!!!!!!!!!!!!!!",
      "!!!!!!!!!!!!!!!!"
    ],
    [
      "     $ !!       ",
      "     $!!!! !AA! ",
      "     $ !!  B  B ",
      "     $     B  B ",
      "     $     !AA! ",
      "     $          ",
      "$$$$$$        ! ",
      "!!! $        !!!",
      "!!!          !!!",
      " !            ! ",
      "                ",
      " !AA!      !AA! ",
      " B  B      B  B ",
      " B  B  !!  B  B ",
      " !AA! !!!! !AA! ",
      "       !!       "
    ],
    [
      "     $          ",
      "     $ !!  )((* ",
      "     $     =  = ",
      "     $     =  = ",
      "     $     +((, ",
      "     $          ",
      "$$$$$$          ",
      " !  $         ! ",
      " !            ! ",
      "                ",
      "                ",
      " )((*      )((* ",
      " =  =      =  = ",
      " =  =      =  = ",
      " +((,  !!  +((, ",
      "                "
    ],
    [
      "     $          ",
      "     $ !!  )((* ",
      "     $     =  = ",
      "     $     =  = ",
      "     $     +((, ",
      "     $          ",
      "$$$$$$          ",
      " !  $         ! ",
      " !            ! ",
      "                ",
      "                ",
      " )((*      )((* ",
      " =  =      =  = ",
      " =  =      =  = ",
      " +((,  !!  +((, ",
      "                "
    ]
  ]
}