{
  "xsize": 16,
  "zsize": 16,
  "refpalette": "lostcities:offshore",
  "slices": [
    [
      "  D$$$D  D$$..  ",
      "           ..   ",
      "         .      ",
      "  D$$$D .D$$    ",
      "  $$$$$. $$$$   ",
      "  $   $  $      ",
      "  $.. $  $      ",
      " .D$$$D  D$$    ",
      " ....           ",
      "  .             ",
      "  D$$$D  D$$    ",
      "  $   $  $      ",
      "  $   $  $      ",
      "  $   $  $   $  ",
      "  D$$$D  D$$$D  ",
      "                "
    ],
    [
      "  D $$D  D$$$D. ",
      "            ..  ",
      "         .      ",
      "    $$D .D$$$   ",
      "  $DDD$..$DDD   ",
      "   DDD$. $DDD   ",
      "   DDD$  $DDD   ",
      "  ..$$D  D$$    ",
      "  . .           ",
      "                ",
      "    $$D  D$$    ",
      "  $DDD$  $DDD   ",
      "  $DDD$  $DDD   ",
      "  $DDD$  $DDD   ",
      "  D$$$D  D$$$D  ",
      "                "
    ],
    [
      "     DD  DDDDD. ",
      "           ...  ",
      "                ",
      "     DD  DDDDD  ",
      "     DD .DDDDD  ",
      "    .DD. DDDDD  ",
      "   .DDD  DDDD   ",
      "    .DD  DDDD   ",
      "                ",
      "                ",
      "     DD  DDD    ",
      "    DDD  DDD    ",
      "  DDDDD  DDDD   ",
      "  DDDDD  DDDDD  ",
      "  DDDDD  DDDDD  ",
      "                "
    ],
    [
      "           ...  ",
      "                ",
      "                ",
      "                ",
      "         ..     ",
      "     ..         ",
      "    ..          ",
      "                ",
      "                ",
      "                ",
      "                ",
      "                ",
      "                ",
      "                ",
      "                ",
      "                "
    ],
    [
      "                ",
      "                ",
      "                ",
      "                ",
      "                ",
      "                ",
      "                ",
      "                ",
      "                ",
      "                ",
      "                ",
      "                ",
      "                ",
      "                ",
      "                ",
      "                "
    ],
    [
      "                ",
      "                ",
      "                ",
      "                ",
      "                ",
      "                ",
      "                ",
      "                ",
      "                ",
      "                ",
      "                ",
      "                ",
      "                ",
      "                ",
      "                ",
      "                "
    ]
  ]
}