{
  "xsize": 16,
  "zsize": 16,
  "refpalette": "pomkotsmechs:offshore",
  "slices": [
    [
      "       !!       ",
      " !AA! !!!! !AA  ",
      " B  B  !!  B    ",
      " B  B      B    ",
      " !AA!      !AA  ",
      "              )*",
      " !            +,",
      "!!!          !!!",
      "!!!          !!!",
      " !            ! ",
      "                ",
      " !AA!      !AA! ",
      " B  B      B  B ",
      " B  B  !!  B  B ",
      " !AA! !!!! !AA! ",
      "       !!       "
    ],
    [
      "DDDDDDDDDDDDDD  ",
      "DDDDDDDDDDDDDD  ",
      "DDDDDDDDDDDDDD  ",
      "DDDDDDDDDDDDDD  ",
      "DDDDDDDDDDDDDD  ",
      "!!!!!!!!!!!!!!)*",
      "!!!!!!!!!!!!!!+,",
      "!!!!!!!!!!!!!!!!",
      "!!!!!!!!!!!!!!!!",
      "!!!!!!!!!!!!!!!!",
      "!!!!!!!!!!!!!!!!",
      "!!!!!!!!!!!!!!!!",
      "!!!!!!!!!!!!!!!!",
      "!!!!!!!!!!!!!!!!",
      "!!!!!!!!!!!!!!!!",
      "!!!!!!!!!!!!!!!!"
    ],
    [
      "              $$",
      "              $$",
      "              $$",
      "              $$",
      "              $$",
      "              $$",
      "              $$",
      "                ",
      "                ",
      "                ",
      "                ",
      "                ",
      "                ",
      "                ",
      "         !AA!   ",
      "         B  B   "
    ],
    [
      "                ",
      "                ",
      "                ",
      "                ",
      "                ",
      "              $$",
      "              $$",
      "                ",
      "                ",
      "                ",
      "                ",
      "                ",
      "                ",
      "                ",
      "         )((*   ",
      "         =  =   "
    ],
    [
      "                ",
      "                ",
      "                ",
      "                ",
      "                ",
      "              $$",
      "              $$",
      "                ",
      "                ",
      "                ",
      "                ",
      "                ",
      "                ",
      "                ",
      "          ?>    ",
      "         f  f   "
    ],
    [
      "                ",
      "                ",
      "                ",
      "                ",
      "                ",
      "              )*",
      "              +,",
      "                ",
      "                ",
      "                ",
      "                ",
      "                ",
      "                ",
      "                ",
      "         )((*   ",
      "         =  =   "
    ]
  ]
}