{
  "xsize": 16,
  "zsize": 16,
  "refpalette": "pomkotsmechs:offshore",
  "slices": [
    [
      "   B  B      .B ",
      "   !AA!       !A",
      "                ",
      "                ",
      "                ",
      "                ",
      "                ",
      "                ",
      "   !AA!       !A",
      "   B  B       B ",
      "   B  B       B ",
      "   !AA!       !A",
      "                ",
      "                ",
      "                ",
      "                "
    ],
    [
      "!!!!!!!!    .!!!",
      "!!!!!!!!     !!!",
      "!!!!!!!!     !!!",
      "!!!!!!!!     !!!",
      "!!!!!!!!     !!!",
      "!!!!!!!!     !!!",
      "!!!!!!!!     !!!",
      "!!!!!!!!     !!!",
      "!!!!!!!!     !!!",
      "!!!!!!!!     !!!",
      "!!!!!!!!     !!!",
      "!!!!!!!!     !!!",
      "!!!!!!!!     !!!",
      "                ",
      "                ",
      "                "
    ],
    [
      "      #     ..# ",
      "      #      .# ",
      "      #       # ",
      "      #       # ",
      "!!    #       # ",
      "!!    #       # ",
      "!     #       # ",
      "      #       # ",
      "      #       # ",
      "      #       # ",
      "     &&&     &&&",
      "#####&!&     &!&",
      "     &&&     &&&",
      "                ",
      "                ",
      "                "
    ],
    [
      "      #     ..# ",
      "      #      .  ",
      "              # ",
      "                ",
      "              # ",
      "9!              ",
      "6!            # ",
      "                ",
      "      #       # ",
      "      #       # ",
      "      &       & ",
      " # ##&!&     &!&",
      "      &       & ",
      "                ",
      "                ",
      "                "
    ],
    [
      "      #      .# ",
      "      #         ",
      "      #       # ",
      "      #         ",
      "      #       # ",
      "=     #         ",
      "6!    #       # ",
      "k!    #         ",
      "      #       # ",
      "      #       # ",
      "                ",
      " # ## !       ! ",
      "                ",
      "                ",
      "                ",
      "                "
    ],
    [
      "      #      .# ",
      "      #       # ",
      "      #       # ",
      "      #       # ",
      "      #       # ",
      "=     #       # ",
      "5     #       # ",
      "!     #       # ",
      "      #       # ",
      "      #       # ",
      "                ",
      "##### !       ! ",
      "                ",
      "                ",
      "                ",
      "                "
    ]
  ]
}