{
  "xsize": 16,
  "zsize": 16,
  "refpalette": "lostcities:offshore",
  "slices": [
    [
      "                ",
      "  $       D$$$D ",
      "          $   $ ",
      "     !    $   $ ",
      "  $ !!!   $   $ ",
      "  $!!!!!  D$$$D ",
      "    !!!         ",
      "     !          ",
      "  $             ",
      "                ",
      "                ",
      "  $             ",
      "                ",
      "                ",
      "                ",
      "                "
    ],
    [
      "$$$             ",
      "$$$       D$$$D ",
      "$$$       $DDD$ ",
      "$$$  !    $DDD$ ",
      "$$$ !!!   $DDD$ ",
      "$$$!!!!!  D$$$D ",
      "$$$ !!!         ",
      "$$$  !          ",
      "$$$             ",
      "$$$             ",
      "$$$             ",
      "$$$             ",
      "                ",
      "                ",
      "                ",
      "                "
    ],
    [
      "DDD  !          ",
      "DDD  !    DDDDD ",
      "DDD  !    DDDDD ",
      "DDD !!!   DDDDD ",
      "DDD!!!!!  DDDDD ",
      "DDD!!!!!  DDDDD ",
      "DDD!!!!!        ",
      "DDD !!!         ",
      "DDD             ",
      "DDD             ",
      "DDD             ",
      "DDD             ",
      "DDD             ",
      "                ",
      "                ",
      "                "
    ],
    [
      "$$$             ",
      "$$$             ",
      "$$$             ",
      "$$$  !          ",
      "$$$ !!!         ",
      "$$$!!!!!        ",
      "$$$ !!!         ",
      "$$$  !          ",
      "$$$             ",
      "$$$             ",
      "$$$             ",
      "$$$             ",
      "                ",
      "                ",
      "                ",
      "                "
    ],
    [
      "  $             ",
      "  $             ",
      "  $             ",
      "  $  !          ",
      "  $ !!!         ",
      "  $!!!!!        ",
      "  $ !!!         ",
      "  $  !          ",
      "  $             ",
      "  $             ",
      "  $             ",
      "$$$             ",
      "DD              ",
      "                ",
      "                ",
      "                "
    ],
    [
      "     !          ",
      "  $  !          ",
      "     !          ",
      "     !          ",
      "  $ !!!         ",
      "  $!!!!!        ",
      "    !!!         ",
      "     !          ",
      "  $             ",
      "                ",
      "                ",
      "  $             ",
      "                ",
      "                ",
      "                ",
      "                "
    ]
  ]
}