{
  "xsize": 16,
  "zsize": 16,
  "refpalette": "lostcities:offshore",
  "slices": [
    [
      "                ",
      "                ",
      "                ",
      "                ",
      "                ",
      "                ",
      "                ",
      "                ",
      "                ",
      "                ",
      "                ",
      "                ",
      "!               ",
      " !!            !",
      "   !!     .  !! ",
      "   ! !!!!!!!! ! "
    ],
    [
      "mmmmmmmmmmmmmmmm",
      "mmmmmmmmmmmmmmmm",
      "mmmmmmmmmmmmmmmm",
      "mmmmmmmmmmmmmmmm",
      "mmmmmmmmmmmmmmmm",
      "mmmmmmmmmmmmmmmm",
      "mmmmmmmmmmmmmmmm",
      "mmmmmmmmmmmmmmmm",
      "mmmmmmmmmmmmmmmm",
      "mmmmmmmmmmmmmmmm",
      "mmmmmmmmmmmmmmmm",
      "mmmmmmmmmmmmmmmm",
      "!mmmmmmmmmmmmmmm",
      " !!mmmmmmmmmmmm!",
      "   !!mmmmmmmm!! ",
      "   ! !!!!!!!! ! "
    ],
    [
      "                ",
      "                ",
      "                ",
      "                ",
      ".               ",
      ".               ",
      "                ",
      "                ",
      "                ",
      "                ",
      "                ",
      "m               ",
      " mm            m",
      "   mm     .  mm ",
      "     mmmmmmmm   ",
      "   !      .   ! "
    ],
    [
      "                ",
      "                ",
      "                ",
      "                ",
      "                ",
      ".               ",
      "                ",
      "                ",
      "                ",
      "                ",
      "                ",
      "m               ",
      " mm            m",
      "   mm     .  mm ",
      "     mmmmmmmm   ",
      "   !      .   ! "
    ],
    [
      "                ",
      "                ",
      "                ",
      "                ",
      "                ",
      "                ",
      "                ",
      "                ",
      "                ",
      "                ",
      "                ",
      "m               ",
      " mm            m",
      "   mm     .  mm ",
      "     mmmmmmmm   ",
      "   !      .   ! "
    ],
    [
      "                ",
      "                ",
      "                ",
      "                ",
      "                ",
      "                ",
      "                ",
      "                ",
      "                ",
      "                ",
      "                ",
      "m               ",
      " mm            m",
      "   mm     .. mm ",
      "     mmmmmmmm   ",
      "   !      ..  ! "
    ]
  ]
}