{
  "xsize": 16,
  "zsize": 16,
  "refpalette": "pomkotsmechs:offshore",
  "slices": [
    [
      "                ",
      "  )((*  !!  )((*",
      "  =  =      =  =",
      "  =  =      =  =",
      "  +((,      +((,",
      "                ",
      "                ",
      "  !            !",
      "  !  !         !",
      "    !!!         ",
      "   !!!!!        ",
      "  )((*!     )((*",
      "  =  =      =  =",
      "  =  =      =  =",
      "! +((,  !!  +((,",
      " !              "
    ],
    [
      "        !!      ",
      "  !AA! !!!! !AA!",
      "  B  B  !!  B  B",
      "  B  B      B  B",
      "  !AA!      !AA!",
      "                ",
      "  !            !",
      "!!!!          !!",
      "!!!! !        !!",
      "  ! !!!        !",
      "   !!!!!        ",
      "  !AA!!     !AA!",
      "  B  B      B  B",
      "  B  B  !!  B  B",
      "! !AA! !!!! !AA!",
      " !      !!      "
    ],
    [
      "!!!!!!!!!!!!!!!!",
      "!!!!!!!!!!!!!!!!",
      "!!!!!!!!!!!!!!!!",
      "!!!!!!!!!!!!!!!!",
      "!!!!!!!!!!!!!!!!",
      "!!!!!!!!!!!!!!!!",
      "$$$$$$$$$$$$$$$$",
      "$$$$$$$$$$$$$$$$",
      "$$$$$$$$$$$$$$$$",
      "$$$$$$$$$$$$$$$$",
      "$$$$$$$$$$$$$$$$",
      "$$$$$$$$$$$$$$$$",
      "$$$$$$$$$$$$$$$$",
      "$$$$$$$$$$$$$$$$",
      "$$$$$$$$$$$$$$$$",
      "$$$$$$$$$$$$$$$$"
    ],
    [
      "          &   & ",
      "                ",
      "                ",
      "          &   & ",
      "                ",
      "                ",
      "                ",
      "          &   & ",
      "     !          ",
      "    !!!         ",
      "   !!!!!  &   & ",
      "    !!!         ",
      "     !          ",
      "  D             ",
      "$$$       &   & ",
      "$$$             "
    ],
    [
      "          DDDDD ",
      "                ",
      "                ",
      "          DDDDD ",
      "          DDDDD ",
      "          DDDDD ",
      "          DDDDD ",
      "          DDDDD ",
      "     !          ",
      "    !!!         ",
      "   !!!!!  DDDDD ",
      "    !!!   DDDDD ",
      "     !    DDDDD ",
      "DDD       DDDDD ",
      "$$$       DDDDD ",
      "  $             "
    ],
    [
      "          D$$$D ",
      "                ",
      "                ",
      "          D$$$D ",
      "          $EE $ ",
      "          $   $ ",
      "          $   $ ",
      "          D$$$D ",
      "     !          ",
      "    !!!         ",
      "!!!!!!!!  D$$$D ",
      "    !!!   $EE$$ ",
      "     !    $EE $ ",
      "     !    $   $ ",
      "  $  !    D$$$D ",
      "     !          "
    ]
  ]
}