{
  "xsize": 16,
  "zsize": 16,
  "refpalette": "pomkotsmechs:offshore",
  "slices": [
    [
      " !A    !!       ",
      "DB A! !!!! !AA! ",
      "DB  B  !!  B  B ",
      "D!A B      B  B ",
      "D  A!      !AA! ",
      "D               ",
      "D!A           ! ",
      "DB           !!!",
      "DB           !!!",
      " !A           ! ",
      "                ",
      " ! A!      !AA! ",
      "!!! B           ",
      " B  B  !!  B  B ",
      " !AA! !!!! !AA! ",
      "       !!       "
    ],
    [
      "!!!!!!!!!!!!!!!!",
      "!!!!!!!!!!!!!!!!",
      "D!!!!!!!!!!!!!!!",
      "!!!!!!!!!!!!!!!!",
      "!!!!!!!!!!!!!!!!",
      "!!!!!!!!!!!!!!!!",
      "!!!!!!!!!!!!!!!!",
      "D!!!!!!!!!!!!!!!",
      "!!!!!!!!!!!!!!!!",
      "!!!!!!!!!!!!!!! ",
      "!!!!!!!!!!!!!!  ",
      "!!!!!!!!!!      ",
      "!!!!!!!!!       ",
      "!!!!!!!!!       ",
      "!!!!!!!!!!     !",
      "!!!!!!!!!!!!!!!!"
    ],
    [
      "DDD             ",
      "DDD             ",
      "DDD             ",
      "DDD             ",
      "DDD             ",
      "DDD             ",
      "DDD             ",
      "DDD             ",
      "DDD             ",
      "DDD             ",
      "DDD             ",
      "DDD             ",
      "                ",
      "                ",
      "                ",
      "                "
    ],
    [
      "  =             ",
      "  =             ",
      "D =             ",
      "D =             ",
      "  =             ",
      "  =             ",
      "D =             ",
      "D =             ",
      "  =             ",
      "  =             ",
      "  =             ",
      "(($             ",
      "                ",
      "                ",
      "                ",
      "                "
    ],
    [
      "                ",
      "                ",
      "D               ",
      "D               ",
      "                ",
      "                ",
      "D               ",
      "D               ",
      "                ",
      "                ",
      "                ",
      "                ",
      "                ",
      "                ",
      "                ",
      "                "
    ],
    [
      "                ",
      "                ",
      "                ",
      "                ",
      "                ",
      "                ",
      "                ",
      "                ",
      "                ",
      "                ",
      "                ",
      "                ",
      "                ",
      "                ",
      "                ",
      "                "
    ]
  ]
}