{
  "xsize": 16,
  "zsize": 16,
  "refpalette": "pomkotsmechs:offshore",
  "slices": [
    [
      "         B  B   ",
      "         !AA!   ",
      "                ",
      "                ",
      "                ",
      "                ",
      "             !  ",
      "        .    !  ",
      "       ..!AA!   ",
      "        .B  B   ",
      "         B  B   ",
      "         !AA!   ",
      "                ",
      "                ",
      "                ",
      "                "
    ],
    [
      "        !!!!!!!!",
      "        !!!!!!!!",
      "        !!!!!!!!",
      "        !!!!!!!!",
      "        !!!!! !!",
      "        !!!!! ! ",
      "        !!!!! !!",
      "        !!!!!!!!",
      "       .!!!!!!!!",
      "        !!!!!!!!",
      "        !!!!!!!!",
      "        !!!!!!!!",
      "        !!!!!!!!",
      "                ",
      "                ",
      "                "
    ],
    [
      "         #      ",
      "         #      ",
      "         #      ",
      "         #      ",
      "         #     (",
      "         #      ",
      "         #      ",
      "        .#      ",
      "       ..#.     ",
      "        .#      ",
      "        &&&     ",
      "        &!&#####",
      "        &&&     ",
      "                ",
      "                ",
      "                "
    ],
    [
      "         #      ",
      "                ",
      "         #      ",
      "                ",
      "         #      ",
      "                ",
      "         #      ",
      "         .      ",
      "        .#.     ",
      "         #      ",
      "         &      ",
      "        &!&# # #",
      "         &      ",
      "                ",
      "                ",
      "                "
    ],
    [
      "         #      ",
      "                ",
      "         #      ",
      "                ",
      "         #      ",
      "                ",
      "         #      ",
      "         .      ",
      "        .#.     ",
      "        .#      ",
      "                ",
      "         ! # # #",
      "                ",
      "                ",
      "                ",
      "                "
    ],
    [
      "         #      ",
      "         #      ",
      "         #      ",
      "         #      ",
      "         #      ",
      "         #      ",
      "         #      ",
      "        .#     k",
      "       ..#.     ",
      "       ..#      ",
      "        .       ",
      "         ! #####",
      "                ",
      "                ",
      "                ",
      "                "
    ]
  ]
}