{
  "xsize": 16,
  "zsize": 16,
  "refpalette": "pomkotsmechs:offshore",
  "slices": [
    [
      " )*           / ",
      " +,           / ",
      "              / ",
      "              / ",
      "              / ",
      "              / ",
      "              / ",
      "              / ",
      "              !!",
      "              ! ",
      "             !!!",
      "              / ",
      "              / ",
      "              / ",
      "              / ",
      "              / "
    ],
    [
      " )*           / ",
      " +,           / ",
      "              / ",
      "              / ",
      "              / ",
      "              / ",
      "              / ",
      "              / ",
      "              !!",
      "              ! ",
      "             !!!",
      "              / ",
      "              / ",
      "              / ",
      "              / ",
      "              / "
    ],
    [
      " )*           / ",
      " +,           / ",
      "              / ",
      "              / ",
      "              / ",
      "              / ",
      "              / ",
      "              / ",
      "              !!",
      "              ! ",
      "             !!!",
      "              / ",
      "              / ",
      "              / ",
      "              / ",
      "              / "
    ],
    [
      " )*           / ",
      " +,           / ",
      "              / ",
      "              / ",
      "              / ",
      "              / ",
      "              / ",
      "              / ",
      "              !!",
      "              ! ",
      "             !!!",
      "              / ",
      "              / ",
      "              / ",
      "              / ",
      "              / "
    ],
    [
      " $$           / ",
      " $$           / ",
      "              / ",
      "              / ",
      "              / ",
      "              / ",
      "              / ",
      "              / ",
      "              !!",
      "              ! ",
      "             !!!",
      "              / ",
      "              / ",
      "              / ",
      "              / ",
      "              / "
    ],
    [
      "9$$$$$$$$$$$$$/ ",
      "9$$$$$$$$$$$$$/ ",
      "9$$6666666666,/ ",
      "9$$           / ",
      "9$$           / ",
      "9$$           / ",
      "9$$           / ",
      "9$$           / ",
      "9$$           !!",
      "9$$           ! ",
      "9$$          !!!",
      "9$$           / ",
      "9$$           / ",
      "9$$           / ",
      "9$$           / ",
      "9$$           / "
    ]
  ]
}