{
  "xsize": 16,
  "zsize": 16,
  "refpalette": "pomkotsmechs:offshore",
  "slices": [
    [
      "                ",
      "                ",
      "     G       .  ",
      "            HIH ",
      "           $$$$ ",
      "         $$    $",
      "        $       ",
      "        $       ",
      "      H$        ",
      "      I$        ",
      "      H$        ",
      "       $        ",
      "        $       ",
      "        $       ",
      "         $$    $",
      "           $$$$ "
    ],
    [
      "                ",
      "                ",
      "     G       .  ",
      "            HIH ",
      "           $$$$ ",
      "         $$    $",
      "        $       ",
      "        $       ",
      "      H$        ",
      "      I$        ",
      "      H$        ",
      "       $        ",
      "        $       ",
      "        $       ",
      "         $$    $",
      "           $$$$ "
    ],
    [
      "                ",
      "                ",
      "     G      ..  ",
      "          !!!!!!",
      "         !!$$$$!",
      "        !$$    $",
      "       !$       ",
      "      !!$       ",
      "      !$        ",
      "      !$        ",
      "      !$        ",
      "      !$        ",
      "      !!$       ",
      "       !$       ",
      "        !$$    $",
      "         !!$$$$!"
    ],
    [
      "                ",
      "                ",
      "     G      .   ",
      "          !!!!!!",
      "         !!$$$$!",
      "        !$$    $",
      "       !$       ",
      "      !!$       ",
      "      !$        ",
      "      !$        ",
      "      !$        ",
      "      !$        ",
      "      !!$       ",
      "       !$       ",
      "        !$$    $",
      "         !!$$$$!"
    ],
    [
      "                ",
      "                ",
      "     G      ..  ",
      "           .HIH ",
      "           $$$$ ",
      "         $$    $",
      "        $       ",
      "        $       ",
      "      H$        ",
      "      I$        ",
      "      H$        ",
      "       $        ",
      "        $       ",
      "        $       ",
      "         $$    $",
      "           $$$$ "
    ],
    [
      "                ",
      "                ",
      "     G       .  ",
      "            HIH ",
      "           $$$$ ",
      "         $$    $",
      "        $       ",
      "        $       ",
      "      H$        ",
      "      I$        ",
      "      H$        ",
      "       $        ",
      "        $       ",
      "        $       ",
      "         $$    $",
      "           $$$$ "
    ]
  ]
}