{
  "xsize": 16,
  "zsize": 16,
  "refpalette": "pomkotsmechs:offshore",
  "slices": [
    [
      "           HIH  ",
      "     G          ",
      "                ",
      "                ",
      "                ",
      "                ",
      "                ",
      "                ",
      "                ",
      "                ",
      "                ",
      "                ",
      "                ",
      "                ",
      "                ",
      "                "
    ],
    [
      "           HIH  ",
      "     G          ",
      "                ",
      "                ",
      "                ",
      "                ",
      "                ",
      "                ",
      "                ",
      "                ",
      "                ",
      "                ",
      "                ",
      "                ",
      "                ",
      "                "
    ],
    [
      "!!!!!!!!!!!!!!!!",
      "!!!!!G!!!!!!!!!!",
      "!!!!!!!!!!!!!!!!",
      "!!!!!!!!!!!!!!!!",
      "!!!!!!!!!!!!!!!!",
      "!!!!!!!!!!!!!!!!",
      "!!!!!!!!!!!!!!!!",
      "!!!!!!!!!!!!!!!!",
      "!!!!!!!!!!!!!!!!",
      "!!!!!!!!!!!!!!!!",
      "!!!!!!!!!!!!!!!!",
      "!!!!!!!!!!!!!!!!",
      "!!!!!!!!!!!!!!!!",
      "!!!!!!!!!!!!!!!!",
      "!!!!!!!!!!!!!!!!",
      "!!!!!!!!!!!!!!!!"
    ],
    [
      "       !! !!!!!!",
      " !AA!G!!!! !AA! ",
      " B  B  !!  B  B ",
      " B  B      B  B ",
      " !AA!      !AA! ",
      "                ",
      " !            ! ",
      "!!!          !!!",
      "!!!          !!!",
      " !            ! ",
      "                ",
      " !AA!      !AA! ",
      " B  B      B  B ",
      " B  B  !!  B  B ",
      " !AA! !!!! !AA! ",
      "       !!       "
    ],
    [
      "           HIH  ",
      " )((*G !!  )((* ",
      " =  =      =  = ",
      " =  =      =  = ",
      " +((,      +((, ",
      "                ",
      "                ",
      " !            ! ",
      " !            ! ",
      "                ",
      "                ",
      " )((*      )((* ",
      " =  =      =  = ",
      " =  =      =  = ",
      " +((,  !!  +((, ",
      "                "
    ],
    [
      "           HIH  ",
      " )((*G !!  )((* ",
      " =  =      =  = ",
      " =  =      =  = ",
      " +((,      +((, ",
      "                ",
      "                ",
      " !            ! ",
      " !            ! ",
      "                ",
      "                ",
      " )((*      )((* ",
      " =  =      =  = ",
      " =  =      =  = ",
      " +((,  !!  +((, ",
      "                "
    ]
  ]
}