{
  "xsize": 16,
  "zsize": 16,
  "refpalette": "pomkotsmechs:offshore",
  "slices": [
    [
      "       !!       ",
      " !AA! !!!! !AA! ",
      " B  B  !G  B  B ",
      "HIH B      B  B ",
      "$$$A!      !AA! ",
      "   $$           ",
      " !   $        ! ",
      "!!!  $       !!!",
      "!!!   $      !!!",
      " !    $H      ! ",
      "      $I        ",
      " !AA! $H   !AA! ",
      " B  B$     B  B ",
      " B  B$ !!  B  B ",
      " !A$$ !!!! !AA! ",
      "$$$    !!       "
    ],
    [
      "!!!!!!!!!!!!!!!!",
      "!!!!!!!!!!!!!!!!",
      "!!!!!!!!G!!!!!!!",
      "HIH!!!!!!!!!!!!!",
      "$$$!!!!!!!!!!!!!",
      "!!!$$!!!!!!!!!!!",
      "!!!!!$!!!!!!!!!!",
      "!!!!!$!!!!!!!!!!",
      "!!!!!!$!!!!!!!!!",
      "!!!!!!$H!!!!!!!!",
      "!!!!!!$I!!!!!!!!",
      "!!!!!!$H!!!!!!!!",
      "!!!!!$!!!!!!!!!!",
      "!!!!!$!!!!!!!!!!",
      "!!!$$!!!!!!!!!!!",
      "$$$!!!!!!!!!!!!!"
    ],
    [
      "                ",
      "                ",
      "        G       ",
      "HIH             ",
      "$$$             ",
      "   $$           ",
      "     $          ",
      "     $  .       ",
      "      $..       ",
      "      $H.       ",
      "      $I.       ",
      "      $H        ",
      "     $          ",
      "     $          ",
      "   $$           ",
      "$$$             "
    ],
    [
      "                ",
      "                ",
      "GGGGGGGGG       ",
      "HIH     G       ",
      "$$$     G       ",
      "   $$   G       ",
      "     $  G       ",
      "     $ .G.      ",
      "      $.G.      ",
      "      $HG.      ",
      "      $IG       ",
      "      $HG       ",
      "     $  G       ",
      "     $  G       ",
      "   $$   G       ",
      "$$$     G       "
    ],
    [
      "                ",
      "                ",
      "        G       ",
      "HIH             ",
      "$$$             ",
      "   $$           ",
      "     $          ",
      "     $  .       ",
      "      $..       ",
      "      $H.       ",
      "      $I        ",
      "      $H        ",
      "     $          ",
      "     $          ",
      "   $$           ",
      "$$$             "
    ],
    [
      "                ",
      "                ",
      "        G       ",
      "HIH             ",
      "$$$             ",
      "   $$           ",
      "     $          ",
      "     $ .        ",
      "      $..       ",
      "      $H.       ",
      "      $I        ",
      "      $H        ",
      "     $          ",
      "     $          ",
      "   $$           ",
      "$$$             "
    ]
  ]
}