{
  "xsize": 16,
  "zsize": 16,
  "refpalette": "pomkotsmechs:offshore",
  "slices": [
    [
      " EEEEE EE!EE    ",
      " EEEEE EE EE    ",
      "   E  )(*iE     ",
      " EEEEE=EElEE    ",
      " EEEEE+EE EE    ",
      ".  E!    !E     ",
      ".EE!EEEEEEEE    ",
      " EE EE EE EE    ",
      "                ",
      "!            !  ",
      "                ",
      "                ",
      "                ",
      "                ",
      "                ",
      "                "
    ],
    [
      " EE!EEEEEEEE    ",
      " EE!EEEEEEEE    ",
      "   !EE)(*E!     ",
      " EE!EE=EEiEE    ",
      " EE!EE+EElEE    ",
      "   !EEEEE&!     ",
      ".EE!EE!EE!EE    ",
      " EE EE EE EE    ",
      "&            &  ",
      "!&          &!& ",
      "&            &  ",
      "                ",
      "                ",
      "                ",
      "                ",
      "                "
    ],
    [
      "!!!!!!!!!!!!!!! ",
      "!!!!!!!!!E!!!!! ",
      "!!!!!!!!!E!!!!! ",
      "!!!!!!!E!E!!!!! ",
      "!!!!!!!!!i!!!!! ",
      "!!!!!!!jkI!!!!! ",
      "!!!!!!!!!!!!!!! ",
      "!!!!!!!!!!!!!!! ",
      "!!!!!!!!!!!!!!! ",
      "!!!!!!!!!!!!!!! ",
      "!!!!!!!!!!!!!!! ",
      "                ",
      "                ",
      "                ",
      "                ",
      "                "
    ],
    [
      " !!E!!!!!!!!    ",
      " !!E!!h!!!!!    ",
      "  !E!!!!!!E!    ",
      " !!E!!=!!!!!    ",
      " !!E!!!!!!!!    ",
      ". !E!!!!!!E!    ",
      " !!E!!E!!E!!    ",
      "!!!!!!!!!!!!    ",
      "&&          &&& ",
      "!&          &!& ",
      "&&          &&& ",
      "                ",
      "                ",
      "                ",
      "                ",
      "                "
    ],
    [
      " EEEEE EEDEE    ",
      " EEEEE EE EE    ",
      "   E  )(* E     ",
      " EEEEE=EE EE    ",
      " EEEEE+EE EE    ",
      ".  ED    DE     ",
      " EEEEEEEEEEE    ",
      " EE EE EE EE    ",
      "&            &  ",
      "!&          &!& ",
      "&            &  ",
      "                ",
      "                ",
      "                ",
      "                ",
      "                "
    ],
    [
      " EEEEE!EE!EE    ",
      " EEEEE!EEIEE    ",
      "  !E!!)(*lE!    ",
      " EEEEE=EE!EE    ",
      " EEEEEgEE!EE    ",
      ". !E!!!!!!E!    ",
      " EEEEEEEEEEE    ",
      " EE!EE!EE!EE    ",
      "                ",
      "!            !  ",
      "                ",
      "                ",
      "                ",
      "                ",
      "                ",
      "                "
    ]
  ]
}