{
  "xsize": 16,
  "zsize": 16,
  "refpalette": "lostcities:offshore",
  "slices": [
    [
      " B      B  B    ",
      "A!      !AA!    ",
      "                ",
      "                ",
      "                ",
      "            .   ",
      "  !        ...  ",
      "  !         .   ",
      "A!      !AA!    ",
      " B      B  B    ",
      " B      B  B    ",
      "A!      !AA!    ",
      "                ",
      "                ",
      "                ",
      "                "
    ],
    [
      "!!!!!!!!!!!!!   ",
      "!!!!!!!!!!!!!   ",
      "!!!!!!!!!!!!!   ",
      "!!!!!!!!!!!!!   ",
      "!! !!!!!!!!!!   ",
      "!! ! !!!!!!!!   ",
      "!! !!!!!!!!!!.  ",
      "!!!!!!!!!!!!!   ",
      "!!!!!!!!!!!!!   ",
      "!!!!!!!!!!!!!   ",
      "!!!!!!!!!!!!!   ",
      "!!!!!!!!!!!!!   ",
      "!!!!!!!!!!!!!   ",
      "                ",
      "                ",
      "                "
    ],
    [
      "           #    ",
      "           #    ",
      "           #    ",
      "           #    ",
      "    (!!    #    ",
      "     !!    #.   ",
      "     !    .#..  ",
      "           #.   ",
      "           #    ",
      "           #    ",
      "          &&&   ",
      "##########&!&   ",
      "          &&&   ",
      "                ",
      "                ",
      "                "
    ],
    [
      "           #    ",
      "           #    ",
      "                ",
      "                ",
      "                ",
      "     9!    ..   ",
      "     6!   ...   ",
      "           .    ",
      "           #    ",
      "           #    ",
      "           &    ",
      "# # # # ##&!&   ",
      "           &    ",
      "                ",
      "                ",
      "                "
    ],
    [
      "           #    ",
      "           #    ",
      "           #    ",
      "           #    ",
      "           #.   ",
      "     =     #..  ",
      "     6!   .#..  ",
      "     k!    #.   ",
      "           #    ",
      "           #    ",
      "                ",
      "# # # # ## !    ",
      "                ",
      "                ",
      "                ",
      "                "
    ],
    [
      "           #    ",
      "           #    ",
      "           #    ",
      "           #    ",
      "           #.   ",
      "     =     #..  ",
      "     5     #.   ",
      "    k!     #    ",
      "           #    ",
      "           #    ",
      "                ",
      "########## !    ",
      "                ",
      "                ",
      "                ",
      "                "
    ]
  ]
}