{
  "xsize": 16,
  "zsize": 16,
  "refpalette": "pomkotsmechs:offshore",
  "slices": [
    [
      "       !!       ",
      " !AA! !!!! !AA! ",
      " B  B  !!  B  B ",
      " B  B      B  B ",
      " !AA!      !AA! ",
      "                ",
      " !            ! ",
      "!!!          !!!",
      "!!!          !!!",
      " !            ! ",
      "                ",
      " !AA!      !AA! ",
      " B  B      B  B ",
      " B  B  !!  B  B ",
      " !AA! !!!! !AA! ",
      "       !!       "
    ],
    [
      "$$!!!!!!!!!!!!!!",
      "$$!!!!!!!!!!!!!!",
      "$$!!!!!!!!!!!!!!",
      "$$!!!!!!!!!!!!!!",
      "$$!!!!!!!!!!!!!!",
      "$$!!!!!!!!!!!!!!",
      "$$!!!!!!!!!!!!!!",
      "$$!!!!!!!!!!!!!!",
      "$$!!!!!!!!!!!!!!",
      "$$!!!!!!!!!!!!!!",
      "$$!!!!!!!!!!!!!!",
      "$$!!!!!!!!!!!!!!",
      "$$!!!!!!!!!!!!!!",
      "$$!!!!!!!!!!!!!!",
      "$$!!!!!!!!!!!!!!",
      "$$!!!!!!!!!!!!!!"
    ],
    [
      "                ",
      "                ",
      "                ",
      "                ",
      "                ",
      "                ",
      "                ",
      "                ",
      "                ",
      "!!!!!!!!!!!!!!! ",
      "!!!!!!!!!!!!!!! ",
      "!!!!!!!!!!!!!!! ",
      "!!!!!!!!!!!!!!! ",
      "!!!!!!!!!!!!!!! ",
      "!!!!!!!!!!!!!!! ",
      "!!!!!!!!!E!!!!! "
    ],
    [
      "                ",
      "                ",
      "                ",
      "                ",
      "                ",
      "                ",
      "                ",
      "                ",
      "                ",
      "&&          &&& ",
      "!&          &!& ",
      "&!! !! !! !!&&& ",
      " !!!!!!!!!!!    ",
      "  !EEEEEEEE!    ",
      " !!E!!!!!!!!    ",
      " !!E!!h!!!!!    "
    ],
    [
      "                ",
      "                ",
      "                ",
      "                ",
      "                ",
      "                ",
      "                ",
      "                ",
      "                ",
      "&            &  ",
      "!&          &!& ",
      "&EE EE EE EE &  ",
      " EE EE EE EE    ",
      "   EEEEEEEE     ",
      " EEEEE EE EE    ",
      " EEEEE EE EE    "
    ],
    [
      "                ",
      "                ",
      "                ",
      "                ",
      "                ",
      "                ",
      "                ",
      "                ",
      "                ",
      "                ",
      "!            !  ",
      " EE EE EE EE    ",
      " EE!EE!EE!EE    ",
      "  !EEEEEEEE!    ",
      " EEEEE!EE!EE    ",
      " EEEEE!EEIEE    "
    ]
  ]
}