{
  "xsize": 16,
  "zsize": 16,
  "refpalette": "lostcities:offshore",
  "slices": [
    [
      "      !!        ",
      " !A! !!!! !AA! !",
      " B B  !!  B  B B",
      " B B      B  B B",
      " !A!      !AA! !",
      "                ",
      " !           !!!",
      "!!!          !!!",
      "!!!          !!!",
      " !            ! ",
      "                ",
      " !AA!      !AA! ",
      " B  B      B  B ",
      " B        .. !!!",
      " !AA       .  ! ",
      "                "
    ],
    [
      "!!DDDDDDDDDDDDDD",
      "!!DDDDDDDDDDDDDD",
      "!!DDDDDDDDDDDDDD",
      "!!DDDDDDDDDDDDDD",
      "!!DDDDDDDDDDDDDD",
      "!!!!!!!!!!!!!!!!",
      "!!!!!!!!!!!!!!!!",
      "!!!!!!!!!!!!!!!!",
      "!!!!!!!!!!!!!!!!",
      "!!!!!!!!!!!!!!!!",
      "!!!!!!!!!!!!!!!!",
      "!!!!!!!!!!!!!!!!",
      "!!!!!!!!!!!!!!!!",
      "!!!!!!!!!!!!!!!!",
      "!!!!!!!!!!!!!!!!",
      "!!!!!!!!!!!!!!!!"
    ],
    [
      "                ",
      "                ",
      "                ",
      "                ",
      "                ",
      "                ",
      "                ",
      "                ",
      "                ",
      "                ",
      "                ",
      "                ",
      "                ",
      "          ..    ",
      "     DDDDDDDDDDD",
      "     DDDDDDDDDDD"
    ],
    [
      "                ",
      "                ",
      "                ",
      "                ",
      "                ",
      "                ",
      "                ",
      "                ",
      "                ",
      "                ",
      "                ",
      "                ",
      "                ",
      "           .    ",
      "     $((((((((((",
      "     =     .    "
    ],
    [
      "                ",
      "                ",
      "                ",
      "                ",
      "                ",
      "                ",
      "                ",
      "                ",
      "                ",
      "                ",
      "                ",
      "                ",
      "                ",
      "          ..    ",
      "         ....   ",
      "          ..    "
    ],
    [
      "                ",
      "                ",
      "                ",
      "                ",
      "                ",
      "                ",
      "                ",
      "                ",
      "                ",
      "                ",
      "                ",
      "                ",
      "                ",
      "          .     ",
      "         ...    ",
      "          . .   "
    ]
  ]
}