{
  "xsize": 16,
  "zsize": 16,
  "refpalette": "lostcities:offshore",
  "slices": [
    [
      "                ",
      "  $             ",
      "                ",
      "     !          ",
      "  $ !!!         ",
      "  $!!!!!        ",
      "    !!!         ",
      "     !          ",
      "  $             ",
      "                ",
      "                ",
      "  $             ",
      "                ",
      "                ",
      "                ",
      "                "
    ],
    [
      "$$$!!           ",
      "$$$!!           ",
      "$$$!!           ",
      "$$$!!!          ",
      "$$$!!!!         ",
      "$$$!!!!!        ",
      "$$$ !!!         ",
      "$$$  !          ",
      "$$$             ",
      "$$$             ",
      "$$$             ",
      "$$$             ",
      "                ",
      "                ",
      "                ",
      "                "
    ],
    [
      "DDD!!!!!!!!!!!!!",
      "DDD!!!!!!!!!!!!!",
      "DDD!!!!!!!!!!!!!",
      "DDD!!!!!!!!!!!!!",
      "DDD!!!!!!!!!!!!!",
      "DDD!!!!!!!!!!!!!",
      "DDD!!!!!!!!!!!!!",
      "DDD!!!!!!!!!!!!!",
      "DDD!!!!!!!!!!!!!",
      "DDD!!!!!!!!!!!!!",
      "DDD!!!!!!!!!!!!!",
      "DDD!!!!!!!!!!!!!",
      "DDD!!!!!!!!!!!!!",
      "!!!!!!!!!!!!!!!!",
      "!!!!!!!!!!!!!!!!",
      "!!!!!!!!!!!!!!!!"
    ],
    [
      " !A    !!       ",
      " B A! !!!! !AA! ",
      "DB  B  !!  B  B ",
      "D!A B      B  B ",
      "   A!      !AA! ",
      "                ",
      "D!A           ! ",
      "DB           !!!",
      " B           !!!",
      " !A           ! ",
      "                ",
      " ! A!      !AA! ",
      "((( B      B  B ",
      " B  B  !!  B  B ",
      " !AA! !!!! !AA! ",
      "       !!       "
    ],
    [
      " )(             ",
      " = (*  !!  )((* ",
      "D=  =      =  = ",
      "D+( =      =  = ",
      "   (,      +((, ",
      "                ",
      "D)(             ",
      "D=            ! ",
      " =            ! ",
      " +(             ",
      "                ",
      "   (*      )((* ",
      " !  =      =  = ",
      " =  =      =  = ",
      " +((,  !!  +((, ",
      "                "
    ],
    [
      " )(             ",
      " = (*  !!  )((* ",
      " =  =      =  = ",
      " +( =      =  = ",
      "   (,      +((, ",
      "                ",
      " )(             ",
      " =            ! ",
      " =            ! ",
      " +(             ",
      "                ",
      "   (*      )((  ",
      " !  =           ",
      " =  =           ",
      " +((,  !!  +((, ",
      "                "
    ]
  ]
}