{
  "xsize": 16,
  "zsize": 16,
  "refpalette": "pomkotsmechs:offshore",
  "slices": [
    [
      "                ",
      "                ",
      "                ",
      "                ",
      "                ",
      "                ",
      "                ",
      "                ",
      "                ",
      "                ",
      "!            !  ",
      " EE EE EE EE    ",
      " EE EE EE EE    ",
      "   !EEEEEE!     ",
      " EEEEE EE!EE    ",
      " EEEEE EE EE    "
    ],
    [
      "                ",
      "                ",
      "                ",
      "                ",
      "                ",
      "                ",
      "                ",
      "                ",
      "                ",
      "&            &  ",
      "!&          &!& ",
      "&EE EE EE EE &  ",
      " EE EE EE EE    ",
      "   !!!!!!!!     ",
      " EE!EEEEEEEE    ",
      ".EE!EEEEEEEE    "
    ],
    [
      "                ",
      "                ",
      "                ",
      "                ",
      "                ",
      "                ",
      "                ",
      "                ",
      "                ",
      "!!!!!!!!!!!!!!! ",
      "!!!!!!!!!!!!!!! ",
      "!!!!!!!!!!!!!!! ",
      "!!!!!!!!!!!!!!! ",
      "!!!!!!!!!!!!!!! ",
      "!!!!!!!!!!!!!!! ",
      "!!!!!!!!!E!!!!! "
    ],
    [
      "                ",
      "                ",
      "                ",
      "                ",
      "                ",
      "                ",
      "                ",
      "                ",
      "                ",
      "&&          &&& ",
      "!&          &!& ",
      "&!! !! !! !!&&& ",
      " !!!!!!!!!!!    ",
      "  !EEEEEEEE!    ",
      " !!E!!!!!!!!    ",
      " !!E!!h!!!!!    "
    ],
    [
      "                ",
      "                ",
      "                ",
      "                ",
      "                ",
      "                ",
      "                ",
      "                ",
      "                ",
      "&            &  ",
      "!&          &!& ",
      "&EE EE EE EE &  ",
      " EE EE EE EE    ",
      "   EEEEEEEE     ",
      " EEEEE EEDEE    ",
      " EEEEE EE EE    "
    ],
    [
      "                ",
      "                ",
      "                ",
      "                ",
      "                ",
      "                ",
      "                ",
      "                ",
      "                ",
      "                ",
      "!            !  ",
      " EE EE EE EE    ",
      " EE!EE!EE!EE    ",
      "  !EEEEEEEE!    ",
      " EEEEE!EE!EE    ",
      " EEEEE!EEIEE    "
    ]
  ]
}