{
  "xsize": 16,
  "zsize": 16,
  "refpalette": "pomkotsmechs:offshore",
  "slices": [
    [
      "                ",
      "                ",
      "                ",
      "                ",
      "                ",
      "          .     ",
      "          .     ",
      "         ...    ",
      "    .    ...    ",
      "   ...    .     ",
      "    .           ",
      "                ",
      "                ",
      "                ",
      "                ",
      "                "
    ],
    [
      "                ",
      "                ",
      "                ",
      "                ",
      "                ",
      "                ",
      "          .     ",
      "    .    ...    ",
      "   ...    .     ",
      "   ...          ",
      "    .           ",
      "                ",
      "                ",
      "                ",
      "                ",
      "                "
    ],
    [
      "                ",
      "                ",
      "                ",
      "                ",
      "                ",
      "          .     ",
      "         ...    ",
      "    .    ...    ",
      "   ...    .     ",
      "    .           ",
      "                ",
      "                ",
      "                ",
      "                ",
      "                ",
      "                "
    ],
    [
      "                ",
      "                ",
      "                ",
      "                ",
      "                ",
      "          .     ",
      "         mmm    ",
      "    .. mmmmmmm  ",
      "   .mmmmmmmmmmmm",
      "   mmmmmmmmmmmmm",
      "  mmmmmmmmmmmmmm",
      "mmmmmmmmmmmmmmmm",
      "mmmmmmmmmmmmmmmm",
      "mmmmmmmmmmmmmmmm",
      "mmmmmmmmmmmmmmmm",
      "mmmmmmmmmmmmmmmm"
    ],
    [
      "                ",
      "                ",
      "                ",
      "                ",
      "                ",
      "          .     ",
      "        mmmm    ",
      "     . mmmmmmmm ",
      "    ..mmmmmmmmmm",
      "   mmmmmmmmmmmmm",
      "  mmmmmmmmmmmmmm",
      "mmmmmmmmmmmmmmmm",
      "mmmmmmmmmmmmmmmm",
      "mmmmmmmmmmmmmmmm",
      "mmmmmmmmmmmmmmmm",
      "mmmmmmmmmmmmmmmm"
    ],
    [
      "                ",
      "                ",
      "                ",
      "                ",
      "                ",
      "                ",
      "          .     ",
      "       mmmmm    ",
      "     .mmmmmmmmm ",
      "    .mmmmmmmmmmm",
      "     mmmmmmmmmmm",
      "    mmmmmmmmmmmm",
      "mmmmmmmmmmmmmmmm",
      "mmmmmmmmmmmmmmmm",
      "mmmmmmmmmmmmmmmm",
      "mmmmmmmmmmmmmmmm"
    ]
  ]
}