{
  "xsize": 16,
  "zsize": 16,
  "refpalette": "pomkotsmechs:offshore",
  "slices": [
    [
      "                ",
      "                ",
      "                ",
      "                ",
      "                ",
      "PPPPPYYYZZ      ",
      "MMMMM[[[\\\\      ",
      "PPPPPPPM        ",
      "MMMMMYYYZZ      ",
      "PPPPP[[[\\\\      ",
      "                ",
      "                ",
      "                ",
      "                ",
      "                ",
      "                "
    ],
    [
      "MMMMM     SS    ",
      "MMMMM    SSSS   ",
      "MMMM    SSSSS   ",
      "MMMM   SSSS     ",
      "PPPPPPPPP       ",
      "PPPPP]]]^^      ",
      "P__PP```aa      ",
      "PPPPPPPS        ",
      "P__PP]]]^^      ",
      "PPPPP```aa      ",
      "PPPPPPPPP       ",
      "MMMM   SSSS     ",
      "MMMM    SSSSS   ",
      "MMMMM    SSSS   ",
      "MMMMM     SS    ",
      "MMMMM           "
    ],
    [
      "                ",
      "                ",
      "                ",
      "                ",
      "    SPPPPPM     ",
      "                ",
      "                ",
      "SSS             ",
      "                ",
      "                ",
      "    SPPPPPM     ",
      "                ",
      "                ",
      "                ",
      "                ",
      "                "
    ],
    [
      "                ",
      "                ",
      "                ",
      "                ",
      "     PPPPbc     ",
      "                ",
      "                ",
      "                ",
      "                ",
      "                ",
      "     PPPPbc     ",
      "                ",
      "                ",
      "                ",
      "                ",
      "                "
    ],
    [
      "                ",
      "                ",
      "                ",
      "                ",
      "      PPPbc     ",
      "                ",
      "                ",
      "                ",
      "                ",
      "                ",
      "      PPPbc     ",
      "                ",
      "                ",
      "                ",
      "                ",
      "                "
    ],
    [
      "                ",
      "                ",
      "                ",
      "                ",
      "      SPPbc     ",
      "                ",
      "                ",
      "                ",
      "                ",
      "                ",
      "      SPPbc     ",
      "                ",
      "                ",
      "                ",
      "                ",
      "                "
    ]
  ]
}