{
  "xsize": 16,
  "zsize": 16,
  "refpalette": "lostcities:offshore",
  "slices": [
    [
      "             #!#",
      "              #!",
      "               #",
      "          !     ",
      "         !!!    ",
      "         !!!!   ",
      "         !!!    ",
      "                ",
      "                ",
      "                ",
      "                ",
      "                ",
      "                ",
      "                ",
      "                ",
      "                "
    ],
    [
      "           !! ! ",
      "           !!! !",
      "           !!!! ",
      "          !!!!!!",
      "         !!!!!!!",
      "         !!!!   ",
      "         !!!    ",
      "                ",
      "                ",
      "                ",
      "                ",
      "                ",
      "                ",
      "                ",
      "                ",
      "                "
    ],
    [
      "      !!!!!!!!!!",
      "!     !!!!!!!!!!",
      "!!    !!!!!!!!!!",
      "!!       !!!!!!!",
      "!!        !!!!!!",
      "!!        !!!!!!",
      "!!        !!!!!!",
      "!!           !!!",
      "!!            !!",
      "!!              ",
      "!!!             ",
      "!!!!!         !!",
      "!!!!!!!!!!!!!!!!",
      "!!!!!!!!!!!!!!!!",
      "!!!!!!!!!!!!!!!!",
      "!!!!!!!!!!!!!!!!"
    ],
    [
      "       !!       ",
      "      !!!! !AA! ",
      "       !!  B  B ",
      "           B  B ",
      "           !AA! ",
      "                ",
      "              ! ",
      "             !!!",
      "               !",
      "                ",
      "                ",
      " !A           ! ",
      " B  B      B  B ",
      " B  B  !!  B  B ",
      " !AA! !!!! !AA! ",
      "       !!       "
    ],
    [
      "                ",
      "       !!  )((* ",
      "    =      =  = ",
      "           =  = ",
      "           +((, ",
      "                ",
      "                ",
      "              ! ",
      "              ! ",
      "                ",
      "                ",
      " )           (* ",
      " =         =  = ",
      " =  =      =  = ",
      " +((,  !!  +((, ",
      "                "
    ],
    [
      "                ",
      " )((*  !!  )((* ",
      " =  =      =  = ",
      " =  =      =  = ",
      " +((,      +((, ",
      "                ",
      "                ",
      "              ! ",
      "              ! ",
      "                ",
      "                ",
      "           )((* ",
      "    =      =  = ",
      " =  =      =  = ",
      " +((,  !!  +((, ",
      "                "
    ]
  ]
}