{
  "xsize": 16,
  "zsize": 16,
  "refpalette": "pomkotsmechs:offshore",
  "slices": [
    [
      " =      =  =    ",
      "(,      +((,    ",
      "       !        ",
      "       !        ",
      "                ",
      "                ",
      "                ",
      "           .    ",
      "(*      )((*.   ",
      " =      = .=.   ",
      " =      =  =    ",
      "(,      +((,    ",
      "                ",
      "                ",
      "                ",
      "                "
    ],
    [
      " B      B  B    ",
      "A!!!!!!!!AA!    ",
      " !!    !!       ",
      " !      !       ",
      " !      !       ",
      " !      !       ",
      " !      !       ",
      " !      !  .    ",
      "A!!!!!!!!AA!.   ",
      " B      B  B    ",
      " B      B  B    ",
      "A!      !AA!    ",
      "                ",
      "                ",
      "                ",
      "                "
    ],
    [
      " =      =  =    ",
      "(,      +((,    ",
      "  !             ",
      "  !             ",
      "                ",
      "                ",
      "                ",
      "           .    ",
      "(*      )((*.   ",
      " =      =  =    ",
      " =      =  =    ",
      "(,      +((,    ",
      "                ",
      "                ",
      "                ",
      "                "
    ],
    [
      " g      g  g    ",
      ">        ?>     ",
      "                ",
      "  !             ",
      "  !             ",
      "                ",
      "           .    ",
      "          ...   ",
      ">        ?>..   ",
      " f      f  f    ",
      " g      g  g    ",
      ">        ?>     ",
      "                ",
      "                ",
      "                ",
      "                "
    ],
    [
      " =      =  =    ",
      "(,      +((,    ",
      "                ",
      "                ",
      "  !             ",
      "  !             ",
      "           ..   ",
      "          ....  ",
      "(*      )((*.   ",
      " =      =  =    ",
      " =      =  =    ",
      "(,      +((,    ",
      "                ",
      "                ",
      "                ",
      "                "
    ],
    [
      " g      g  g    ",
      ">        ?>     ",
      "                ",
      "                ",
      "                ",
      "  !         .   ",
      "  !        ...  ",
      "           ...  ",
      ">        ?> .   ",
      " f      f  f    ",
      " g      g  g    ",
      ">        ?>     ",
      "                ",
      "                ",
      "                ",
      "                "
    ]
  ]
}