{
  "xsize": 16,
  "zsize": 16,
  "refpalette": "lostcities:offshore",
  "slices": [
    [
      "              ! ",
      "  )((*  !!  )((*",
      "  =  =      =  =",
      "  =  =    ! =  =",
      "  +((,   !!!+((,",
      "        !!!!!   ",
      "         !!!    ",
      "  !       !    !",
      "  !            !",
      "                ",
      "                ",
      "  )((*      )((*",
      "  =  =      =  =",
      "  =  =      =  =",
      "  +((,  !!  +((,",
      "                "
    ],
    [
      "        !!    ! ",
      "  !AA! !!!! !AA!",
      "  B  B  !!  B  B",
      "  B  B    ! B  B",
      "  !AA!   !!!!AA!",
      "        !!!!!   ",
      "  !      !!!   !",
      " !!!      !   !!",
      " !!!          !!",
      "  !            !",
      "                ",
      "  !AA!      !AA!",
      "  B  B      B  B",
      "  B  B  !!  B  B",
      "  !AA! !!!! !AA!",
      "        !!      "
    ],
    [
      " !!!!!!!!!!!!!!$",
      " !!!!!!!!!!!!!!$",
      " !!!!!!!!!!!!!!$",
      " !!!!!!!!!!!!!!$",
      " !!!!!!!!!!!!!!$",
      " !!!!!!!!!!!!!!$",
      " !!!!!!!!!!!!!!!",
      " !!!!!!!!!!!!!!!",
      " !!!!!!!!!!!!!!!",
      " !!!!!!!!!!!!!!!",
      " !!!!!!!!!!!!!!!",
      " !!!!!!!!!!!!!!!",
      " !!!!!!!!!!!!!!!",
      " !!!!!!!!!!!!!!!",
      " !!!!!!!!!!!!!!!",
      " !!!!!!!!!!!!!!!"
    ],
    [
      "     $$$$$$$$$$$",
      "     $$$$$$$$$$$",
      "     $$$$$$$$$$$",
      "     $$$$$$$$$$$",
      "     $$$$$$$$$$$",
      "     $$$$$$$$$$$",
      "     $$$$$$$$$$$",
      "     $$$$$$$$$$$",
      "     $$$$$$$$$$$",
      "     $$$$$$$$$$$",
      "     $$$$$$$$$$$",
      "     $$$$$$$$$$$",
      "    !           ",
      "                ",
      "                ",
      "                "
    ],
    [
      "    D$          ",
      "    D$          ",
      "    D$          ",
      "    D$          ",
      "    D$          ",
      "    D$        DD",
      "    D$        DD",
      "    D$          ",
      "    D$          ",
      "    D$          ",
      "    D$          ",
      "    D$$$$$$$$$$$",
      "    !DDDDDDDDDDD",
      "                ",
      "                ",
      "                "
    ],
    [
      "                ",
      "     $          ",
      "                ",
      "                ",
      "     $          ",
      "     $          ",
      "              DD",
      "              DD",
      "     $          ",
      "                ",
      "                ",
      "     $  $  $$  $",
      "    !           ",
      "                ",
      "                ",
      "                "
    ]
  ]
}