{
  "xsize": 16,
  "zsize": 16,
  "refpalette": "lostcities:offshore",
  "slices": [
    [
      " EEEEE EE!EE    ",
      " EEEEE EE EE    ",
      "   E. )(*iE     ",
      " EEEEE=EElEE    ",
      ".EEEEE+EE EE    ",
      ".  E!    !E     ",
      " EE!EEEEEEEE    ",
      " EE EE EE EE    ",
      "                ",
      "!            !  ",
      "                ",
      "                ",
      "                ",
      "                ",
      "                ",
      "                "
    ],
    [
      "!!!!!!!!!D!!!!! ",
      "!!!!!!!!!E!!!!! ",
      "!!!!!!!!!E!!!!! ",
      "!!!!!!!!!i!!!!! ",
      "!!!!!!!!!l!!!!! ",
      "!!!!!!!!!i!!!!! ",
      "!!!!!!!!!!!!!!! ",
      "!!!!!!!!!!!!!!! ",
      "!!!!!!!!!!!!!!! ",
      "!!!!!!!!!!!!!!! ",
      "!!!!!!!!!!!!!!! ",
      "                ",
      "                ",
      "                ",
      "                ",
      "                "
    ],
    [
      "   .D..  D      ",
      "   !..    !     ",
      "  .D..    D     ",
      " ..D.     D     ",
      "...!      !     ",
      ".   D    D      ",
      "     !DD!       ",
      "                ",
      "                ",
      "                ",
      "                ",
      "                ",
      "                ",
      "                ",
      "                ",
      "                "
    ],
    [
      "   .D.   D      ",
      "   !.     !     ",
      "   D..    D     ",
      "  .D..    D     ",
      "   !.     !     ",
      "    D    D      ",
      "     !DD!       ",
      "                ",
      "                ",
      "                ",
      "                ",
      "                ",
      "                ",
      "                ",
      "                ",
      "                "
    ],
    [
      "    D    D      ",
      "   !      !     ",
      "   D.     D     ",
      "  .D..    D     ",
      "   !.     !     ",
      "    D    D      ",
      "     !DD!       ",
      "                ",
      "                ",
      "                ",
      "                ",
      "                ",
      "                ",
      "                ",
      "                ",
      "                "
    ],
    [
      "    D    D      ",
      "   !      !     ",
      "  .D.     D     ",
      " ..D..    D     ",
      "  .!.     !     ",
      "    D    D      ",
      "     !DD!       ",
      "                ",
      "                ",
      "                ",
      "                ",
      "                ",
      "                ",
      "                ",
      "                ",
      "                "
    ]
  ]
}