{
  "xsize": 16,
  "zsize": 16,
  "refpalette": "pomkotsmechs:offshore",
  "slices": [
    [
      "                ",
      "     $          ",
      "                ",
      "                ",
      "     $          ",
      "     $          ",
      "                ",
      "                ",
      "     $          ",
      "                ",
      "                ",
      "     $  $  $$  $",
      "    !           ",
      "                ",
      "                ",
      "                "
    ],
    [
      "     $$$$$$$$$$$",
      "     $$$$$$$$$$$",
      "     $$$$$$$$$$$",
      "     $$$$$$$$$$$",
      "     $$$$$$$$$  ",
      "     $$$$$$$$$$$",
      "     $$$$$$$$$$$",
      "     $$$$$$$$$$$",
      "     $$$$$$$$$$$",
      "     $$$$$$$$$$$",
      "     $$$$$$$$$$$",
      "     $$$$$$$$$$$",
      "    !           ",
      "                ",
      "                ",
      "                "
    ],
    [
      "    DDDDDDDDDDDD",
      "    DDDDDDDDDDDD",
      "    DDDDDDDDDDDD",
      "    DDDDDDDDDDDD",
      "    DDDDDDDDDD  ",
      "    DDDDDDDDDDDD",
      "    DDDDDDDDDDDD",
      "    DDDDDDDDDDDD",
      "    DDDDDDDDDDDD",
      "    DDDDDDDDDDDD",
      "    DDDDDDDDDDDD",
      "    DDDDDDDDDDDD",
      "    DDDDDDDDDDDD",
      "                ",
      "                ",
      "                "
    ],
    [
      "     $$$$$$$$$$$",
      "     $$$$$$$$$$$",
      "     $$$$$$$$$$$",
      "     $$$$$$$$$$$",
      "     $$$$$$$$$  ",
      "     $$$$$$$$$$$",
      "     $$$$$$$$$$$",
      "     $$$$$$$$$$$",
      "     $$$$$$$$$$$",
      "     $$$$$$$$$$$",
      "     $$$$$$$$$$$",
      "     $$$$$$$$$$$",
      "    !           ",
      "                ",
      "                ",
      "                "
    ],
    [
      "    D$          ",
      "    D$          ",
      "    D$          ",
      "    D$          ",
      "    D$          ",
      "    D$          ",
      "    D$          ",
      "    D$          ",
      "    D$          ",
      "    D$          ",
      "    D$          ",
      "    D$$$$$$$$$$$",
      "    !DDDDDDDDDDD",
      "                ",
      "                ",
      "                "
    ],
    [
      "                ",
      "     $          ",
      "                ",
      "                ",
      "     $          ",
      "     $          ",
      "                ",
      "                ",
      "     $          ",
      "                ",
      "                ",
      "     $  $  $$  $",
      "    !           ",
      "                ",
      "                ",
      "                "
    ]
  ]
}