{
  "xsize": 16,
  "zsize": 16,
  "refpalette": "pomkotsmechs:offshore",
  "slices": [
    [
      "          ....DD",
      "           $$$$$",
      "            .. $",
      "               $",
      "               $",
      "        $      $",
      "        $  .   $",
      "        $ ..   $",
      "       D$$$$$$$$",
      "        DDDDDDDD",
      "       .        ",
      "      ...       ",
      "       .        ",
      "                ",
      "                ",
      "                "
    ],
    [
      "         D... D ",
      "         $$$$$$$",
      "           $$$$$",
      "          $$$$$$",
      "         $$$$$$$",
      "         $$$$$$$",
      "         $$$$$$$",
      "        $$$$$$$$",
      "        $$$$$$$$",
      "        .D.   D ",
      "      ...       ",
      "     ....       ",
      "      ..        ",
      "                ",
      "                ",
      "                "
    ],
    [
      "     DD   ...  D",
      "          .... D",
      "           .. DD",
      "           DDDDD",
      "           DDDDD",
      "           .DDDD",
      "          ..DDDD",
      "         ..DDDDD",
      "        DDDDDDDD",
      "     DDDDDDDDDDD",
      "     DDDDDDDDDDD",
      "     DDDDDDDDDDD",
      "      ...       ",
      "                ",
      "                ",
      "                "
    ],
    [
      "     =    ...   ",
      "          ...   ",
      "           .    ",
      "                ",
      "           DD   ",
      "           DD   ",
      "          ....  ",
      "          ...   ",
      "         .      ",
      "     =  ..      ",
      "     =  .       ",
      "     $((((((((((",
      "                ",
      "                ",
      "                ",
      "                "
    ],
    [
      "          ...   ",
      "           .    ",
      "                ",
      "                ",
      "           DD   ",
      "           DD   ",
      "          ...   ",
      "          ..    ",
      "                ",
      "                ",
      "                ",
      "                ",
      "                ",
      "                ",
      "                ",
      "                "
    ],
    [
      "         ....   ",
      "          ..    ",
      "                ",
      "                ",
      "           DD   ",
      "          .DD   ",
      "         ....   ",
      "         ...    ",
      "          .     ",
      "                ",
      "                ",
      "                ",
      "                ",
      "                ",
      "                ",
      "                "
    ]
  ]
}