{
  "xsize": 16,
  "zsize": 16,
  "refpalette": "pomkotsmechs:offshore",
  "slices": [
    [
      "                ",
      "                ",
      "     G       .  ",
      "            HIH ",
      "           $$$$ ",
      "         $$    $",
      "        $       ",
      "        $       ",
      "      H$        ",
      "      I$        ",
      "      H$        ",
      "       $        ",
      "        $       ",
      "        $       ",
      "         $$    $",
      "           $$$$ "
    ],
    [
      "                ",
      "             .  ",
      "     G      ... ",
      "            HIH ",
      "           $$$$ ",
      "         $$    $",
      "        $       ",
      "        $       ",
      "      H$        ",
      "      I$        ",
      "      H$        ",
      "       $        ",
      "        $       ",
      "        $       ",
      "         $$    $",
      "           $$$$ "
    ],
    [
      "                ",
      "            ..  ",
      "     G     .... ",
      "            HIH ",
      "           $$$$ ",
      "         $$    $",
      "        $       ",
      "        $       ",
      "      H$        ",
      "      I$        ",
      "      H$        ",
      "       $        ",
      "        $       ",
      "        $       ",
      "         $$    $",
      "           $$$$ "
    ],
    [
      "                ",
      "            .   ",
      "     GGGGGGGGGGG",
      "     G      HIH ",
      "     G     $$$$ ",
      "     G   $$    $",
      "     G  $       ",
      "     G  $       ",
      "     GH$        ",
      "     GI$        ",
      "     GH$        ",
      "     G $        ",
      "     G  $       ",
      "     G  $       ",
      "     G   $$    $",
      "     G     $$$$ "
    ],
    [
      "            .   ",
      "           ...  ",
      "     G     ...  ",
      "            HIH ",
      "           $$$$ ",
      "         $$    $",
      "        $       ",
      "        $       ",
      "      H$        ",
      "      I$        ",
      "      H$        ",
      "       $        ",
      "        $       ",
      "        $       ",
      "         $$    $",
      "           $$$$ "
    ],
    [
      "            .   ",
      "           ...  ",
      "     G      .   ",
      "            HIH ",
      "           $$$$ ",
      "         $$    $",
      "        $       ",
      "        $       ",
      "      H$        ",
      "      I$        ",
      "      H$        ",
      "       $        ",
      "        $       ",
      "        $       ",
      "         $$    $",
      "           $$$$ "
    ]
  ]
}