{
  "xsize": 16,
  "zsize": 16,
  "refpalette": "pomkotsmechs:offshore",
  "slices": [
    [
      "                ",
      "                ",
      "        G       ",
      "HIH             ",
      "$$$             ",
      "   $$           ",
      "     $          ",
      "     $          ",
      "     !$         ",
      "    !!$H        ",
      "   !!!$I        ",
      "    !!$H        ",
      "     $          ",
      "     $          ",
      "!  $$           ",
      "$$$             "
    ],
    [
      "                ",
      "                ",
      "        G       ",
      "HIH             ",
      "$$$             ",
      "   $$           ",
      "     $          ",
      "     $          ",
      "     !$         ",
      "    !!$H        ",
      "   !!!$I        ",
      "    !!$H        ",
      "     $          ",
      "     $          ",
      "!  $$           ",
      "$$$             "
    ],
    [
      "                ",
      "                ",
      "        G       ",
      "HIH             ",
      "$$$             ",
      "   $$           ",
      "     $          ",
      "     $          ",
      "    !!$         ",
      "   !!!$H        ",
      "!!!!!!$I        ",
      "   !!!$H        ",
      "    !$!         ",
      "     $          ",
      "!  $$!          ",
      "$$$  !          "
    ],
    [
      "                ",
      "                ",
      "GGGGGGGGG       ",
      "HIH     G       ",
      "$$$     G       ",
      "   $$   G       ",
      "     $  G       ",
      "     $  G       ",
      "     !$ G       ",
      "    !!$HG       ",
      "   !!!$IG       ",
      "    !!$HG       ",
      "     $  G       ",
      "     $  G       ",
      "!  $$   G       ",
      "$$$     G       "
    ],
    [
      "                ",
      "                ",
      "        G       ",
      "HIH             ",
      "$$$             ",
      "   $$           ",
      "     $          ",
      "     $          ",
      "     !$         ",
      "    !!$H        ",
      "   !!!$I        ",
      "    !!$H        ",
      "     $          ",
      "     $          ",
      "!  $$           ",
      "$$$             "
    ],
    [
      "                ",
      "                ",
      "        G       ",
      "HIH             ",
      "$$$             ",
      "   $$           ",
      "     $          ",
      "     $          ",
      "     !$         ",
      "    !!$H        ",
      "!!!!!!$I        ",
      "    !!$H        ",
      "     $          ",
      "     $          ",
      "!  $$!          ",
      "$$$  !          "
    ]
  ]
}