{
  "xsize": 16,
  "zsize": 16,
  "refpalette": "pomkotsmechs:offshore",
  "slices": [
    [
      "                ",
      "                ",
      "                ",
      "                ",
      "                ",
      "                ",
      "                ",
      "                ",
      "     !          ",
      "    !!!         ",
      "   !!!!!        ",
      "    !!!         ",
      "     !          ",
      "                ",
      "  $             ",
      "                "
    ],
    [
      "                ",
      "                ",
      "                ",
      "                ",
      "                ",
      "                ",
      "                ",
      "                ",
      "     !          ",
      "    !!!         ",
      "   !!!!!        ",
      "!!!!!!!         ",
      "!!!!!!          ",
      "   !!           ",
      "$$$!!           ",
      "$$$!!           "
    ],
    [
      "!!!!!!!!!!!!!!!!",
      "!!!!!!!!!!!!!!!!",
      "!!!!!!!!!!!!!!!!",
      "!!!!!!!!!!!!!!!!",
      "!!!!!!!!!!!!!!!!",
      "!!!!!!!!!!!!!!!!",
      "!!!!!!!!!!!!!!!!",
      "!!!!!!!!!!!!!!!!",
      "!!!!!!!!!!!!!!!!",
      "!!!!!!!!!!!!!!!!",
      "!!!!!!!!!!!!!!!!",
      "!!!!!!!!!!!!!!!!",
      "!!!!!!!!!!!!!!!!",
      "DDD!!!!!!!!!!!!!",
      "DDD!!!!!!!!!!!!!",
      "DDD!!!!!!!!!!!!!"
    ],
    [
      "       !!       ",
      "AA!A! !!!! !AA! ",
      "  B B  !!  B  B ",
      "  B B      B  B ",
      "AA!A!      !AA! ",
      "                ",
      "!!!           ! ",
      "!!!          !!!",
      "!!!          !!!",
      " !            ! ",
      "                ",
      " !AA!      !AA! ",
      " B  B      B  B ",
      "((( B  !!  B  B ",
      " ! A! !!!! !AA! ",
      "       !!       "
    ],
    [
      "                ",
      "((*(*  !!  )((* ",
      "  = =      =  = ",
      "  = =      =  = ",
      "((,(,      +((, ",
      "                ",
      " !              ",
      " !            ! ",
      " !            ! ",
      "                ",
      "                ",
      " )((*      )((* ",
      " =  =      =  = ",
      " !  =      =  = ",
      "   (,  !!  +((, ",
      "                "
    ],
    [
      "                ",
      "((*(*  !!  )((* ",
      "  = =      =  = ",
      "  = =      =  = ",
      "((,(,      +((, ",
      "                ",
      " !              ",
      " !            ! ",
      " !            ! ",
      "                ",
      "                ",
      " )((*      )((* ",
      " =  =      =  = ",
      " !  =      =  = ",
      "   (,  !!  +((, ",
      "                "
    ]
  ]
}