{
  "xsize": 16,
  "zsize": 16,
  "refpalette": "pomkotsmechs:offshore",
  "slices": [
    [
      "    !   DDDDDDDD",
      " !AAB  D$$$$$$$$",
      " B  B  D$  B  B$",
      " B  ! !D$! !AA!$",
      " !AA   D$      $",
      "       D$      $",
      " !  ! !D$! !AA!$",
      "!!! B  D$  B  B$",
      "!!! B  D$$$$$$$$",
      " !  !   DDDDDDDD",
      "                ",
      " !AA          ! ",
      " B      .    !!!",
      " B  B  !!  B  B ",
      " !AA! !!!! !AA! ",
      "       !!       "
    ],
    [
      "!!!!!!!!!D!!!!D!",
      "!!!!!!!!$$$$$$$$",
      "!!!!!!!D$$$$$$$$",
      "!!!!!!!!$$$$$$$$",
      "!!!!!!!!$$$$$$$$",
      "!!!!!!!!$$$$$$$$",
      "!!!!!!!!$$$$$$$$",
      "!!!!!!!D$$$$$$$$",
      "!!!!!!!!$$$$$$$$",
      "!!!!!!!!!D!!!!D!",
      "!!!!!!!!!!!!!!!!",
      "!!!!!!!!!!!!!!!!",
      "!!!!!!!!!!!!!!!!",
      "!!!!!!!!!!!!!!!!",
      "!!!!!!!!!!!!!!!!",
      "!!!!!!!!!!!!!!!!"
    ],
    [
      "     DDD DDDDDDD",
      "     DD  DDDDDDD",
      "     DDDDDDDDDDD",
      "     DDDDDDDDDDD",
      "     DDDDDDDDDDD",
      "     DDDDDDDDDDD",
      "     DDDDDDDDDDD",
      "     DDDDDDDDDDD",
      "     DDDDDDDDDDD",
      "     DDDDDDDDDDD",
      "     DDDDDDDDDDD",
      "     DDDDDDDDDDD",
      "       ...      ",
      "       ..       ",
      "                ",
      "                "
    ],
    [
      "     =    D  DD ",
      "     =   $$  $$$",
      "     =       $$$",
      "     =  $  $$$$$",
      "     =  $$$$$$$$",
      "     =  $$$$$$$$",
      "     = D$$$$$$$$",
      "     = D$$$$$$$$",
      "     =  $$$$$$$$",
      "     =   DD  DD ",
      "     =  ..      ",
      "     $((((((((((",
      "        ..      ",
      "                ",
      "                ",
      "                "
    ],
    [
      "          D .DD ",
      "            .$$$",
      "             . $",
      "               $",
      "               $",
      "        $      $",
      "       D$      $",
      "       D$      $",
      "        $$$$$$$$",
      "         DD  DD ",
      "        .       ",
      "       ...      ",
      "        .       ",
      "                ",
      "                ",
      "                "
    ],
    [
      "           ..D  ",
      "           ....$",
      "            ..  ",
      "                ",
      "               $",
      "        $      $",
      "                ",
      "                ",
      "        $  $$  $",
      "                ",
      "       ..       ",
      "      ....      ",
      "       ..       ",
      "                ",
      "                ",
      "                "
    ]
  ]
}