{
  "xsize": 16,
  "zsize": 16,
  "refpalette": "lostcities:offshore",
  "slices": [
    [
      "                ",
      "                ",
      "                ",
      "                ",
      "                ",
      "                ",
      "                ",
      "                ",
      "                ",
      "                ",
      "                ",
      "      !    !    ",
      "                ",
      "                ",
      "                ",
      "                "
    ],
    [
      "                ",
      "                ",
      "                ",
      "                ",
      "                ",
      "                ",
      "                ",
      "                ",
      "                ",
      "                ",
      "                ",
      "      !   !!    ",
      "      !    !    ",
      "                ",
      "                ",
      "                "
    ],
    [
      "                ",
      "                ",
      "                ",
      "                ",
      "                ",
      "                ",
      "                ",
      "                ",
      "                ",
      "                ",
      "                ",
      "      !  !!!    ",
      "      !    !    ",
      "      !    !    ",
      "                ",
      "                "
    ],
    [
      "                ",
      "                ",
      "                ",
      "                ",
      "     mmmmmmmmmmm",
      "     mmmmmmmmmmm",
      "     m   mm   mm",
      "     m   mm   mm",
      "     m   mm   mm",
      "     mmmmmmmmmmm",
      "     mmmmmmmmmmm",
      "      !!!!!!    ",
      "      !    !    ",
      "      !    !    ",
      "      !    !    ",
      "      !    !    "
    ],
    [
      "                ",
      "                ",
      "                ",
      "                ",
      "     mmmmmmmmmmm",
      "     m   mm mmmm",
      "     m   mm mmmm",
      "     mmmmmmmmmmm",
      "     mmmmmmmmmmm",
      "     mmmmmmmmmmm",
      "     mmmmmmmmmmm",
      "     m!!!!!!mmmm",
      "     m!    !mmmm",
      "     m!    !mmmm",
      "     m!    !mmmm",
      "     m!    !mmmm"
    ],
    [
      "                ",
      "                ",
      "                ",
      "                ",
      "     mmmmmmm    ",
      "     mmmmmmmm   ",
      "     mmmmmmm    ",
      "     mmmmmmmm   ",
      "     mmmmmmm    ",
      "     mmmmmmm    ",
      "     mmmmmmm    ",
      "      !    !    ",
      "                ",
      "                ",
      "                ",
      "        .   m   "
    ]
  ]
}