{
  "xsize": 16,
  "zsize": 16,
  "refpalette": "pomkotsmechs:offshore",
  "slices": [
    [
      "                ",
      "                ",
      "    G    G      ",
      "                ",
      "               $",
      "$            $$ ",
      " $          $   ",
      " $          $   ",
      "  $        $    ",
      "  $       I$    ",
      "  $I       $    ",
      "  $        $    ",
      " $          $   ",
      " $          $   ",
      "$            $$ ",
      "               $"
    ],
    [
      "                ",
      "                ",
      "    G    G      ",
      "                ",
      "               $",
      "$            $$ ",
      " $          $   ",
      " $          $   ",
      "  $        $    ",
      "  $       I$    ",
      "  $I       $    ",
      "  $        $    ",
      " $          $   ",
      " $          $   ",
      "$            $$ ",
      "               $"
    ],
    [
      "                ",
      "                ",
      "    G    G      ",
      "                ",
      "               $",
      "$            $$ ",
      " $          $   ",
      " $          $   ",
      "  $        $    ",
      "  $       I$    ",
      "  $I       $    ",
      "  $        $    ",
      " $          $   ",
      " $          $   ",
      "$            $$ ",
      "               $"
    ],
    [
      "                ",
      "                ",
      "GGGGG    GGGGGGG",
      "    G    G      ",
      "    G    G     $",
      "$   G    G   $$ ",
      " $  G    G  $   ",
      " $  G    G  $   ",
      "  $ G    G $    ",
      "  $ G    GI$    ",
      "  $IG    G $    ",
      "  $ G    G $    ",
      " $  G    G  $   ",
      " $  G    G  $   ",
      "$   G    G   $$ ",
      "    G    G     $"
    ],
    [
      "                ",
      "                ",
      "                ",
      "                ",
      "               $",
      "$            $$ ",
      " $          $   ",
      " $          $   ",
      "  $        $    ",
      "  $       I$    ",
      "  $I       $    ",
      "  $        $    ",
      " $          $   ",
      " $          $   ",
      "$            $$ ",
      "               $"
    ],
    [
      "                ",
      "                ",
      "                ",
      "                ",
      "               $",
      "$            $$$",
      "$$          $$$$",
      "$$          $$$$",
      "$$$        $$$$$",
      "$$$       I$$$$$",
      "$$$I       $$$$$",
      "$$$        $$$$$",
      "$$          $$$$",
      "$$          $$$$",
      "$            $$$",
      "               $"
    ]
  ]
}