{
  "xsize": 16,
  "zsize": 16,
  "refpalette": "pomkotsmechs:offshore",
  "slices": [
    [
      "          D$$$D ",
      "                ",
      "                ",
      "          D$$$D ",
      "          $   $ ",
      "          $   $ ",
      "          $   $ ",
      "          D$$$D ",
      "     !          ",
      "    !!!         ",
      "   !!!!!  D$$$D ",
      "    !!!   $$$$$ ",
      "     !    $   $ ",
      "          $   $ ",
      "  $       D$$$D ",
      "                "
    ],
    [
      "          D$$$D ",
      "                ",
      "                ",
      "          D$$$D ",
      "          $DDD$ ",
      "          $DDD$ ",
      "          $DDD$ ",
      "          D$$$D ",
      "     !          ",
      "    !!!         ",
      "   !!!!!  D$$$D ",
      "!!!!!!!   $DDD$ ",
      "!!!!!!    $DDD$ ",
      "   !!     $DDD$ ",
      "$$$!!     D$$$D ",
      "  $!!           "
    ],
    [
      "          DDDDD ",
      "                ",
      "                ",
      "          DDDDD ",
      "          DDDDD ",
      "          DDDDD ",
      "          DDDDD ",
      "          DDDDD ",
      "    !!!         ",
      "   !!!!!        ",
      "   !!!!!  DDDDD ",
      "   !!!!!  DDDDD ",
      "   !!!!!  DDDDD ",
      "DDD       DDDDD ",
      "DDD       DDDDD ",
      "DDD             "
    ],
    [
      "          &   & ",
      "                ",
      "                ",
      "          &   & ",
      "                ",
      "                ",
      "                ",
      "          &   & ",
      "     !          ",
      "    !!!         ",
      "   !!!!!  &   & ",
      "    !!!         ",
      "     !          ",
      "                ",
      "$$$       &   & ",
      "$$$             "
    ],
    [
      "          DDDDD ",
      "                ",
      "                ",
      "          DDDDD ",
      "          DDDDD ",
      "          DDDDD ",
      "          DDDDD ",
      "          DDDDD ",
      "     !          ",
      "    !!!         ",
      "   !!!!!  DDDDD ",
      "    !!!   DDDDD ",
      "     !    DDDDD ",
      "DDD       DDDDD ",
      "$$$       DDDDD ",
      "  $             "
    ],
    [
      "          D$$$D ",
      "                ",
      "                ",
      "          D$$$D ",
      "          $EE $ ",
      "          $   $ ",
      "          $   $ ",
      "          D$$$D ",
      "     !          ",
      "    !!!         ",
      "!!!!!!!!  D$$$D ",
      "    !!!   $EE$$ ",
      "     !    $EE $ ",
      "     !    $   $ ",
      "  $  !    D$$$D ",
      "     !          "
    ]
  ]
}