{
  "xsize": 16,
  "zsize": 16,
  "refpalette": "lostcities:offshore",
  "slices": [
    [
      "       !!.      ",
      " !AA! !!!! !AA! ",
      " B  B  !!  B  B ",
      " B  B      B  B ",
      " !AA!      !AA! ",
      "                ",
      " !            ! ",
      "!!!          !!!",
      "!!!          !!!",
      " !            ! ",
      "                ",
      " !AA!      !AA! ",
      " B  B      B  B ",
      " B  B  !!  B  B ",
      " !AA! !!!! !AA! ",
      "       !!       "
    ],
    [
      "!!!!!!!!!!!!!!!!",
      "!!!!!!!!!!!!!!!!",
      "!!!!!!!!!!!!!!!!",
      "!!!!!!!!!!!!!!!!",
      "!!!!!!!!!!!!!!!!",
      "!!!!!!!!!!!!!!!!",
      "!!!!!!!!!!!!!!!!",
      "!!!!!!!!!!!!!!!!",
      "!!!!!!!!!!!!!!!!",
      "!!!!!!!!!!!!!!!!",
      "!!!!!!!!!!!!!!!!",
      "!!!!!!!!!!!!!!!!",
      "!!!!!!!!!!!!!!!!",
      "!!!!!!!!!!!!!!!!",
      "!!!!!!!!!!!!!!!!",
      "!!!!!!!!!!!!!!!!"
    ],
    [
      "   B  B...   .B.",
      "   !AA! .     !A",
      "                ",
      "                ",
      "                ",
      "                ",
      "                ",
      "                ",
      "   !AA!       !A",
      "   B  B       B ",
      "   B  B       B ",
      "   !AA!       !A",
      "                ",
      "                ",
      "                ",
      "                "
    ],
    [
      "   =  =...   .=.",
      "   +((,..     +(",
      "                ",
      "                ",
      "                ",
      "                ",
      "                ",
      "                ",
      "   )((*       )(",
      "   =  =       = ",
      "   =  =       = ",
      "   +((,       +(",
      "                ",
      "                ",
      "                ",
      "                "
    ],
    [
      "   g  g..    .g.",
      "    ?>        .?",
      "                ",
      "                ",
      "                ",
      "                ",
      "                ",
      "                ",
      "    ?>         ?",
      "   f  f       f ",
      "   g  g       g ",
      "    ?>         ?",
      "                ",
      "                ",
      "                ",
      "                "
    ],
    [
      "   = .=.     .=.",
      "   +((,       +(",
      "                ",
      "                ",
      "                ",
      "                ",
      "                ",
      "                ",
      "   )((*       )(",
      "   =  =       = ",
      "   =  =       = ",
      "   +((,       +(",
      "                ",
      "                ",
      "                ",
      "                "
    ]
  ]
}