{
  "xsize": 16,
  "zsize": 16,
  "refpalette": "pomkotsmechs:offshore",
  "slices": [
    [
      "96,           / ",
      "= (?(((((((((>/ ",
      "=             / ",
      "=             / ",
      "=             / ",
      "=             / ",
      "=             / ",
      "=            !!!",
      "=             ! ",
      "=             !!",
      "=             / ",
      "=             / ",
      "=             / ",
      "=             / ",
      "=             / ",
      "= (?((((((((((/ "
    ],
    [
      " +,           / ",
      "              / ",
      "              / ",
      "              / ",
      "              / ",
      "              / ",
      "              / ",
      "             !!!",
      "              ! ",
      "              !!",
      "              / ",
      "              / ",
      "              / ",
      "              / ",
      "              / ",
      "              / "
    ],
    [
      " +,           / ",
      "              / ",
      "              / ",
      "              / ",
      "              / ",
      "              / ",
      "              / ",
      "             !!!",
      "              ! ",
      "              !!",
      "              / ",
      "              / ",
      "              / ",
      "              / ",
      "              / ",
      "              / "
    ],
    [
      " +,           / ",
      "              / ",
      "              / ",
      "              / ",
      "              / ",
      "              / ",
      "              / ",
      "             !!!",
      "              ! ",
      "              !!",
      "              / ",
      "              / ",
      "              / ",
      "              / ",
      "              / ",
      "              / "
    ],
    [
      " +,          !!!",
      "             !!!",
      "             !!!",
      "             !!!",
      "             !!!",
      "             !!!",
      "             !!!",
      "             !!!",
      "             !!!",
      "             !!!",
      "             !!!",
      "             !!!",
      "             !!!",
      "             !!!",
      "             !!!",
      "             !!!"
    ],
    [
      " +,          !!!",
      "             !!!",
      "             !!!",
      "             !!!",
      "             !!!",
      "             !!!",
      "             !!!",
      "             !!!",
      "             !!!",
      "             !!!",
      "             !!!",
      "             !!!",
      "             !!!",
      "             !!!",
      "             !!!",
      "             !!!"
    ]
  ]
}