{
  "xsize": 16,
  "zsize": 16,
  "refpalette": "pomkotsmechs:offshore",
  "slices": [
    [
      " %              ",
      " %              ",
      " %              ",
      " %              ",
      " %              ",
      " %              ",
      "!!!             ",
      " !              ",
      "!!              ",
      " %              ",
      " %              ",
      " %              ",
      " %              ",
      " %              ",
      " %              ",
      " %           )* "
    ],
    [
      " %              ",
      " %              ",
      " %              ",
      " %              ",
      " %              ",
      " %              ",
      "!!!             ",
      " !              ",
      "!!              ",
      " %              ",
      " %              ",
      " %              ",
      " %              ",
      " %              ",
      " %              ",
      " %           )* "
    ],
    [
      " %              ",
      " %              ",
      " %              ",
      " %              ",
      " %              ",
      " %              ",
      "!!!             ",
      " !              ",
      "!!              ",
      " %              ",
      " %              ",
      " %              ",
      " %              ",
      " %              ",
      " %              ",
      " %           )* "
    ],
    [
      " %              ",
      " %              ",
      " %              ",
      " %              ",
      " %              ",
      " %              ",
      "!!!             ",
      " !              ",
      "!!              ",
      " %              ",
      " %              ",
      " %              ",
      " %              ",
      " %              ",
      " %              ",
      " %           )* "
    ],
    [
      " %              ",
      " %              ",
      " %              ",
      " %              ",
      " %              ",
      " %              ",
      "!!!             ",
      " !              ",
      "!!              ",
      " %              ",
      " %              ",
      " %              ",
      " %              ",
      " %              ",
      " %              ",
      " %           $$ "
    ],
    [
      " %           $$5",
      " %           $$5",
      " %           $$5",
      " %           $$5",
      " %           $$5",
      " %           $$5",
      "!!!          $$5",
      " !           $$5",
      "!!           $$5",
      " %           $$5",
      " %           $$5",
      " %           $$5",
      " %           $$5",
      " %           $$5",
      " %33333333333$$5",
      " %$$$$$$$$$$$$$5"
    ]
  ]
}