{
  "xsize": 16,
  "zsize": 16,
  "refpalette": "pomkotsmechs:offshore",
  "slices": [
    [
      "$$D .D$$$D  D$$$",
      "DD$  $DDD$. $DDD",
      "DD$  $DDD$..$DDD",
      "DD$  $DDD$..$DDD",
      "$$D  D$$$D .D$$$",
      "            ..  ",
      "           ...  ",
      "$$D  D$$$D  D$$$",
      "DD$  $DDD$  $DDD",
      "DD$  $DDD$  $DDD",
      "DD$  $DDD$  $DDD",
      "$$D  D$$$D  D$$$",
      "                ",
      "                ",
      "                ",
      "                "
    ],
    [
      "DDD .DDDDD  DDDD",
      "DDD  DDDDD. DDDD",
      "DDD  DDDDD..DDDD",
      "DDD  DDDDD..DDDD",
      "DDD  DDDDD..DDDD",
      "            .   ",
      "           ...  ",
      "DDD  DDDDD  DDDD",
      "DDD  DDDDD .DDDD",
      "DDD  DDDDD .DDDD",
      "DDD  DDDDD .DDDD",
      "DDD  DDDDD  DDDD",
      "               .",
      "                ",
      "                ",
      "                "
    ],
    [
      "  &  &   &  &   ",
      "                ",
      "          .     ",
      "         ...    ",
      "  &  &   &. &   ",
      "            .   ",
      "           ...  ",
      "  &  &   & .&.  ",
      "           ...  ",
      "            .   ",
      "           .....",
      "  &  &   &  &...",
      "              ..",
      "                ",
      "                ",
      "                "
    ],
    [
      "DDD .DDDDD  DDDD",
      "DDD  DDDDD  DDDD",
      "DDD  DDDDD. DDDD",
      "DDD  DDDDD..DDDD",
      "DDD  DDDDD. DDDD",
      "                ",
      "            .   ",
      "DDD  DDDDD .DDDD",
      "DDD  DDDDD .DDDD",
      "DDD  DDDDD  DDD ",
      "DDD  DDDDD .DDD ",
      "DDD  DDDDD .DDD.",
      "            . . ",
      "                ",
      "                ",
      "                "
    ],
    [
      "$$D .D$$$D  D$$$",
      "  $  $$  $  $   ",
      "  $  $EE $. $E  ",
      "  $  $EE.$..$E  ",
      "$$D  D$$$D. D$$$",
      "                ",
      "            .   ",
      "$$D  D$$$D .D$$$",
      "  $  $$  $ .$.  ",
      "  $  $EE $  $E  ",
      "  $  $EE $  $E. ",
      "$$D  D$$$D .D$..",
      "            ... ",
      "                ",
      "                ",
      "                "
    ],
    [
      "$$D .D$$$D  D$$$",
      "  $  $$  $  $   ",
      "  $  $$  $  $   ",
      "  $  $$ .$. $   ",
      "$$D  D$$$D. D$$$",
      "         .      ",
      "                ",
      "$$D  D$$$D  D$$$",
      "  $  $$  $  $   ",
      "  $  $$  $  $   ",
      "  $  $$  $      ",
      "$$D  D$$$D  ... ",
      "                ",
      "                ",
      "                ",
      "                "
    ]
  ]
}