{
  "xsize": 16,
  "zsize": 16,
  "refpalette": "pomkotsmechs:offshore",
  "slices": [
    [
      "                ",
      "     $          ",
      "                ",
      "                ",
      "     $          ",
      "     $          ",
      "                ",
      "                ",
      "     $          ",
      "                ",
      "                ",
      "     $  $  $$  $",
      "    !           ",
      "                ",
      "                ",
      "                "
    ],
    [
      "     $$$$$$$$$$$",
      "     $$$$$$$$$$$",
      "     $$$$$$$$$$$",
      "     $$$$$$$$$$$",
      "     $$$$$$$$$$$",
      "     $$$$$$$$$$$",
      "     $$$$$$$$$$$",
      "     $$$$$$$$$$$",
      "     $$$$$$$$$$$",
      "     $$$$$$$$$$$",
      "     $$$$$$$$$$$",
      "     $$$$$$$$$$$",
      "    !           ",
      "                ",
      "                ",
      "                "
    ],
    [
      "!!!!DDDDDDDDDDDD",
      "!!!!DDDDDDDDDDDD",
      "!!!!DDDDDDDDDDDD",
      "!!!!DDDDDDDDDDDD",
      "!!!!DDDDDDDDDDDD",
      "!!!!DDDDDDDDDDDD",
      "!!!!DDDDDDDDDDDD",
      "!!!!DDDDDDDDDDDD",
      "!!!!DDDDDDDDDDDD",
      "!!!!DDDDDDDDDDDD",
      "!!!!DDDDDDDDDDDD",
      "!!!!DDDDDDDDDDDD",
      "!!!!DDDDDDDDDDDD",
      "!!!!!!!!!!!!!!!!",
      "!!!!!!!!!!!!!!!!",
      "!!!!!!!!!!!!!!!!"
    ],
    [
      "    =    DD!ADD ",
      " !AA=   $$$B $$$",
      " B  =  D$$$B $$$",
      " B  = !D$$$$$$$$",
      " !AA=  !$$$$$$$$",
      "    =  !$$$$$$$$",
      " !  = !D$$$$$$$$",
      "!!! =  D$$$$$$$$",
      "!!! =   $$$$$$$$",
      " !  =    DD!ADD ",
      "    =           ",
      " !AA=         ! ",
      " B  !(((((((((((",
      " B  B  !!  B  B ",
      " !AA! !!!! !AA! ",
      "       !!       "
    ],
    [
      "    *    DD)(DD ",
      " )((=   $$$= $$$",
      " =  =  D$  =  =$",
      " =  ,  D$  +((,$",
      " +((    $      $",
      "        $      $",
      "    *  D$  )((*$",
      " !  =  D$  =  =$",
      " !  =   $$$$$$$$",
      "    ,    DD+(DD ",
      "                ",
      " )((            ",
      " =  !         ! ",
      " =  =      =  = ",
      " +((,  !!  +((, ",
      "                "
    ],
    [
      "    *     D)(D* ",
      " )((=   $  =  =$",
      " =  =      =  = ",
      " =  ,  !!  +((, ",
      " +((    $      $",
      "        $      $",
      "    *  !!  )((* ",
      " !  =      =  = ",
      " !  =   $  $$ =$",
      "    ,      +((, ",
      "                ",
      " )((            ",
      " =            ! ",
      " =  =      =  = ",
      " +((,  !!  +((, ",
      "                "
    ]
  ]
}