{
  "xsize": 16,
  "zsize": 16,
  "refpalette": "pomkotsmechs:offshore",
  "slices": [
    [
      "                ",
      "  )((*  !!  )(**",
      "  =  =      = ==",
      "  =  =      = ==",
      "  +((,      +(,,",
      "                ",
      "                ",
      "  !           !!",
      "  !           !!",
      "                ",
      "                ",
      "  )((*      )(**",
      "  =  =      = ==",
      "  =  =      = ==",
      "  +((,  !!  +(,,",
      "                "
    ],
    [
      "        !!      ",
      "  !AA! !!!! !A!!",
      "  B  B  !!  B BB",
      "  B  B      B BB",
      "  !AA!      !A!!",
      "                ",
      "  !           !!",
      "!!!!         !!!",
      "!!!!         !!!",
      "  !           !!",
      "                ",
      "  !AA!      !A!!",
      "  B  B      B BB",
      "  B  B  !!  B BB",
      "  !AA! !!!! !A!!",
      "        !!      "
    ],
    [
      "!!!!!!!!!!!!!!!!",
      "!!!!!!!!!!!!!!!!",
      "!!!!!!!!!!!!!!!!",
      "!!!!!!!!!!!!!!!!",
      "!!!!!!!!!!!!!!!!",
      "!!!!!!!!!!!!!!!!",
      "!!!!!!!!!!!!!!!!",
      "!!!!!!!!!!!!!!!!",
      "!!!!!!!!!!!!!!!!",
      "!!!!!!!!!!!!!!!!",
      "!!!!!!!!!!!!!!!!",
      "!!!!!!!!!!!!!!!!",
      "!!!!!!!!!!!!!!!!",
      "!!!!!!!!!!!!!!!!",
      "!!!!!!!!!!!!!!!!",
      "!!!!!!!!!!!!!!!!"
    ],
    [
      "                ",
      "                ",
      "                ",
      "                ",
      "                ",
      "                ",
      "                ",
      "                ",
      "                ",
      "                ",
      "                ",
      "                ",
      "                ",
      "                ",
      "             !!!",
      "             !!!"
    ],
    [
      "                ",
      "                ",
      "                ",
      "                ",
      "                ",
      "                ",
      "                ",
      "                ",
      "                ",
      "                ",
      "                ",
      "                ",
      "                ",
      "                ",
      "               !",
      "              !!"
    ],
    [
      "                ",
      "                ",
      "                ",
      "                ",
      "                ",
      "                ",
      "                ",
      "                ",
      "                ",
      "                ",
      "                ",
      "                ",
      "                ",
      "                ",
      "               !",
      "              !!"
    ]
  ]
}