{
  "xsize": 16,
  "zsize": 16,
  "refpalette": "pomkotsmechs:offshore",
  "slices": [
    [
      "   E  )(*iE     ",
      " EEEEE=EElEE    ",
      " EEEEE+EE EE    ",
      "   E!    !E     ",
      " EE!EEEEEEEE    ",
      " EE EE EE EE    ",
      "                ",
      "!            !  ",
      "                ",
      "                ",
      "                ",
      "                ",
      "!            !  ",
      " EE EE EE EE    ",
      " EE EE EE EE    ",
      "   !EEEEEE!     "
    ],
    [
      ".  !EE)(*E!     ",
      " EE!EE=EEiEE    ",
      " EE!EE+EElEE    ",
      "   !EEEEE&!     ",
      " EE!EE!EE!EE    ",
      " EE EE EE EE    ",
      "&            &  ",
      "!&          &!& ",
      "&            &  ",
      "                ",
      "                ",
      "&            &  ",
      "!&          &!& ",
      "&EE EE EE EE &  ",
      " EE EE EE EE    ",
      "   !!!!!!!!     "
    ],
    [
      "!!!!!!!!!E!!!!! ",
      "!!!!!!!E!E!!!!! ",
      "!!!!!!!!!i!!!!! ",
      "!!!!!!!jkI!!!!! ",
      "!!!!!!!!!!!!!!! ",
      "!!!!!!!!!!!!!!! ",
      "!!!!!!!!!!!!!!! ",
      "!!!!!!!!!!!!!!! ",
      "!!!!!!!!!!!!!!! ",
      "                ",
      "                ",
      "!!!!!!!!!!!!!!! ",
      "!!!!!!!!!!!!!!! ",
      "!!!!!!!!!!!!!!! ",
      "!!!!!!!!!!!!!!! ",
      "!!!!!!!!!!!!!!! "
    ],
    [
      ". !E!!!!!!E!    ",
      " !!E!!=!!!!!    ",
      " !!E!!!!!!!!    ",
      "  !E!!!!!!E!    ",
      " !!E!!E!!E!!    ",
      "!!!!!!!!!!!!    ",
      "&&          &&& ",
      "!&          &!& ",
      "&&          &&& ",
      "                ",
      "                ",
      "&&          &&& ",
      "!&          &!& ",
      "&!! !! !! !!&&& ",
      " !!!!!!!!!!!    ",
      "  !EEEEEEEE!    "
    ],
    [
      ".  E  )(* E     ",
      " EEEEE=EE EE    ",
      " EEEEE+EE EE    ",
      "   ED    DE     ",
      " EEEEEEEEEEE    ",
      " EE EE EE EE    ",
      "&            &  ",
      "!&          &!& ",
      "&            &  ",
      "                ",
      "                ",
      "&            &  ",
      "!&          &!& ",
      "&EE EE EE EE &  ",
      " EE EE EE EE    ",
      "   EEEEEEEE     "
    ],
    [
      ". !E!!)(*lE!    ",
      ".EEEEE=EE!EE    ",
      " EEEEEgEE!EE    ",
      "  !E!!!!!!E!    ",
      " EEEEEEEEEEE    ",
      " EE!EE!EE!EE    ",
      "                ",
      "!            !  ",
      "                ",
      "                ",
      "                ",
      "                ",
      "!            !  ",
      " EE EE EE EE    ",
      " EE!EE!EE!EE    ",
      "  !EEEEEEEE!    "
    ]
  ]
}