{
  "xsize": 16,
  "zsize": 16,
  "refpalette": "lostcities:offshore",
  "slices": [
    [
      "=             / ",
      "=             / ",
      "=             / ",
      "93*          !/ ",
      "9<5          !!!",
      "+66((((((((((!!!",
      "!!  !!        ! ",
      "!!!!!!--------! ",
      "!!  !!        ! ",
      "                ",
      "                ",
      "                ",
      "                ",
      "                ",
      "                ",
      "                "
    ],
    [
      "              / ",
      "              / ",
      "              / ",
      " )*          !/ ",
      " +,          !!!",
      "             !!!",
      "!!  !!        ! ",
      "!!!!!!--------! ",
      "!!  !!        ! ",
      "                ",
      "                ",
      "                ",
      "                ",
      "                ",
      "                ",
      "                "
    ],
    [
      "              / ",
      "              / ",
      "              / ",
      " )*          !/ ",
      " +,          !!!",
      "             !!!",
      "!!  !!        ! ",
      "!!!!!!--------! ",
      "!!  !!        !!",
      "                ",
      "                ",
      "                ",
      "                ",
      "                ",
      "                ",
      "                "
    ],
    [
      "              / ",
      "              / ",
      "              / ",
      " )*          !/ ",
      " +,          !!!",
      "             !!!",
      "!!  !!        ! ",
      "!!!!!!--------! ",
      "!!  !!        !&",
      "                ",
      "                ",
      "                ",
      "                ",
      "                ",
      "                ",
      "                "
    ],
    [
      "             !!!",
      "             !!!",
      "             !!!",
      " )*          !!!",
      " +,          !!!",
      "             !!!",
      "!!!!!!!!!!!!!!!!",
      "!!!!!!!!!!!!!!!!",
      "!!  !!!!!!!!!!!&",
      "                ",
      "                ",
      "                ",
      "                ",
      "                ",
      "                ",
      "                "
    ],
    [
      "             !!!",
      "             !!!",
      "             !!!",
      " )*          !!!",
      " +,          !!!",
      "             !!!",
      "!!!!!!!!!!!!!!!!",
      "!!!!!!!!!!!!!!!!",
      "!!  !!!!!!!!!!!!",
      "                ",
      "                ",
      "                ",
      "                ",
      "                ",
      "                ",
      "                "
    ]
  ]
}