{
  "xsize": 16,
  "zsize": 16,
  "refpalette": "pomkotsmechs:offshore",
  "slices": [
    [
      "            $   ",
      "            $   ",
      "            $   ",
      "            $   ",
      "           $$   ",
      "            $   ",
      "            $$$$",
      "             $  ",
      "          !     ",
      "         !!!    ",
      "        !!!!!   ",
      "         !!!    ",
      "          !     ",
      "               #",
      "              #!",
      "             #!#"
    ],
    [
      "            $   ",
      "            $   ",
      "            $   ",
      "            $   ",
      "           $$   ",
      "            $   ",
      "            $$$$",
      "             $  ",
      "          !     ",
      "         !!!    ",
      "        !!!!!   ",
      "         !!!!!!!",
      "          !!!!!!",
      "           !!!! ",
      "           !!! !",
      "           !! ! "
    ],
    [
      "!  !!!!!!!! $   ",
      "   !!!!!!!! $   ",
      "    !!!!!!! $   ",
      "    !!!!!!! $   ",
      "    !!!!!!!$$   ",
      "    !!!!!!! $   ",
      "    !!!!!!! $$$$",
      "   !!!!!!!!  $!!",
      "   !!!!!!!!!!!!!",
      "   !!!!!!!!!!!!!",
      "    !!!!!!!!!!!!",
      "   !!!!!!!!!!!!!",
      "!  !!!!!!!!!!!!!",
      "!   !!!!!!!!!!!!",
      "    !!!!!!!!!!!!",
      "    !!!!!!!!!!!!"
    ],
    [
      "       !!   $   ",
      "   A! !!!!  $   ",
      "    B  !!   $   ",
      "    B       $   ",
      "   A!      $$   ",
      "            $   ",
      "            $$$$",
      "             $!!",
      "             !!!",
      "              ! ",
      "                ",
      "   A!      !AA! ",
      "    B      B  B ",
      "    B  !!  B  B ",
      "    ! !!!! !AA! ",
      "       !!       "
    ],
    [
      "            $   ",
      "  ((*  !!   $   ",
      "    =       $   ",
      "    =       $   ",
      "  ((,      $$   ",
      "            $   ",
      "            $$$$",
      "             $! ",
      "              ! ",
      "                ",
      "                ",
      "  ((*      )((* ",
      "    =      =  = ",
      "    =      =  = ",
      "   (,  !!  +((, ",
      "                "
    ],
    [
      "            $   ",
      " )((*  !!   $   ",
      " =  =       $   ",
      " =  =       $   ",
      " +((,      $$   ",
      "            $   ",
      "            $$$$",
      " !           $! ",
      " !            ! ",
      "                ",
      "                ",
      " )((*      )((* ",
      " =  =      =  = ",
      " =  =      =  = ",
      " +((,  !!  +((, ",
      "                "
    ]
  ]
}