{
  "xsize": 16,
  "zsize": 16,
  "refpalette": "lostcities:offshore",
  "slices": [
    [
      "                ",
      "                ",
      "                ",
      "                ",
      "                ",
      "                ",
      "                ",
      "                ",
      "                ",
      "                ",
      "                ",
      "                ",
      "                ",
      "                ",
      "                ",
      "                "
    ],
    [
      "                ",
      "                ",
      "                ",
      "                ",
      "                ",
      "                ",
      "                ",
      "                ",
      "                ",
      "                ",
      "                ",
      "                ",
      "                ",
      "                ",
      "                ",
      "                "
    ],
    [
      "!!!!!!!!!!!!!!!!",
      "!!!!!!!!!!!!!!!!",
      "!!!!!!!!!!!!!!!!",
      "!!!!!!!!!!!!!!!!",
      "!!!!!!!!!!!!!!!!",
      "!!!!!!!!!!!!!!!!",
      "!!!!!!!!!!!!!!!!",
      "!!!!!!!!!!!!!!!!",
      "!!!!!!!!!!!!!!!!",
      "!!!!!!!!!!!!!!!!",
      "!!!!!!!!!!!!!!!!",
      "!!!!!!!!!!!!!!!!",
      "!!!!!!!!!!!!!!!!",
      "!!!!!!!!!!!!!!!!",
      "!!!!!!!!!!!!!!!!",
      "!!!!!!!!!!!!!!!!"
    ],
    [
      "        !!      ",
      " !AAA! !!!! !AA!",
      " B   B  !!  B  B",
      " B   B      B  B",
      " !AAA!      !AA!",
      "                ",
      " !             !",
      "!!!           !!",
      "!!          !!  ",
      " !           !  ",
      "                ",
      " !A!      !AA! !",
      " B B      B  B B",
      " B B  !!  B  B B",
      " !A! !!!! !AA! !",
      "      !!        "
    ],
    [
      "                ",
      " )(((*  !!  )((*",
      " =   =      =  =",
      " =   =      =  =",
      " +(((,      +((,",
      "                ",
      "                ",
      " !             !",
      " !           !  ",
      "                ",
      "                ",
      " )(*      )((* )",
      " = =      =  = =",
      " = =      =  = =",
      " +(,  !!  +((, +",
      "                "
    ],
    [
      "                ",
      " )(((*  !!  )((*",
      " =   =      =  =",
      " =   =      =  =",
      " +(((,      +((,",
      "                ",
      "                ",
      " !             !",
      " !           !  ",
      "                ",
      "                ",
      " )(*      )((* )",
      " = =      =  = =",
      " = =      =  = =",
      " +(,  !!  +((, +",
      "                "
    ]
  ]
}