{
  "xsize": 16,
  "zsize": 16,
  "refpalette": "lostcities:offshore",
  "slices": [
    [
      "                ",
      "                ",
      "                ",
      "                ",
      "                ",
      "            )   ",
      "            +   ",
      "                ",
      "     !          ",
      "    !!!         ",
      "   !!!!!        ",
      "    !!!         ",
      "     !          ",
      "#               ",
      "!#              ",
      "#!#             "
    ],
    [
      "MMM             ",
      "                ",
      "                ",
      "                ",
      "                ",
      "            )   ",
      "            +   ",
      "                ",
      "     !          ",
      "    !!!         ",
      "   !!!!!        ",
      "!!!!!!!         ",
      "!!!!!!          ",
      " !!!!           ",
      "! !!!           ",
      " ! !!           "
    ],
    [
      "             !!!",
      "             !!!",
      "             !!!",
      "             !!!",
      "             !!!",
      "            )!!!",
      "            +!!!",
      "!!!!!!!!!!!!!!!!",
      "!!!!!!!!!!!!!!!!",
      "!!!!!!!!!!!!!!!!",
      "!!!!!!!!!!!!!!!!",
      "!!!!!!!!!!!!!!!!",
      "!!!!!!!!!!!!!!!!",
      "!!!!!!!!!!!!!!!!",
      "!!!!!!!!!!!!!!!!",
      "!!!!!!!!!!!!!!!!"
    ],
    [
      "                ",
      "             A! ",
      "              B ",
      "              B ",
      "             A! ",
      "            )   ",
      "            + ! ",
      "!!!          !!!",
      "!!!          !!!",
      " !            ! ",
      "                ",
      " !AA!      !AA! ",
      " B  B      B  B ",
      " B  B  !!  B  B ",
      " !AA! !!!! !AA! ",
      "       !!       "
    ],
    [
      "                ",
      "             (* ",
      "              = ",
      "              = ",
      "             (, ",
      "            )   ",
      "            +   ",
      " !            ! ",
      " !            ! ",
      "                ",
      "                ",
      " )((*      )((* ",
      " =  =      =  = ",
      " =  =      =  = ",
      " +((,  !!  +((, ",
      "                "
    ],
    [
      "                ",
      "             (* ",
      "              = ",
      "              = ",
      "             (, ",
      "            )   ",
      "            +   ",
      " !            ! ",
      " !            ! ",
      "                ",
      "                ",
      " )((*      )((* ",
      " =  =      =  = ",
      " =  =      =  = ",
      " +((,  !!  +((, ",
      "                "
    ]
  ]
}