{
  "xsize": 16,
  "zsize": 16,
  "refpalette": "lostcities:offshore",
  "slices": [
    [
      " %           )* ",
      " %           +, ",
      " %              ",
      " %              ",
      " %              ",
      " %              ",
      " %              ",
      " %              ",
      "!!              ",
      " !              ",
      "!!!             ",
      " %              ",
      " %              ",
      " %              ",
      " %              ",
      " %              "
    ],
    [
      " %           )* ",
      " %           +, ",
      " %              ",
      " %              ",
      " %              ",
      " %              ",
      " %              ",
      " %              ",
      "!!              ",
      " !              ",
      "!!!             ",
      " %              ",
      " %              ",
      " %              ",
      " %              ",
      " %              "
    ],
    [
      " %           )* ",
      " %           +, ",
      " %              ",
      " %              ",
      " %              ",
      " %              ",
      " %              ",
      " %              ",
      "!!              ",
      " !              ",
      "!!!             ",
      " %              ",
      " %              ",
      " %              ",
      " %              ",
      " %              "
    ],
    [
      " %           )* ",
      " %           +, ",
      " %              ",
      " %              ",
      " %              ",
      " %              ",
      " %              ",
      " %              ",
      "!!              ",
      " !              ",
      "!!!             ",
      " %              ",
      " %              ",
      " %              ",
      " %              ",
      " %              "
    ],
    [
      " %           $$ ",
      " %           $$ ",
      " %              ",
      " %              ",
      " %              ",
      " %              ",
      " %              ",
      " %              ",
      "!!              ",
      " !              ",
      "!!!             ",
      " %              ",
      " %              ",
      " %              ",
      " %              ",
      " %              "
    ],
    [
      " %$$$$$$$$$$$$$5",
      " %$$$$$$$$$$$$$5",
      " %+6666666666$$5",
      " %           $$5",
      " %           $$5",
      " %           $$5",
      " %           $$5",
      " %           $$5",
      "!!           $$5",
      " !           $$5",
      "!!!          $$5",
      " %           $$5",
      " %           $$5",
      " %           $$5",
      " %           $$5",
      " %           $$5"
    ]
  ]
}