{
  "xsize": 16,
  "zsize": 16,
  "refpalette": "pomkotsmechs:offshore",
  "slices": [
    [
      "          !  #!#",
      "          !   #!",
      "          !    #",
      "          !     ",
      "         !!!    ",
      "        !!!!!   ",
      "         !!!    ",
      "          !     ",
      "                ",
      "                ",
      "                ",
      "                ",
      "                ",
      "                ",
      "                ",
      "                "
    ],
    [
      "           !! ! ",
      "           !!! !",
      "           !!!! ",
      "          !!!!!!",
      "         !!!!!!!",
      "        !!!!!   ",
      "         !!!    ",
      "          !     ",
      "                ",
      "                ",
      "                ",
      "                ",
      "                ",
      "                ",
      "                ",
      "                "
    ],
    [
      "           !!#!#",
      "           !!###",
      "           !!   ",
      "         !!!!   ",
      "        !!!!!   ",
      "        !!!!!   ",
      "        !!!!!   ",
      "         !!!    ",
      "                ",
      "                ",
      "                ",
      "                ",
      "                ",
      "                ",
      "                ",
      "                "
    ],
    [
      "!!!!!!!!!!!!!!!!",
      "!!!!!!!!!!!!!!!!",
      "!!!!!!!!!!!!!!!!",
      "!!!!!!!!!!!!!!!!",
      "!!!!!!!!!!!!!!!!",
      "!!!!!!!!!!!!!!!!",
      "!!!!!!!!!!!!!!!!",
      "!!!!!!!!!!!!!!!!",
      "!!!!!!!!!!!!!!!!",
      "!!!!!!!!!!!!!!!!",
      "!!!!!!!!!!!!!!!!",
      "!!!!!!!!!!!!!!!!",
      "!!!!!!!!!!!!!!!!",
      "!!!!!!!!!!!!!!!!",
      "!!!!!!!!!!!!!!!!",
      "!!!!!!!!!!!!!!!!"
    ],
    [
      "       !!!    ! ",
      " !AA!!!!!!!!AAA!",
      " BB BB !!! BB  B",
      " BB BB    !BB  B",
      " !AA!!   !!!AAA!",
      "        !!!!!   ",
      " !!      !!!   !",
      "!!!!      !   !!",
      "!!!!          !!",
      " !!            !",
      "                ",
      " !AA!!     !AAA!",
      " BB BB     BB  B",
      " BB BB !!! BB  B",
      " !AA!!!!!!!!AAA!",
      "       !!!      "
    ],
    [
      "          !   ! ",
      " )((** !!!!)(((*",
      " == ==    !==  =",
      " == ==    !==  =",
      " +((,,   !!+(((,",
      "        !!!!!!!!",
      "         !!!    ",
      " !!       !    !",
      " !!            !",
      "                ",
      "                ",
      " )((**     )(((*",
      " == ==     ==  =",
      " == ==     ==  =",
      " +((,, !!! +(((,",
      "                "
    ]
  ]
}