{
  "xsize": 16,
  "zsize": 16,
  "refpalette": "lostcities:offshore",
  "slices": [
    [
      " !              ",
      "! )((*  !!  )((*",
      "  =  =      =  =",
      "  =  =      =  =",
      "  +((,!     +((,",
      "   !!!!!        ",
      "    !!!         ",
      "  !  !         !",
      "  !            !",
      "                ",
      "                ",
      "  )((*      )((*",
      "  =  =      =  =",
      "  =  =      =  =",
      "  +((,  !!  +((,",
      "                "
    ],
    [
      " !      !!      ",
      "! !AA! !!!! !AA!",
      "  B  B  !!  B  B",
      "  B  B      B  B",
      "  !AA!!     !AA!",
      "   !!!!!        ",
      "  ! !!!        !",
      "!!!! !        !!",
      "!!!!          !!",
      "  !            !",
      "                ",
      "  !AA!      !AA!",
      "  B  B      B  B",
      "  B  B  !!  B  B",
      "  !AA! !!!! !AA!",
      "        !!      "
    ],
    [
      "$$$$$$$$$$$$$$$$",
      "$$$$$$$$$$$$$$$$",
      "$$$$$$$$$$$$$$$$",
      "$$$$$$$$$$$$$$$$",
      "$$$$$$$$$$$$$$$$",
      "$$$$$$$$$$$$$$$$",
      "!!!!!!!!!!!!!!!!",
      "!!!!!!!!!!!!!!!!",
      "!!!!!!!!!!!!!!!!",
      "!!!!!!!!!!!!!!!!",
      "!!!!!!!!!!!!!!!!",
      "!!!!!!!!!!!!!!!!",
      "!!!!!!!!!!!!!!!!",
      "!!!!!!!!!!!!!!!!",
      "!!!!!!!!!!!!!!!!",
      "!!!!!!!!!!!!!!!!"
    ],
    [
      "$$$             ",
      "$$$       &   & ",
      "$$$             ",
      "$$$  !          ",
      "$$$ !!!         ",
      "$$$!!!!!  &   & ",
      "$$$ !!!         ",
      "$$$  !          ",
      "$$$             ",
      "$$$             ",
      "$$$             ",
      "$$$             ",
      "                ",
      "                ",
      "                ",
      "                "
    ],
    [
      "  $             ",
      "  $       DDDDD ",
      "  $       DDDDD ",
      "  $  !    DDDDD ",
      "  $ !!!   DDDDD ",
      "  $!!!!!  DDDDD ",
      "  $ !!!         ",
      "  $  !          ",
      "  $             ",
      "  $             ",
      "  $             ",
      "$$$             ",
      "DD              ",
      "                ",
      "                ",
      "                "
    ],
    [
      "     !          ",
      "  $  !    D$$$D ",
      "     !    $EE $ ",
      "     !    $   $ ",
      "  $ !!!   $   $ ",
      "  $!!!!!  D$$$D ",
      "    !!!         ",
      "     !          ",
      "  $             ",
      "                ",
      "                ",
      "  $             ",
      "                ",
      "                ",
      "                ",
      "                "
    ]
  ]
}