{
  "xsize": 16,
  "zsize": 16,
  "refpalette": "lostcities:offshore",
  "slices": [
    [
      "  D$$$D. D$$$D  ",
      "      ...       ",
      "       ..   ..  ",
      "  D$$$D  D$$$D. ",
      "  $$$$$  $$$$$. ",
      " .$   $  $   $  ",
      "..$   $  $   $  ",
      " .D$$$D  D$$$D  ",
      "                ",
      "                ",
      "  D$$$D  D$$$D  ",
      "  $   $  $   $  ",
      "  $   $  $   $  ",
      "  $   $  $   $  ",
      "  D$$$D  D$$$D  ",
      "                "
    ],
    [
      "  D$$$D..D$$$D  ",
      "      ....      ",
      "      ....   .  ",
      "  D$$$D..D$$$D. ",
      "  $DDD$  $DDD$  ",
      " .$DDD$  $DDD$  ",
      "..$DDD$  $DDD$  ",
      "..D$$$D  D$$$D  ",
      " .              ",
      "                ",
      "  D$$$D  D$$$D  ",
      "  $DDD$  $DDD$  ",
      "  $DDD$  $DDD$  ",
      "  $DDD$  $DDD$  ",
      "  D$$$D  D$$$D  ",
      "                "
    ],
    [
      "  DDDDD .DDDDD  ",
      "       ....     ",
      "      ....      ",
      "  DDDDD..DDDDD  ",
      "  DDDDD. DDDDD  ",
      "  DDDDD  DDDDD  ",
      " .DDDDD  DDDDD  ",
      "..DDDDD  DDDDD  ",
      " .              ",
      "                ",
      "  DDDDD  DDDDD  ",
      "  DDDDD  DDDDD  ",
      "  DDDDD  DDDDD  ",
      "  DDDDD  DDDDD  ",
      "  DDDDD  DDDDD  ",
      "                "
    ],
    [
      "  &   & .&..    ",
      "        ...     ",
      "       ...      ",
      "  &   &..&   &  ",
      "      ..        ",
      "                ",
      " .              ",
      "..&   &  &   &  ",
      " ..             ",
      "                ",
      "  &   &  &   &  ",
      "                ",
      "                ",
      "                ",
      "  &   &  &   &  ",
      "                "
    ],
    [
      "  DDDDD  DDD    ",
      "        . .     ",
      "      ....      ",
      "  DDDDD..DDDD   ",
      "  DDDDD..DDDDD  ",
      "  DDDDD  DDDDD  ",
      " .DDDDD  DDDDD  ",
      "..DDDDD  DDDDD  ",
      " ...            ",
      "  .             ",
      "  DDDDD  DDDDD  ",
      "  DDDDD  DDDDD  ",
      "  DDDDD  DDDDD  ",
      "  DDDDD  DDDDD  ",
      "  DDDDD  DDDDD  ",
      "                "
    ],
    [
      "  D$$$D  D$..   ",
      "          ..    ",
      "        ..      ",
      "  D$$$D..D$$    ",
      "  $EE$$. $EE$   ",
      "  $EE $  $E     ",
      "  $   $  $      ",
      " .D$$$D  D$$$D  ",
      " ...            ",
      "  .             ",
      "  D$$$D  D$$$D  ",
      "  $EE $  $EE $  ",
      "  $   $  $   $  ",
      "  $   $  $   $  ",
      "  D$$$D  D$$$D  ",
      "                "
    ]
  ]
}