{
  "xsize": 16,
  "zsize": 16,
  "refpalette": "pomkotsmechs:offshore",
  "slices": [
    [
      "       !!       ",
      "AA!A! !!!! !AA! ",
      "  B B  !!  B  B ",
      "  B B      B  B ",
      "AA!A!      !AA! ",
      "                ",
      "!!!           ! ",
      "!!!          !!!",
      "!!!          !!!",
      " !            ! ",
      "                ",
      " !AA!      !AA! ",
      " B  B      B  B ",
      "!!! B  !!  B  B ",
      " ! A! !!!! !AA! ",
      "       !!       "
    ],
    [
      "DDDDDDDDDDDDDDDD",
      "DDDDDDDDDDDDDDDD",
      "DDDDDDDDDDDDDDDD",
      "DDDDDDDDDDDDDDDD",
      "DDDDDDDDDDDDDDDD",
      "!!!!!!!!!!!!!!!!",
      "!!!!!!!!!!!!!!!!",
      "!!!!!!!!!!!!!!!!",
      "!!!!!!!!!!!!!!!!",
      "!!!!!!!!!!!!!!!!",
      "!!!!!!!!!!!!!!!!",
      "!!!!!!!!!!!!!!!!",
      "!!!!!!!!!!!!!!!!",
      "!!!!!!!!!!!!!!!!",
      "!!!!!!!!!!!!!!!!",
      "!!!!!!!!!!!!!!!!"
    ],
    [
      "                ",
      "                ",
      "                ",
      "                ",
      "                ",
      "                ",
      "                ",
      "                ",
      "                ",
      "                ",
      "                ",
      "                ",
      "                ",
      "                ",
      "DDD             ",
      "DDD             "
    ],
    [
      "                ",
      "                ",
      "                ",
      "                ",
      "                ",
      "                ",
      "                ",
      "                ",
      "                ",
      "                ",
      "                ",
      "                ",
      "                ",
      "                ",
      "(($             ",
      "  =             "
    ],
    [
      "                ",
      "                ",
      "                ",
      "                ",
      "                ",
      "                ",
      "                ",
      "                ",
      "                ",
      "                ",
      "                ",
      "                ",
      "                ",
      "                ",
      "                ",
      "                "
    ],
    [
      "                ",
      "                ",
      "                ",
      "                ",
      "                ",
      "                ",
      "                ",
      "                ",
      "                ",
      "                ",
      "                ",
      "                ",
      "                ",
      "                ",
      "                ",
      "                "
    ]
  ]
}