{
  "xsize": 16,
  "zsize": 16,
  "refpalette": "pomkotsmechs:offshore",
  "slices": [
    [
      "#!#             ",
      "!#              ",
      "#               ",
      "     !          ",
      "    !!!         ",
      "   !!!!!        ",
      "    !!!         ",
      "            )   ",
      "            +   ",
      "                ",
      "                ",
      "                ",
      "                ",
      "                ",
      "                ",
      "                "
    ],
    [
      " ! !!           ",
      "! !!!           ",
      " !!!!           ",
      "!!!!!!          ",
      "!!!!!!!         ",
      "   !!!!!        ",
      "    !!!         ",
      "            )   ",
      "            +   ",
      "                ",
      "                ",
      "                ",
      "                ",
      "                ",
      "MMM             ",
      "MMMMM           "
    ],
    [
      "!!!!!!!!!!!!!!!!",
      "!!!!!!!!!!!!!!!!",
      "!!!!!!!!!!!!!!!!",
      "!!!!!!!!!!!!!!!!",
      "!!!!!!!!!!!!!!!!",
      "!!!!!!!!!!!!!!!!",
      "!!!!!!!!!!!!!!!!",
      "            )!!!",
      "            +!!!",
      "             !!!",
      "             !!!",
      "             !!!",
      "             !!!",
      "             !!!",
      "             !!!",
      "             !!!"
    ],
    [
      "       !!      .",
      " !AA! !!!! !AA! ",
      " B  B  !!  B  B ",
      " B  B      B  B ",
      " !AA!      !AA! ",
      "                ",
      " !            ! ",
      "            )!!!",
      "            +!!!",
      "              ! ",
      "                ",
      "             A! ",
      "              B ",
      "              B ",
      "             A! ",
      "                "
    ],
    [
      "               .",
      " )((*  !!  )((* ",
      " =  =      =  = ",
      " =  =      =  = ",
      " +((,      +((, ",
      "                ",
      "                ",
      "            ) ! ",
      "            + ! ",
      "                ",
      "                ",
      "             (* ",
      "              = ",
      "              = ",
      "             (, ",
      "                "
    ],
    [
      "               .",
      " )((*  !!  )((* ",
      " =  =      =  = ",
      " =  =      =  = ",
      " +((,      +((, ",
      "                ",
      "                ",
      "            ) ! ",
      "            + ! ",
      "                ",
      "                ",
      "             (* ",
      "              = ",
      "              = ",
      "             (, ",
      "                "
    ]
  ]
}