{
  "xsize": 16,
  "zsize": 16,
  "refpalette": "pomkotsmechs:offshore",
  "slices": [
    [
      "                ",
      "                ",
      "                ",
      "                ",
      " !     !!!!!!!! ",
      " !!   !!!!!!!!! ",
      " !!   !!!!!!!!! ",
      " !    .!!!!!!!! ",
      " !!   !!!!!!!!! ",
      " !!  .!!!!!!!!! ",
      "    ...!!!!!!!! ",
      " !!. .!!!!!!!!! ",
      " !!!.!!!!!!!!!! ",
      " !!!!!!!!!!!!!! ",
      " !!!!!!!!!!!!!! ",
      " !!!!!!!!!!!!!! "
    ],
    [
      "                ",
      "                ",
      "                ",
      "                ",
      "                ",
      "      E  EE EE  ",
      "      E..EE EE  ",
      "      ...       ",
      "     .E..EE EE  ",
      "     .E. EE EE  ",
      "    ....        ",
      "   . .E  EE EE  ",
      "  EE.EE  EE EE  ",
      " ....           ",
      "  EE EE  EE EE  ",
      "  EE EE  EE EE  "
    ],
    [
      "                ",
      "                ",
      "                ",
      "                ",
      "                ",
      "      E  EE EE  ",
      "      E  EE EE  ",
      "      ..        ",
      "     .E. EE EE  ",
      "     .E. EE EE  ",
      "     ..         ",
      "      E  EE EE  ",
      "  E. EE  EE EE  ",
      "  ..            ",
      "  EE EE  EE EE  ",
      "  EE EE  EE EE  "
    ],
    [
      "                ",
      "                ",
      "                ",
      "                ",
      "                ",
      "                ",
      "                ",
      "                ",
      "      .         ",
      "      .         ",
      "                ",
      "                ",
      "                ",
      "                ",
      "                ",
      "                "
    ],
    [
      "                ",
      "                ",
      "                ",
      "                ",
      "                ",
      "                ",
      "                ",
      "                ",
      "                ",
      "                ",
      "                ",
      "                ",
      "                ",
      "                ",
      "                ",
      "                "
    ],
    [
      "                ",
      "                ",
      "                ",
      "                ",
      "                ",
      "                ",
      "                ",
      "                ",
      "                ",
      "                ",
      "                ",
      "                ",
      "                ",
      "                ",
      "                ",
      "                "
    ]
  ]
}