{
  "xsize": 16,
  "zsize": 16,
  "refpalette": "pomkotsmechs:offshore",
  "slices": [
    [
      "             #!#",
      "$$$D          #!",
      "   $           #",
      "   $      !     ",
      "   $     !!!    ",
      "$$$D    !!!!!   ",
      "         !!!    ",
      "          !     ",
      "                ",
      "                ",
      "                ",
      "                ",
      "                ",
      "                ",
      "                ",
      "                "
    ],
    [
      "           !! ! ",
      "$$$D       !!! !",
      "DDD$       !!!! ",
      "DDD$      !!!!!!",
      "DDD$     !!!!!!!",
      "$$$D    !!!!!   ",
      "         !!!    ",
      "          !     ",
      "                ",
      "                ",
      "                ",
      "                ",
      "                ",
      "                ",
      "                ",
      "                "
    ],
    [
      "             #!#",
      "DDDD         ###",
      "DDDD            ",
      "DDDD     !!!!   ",
      "DDDD    !!!!!   ",
      "DDDD    !!!!!   ",
      "        !!!!!   ",
      "         !!!    ",
      "                ",
      "                ",
      "                ",
      "                ",
      "                ",
      "                ",
      "                ",
      "                "
    ],
    [
      "              !#",
      "   &           !",
      "                ",
      "          !     ",
      "         !!!    ",
      "   &    !!!!!   ",
      "         !!!    ",
      "          !     ",
      "                ",
      "                ",
      "                ",
      "                ",
      "                ",
      "                ",
      "                ",
      "                "
    ],
    [
      "              ! ",
      "DDDD           !",
      "DDDD            ",
      "DDDD      !     ",
      "DDDD     !!!    ",
      "DDDD    !!!!!   ",
      "         !!!    ",
      "          !     ",
      "                ",
      "                ",
      "                ",
      "                ",
      "                ",
      "                ",
      "                ",
      "                "
    ],
    [
      "          !   ! ",
      "$$$D      !    !",
      "EE $      !     ",
      "   $      !     ",
      "   $     !!!    ",
      "$$$D    !!!!!!!!",
      "         !!!    ",
      "          !     ",
      "                ",
      "                ",
      "                ",
      "                ",
      "                ",
      "                ",
      "                ",
      "                "
    ]
  ]
}