{
  "xsize": 16,
  "zsize": 16,
  "refpalette": "lostcities:offshore",
  "slices": [
    [
      "                ",
      "                ",
      "    G    G      ",
      "                ",
      "               $",
      "$            $$ ",
      " $          $   ",
      " $          $   ",
      "  $       H$    ",
      "  $H     !I$    ",
      "  $I    !!H$!   ",
      "  $H     !!$    ",
      " $        ! $   ",
      " $          $   ",
      "$            $$!",
      "              !$"
    ],
    [
      "                ",
      "                ",
      "    G    G      ",
      "                ",
      "               $",
      "$            $$ ",
      " $          $   ",
      " $          $   ",
      "  $       H$    ",
      "  $H     !I$    ",
      "  $I    !!H$!   ",
      "  $H     !!$    ",
      " $        ! $   ",
      " $          $   ",
      "$            $$!",
      "              !$"
    ],
    [
      "                ",
      "                ",
      "    G    G      ",
      "                ",
      "               $",
      "$            $$ ",
      " $          $   ",
      " $          $   ",
      "  $      !H$    ",
      "  $H    !!I$!   ",
      "  $I    !!H$!!!!",
      "  $H    !!!$!   ",
      " $       !!!$   ",
      " $        ! $   ",
      "$         !  $$!",
      "          !   !$"
    ],
    [
      "                ",
      "                ",
      "GGGGG    GGGGGGG",
      "    G    G      ",
      "    G    G     $",
      "$   G    G   $$ ",
      " $  G    G  $   ",
      " $  G    G  $   ",
      "  $ G    GH$    ",
      "  $HG    GI$    ",
      "  $IG   !GH$!   ",
      "  $HG    G!$    ",
      " $  G    G! $   ",
      " $  G    G  $   ",
      "$   G    G   $$!",
      "    G    G    !$"
    ],
    [
      "                ",
      "                ",
      "    G    G      ",
      "                ",
      "               $",
      "$            $$ ",
      " $          $   ",
      " $          $   ",
      "  $       H$    ",
      "  $H     !I$    ",
      "  $I    !!H$!   ",
      "  $H     !!$    ",
      " $        ! $   ",
      " $          $   ",
      "$            $$!",
      "              !$"
    ],
    [
      "                ",
      "                ",
      "    G    G      ",
      "                ",
      "               $",
      "$            $$ ",
      " $          $   ",
      " $          $   ",
      "  $       H$    ",
      "  $H     !I$    ",
      "  $I    !!H$!!!!",
      "  $H     !!$    ",
      " $        ! $   ",
      " $        ! $   ",
      "$         !  $$!",
      "          !   !$"
    ]
  ]
}