{
  "xsize": 16,
  "zsize": 16,
  "refpalette": "pomkotsmechs:offshore",
  "slices": [
    [
      "              / ",
      "              / ",
      "              / ",
      " )*          !/ ",
      " +,          !!!",
      "             !!!",
      "!!  !!        ! ",
      "!!!!!!--------! ",
      "!!  !!        !!",
      "                ",
      "                ",
      "                ",
      "                ",
      "                ",
      "                ",
      "                "
    ],
    [
      "              / ",
      "              / ",
      "              / ",
      " )*          !/ ",
      " +,          !!!",
      "             !!!",
      "!!  !!        ! ",
      "!!!!!!--------! ",
      "!!  !!        ! ",
      "                ",
      "                ",
      "                ",
      "                ",
      "                ",
      "                ",
      "                "
    ],
    [
      "              / ",
      "              / ",
      "              / ",
      " )*          !/ ",
      " +,          !!!",
      "             !!!",
      "!!  !!        ! ",
      "!!!!!!--------! ",
      "!!  !!        ! ",
      "                ",
      "                ",
      "                ",
      "                ",
      "                ",
      "                ",
      "                "
    ],
    [
      "              / ",
      "              / ",
      "              / ",
      " )*          !/ ",
      " +,          !!!",
      "             !!!",
      "!!  !!        ! ",
      "!!!!!!--------! ",
      "!!  !!        !!",
      "                ",
      "                ",
      "                ",
      "                ",
      "                ",
      "                ",
      "                "
    ],
    [
      "              / ",
      "              / ",
      "              / ",
      " $$          !/ ",
      " $$          !!!",
      "             !!!",
      "!!  !!        ! ",
      "!!!!!!--------! ",
      "!!  !!        !;",
      "                ",
      "                ",
      "                ",
      "                ",
      "                ",
      "                ",
      "                "
    ],
    [
      "9$$           / ",
      "9$$           / ",
      "9$$           / ",
      "9$$$$$$$$$$$$!/ ",
      "9$$$$$$$$$$$$!!!",
      "+666666666666!!!",
      "!!  !!        ! ",
      "!!!!!!--------! ",
      "!!  !!        ! ",
      "                ",
      "                ",
      "                ",
      "                ",
      "                ",
      "                ",
      "                "
    ]
  ]
}