{
  "xsize": 16,
  "zsize": 16,
  "slices": [
    [
      "################",
      "################",
      "################",
      "################",
      "################",
      "################",
      "################",
      "################",
      "################",
      "#######l########",
      "################",
      "################",
      "################",
      "################",
      "################",
      "################"
    ],
    [
      "``````####``````",
      "`              `",
      "` $$$        L `",
      "` $$$      L1L `",
      "` $$$      L   `",
      "`            L `",
      "#              #",
      "#              #",
      "#              #",
      "#      l       #",
      "`     ###      `",
      "` ..       . . `",
      "`              `",
      "` $$       . . `",
      "`              `",
      "``````####``````"
    ],
    [
      "``````####``````",
      "`              `",
      "` :::        L `",
      "` :C:      L L `",
      "` :::      L   `",
      "`            L `",
      "#              #",
      "#              #",
      "#              #",
      "#      l       #",
      "`     ###      `",
      "` --       - - `",
      "`              `",
      "` *        - - `",
      "`              `",
      "``````####``````"
    ],
    [
      "################",
      "#              #",
      "# :::          #",
      "# : :          #",
      "# :::          #",
      "#              #",
      "#              #",
      "#              #",
      "#              #",
      "#      l       #",
      "#     ###      #",
      "#              #",
      "#              #",
      "#              #",
      "#              #",
      "################"
    ],
    [
      "``````####``````",
      "`              `",
      "` :::          `",
      "` : :          `",
      "` :::          `",
      "`              `",
      "#              #",
      "#              #",
      "#              #",
      "#      l       #",
      "`     ###      `",
      "`              `",
      "`              `",
      "`              `",
      "`              `",
      "``````####``````"
    ],
    [
      "``````####``````",
      "`              `",
      "` :::          `",
      "` : :          `",
      "` :::          `",
      "`              `",
      "#              #",
      "#              #",
      "#              #",
      "#      l       #",
      "`     ###      `",
      "`              `",
      "`              `",
      "`              `",
      "`              `",
      "``````####``````"
    ]
  ]
}
