{
  "xsize": 16,
  "zsize": 16,
  "slices": [
    [
      "################",
      "################",
      "################",
      "################",
      "################",
      "################",
      "################",
      "################",
      "################",
      "#######l########",
      "################",
      "################",
      "################",
      "################",
      "################",
      "################"
    ],
    [
      "``````####``````",
      "`              `",
      "` $        $ $ `",
      "` $        $ $ `",
      "`              `",
      "`              `",
      "### ### ###:::##",
      "#    #   #     #",
      "#    #   #F    #",
      "#    # l #F    #",
      "`    #####     `",
      "`      FF      `",
      "` $          $ `",
      "` $          $ `",
      "`              `",
      "``````####``````"
    ],
    [
      "``````####``````",
      "`              `",
      "`          * * `",
      "` *            `",
      "`              `",
      "`              `",
      "### ### ###:::##",
      "#    #   #     #",
      "#    #   #     #",
      "#    # l #     #",
      "`    #####     `",
      "`              `",
      "` *            `",
      "`            * `",
      "`              `",
      "``````####``````"
    ],
    [
      "################",
      "#              #",
      "#              #",
      "#              #",
      "#              #",
      "#              #",
      "###########:::##",
      "#    #   #     #",
      "#    #   #     #",
      "#    # l #     #",
      "#    #####     #",
      "#              #",
      "#              #",
      "#              #",
      "#              #",
      "################"
    ],
    [
      "``````####``````",
      "`              `",
      "`              `",
      "`           E  `",
      "`              `",
      "`              `",
      "################",
      "#    #   #     #",
      "#    #   #     #",
      "#    # l #     #",
      "`    #####     `",
      "`              `",
      "`           E  `",
      "`              `",
      "`              `",
      "``````####``````"
    ],
    [
      "``````####``````",
      "`              `",
      "`              `",
      "`           {  `",
      "`              `",
      "`              `",
      "################",
      "#    #   #     #",
      "#    #   #     #",
      "#    # l #     #",
      "`    #####     `",
      "`              `",
      "`           {  `",
      "`              `",
      "`              `",
      "``````####``````"
    ]
  ]
}
