{
  "xsize": 16,
  "zsize": 16,
  "slices": [
    [
      "################",
      "################",
      "################",
      "################",
      "################",
      "################",
      "################",
      "################",
      "################",
      "#######l########",
      "################",
      "################",
      "################",
      "################",
      "################",
      "################"
    ],
    [
      "``````####``````",
      "`              `",
      "`              `",
      "`              `",
      "`              `",
      "`              `",
      "#              #",
      "#              #",
      "#              #",
      "#      l       #",
      "`     ###      `",
      "`              `",
      "`              `",
      "`              `",
      "`              `",
      "``````####``````"
    ],
    [
      "``````####``````",
      "`              `",
      "`              `",
      "`              `",
      "`              `",
      "`              `",
      "#              #",
      "#              #",
      "#              #",
      "#      l       #",
      "`     ###      `",
      "`              `",
      "`              `",
      "`              `",
      "`              `",
      "``````####``````"
    ],
    [
      "################",
      "#              #",
      "#              #",
      "#              #",
      "#              #",
      "#              #",
      "#              #",
      "#              #",
      "#              #",
      "#      l       #",
      "#     ###      #",
      "#              #",
      "#              #",
      "#              #",
      "#              #",
      "################"
    ],
    [
      "``````####``````",
      "`              `",
      "`              `",
      "`              `",
      "`              `",
      "`              `",
      "#              #",
      "#              #",
      "#              #",
      "#      l       #",
      "`     ###      `",
      "`              `",
      "`              `",
      "`              `",
      "`              `",
      "``````####``````"
    ],
    [
      "``````####``````",
      "`              `",
      "`              `",
      "`              `",
      "`              `",
      "`              `",
      "#              #",
      "#              #",
      "#              #",
      "#      l       #",
      "`     ###      `",
      "`              `",
      "`              `",
      "`              `",
      "`              `",
      "``````####``````"
    ]
  ]
}