{
  "xsize": 16,
  "zsize": 16,
  "refpalette": "rails",
  "slices": [
    [
      "     yyyyyyy    ",
      "     yyyyyyy    ",
      "     yyyyyyy    ",
      "     yyyyyyy    ",
      "     yyyyyyy    ",
      "     yyyyyyy    ",
      "     yyyyyyy    ",
      "     yyyyyyy    ",
      "     yyyyyyy    ",
      "     yyyyyyy    ",
      "     yyyyyyy    ",
      "     yyyyyyy    ",
      "     yyyyyyy    ",
      "     yyyyyyy    ",
      "     yyyyyyy    ",
      "     yyyyyyy    "
    ],
    [
      "     y~~k~~y    ",
      "     y~~k~~y    ",
      "     y~~k~~y    ",
      "     y~~k~~y    ",
      "     y~~k~~y    ",
      "     y~~k~~y    ",
      "     y~~k~~y    ",
      "     y~~k~~y    ",
      "     y~gmg~y    ",
      "     y~~k~~y    ",
      "     y~~k~~y    ",
      "     y~~k~~y    ",
      "     y~~k~~y    ",
      "     y~~k~~y    ",
      "     y~~k~~y    ",
      "     y~~k~~y    "
    ],
    [
      "     y~~~~~y    ",
      "     y~~~~~y    ",
      "     y~~~~~y    ",
      "     y~~~~~y    ",
      "     y~~~~~y    ",
      "     y~~~~~y    ",
      "     yT~~~~y    ",
      "     y~~~~~y    ",
      "     y~~~~~y    ",
      "     y~~~~~y    ",
      "     y~~~~~y    ",
      "     y~~~~~y    ",
      "     y~~~~~y    ",
      "     y~~~~~y    ",
      "     y~~~~~y    ",
      "     y~~~~~y    "
    ],
    [
      "     +~~~~~+    ",
      "     +~~~~~+    ",
      "     +~~~~~+    ",
      "     +~~~~~+    ",
      "     +~~~~~+    ",
      "     +~~~~~+    ",
      "     +~~~~~+    ",
      "     +~~~~~+    ",
      "     +~~~~~+    ",
      "     +~~~~~+    ",
      "     +~~~~~+    ",
      "     +~~~~~+    ",
      "     +~~~~~+    ",
      "     +~~~~~+    ",
      "     +~~~~~+    ",
      "     +~~~~~+    "
    ],
    [
      "     +~~~~~+    ",
      "     +~~~~~+    ",
      "     +~~~~~+    ",
      "     +~~~~~+    ",
      "     +~~~~~+    ",
      "     +~~~~~+    ",
      "     +~~~~~+    ",
      "     +~~~~~+    ",
      "     +~~~~~+    ",
      "     +~~~~~+    ",
      "     +~~~~~+    ",
      "     +~~~~~+    ",
      "     +~~~~~+    ",
      "     +~~~~~+    ",
      "     +~~~~~+    ",
      "     +~~~~~+    "
    ],
    [
      "     +~~~~~+    ",
      "     +~~~~~+    ",
      "     +~~~~~+    ",
      "     +~~~~~+    ",
      "     +~~~~~+    ",
      "     +~~~~~+    ",
      "     +~~~~~+    ",
      "     +~~~~~+    ",
      "     +~~~~~+    ",
      "     +~~~~~+    ",
      "     +~~~~~+    ",
      "     +~~~~~+    ",
      "     +~~~~~+    ",
      "     +~~~~~+    ",
      "     +~~~~~+    ",
      "     +~~~~~+    "
    ],
    [
      "     +~~~~~+    ",
      "     +~~~~~+    ",
      "     +~~~~~+    ",
      "     +~~~~~+    ",
      "     +~~~~~+    ",
      "     +~~~~~+    ",
      "     +~~~~~+    ",
      "     +~~~~~+    ",
      "     +~~~~~+    ",
      "     +~~~~~+    ",
      "     +~~~~~+    ",
      "     +~~~~~+    ",
      "     +~~~~~+    ",
      "     +~~~~~+    ",
      "     +~~~~~+    ",
      "     +~~~~~+    "
    ],
    [
      "     +~~~~~+    ",
      "     +~~~~~+    ",
      "     +~~~~~+    ",
      "     +~~~~~+    ",
      "     +~~~~~+    ",
      "     +~~~~~+    ",
      "     +~~~~~+    ",
      "     +~~~~~+    ",
      "     +~~~~~+    ",
      "     +~~~~~+    ",
      "     +~~~~~+    ",
      "     +~~~~~+    ",
      "     +~~~~~+    ",
      "     +~~~~~+    ",
      "     +~~~~~+    ",
      "     +~~~~~+    "
    ],
    [
      "     yyy+yyy    ",
      "     yyy+yyy    ",
      "     yyy+yyy    ",
      "     yyy+yyy    ",
      "     yyy+yyy    ",
      "     yyy+yyy    ",
      "     yyy+yyy    ",
      "     yyy+yyy    ",
      "     yyy+yyy    ",
      "     yyy+yyy    ",
      "     yyy+yyy    ",
      "     yyy+yyy    ",
      "     yyy+yyy    ",
      "     yyy+yyy    ",
      "     yyy+yyy    ",
      "     yyy+yyy    "
    ]
  ]
}