{
  "xsize": 16,
  "zsize": 16,
  "slices": [
    [
      "################",
      "################",
      "################",
      "################",
      "################",
      "################",
      "################",
      "################",
      "################",
      "#######l########",
      "################",
      "################",
      "################",
      "################",
      "################",
      "################"
    ],
    [
      "##a#a#a##a#a#a##",
      "#              #",
      "a              a",
      "#  . .         #",
      "a              a",
      "#  . .         #",
      "a              a",
      "#              #",
      "#              #",
      "a  l   l    l  a",
      "#  #   #    #  #",
      "a           F  a",
      "#              #",
      "a              a",
      "#           F  #",
      "##a#a#a##a#a#a##"
    ],
    [
      "##a#a#a##a#a#a##",
      "#              #",
      "a              a",
      "#  - -         #",
      "a              a",
      "#  - -         #",
      "a              a",
      "#              #",
      "#              #",
      "a  l   l    l  a",
      "#  #   #    #  #",
      "a              a",
      "#  E           #",
      "a              a",
      "#              #",
      "##a#a#a##a#a#a##"
    ],
    [
      "################",
      "#              #",
      "#              #",
      "#              #",
      "#              #",
      "#              #",
      "#              #",
      "#              #",
      "#              #",
      "#  l   l    l  #",
      "################",
      "################",
      "################",
      "################",
      "################",
      "################"
    ],
    [
      "##a#a#a##a#a#a##",
      "#              #",
      "a              a",
      "#              #",
      "a          E   a",
      "#              #",
      "a              a",
      "#              #",
      "#              #",
      "a      l       a",
      "#      #       #",
      "a              a",
      "#  . .    . .  #",
      "a              a",
      "#              #",
      "##a#a#a##a#a#a##"
    ],
    [
      "##a#a#a##a#a#a##",
      "#              #",
      "a              a",
      "#              #",
      "a          {   a",
      "#              #",
      "a              a",
      "#              #",
      "#              #",
      "a      l       a",
      "#      #       #",
      "a              a",
      "#  - -    - -  #",
      "a              a",
      "#              #",
      "##a#a#a##a#a#a##"
    ]
  ]
}
