{
  "xsize": 16,
  "zsize": 16,
  "refpalette": "lostcities:ships",
  "slices": [
    [
      "                ",
      "                ",
      "        $$$$$$$$",
      "     H  H    H΃΃",
      "     H  H    HHH",
      "     H  H    H &",
      "        H    H b",
      "        H    H  ",
      "        HHHHHH &",
      "        ΃΃΃΃΃H &",
      "      ΃΃΃΃΃΃΃H  ",
      "     H΃΃΃΃΃΃΃H/a",
      "     H΃΃΃΃΃΃΃HH&",
      "     H΃΃΃΃΃΃΃HHϫ",
      "     H΃΃΃΃΃΃΃΃HH",
      "     HH΃΃΃΃΃΃H''"
    ],
    [
      "                ",
      "                ",
      "      ^^$$$$$$$$",
      "     H  H    H  ",
      "     H  H    H a",
      "     H  H I  H &",
      "        H    H b",
      "        H    H  ",
      "        HHHHHH &",
      "        Ϛ    H &",
      "        ΩΪ   H  ",
      "     j       H a",
      "     j Ϭ    $H &",
      "     j ϭ    $H b",
      "     j Ϭ        ",
      "     m;      H  "
    ],
    [
      "      ΃ ΃΃΃΃΃΃΃΃",
      "      ΃ ΃΃΃΃΃΃΃΃",
      "     H΃΃΃΃΃΃΃H  ",
      "     H΃΃΃΃΃΃΃H  ",
      "     H΃΃΃΃΃΃΃H a",
      "     H΃΃΃΃΃΃΃H &",
      "        ΃΃΃΃΃H b",
      "        ΃΃΃΃΃H  ",
      "      HHHHHHHH &",
      "       Ϛ     H &",
      "       ΩΪ   ΢H  ",
      "             H a",
      "            %H &",
      "            %H b",
      "                ",
      "             H# "
    ],
    [
      "              $$",
      "     j     ##HHH",
      "     j    ##$H  ",
      "     j     #$H  ",
      "     j       H a",
      "     j       H &",
      "             H b",
      "             H  ",
      "        ΩiiiiH &",
      "      j      H &",
      "      mΪ     H  ",
      "             H a",
      "             H &",
      "             H b",
      "             H  ",
      "             H# "
    ],
    [
      "              %%",
      "            #HHH",
      "           #%H# ",
      "            %H  ",
      "             H a",
      "            ΢H &",
      "             H b",
      "             H  ",
      "             H &",
      "             H &",
      "             H  ",
      "             Z a",
      "             Z &",
      "             Z b",
      "             H #",
      "             HHH"
    ],
    [
      "                ",
      "             HHH",
      "            #H# ",
      "             H  ",
      "             H a",
      "             H &",
      "             H b",
      "             H  ",
      "             Z &",
      "             Z &",
      "             H  ",
      "             Z a",
      "             Z#&",
      "              #b",
      "              HH",
      "             #HH"
    ]
  ]
}