{
  "xsize": 16,
  "zsize": 16,
  "refpalette": "lostcities:ships",
  "slices": [
    [
      "       ! $    $ ",
      "      !$ $    $ ",
      "      !$$$    $ ",
      "      !$$$ ) )$ ",
      "      !$$$ ) )$ ",
      "      !$$$$$$$$ ",
      "      !$      $ ",
      "      !$Q     $ ",
      "      !$Q     $ ",
      "      !$Q     $ ",
      "      !$Q     $ ",
      "      !$(     $ ",
      "      !$(     $ ",
      "      !$(     $ ",
      "      !$(     $ ",
      "      !$(     $ "
    ],
    [
      "      !$ $    $ ",
      "      !$ $    $ ",
      "      !$$$    $ ",
      "      !$$$    $ ",
      "      !$$$    $ ",
      "      !$$$$$$$$ ",
      "      !$      $ ",
      "      !$Q     $ ",
      "      !$Q     $ ",
      "      !$Q     $ ",
      "      !$Q     $ ",
      "      !$(     $ ",
      "      !$(     $ ",
      "      !$(     $ ",
      "      !$(     $ ",
      "      !$(     $ "
    ],
    [
      "      !$ $ II $ ",
      "      !$&$    $ ",
      "      !$$$    $ ",
      "      !$$$    $ ",
      "      !$$$    $ ",
      "      !$$$$$$$$ ",
      "      !$      $ ",
      "      !$      $ ",
      "      !$      $ ",
      "      !$      $ ",
      "      !$  II  $ ",
      "      !$  II  $ ",
      "      !$      $ ",
      "      !$      $ ",
      "      !$      $ ",
      "      !$      $ "
    ],
    [
      "      &$ &&&&&&&",
      "      &$ &&&&&&&",
      "      &$$&&&&&&&",
      "      &$$&&&&&&&",
      "      &$$&&&&&&&",
      "      &$$&&&&&&&",
      "      &$$&&&&&&&",
      "      &$$&&&&&&&",
      "      &$$&&&&&&&",
      "      &$$&&&&&&&",
      "      &$$&&&&&&&",
      "      &$$&&&&&&&",
      "      &$$&&&&&&&",
      "      &$$&&&&&&&",
      "      &$$&&&&&&&",
      "      &$$$$$$$$$"
    ],
    [
      "      H$&&  RNNN",
      "      H$&S   NNN",
      "      H$&S   NNN",
      "      H$&&   NNN",
      "      H$&   TNUV",
      "      H$&&  MNWX",
      "      H$&S  RNWX",
      "      H$&S   NWX",
      "      H$&&   NYZ",
      "      H$&    NNN",
      "      H$&&  TNNN",
      "      H$&S  MNNN",
      "      H$&S  [KK\\",
      "      H$&&      ",
      "      H$&&&&&&&$",
      "      H$        "
    ],
    [
      "      H$&&     ]",
      "      H$^_      ",
      "      H$^_      ",
      "      H$&&      ",
      "      H$&       ",
      "      H$&&      ",
      "      H$^_      ",
      "      H$^_      ",
      "      H$&&      ",
      "      H$&       ",
      "      H$&&      ",
      "      H$`_      ",
      "      H$^_      ",
      "      H$&&      ",
      "      H$&&&&&&&$",
      "      H$       5"
    ]
  ]
}