{
  "xsize": 16,
  "zsize": 16,
  "refpalette": "lostcities:ships",
  "slices": [
    [
      "   DE  ''$!     ",
      "'''''''  $!     ",
      "   DE    $!     ",
      "         $!     ",
      "         $!     ",
      "   ; 8 ; $!     ",
      "   ; 8 ; $!     ",
      "         $!     ",
      "         $!     ",
      "   ; 8 ; $!     ",
      "   ; 8 ; $!     ",
      "         $!     ",
      "         $!     ",
      "   ; 8 ; $!     ",
      "   ; 8 ; $!     ",
      "         $!     "
    ],
    [
      "  DE   ''$!     ",
      "'''''''  $!     ",
      "  DE     $!     ",
      "         $!     ",
      "         $!     ",
      "   ;   < $!     ",
      "   ;   < $!     ",
      "         $!     ",
      "         $!     ",
      "   ;   < $!     ",
      "   ;   < $!     ",
      "         $!     ",
      "         $!     ",
      "   ;   < $!     ",
      "   ;   < $!     ",
      "         $!     "
    ],
    [
      " DE    ''$!     ",
      "'''''''  $!     ",
      " DE      $!     ",
      "         $!     ",
      "         $!     ",
      "   < 8 < $!     ",
      "   < 8 < $!     ",
      "         $!     ",
      "         $!     ",
      "   < 8 < $!     ",
      "   < 8 < $!     ",
      "         $!     ",
      "         $!     ",
      "   < 8 < $!     ",
      "   < 8 < $!     ",
      "         $!     "
    ],
    [
      "$E   $$''$&     ",
      "'$'''''  $&     ",
      "$E   8   $&     ",
      "$;   8   $&     ",
      "$f   8   $&     ",
      "$f <888< $&     ",
      "$f <888< $&     ",
      "$f   8   $&     ",
      "$f   8   $&     ",
      "$f <888< $&     ",
      "$f <888< $&     ",
      "$f   8   $&     ",
      "$f   8   $&     ",
      "$f <888< $&     ",
      "$f <888< $&     ",
      "$f   8   $&     "
    ],
    [
      "       ''$H     ",
      " $'''''  $H     ",
      "    888  $H     ",
      " o  888  $H     ",
      " j  888  $H     ",
      " j 88888 $H     ",
      " j 88888 $H     ",
      " j  888  $H     ",
      " j  888  $H     ",
      " j 88888 $H     ",
      " j 88888 $H     ",
      " j  888  $H     ",
      " j  888  $H     ",
      " j 88888 $H     ",
      " j 88888 $H     ",
      " j  888  $H     "
    ],
    [
      "       ''$H     ",
      " $'''''  $H     ",
      "     8   $H     ",
      "     8   $H     ",
      "     8   $H     ",
      "    888  $H     ",
      "    888  $H     ",
      "     8   $H     ",
      "     8   $H     ",
      "    888  $H     ",
      "    888  $H     ",
      "     8   $H     ",
      "     8   $H     ",
      "    888  $H     ",
      "    888  $H     ",
      "     8   $H     "
    ]
  ]
}