{
  "xsize": 16,
  "zsize": 16,
  "refpalette": "lostcities:ships",
  "slices": [
    [
      "                ",
      "                ",
      "$$$$$$$$$       ",
      "΃΃΃H    H  H    ",
      "HHHH    H       ",
      " & H    H       ",
      "&ͺ H    H       ",
      "   H    H       ",
      "&  HHHHHH       ",
      "&  H΃΃΃΃΃       ",
      "   H΃΃΃΃΃΃΃     ",
      "&ͻ/H΃΃΃΃΃΃΃     ",
      " &μ΃΃΃΃΃΃΃΃H    ",
      "&ϹHH΃΃΃΃΃΃΃H#   ",
      "HHHH΃΃΃΃΃΃΃H    ",
      "'''H΃΃΃΃΃΃HH    "
    ],
    [
      "           H    ",
      "                ",
      "I$$$$$$$$^^H    ",
      "   H    H  H    ",
      "Hͻ H    H       ",
      " & H  I H       ",
      "&ͺ H    H       ",
      "   H    H       ",
      "&  HHHHHH       ",
      "&  H    Υ       ",
      "   H#  ΩΪ       ",
      "&ͻ#H##          ",
      " & ##### Ϭ#j    ",
      "&ͺ H   ##Ϻ#j#   ",
      "   H$    Ϭ#j    ",
      "   H$     nͽ    "
    ],
    [
      "΃΃΃΃΃΃΃΃΃΃΃H    ",
      "΃΃΃΃΃΃΃΃΃΃΃H    ",
      "H   ΃΃΃΃΃΃΃H    ",
      "   H΃΃΃΃΃΃΃H    ",
      "&ͻ H΃΃΃΃΃΃΃     ",
      " & H΃΃΃΃΃       ",
      "&ͺ H΃΃΃΃΃       ",
      "&  H΃΃΃΃΃΃΃     ",
      "&  HHHHHHHH     ",
      "&  H     Υ      ",
      "&  Hϔ   ΩΪ      ",
      "&ͻ#H#           ",
      " & #            ",
      "&ͺ H     ###    ",
      "   H%           ",
      "   H%           "
    ],
    [
      " $$        j    ",
      "HHHH       j    ",
      "H HH       j    ",
      "   H       j    ",
      "&ͻ H       j    ",
      " & H$           ",
      "&ͺ H$           ",
      "   H            ",
      "&  HiiiiΪ n     ",
      "&  H      j     ",
      "   H     Ωͽ     ",
      "&ͻ#H#           ",
      "#& H            ",
      "&ͺ H            ",
      "   H            ",
      "   H            "
    ],
    [
      " $$             ",
      "HHHH            ",
      "H HH            ",
      "   Hϻ           ",
      "&ͻ H            ",
      " & H%           ",
      "&ͺ H%           ",
      "   H            ",
      "&  H            ",
      "&  H            ",
      "#  H            ",
      "&ͻ#Z#           ",
      "#& Z            ",
      "&ͺ Z            ",
      "   H            ",
      "HHHH            "
    ],
    [
      "                ",
      "HHHH            ",
      "H HH            ",
      "   H            ",
      "&ͻ H            ",
      " & H            ",
      "&ͺ H            ",
      "   H            ",
      "&  Z            ",
      "&  Z            ",
      "#  H            ",
      "&ͻ#Z#           ",
      "#& Z            ",
      "&ͺ Z            ",
      "HHHH            ",
      "HHHH            "
    ]
  ]
}