{
  "xsize": 16,
  "zsize": 16,
  "refpalette": "lostcities:ships",
  "slices": [
    [
      "         'H     ",
      "'''''''   H     ",
      "      '   H     ",
      "      '   H     ",
      "      '  /H     ",
      "      '  'H     ",
      "      '  'H     ",
      "      '  'H     ",
      "'''''''''ϛ      ",
      "      'Hϛ       ",
      "     HHϛ        ",
      "HHHHHH          ",
      "                ",
      "                ",
      "                ",
      "                "
    ],
    [
      "         'H     ",
      "'''''''   H     ",
      "      '   HH    ",
      "      '   HH    ",
      "I     '   HH    ",
      "I     '  /H     ",
      "      '  'H     ",
      "      ' 'H      ",
      "''''''''ϛ       ",
      "      Hϛ        ",
      "HHHHHHH         ",
      "HHHH            ",
      "                ",
      "                ",
      "                ",
      "                "
    ],
    [
      "HHHHHHH΃΃΃H϶    ",
      "HHHHHHH΃΃΃΃H϶   ",
      "HHHHHHH΃΃΃΃΃H   ",
      "HHHHHH΃΃΃ ΃΃H   ",
      "HHHHHH΃΃΃ ΃΃H   ",
      "΃΃΃΃΃΃΃΃΃ ΃H϶   ",
      "΃΃΃΃΃΃΃΃΃/H϶    ",
      "΃΃΃΃΃΃΃΃΃H      ",
      "΃΃΃΃΃΃HHH       ",
      "΃΃΃΃΃HHH        ",
      "HHHHHHH         ",
      "                ",
      "                ",
      "                ",
      "                ",
      "                "
    ],
    [
      "NNNNW  H HHδ    ",
      "NNNN   H  HHδ   ",
      "NNNN       HH   ",
      " ..  HHH    H   ",
      "HHHHHHHH    H   ",
      "      H    HІ   ",
      "HHHHHH    HІ    ",
      "         HІ     ",
      "      HHHІ      ",
      "    HHH         ",
      "HHHHH           ",
      "                ",
      "                ",
      "                ",
      "                ",
      "                "
    ],
    [
      "       ϥ        ",
      "       Π        ",
      "                ",
      " ..  HHH        ",
      "HHHHHHHH        ",
      "      H         ",
      "HHHHHH          ",
      "                ",
      "                ",
      "      H         ",
      "                ",
      "                ",
      "                ",
      "                ",
      "                ",
      "                "
    ],
    [
      "HHHHHHHH        ",
      "HHHHHHHH        ",
      "HHHHHHHH        ",
      "HHHHHHHH        ",
      "HHHHHHHH        ",
      "HHHHHHH         ",
      "HHHHHH          ",
      "                ",
      "     H          ",
      "     αΰ         ",
      "                ",
      "                ",
      "                ",
      "                ",
      "                ",
      "                "
    ]
  ]
}