{
  "xsize": 16,
  "zsize": 16,
  "refpalette": "lostcities:ships",
  "slices": [
    [
      "      !$''  97  ",
      "      !$  ''''''",
      "      !$    97  ",
      "      !$        ",
      "      !$        ",
      "      !$ ; 8 ;  ",
      "      !$ ; 8 ;  ",
      "      !$        ",
      "      !$        ",
      "      !$ ; 8 ;  ",
      "      !$ ; 8 ;  ",
      "      !$        ",
      "      !$        ",
      "      !$ ; 8 ;  ",
      "      !$ ; 8 ;  ",
      "      !$        "
    ],
    [
      "      !$''   97 ",
      "      !$  ''''''",
      "      !$     97 ",
      "      !$        ",
      "      !$        ",
      "      !$ <   ;  ",
      "      !$ <   ;  ",
      "      !$        ",
      "      !$        ",
      "      !$ <   ;  ",
      "      !$ <   ;  ",
      "      !$        ",
      "      !$        ",
      "      !$ <   ;  ",
      "      !$ <   ;  ",
      "      !$        "
    ],
    [
      "      !$''    97",
      "      !$  ''''''",
      "      !$      97",
      "      !$        ",
      "      !$        ",
      "      !$ < 8 <  ",
      "      !$ < 8 <  ",
      "      !$        ",
      "      !$        ",
      "      !$ < 8 <  ",
      "      !$ < 8 <  ",
      "      !$        ",
      "      !$        ",
      "      !$ < 8 <  ",
      "      !$ < 8 <  ",
      "      !$        "
    ],
    [
      "      &$''$$   9",
      "      &$  '''''$",
      "      &$   8   9",
      "      &$   8   n",
      "      &$   8   h",
      "      &$ <888< h",
      "      &$ <888< h",
      "      &$   8   h",
      "      &$   8   h",
      "      &$ <888< h",
      "      &$ <888< h",
      "      &$   8   h",
      "      &$   8   h",
      "      &$ <888< h",
      "      &$ <888< h",
      "      &$   8   h"
    ],
    [
      "      H$''      ",
      "      H$  '''''$",
      "      H$  888   ",
      "      H$  888  o",
      "      H$  888  j",
      "      H$ 88888 j",
      "      H$ 88888 j",
      "      H$  888  j",
      "      H$  888  j",
      "      H$ 88888 j",
      "      H$ 88888 j",
      "      H$  888  j",
      "      H$  888  j",
      "      H$ 88888 j",
      "      H$ 88888 j",
      "      H$  888  j"
    ],
    [
      "      H$''      ",
      "      H$  '''''$",
      "      H$   8    ",
      "      H$   8    ",
      "      H$   8    ",
      "      H$  888   ",
      "      H$  888   ",
      "      H$   8    ",
      "      H$   8    ",
      "      H$  888   ",
      "      H$  888   ",
      "      H$   8    ",
      "      H$   8    ",
      "      H$  888   ",
      "      H$  888   ",
      "      H$   8    "
    ]
  ]
}