{
  "xsize": 16,
  "zsize": 16,
  "refpalette": "lostcities:ships",
  "slices": [
    [
      "  -   H         ",
      "  -   H         ",
      "  -   H         ",
      "  -   H         ",
      "  - # H         ",
      "  - # H         ",
      "  - ##H#        ",
      "  -  #H#        ",
      "  -   H         ",
      "---   H         ",
      "      H         ",
      "     HH  HHH    ",
      "HHHHHHH  HHH    ",
      " <   HH  HHH    ",
      "     HH         ",
      "     HH         "
    ],
    [
      "  -΃΃΃H         ",
      "  -H΃΃H         ",
      "  -H΃΃H         ",
      "  -H΃΃H         ",
      "  -H΃΃H         ",
      "  -H΃΃H         ",
      "  -H΃΃H#        ",
      "  -H΃΃H         ",
      "  -H΃΃H         ",
      "---H΃΃          ",
      "   H΃           ",
      "gggH΃    ϽϾЀ    ",
      "HHHH΃΃   ЁHЂ    ",
      "eeeH΃΃H  ЃЄЅ    ",
      "   H΃΃H         ",
      "   H΃΃H         "
    ],
    [
      "&Ͷ-H  j         ",
      " &-H  j         ",
      "&ͷ-H  j         ",
      "---H  j         ",
      "---H# j         ",
      "---H##j         ",
      "---H##j#        ",
      "&͸-H  j         ",
      " &-H            ",
      "&͹-H            ",
      "   H            ",
      "iiiH       δ    ",
      "          HH    ",
      "iiiH  j  αHІ    ",
      "   H  j         ",
      "   H  j         "
    ],
    [
      "&Ͷ H            ",
      " & H            ",
      "&ͺ Hϻ           ",
      "   H            ",
      "&  H            ",
      "& #H#           ",
      "   H  #         ",
      "&ͻ H            ",
      " & H            ",
      "&Ͷ H            ",
      "   H            ",
      "   H            ",
      "                ",
      "   H            ",
      "I^IH            ",
      "HHHHϻ           "
    ],
    [
      "&ͼ H            ",
      " & H            ",
      "&ͺ H            ",
      "&  H            ",
      "&  H            ",
      "& #H#           ",
      "&  Z            ",
      "&ͻ Z            ",
      " & Z            ",
      "&ͷ H            ",
      "   H            ",
      "HHHH            ",
      "   H            ",
      "   H            ",
      "HHHH            ",
      "#  j            "
    ],
    [
      "   H            ",
      "   H            ",
      "   H            ",
      "   H            ",
      "   Z            ",
      "  #H#           ",
      "   Z            ",
      " ##Z            ",
      "   Z            ",
      "   H            ",
      "HHHH            ",
      "HHHH            ",
      "  HH            ",
      "   H            ",
      "HHHH            ",
      "                "
    ]
  ]
}