{
  "xsize": 16,
  "zsize": 16,
  "refpalette": "lostcities:ships",
  "slices": [
    [
      "                ",
      "                ",
      "                ",
      "                ",
      "                ",
      "                ",
      "                ",
      "                ",
      "                ",
      "                ",
      "                ",
      "                ",
      "                ",
      "                ",
      "                ",
      "                "
    ],
    [
      "                ",
      "                ",
      "                ",
      "                ",
      "                ",
      "                ",
      "                ",
      "                ",
      "                ",
      "                ",
      "                ",
      "                ",
      "                ",
      "                ",
      "                ",
      "                "
    ],
    [
      "!!!!!!!         ",
      "!!!!!!!         ",
      "!!!!!!!         ",
      "!!!!!!!         ",
      "!!!!!!!         ",
      "!!!!!!!         ",
      "!!!!!!!         ",
      "!!!!!!!         ",
      "!!!!!!!         ",
      "!!!!!!!         ",
      "!!!!!!!         ",
      "!!!!!!!         ",
      "!!!!!!!         ",
      "!!!!!!!         ",
      "!!!!!!!         ",
      "!!!!!!!         "
    ],
    [
      "$$$%%%%!        ",
      "$$$''''!        ",
      "$$$%%%<!        ",
      "$$$%%%'!        ",
      "$$$%%%6!        ",
      "$$$%888!        ",
      "$$$%888!        ",
      "$$$%%%%!        ",
      "$$$%%%%!        ",
      "$$$%888!        ",
      "$$$%888!        ",
      "$$$%%%%!        ",
      "$$$%%%%!        ",
      "$$$%888!        ",
      "$$$%888!        ",
      "$$$%%%%!        "
    ],
    [
      "     D'$!       ",
      " ''''''$!       ",
      "     D'$!       ",
      "      6$!       ",
      "     . $!       ",
      "   88.88!       ",
      "   88.88!       ",
      "     . $!       ",
      "     . $!       ",
      "   88.88!       ",
      "   88.88!       ",
      "     . $!       ",
      "     . $!       ",
      "   88.88!       ",
      "   88.88!       ",
      "     . $!       "
    ],
    [
      "    DE '$!      ",
      " '''''' $!      ",
      "    DE  $!      ",
      "        $!      ",
      "        $!      ",
      "   ;888;$!      ",
      "   ;888;$!      ",
      "        $!      ",
      "        $!      ",
      "   ;888;$!      ",
      "   ;888;$!      ",
      "        $!      ",
      "        $!      ",
      "   ;888;$!      ",
      "   ;888;$!      ",
      "        $!      "
    ]
  ]
}