{
  "xsize": 16,
  "zsize": 16,
  "refpalette": "lostcities:ships",
  "slices": [
    [
      "        H $     ",
      "        H $ < < ",
      "        H $     ",
      "        H $ < < ",
      "       H  $     ",
      "       H $$ < < ",
      "       H $$     ",
      "       H $$ < < ",
      "       H $$     ",
      "       H $$     ",
      "       H $''''''",
      "      H$&&&&&&&&",
      "      H$&       ",
      "      H$&       ",
      "      H$&      Ί",
      "      H$&      ΋"
    ],
    [
      "        H $     ",
      "        H $ p p ",
      "       H  $     ",
      "       H  $ p p ",
      "       H  $     ",
      "       H $$ p p ",
      "       H $$     ",
      "       H $$ p p ",
      "      H$ $$     ",
      "      H$ $$     ",
      "      H$ $''''''",
      "      H$&&&&&&&&",
      "      H$&       ",
      "     H $&       ",
      "     H $&      Ό",
      "     H $&      ΍"
    ],
    [
      "       H  $     ",
      "       H  $     ",
      "       H  $     ",
      "       H  $     ",
      "       H  $     ",
      "      H$ $$     ",
      "      H$ $$     ",
      "      H$ $$     ",
      "      H$ $$     ",
      "      H$ $$     ",
      "      H$ $''''''",
      "     H $&&&&&&&&",
      "     H $&       ",
      "     H $&       ",
      "     H $&       ",
      "     H $&       "
    ],
    [
      "       H΃΃΃΃΃΃΃΃",
      "       H΃΃΃΃΃΃΃΃",
      "      HH΃΃΃΃΃΃΃΃",
      "      H΃΃΃΃΃΃΃΃΃",
      "      H΃΃΃΃΃΃΃΃΃",
      "      H΃΃΃΃΃΃΃΃΃",
      "      H΃΃΃΃΃΃΃΃΃",
      "      H΃΃΃΃΃΃΃΃΃",
      "     HH΃΃΃΃΃΃΃΃΃",
      "     H΃΃΃΃΃΃΃΃΃΃",
      "     H΃΃΃΃΃΃΃΃΃΃",
      "     H΃΃΃΃΃΃΃΃΃΃",
      "     H΃΃΃΃΃΃΃΃΃΃",
      "     H΃΃΃΃΃΃΃΃΃΃",
      "     H΃΃΃΃΃΃΃΃΃΃",
      "     H΃΃΃΃΃΃΃΃΃΃"
    ],
    [
      "       j        ",
      "       j Ύ  $   ",
      "      nͽ   HHHHH",
      "      j   HH ΏΏΏ",
      "      j  HH +   ",
      "      j HH  ,   ",
      "      H H$  +   ",
      "      H  $  ,   ",
      "     HH  $ΐΐ$   ",
      "     H   $    <<",
      "     H   $    <<",
      "     H   $      ",
      "     H   $      ",
      "     H$ $$ $$$$$",
      "     H  $       ",
      "     H  $       "
    ],
    [
      "                ",
      "            %   ",
      "           HHHHH",
      "         ΑHH    ",
      "         HH +   ",
      "        HH  ,   ",
      "      H H   +   ",
      "      H  $  ,   ",
      "     HH  $ΐΐ$   ",
      "     H   $      ",
      "     H   $      ",
      "     H   $      ",
      "     H   $      ",
      "     H$ $$ $    ",
      "     H  $       ",
      "     H  $       "
    ]
  ]
}