{
  "xsize": 16,
  "zsize": 16,
  "refpalette": "lostcities:ships",
  "slices": [
    [
      "      H$&&     Β",
      "      H$&&      ",
      "      H$&&      ",
      "      H$&&      ",
      "      H$&       ",
      "      H$&&      ",
      "      H$&&      ",
      "      H$&&      ",
      "      H$&&      ",
      "      H$&       ",
      "      H$&&      ",
      "      H$&&      ",
      "      H$&&      ",
      "      H$&&      ",
      "      H$&&&&&&&$",
      "      H$        "
    ],
    [
      "     H $&      Γ",
      "     H $&       ",
      "     H $&       ",
      "     H $&       ",
      "     H $&       ",
      "     H $&       ",
      "     H $&       ",
      "     H $&       ",
      "     H $&       ",
      "     H $&       ",
      "     H $&       ",
      "     H $&       ",
      "     H $&       ",
      "     H $&       ",
      "     H $&&&&&&&&",
      "     H $        "
    ],
    [
      "     H $&       ",
      "     H $&       ",
      "     H $&       ",
      "     H $&       ",
      "     H $&       ",
      "     H $&       ",
      "     H $&       ",
      "     H $&       ",
      "     H $&       ",
      "     H $&       ",
      "     H $&       ",
      "     H $&       ",
      "     H $&       ",
      "     H $&       ",
      "     H $&&&&&&&&",
      "     H $       &"
    ],
    [
      "     H΃΃΃΃΃΃΃΃΃΃",
      "     H΃΃΃΃΃΃΃΃΃΃",
      "     H΃΃΃΃΃΃΃΃΃΃",
      "     H΃΃΃΃΃΃΃΃΃΃",
      "     H΃΃΃΃΃΃΃΃΃΃",
      "     H΃΃΃΃΃΃΃΃΃΃",
      "     H΃΃΃΃΃΃΃΃΃΃",
      "     H΃΃΃΃΃΃΃΃΃΃",
      "     H΃΃΃΃΃΃΃΃΃΃",
      "     H΃΃΃΃΃΃΃΃΃΃",
      "     H΃΃΃΃΃΃΃΃΃΃",
      "     H΃΃΃΃΃΃΃΃΃΃",
      "     H΃΃΃΃΃΃΃΃΃΃",
      "     H΃΃΃΃΃΃΃΃΃΃",
      "     H΃΃΃΃΃΃΃΃΃΃",
      "     H΃΃΃΃΃΃΃΃΃΃"
    ],
    [
      "     H  $       ",
      "     H  $ ΔΕ ΔΕ ",
      "     H  $ ΖΗ ΖΗ ",
      "     H  $ ΖΗ ΖΗ ",
      "     H  $ ΘΙ ΘΙ ",
      "     H6 $       ",
      "     H  $       ",
      "     H  $ ΔΕ ΔΕ ",
      "     H  $ ΖΗ ΖΗ ",
      "     H  $ ΖΗ ΖΗ ",
      "     H  $ ΘΙ ΘΙ ",
      "     H  $       ",
      "     H  $       ",
      "     H  $$$$$$$ ",
      "     H          ",
      "     H          "
    ],
    [
      "     H  $       ",
      "     H  $       ",
      "     H  $       ",
      "     H  $       ",
      "     H6 $       ",
      "     H  $       ",
      "     H  $       ",
      "     H  $       ",
      "     H  $       ",
      "     H  $       ",
      "     H  $       ",
      "     H  $       ",
      "     H  $       ",
      "     H  $$$$$$$ ",
      "     H          ",
      "     H          "
    ]
  ]
}