{
  "xsize": 16,
  "zsize": 16,
  "refpalette": "lostcities:ships",
  "slices": [
    [
      "                ",
      "                ",
      "                ",
      "                ",
      "                ",
      "                ",
      "                ",
      "                ",
      "                ",
      "                ",
      "                ",
      "                ",
      "                ",
      "                ",
      "                ",
      "                "
    ],
    [
      "                ",
      "                ",
      "                ",
      "                ",
      "                ",
      "                ",
      "                ",
      "                ",
      "                ",
      "                ",
      "                ",
      "                ",
      "                ",
      "                ",
      "                ",
      "                "
    ],
    [
      "          !!!!!!",
      "          !!!!!!",
      "          !!!!!!",
      "          !!!!!!",
      "          !!!!!!",
      "          !!!!!!",
      "          !!!!!!",
      "          !!!!!!",
      "          !!!!!!",
      "          !!!!!!",
      "          !!!!!!",
      "          !!!!!!",
      "          !!!!!!",
      "          !!!!!!",
      "          !!!!!!",
      "          !!!!!!"
    ],
    [
      "         !$$$$$$",
      "         !''''$$",
      "         !%%%%$$",
      "         !%%%%$-",
      "         !%%%.$-",
      "         !%%%%$-",
      "         !%%%.$-",
      "         !%%%%$-",
      "         !%%%.$-",
      "         !%%%%$-",
      "         !%%%.$-",
      "         !%%%%$-",
      "         !%%%.$-",
      "         !%%%%$-",
      "         !/%%%$-",
      "         !%%%%$$"
    ],
    [
      "        !$ 00 $ ",
      "        !$''''''",
      "        !$      ",
      "        !$    --",
      "        !$   .- ",
      "        !$    - ",
      "        !$   .- ",
      "        !$    - ",
      "        !$   .- ",
      "        !$    - ",
      "        !$   .- ",
      "        !$    - ",
      "        !$   .- ",
      "        !$    - ",
      "        !$    --",
      "        !$/     "
    ],
    [
      "       !$2    $3",
      "       !$'''''''",
      "       !$      5",
      "       !$    ---",
      "       !$    -- ",
      "       !$    -- ",
      "       !$    -- ",
      "       !$    -- ",
      "       !$    -- ",
      "       !$    -- ",
      "       !$    -- ",
      "       !$    -- ",
      "       !$    -- ",
      "       !$    -- ",
      "       !$    ---",
      "       !$       "
    ]
  ]
}