{
  "xsize": 16,
  "zsize": 16,
  "refpalette": "lostcities:ships",
  "slices": [
    [
      "      H'        ",
      "      H   ''''''",
      "      H   '     ",
      "      H   '     ",
      "      H/  '     ",
      "      H'  '     ",
      "      HH  '     ",
      "      HH  '     ",
      "       ϛ''''''''",
      "        ϛH      ",
      "         ϛHH    ",
      "           HHHHH",
      "                ",
      "                ",
      "                ",
      "                "
    ],
    [
      "      H'        ",
      "      H   ''''''",
      "     HH   '     ",
      "     HH   '     ",
      "     HH   '    ^",
      "      H/  '    I",
      "      H'  '     ",
      "       H' '     ",
      "        ϛ'''''''",
      "         ϛHH    ",
      "          HHHHHH",
      "             HHH",
      "                ",
      "                ",
      "                ",
      "                "
    ],
    [
      "     ϤH΃΃΃HHHHHH",
      "    ϤH΃΃΃΃HHHHHH",
      "    H΃΃΃΃΃HHHHHH",
      "    H΃΃ ΃΃΃HHHHH",
      "    H΃΃ ΃΃΃HHHHH",
      "    ϤH΃ ΃΃΃΃΃΃΃΃",
      "     ϤH/΃΃΃΃΃΃΃΃",
      "       H΃΃΃΃΃΃΃΃",
      "        HHH΃΃΃΃΃",
      "         HHH΃΃΃΃",
      "          HHHHHH",
      "                ",
      "                ",
      "                ",
      "                ",
      "                "
    ],
    [
      "     ζHH H  zNNN",
      "    ζHH  H   NNN",
      "    HH       NNN",
      "    H    HHH  ..",
      "    H    HHHHHHH",
      "    αH    H     ",
      "     αH    HHHHH",
      "      αH        ",
      "       αHHH     ",
      "          HHH   ",
      "            HHHH",
      "                ",
      "                ",
      "                ",
      "                ",
      "                "
    ],
    [
      "         ϥ      ",
      "         Π      ",
      "                ",
      "         HHH# ..",
      "         HHHHHHH",
      "          H#    ",
      "           HHHHH",
      "                ",
      "                ",
      "          H     ",
      "                ",
      "                ",
      "                ",
      "                ",
      "                ",
      "                "
    ],
    [
      "         H   HHH",
      "         HHHHHHH",
      "         HHHHHHH",
      "         HHHHHHH",
      "         HHHHHHH",
      "          HHHHHH",
      "           HHHHH",
      "                ",
      "           H    ",
      "          ΤІ    ",
      "                ",
      "                ",
      "                ",
      "                ",
      "                ",
      "                "
    ]
  ]
}