{
  "xsize": 16,
  "zsize": 16,
  "refpalette": "lostcities:ships",
  "slices": [
    [
      "#!              ",
      " !#             ",
      "#!##            ",
      " #!             ",
      "  !             ",
      "  !             ",
      "  !             ",
      "  !             ",
      "   !            ",
      "   !            ",
      "   !            ",
      "   !            ",
      "   !#           ",
      "   #!#          ",
      "    !           ",
      "    !           "
    ],
    [
      "#!              ",
      "#!#             ",
      " #!#            ",
      "  !             ",
      "  !             ",
      "  !             ",
      "  !             ",
      "   !            ",
      "   !            ",
      "   !            ",
      "   !            ",
      "   !            ",
      "    !           ",
      "   #!#          ",
      "    !           ",
      "    !           "
    ],
    [
      " !              ",
      "#!#             ",
      "##!#            ",
      "##!#            ",
      "  !             ",
      "  !             ",
      "  !             ",
      "   !            ",
      "   !            ",
      "   !            ",
      "   !            ",
      "   !            ",
      "    !           ",
      "   #!#          ",
      "    !           ",
      "    !           "
    ],
    [
      "$&#             ",
      "$&#             ",
      "$$&             ",
      "$$&#            ",
      "$$&             ",
      "$$&             ",
      "$$&             ",
      "$$$&            ",
      "$$$&            ",
      "$$$&            ",
      "$$$&            ",
      "$$$&            ",
      "$$$$&#          ",
      "$$$$&#          ",
      "$$$$&           ",
      "'$$$&           "
    ],
    [
      "#H#             ",
      "##H             ",
      "# H             ",
      "##H#            ",
      " #H#            ",
      "  H             ",
      "   H            ",
      "   H            ",
      "   H            ",
      "   H            ",
      "   H            ",
      "    H#          ",
      "    H##         ",
      "   #H##         ",
      "    H#          ",
      " $$$H           "
    ],
    [
      " #H             ",
      "  H             ",
      "  H             ",
      "  H#            ",
      " #H##           ",
      "  #H            ",
      "   H            ",
      "   H            ",
      "   H            ",
      "   H            ",
      "    H           ",
      "    H#          ",
      "    H##         ",
      "    H#          ",
      "    H           ",
      " $$$$H          "
    ]
  ]
}