{
  "xsize": 16,
  "zsize": 16,
  "slices": [
    [
      "################",
      "##QSQSQSQSQSQSQ#",
      "#QSQSQSQSQSQSQSQ",
      "#SQSQSQSQSQSQSQS",
      "#QSQSQSQSQSQSQSQ",
      "#SQSQSQSQSQSQSQS",
      "#QSQSQSQSQSQSQSQ",
      "#SQSQSQSQSQSQSQS",
      "#QSQSQSQSQSQSQSQ",
      "#SQSQSQSQSQSQ  S",
      "#QSQSQSQSQSQS  Q",
      "#SQSQSQSQSQSQ  S",
      "#QSQSQSQSQSQS  Q",
      "#SQSQSQSQSQSQ))S",
      "#QSQSQSQSQSQSQSQ",
      "##QSQSQSQSQSQSQS"
    ],
    [
      "##aaaaaaaaaaaaa#",
      "##             #",
      "a               ",
      "a               ",
      "a               ",
      "a               ",
      "a               ",
      "a               ",
      "a            )) ",
      "a           Q  Q",
      "a           Q  Q",
      "a           Q  Q",
      "a           Q  Q",
      "a           Q  Q",
      "a               ",
      "##              "
    ],
    [
      "##aaaaaaaaaaaaa#",
      "##             #",
      "a               ",
      "a               ",
      "a               ",
      "a               ",
      "a               ",
      "a               ",
      "a               ",
      "a           a))a",
      "a           a  a",
      "a           a  a",
      "a           a  a",
      "a           a  a",
      "a               ",
      "##              "
    ],
    [
      "##aaaaaaaaaaaaa#",
      "##             #",
      "a               ",
      "a               ",
      "a               ",
      "a               ",
      "a               ",
      "a               ",
      "a               ",
      "a           a  a",
      "a           a))a",
      "a           a  a",
      "a           a  a",
      "a           a  a",
      "a               ",
      "##              "
    ],
    [
      "##aaaaaaaaaaaaa#",
      "##             #",
      "a               ",
      "a               ",
      "a               ",
      "a               ",
      "a               ",
      "a               ",
      "a               ",
      "a           a  a",
      "a           a  a",
      "a           a))a",
      "a           a  a",
      "a           a  a",
      "a               ",
      "##              "
    ],
    [
      "################",
      "################",
      "################",
      "################",
      "################",
      "################",
      "################",
      "################",
      "################",
      "#############  #",
      "#############  #",
      "#############  #",
      "#############))#",
      "#############  #",
      "################",
      "################"
    ]
  ]
}