{
  "refpalette": "lostcities:town_interior",
  "xsize": 16,
  "zsize": 16,
  "slices": [
    [
      "                ",
      "                ",
      "                ",
      "  kkkkkkkkkkk   ",
      "  k         k   ",
      "  kkkkkkkkkkk   ",
      "                ",
      "  kkkkkkkkkkk   ",
      "  k         k   ",
      "  kkkkkkkkkkk   ",
      "                ",
      "  kkkkkkkkkkk   ",
      "  k         k   ",
      "  kkkkkkkkkkk   ",
      "                ",
      "                "
    ],
    [
      "                ",
      "                ",
      ":               ",
      ":               ",
      ":  ummmmmmmu    ",
      ":               ",
      "#               ",
      "                ",
      "   ummmmmmmu    ",
      "#               ",
      ":               ",
      ":               ",
      ":  ummmmmmmu    ",
      ":               ",
      ":               ",
      "#:::::#  #::::  "
    ],
    [
      "                ",
      "                ",
      ":               ",
      ":               ",
      ":  uHHHHHHHu    ",
      ":               ",
      "#               ",
      "                ",
      "   uHHHHHHHu    ",
      "#               ",
      ":               ",
      ":               ",
      ":  uHHHHHHHu    ",
      ":               ",
      ":               ",
      "#:::::#  #::::  "
    ],
    [
      "                ",
      "                ",
      ":               ",
      ":               ",
      ":  uHHHHHHHu    ",
      ":               ",
      "#               ",
      "                ",
      "   uHHHHHHHu    ",
      "#               ",
      ":               ",
      ":               ",
      ":  uHHHHHHHu    ",
      ":               ",
      ":               ",
      "#:::::#  #::::  "
    ],
    [
      "                ",
      "                ",
      ":               ",
      ":               ",
      ":               ",
      ":               ",
      "#  <   E   >    ",
      "#               ",
      "#               ",
      "#               ",
      ":  <   E   >    ",
      ":               ",
      ":               ",
      ":               ",
      ":               ",
      "#:::::####::::  "
    ]
  ]
}