{
  "xsize": 16,
  "zsize": 16,
  "refpalette": "lostcities:town_interior",
  "slices": [
    [
      "                ",
      "                ",
      "                ",
      "                ",
      "                ",
      "                ",
      "                ",
      "                ",
      "                ",
      "                ",
      "      kkkk      ",
      "      kkkk      ",
      "      kkkk      ",
      "  1             ",
      "                ",
      "                "
    ],
    [
      "  ````#  #````##",
      "      |  |    |#",
      "   .            ",
      "                ",
      "   .           #",
      "               `",
      "             u `",
      "      (  (   u `",
      "             u `",
      "     $$$$$$    `",
      "     $    $  u `",
      "       ))    u `",
      "             u `",
      "  uu  uuuu     `",
      "                ",
      "                "
    ],
    [
      "  ````#  #````##",
      "      i  i    i#",
      "   -            ",
      "                ",
      "   -           #",
      "               `",
      "             L `",
      "             L `",
      "             L `",
      "       -- *    `",
      "             L `",
      "             L `",
      "             L `",
      "  LL  LLLL     `",
      "                ",
      "                "
    ],
    [
      "  ````#  #````##",
      "      i  i    i#",
      "                ",
      "                ",
      "               #",
      "               `",
      "             L `",
      "             L `",
      "             L `",
      "               `",
      "             L `",
      "             L `",
      "             L `",
      "  ?L  LLLL     `",
      "                ",
      "                "
    ],
    [
      "  ````####````##",
      "               #",
      "               #",
      "               #",
      "               #",
      "               `",
      "               `",
      "               `",
      "               `",
      "               `",
      "               `",
      "               `",
      "               `",
      "               `",
      "                ",
      "                "
    ]
  ]
}
