{
  "xsize": 16,
  "zsize": 16,
  "refpalette": "lostcities:town_interior",
  "slices": [
    [
      "                ",
      "                ",
      "             1  ",
      "      kkkk      ",
      "      kkkk      ",
      "      kkkk      ",
      "                ",
      "                ",
      "                ",
      "                ",
      "                ",
      "                ",
      "                ",
      "                ",
      "                ",
      "                "
    ],
    [
      "                ",
      "                ",
      "`     uuuu  uu  ",
      "` u             ",
      "` u    ((       ",
      "` u  $    $     ",
      "` u  $$$$$$     ",
      "`               ",
      "` |   )  )      ",
      "`               ",
      "` u             ",
      "` u         .   ",
      "` u             ",
      "` u         .   ",
      "#     |  |      ",
      "##````#  #````  "
    ],
    [
      "                ",
      "                ",
      "`     LLLL  LL  ",
      "` L             ",
      "` L             ",
      "` L             ",
      "` L  * --       ",
      "`               ",
      "` i             ",
      "`               ",
      "` L             ",
      "` L         -   ",
      "` L             ",
      "` L         -   ",
      "#     i  i      ",
      "##````#  #````  "
    ],
    [
      "                ",
      "                ",
      "`     LLLL  L?  ",
      "` L             ",
      "` L             ",
      "` L             ",
      "` L             ",
      "`               ",
      "` i             ",
      "`               ",
      "` L             ",
      "` L             ",
      "` L             ",
      "` L             ",
      "#     i  i      ",
      "##````#  #````  "
    ],
    [
      "                ",
      "                ",
      "`               ",
      "`               ",
      "`               ",
      "`               ",
      "`               ",
      "`               ",
      "`               ",
      "`               ",
      "`               ",
      "`               ",
      "`               ",
      "`               ",
      "#               ",
      "##````####````  "
    ]
  ]
}