{
  "refpalette": "lostcities:town_interior",
  "xsize": 16,
  "zsize": 16,
  "slices": [
    [
      "                ",
      "                ",
      "                ",
      "                ",
      "                ",
      "                ",
      "                ",
      "                ",
      "                ",
      "                ",
      "                ",
      "                ",
      "                ",
      "                ",
      "                ",
      "                "
    ],
    [
      "                ",
      "                ",
      "                ",
      "  ###########   ",
      "  #        1#   ",
      "  # #:      #   ",
      "  # #########   ",
      "  #        j#   ",
      "  # ## ### ##   ",
      "  # 1# #V1  #   ",
      "  #  # #V   #   ",
      "  # :# #V   #   ",
      "  #  # #V  1#   ",
      "  #VV# #VVVV#   ",
      "  ###$:$#####   ",
      "                "
    ],
    [
      "                ",
      "                ",
      "                ",
      "  ###########   ",
      "  #         #   ",
      "  # #: VVVV #   ",
      "  # #########   ",
      "  #        *#   ",
      "  # ## ### ##   ",
      "  #  # #    #   ",
      "  #  # #!   #   ",
      "  # :# #!   #   ",
      "  #  # #    #   ",
      "  #C # # !! #   ",
      "  ###$:$#####   ",
      "                "
    ],
    [
      "                ",
      "                ",
      "                ",
      "  ###########   ",
      "  # #       #   ",
      "  # #:  ?   #   ",
      "  # #########   ",
      "  # #       #   ",
      "  #### ######   ",
      "  #  # #    #   ",
      "  #  # #    #   ",
      "  # :# #  V #   ",
      "  #  # #    #   ",
      "  #  # #    #   ",
      "  ###$$$#####   ",
      "                "
    ],
    [
      "                ",
      "                ",
      "                ",
      "  ###########   ",
      "  #{#%   %  #   ",
      "  # #::     #   ",
      "  # #########   ",
      "  # # %%   {#   ",
      "  #### ######   ",
      "  #% # #  % #   ",
      "  #  # #    #   ",
      "  # :# #  u #   ",
      "  # :# #    #   ",
      "  #  # #    #   ",
      "  ###########   ",
      "                "
    ]
  ]
}
