{
  "xsize": 16,
  "zsize": 16,
  "slices": [
    [
      "################",
      "################",
      "################",
      "################",
      "################",
      "################",
      "################",
      "################",
      "################",
      "#######l########",
      "################",
      "################",
      "################",
      "################",
      "################",
      "################"
    ],
    [
      "                ",
      "                ",
      "           # #  ",
      "                ",
      "           # #  ",
      "                ",
      "    aaaaaaa     ",
      "    a:   :a     ",
      "                ",
      "                ",
      "                ",
      "    a:   :a     ",
      "    aaaaaaa     ",
      "                ",
      "                ",
      "                "
    ],
    [
      "                ",
      "                ",
      "           : :  ",
      "                ",
      "           : :  ",
      "                ",
      "    aaaaaaa     ",
      "    a:   :a     ",
      "                ",
      "                ",
      "                ",
      "    a:   :a     ",
      "    aaaaaaa     ",
      "                ",
      "                ",
      "                "
    ],
    [
      "                ",
      "                ",
      "           :::  ",
      "           : :  ",
      "           :::  ",
      "                ",
      "    #######     ",
      "    #######     ",
      "    #######     ",
      "    #######     ",
      "    #######     ",
      "    #######     ",
      "    #######     ",
      "                ",
      "                ",
      "                "
    ],
    [
      "                ",
      "                ",
      "            :   ",
      "           :::  ",
      "            :   ",
      "                ",
      "                ",
      "                ",
      "                ",
      "                ",
      "                ",
      "     :          ",
      "                ",
      "                ",
      "                ",
      "                "
    ],
    [
      "                ",
      "                ",
      "                ",
      "            :   ",
      "                ",
      "                ",
      "                ",
      "                ",
      "                ",
      "                ",
      "                ",
      "     :          ",
      "                ",
      "                ",
      "                ",
      "                "
    ],
    [
      "                ",
      "                ",
      "                ",
      "            g   ",
      "                ",
      "                ",
      "                ",
      "                ",
      "                ",
      "                ",
      "                ",
      "                ",
      "                ",
      "                ",
      "                ",
      "                "
    ]
  ]
}