{
  "xsize": 16,
  "zsize": 16,
  "slices": [
    [
      "################",
      "################",
      "################",
      "################",
      "################",
      "################",
      "################",
      "################",
      "################",
      "################",
      "################",
      "################",
      "################",
      "################",
      "################",
      "################"
    ],
    [
      "################",
      "#DDDGDDDDDGDDDD#",
      "#DGGDDDDDDDDGDD#",
      "#DDDDGDDDDDGDDD#",
      "#DDDDDDGDDGDDDD#",
      "#DDDGDDDDDDDDGD#",
      "#DDDDDDDGDDDDDD#",
      "#DDDGDDDDGDDDGD#",
      "#DDDGDDGDGDDDDD#",
      "#DDDDDDDGDDDDGD#",
      "#DDDDGDDDDDDGDD#",
      "#DDDDDDGDDGDDDD#",
      "#DGDDDGDDDDGDDD#",
      "#DDGDDDDDDGDDDD#",
      "#DDDGDDDDDDDDDD#",
      "################"
    ],
    [
      "                ",
      "     K       p  ",
      " p    p         ",
      "           p    ",
      "    p           ",
      "         p      ",
      " K     K        ",
      "           K    ",
      "    p        p  ",
      "                ",
      "     K          ",
      "        p       ",
      "            K   ",
      "   p            ",
      "           p    ",
      "                "
    ]
  ]
}