{
  "xsize": 16,
  "zsize": 16,
  "refpalette": "lostcities:top_decorations",
  "slices": [
    [
      "################",
      "################",
      "################",
      "################",
      "################",
      "################",
      "################",
      "################",
      "################",
      "################",
      "################",
      "################",
      "################",
      "################",
      "################",
      "################"
    ],
    [
      "                ",
      "                ",
      "                ",
      "   uukuu        ",
      "   uukuu        ",
      "     k          ",
      "   uukuu        ",
      "   uukuu        ",
      "     k          ",
      "     k          ",
      "     k    uuu   ",
      "     kkkkkuuu   ",
      "          uuu   ",
      "                ",
      "                ",
      "                "
    ],
    [
      "                ",
      "                ",
      "                ",
      "   mn mn        ",
      "   qr qr        ",
      "                ",
      "   mn mn        ",
      "   qr qr        ",
      "                ",
      "                ",
      "                ",
      "           :    ",
      "                ",
      "                ",
      "                ",
      "                "
    ],
    [
      "                ",
      "                ",
      "                ",
      "                ",
      "                ",
      "                ",
      "                ",
      "                ",
      "                ",
      "                ",
      "           :    ",
      "          :::   ",
      "           :    ",
      "                ",
      "                ",
      "                "
    ]
  ]
}
