{
  "xsize": 16,
  "zsize": 16,
  "slices": [
    [
      "################",
      "################",
      "################",
      "################",
      "################",
      "################",
      "################",
      "################",
      "################",
      "################",
      "################",
      "################",
      "################",
      "################",
      "################",
      "################"
    ],
    [
      "                ",
      "                ",
      "                ",
      "                ",
      "    #aa#aa#     ",
      "    a     a     ",
      "    a     a     ",
      "          a     ",
      "    a     a     ",
      "    a     a     ",
      "    #aa#aa#     ",
      "                ",
      "                ",
      "                ",
      "                ",
      "                "
    ],
    [
      "                ",
      "                ",
      "                ",
      "                ",
      "    #aa#aa#     ",
      "    a     a     ",
      "    a     a     ",
      "          a     ",
      "    a     a     ",
      "    a     a     ",
      "    #aa#aa#     ",
      "                ",
      "                ",
      "                ",
      "                ",
      "                "
    ],
    [
      "                ",
      "                ",
      "                ",
      "                ",
      "    #######     ",
      "    #######     ",
      "    #######     ",
      "    #######     ",
      "    #######     ",
      "    #######     ",
      "    #######     ",
      "                ",
      "                ",
      "                ",
      "                ",
      "                "
    ]
  ]
}