{
  "xsize": 16,
  "zsize": 16,
  "slices": [
    [
      "################",
      "#SSSSSSSSSSSSSSS",
      "#SSSSSSSSSSSSSSS",
      "#SS#############",
      "#SS#QQQQQQQQQQQQ",
      "#SS#QQQQQQQQQQQQ",
      "#SS#QQQQQQQQQQQQ",
      "#SS#QQQQQQQQQQQQ",
      "#SS#QQQQQQQQQ((Q",
      "#SS#QQQQQQQQQ  Q",
      "#SS#QQQQQQQQQ  Q",
      "#SS#QQQQQQQQQ  Q",
      "#SS#QQQQQQQQQ  Q",
      "#SS#QQQQQQQQQ  Q",
      "#SS#QQQQQQQQQQQQ",
      "#SS#QQQQQQQQQQQQ"
    ],
    [
      "################",
      "#               ",
      "#               ",
      "#               ",
      "#               ",
      "#               ",
      "#               ",
      "#               ",
      "#           w  w",
      "#           w  w",
      "#           w  w",
      "#           w  w",
      "#           w  w",
      "#           w((w",
      "#               ",
      "#               "
    ],
    [
      "################",
      "#               ",
      "#               ",
      "#               ",
      "#               ",
      "#               ",
      "#               ",
      "#               ",
      "#           :  :",
      "#           :  :",
      "#           :  :",
      "#           :  :",
      "#           :((:",
      "#           :  :",
      "#               ",
      "#               "
    ],
    [
      "################",
      "#               ",
      "#               ",
      "#               ",
      "#               ",
      "#               ",
      "#               ",
      "#               ",
      "#           :  :",
      "#           :  :",
      "#           :  :",
      "#           :((:",
      "#           :  :",
      "#           :  :",
      "#               ",
      "#               "
    ],
    [
      "################",
      "#               ",
      "#               ",
      "#               ",
      "#               ",
      "#               ",
      "#               ",
      "#               ",
      "#           :  :",
      "#           :  :",
      "#           :((:",
      "#           :  :",
      "#           :  :",
      "#           :  :",
      "#               ",
      "#               "
    ],
    [
      "################",
      "################",
      "################",
      "################",
      "################",
      "################",
      "################",
      "################",
      "#############  #",
      "#############((#",
      "#############  #",
      "#############  #",
      "#############  #",
      "#############  #",
      "################",
      "################"
    ]
  ]
}
