{
  "refpalette": "lostcities:top_decorations",
  "xsize": 16,
  "zsize": 16,
  "slices": [
    [
      "################",
      "################",
      "################",
      "################",
      "################",
      "################",
      "################",
      "################",
      "################",
      "################",
      "################",
      "################",
      "################",
      "################",
      "################",
      "################"
    ],
    [
      "                ",
      "                ",
      "                ",
      "   :uu     ::   ",
      "   :uukkkkku:   ",
      "   :uu     k    ",
      "   :uu     k    ",
      "    PP     k    ",
      "    P     uu    ",
      "   :uu    uu    ",
      "   :uu    PP    ",
      "   :uu    uu    ",
      "   :uu    uu    ",
      "                ",
      "                ",
      "                "
    ],
    [
      "                ",
      "                ",
      "                ",
      "    __          ",
      "    __     u    ",
      "    __          ",
      "    __          ",
      "                ",
      "          mn    ",
      "    __    qr    ",
      "    __          ",
      "    __    mn    ",
      "    __    qr    ",
      "                ",
      "                ",
      "                "
    ],
    [
      "                ",
      "                ",
      "                ",
      "                ",
      "           :    ",
      "                ",
      "                ",
      "                ",
      "                ",
      "                ",
      "                ",
      "                ",
      "                ",
      "                ",
      "                ",
      "                "
    ],
    [
      "                ",
      "                ",
      "                ",
      "                ",
      "           g    ",
      "                ",
      "                ",
      "                ",
      "                ",
      "                ",
      "                ",
      "                ",
      "                ",
      "                ",
      "                ",
      "                "
    ]
  ]
}
