{
  "refpalette": "lostcities:top_decorations",
  "xsize": 16,
  "zsize": 16,
  "slices": [
    [
      "################",
      "################",
      "################",
      "################",
      "################",
      "################",
      "################",
      "################",
      "################",
      "################",
      "################",
      "################",
      "################",
      "################",
      "################",
      "################"
    ],
    [
      "                ",
      "                ",
      "                ",
      "                ",
      "    uu uu uu    ",
      "    uu uu uu    ",
      "                ",
      "                ",
      "                ",
      "                ",
      "    uu uu uu    ",
      "    uu uu uu    ",
      "                ",
      "                ",
      "                ",
      "                "
    ],
    [
      "                ",
      "                ",
      "                ",
      "                ",
      "    mn mn mn    ",
      "    qr qr qr    ",
      "                ",
      "                ",
      "                ",
      "                ",
      "    mn mn mn    ",
      "    qr qr qr    ",
      "                ",
      "                ",
      "                ",
      "                "
    ]
  ]
}
