{
  "meta": [
    {
      "key": "dontconnect",
      "boolean": true
    }
  ],
  "xsize": 16,
  "zsize": 16,
  "slices": [
    [
      "################",
      "#SSSSSSSSSS#SSSS",
      "#SSSSSSSSS#SSSSS",
      "#SSSSSSSS#SSS###",
      "#SSSSSSS#SSS#QQQ",
      "#SSSSSS#SSS#QQQQ",
      "#SSSSS#SSS#QQQQQ",
      "#SSSS#SSS#QQQQQQ",
      "#SSS#SSS#QQQQ((Q",
      "#SS#SSS#QQQQQ  Q",
      "#S#SSS#QQQQQQ  Q",
      "##SSS#QQQQQQQ  Q",
      "#SSS#QQQQQQQQ  Q",
      "#SS#QQQQQQQQQ  Q",
      "#SS#QQQQQQQQQQQQ",
      "#SS#QQQQQQQQQQQQ"
    ],
    [
      "#######     #aaa",
      "#WWWWW#    +    ",
      "#WWWW#    +     ",
      "#WWW#    +      ",
      "#WW#    #       ",
      "#W#    +        ",
      "##    +         ",
      "     +          ",
      "    #       w  w",
      "   +        w  w",
      "  +         w  w",
      " +          w  w",
      "#           w  w",
      "a           w((w",
      "a               ",
      "a               "
    ],
    [
      "##### *     #aaa",
      "#WW        +    ",
      "#W        +     ",
      "#        +      ",
      "#       #       ",
      "       +        ",
      "*     +         ",
      "     +          ",
      "    #       :  :",
      "   +        :  :",
      "  +         :  :",
      " +          :  :",
      "#           :((:",
      "a           :  :",
      "a               ",
      "a               "
    ],
    [
      "####        #aaa",
      "#W         +    ",
      "#         +     ",
      "#        +      ",
      "        #       ",
      "       +        ",
      "      +         ",
      "     +          ",
      "    #       :  :",
      "   +        :  :",
      "  +         :  :",
      " +          :((:",
      "#           :  :",
      "a           :  :",
      "a               ",
      "a               "
    ],
    [
      "###         ####",
      "#          #    ",
      "#         #     ",
      "         #      ",
      "        #       ",
      "       #        ",
      "      #         ",
      "     #          ",
      "    #       :  :",
      "   #        :  :",
      "  #         :((:",
      " #          :  :",
      "#           :  :",
      "#           :  :",
      "#               ",
      "#               "
    ],
    [
      "            ####",
      "           #####",
      "          ######",
      "         #######",
      "        ########",
      "       #########",
      "      ##########",
      "     ###########",
      "    #########  #",
      "   ##########((#",
      "  ###########  #",
      " ############  #",
      "#############  #",
      "#############  #",
      "################",
      "################"
    ]
  ]
}
