{
  "refpalette": "lcmt:library_interior",
  "xsize": 16,
  "zsize": 16,
  "slices": [
    [
      "                ",
      "                ",
      "                ",
      "                ",
      "                ",
      "                ",
      "                ",
      "                ",
      "                ",
      "                ",
      "                ",
      "                ",
      "                ",
      "                ",
      "                ",
      "                "
    ],
    [
      "                ",
      "                ",
      "   jQj jQj      ",
      "   Q1j j1Q      ",
      "  LQ     QL     ",
      "  LQ     QL     ",
      "  LQ     QL     ",
      "  LQjj*jjQL     ",
      "   QQQQQQQ      ",
      "   jQQQQQj      ",
      "  |  LHL  |     ",
      "                ",
      "                ",
      "                ",
      "                ",
      "                "
    ],
    [
      "                ",
      "                ",
      "   jfj jfj      ",
      "   f j j f      ",
      "  Lf     fL     ",
      "  Lf     fL     ",
      "  Lf     fL     ",
      "  Lf?C C?fL     ",
      "   fffffff      ",
      "   jfffffj      ",
      "  i  LLH  i     ",
      "                ",
      "                ",
      "                ",
      "                ",
      "                "
    ],
    [
      "                ",
      "                ",
      "   jfQQQfj      ",
      "   f QQQ f      ",
      "  Lf     fL     ",
      "  Lf     fL     ",
      "  Lf     fL     ",
      "  Lf     fL     ",
      "   fffffff      ",
      "   jfffffj      ",
      "  i  HLL  i     ",
      "                ",
      "                ",
      "                ",
      "                ",
      "                "
    ],
    [
      "                ",
      "                ",
      "   jfffffj      ",
      "   f fff f      ",
      "   f     f      ",
      "   f     f      ",
      "   f     f      ",
      "   fIILILf      ",
      "   f4fff1f      ",
      "   jfffffj      ",
      "                ",
      "                ",
      "                ",
      "                ",
      "                ",
      "                "
    ]
  ]
}
