{
  "xsize": 16,
  "zsize": 16,
  "slices": [
    [
      "#SS#QQQQQQQQQQQQ",
      "#SS#QQQQQQQQQQQQ",
      "#SS#QQQQQQQQQQQQ",
      "#SS#QQQQQQQQQQQQ",
      "#SS#QQQQQQQQQQQQ",
      "#SS#QQQQQQQQQQQQ",
      "#SS#QQQQQQQQQQQQ",
      "#SS#QQQQQQQQQQQQ",
      "#SS#QQQQQQQQQQQQ",
      "#SS#QQQQQQQQQQQQ",
      "#SS#QQQQQQQQQQQQ",
      "#SS#QQQQQQQQQQQQ",
      "#SS#############",
      "#SSSSSSSSSSSSSSS",
      "#SSSSSSSSSSSSSSS",
      "################"
    ],
    [
      "#               ",
      "#               ",
      "#               ",
      "#               ",
      "#               ",
      "#               ",
      "#               ",
      "#               ",
      "#               ",
      "#               ",
      "#               ",
      "#               ",
      "#               ",
      "#               ",
      "#               ",
      "################"
    ],
    [
      "#               ",
      "#               ",
      "#               ",
      "#               ",
      "#               ",
      "#               ",
      "#               ",
      "#               ",
      "#               ",
      "#               ",
      "#               ",
      "#               ",
      "#               ",
      "#               ",
      "#               ",
      "################"
    ],
    [
      "#               ",
      "#               ",
      "#               ",
      "#               ",
      "#               ",
      "#               ",
      "#               ",
      "#               ",
      "#               ",
      "#               ",
      "#               ",
      "#               ",
      "#               ",
      "#               ",
      "#               ",
      "################"
    ],
    [
      "#               ",
      "#               ",
      "#               ",
      "#               ",
      "#               ",
      "#               ",
      "#               ",
      "#               ",
      "#               ",
      "#               ",
      "#               ",
      "#               ",
      "#               ",
      "#               ",
      "#               ",
      "################"
    ],
    [
      "################",
      "################",
      "################",
      "################",
      "################",
      "################",
      "################",
      "################",
      "################",
      "################",
      "################",
      "################",
      "################",
      "################",
      "################",
      "################"
    ]
  ]
}