{
  "xsize": 16,
  "zsize": 16,
  "slices": [
    [
      "            ####",
      "           #####",
      "          ######",
      "         #######",
      "        ########",
      "       #########",
      "      ##########",
      "     ###########",
      "    #########((#",
      "   ##########  #",
      "  ###########  #",
      " ############  #",
      "#############  #",
      "#############  #",
      "################",
      "################"
    ],
    [
      "                ",
      "                ",
      "                ",
      "                ",
      "                ",
      "                ",
      "                ",
      "            :  :",
      "            :  :",
      "       ##   :  :",
      "      #D#   :  :",
      "     #GD#   :  :",
      "    #DDD#   :  :",
      "    #####   :  :",
      "            :  :",
      "            ::::"
    ],
    [
      "                ",
      "                ",
      "                ",
      "                ",
      "                ",
      "                ",
      "                ",
      "                ",
      "                ",
      "                ",
      "       K        ",
      "      KK        ",
      "     KKK        ",
      "                ",
      "                ",
      "                "
    ]
  ]
}
