{
  "xsize": 16,
  "zsize": 16,
  "slices": [
    [
      "#@#@#@#@@#@#@#@#",
      "@##############@",
      "################",
      "@##############@",
      "################",
      "@##############@",
      "################",
      "@##############@",
      "@##############@",
      "################",
      "@#########  ###@",
      "##########  ####",
      "@#########  ###@",
      "##########cc####",
      "@##############@",
      "#@#@#@#@@#@#@#@#"
    ],
    [
      "#`#`#`#``#`#`#`#",
      "`     :  :   F `",
      "#L    #  #     #",
      "`              `",
      "#L    #  #    F#",
      "`     :  : C   `",
      "#:# #:#  #:# #:#",
      "`              `",
      "`         cc   `",
      "#:# #:#  :dd:  #",
      "`     :  :  :  `",
      "#L    #  :  :  #",
      "`        :  :  `",
      "#     #        #",
      "` F F :       *`",
      "#`#`#`#``#`#`#`#"
    ],
    [
      "#`#`#`#``#`#`#`#",
      "`     :  :     `",
      "#L    #  #     #",
      "`              `",
      "#L    #  #     #",
      "`     :  :     `",
      "#:# #:#  #:# #:#",
      "`              `",
      "`              `",
      "#:# #:#   cc   #",
      "`     :   dd   `",
      "#     #        #",
      "`              `",
      "#     #        #",
      "`     :        `",
      "#`#`#`#``#`#`#`#"
    ],
    [
      "#`#`#`#``#`#`#`#",
      "`     :  :     `",
      "#     #  #     #",
      "`              `",
      "#     #  #     #",
      "`     :  :     `",
      "#:# #:#  #:# #:#",
      "`              `",
      "`              `",
      "#:# #:#        #",
      "`     :   cc   `",
      "#     #   dd   #",
      "`              `",
      "#     #        #",
      "`     :        `",
      "#`#`#`#``#`#`#`#"
    ],
    [
      "#`#`#`#``#`#`#`#",
      "`     :  :     `",
      "#     #  #     #",
      "`           E  `",
      "#     #  #     #",
      "`     :  :     `",
      "#:# #:#  #:# #:#",
      "`              `",
      "`              `",
      "#:# #:#        #",
      "`     :        `",
      "#     #   cc   #",
      "`  E      dd   `",
      "#     #        #",
      "`     :        `",
      "#`#`#`#``#`#`#`#"
    ],
    [
      "#`#`#`#``#`#`#`#",
      "`     #  #     `",
      "#     #  #     #",
      "`     #  #  {  `",
      "#     #  #     #",
      "`     #  #     `",
      "######1#########",
      "`     #        `",
      "`     #        `",
      "#######        #",
      "`     #        `",
      "#     #        #",
      "`  {  #   cc   `",
      "#     #   dd   #",
      "`     #        `",
      "#`#`#`#``#`#`#`#"
    ]
  ]
}
