{
  "xsize": 16,
  "zsize": 16,
  "slices": [
    [
      "#@#@#@#@@#@#@#@#",
      "@##############@",
      "################",
      "@##############@",
      "################",
      "@##############@",
      "################",
      "@##############@",
      "@##############@",
      "################",
      "@#########  ###@",
      "##########  ####",
      "@#########  ###@",
      "##########cc####",
      "@##############@",
      "#@#@#@#@@#@#@#@#"
    ],
    [
      "#`#`#`#``#`#`#`#",
      "`     #        `",
      "#     `      $ #",
      "` F F `        `",
      "# $$$ `      $ #",
      "`     #        `",
      "#     #        #",
      "`              `",
      "`         cc   `",
      "#     #  :dd:  #",
      "`     #  :  :  `",
      "# $$$ `  :  :  #",
      "` F F `  :  :  `",
      "#     `        #",
      "`     #        `",
      "#`#`#`#``#`#`#`#"
    ],
    [
      "#`#`#`#``#`#`#`#",
      "`     #        `",
      "#     `      + #",
      "`     `        `",
      "# *   `      + #",
      "`     #        `",
      "#     #        #",
      "`              `",
      "`              `",
      "#     #   cc   #",
      "`     #   dd   `",
      "#   * `        #",
      "`     `        `",
      "#     `        #",
      "`     #        `",
      "#`#`#`#``#`#`#`#"
    ],
    [
      "#`#`#`#``#`#`#`#",
      "`     #        `",
      "#     `        #",
      "`     `        `",
      "#     `        #",
      "`     #        `",
      "#     #        #",
      "`              `",
      "`              `",
      "#     #        #",
      "`     #   cc   `",
      "#     `   dd   #",
      "`     `        `",
      "#     `        #",
      "`     #        `",
      "#`#`#`#``#`#`#`#"
    ],
    [
      "#`#`#`#``#`#`#`#",
      "`     #        `",
      "#     `        #",
      "`  E  `        `",
      "#     `        #",
      "`     #        `",
      "#     #        #",
      "`     #        `",
      "`     #        `",
      "#     #        #",
      "`     #        `",
      "#     `   cc   #",
      "`  E  `   dd   `",
      "#     `        #",
      "`     #        `",
      "#`#`#`#``#`#`#`#"
    ],
    [
      "#`#`#`#``#`#`#`#",
      "`     #        `",
      "#     `        #",
      "`  {  `        `",
      "#     `        #",
      "`     #        `",
      "#     #        #",
      "`     #        `",
      "`     #        `",
      "#     #        #",
      "`     #        `",
      "#     `        #",
      "`  {  `   cc   `",
      "#     `   dd   #",
      "`     #        `",
      "#`#`#`#``#`#`#`#"
    ]
  ]
}
