{
  "xsize": 16,
  "zsize": 16,
  "refpalette": "lostcities:top_decorations",
  "slices": [
    [
      "################",
      "################",
      "################",
      "################",
      "################",
      "################",
      "################",
      "################",
      "################",
      "################",
      "##########  ####",
      "##########  ####",
      "##########  ####",
      "##########cc####",
      "################",
      "################"
    ],
    [
      "                ",
      "                ",
      "                ",
      "         uuuu   ",
      "                ",
      "         uuuu   ",
      "                ",
      "                ",
      "                ",
      "                ",
      "         :  :   ",
      "         :  :   ",
      "         :  :   ",
      "         :  :   ",
      "                ",
      "                "
    ],
    [
      "                ",
      "                ",
      "                ",
      "         kkkk   ",
      "                ",
      "         kkkk   ",
      "                ",
      "                ",
      "                ",
      "                ",
      "         :  :   ",
      "         :  :   ",
      "         :  :   ",
      "         :  :   ",
      "                ",
      "                "
    ],
    [
      "                ",
      "                ",
      "                ",
      "                ",
      "                ",
      "                ",
      "                ",
      "                ",
      "                ",
      "                ",
      "         ____   ",
      "         ____   ",
      "         ____   ",
      "         ____   ",
      "                ",
      "                "
    ]
  ]
}