{
  "xsize": 16,
  "zsize": 16,
  "slices": [
    [
      "#@#@#@#@@#@#@#@#",
      "@##############@",
      "################",
      "@##############@",
      "################",
      "@##############@",
      "################",
      "@##############@",
      "@##############@",
      "################",
      "@#########  ###@",
      "##########  ####",
      "@#########  ###@",
      "##########cc####",
      "@##############@",
      "#@#@#@#@@#@#@#@#"
    ],
    [
      "#`#`#`#``#`#`#`#",
      "`              `",
      "#              #",
      "`              `",
      "#              #",
      "`    $LFF      `",
      "#    L1###  ####",
      "`    F#        `",
      "`    F#   cc   `",
      "##:::##  :dd:  #",
      "`     #  :  :  `",
      "# $$$ :  :  :  #",
      "` $$$ :  :  :  `",
      "# $$$ :        #",
      "`     #        `",
      "#`#`#`#``#`#`#`#"
    ],
    [
      "#`#`#`#``#`#`#`#",
      "`              `",
      "#              #",
      "`              `",
      "#              #",
      "`    *         `",
      "#     ####  ####",
      "`     #        `",
      "`     #        `",
      "##:::##   cc   #",
      "`     #   dd   `",
      "#     :        #",
      "`  C  :        `",
      "#     :        #",
      "`     #        `",
      "#`#`#`#``#`#`#`#"
    ],
    [
      "#`#`#`#``#`#`#`#",
      "`              `",
      "#              #",
      "`              `",
      "#              #",
      "`              `",
      "#     ##########",
      "`     #        `",
      "`     #        `",
      "##:::##        #",
      "`     #   cc   `",
      "#     :   dd   #",
      "`     :        `",
      "#     :        #",
      "`     #        `",
      "#`#`#`#``#`#`#`#"
    ],
    [
      "#`#`#`#``#`#`#`#",
      "`              `",
      "#              #",
      "`           E  `",
      "#              #",
      "`              `",
      "#     ##########",
      "`     #        `",
      "`     #        `",
      "#######        #",
      "`     #        `",
      "#     #   cc   #",
      "`     #   dd   `",
      "#     #        #",
      "`     #        `",
      "#`#`#`#``#`#`#`#"
    ],
    [
      "#`#`#`#``#`#`#`#",
      "`              `",
      "#              #",
      "`           {  `",
      "#              #",
      "`              `",
      "#     ##########",
      "`     #        `",
      "`     #        `",
      "#######        #",
      "`     #        `",
      "#     #        #",
      "`     #   cc   `",
      "#     #   dd   #",
      "`     #        `",
      "#`#`#`#``#`#`#`#"
    ]
  ]
}
