{
  "xsize": 16,
  "zsize": 16,
  "slices": [
    [
      "#@#@#@#@@#@#@#@#",
      "@##############@",
      "################",
      "@##############@",
      "################",
      "@##############@",
      "################",
      "@##############@",
      "@##############@",
      "################",
      "@#########  ###@",
      "##########  ####",
      "@#########  ###@",
      "##########cc####",
      "@##############@",
      "#@#@#@#@@#@#@#@#"
    ],
    [
      "#`#`#`#``#`#`#`#",
      "`              `",
      "#           __ #",
      "`              `",
      "#  _ Q _    QQ #",
      "`  _ Q _       `",
      "#    Q         #",
      "`  _ Q _       `",
      "`  _ Q _  cc   `",
      "#    Q   :dd:  #",
      "`  _ Q _ :  :  `",
      "#  _ Q _ :  :  #",
      "`        :  :  `",
      "#              #",
      "`              `",
      "#`#`#`#``#`#`#`#"
    ],
    [
      "#`#`#`#``#`#`#`#",
      "`              `",
      "#              #",
      "`              `",
      "#           *  #",
      "`              `",
      "#    *         #",
      "`              `",
      "`              `",
      "#    *    cc   #",
      "`         dd   `",
      "#              #",
      "`              `",
      "#              #",
      "`              `",
      "#`#`#`#``#`#`#`#"
    ],
    [
      "#`#`#`#``#`#`#`#",
      "`              `",
      "#              #",
      "`              `",
      "#              #",
      "`              `",
      "#              #",
      "`              `",
      "`              `",
      "#              #",
      "`         cc   `",
      "#         dd   #",
      "`              `",
      "#              #",
      "`              `",
      "#`#`#`#``#`#`#`#"
    ],
    [
      "#`#`#`#``#`#`#`#",
      "`              `",
      "#              #",
      "`              `",
      "#              #",
      "`              `",
      "#    E         #",
      "`              `",
      "`              `",
      "#    E         #",
      "`              `",
      "#         cc   #",
      "`         dd   `",
      "#              #",
      "`              `",
      "#`#`#`#``#`#`#`#"
    ],
    [
      "#`#`#`#``#`#`#`#",
      "`              `",
      "#              #",
      "`              `",
      "#              #",
      "`              `",
      "#    {         #",
      "`              `",
      "`              `",
      "#    {         #",
      "`              `",
      "#              #",
      "`         cc   `",
      "#         dd   #",
      "`              `",
      "#`#`#`#``#`#`#`#"
    ]
  ]
}
