{
  "meta": [
    {
      "integer": 4,
      "key": "z1"
    },
    {
      "integer": 11,
      "key": "z2"
    }
  ],
  "xsize": 6,
  "zsize": 12,
  "slices": [
    [
      "      ",
      "      ",
      "      ",
      "      ",
      "vvvvv§",
      "vvvvv/",
      "vvvvv/",
      "vvvvv/",
      "vvvvv/",
      "vvvvv/",
      "vvvvv/",
      "vvvvv§"
    ],
    [
      "      ",
      "      ",
      "      ",
      "      ",
      "vvvv§i",
      "vvvv/ ",
      "vvvv/ ",
      "vvvv/ ",
      "vvvv/ ",
      "vvvv/ ",
      "vvvv/ ",
      "vvvv§i"
    ],
    [
      "      ",
      "      ",
      "      ",
      "      ",
      "vvv§i ",
      "vvv/  ",
      "vvv/  ",
      "vvv/  ",
      "vvv/  ",
      "vvv/  ",
      "vvv/  ",
      "vvv§i "
    ],
    [
      "      ",
      "      ",
      "      ",
      "      ",
      "vv§i  ",
      "vv/   ",
      "vv/   ",
      "vv/   ",
      "vv/   ",
      "vv/   ",
      "vv/   ",
      "vv§i  "
    ],
    [
      "      ",
      "      ",
      "      ",
      "      ",
      "v§i   ",
      "v/    ",
      "v/    ",
      "v/    ",
      "v/    ",
      "v/    ",
      "v/    ",
      "v§i   "
    ],
    [
      "      ",
      "      ",
      "      ",
      "      ",
      "§i    ",
      "/     ",
      "/     ",
      "/     ",
      "/     ",
      "/     ",
      "/     ",
      "§i    "
    ],
    [
      "      ",
      "      ",
      "      ",
      "      ",
      "i     ",
      "      ",
      "      ",
      "      ",
      "      ",
      "      ",
      "      ",
      "i     "
    ]
  ]
}
