{
  "meta": [
    {
      "integer": 5,
      "key": "z1"
    },
    {
      "integer": 10,
      "key": "z2"
    }
  ],
  "xsize": 6,
  "zsize": 11,
  "slices": [
    [
      "      ",
      "      ",
      "      ",
      "      ",
      "      ",
      "vvvvvv",
      "vvvvv/",
      "vvvvv/",
      "vvvvv/",
      "vvvvv/",
      "vvvvvv"
    ],
    [
      "      ",
      "      ",
      "      ",
      "      ",
      "      ",
      "vvvvv_",
      "vvvv/ ",
      "vvvv/ ",
      "vvvv/ ",
      "vvvv/ ",
      "vvvvv_"
    ],
    [
      "      ",
      "      ",
      "      ",
      "      ",
      "      ",
      "vvvv_ ",
      "vvv/  ",
      "vvv/  ",
      "vvv/  ",
      "vvv/  ",
      "vvvv_ "
    ],
    [
      "      ",
      "      ",
      "      ",
      "      ",
      "      ",
      "vvv_  ",
      "vv/   ",
      "vv/   ",
      "vv/   ",
      "vv/   ",
      "vvv_  "
    ],
    [
      "      ",
      "      ",
      "      ",
      "      ",
      "      ",
      "vv_   ",
      "v/    ",
      "v/    ",
      "v/    ",
      "v/    ",
      "vv_   "
    ],
    [
      "      ",
      "      ",
      "      ",
      "      ",
      "      ",
      "v_    ",
      "/     ",
      "/     ",
      "/     ",
      "/     ",
      "v_    "
    ],
    [
      "      ",
      "      ",
      "      ",
      "      ",
      "      ",
      "_     ",
      "      ",
      "      ",
      "      ",
      "      ",
      "_     "
    ]
  ]
}