{
  "xsize": 16,
  "zsize": 16,
  "refpalette": "rails",
  "slices": [
    [
      "yyyyyyyyyyyyyyyy",
      "yyyyyyyyyyyyyyyy",
      "yyyyyyyyyyyyyyyy",
      "yyyyyyyyyyyyyyyy",
      "yyyyyyyyyyyyyyyy",
      "yyyyyyyyyyyyyyyy",
      "yyyyyyyyyyyyyyyy",
      "yyyyyyyyyyyyyyyy",
      "yyyyyyyyyyyyyyyy",
      "yyyyyyyyyyyyyyyy",
      "yyyyyyyyyyyyyyyy",
      "yyyyyyyyyyyyyyyy",
      "yyyyyyyyyyyyyyyy",
      "yyyyyyyyyyyyyyyy",
      "yyyyyyyyyyyyyyyy",
      "yyyyyyyyyyyyyyyy"
    ],
    [
      "yyyyyyyyyyyyyyyy",
      "~~~~~~~~~~~~~~~y",
      "~~~~~~~~~~~~~~~y",
      "~~~~~~~~~~~~~~~y",
      "~~~~~~~~~~~~~~~y",
      "eeeeeeefeee~~~~e",
      "~~~~~~~g~~~~~~~y",
      "eeeeeeefeee~~~~e",
      "~~~~~~~g~~~~~~~y",
      "eeeeeeefeee~~~~e",
      "~~~~~~~~~~~~~~~y",
      "~~~~~~~~~~~~~~~y",
      "~~~~~~~~~~~~~~~y",
      "~~~~~~~~~~~~~~~y",
      "~~~~~~~~~~~~~~~y",
      "yyyyyyyyyyyyyyyy"
    ],
    [
      "yyyyyyyyyyyyyyyy",
      "~~~~~~~~~~~~~~~y",
      "~~~~~~~~~~~~~~~y",
      "~~~~~~~~~~~~~~~y",
      "~~~~~~~~~~~~~~~y",
      "~~~~~~~~~~~~~~~y",
      "~~~~~~~~~~~~~~~y",
      "~~~~~~~~~~~~~~~y",
      "~~~~~~~~~~~~~~~y",
      "~~~~~~~~~~~~~~~y",
      "~~~~~~~~~~~~~~~y",
      "~~~~~~~~~~~~~~~y",
      "~~~~~~~~~~~~~~~y",
      "~~~~~~~~~~~~~~~y",
      "~~~~~~~~~~~~~~~y",
      "yyyyyyyyyyyyyyyy"
    ],
    [
      "yyyyyyyyyyyyyyyy",
      "~~~~~~~~~~~~~~~y",
      "~~~~~~~~~~~~~~~y",
      "~~~~~~~~~~~~~~~y",
      "~~~~~~~~~~~~~~~y",
      "~~~~~~~~~~~~~~~y",
      "~~~~~~~~~~~~~~~y",
      "~~~~~~~~~~~~~~~y",
      "~~~~~~~~~~~~~~~y",
      "~~~~~~~~~~~~~~~y",
      "~~~~~~~~~~~~~~~y",
      "~~~~~~~~~~~~~~~y",
      "~~~~~~~~~~~~~~~y",
      "~~~~~~~~~~~~~~~y",
      "~~~~~~~~~~~~~~~y",
      "yyyyyyyyyyyyyyyy"
    ],
    [
      "yyyyyyyyyyyyyyyy",
      "~~~~~~~~~~~~~~~y",
      "~~~~~~~~~~~~~~~y",
      "~~~~~~~~~~~~~~~y",
      "~~~~~~~~~~~~~~~y",
      "~~~~~~~~~~~~~~~y",
      "~~~~~~~~~~~~~~~y",
      "~~~~~~~~~~~~~~~y",
      "~~~~~~~~~~~~~~~y",
      "~~~~~~~~~~~~~~~y",
      "~~~~~~~~~~~~~~~y",
      "~~~~~~~~~~~~~~~y",
      "~~~~~~~~~~~~~~~y",
      "~~~~~~~~~~~~~~~y",
      "~~~~~~~~~~~~~~~y",
      "yyyyyyyyyyyyyyyy"
    ],
    [
      "yyyyyyyyyyyyyyyy",
      "~~~~~~~~~~~~~~~y",
      "~~~~~~~~~~~~~~~y",
      "~~~~~~~~~~~~~~~y",
      "~~~~~~~~~~~~~~~y",
      "~~~~~~~~~~~~~~~y",
      "~~~~~~~~~~~~~~~y",
      "~~~~~~~~~~~~~~~y",
      "~~~~~~~~~~~~~~~y",
      "~~~~~~~~~~~~~~~y",
      "~~~~~~~~~~~~~~~y",
      "~~~~~~~~~~~~~~~y",
      "~~~~~~~~~~~~~~~y",
      "~~~~~~~~~~~~~~~y",
      "~~~~~~~~~~~~~~~y",
      "yyyyyyyyyyyyyyyy"
    ],
    [
      "yyyyyyyyyyyyyyyy",
      "~~~~~~~~~~~~~~~y",
      "~~~~~~~~~~~~~~~y",
      "~~~~~~~~~~~~~~~y",
      "~~~~~~~~~~~~~~~y",
      "~~~~~~~~~~~~~~~y",
      "~~~~~~~~~~~~~~~y",
      "~~~~~~~~~~~~~~~y",
      "~~~~~~~~~~~~~~~y",
      "~~~~~~~~~~~~~~~y",
      "~~~~~~~~~~~~~~~y",
      "~~~~~~~~~~~~~~~y",
      "~~~~~~~~~~~~~~~y",
      "~~~~~~~~~~~~~~~y",
      "~~~~~~~~~~~~~~~y",
      "yyyyyyyyyyyyyyyy"
    ],
    [
      "yyyyyyyyyyyyyyyy",
      "~~~~~~~~~~~~~~~y",
      "~~~~~~~~~~~~~~~y",
      "~~~~~~~~~~~~~~~y",
      "~~~~~~~~~~~~~~~y",
      "~~~~~~~~~~~~~~~y",
      "~~~~~~~~~~~~~~~y",
      "~~~~~~~~~~~~~~~y",
      "~~~~~~~~~~~~~~~y",
      "~~~~~~~~~~~~~~~y",
      "~~~~~~~~~~~~~~~y",
      "~~~~~~~~~~~~~~~y",
      "~~~~~~~~~~~~~~~y",
      "~~~~~~~~~~~~~~~y",
      "~~~~~~~~~~~~~~~y",
      "yyyyyyyyyyyyyyyy"
    ],
    [
      "yyyyyyyyyyyyyyyy",
      "yyyyyyyyyyyyyyyy",
      "yyyyyyyyyyyyyyyy",
      "yyyyyyyyyyyyyyyy",
      "yyyyyyyyyyyyyyyy",
      "yyyyyyyyyyyyyyyy",
      "yyyyyyyyyyyyyyyy",
      "yyyyyyyyyyyyyyyy",
      "yyyyyyyyyyyyyyyy",
      "yyyyyyyyyyyyyyyy",
      "yyyyyyyyyyyyyyyy",
      "yyyyyyyyyyyyyyyy",
      "yyyyyyyyyyyyyyyy",
      "yyyyyyyyyyyyyyyy",
      "yyyyyyyyyyyyyyyy",
      "yyyyyyyyyyyyyyyy"
    ]
  ]
}