{
  "xsize": 16,
  "zsize": 16,
  "refpalette": "rails",
  "slices": [
    [
      "yyyyyyyyyyyy    ",
      "yyyyyyyyyyyy    ",
      "yyyyyyyyyyyy    ",
      "yyyyyyyyyyyy    ",
      "yyyyyyyyyyyy    ",
      "yyyyyyyyyyyy    ",
      "yyyyyyyyyyyy    ",
      "yyyyyyyyyyyy    ",
      "yyyyyyyyyyyy    ",
      "yyyyyyyyyyyy    ",
      "yyyyyyyyyyyy    ",
      "yyyyyyyyyyyy    ",
      "yyyyyyyyyyyy    ",
      "yyyyyyyyyyyy    ",
      "yyyyyyyyyyyy    ",
      "yyyyyyyyyyyy    "
    ],
    [
      "yyyyyy~~~k~y    ",
      "yyyyyy~~~k~y    ",
      "yyyyyy~~~k~y    ",
      "yyyyyy~~k~~y    ",
      "~~~~~~~gm~~y    ",
      "eeeeeeefr~~y    ",
      "~~~~~~~~~~~y    ",
      "~~~~~~~~~~~y    ",
      "~~~~~~~~~~~y    ",
      "eeeeeeefs~~y    ",
      "~~~~~~~gm~~y    ",
      "yyyyyy~~k~~y    ",
      "yyyyyy~~~k~y    ",
      "yyyyyy~~~k~y    ",
      "yyyyyy~~~k~y    ",
      "yyyyyy~~~k~y    "
    ],
    [
      "yyyyyy~~~~~y    ",
      "yyyyyy~~~~~y    ",
      "yyyyyy~~~~~y    ",
      "yyyyyy~~~~~y    ",
      "~~~~~~~~~~~y    ",
      "~~~~~~~~~~~y    ",
      "~~~~~~~~~~~y    ",
      "~~~~~~~~~~~y    ",
      "~~~~~~~~~~~y    ",
      "~~~~~~~~~~~y    ",
      "~~~~~~~~~~~y    ",
      "yyyyyy~~~~~y    ",
      "yyyyyy~~~~~y    ",
      "yyyyyy~~~~~y    ",
      "yyyyyy~~~~~y    ",
      "yyyyyy~~~~~y    "
    ],
    [
      "yyyyyy~~~~~y    ",
      "yyyyyy~~~~~y    ",
      "yyyyyy~~~~~y    ",
      "yyyyyy~~~~~y    ",
      "~~~~~~~~~~~y    ",
      "~~~~~~~~~~~y    ",
      "~~~~~~~~~~~y    ",
      "~~~~~~~~~~~y    ",
      "~~~~~~~~~~~y    ",
      "~~~~~~~~~~~y    ",
      "~~~~~~~~~~~y    ",
      "yyyyyy~~~~~y    ",
      "yyyyyy~~~~~y    ",
      "yyyyyy~~~~~y    ",
      "yyyyyy~~~~~y    ",
      "yyyyyy~~~~~y    "
    ],
    [
      "yyyyyy~~~~~y    ",
      "yyyyyy~~~~~y    ",
      "yyyyyy~~~~~y    ",
      "yyyyyy~~~~~y    ",
      "~~~~~~~~~~~y    ",
      "~~~~~~~~~~~y    ",
      "~~~~~~~~~~~y    ",
      "~~~~~~~~~~~y    ",
      "~~~~~~~~~~~y    ",
      "~~~~~~~~~~~y    ",
      "~~~~~~~~~~~y    ",
      "yyyyyy~~~~~y    ",
      "yyyyyy~~~~~y    ",
      "yyyyyy~~~~~y    ",
      "yyyyyy~~~~~y    ",
      "yyyyyy~~~~~y    "
    ],
    [
      "yyyyyy~~~~~y    ",
      "yyyyyy~~~~~y    ",
      "yyyyyy~~~~~y    ",
      "yyyyyy~~~~~y    ",
      "~~~~~~~~~~~y    ",
      "~~~~~~~~~~~y    ",
      "~~~~~~~~~~~y    ",
      "~~~~~~~~~~~y    ",
      "~~~~~~~~~~~y    ",
      "~~~~~~~~~~~y    ",
      "~~~~~~~~~~~y    ",
      "yyyyyy~~~~~y    ",
      "yyyyyy~~~~~y    ",
      "yyyyyy~~~~~y    ",
      "yyyyyy~~~~~y    ",
      "yyyyyy~~~~~y    "
    ],
    [
      "yyyyyy~~~~~y    ",
      "yyyyyy~~~~~y    ",
      "yyyyyy~~~~~y    ",
      "yyyyyy~~~~~y    ",
      "~~~~~~~~~~~y    ",
      "~~~~~~~~~~~y    ",
      "~~~~~~~~~~~y    ",
      "~~~~~~~~~~~y    ",
      "~~~~~~~~~~~y    ",
      "~~~~~~~~~~~y    ",
      "~~~~~~~~~~~y    ",
      "yyyyyy~~~~~y    ",
      "yyyyyy~~~~~y    ",
      "yyyyyy~~~~~y    ",
      "yyyyyy~~~~~y    ",
      "yyyyyy~~~~~y    "
    ],
    [
      "yyyyyy~~~~~y    ",
      "yyyyyy~~~~~y    ",
      "yyyyyy~~~~~y    ",
      "yyyyyy~~~~~y    ",
      "~~~~~~~~~~~y    ",
      "~~~~~~~~~~~y    ",
      "~~~~~~~~~~~y    ",
      "~~~~~~~~~~~y    ",
      "~~~~~~~~~~~y    ",
      "~~~~~~~~~~~y    ",
      "~~~~~~~~~~~y    ",
      "yyyyyy~~~~~y    ",
      "yyyyyy~~~~~y    ",
      "yyyyyy~~~~~y    ",
      "yyyyyy~~~~~y    ",
      "yyyyyy~~~~~y    "
    ],
    [
      "yyyyyyyyyyyy    ",
      "yyyyyyyyyyyy    ",
      "yyyyyyyyyyyy    ",
      "yyyyyyyyyyyy    ",
      "yyyyyyyyyyyy    ",
      "yyyyyyyyyyyy    ",
      "yyyyyyyyyyyy    ",
      "yyyyyyyyyyyy    ",
      "yyyyyyyyyyyy    ",
      "yyyyyyyyyyyy    ",
      "yyyyyyyyyyyy    ",
      "yyyyyyyyyyyy    ",
      "yyyyyyyyyyyy    ",
      "yyyyyyyyyyyy    ",
      "yyyyyyyyyyyy    ",
      "yyyyyyyyyyyy    "
    ]
  ]
}