{
  "xsize": 16,
  "zsize": 16,
  "refpalette": "rails",
  "slices": [
    [
      "yyyyyyyyyyyyyyyy",
      "yyyyyyyyyyyyyyyy",
      "yyyyyyyyyyyyyyyy",
      "yyyyyyyyyyyyyyyy",
      "yyyyyyyyyyyyyyyy",
      "yyyyyyyyyyyyyyyy",
      "yyyyyyyyyyyyyyyy",
      "yyyyyyyyyyyyyyyy",
      "yyyyyyyyyyyyyyyy",
      "yyyyyyyyyyyyyyyy",
      "yyyyyyyyyyyyyyyy",
      "yyyyyyyyyyyyyyyy",
      "yyyyyyyyyyyyyyyy",
      "yyyyyyyyyyyyyyyy",
      "yyyyyyyyyyyyyyyy",
      "yyyyyyyyyyyyyyyy"
    ],
    [
      "yyyyyy~~k~~yyyyy",
      "yyyyyy~gmg~yyyyy",
      "yyyyyy~~k~~yyyyy",
      "yyyyyy~~k~~yyyyy",
      "~~~~~~~~k~~~~~~~",
      "~~~~~~~~nfeeeeee",
      "~g~~~~~~~g~~~~~~",
      "efeeeeeeefeeeeee",
      "~g~~~~~~~g~~~~~~",
      "~~~~~~~~qfeeeeee",
      "~~~~~~~~k~~~~~~~",
      "yyyyyy~~k~~yyyyy",
      "yyyyyy~~k~~yyyyy",
      "yyyyyy~~k~~yyyyy",
      "yyyyyy~gmg~yyyyy",
      "yyyyyy~~k~~yyyyy"
    ],
    [
      "yyyyyy~~~~~yyyyy",
      "yyyyyy~~~~~yyyyy",
      "yyyyyy~~~~~yyyyy",
      "yyyyyy~~~~~yyyyy",
      "~~~~~~~~~~~~~~~~",
      "~~~~~~~~~~~~~~~~",
      "~~~~~~~~~~~~~~~~",
      "~~~~~~~~~~~~~~~~",
      "~~~~~~~~~~~~~~~~",
      "~~~~~~~~~~~~~~~~",
      "~~~~~~~~~~~~~~~~",
      "yyyyyy~~~~~yyyyy",
      "yyyyyy~~~~~yyyyy",
      "yyyyyy~~~~~yyyyy",
      "yyyyyy~~~~~yyyyy",
      "yyyyyy~~~~~yyyyy"
    ],
    [
      "yyyyyy~~~~~yyyyy",
      "yyyyyy~~~~~yyyyy",
      "yyyyyy~~~~~yyyyy",
      "yyyyyy~~~~~yyyyy",
      "~~~~~~~~~~~~~~~~",
      "~~~~~~~~~~~~~~~~",
      "~~~~~~~~~~~~~~~~",
      "~~~~~~~~~~~~~~~~",
      "~~~~~~~~~~~~~~~~",
      "~~~~~~~~~~~~~~~~",
      "~~~~~~~~~~~~~~~~",
      "yyyyyy~~~~~yyyyy",
      "yyyyyy~~~~~yyyyy",
      "yyyyyy~~~~~yyyyy",
      "yyyyyy~~~~~yyyyy",
      "yyyyyy~~~~~yyyyy"
    ],
    [
      "yyyyyy~~~~~yyyyy",
      "yyyyyy~~~~~yyyyy",
      "yyyyyy~~~~~yyyyy",
      "yyyyyy~~~~~yyyyy",
      "~~~~~~~~~~~~~~~~",
      "~~~~~~~~~~~~~~~~",
      "~~~~~~~~~~~~~~~~",
      "~~~~~~~~~~~~~~~~",
      "~~~~~~~~~~~~~~~~",
      "~~~~~~~~~~~~~~~~",
      "~~~~~~~~~~~~~~~~",
      "yyyyyy~~~~~yyyyy",
      "yyyyyy~~~~~yyyyy",
      "yyyyyy~~~~~yyyyy",
      "yyyyyy~~~~~yyyyy",
      "yyyyyy~~~~~yyyyy"
    ],
    [
      "yyyyyy~~~~~yyyyy",
      "yyyyyy~~~~~yyyyy",
      "yyyyyy~~~~~yyyyy",
      "yyyyyy~~~~~yyyyy",
      "~~~~~~~~~~~~~~~~",
      "~~~~~~~~~~~~~~~~",
      "~~~~~~~~~~~~~~~~",
      "~~~~~~~~~~~~~~~~",
      "~~~~~~~~~~~~~~~~",
      "~~~~~~~~~~~~~~~~",
      "~~~~~~~~~~~~~~~~",
      "yyyyyy~~~~~yyyyy",
      "yyyyyy~~~~~yyyyy",
      "yyyyyy~~~~~yyyyy",
      "yyyyyy~~~~~yyyyy",
      "yyyyyy~~~~~yyyyy"
    ],
    [
      "yyyyyy~~~~~yyyyy",
      "yyyyyy~~~~~yyyyy",
      "yyyyyy~~~~~yyyyy",
      "yyyyyy~~~~~yyyyy",
      "~~~~~~~~~~~~~~~~",
      "~~~~~~~~~~~~~~~~",
      "~~~~~~~~~~~~~~~~",
      "~~~~~~~~~~~~~~~~",
      "~~~~~~~~~~~~~~~~",
      "~~~~~~~~~~~~~~~~",
      "~~~~~~~~~~~~~~~~",
      "yyyyyy~~~~~yyyyy",
      "yyyyyy~~~~~yyyyy",
      "yyyyyy~~~~~yyyyy",
      "yyyyyy~~~~~yyyyy",
      "yyyyyy~~~~~yyyyy"
    ],
    [
      "yyyyyy~~~~~yyyyy",
      "yyyyyy~~~~~yyyyy",
      "yyyyyy~~~~~yyyyy",
      "yyyyyy~~~~~yyyyy",
      "~~~~~~~~~~~~~~~~",
      "~~~~~~~~~~~~~~~~",
      "~~~~~~~~~~~~~~~~",
      "~~~~~~~~~~~~~~~~",
      "~~~~~~~~~~~~~~~~",
      "~~~~~~~~~~~~~~~~",
      "~~~~~~~~~~~~~~~~",
      "yyyyyy~~~~~yyyyy",
      "yyyyyy~~~~~yyyyy",
      "yyyyyy~~~~~yyyyy",
      "yyyyyy~~~~~yyyyy",
      "yyyyyy~~~~~yyyyy"
    ],
    [
      "yyyyyyyyyyyyyyyy",
      "yyyyyyyyyyyyyyyy",
      "yyyyyyyyyyyyyyyy",
      "yyyyyyyyyyyyyyyy",
      "yyyyyyyyyyyyyyyy",
      "yyyyyyyyyyyyyyyy",
      "yyyyyyyyyyyyyyyy",
      "yyyyyyyyyyyyyyyy",
      "yyyyyyyyyyyyyyyy",
      "yyyyyyyyyyyyyyyy",
      "yyyyyyyyyyyyyyyy",
      "yyyyyyyyyyyyyyyy",
      "yyyyyyyyyyyyyyyy",
      "yyyyyyyyyyyyyyyy",
      "yyyyyyyyyyyyyyyy",
      "yyyyyyyyyyyyyyyy"
    ]
  ]
}