{
  "xsize": 16,
  "zsize": 16,
  "refpalette": "rails",
  "palette": {
    "palette": [
      {
        "char": "J",
        "block": "minecraft:rail[shape=east_west,waterlogged=false]"
      },
      {
        "char": "M",
        "block": "minecraft:rail[shape=ascending_east,waterlogged=false]"
      },
      {
        "char": "N",
        "block": "minecraft:lantern[hanging=true,waterlogged=false]"
      },
      {
        "char": "O",
        "block": "minecraft:mossy_stone_brick_slab[type=top,waterlogged=false]"
      }
    ]
  },
  "slices": [
    [
      "y               ",
      "y               ",
      "y               ",
      "yyyyyy~~~~~~~~~~",
      "yyyyyy~~~~~~~~~~",
      "yyyyyy~~~~~~~~~~",
      "yyyyyy~~~~~~~~~~",
      "yyyyyy~~~~~~~~~~",
      "yyyyyy~~~~~~~~~~",
      "yyyyyy~~~~~~~~~~",
      "yyyyyy~~~~~~~~~~",
      "yyyyyy~~~~~~~~~~",
      "y               ",
      "y               ",
      "y               ",
      "y               "
    ],
    [
      "y               ",
      "y               ",
      "y               ",
      "yyyyyyy~~~~~~~~~",
      "yyyyyyy~~~~~~~~~",
      "JJJJJMy~~~~~~~~~",
      "yyyyyyy~~~~~~~~~",
      "JJJJJMy~~~~~~~~~",
      "yyyyyyy~~~~~~~~~",
      "JJJJJMy~~~~~~~~~",
      "yyyyyyy~~~~~~~~~",
      "yyyyyyy~~~~~~~~~",
      "y               ",
      "y               ",
      "y               ",
      "y               "
    ],
    [
      "y~~~~~~~~~~~~~~~",
      "y~~~~~~~~~~~~~~~",
      "y~~~~~~~~~~~~~~~",
      "yyyyyyyy~~~~~~~~",
      "yyyyyyyy~~~~~~~~",
      "~~~~~~My~~~~~~~~",
      "~~~~~~~y~~~~~~~~",
      "~~~~~~My~~~~~~~~",
      "~~~~~~~y~~~~~~~~",
      "~~~~~~My~~~~~~~~",
      "yyyyyyyy~~~~~~~~",
      "yyyyyyyy~~~~~~~~",
      "y~~~~~~~~~~~~~~~",
      "y~~~~~~~~~~~~~~~",
      "y~~~~~~~~~~~~~~~",
      "y~~~~~~~~~~~~~~~"
    ],
    [
      "y               ",
      "y               ",
      "y               ",
      "yyyyyyyyy~~~~~~~",
      "~~~~~~~yy~~~~~~~",
      "~~~~~~~My~~~~~~~",
      "~~~~~~~~y~~~~~~~",
      "~~~~~~~My~~~~~~~",
      "~~~~~~~~y~~~~~~~",
      "~~~~~~~My~~~~~~~",
      "~~~~~~~yy~~~~~~~",
      "yyyyyyyyy~~~~~~~",
      "y               ",
      "y               ",
      "y               ",
      "y               "
    ],
    [
      "y               ",
      "y               ",
      "y               ",
      "yyyyyyyyyy~~~~~~",
      "~~~~~~~~yy~~~~~~",
      "~~~~~~~~My~~~~~~",
      "~~~~~~~~~y~~~~~~",
      "~~~~~~~~My~~~~~~",
      "~~~~~~~~~y~~~~~~",
      "~~~~~~~~My~~~~~~",
      "~~~~~~~~yy~~~~~~",
      "yyyyyyyyyy~~~~~~",
      "y               ",
      "y               ",
      "y               ",
      "y               "
    ],
    [
      "y               ",
      "y               ",
      "y               ",
      "yyyyyyyyyyy~~~~~",
      "~~~~~~~~~yy~~~~~",
      "~~~~~~~~~My~~~~~",
      "~~~~~~~~~~y~~~~~",
      "~~~~~~~~~My~~~~~",
      "~~~~~~~~~~y~~~~~",
      "~~~~~~~~~My~~~~~",
      "~~~~~~~~~yy~~~~~",
      "yyyyyyyyyyy~~~~~",
      "y               ",
      "y               ",
      "y               ",
      "y               "
    ],
    [
      "y               ",
      "y               ",
      "y               ",
      "yyyyyyyyyyyy~~~~",
      "~~~~~~~~~~yy~~~~",
      "~~~~~~~~~~My~~~~",
      "~~~~~~~~~~~y~~~~",
      "~~~~~~~~~~My~~~~",
      "~~~~~~~~~~~y~~~~",
      "~~~~~~~~~~My~~~~",
      "~~~~~~~~~~yy~~~~",
      "yyyyyyyyyyyy~~~~",
      "y               ",
      "y               ",
      "y               ",
      "y               "
    ],
    [
      "y               ",
      "y               ",
      "y               ",
      "yyyyyyyyyyyyy~~~",
      "~~~~~~~~~~~yy~~~",
      "~~~~~~~~~~~My~~~",
      "~~~~~~~~~~~~y~~~",
      "~~~~~~~~~~~My~~~",
      "~~~~~~~~~~~~y~~~",
      "~~~~~~~~~~~My~~~",
      "~~~~~~~~~~~yy~~~",
      "yyyyyyyyyyyyy~~~",
      "y               ",
      "y               ",
      "y               ",
      "y               "
    ],
    [
      "y               ",
      "y               ",
      "y               ",
      "yyyyyyyyyyyy~y~~",
      "y~~~~~~~~~~~yy~~",
      "y~~~~~~~~~~~My~~",
      "y~~~~~~~~~~~~y~~",
      "y~~~~~~~~~~~My~~",
      "y~~~~~~~~~~~~y~~",
      "y~~~~~~~~~~~My~~",
      "y~~~~~~~~~~~yy~~",
      "yyyyyyyyyyyyyy~~",
      "y               ",
      "y               ",
      "y               ",
      "y               "
    ],
    [
      "y               ",
      "y               ",
      "y               ",
      "yyyyyyyyyyyyyyy~",
      "y~~~~~~~~~~~~yy~",
      "y~~~~~~~~~~~~My~",
      "y~~~~~~~~~~~~~y~",
      "y~~~~~~~~~~~~My~",
      "y~~~~~~~~~~~~~y~",
      "y~~~~~~~~~~~~My~",
      "y~~~~~~~~~~~~yy~",
      "yyyyyyyyyyyyyyy~",
      "y               ",
      "y               ",
      "y               ",
      "y               "
    ],
    [
      "y               ",
      "y               ",
      "y               ",
      "yyyyyyyyyyyyyyyy",
      "y~~~~~~~~~~~~~yy",
      "y~~~~~~~~~~~~~My",
      "y~~~~~~~~~~~~~~y",
      "y~~~~~~~~~~~~~My",
      "y~~~~~~~~~~~~~~y",
      "y~~~~~~~~~~~~~My",
      "y~~~~~~~~~~~~~yy",
      "yyyyyyyyyyyyyyyy",
      "y               ",
      "y               ",
      "y               ",
      "y               "
    ],
    [
      "y               ",
      "y               ",
      "y               ",
      "yyyyyyyyyyyyyyyy",
      "y~~~~~~~~~~~~~~y",
      "y~~~~~~~~~~~~~~M",
      "y~~~~~~~~~~~~~~~",
      "y~~~~~~~~~~~~~~M",
      "y~~~~~~~~~~~~~~~",
      "y~~~~~~~~~~~~~~M",
      "y~~~~~~~~~~~~~~y",
      "yyyyyyyyyyyyyyyy",
      "y               ",
      "y               ",
      "y               ",
      "y               "
    ],
    [
      "y               ",
      "y               ",
      "y               ",
      "yyyyyyyyyyyyyyyy",
      "y~~~~~~~~~~~~~~~",
      "y~~~~~~~~~~~~~~~",
      "y~~~~~~~~~~~~~~~",
      "y~~~~~~~~~~~~~~~",
      "y~~~~~~~~~~~~~~~",
      "y~~~~~~~~~~~~~~~",
      "y~~~~~~~~~~~~~~~",
      "yyyyyyyyyyyyyyyy",
      "y               ",
      "y               ",
      "y               ",
      "y               "
    ],
    [
      "y               ",
      "y               ",
      "y               ",
      "yyyyyyyyyyyyyyyy",
      "y~~~~~~~~~~~~~~~",
      "y~~~~~~~~~~~~~~~",
      "y~~~~~~~~~~~~~~~",
      "y~~~~~~~~~~~~~~~",
      "y~~~~~~~~~~~~~~~",
      "y~~~~~~~~~~~~~~~",
      "y~~~~~~~~~~~~~~~",
      "yyyyyyyyyyyyyyyy",
      "y               ",
      "y               ",
      "y               ",
      "y               "
    ],
    [
      "y               ",
      "y               ",
      "y               ",
      "yyyyyyyyyyyyyyyy",
      "y~~~~~~~~~~~~~~~",
      "y~~~~~~~~~~~~~~~",
      "y~~~~~~~~~~~~~~~",
      "y~~~~~~~~~~~~~~~",
      "y~~~~~~~~~~~~~~~",
      "y~~~~~~~~~~~~~~~",
      "y~~~~~~~~~~~~~~~",
      "yyyyyyyyyyyyyyyy",
      "y               ",
      "y               ",
      "y               ",
      "y               "
    ],
    [
      "y               ",
      "y               ",
      "y               ",
      "yyyyyyyyyyyyyyyy",
      "y~~~~~~~~~~~~~~~",
      "y~~~~~~~~~~~~~~~",
      "y~~~~~~~~~~~~~~~",
      "y~~~~~~~~~~~~~~~",
      "y~~~~~~~~~~~~~~~",
      "y~~~~~~~~~~~~~~~",
      "y~~~~~~~~~~~~~~~",
      "yyyyyyyyyyyyyyyy",
      "y               ",
      "y               ",
      "y               ",
      "y               "
    ],
    [
      "y               ",
      "y               ",
      "y               ",
      "yyyyyyyyyyyyyyyy",
      "y~~~~~~~~~~~~~~~",
      "y~~~~~~~~~~~~~~~",
      "y~~~~~~~~~~~~~~~",
      "y~~~~N~~~~~~~~~~",
      "y~~~~~~~~~~~~~~~",
      "y~~~~~~~~~~~~~~~",
      "y~~~~~~~~~~~~~~~",
      "yyyyyyyyyyyyyyyy",
      "y               ",
      "y               ",
      "y               ",
      "y               "
    ],
    [
      "y               ",
      "y               ",
      "y               ",
      "yyyyyyyyyyyyyyyy",
      "yyyyyyyyyyyyyyO~",
      "yyyyyyyyyyy~~~~~",
      "yyyyyyyyyyy~~~~~",
      "yyyyyyyyyyy~~~~~",
      "yyyyyyyyyyy~~~~~",
      "yyyyyyyyyyy~~~~~",
      "yyyyyyyyyyyyyyO~",
      "yyyyyyyyyyyyyyyy",
      "y               ",
      "y               ",
      "y               ",
      "y               "
    ]
  ]
}