{
  "xsize": 16,
  "zsize": 16,
  "refpalette": "rails",
  "palette": {
    "palette": [
      {
        "char": "o",
        "block": "minecraft:rail[shape=east_west,waterlogged=false]"
      },
      {
        "char": "I",
        "block": "minecraft:rail[shape=ascending_east,waterlogged=false]"
      },
      {
        "char": "O",
        "block": "minecraft:mossy_stone_brick_slab[type=bottom]"
      }
    ]
  },
  "slices": [
    [
      "                ",
      "                ",
      "                ",
      "yyyyyyyyyyyyyyyy",
      "OOOOOOyyyy      ",
      "oooooooooIy     ",
      "OOOOOOyyyy      ",
      "oooooooooIyy    ",
      "OOOOOOyyyy      ",
      "oooooooooIyy    ",
      "OOOOOOyyyy      ",
      "yyyyyyyyyyyyyyyy",
      "                ",
      "                ",
      "                ",
      "                "
    ],
    [
      "                ",
      "                ",
      "                ",
      "yyyyyyyyyyyyyyyy",
      "~~~~~~~~~yyy    ",
      "~~~~~~~~~~Iyy   ",
      "~~~~~~~~~yy     ",
      "~~~~~~~~~~Iy    ",
      "~~~~~~~~~yy     ",
      "~~~~~~~~~~Iyy   ",
      "~~~~~~~~~yy     ",
      "yyyyyyyyyyyyyyyy",
      "                ",
      "                ",
      "                ",
      "                "
    ],
    [
      "                ",
      "                ",
      "                ",
      "yyyyyyyyyyyyyyyy",
      "~~~~~~~~~~yy    ",
      "~~~~~~~~~~~Iy   ",
      "~~~~~~~~~~yy    ",
      "~~~~~~~~~~~Iyy  ",
      "~~~~~~~~~~yy    ",
      "~~~~~~~~~~~Iyy  ",
      "~~~~~~~~~~yy    ",
      "yyyyyyyyyyyyyyyy",
      "                ",
      "                ",
      "                ",
      "                "
    ],
    [
      "                ",
      "                ",
      "                ",
      "yyyyyyyyyyyyyyyy",
      "~~~~~~~~~~~yy   ",
      "~~~~~~~~~~~~Iy  ",
      "~~~~~~~~~~~yy   ",
      "~~~~~~~~~~~~Iyy ",
      "~~~~~~~~~~~yy   ",
      "~~~~~~~~~~~~Iyy ",
      "~~~~~~~~~~~yy   ",
      "yyyyyyyyyyyyyyyy",
      "                ",
      "                ",
      "                ",
      "                "
    ],
    [
      "                ",
      "                ",
      "                ",
      "yyyyyyyyyyyyyyyy",
      "~~~~~~~~~~~~yy  ",
      "~~~~~~~~~~~~~Iy ",
      "~~~~~~~~~~~~yy  ",
      "~~~~~~~~~~~~~Iyy",
      "~~~~~~~~~~~~yy  ",
      "~~~~~~~~~~~~~Iyy",
      "~~~~~~~~~~~~yy  ",
      "yyyyyyyyyyyyyyyy",
      "                ",
      "                ",
      "                ",
      "                "
    ],
    [
      "                ",
      "                ",
      "                ",
      "yyyyyyyyyyyyyyyy",
      "~~~~~~~~~~~~~yy~",
      "~~~~~~~~~~~~~~Iy",
      "~~~~~~~~~~~~~yy~",
      "~~~~~~~~~~~~~~Iy",
      "~~~~~~~~~~~~~yy~",
      "~~~~~~~~~~~~~~Iy",
      "~~~~~~~~~~~~~yy~",
      "yyyyyyyyyyyyyy~~",
      "                ",
      "                ",
      "                ",
      "                "
    ],
    [
      "                ",
      "                ",
      "                ",
      "yyyyyyyyyyyyyyyy",
      "~~~~~~~~~~~~~~yy",
      "~~~~~~~~~~~~~~~I",
      "~~~~~~~~~~~~~~yy",
      "~~~~~~~~~~~~~~~I",
      "~~~~~~~~~~~~~~yy",
      "~~~~~~~~~~~~~~~I",
      "~~~~~~~~~~~~~~yy",
      "yyyyyyyyyyyyyyyy",
      "                ",
      "                ",
      "                ",
      "                "
    ],
    [
      "                ",
      "                ",
      "                ",
      "yyyyyyyyyyyyyyyy",
      "yy~~~~~~~~~~~~~y",
      "yy~~~~~~~~~~~~~~",
      "yy~~~~~~~~~~~~~y",
      "yy~~~~~~~~~~~~~~",
      "yy~~~~~~~~~~~~~y",
      "yy~~~~~~~~~~~~~~",
      "yy~~~~~~~~~~~~~y",
      "yyyyyyyyyyyyyyyy",
      "                ",
      "                ",
      "                ",
      "                "
    ],
    [
      "                ",
      "                ",
      "                ",
      " y::::yyyyyyyyyy",
      " :~~~~~~~~~~~~~~",
      " :~~~~~~~~~~~~~~",
      " :~~~~~~~~~~~~~~",
      " :~~~~~~~~~~~~~~",
      " :~~~~~~~~~~~~~~",
      " :~~~~~~~~~~~~~~",
      " :~~~~~~~~~~~~~~",
      " y::::yyyyyyyyyy",
      "                ",
      "                ",
      "                ",
      "                "
    ],
    [
      "                ",
      "                ",
      "                ",
      " y::::y         ",
      " :~~~~~~~~~~~~~~",
      " :~~~~~~~~~~~~~~",
      " :~~~~~~~~~~~~~~",
      " :~~~~~~~~~~~~~~",
      " :~~~~~~~~~~~~~~",
      " :~~~~~~~~~~~~~~",
      " :~~~~~~~~~~~~~~",
      " y::::y         ",
      "                ",
      "                ",
      "                ",
      "                "
    ],
    [
      "                ",
      "                ",
      "                ",
      " y::::y         ",
      " :~~~~~~~~~~~~~~",
      " :~~~~~~~~~~~~~~",
      " :~~~~~~~~~~~~~~",
      " :~~~~~~~~~~~~~~",
      " :~~~~~~~~~~~~~~",
      " :~~~~~~~~~~~~~~",
      " :~~~~~~~~~~~~~~",
      " y::::y         ",
      "                ",
      "                ",
      "                ",
      "                "
    ],
    [
      "                ",
      "                ",
      "                ",
      " y::::y         ",
      " :~~~~~~~~~~~~~~",
      " :~~~~~~~~~~~~~~",
      " :~~~~~~~~~~~~~~",
      " :~~~~~~~~~~~~~~",
      " :~~~~~~~~~~~~~~",
      " :~~~~~~~~~~~~~~",
      " :~~~~~~~~~~~~~~",
      " y::::y         ",
      "                ",
      "                ",
      "                ",
      "                "
    ],
    [
      "                ",
      "                ",
      "                ",
      " y::::y         ",
      " :~~~~~~~~~~~~~~",
      " :~~~~~~~~~~~~~~",
      " :~~~~~~~~~~~~~~",
      " :~~~~~~~~~~~~~~",
      " :~~~~~~~~~~~~~~",
      " :~~~~~~~~~~~~~~",
      " :~~~~~~~~~~~~~~",
      " y::::y         ",
      "                ",
      "                ",
      "                ",
      "                "
    ],
    [
      "                ",
      "                ",
      "                ",
      " y~~~~y         ",
      " ~~~~~~~~~~~~~~~",
      " ~~~~~~~~~~~~~~~",
      " ~~~~~~~~~~~~~~~",
      " ~~~~~~~~~~~~~~~",
      " ~~~~~~~~~~~~~~~",
      " ~~~~~~~~~~~~~~~",
      " ~~~~~~~~~~~~~~~",
      " y~~~~y         ",
      "                ",
      "                ",
      "                ",
      "                "
    ],
    [
      "                ",
      "                ",
      "                ",
      " ______         ",
      " _~~~~_~~~~~~~~~",
      " _~~~~_~~~~~~~~~",
      " _~~~~_~~~~~~~~~",
      " _~~~~_~~~~~~~~~",
      " _~~~~_~~~~~~~~~",
      " _~~~~_~~~~~~~~~",
      " _~~~~_~~~~~~~~~",
      " ______         ",
      "                ",
      "                ",
      "                ",
      "                "
    ]
  ]
}