{
  "xsize": 16,
  "zsize": 16,
  "refpalette": "lostcities:scattered",
  "slices": [
    [
      "                ",
      "                ",
      "                ",
      "                ",
      "                ",
      "                ",
      "      $  $      ",
      "       $$       ",
      "       $$       ",
      "      $  $#     ",
      "          #     ",
      "          #     ",
      "           #    ",
      "           #    ",
      "            #   ",
      "            #   "
    ],
    [
      "00&&vvvvv&vv&023",
      "&&&vvvv&&&&&&023",
      "&&vv&&00000&&02v",
      "&&&&&0233220&0vv",
      "0&&&0vvv3320&vvv",
      "200002vvvvvvvvvv",
      "200000vvvvvvvvvv",
      "00000&vvvvvvvvvv",
      "&&&&&&vvvvvvvvvv",
      "&&&&&vvvvvvvvvvv",
      "&&&&vvv&23v33vvv",
      "&&&&&v&023v332vv",
      "0&&&&&&0232v222v",
      "0&&&&&&0000v0023",
      "000&&&&&&&&&v022",
      "&&0&&&&&&vvvv&02"
    ],
    [
      "              ..",
      "#            .. ",
      "#      $$$   .  ",
      "       $$$  .   ",
      "       $$$  .   ",
      "           ..   ",
      "           .    ",
      "     $$    .    ",
      "     $$  # .    ",
      "        ###.    ",
      "        ###.    ",
      "         ##.#   ",
      "          #..   ",
      "          ##.#  ",
      "           #.#  ",
      "           ##.  "
    ],
    [
      "              ..",
      "             .. ",
      "             .  ",
      "        $   .   ",
      "            .   ",
      "           ..   ",
      "           .    ",
      "           .    ",
      "           .    ",
      "         # .    ",
      "        ###.    ",
      "         ##.    ",
      "          #..   ",
      "           #.   ",
      "           #.#  ",
      "           ##.# "
    ],
    [
      " .....        ..",
      " .....       .. ",
      " $$$$$       .  ",
      " .....  $   .   ",
      " .....      .   ",
      " .....     ..   ",
      " .....     .    ",
      " .....     .    ",
      " .....     .    ",
      " .....   # .    ",
      " .....  ###.    ",
      " .....  ###.    ",
      " .....   # ..   ",
      " .....      .   ",
      " .....      .   ",
      " .....      #.  "
    ],
    [
      ".     ..      ..",
      ". $$$ ..     .. ",
      "$$$$$$$$     .  ",
      ".     ..$   .   ",
      ".     ..    .   ",
      ".     ..   ..   ",
      ".     ..   .    ",
      ".     ..   .    ",
      ".     ..   .    ",
      ".     ..   .    ",
      ".     .. # .    ",
      ".     ..###.    ",
      ".     .. # ..   ",
      ".     ..    .   ",
      ".     ..    .   ",
      ".     ..     .  "
    ],
    [
      "       ..     ..",
      "$$$$$$$..    .. ",
      "$$$$$$$$$$   .  ",
      "       ..$  .   ",
      "       ..$  .   ",
      "       ..  ..   ",
      "       ..  .    ",
      "       ..  .    ",
      "       ..  .    ",
      "       ..  .    ",
      "       ..# .    ",
      "       ..##.    ",
      "       ..##..   ",
      "       ..#  .   ",
      "       ..   .   ",
      "       ..    .  "
    ],
    [
      "        .     ..",
      "$$$$$$$$.    .. ",
      "$$$$$$$$$    .  ",
      "        .   .   ",
      "        .   .   ",
      "        .  ..   ",
      "        .  .    ",
      "        .  .    ",
      "        .  .    ",
      "        .  .    ",
      "        .  .    ",
      "        .# .    ",
      "        .##..   ",
      "        .#  .   ",
      "        .   .   ",
      "        .    .  "
    ],
    [
      "  $$$    .    ..",
      "$$   $$$ .   .. ",
      "$$$$$$$$$$   .  ",
      "         .  .   ",
      "         .  .   ",
      "         . ..   ",
      "         . .    ",
      "         . .    ",
      "         . .    ",
      "         . .    ",
      "         . .    ",
      "         . .    ",
      "        #.#..   ",
      "        #.# .   ",
      "         .  .   ",
      "         .   .  "
    ],
    [
      " $$$$$   .    ..",
      "$     $$$.   .. ",
      "$$$$$$$$$$   .  ",
      "         .  .   ",
      "         .  .   ",
      "         . ..   ",
      "         . .    ",
      "         . .    ",
      "         . .    ",
      "         . .    ",
      "         . .    ",
      "         . .    ",
      "         . ..   ",
      "        #.# .   ",
      "         .  .   ",
      "         .   .  "
    ],
    [
      " $$$$$   .    ..",
      "$     $$$.   .. ",
      "$$$$$$$$$$   .  ",
      "         .  .   ",
      "         .  .   ",
      "         . ..   ",
      "         . .    ",
      "         . .    ",
      "         . .    ",
      "         . .    ",
      "         . .    ",
      "         . .    ",
      "         . ..   ",
      "        #.# .   ",
      "         .  .   ",
      "         .   .  "
    ],
    [
      " $$$$$   .    ..",
      "$     $$$.   .. ",
      "$$$$$$$$$$   .  ",
      "         .  .   ",
      "         .  .   ",
      "         . ..   ",
      "         . .    ",
      "         . .    ",
      "         . .    ",
      "         . .    ",
      "         . .    ",
      "         . .    ",
      "         . ..   ",
      "        #.# .   ",
      "        #.# .   ",
      "         .   .  "
    ],
    [
      "  $$$    .    ..",
      "$$   $$$ .   .. ",
      "$$$$$$$$$$   .  ",
      "         .  .   ",
      "         .  .   ",
      "         . ..   ",
      "         . .    ",
      "         . .    ",
      "         . .    ",
      "         . .    ",
      "         . .    ",
      "         . .    ",
      "         . ..   ",
      "         .  .   ",
      "        #.# .   ",
      "        #.#  .  "
    ],
    [
      "        .     ..",
      "$$$$$$$$.    .. ",
      "$$$$$$$$$    .  ",
      "        .   .   ",
      "        .   .   ",
      "        .  ..   ",
      "        .  .    ",
      "        .  .    ",
      "        .  .    ",
      "        .  .    ",
      "        .  .    ",
      "        .  .    ",
      "        .  ..   ",
      "        .   .   ",
      "        .#  .   ",
      "        .#   .  "
    ],
    [
      "       ..     ..",
      "$$$$$$$..    .. ",
      "$$$$$$$$$    .  ",
      "       ..   .   ",
      "       ..   .   ",
      "       ..  ..   ",
      "       ..  .    ",
      "       ..  .    ",
      "       ..  .    ",
      "       ..  .    ",
      "       ..  .    ",
      "       ..  .    ",
      "#      ..  ..   ",
      "##     ..   .   ",
      "       ..   .   ",
      "       ..    .  "
    ],
    [
      ".     ..      ..",
      ". $$$ ..     .. ",
      "$$$$$$$$     .  ",
      ".     ..    .   ",
      ".     ..    .   ",
      ".     ..   ..   ",
      ".     ..   .    ",
      ".     ..   .    ",
      ".     ..   .    ",
      ".     ..   .    ",
      ".     ..   .    ",
      ".     ..   .    ",
      ".#    ..   ..   ",
      ".##   ..    .   ",
      ".# #  ..    .   ",
      ".  ## ..     .  "
    ],
    [
      " .....        ..",
      " .....       .. ",
      " $$$$$       .  ",
      " .....      .   ",
      " .....      .   ",
      " .....     ..   ",
      " .....     .    ",
      " .....     .    ",
      " .....     .    ",
      " .....     .    ",
      " .....     .    ",
      " .....     .    ",
      " .....     ..   ",
      "#.....      .   ",
      "#.....      .   ",
      " .....       .  "
    ],
    [
      "              ..",
      "             .. ",
      "             .  ",
      "            .   ",
      "            .   ",
      "           ..   ",
      "           .    ",
      "           .    ",
      "   .       .    ",
      "           .    ",
      "           .    ",
      "           .    ",
      "           ..   ",
      " #          .   ",
      " # #        .   ",
      "   ##        .  "
    ],
    [
      "              ..",
      "             .. ",
      "             .  ",
      "            .   ",
      "            .   ",
      "           ..   ",
      "           .    ",
      "           .    ",
      "   .       .    ",
      "           .    ",
      "           .    ",
      "           .    ",
      "           ..   ",
      "            .   ",
      "            .   ",
      "             .  "
    ],
    [
      "              ..",
      "             .. ",
      "             .  ",
      "            .   ",
      "            .   ",
      "           ..   ",
      "           .    ",
      "           .    ",
      "   .       .    ",
      "           .    ",
      "           .    ",
      "           .    ",
      "           ..   ",
      "            .   ",
      "            .   ",
      "             .  "
    ],
    [
      "              ..",
      "             .. ",
      "             .  ",
      "            .   ",
      "            .   ",
      "           ..   ",
      "           .    ",
      "           .    ",
      "   .       .    ",
      "           .    ",
      "           .    ",
      "           .    ",
      "           ..   ",
      "            .   ",
      "            .   ",
      "             .  "
    ],
    [
      "              ..",
      "             .. ",
      "             .  ",
      "            .   ",
      "            .   ",
      "           ..   ",
      "           .    ",
      "           .    ",
      "   .       .    ",
      "           .    ",
      "           .    ",
      "           .    ",
      "           ..   ",
      "            .   ",
      "            .   ",
      "             .  "
    ],
    [
      "              ..",
      "             .. ",
      "             .  ",
      "            .   ",
      "            .   ",
      "           ..   ",
      "           .    ",
      "           .    ",
      "   .       .    ",
      "           .    ",
      "           .    ",
      "           .    ",
      "           ..   ",
      "            .   ",
      "            .   ",
      "             .  "
    ],
    [
      "              ..",
      "             .. ",
      "             .  ",
      "            .   ",
      "            .   ",
      "           ..   ",
      "           .    ",
      "           .    ",
      "   .       .    ",
      "           .    ",
      "           .    ",
      "           .    ",
      "           ..   ",
      "            .   ",
      "            .   ",
      "             .  "
    ],
    [
      "       .     ...",
      "       .    ....",
      "       .    ....",
      "       .   .....",
      "       .   .....",
      "       .  ......",
      "       .  ......",
      "       .  ......",
      "   .............",
      "          ......",
      "          ......",
      "          ......",
      "          ......",
      "           .....",
      "           .....",
      "            ...."
    ],
    [
      "              ..",
      "             .. ",
      "             .  ",
      "            .   ",
      "            .   ",
      "           ..   ",
      "           .    ",
      "           .    ",
      "           .    ",
      "           .    ",
      "           .    ",
      "           .    ",
      "           ..   ",
      "            .   ",
      "            .   ",
      "             .  "
    ],
    [
      "              ..",
      "             .. ",
      "             .  ",
      "            .   ",
      "            .   ",
      "           ..   ",
      "           .    ",
      "           .    ",
      "           .    ",
      "           .    ",
      "           .    ",
      "           .    ",
      "           ..   ",
      "            .   ",
      "            .   ",
      "             .  "
    ],
    [
      "              ..",
      "             .. ",
      "             .  ",
      "            .   ",
      "            .   ",
      "           ..   ",
      "           .    ",
      "           .    ",
      "           .    ",
      "           .    ",
      "           .    ",
      "           .    ",
      "           ..   ",
      "            .   ",
      "            .   ",
      "             .  "
    ],
    [
      "                ",
      "                ",
      "                ",
      "                ",
      "                ",
      "                ",
      "                ",
      "                ",
      "                ",
      "                ",
      "                ",
      "                ",
      "                ",
      "                ",
      "                ",
      "                "
    ],
    [
      "                ",
      "                ",
      "                ",
      "                ",
      "                ",
      "                ",
      "                ",
      "                ",
      "                ",
      "                ",
      "                ",
      "                ",
      "                ",
      "                ",
      "                ",
      "                "
    ],
    [
      "                ",
      "                ",
      "                ",
      "                ",
      "                ",
      "                ",
      "                ",
      "                ",
      "                ",
      "                ",
      "                ",
      "                ",
      "                ",
      "                ",
      "                ",
      "                "
    ],
    [
      "                ",
      "                ",
      "                ",
      "                ",
      "                ",
      "                ",
      "                ",
      "                ",
      "                ",
      "                ",
      "                ",
      "                ",
      "                ",
      "                ",
      "                ",
      "                "
    ],
    [
      "                ",
      "                ",
      "                ",
      "                ",
      "                ",
      "                ",
      "                ",
      "                ",
      "                ",
      "                ",
      "                ",
      "                ",
      "                ",
      "                ",
      "                ",
      "                "
    ],
    [
      "                ",
      "                ",
      "                ",
      "                ",
      "                ",
      "                ",
      "                ",
      "                ",
      "                ",
      "                ",
      "                ",
      "                ",
      "                ",
      "                ",
      "                ",
      "                "
    ],
    [
      "                ",
      "                ",
      "                ",
      "                ",
      "                ",
      "                ",
      "                ",
      "                ",
      "                ",
      "                ",
      "                ",
      "                ",
      "                ",
      "                ",
      "                ",
      "                "
    ],
    [
      "                ",
      "                ",
      "                ",
      "                ",
      "                ",
      "                ",
      "                ",
      "                ",
      "                ",
      "                ",
      "                ",
      "                ",
      "                ",
      "                ",
      "                ",
      "                "
    ],
    [
      "                ",
      "                ",
      "                ",
      "                ",
      "                ",
      "                ",
      "                ",
      "                ",
      "                ",
      "                ",
      "                ",
      "                ",
      "                ",
      "                ",
      "                ",
      "                "
    ],
    [
      "                ",
      "                ",
      "                ",
      "                ",
      "                ",
      "                ",
      "                ",
      "                ",
      "                ",
      "                ",
      "                ",
      "                ",
      "                ",
      "                ",
      "                ",
      "                "
    ],
    [
      "                ",
      "                ",
      "                ",
      "                ",
      "                ",
      "                ",
      "                ",
      "                ",
      "                ",
      "                ",
      "                ",
      "                ",
      "                ",
      "                ",
      "                ",
      "                "
    ],
    [
      "                ",
      "                ",
      "                ",
      "                ",
      "                ",
      "                ",
      "                ",
      "                ",
      "                ",
      "                ",
      "                ",
      "                ",
      "                ",
      "                ",
      "                ",
      "                "
    ],
    [
      "                ",
      "                ",
      "                ",
      "                ",
      "                ",
      "                ",
      "                ",
      "                ",
      "                ",
      "                ",
      "                ",
      "                ",
      "                ",
      "                ",
      "                ",
      "                "
    ],
    [
      "                ",
      "                ",
      "                ",
      "                ",
      "                ",
      "                ",
      "                ",
      "                ",
      "                ",
      "                ",
      "                ",
      "                ",
      "                ",
      "                ",
      "                ",
      "                "
    ],
    [
      "                ",
      "                ",
      "                ",
      "                ",
      "                ",
      "                ",
      "                ",
      "                ",
      "                ",
      "                ",
      "                ",
      "                ",
      "                ",
      "                ",
      "                ",
      "                "
    ],
    [
      "                ",
      "                ",
      "                ",
      "                ",
      "                ",
      "                ",
      "                ",
      "                ",
      "                ",
      "                ",
      "                ",
      "                ",
      "                ",
      "                ",
      "                ",
      "                "
    ],
    [
      "                ",
      "                ",
      "                ",
      "                ",
      "                ",
      "                ",
      "                ",
      "                ",
      "                ",
      "                ",
      "                ",
      "                ",
      "                ",
      "                ",
      "                ",
      "                "
    ],
    [
      "                ",
      "                ",
      "                ",
      "                ",
      "                ",
      "                ",
      "                ",
      "                ",
      "                ",
      "                ",
      "                ",
      "                ",
      "                ",
      "                ",
      "                ",
      "                "
    ],
    [
      "                ",
      "                ",
      "                ",
      "                ",
      "                ",
      "                ",
      "                ",
      "                ",
      "                ",
      "                ",
      "                ",
      "                ",
      "                ",
      "                ",
      "                ",
      "                "
    ],
    [
      "                ",
      "                ",
      "                ",
      "                ",
      "                ",
      "                ",
      "                ",
      "                ",
      "                ",
      "                ",
      "                ",
      "                ",
      "                ",
      "                ",
      "                ",
      "                "
    ]
  ]
}