{
  "xsize": 16,
  "zsize": 16,
  "refpalette": "lostcities:scattered",
  "slices": [
    [
      "    &&&&&&&&&&&&",
      "    &&&&&&&&&&&&",
      "    &&&&&&&&&&&&",
      "    &&&&&&&&&&&&",
      "    &&&&&&&&&&&&",
      "    &&&&&&&&&&&&",
      "    &&&&&&&&&&&&",
      "    &&&&&&&&&&&&",
      "    &&&&&&&&&&&&",
      "    &&&&&&&&&&&&",
      "    &&&&&&&&&&&&",
      "    &&&&&&&&&&&&",
      "    &&&&&&&&&&&&",
      "&&&&&&&&&&&&&&&&",
      "&&&&&&&&&&&&&&&&",
      "&&&&&&&&&&&&&&&&"
    ],
    [
      "     $$$$c$$$$$$",
      "     $$$$c$$$$$$",
      "     $$$$c$$$$$$",
      "     $$$$c$$$$$$",
      "   ww$$$$c$$$$$$",
      "   ww$$$$$c$$$$$",
      "     $$$$$c$$$$$",
      "     $$$$$$c$$$$",
      "     $$$$$$$cc$$",
      "     $$$$$$$$$cc",
      "     $$$$$$$$$$$",
      "     $$$$$$$$$$$",
      "    $$$&&&&&&&&&",
      "$$$$$$$$$$$$$$$$",
      "$$$$$$$$$$$$$$$$",
      "$$              "
    ],
    [
      "     fj         ",
      "     f         w",
      "     f          ",
      "     f          ",
      "    wf  m j     ",
      "   wwf          ",
      "     f      ww j",
      "     f     w    ",
      "     f   j   j  ",
      "     f          ",
      "     f j  j   j ",
      "     f$         ",
      "    $$$eeeeeeeee",
      "$$$ $$$         ",
      "$$++++++++++++++",
      "$$              "
    ],
    [
      "     f          ",
      "     f          ",
      "     f          ",
      "     f          ",
      "    wf  n       ",
      "   wwf          ",
      "     f      mw  ",
      "     f          ",
      "     f          ",
      "     f          ",
      "     f          ",
      "     f$         ",
      "    $$$j        ",
      "$$$ $$$         ",
      "$$++++++++++++++",
      "$$              "
    ],
    [
      "     f          ",
      "     f          ",
      "     f          ",
      "    pf          ",
      "    wf          ",
      "  rpwf          ",
      "  rrpf      nw  ",
      "     f          ",
      "     f          ",
      "     f          ",
      "     f          ",
      "     f$         ",
      "    $$$         ",
      "$$$ $$$         ",
      "$$++++++++++++++",
      "$$              "
    ],
    [
      "    rf          ",
      "     f          ",
      "    rf          ",
      "  ptpf          ",
      "   wwf          ",
      "  ppwf          ",
      "  rrpf       w  ",
      "     f          ",
      "     f          ",
      "     f          ",
      "     f          ",
      "     f$         ",
      "    $$$         ",
      "$$$ $$$         ",
      "$$++++++++++++++",
      "$$              "
    ],
    [
      "   prpr       pp",
      "               p",
      "   prr          ",
      "   tppp         ",
      " rpwwfp         ",
      " pwwwfrq     p  ",
      " rpptf       wp ",
      "  rrpf          ",
      "    rf          ",
      "     f          ",
      "     f          ",
      "     f$         ",
      "    $$$         ",
      "$$$ $$$         ",
      "$$++++++++++++++",
      "$$              "
    ],
    [
      "  rpr         pp",
      "  r           rp",
      "  rprr          ",
      " rpwppr         ",
      " qrpwwp         ",
      " rpppfr         ",
      "  rpwfrq     w  ",
      "  qrpfq      t  ",
      "  srrf          ",
      "     f          ",
      "     f          ",
      "     f$         ",
      "    $$$         ",
      "$$$  $$         ",
      "$$++++++++++++++",
      "$$              "
    ],
    [
      "   rrqs       pw",
      "   qqs        r ",
      "  qrrqs       rp",
      " qrpprq        r",
      " qrpwprq     rp ",
      "qrputpr   r pptu",
      " qrppfq   puuwu ",
      " sqrrf     utt  ",
      "  sqqf     ppt  ",
      "     f          ",
      "     f          ",
      "     f$         ",
      "      $         ",
      "$     $         ",
      "$$+  +++++++++++",
      "$$              "
    ],
    [
      "    q         rp",
      "     x       qrp",
      "  sqqs         r",
      "  qrrqs       pq",
      " qrpprq    rq ts",
      " rpwprq   rprpw ",
      " qrprf     wp wu",
      " sqrqf     tpwpt",
      "   qsf     prprp",
      "     f     rqrqr",
      "             qs ",
      "      $         ",
      "                ",
      "                ",
      "$     ++++++++++",
      "$$              "
    ],
    [
      "    s        sqr",
      "              qr",
      "    sx         q",
      "   rqs      qqpp",
      " qrprqq  xsqrpwu",
      " rpwpr    qqqrpp",
      " qrprfs   qprpwp",
      "  qrqf    rprppp",
      "    sf    qrqrr ",
      "     f     qsq  ",
      "            xs  ",
      "                ",
      "                ",
      "                ",
      "       +++++++++",
      "$$              "
    ],
    [
      "              sq",
      "              sq",
      "               q",
      "    sx      sqrr",
      "   rqs    xxqqpp",
      " qrprf    sssqr ",
      "  qrqf    qrqrpr",
      "   qsf     rqrrr",
      "     f    sqsqqq",
      "          ssxss ",
      "            yxx ",
      "                ",
      "                ",
      "                ",
      "       +++++++++",
      "$               "
    ],
    [
      "              xs",
      "                ",
      "                ",
      "    x       xsqq",
      "   qs     xxsqrr",
      "   rqf    ssxsqq",
      "   qsf    sqs rq",
      "     f   xsqsqq ",
      "     f    xsxsss",
      "            yxxx",
      "             y  ",
      "                ",
      "                ",
      "                ",
      "       +++++++++",
      "                "
    ],
    [
      "               x",
      "               s",
      "                ",
      "     f       xs ",
      "     f     #xsqq",
      "     f     xyxss",
      "     f   yxsxsq ",
      "     f    xsxss ",
      "           xyxx ",
      "            #xyy",
      "            ##  ",
      "                ",
      "                ",
      "                ",
      "       +++++++++",
      "                "
    ],
    [
      "     f         y",
      "     f          ",
      "     f          ",
      "     f          ",
      "     f     #yxs ",
      "     f     y#yxx",
      "     f    yxyxsx",
      "     f    yxyxx ",
      "           yyyy ",
      "             #  ",
      "                ",
      "                ",
      "                ",
      "                ",
      "       +++++++++",
      "                "
    ],
    [
      "     f          ",
      "     f          ",
      "     f          ",
      "     f          ",
      "     f     # y  ",
      "     f     ###yy",
      "     f    #y#yxy",
      "     f     y#yy ",
      "             #  ",
      "                ",
      "                ",
      "         &&&&&&&",
      "        &&&&&&&&",
      "        kkkkkkkk",
      "       +++++++++",
      "                "
    ],
    [
      "     f          ",
      "     f          ",
      "     f          ",
      "     f          ",
      "     f          ",
      "     f     #### ",
      "     f     ###y#",
      "            ### ",
      "                ",
      "                ",
      "                ",
      "                ",
      "                ",
      "        eeeeeeee",
      "       ++++++++ ",
      "                "
    ],
    [
      "     f          ",
      "     f          ",
      "     f          ",
      "     f          ",
      "     f          ",
      "     f       #  ",
      "     f     #### ",
      "                ",
      "                ",
      "                ",
      "                ",
      "                ",
      "                ",
      "                ",
      "      ++++++++  ",
      "                "
    ],
    [
      "     f          ",
      "     f          ",
      "     f          ",
      "     f          ",
      "     f          ",
      "     f          ",
      "            #   ",
      "                ",
      "                ",
      "                ",
      "                ",
      "                ",
      "                ",
      "                ",
      "      +++++++   ",
      "                "
    ],
    [
      "     f          ",
      "     f          ",
      "     f          ",
      "     f          ",
      "     f          ",
      "     f          ",
      "                ",
      "                ",
      "                ",
      "                ",
      "                ",
      "                ",
      "                ",
      "                ",
      "     ++++++++   ",
      "                "
    ],
    [
      "     f          ",
      "     f          ",
      "     f          ",
      "     f          ",
      "     f          ",
      "     f          ",
      "                ",
      "                ",
      "                ",
      "                ",
      "                ",
      "                ",
      "                ",
      "                ",
      "    ++++++++    ",
      "                "
    ],
    [
      "     f          ",
      "     f          ",
      "     f          ",
      "     f          ",
      "     f          ",
      "                ",
      "                ",
      "                ",
      "                ",
      "                ",
      "                ",
      "                ",
      "                ",
      "                ",
      "    ++++++++    ",
      "                "
    ],
    [
      "     f          ",
      "     f          ",
      "     f          ",
      "     f          ",
      "     f          ",
      "                ",
      "                ",
      "                ",
      "                ",
      "                ",
      "                ",
      "                ",
      "                ",
      "      $         ",
      "    +++++++     ",
      "                "
    ],
    [
      "     f          ",
      "     f          ",
      "     f          ",
      "     f          ",
      "                ",
      "                ",
      "                ",
      "                ",
      "                ",
      "                ",
      "                ",
      "                ",
      "                ",
      "     $$         ",
      "    +++++++     ",
      "                "
    ],
    [
      "     f          ",
      "     f          ",
      "     f          ",
      "     f          ",
      "                ",
      "                ",
      "                ",
      "                ",
      "                ",
      "                ",
      "                ",
      "                ",
      "                ",
      "     $$         ",
      "    +++++++     ",
      "                "
    ],
    [
      "     f          ",
      "     f          ",
      "     f          ",
      "                ",
      "                ",
      "                ",
      "                ",
      "                ",
      "                ",
      "                ",
      "                ",
      "                ",
      "                ",
      "     $$         ",
      "    +++++++     ",
      "                "
    ],
    [
      "    $$$         ",
      "    $$$         ",
      "    $$$         ",
      "                ",
      "                ",
      "                ",
      "                ",
      "                ",
      "                ",
      "                ",
      "                ",
      "                ",
      "                ",
      "    $$$$$$      ",
      "    $$$$$$      ",
      "    $$$$$$      "
    ],
    [
      "    $$$         ",
      "    $$$         ",
      "    $$$         ",
      "                ",
      "                ",
      "                ",
      "                ",
      "                ",
      "                ",
      "                ",
      "                ",
      "                ",
      "                ",
      "     $$$$$      ",
      "    $$$$$$      ",
      "    $$$$$$      "
    ],
    [
      "                ",
      "                ",
      "      $         ",
      "                ",
      "                ",
      "                ",
      "                ",
      "                ",
      "                ",
      "                ",
      "                ",
      "                ",
      "                ",
      "      $$        ",
      "                ",
      "                "
    ],
    [
      "                ",
      "                ",
      "      $         ",
      "                ",
      "                ",
      "                ",
      "                ",
      "                ",
      "                ",
      "                ",
      "                ",
      "                ",
      "                ",
      "       $        ",
      "                ",
      "                "
    ],
    [
      "      &         ",
      "      &         ",
      "      $         ",
      "                ",
      "                ",
      "                ",
      "                ",
      "                ",
      "                ",
      "                ",
      "                ",
      "                ",
      "                ",
      "       $&       ",
      "                ",
      "                "
    ],
    [
      "    $$$$        ",
      "    $$$$        ",
      "    $$$$        ",
      "    $  $        ",
      "                ",
      "                ",
      "                ",
      "                ",
      "                ",
      "                ",
      "                ",
      "                ",
      "                ",
      "        $       ",
      "       $$       ",
      "      $$$       "
    ],
    [
      "    llllllllllll",
      "    llllllllllll",
      "    llllllllllll",
      "    llllllllllll",
      "       lllllll  ",
      "         ll     ",
      "         l      ",
      "                ",
      "                ",
      "                ",
      "                ",
      "                ",
      "                ",
      "                ",
      "                ",
      "                "
    ],
    [
      "                ",
      "               j",
      "                ",
      "                ",
      "                ",
      "                ",
      "                ",
      "                ",
      "                ",
      "                ",
      "                ",
      "                ",
      "                ",
      "                ",
      "                ",
      "                "
    ],
    [
      "                ",
      "                ",
      "                ",
      "                ",
      "                ",
      "                ",
      "                ",
      "                ",
      "                ",
      "                ",
      "                ",
      "                ",
      "                ",
      "                ",
      "                ",
      "                "
    ],
    [
      "                ",
      "                ",
      "                ",
      "                ",
      "                ",
      "                ",
      "                ",
      "                ",
      "                ",
      "                ",
      "                ",
      "                ",
      "                ",
      "                ",
      "                ",
      "                "
    ]
  ]
}