{
  "xsize": 16,
  "zsize": 16,
  "refpalette": "lostcities:scattered",
  "slices": [
    [
      "                ",
      "                ",
      "                ",
      "                ",
      "                ",
      "                ",
      "      $  $      ",
      "       $$       ",
      "       $$       ",
      "      $  $      ",
      "                ",
      "                ",
      "                ",
      "                ",
      "                ",
      "                "
    ],
    [
      "v220&&&&02vvvvvv",
      "2220&&&&00220000",
      "3320&&&002200&&&",
      "333200002220&&&&",
      "333200022220&&&&",
      "332200222200&&&&",
      "2220022220&&&&&&",
      "000022222&vvv&&&",
      "0&&023332&vvv&&&",
      "&&&023332&vvv&&&",
      "&v&023320&&&&0vv",
      "&v&023200&&&0vvv",
      "&&023320&&&02vvv",
      "00233320&&02vvvv",
      "22333200002vvvvv",
      "3333320002vvvvvv"
    ],
    [
      "             ..#",
      ".           ..##",
      " ..       ..   #",
      "   .......      ",
      "                ",
      "                ",
      "                ",
      "                ",
      "                ",
      "             $$ ",
      "  $$         $$ ",
      "  $$            ",
      "    ........    ",
      "  ...      ...  ",
      "..            ..",
      ".              ."
    ],
    [
      "             ..#",
      ".           .. #",
      " ..       ..    ",
      "   .......      ",
      "                ",
      "                ",
      "                ",
      "                ",
      "                ",
      "                ",
      "                ",
      "                ",
      "    ........    ",
      "  ...      ...  ",
      "..            ..",
      ".              ."
    ],
    [
      "             ..#",
      ".           ..##",
      " ..       ..    ",
      "   .......      ",
      "                ",
      "                ",
      "                ",
      "                ",
      "                ",
      "                ",
      "                ",
      "                ",
      "    ........    ",
      "  ...      ...  ",
      "..            ..",
      ".              ."
    ],
    [
      "             ..#",
      ".           ..##",
      " ..       .. ## ",
      "   .......      ",
      "                ",
      "                ",
      "                ",
      "                ",
      "                ",
      "                ",
      "                ",
      "                ",
      "    ........    ",
      "  ...      ...  ",
      "..            ..",
      ".              ."
    ],
    [
      "             ..#",
      ".           ..##",
      " ..       .. ## ",
      "   .......      ",
      "                ",
      "                ",
      "                ",
      "                ",
      "                ",
      "                ",
      "                ",
      "                ",
      "    ........    ",
      "  ...      ...  ",
      "..            ..",
      ".              ."
    ],
    [
      "             .. ",
      ".           ..##",
      " ..       .. ## ",
      "   .......      ",
      "                ",
      "                ",
      "                ",
      "                ",
      "                ",
      "                ",
      "                ",
      "                ",
      "    ........    ",
      "  ...      ...  ",
      "..            ..",
      ".              ."
    ],
    [
      "             .. ",
      ".           ..##",
      " ..       .. ## ",
      "   .......      ",
      "                ",
      "                ",
      "                ",
      "                ",
      "                ",
      "                ",
      "                ",
      "                ",
      "    ........    ",
      "  ...      ...  ",
      "..            ..",
      ".              ."
    ],
    [
      "             ..#",
      ".           ..##",
      " ..       .. ###",
      "   .......    # ",
      "                ",
      "                ",
      "                ",
      "                ",
      "                ",
      "                ",
      "                ",
      "                ",
      "    ........    ",
      "  ...      ...  ",
      "..            ..",
      ".              ."
    ],
    [
      "..           ..#",
      "..          ..# ",
      " ..       ..  # ",
      "   .......      ",
      "                ",
      "                ",
      "                ",
      "                ",
      "                ",
      "                ",
      "                ",
      "                ",
      "    ........    ",
      "  ...      ...  ",
      "..            ..",
      ".              ."
    ],
    [
      " .           ..#",
      ".           ..# ",
      " ..       ..    ",
      "   .......      ",
      "                ",
      "                ",
      "                ",
      "                ",
      "                ",
      "                ",
      "                ",
      "                ",
      "    ........    ",
      "  ...      ...  ",
      "..            ..",
      ".              ."
    ],
    [
      "             ..#",
      ".           ..# ",
      " ..       ..    ",
      "   .......      ",
      "                ",
      "                ",
      "                ",
      "                ",
      "                ",
      "                ",
      "                ",
      "                ",
      "    ........    ",
      "  ...      ...  ",
      "..            ..",
      ".              ."
    ],
    [
      "             ..#",
      ".           ..##",
      " ..       ..    ",
      "   .......      ",
      "                ",
      "                ",
      "                ",
      "                ",
      "                ",
      "                ",
      "                ",
      "                ",
      "    ........    ",
      "  ...      ...  ",
      "..            ..",
      ".              ."
    ],
    [
      "             ..#",
      ".           .. #",
      " ..       ..    ",
      "   .......      ",
      "                ",
      "                ",
      "                ",
      "                ",
      "                ",
      "                ",
      "                ",
      "                ",
      "    ........    ",
      "  ...      ...  ",
      "..            ..",
      ".              ."
    ],
    [
      "             ..#",
      ".           .. #",
      " ..       ..    ",
      "   .......      ",
      "                ",
      "                ",
      "                ",
      "                ",
      "                ",
      "                ",
      "                ",
      "                ",
      "    ........    ",
      "  ...      ...  ",
      "..            ..",
      ".              ."
    ],
    [
      "             ..$",
      ".           ..$$",
      "$..       ..$$$$",
      "$$$.......$$$$  ",
      "$$$$$$$$$$$$$   ",
      "   $$$$$$$      ",
      "                ",
      "                ",
      "                ",
      "                ",
      "                ",
      "                ",
      "    ........    ",
      "  ...      ...  ",
      "..            ..",
      ".              ."
    ],
    [
      "             ..#",
      ".           ..  ",
      " ..       ..    ",
      "   .......      ",
      "                ",
      "                ",
      "                ",
      "                ",
      "                ",
      "                ",
      "                ",
      "                ",
      "    ........    ",
      "  ...      ...  ",
      "..            ..",
      ".              ."
    ],
    [
      "             ..#",
      ".           ..  ",
      " ..       ..    ",
      "   .......      ",
      "                ",
      "                ",
      "                ",
      "                ",
      "                ",
      "                ",
      "                ",
      "                ",
      "    ........    ",
      "  ...      ...  ",
      "..            ..",
      ".              ."
    ],
    [
      "             ..#",
      ".           ..  ",
      " ..       ..    ",
      "   .......      ",
      "                ",
      "                ",
      "                ",
      "                ",
      "                ",
      "                ",
      "                ",
      "                ",
      "    ........    ",
      "  ...    . ...  ",
      "..            ..",
      ".              ."
    ],
    [
      "             ..#",
      ".           ..  ",
      " ..       ..    ",
      "   .......      ",
      "                ",
      "                ",
      "                ",
      "                ",
      "                ",
      "                ",
      "                ",
      "                ",
      "    ........    ",
      "  ...      ...  ",
      "..            ..",
      ".              ."
    ],
    [
      "             ..$",
      ".           ..$$",
      "$..       ..$$$$",
      "$$$.......$$$$  ",
      "$$$$$$$$$$$$$   ",
      "   $$$$$$$      ",
      "                ",
      "                ",
      "                ",
      "                ",
      "                ",
      "                ",
      "    ........    ",
      "  ...      ...  ",
      "..            ..",
      ".              ."
    ],
    [
      "             ..#",
      ".           .. #",
      " ..       ..    ",
      "   .......      ",
      "                ",
      "                ",
      "                ",
      "                ",
      "                ",
      "                ",
      "                ",
      "                ",
      "    ........    ",
      "  ...      ...  ",
      "..            ..",
      ".              ."
    ],
    [
      "             ..#",
      ".           ..  ",
      " ..       ..    ",
      "   .......      ",
      "                ",
      "                ",
      "                ",
      "                ",
      "                ",
      "                ",
      "                ",
      "                ",
      "    ........    ",
      "  ...      ...  ",
      "..           ...",
      ".              ."
    ],
    [
      "             ..#",
      ".           ..  ",
      " ..       ..    ",
      "   .......      ",
      "      .         ",
      "................",
      "                ",
      "                ",
      "                ",
      "                ",
      "                ",
      "    ........    ",
      "  ............  ",
      "................",
      "................",
      "................"
    ],
    [
      "             ..#",
      ".           ..  ",
      " ..       ..    ",
      "   .......      ",
      "                ",
      "   .            ",
      "                ",
      "                ",
      "                ",
      "                ",
      "                ",
      "                ",
      "    ........    ",
      "  ...      ...  ",
      "..            ..",
      ".              ."
    ],
    [
      "             ..#",
      ".           ..  ",
      " ..       ..    ",
      "   .......      ",
      "                ",
      "   .            ",
      "                ",
      "                ",
      "                ",
      "                ",
      "                ",
      "                ",
      "    ........    ",
      "  ...      ...  ",
      "..            ..",
      ".              ."
    ],
    [
      "             ..#",
      ".           ..  ",
      " ..       ..    ",
      "   .......      ",
      "                ",
      "   .            ",
      "                ",
      "                ",
      "                ",
      "                ",
      "                ",
      "                ",
      "    ........    ",
      "  ...      ...  ",
      "..            ..",
      ".              ."
    ],
    [
      "             .. ",
      ".           ..  ",
      " ..       ..    ",
      "   .......      ",
      "                ",
      "   .            ",
      "                ",
      "                ",
      "                ",
      "                ",
      "                ",
      "                ",
      "                ",
      "                ",
      "                ",
      "                "
    ],
    [
      "             .. ",
      ".           ..  ",
      " ..       ..    ",
      "   .......      ",
      "                ",
      "   .            ",
      "                ",
      "                ",
      "                ",
      "                ",
      "                ",
      "                ",
      "                ",
      "                ",
      "                ",
      "                "
    ],
    [
      "             .. ",
      ".           ..  ",
      " ..       ..    ",
      "   .......      ",
      "                ",
      "   .            ",
      "                ",
      "                ",
      "                ",
      "                ",
      "                ",
      "                ",
      "                ",
      "                ",
      "                ",
      "                "
    ],
    [
      "             .. ",
      ".           ..  ",
      " ..       ..    ",
      "   .......      ",
      "                ",
      "   .            ",
      "                ",
      "                ",
      "                ",
      "                ",
      "                ",
      "                ",
      "                ",
      "                ",
      "                ",
      "                "
    ],
    [
      "             ..$",
      ".           ..$$",
      "$..       ..$$$$",
      "$$$.......$$$$  ",
      "$$$$$$$$$$$$$   ",
      "   .$$$$$$      ",
      "   .            ",
      "   .            ",
      "   .            ",
      "   .            ",
      "   .            ",
      "   .            ",
      "   .            ",
      "   .            ",
      "   .            ",
      "   .            "
    ],
    [
      "             .. ",
      ".           ... ",
      " ..       ..    ",
      "   .......      ",
      "   .     .      ",
      "                ",
      "                ",
      "                ",
      "                ",
      "                ",
      "                ",
      "                ",
      "                ",
      "                ",
      "                ",
      "                "
    ],
    [
      "             .. ",
      ".           ... ",
      " ..       ..    ",
      "   .......      ",
      "   .     .      ",
      "                ",
      "                ",
      "                ",
      "                ",
      "                ",
      "                ",
      "                ",
      "                ",
      "                ",
      "                ",
      "                "
    ],
    [
      "/////////////   ",
      " ///////////  . ",
      "   ///////      ",
      "                ",
      "   .     .      ",
      "                ",
      "                ",
      "                ",
      "                ",
      "                ",
      "                ",
      "                ",
      "                ",
      "                ",
      "                ",
      "                "
    ],
    [
      " ///     ///   $",
      "    /////     $$",
      "$           $$$$",
      "$$$       $$$$  ",
      "$$$$$$$$$$$$$   ",
      "   $$$$$$$      ",
      "                ",
      "                ",
      "                ",
      "                ",
      "                ",
      "                ",
      "                ",
      "                ",
      "                ",
      "                "
    ],
    [
      "    /////       ",
      "                ",
      "                ",
      "                ",
      "                ",
      "                ",
      "                ",
      "                ",
      "                ",
      "                ",
      "                ",
      "                ",
      "                ",
      "                ",
      "                ",
      "                "
    ],
    [
      "                ",
      "                ",
      "                ",
      "                ",
      "                ",
      "                ",
      "                ",
      "                ",
      "                ",
      "                ",
      "                ",
      "                ",
      "                ",
      "                ",
      "                ",
      "                "
    ],
    [
      "                ",
      "                ",
      "                ",
      "                ",
      "                ",
      "                ",
      "                ",
      "                ",
      "                ",
      "                ",
      "                ",
      "                ",
      "                ",
      "                ",
      "                ",
      "                "
    ],
    [
      "                ",
      "                ",
      "                ",
      "                ",
      "                ",
      "                ",
      "                ",
      "                ",
      "                ",
      "                ",
      "                ",
      "                ",
      "                ",
      "                ",
      "                ",
      "                "
    ],
    [
      "                ",
      "                ",
      "                ",
      "                ",
      "                ",
      "                ",
      "                ",
      "                ",
      "                ",
      "                ",
      "                ",
      "                ",
      "                ",
      "                ",
      "                ",
      "                "
    ],
    [
      "                ",
      "                ",
      "                ",
      "                ",
      "                ",
      "                ",
      "                ",
      "                ",
      "                ",
      "                ",
      "                ",
      "                ",
      "                ",
      "                ",
      "                ",
      "                "
    ],
    [
      "                ",
      "                ",
      "                ",
      "                ",
      "                ",
      "                ",
      "                ",
      "                ",
      "                ",
      "                ",
      "                ",
      "                ",
      "                ",
      "                ",
      "                ",
      "                "
    ],
    [
      "                ",
      "                ",
      "                ",
      "                ",
      "                ",
      "                ",
      "                ",
      "                ",
      "                ",
      "                ",
      "                ",
      "                ",
      "                ",
      "                ",
      "                ",
      "                "
    ],
    [
      "                ",
      "                ",
      "                ",
      "                ",
      "                ",
      "                ",
      "                ",
      "                ",
      "                ",
      "                ",
      "                ",
      "                ",
      "                ",
      "                ",
      "                ",
      "                "
    ],
    [
      "                ",
      "                ",
      "                ",
      "                ",
      "                ",
      "                ",
      "                ",
      "                ",
      "                ",
      "                ",
      "                ",
      "                ",
      "                ",
      "                ",
      "                ",
      "                "
    ],
    [
      "                ",
      "                ",
      "                ",
      "                ",
      "                ",
      "                ",
      "                ",
      "                ",
      "                ",
      "                ",
      "                ",
      "                ",
      "                ",
      "                ",
      "                ",
      "                "
    ]
  ]
}