{
  "xsize": 16,
  "zsize": 16,
  "refpalette": "lostcities:scattered",
  "slices": [
    [
      "      &   w   $$",
      "      &       $$",
      "      &&     $$$",
      "     &&&   m $$$",
      "     &&&     $$$",
      "     &&&&   &$$$",
      "     &&&&&&&&$$$",
      "j m &&&&&&&&&$$$",
      "   &&&&&&&&&&$$$",
      "&&&&&&&&&&&&&$$$",
      "&&&&&&&&&&&&&$$$",
      "&&&&&&&&&&&&&$$$",
      "&&&&&&&&&&&&&$$$",
      "&&&&&&&&&&&&&$$$",
      "&&&&&&&&&&&&&$$$",
      "&&&&&&&&&&&&&$$$"
    ],
    [
      "          w   j ",
      "      m         ",
      "               j",
      "    w      n    ",
      "     w          ",
      "     w          ",
      "              j ",
      "  n   $$$       ",
      "     $$$$$&&    ",
      "    $$$$$&&&    ",
      "    &&&&&&&&    ",
      " j j j  &&&&    ",
      "             j  ",
      "          j     ",
      "m       &&&&   j",
      "&&&&&&&&&&&&    "
    ],
    [
      "          w     ",
      "      n         ",
      "                ",
      "                ",
      "                ",
      "     w          ",
      "                ",
      "                ",
      "      j         ",
      "                ",
      "     eeee&&j    ",
      "                ",
      "                ",
      "                ",
      "n               ",
      "eeeeeeeee&&j    "
    ],
    [
      "         pw     ",
      "          p     ",
      "                ",
      "                ",
      "                ",
      "     w          ",
      "                ",
      "                ",
      "                ",
      "                ",
      "                ",
      "                ",
      "                ",
      "                ",
      "                ",
      "  m      z{     "
    ],
    [
      "p         wu    ",
      "                ",
      "                ",
      "                ",
      "                ",
      "     w          ",
      "                ",
      "                ",
      "                ",
      "                ",
      "                ",
      "                ",
      "                ",
      "                ",
      "                ",
      "  n      z{     "
    ],
    [
      "        rpwuu   ",
      "        put     ",
      "         t      ",
      "                ",
      "                ",
      "     wp         ",
      "     p          ",
      "                ",
      "                ",
      "                ",
      "                ",
      "                ",
      "                ",
      "                ",
      "                ",
      "                "
    ],
    [
      "pr       p wprq ",
      "p      puwwprqs ",
      "          tupr  ",
      "r          p    ",
      "                ",
      "    uw          ",
      "                ",
      "                ",
      "                ",
      "                ",
      "                ",
      "                ",
      "                ",
      "                ",
      "                ",
      "                "
    ],
    [
      "p      qprpprqs ",
      "rq     pwpwpr   ",
      "pr   prptppp    ",
      "r  ptt   rrrq   ",
      "   putp   q     ",
      "   uuwpr        ",
      "     tup        ",
      "      t         ",
      "                ",
      "                ",
      "                ",
      "                ",
      "                ",
      "                ",
      "                ",
      "                "
    ],
    [
      "rpq    qqqrrqsx ",
      "qrq    rprprqsx ",
      "qq    rrp rrq   ",
      "qsrpuwprrqqqs   ",
      " xqrpprq  ss    ",
      " qrpw p         ",
      " sqrpwwup       ",
      "  rput          ",
      "    p           ",
      "                ",
      "                ",
      "                ",
      "                ",
      "                ",
      "                ",
      "                "
    ],
    [
      "qqq    sqs qsxy ",
      "sqs    qrqrqsx  ",
      "sx qrqqqrqq sx  ",
      "sxqrppqqqsssxy  ",
      " xsqrrqrq  x    ",
      " sqrpprpq       ",
      "   rpwpwp       ",
      "    ppptp       ",
      "   qrrr         ",
      "     q          ",
      "                ",
      "                ",
      "                ",
      "                ",
      "                ",
      "                "
    ],
    [
      "sqs    xsxssxx# ",
      "xsx    sqsqsxy  ",
      "sxss qsxqs   y  ",
      "sxsqrrsxsxxxy   ",
      " yxsqqsqs       ",
      " xsqrrqqq       ",
      " xsqrprpr       ",
      "   qrr pr       ",
      "   sqqqr        ",
      "    ss          ",
      "                ",
      "                ",
      "                ",
      "                ",
      "                ",
      "                "
    ],
    [
      "xsx     xyxxy#  ",
      "yx  x   sxsxy   ",
      "x# xsssx xx     ",
      "   sqqsx  yy    ",
      "  yxssxsx       ",
      " yxsq sqs       ",
      "  xsqrqrq       ",
      "  xs qqrq       ",
      "  yxsssq        ",
      "    x           ",
      "                ",
      "                ",
      "                ",
      "                ",
      "                ",
      "                "
    ],
    [
      "yx      y#yy#   ",
      "#y   y   yxy    ",
      "y#  xx   yy     ",
      "   xssx#        ",
      " ##yxxyx        ",
      " #xxssxsx       ",
      "  yxsqsqs       ",
      "  y   sq        ",
      "   yxxxs        ",
      "         z{     ",
      "         |      ",
      "                ",
      "                ",
      "                ",
      "                ",
      "                "
    ],
    [
      "#y       ###    ",
      "#        #y#    ",
      "##  yy    #     ",
      "   yxxy#        ",
      "   yyy#y        ",
      "  #yxxyx        ",
      "   yxsxs        ",
      "     xx         ",
      "    yy          ",
      "         z{     ",
      "         |}     ",
      "                ",
      "                ",
      "                ",
      "                ",
      "                "
    ],
    [
      "#        ##     ",
      "#         #     ",
      "#    #          ",
      "    yy##        ",
      "    ###         ",
      "   #yy#y        ",
      "    yxy         ",
      "     yy         ",
      "                ",
      "         &&     ",
      "         &&     ",
      "                ",
      "                ",
      "                ",
      "                ",
      "                "
    ],
    [
      "#        &&&&&&&",
      "         &&&&&&&",
      "         &&ͱkkkk",
      "     ##  &&Ͱ    ",
      "    ###  &&Ͱ    ",
      "    ###  &&Ͱ    ",
      "    #y#  &&Ͱ    ",
      "     #   &&Ͱ    ",
      "         &&Ͱ    ",
      "     &&&&&&Ͱ    ",
      "     &&&&&&Ͱ    ",
      "       kkkk}    ",
      "                ",
      "                ",
      "                ",
      "                "
    ],
    [
      "                ",
      "                ",
      "           zeeee",
      "     #     ͳ    ",
      "     #     ͳ    ",
      "     ##    ͳ    ",
      "     #     ͳ    ",
      "           ͳ    ",
      "           ͳ    ",
      "         zhͰ    ",
      "         ͱͱͰ    ",
      "     eeeekk     ",
      "                ",
      "                ",
      "                ",
      "                "
    ],
    [
      "                ",
      "                ",
      "                ",
      "                ",
      "     #          ",
      "                ",
      "                ",
      "                ",
      "                ",
      "         z{     ",
      "         |}     ",
      "                ",
      "                ",
      "                ",
      "                ",
      "                "
    ],
    [
      "                ",
      "                ",
      "                ",
      "                ",
      "                ",
      "                ",
      "                ",
      "                ",
      "                ",
      "         z{     ",
      "         |}     ",
      "                ",
      "                ",
      "                ",
      "                ",
      "                "
    ],
    [
      "                ",
      "                ",
      "                ",
      "                ",
      "                ",
      "                ",
      "                ",
      "                ",
      "                ",
      "         z{     ",
      "         |}     ",
      "                ",
      "                ",
      "                ",
      "                ",
      "                "
    ],
    [
      "                ",
      "                ",
      "                ",
      "                ",
      "                ",
      "                ",
      "                ",
      "                ",
      "                ",
      "         z{     ",
      "         |}     ",
      "                ",
      "                ",
      "                ",
      "                ",
      "         z      "
    ],
    [
      "                ",
      "                ",
      "                ",
      "                ",
      "                ",
      "                ",
      "                ",
      "                ",
      "                ",
      "         z{     ",
      "         |}     ",
      "                ",
      "                ",
      "                ",
      "                ",
      "         z{     "
    ],
    [
      "                ",
      "                ",
      "                ",
      "                ",
      "                ",
      "                ",
      "                ",
      "                ",
      "                ",
      "         z{     ",
      "         |}     ",
      "                ",
      "                ",
      "                ",
      "                ",
      "         z{     "
    ],
    [
      "                ",
      "                ",
      "                ",
      "                ",
      "                ",
      "                ",
      "                ",
      "                ",
      "                ",
      "         z{     ",
      "         |}     ",
      "                ",
      "                ",
      "                ",
      "                ",
      "         z{     "
    ],
    [
      "                ",
      "                ",
      "                ",
      "                ",
      "                ",
      "                ",
      "                ",
      "                ",
      "                ",
      "         z{     ",
      "         |}     ",
      "                ",
      "                ",
      "                ",
      "                ",
      "         z{     "
    ],
    [
      "                ",
      "                ",
      "                ",
      "                ",
      "                ",
      "                ",
      "                ",
      "                ",
      "                ",
      "         z{     ",
      "         |}     ",
      "                ",
      "                ",
      "                ",
      "                ",
      "         z{     "
    ],
    [
      "                ",
      "                ",
      "                ",
      "                ",
      "                ",
      "                ",
      "                ",
      "                ",
      "                ",
      "         z{     ",
      "         |}     ",
      "                ",
      "                ",
      "                ",
      "                ",
      "         z{     "
    ],
    [
      "                ",
      "                ",
      "                ",
      "                ",
      "                ",
      "                ",
      "                ",
      "                ",
      "                ",
      "         z{     ",
      "         |}     ",
      "                ",
      "                ",
      "                ",
      "                ",
      "         z{     "
    ],
    [
      "                ",
      "                ",
      "                ",
      "                ",
      "                ",
      "                ",
      "                ",
      "                ",
      "                ",
      "         z{     ",
      "         |}     ",
      "                ",
      "                ",
      "                ",
      "                ",
      "         z{     "
    ],
    [
      "                ",
      "                ",
      "                ",
      "                ",
      "                ",
      "                ",
      "                ",
      "                ",
      "                ",
      "         &&     ",
      "         &&     ",
      "                ",
      "                ",
      "                ",
      "                ",
      "         &&     "
    ],
    [
      "         &&     ",
      "         &&     ",
      "         &&     ",
      "         &&     ",
      "         &&     ",
      "         &&     ",
      "         &&     ",
      "         &&     ",
      "        &&&&    ",
      "&&&&&&&&&ͱͱ&    ",
      "&&&&&&&&&ͱͱ&    ",
      "        &&&&    ",
      "                ",
      "                ",
      "        &&&&    ",
      "&&&&&&&&&ͱͱ&    "
    ],
    [
      "        $$$$    ",
      "        $$$$    ",
      "        $$$$    ",
      "        $$$$    ",
      "        $$$$    ",
      "        $$$$    ",
      "        $$$$    ",
      "        $$$$    ",
      "$$$$$$$$$$$$$$$$",
      "$$$$$$$$$$$$$$$$",
      "$$$$$$$$$$$$$$$$",
      "$$$$$$$$$$$$$$$$",
      "$$$$$$$$$$$$$$$$",
      "$$$$$$$$$$$$$$$$",
      "$$$$$$$$$$$$$$$$",
      "$$$$$$$$$$$$$$$$"
    ],
    [
      "   lllllllllllll",
      "   lllllllllllll",
      "  llllllllllllll",
      "  llllllllllllll",
      " lllllllllllllll",
      " lllllllllllllll",
      "llllllllllllllll",
      "llllllllllllllll",
      "llllllllllllllll",
      "llllllllllllllll",
      "llllllllllllllll",
      "llllllllllllllll",
      "llllllllllllllll",
      "llllllllllllllll",
      "llllllllllllllll",
      "llllllllllllllll"
    ],
    [
      "              m ",
      "                ",
      "               j",
      "           j    ",
      "                ",
      "                ",
      "              m ",
      "                ",
      "                ",
      "         j      ",
      "           j    ",
      "                ",
      "           j j  ",
      "                ",
      "                ",
      "           j  j "
    ],
    [
      "              n ",
      "                ",
      "                ",
      "                ",
      "                ",
      "                ",
      "              n ",
      "                ",
      "                ",
      "                ",
      "                ",
      "                ",
      "                ",
      "                ",
      "                ",
      "                "
    ],
    [
      "                ",
      "                ",
      "                ",
      "                ",
      "                ",
      "                ",
      "                ",
      "                ",
      "                ",
      "                ",
      "                ",
      "                ",
      "                ",
      "                ",
      "                ",
      "                "
    ]
  ]
}