{
  "xsize": 16,
  "zsize": 16,
  "refpalette": "lostcities:scattered",
  "slices": [
    [
      "                ",
      "                ",
      "                ",
      "                ",
      "                ",
      "                ",
      "                ",
      "                ",
      "             #  ",
      "             #  ",
      "                ",
      "                ",
      "                ",
      "                ",
      "                ",
      "                "
    ],
    [
      "   20&&vvvvvv#  ",
      "33320&&&&&&vvvvv",
      "33320&&&0000&vv&",
      "23320&&&0222&vvv",
      "223320&&02220&v&",
      "022320&&02220&&&",
      "0022220&002200&0",
      "&002220000000002",
      "&&&0222000&&0v23",
      "&&&0233220&&0v33",
      "0&&0233320&&0223",
      "vvvv233332000222",
      "vvvvvvvvvvvvvvvv",
      "vvvvvvvvvvvvvvvv",
      "vvvvvvvvvvvvvvvv",
      "vvvvvvvvvvvvvvvv"
    ],
    [
      "   $$$   #$$$## ",
      "$$$       ###$$$",
      "             #  ",
      "                ",
      "                ",
      "                ",
      "                ",
      "                ",
      "            ##  ",
      "$$$$$$    $$$$$$",
      "$$$$$$$$$$$$$$$$",
      "$$$$$$$$$$$$$$$$",
      "$$$$$$$$$$$$$$$$",
      "$$$$$$$$$$$$$$$$",
      "$$$$$$$$$$$$$$$$",
      "$$$$$$$$$$$$$$$$"
    ],
    [
      "   $$$   #$$$#  ",
      "$$$       ###$$$",
      "             #  ",
      "                ",
      "                ",
      "                ",
      "                ",
      "                ",
      "                ",
      "     $    $ ##  ",
      "$$$$$$    $$$$$$",
      "           ###  ",
      "#          ##   ",
      "#               ",
      "##              ",
      "#               "
    ],
    [
      "   $$$    $$$###",
      "$$$         #$$$",
      "             ###",
      "                ",
      "                ",
      "                ",
      "                ",
      "                ",
      "                ",
      "     $    $     ",
      "     $    $ #   ",
      "$$$$$$    $$$$$$",
      "#         ####  ",
      "##         ##   ",
      "##              ",
      "#               "
    ],
    [
      "   $$$    $$$# #",
      "$$$         #$$$",
      "             # #",
      "                ",
      "                ",
      "                ",
      "                ",
      "                ",
      "                ",
      "     $    $     ",
      "     $    $     ",
      "     $    $##   ",
      "#$$$$$    $$$$$$",
      "##        ##    ",
      "#               ",
      "                "
    ],
    [
      "   $$$$$$$$$$   ",
      "$$$          $$$",
      "               #",
      "                ",
      "                ",
      "                ",
      "                ",
      "                ",
      "                ",
      "     $$$$$$     ",
      "     $$$$$$     ",
      "     $$$$$$#    ",
      "#$$$$$$$$$$$$$$$",
      "##       ####   ",
      "##        ##    ",
      "                "
    ],
    [
      "   $$$$$$$$$$   ",
      "$$$          $$$",
      "               #",
      "                ",
      "                ",
      "                ",
      "                ",
      "                ",
      "                ",
      "                ",
      "                ",
      "                ",
      "##        ##    ",
      "$$$$$$$$$$$$$$$$",
      "####     ###    ",
      " # #     ##     "
    ],
    [
      "   $$$$$$$$$$   ",
      "$$$          $$$",
      "               #",
      "                ",
      "                ",
      "                ",
      "                ",
      "                ",
      "                ",
      "                ",
      "                ",
      "                ",
      "                ",
      "####      #     ",
      "$$$$$$$$$$$$$$$$",
      " ####   ####    "
    ],
    [
      "   $$$$$$$$$    ",
      "  $           $$",
      "               #",
      "                ",
      "                ",
      "                ",
      "                ",
      "                ",
      "                ",
      "                ",
      "                ",
      "                ",
      "                ",
      "                ",
      " ###     ##     ",
      "$$$$$$$$$$$$$$$$"
    ],
    [
      "   $$$$$$$$     ",
      "  $           $$",
      "                ",
      "                ",
      "                ",
      "                ",
      "                ",
      "                ",
      "                ",
      "                ",
      "                ",
      "                ",
      "                ",
      "                ",
      "   ###   #      ",
      "$$$$$$$$$$$$$$$$"
    ],
    [
      "   $$$$$$$      ",
      "  $           $$",
      "                ",
      "                ",
      "                ",
      "                ",
      "                ",
      "                ",
      "                ",
      "                ",
      "                ",
      "                ",
      "                ",
      "                ",
      "                ",
      "   #### ##      "
    ],
    [
      "                ",
      "                ",
      "                ",
      "                ",
      "                ",
      "                ",
      "                ",
      "                ",
      "                ",
      "                ",
      "                ",
      "                ",
      "                ",
      "                ",
      "                ",
      "                "
    ],
    [
      "                ",
      "                ",
      "                ",
      "                ",
      "                ",
      "                ",
      "                ",
      "                ",
      "                ",
      "                ",
      "                ",
      "                ",
      "                ",
      "                ",
      "                ",
      "                "
    ],
    [
      "                ",
      "                ",
      "                ",
      "                ",
      "                ",
      "                ",
      "                ",
      "                ",
      "                ",
      "                ",
      "                ",
      "                ",
      "                ",
      "                ",
      "                ",
      "                "
    ],
    [
      "                ",
      "                ",
      "                ",
      "                ",
      "                ",
      "                ",
      "                ",
      "                ",
      "                ",
      "                ",
      "                ",
      "                ",
      "                ",
      "                ",
      "                ",
      "                "
    ],
    [
      "                ",
      "                ",
      "                ",
      "                ",
      "                ",
      "                ",
      "                ",
      "                ",
      "                ",
      "                ",
      "                ",
      "                ",
      "                ",
      "                ",
      "                ",
      "                "
    ],
    [
      "                ",
      "                ",
      "                ",
      "                ",
      "                ",
      "                ",
      "                ",
      "                ",
      "                ",
      "                ",
      "                ",
      "                ",
      "                ",
      "                ",
      "                ",
      "                "
    ],
    [
      "                ",
      "                ",
      "                ",
      "                ",
      "                ",
      "                ",
      "                ",
      "                ",
      "                ",
      "                ",
      "                ",
      "                ",
      "                ",
      "                ",
      "                ",
      "                "
    ],
    [
      "                ",
      "                ",
      "                ",
      "                ",
      "                ",
      "                ",
      "                ",
      "                ",
      "                ",
      "                ",
      "                ",
      "                ",
      "                ",
      "                ",
      "                ",
      "                "
    ],
    [
      "                ",
      "                ",
      "                ",
      "                ",
      "                ",
      "                ",
      "                ",
      "                ",
      "                ",
      "                ",
      "                ",
      "                ",
      "                ",
      "                ",
      "                ",
      "                "
    ],
    [
      "                ",
      "                ",
      "                ",
      "                ",
      "                ",
      "                ",
      "                ",
      "                ",
      "                ",
      "                ",
      "                ",
      "                ",
      "                ",
      "                ",
      "                ",
      "                "
    ],
    [
      "                ",
      "                ",
      "                ",
      "                ",
      "                ",
      "                ",
      "                ",
      "                ",
      "                ",
      "                ",
      "                ",
      "                ",
      "                ",
      "                ",
      "                ",
      "                "
    ],
    [
      "                ",
      "                ",
      "                ",
      "                ",
      "                ",
      "                ",
      "                ",
      "                ",
      "                ",
      "                ",
      "                ",
      "                ",
      "                ",
      "                ",
      "                ",
      "                "
    ]
  ]
}