{
  "xsize": 16,
  "zsize": 16,
  "refpalette": "lostcities:scattered",
  "slices": [
    [
      "&&&&&&&&&&&&&$$$",
      "&&&&&&&&&&&&&$$$",
      "&&&&&&&&&&&&&$$$",
      "&&&&&&&&&&&&&$$$",
      "&&&&&&&&&&&&&$$$",
      "&&&&&&&&&&&&&$$$",
      "&&&&&&&&&&&&&$$$",
      "&&&&&&&&&&&&&$$$",
      " ww&&&  j  w&$$$",
      "www      ww  $$$",
      " w   j  j     $$",
      "              $$",
      "     &&       $$",
      "     && j     $$",
      "     &&       $$",
      "     &&       $$"
    ],
    [
      "$$$$$$$$$&&&    ",
      "&&&&&&&&&&&&  j ",
      "     www&&&&j   ",
      "      ww        ",
      "      j       j ",
      "        &&&&    ",
      "&&&&&&&&&&&& m  ",
      "           &    ",
      " w  m           ",
      " w       w      ",
      "               j",
      "                ",
      "               m",
      "                ",
      "                ",
      "     j          "
    ],
    [
      "         &&     ",
      "eeeeeeeee&&     ",
      "      ww        ",
      "                ",
      "                ",
      "         j      ",
      "eeeeee    &  n  ",
      "           j    ",
      "    n           ",
      " w       w      ",
      "                ",
      "                ",
      "               n",
      "                ",
      "                ",
      "                "
    ],
    [
      "         z{     ",
      "         |}     ",
      "       w        ",
      "                ",
      "                ",
      "                ",
      "     j    {     ",
      "                ",
      "  wp            ",
      "pww      w      ",
      "                ",
      "                ",
      "                ",
      "                ",
      "                ",
      "                "
    ],
    [
      "         z{     ",
      "       p |}     ",
      "       w        ",
      "      ww        ",
      "      p         ",
      "                ",
      "  p      z{     ",
      " ppp            ",
      "pwppr           ",
      "pwww    pw      ",
      "rppp     p      ",
      "                ",
      "                ",
      "                ",
      "                ",
      "                "
    ],
    [
      "         z{     ",
      "      ppr|}     ",
      "     pwwp       ",
      "    pppwp       ",
      "     ppwp       ",
      "      r         ",
      " rppr    z{     ",
      " ppup    |}     ",
      "uwwpr    t      ",
      "ppuup    w      ",
      "pwpp            ",
      "rp              ",
      "                ",
      "         rp     ",
      "          ttp   ",
      "         ptup   "
    ],
    [
      "      prrz{     ",
      "      tpp|}     ",
      "    rpwpwp      ",
      "    ppwtp       ",
      "    ptptp       ",
      "    rprp        ",
      "rrpr     z{     ",
      "p wp     |}p    ",
      "wpwpr    ttu    ",
      "pppwp   uwuup   ",
      "rprpr  utpp r   ",
      "qrqr    pr      ",
      "s               ",
      "         r      ",
      "t       rpwupr  ",
      "up      qrpprq  "
    ],
    [
      "     rprqz{     ",
      "    rpwpr|}     ",
      "    r pppr      ",
      "    pwwprq      ",
      "    rppwpr      ",
      " q s  rprq      ",
      " rrqs  rqz{r    ",
      "rpprq  pr|}p    ",
      "puwprqptpwpt    ",
      "ptppr  uw pw    ",
      "rprr    wprpr   ",
      "qrq     t qr    ",
      "        x       ",
      "        sqqrq   ",
      "        qqpprq  ",
      "wup    qrqrrqsx "
    ],
    [
      "     qrrqz{     ",
      "     rppr|}     ",
      "   qrptupr      ",
      "    rpwprq      ",
      "   sqrppr       ",
      "  s sqrr sx     ",
      " qqs  q  z{q    ",
      "qrrq  q r|}rq   ",
      "rpprq rppprpr   ",
      "pwpr qrpwprpq   ",
      "rprq  rpprqqq   ",
      "qr     uwprqsx  ",
      "       ppqq     ",
      "r       xsq ss  ",
      "ptp     xsrrqs  ",
      "pwp    sqsqqsxy "
    ],
    [
      "     sqrqz{     ",
      "     qrpr|}     ",
      "    qrpwpr      ",
      "   sqrppr       ",
      "    sqrrq       ",
      "      q xxy     ",
      " ss     sz{ss   ",
      "qqqs  sqq|}qs   ",
      "r rqssqrrrqr    ",
      "pwpr sqrprqrq   ",
      "rpr   q rqsss   ",
      " r    rppqqxx   ",
      "       rrqsx    ",
      "qr      xsssx   ",
      " pr     xsqqs   ",
      "rpr    xsxssxy  "
    ],
    [
      "      qr z{     ",
      "     qrpr|}     ",
      "    sq wpr      ",
      "    sqrpr       ",
      "     sqr        ",
      "      s  y      ",
      "  x   yxxz{     ",
      "  s   xss|}sx   ",
      "qrqs xs qqsqsx  ",
      "rpr   sqr sqs   ",
      "qrq   sqqsxss   ",
      "      qrrqsxx   ",
      "       qqsy     ",
      "sq        xx    ",
      "qrq     #xssx   ",
      "qrq     xyxxy## "
    ],
    [
      "         z{     ",
      "      qrq|}     ",
      "      rpr       ",
      "    xsqrq       ",
      "      s         ",
      "         ##     ",
      "       yyz{     ",
      " sx   y x|}x    ",
      " qsx  x ssxsx   ",
      " rq   x qsxsxy  ",
      " q    xssxyx    ",
      "      sqqsx#    ",
      "        sx      ",
      "xs        yy    ",
      "sq      #yxxy   ",
      "sqs     y#yyy   "
    ],
    [
      "         z{     ",
      "         |}     ",
      "     sqrq       ",
      "     xsq        ",
      "      x         ",
      "                ",
      "         z{     ",
      "  y     y|}y    ",
      " sx   y xxyxy   ",
      "  s   yxsxyxy   ",
      "       xxy#y    ",
      "        sxy#    ",
      "                ",
      "          #     ",
      "x       ##yy    ",
      "xs       ###    "
    ],
    [
      "         z{     ",
      "         |}     ",
      "      s         ",
      "     yxs        ",
      "                ",
      "                ",
      "         z{     ",
      "         |}     ",
      "        yy#y    ",
      "       yxy#y#   ",
      "       yy###    ",
      "         y #    ",
      "                ",
      "                ",
      "y        ##     ",
      "y        ###    "
    ],
    [
      "         &&     ",
      "         &&     ",
      "                ",
      "                ",
      "                ",
      "                ",
      "         &&     ",
      "         &&     ",
      "        ###     ",
      "       #y###    ",
      "        ####    ",
      "                ",
      "                ",
      "                ",
      "          #     ",
      "#         #     "
    ],
    [
      "&&&&&&&&&&&Ͱ    ",
      "&&&&&&&&&&&Ͱ    ",
      "kkkkkkkkkkk}    ",
      "                ",
      "                ",
      "hhhhhhhhhhh{    ",
      "&&&&&&&&&&&Ͱ    ",
      "&&&&&&&&&&&Ͱ    ",
      "         &&Ͱ    ",
      "        #&&Ͱ    ",
      "         &&Ͱ    ",
      "         &&Ͱ    ",
      "         &&Ͱ    ",
      "         &&Ͱ    ",
      "         &&ͱhhhh",
      "         &&&&&&&"
    ],
    [
      "         zhͰ    ",
      "         ͱͱͰ    ",
      "eeeeeeeeekk}    ",
      "                ",
      "                ",
      "eeeeeeeeehh{    ",
      "         ͲͱͰ    ",
      "         |kͰ    ",
      "           ͳ    ",
      "          #ͳ    ",
      "           ͳ    ",
      "           ͳ    ",
      "           ͳ    ",
      "           ͳ    ",
      "           |eeee",
      "                "
    ],
    [
      "         z{     ",
      "         |}     ",
      "                ",
      "                ",
      "                ",
      "                ",
      "         z{     ",
      "         |}     ",
      "                ",
      "                ",
      "                ",
      "                ",
      "                ",
      "                ",
      "                ",
      "                "
    ],
    [
      "         z{     ",
      "         |}     ",
      "                ",
      "                ",
      "                ",
      "                ",
      "         z{     ",
      "         |}     ",
      "                ",
      "                ",
      "                ",
      "                ",
      "                ",
      "                ",
      "                ",
      "                "
    ],
    [
      "         z{     ",
      "         |}     ",
      "                ",
      "                ",
      "                ",
      "                ",
      "         z{     ",
      "         |}     ",
      "                ",
      "                ",
      "                ",
      "                ",
      "                ",
      "                ",
      "                ",
      "                "
    ],
    [
      "         z{     ",
      "         |}     ",
      "                ",
      "                ",
      "                ",
      "                ",
      "         z{     ",
      "         |}     ",
      "                ",
      "                ",
      "                ",
      "                ",
      "                ",
      "                ",
      "                ",
      "                "
    ],
    [
      "         z{     ",
      "         |}     ",
      "                ",
      "                ",
      "                ",
      "                ",
      "         z{     ",
      "         |}     ",
      "                ",
      "                ",
      "                ",
      "                ",
      "                ",
      "                ",
      "                ",
      "                "
    ],
    [
      "         z{     ",
      "         |}     ",
      "                ",
      "                ",
      "                ",
      "                ",
      "         z{     ",
      "         |}     ",
      "                ",
      "                ",
      "                ",
      "                ",
      "                ",
      "                ",
      "                ",
      "                "
    ],
    [
      "         z{     ",
      "         |}     ",
      "                ",
      "                ",
      "                ",
      "                ",
      "         z{     ",
      "         |}     ",
      "                ",
      "                ",
      "                ",
      "                ",
      "                ",
      "                ",
      "                ",
      "                "
    ],
    [
      "         z{     ",
      "         |}     ",
      "                ",
      "                ",
      "                ",
      "                ",
      "         z{     ",
      "         |}     ",
      "                ",
      "                ",
      "                ",
      "                ",
      "                ",
      "                ",
      "                ",
      "                "
    ],
    [
      "         z{     ",
      "         |}     ",
      "                ",
      "                ",
      "                ",
      "                ",
      "         z{     ",
      "         |}     ",
      "                ",
      "                ",
      "                ",
      "                ",
      "                ",
      "                ",
      "                ",
      "                "
    ],
    [
      "         z{     ",
      "         |}     ",
      "                ",
      "                ",
      "                ",
      "                ",
      "         z{     ",
      "         |}     ",
      "                ",
      "                ",
      "                ",
      "                ",
      "                ",
      "                ",
      "                ",
      "                "
    ],
    [
      "         z{     ",
      "         |}     ",
      "                ",
      "                ",
      "                ",
      "                ",
      "         z{     ",
      "         |}     ",
      "                ",
      "                ",
      "                ",
      "                ",
      "                ",
      "                ",
      "                ",
      "                "
    ],
    [
      "         z{     ",
      "         |}     ",
      "                ",
      "                ",
      "                ",
      "                ",
      "         z{     ",
      "         |}     ",
      "                ",
      "                ",
      "                ",
      "                ",
      "                ",
      "                ",
      "                ",
      "                "
    ],
    [
      "         &&     ",
      "         &&     ",
      "                ",
      "                ",
      "                ",
      "                ",
      "         &&     ",
      "         &&     ",
      "                ",
      "                ",
      "                ",
      "                ",
      "                ",
      "                ",
      "                ",
      "                "
    ],
    [
      "       &&ͱͱ&    ",
      "       &&ͱͱ&    ",
      "        &&&&    ",
      "                ",
      "                ",
      "        &&&&    ",
      "     &&&&ͱͱ&    ",
      "     &&&&ͱͱ&    ",
      "        &&&&    ",
      "         &&     ",
      "         &&     ",
      "         &&     ",
      "         &&     ",
      "         &&     ",
      "         &&     ",
      "         &&     "
    ],
    [
      "        $$$$$$$$",
      "       $$$$$$$$$",
      "       $$$$$$$$$",
      "       $$$$$$$$$",
      "       $$$$$$$$$",
      "      $$$$$$$$$$",
      "      $$$$$$$$$$",
      "      $$$$$$$$$$",
      "      $$$$$$$$$$",
      "        $$$$    ",
      "        $$$$    ",
      "        $$$$    ",
      "        $$$$    ",
      "        $$$$    ",
      "        $$$$    ",
      "        $$$$    "
    ],
    [
      "        llllllll",
      "        llllllll",
      "        llllllll",
      "       lllllllll",
      "       lllllllll",
      "       lllllllll",
      "       lllllllll",
      "      llllllllll",
      "      llllllllll",
      "      llllllllll",
      "      llllllllll",
      "      llllllllll",
      "      llllllllll",
      "     lllllllllll",
      "     lllllllllll",
      "    llllllllllll"
    ],
    [
      "                ",
      "                ",
      "                ",
      "                ",
      "                ",
      "                ",
      "                ",
      "                ",
      "                ",
      "                ",
      "                ",
      "                ",
      "                ",
      "                ",
      "                ",
      "                "
    ],
    [
      "                ",
      "                ",
      "                ",
      "                ",
      "                ",
      "                ",
      "                ",
      "                ",
      "                ",
      "                ",
      "                ",
      "                ",
      "                ",
      "                ",
      "                ",
      "                "
    ],
    [
      "                ",
      "                ",
      "                ",
      "                ",
      "                ",
      "                ",
      "                ",
      "                ",
      "                ",
      "                ",
      "                ",
      "                ",
      "                ",
      "                ",
      "                ",
      "                "
    ]
  ]
}