{
  "xsize": 16,
  "zsize": 16,
  "refpalette": "lostcities:scattered",
  "slices": [
    [
      "                ",
      "            $ $ ",
      "             $  ",
      "            $ $ ",
      "                ",
      "                ",
      "                ",
      "                ",
      "                ",
      "                ",
      "                ",
      "                ",
      "                ",
      "                ",
      "                ",
      "                "
    ],
    [
      "33320&00vvvvvvvv",
      "333222223vvvvvvv",
      "3332233333vvvvvv",
      "332233 333vvvvvv",
      "222233333333vvvv",
      "0002232222233vvv",
      "&&002200002222vv",
      "&&&&00&&&&00220v",
      "&&&&&&&vv&&000&&",
      "&&vvvvvvvv&00000",
      "&&vvvvvvv&&00222",
      "&&vvv&&&&&002222",
      "&vvvv&&&&0022233",
      "vvvv&&&000222233",
      "&&&&&&0000222223",
      "&&&0000000000223"
    ],
    [
      "                ",
      "                ",
      "                ",
      "                ",
      "                ",
      "                ",
      "                ",
      "                ",
      "    #           ",
      "    #           ",
      "     #          ",
      "           !!   ",
      "           !!   ",
      "                ",
      ".               ",
      ".               "
    ],
    [
      "                ",
      "                ",
      "                ",
      "                ",
      "                ",
      "                ",
      "                ",
      "                ",
      "                ",
      "    #           ",
      "                ",
      "           !!   ",
      "           !!   ",
      "                ",
      "A               ",
      "A               "
    ],
    [
      "                ",
      "                ",
      "                ",
      "                ",
      "                ",
      "                ",
      "                ",
      "                ",
      "                ",
      "    #           ",
      "                ",
      "           !!   ",
      "           !!   ",
      "                ",
      "X               ",
      "X               "
    ],
    [
      "                ",
      "                ",
      "                ",
      "                ",
      "                ",
      "                ",
      "                ",
      "                ",
      "                ",
      "    #           ",
      "                ",
      "           !!   ",
      "           !!   ",
      "                ",
      ".               ",
      ".               "
    ],
    [
      "                ",
      "                ",
      "                ",
      "                ",
      "                ",
      "                ",
      "                ",
      "                ",
      "                ",
      "    #           ",
      "                ",
      "           !!   ",
      "           !!   ",
      "                ",
      "                ",
      "                "
    ],
    [
      "                ",
      "                ",
      "                ",
      "                ",
      "                ",
      "                ",
      "                ",
      "                ",
      "                ",
      "    ##          ",
      "                ",
      "           !!   ",
      "           !!   ",
      "                ",
      "                ",
      "                "
    ],
    [
      "                ",
      "                ",
      "                ",
      "                ",
      "                ",
      "                ",
      "                ",
      "                ",
      "                ",
      "     #          ",
      "                ",
      "           !!   ",
      "           !!   ",
      "                ",
      "                ",
      "                "
    ],
    [
      "                ",
      "                ",
      "                ",
      "                ",
      "                ",
      "                ",
      "                ",
      "                ",
      "     #          ",
      "^   ^^^^^^^^^^^ ",
      "^^ ^^^^^^^^^^^^ ",
      "^^^^^^^^^^^^^^^ ",
      "^^^^^^^^^^^^^^^ ",
      "^^^^^^^^^^^^^^^ ",
      "^^^^^^^^^^^^^^^ ",
      "^^^^^^^^^^^^^^^ "
    ],
    [
      "                ",
      "                ",
      "                ",
      "                ",
      "                ",
      "                ",
      "                ",
      "                ",
      "                ",
      "     #          ",
      "!   !!!!!!!!!!  ",
      "!!!!!!!!!!!!!!  ",
      "!!!!!!!!!!!!!!  ",
      "!!!!!!!!!!!!!!  ",
      "!!!!!!!!!!!!!!  ",
      "!!!!!!!!##  !!  "
    ],
    [
      "                ",
      "                ",
      "                ",
      "                ",
      "                ",
      "                ",
      "                ",
      "                ",
      "                ",
      "     #          ",
      "     #          ",
      " ##'        '   ",
      "  ###           ",
      "    ###         ",
      "      ###       ",
      "                "
    ],
    [
      "                ",
      "                ",
      "                ",
      "                ",
      "                ",
      "                ",
      "                ",
      "                ",
      "                ",
      "                ",
      "     #          ",
      "^^^^^^^  ^^^^^  ",
      "  #             ",
      "                ",
      "                ",
      "                "
    ],
    [
      "                ",
      "                ",
      "                ",
      "                ",
      "                ",
      "                ",
      "                ",
      "                ",
      "                ",
      "                ",
      "   ##           ",
      "^^^^^^^^^^^^^^  ",
      "  #             ",
      "                ",
      "                ",
      "                "
    ],
    [
      "                ",
      "                ",
      "                ",
      "                ",
      "                ",
      "                ",
      "                ",
      "                ",
      "                ",
      "                ",
      "  ##            ",
      "^^^^^^^^^^^^^^  ",
      " ##             ",
      "                ",
      "                ",
      "                "
    ],
    [
      "                ",
      "                ",
      "                ",
      "                ",
      "                ",
      "                ",
      "                ",
      "                ",
      "                ",
      "                ",
      "# #             ",
      "^^^^^^^^^^^^^^  ",
      " #              ",
      "                ",
      "                ",
      "                "
    ],
    [
      "                ",
      "                ",
      "                ",
      "                ",
      "                ",
      "                ",
      "                ",
      "                ",
      "                ",
      " #              ",
      "##              ",
      "^^^^^^^^^^^^^^  ",
      "##              ",
      "#               ",
      "                ",
      "                "
    ],
    [
      "                ",
      "                ",
      "                ",
      "                ",
      "                ",
      "                ",
      "                ",
      "                ",
      "                ",
      "                ",
      "##              ",
      "^^^^^^^^^^^     ",
      " #              ",
      "                ",
      "                ",
      "                "
    ]
  ]
}