{
  "xsize": 16,
  "zsize": 16,
  "refpalette": "lostcities:scattered",
  "slices": [
    [
      "                ",
      "                ",
      "                ",
      "                ",
      "                ",
      "                ",
      "                ",
      "                ",
      "                ",
      "                ",
      "                ",
      "                ",
      "       $ $      ",
      "        $       ",
      "       $ $      ",
      "                "
    ],
    [
      "vvvvvvvvv3333333",
      "vvvvvvvvv3333332",
      "vvvvvvvvvv333322",
      "vvvvvvvvvvv3332v",
      "vvvvvvvvvvvvvvvv",
      "vvvvvvvvvvvvvvvv",
      "vvvvvvvvvvvvvvvv",
      "vvvvvvvvvvvvvvvv",
      "vvvvvvvvvvvvvvvv",
      "vvvvvvvvvvvvvvvv",
      "vvv&000&&&&vvv&&",
      "vv&&00&&&00&vv&&",
      "v&&00&&v0v00&&&0",
      "&&0200&&02220000",
      "&02220&&02222222",
      "022220&&02223333"
    ],
    [
      "((((((((((((((  ",
      "!!!!!!!!!!!!!(  ",
      "!!!!!!!!!!!!!(  ",
      "!!!!!!!!!!!!!(  ",
      "!!!!!!!!!!!!!(  ",
      "!!!!!!!!!!!!!(  ",
      "!!!!!!!!!!!!!(  ",
      "!!!!!!!!!!!!!(  ",
      "!!!!!!!!!!!!!(  ",
      "!!!!!!!!!!!!!(  ",
      "!!!!!!!!!!!!!(  ",
      "!!!!!!!!!!!!!(  ",
      "(((((((((((((   ",
      "                ",
      "                ",
      "                "
    ],
    [
      "                ",
      "  J&JJJJJJJJ&   ",
      "     ##     !   ",
      "            !   ",
      "            !   ",
      "            !   ",
      "            !   ",
      "            !   ",
      "           #!   ",
      "           #!   ",
      "  #        #!   ",
      "JJJJ&JJJJJJJ&   ",
      "                ",
      "                ",
      "                ",
      "                "
    ],
    [
      "                ",
      "  J&JJJJJJJJ&   ",
      "      ##    !   ",
      "            J   ",
      "            J   ",
      "            J   ",
      "            !   ",
      "            J   ",
      "            J   ",
      "            J   ",
      "# #       ##!   ",
      "JJJJ&JJJJJJJ&   ",
      "                ",
      "                ",
      "                ",
      "                "
    ],
    [
      "                ",
      "  J&JJJJJJJJ&   ",
      "       #    !   ",
      "            J   ",
      "            J   ",
      "            J   ",
      "            !   ",
      "            J   ",
      "            J   ",
      "            J   ",
      "###       # !   ",
      "JJJJ&JJJJJJJ&   ",
      "                ",
      "                ",
      "                ",
      "                "
    ],
    [
      "                ",
      "&&&&JJJJJJJJ&   ",
      "       ##   !   ",
      "            J   ",
      "            J   ",
      "            J   ",
      "            !   ",
      "            J   ",
      "            J   ",
      "            J   ",
      " ##      #  !   ",
      "&&#&&JJJJJJJ&   ",
      "                ",
      "                ",
      "                ",
      "                "
    ],
    [
      "                ",
      "JJJ&JJJJJJJJ    ",
      "        #       ",
      "                ",
      "            !   ",
      "            !   ",
      "            !   ",
      "            !   ",
      "            !   ",
      "            !   ",
      "  #      #  !   ",
      "J    JJJJJJJ&   ",
      "                ",
      "                ",
      "                ",
      "                "
    ],
    [
      "                ",
      "%%%&%%%%%%      ",
      "         #      ",
      "                ",
      "                ",
      "            %   ",
      "            %   ",
      "            %   ",
      "            %   ",
      "            %   ",
      "  #      #  %   ",
      "%     %%%%%%&   ",
      "                ",
      "                ",
      "                ",
      "                "
    ],
    [
      "                ",
      "   &            ",
      "!!!!!!!!!!      ",
      "!!!!!!!!!!      ",
      "!!!!!!!!!!!     ",
      "!!!!!!!!!!!!    ",
      "!!!!!!!!!!!!    ",
      "!!!!!!!!!!!!    ",
      "!!!!!!!!!!!!    ",
      "!    !!!!!!!    ",
      "! #   !!!!!!    ",
      "            &   ",
      "                ",
      "                ",
      "                ",
      "                "
    ],
    [
      "                ",
      "^^^^^^^^^^      ",
      "^^^^^^^^^^      ",
      "^^^^^^^^^^^     ",
      "^^^^^^^^^^^^^   ",
      "^^^^^^^^^^^^^   ",
      "^^^^^^^^^^^^^   ",
      "^^^^^^^^^^^^^   ",
      "^^^^^^^^^^^^^   ",
      "^^^^^^^^^^^^^   ",
      "^^#   ^^^^^^^   ",
      "^     ^^^^^^^   ",
      "                ",
      "                ",
      "                ",
      "                "
    ],
    [
      "                ",
      "                ",
      "                ",
      "                ",
      "                ",
      "#               ",
      "##              ",
      " #              ",
      " #              ",
      " ##             ",
      "                ",
      "                ",
      "                ",
      "                ",
      "                ",
      "                "
    ],
    [
      "                ",
      "                ",
      "                ",
      "                ",
      "                ",
      "                ",
      "                ",
      "                ",
      "                ",
      "                ",
      "                ",
      "                ",
      "                ",
      "                ",
      "                ",
      "                "
    ],
    [
      "                ",
      "                ",
      "                ",
      "                ",
      "                ",
      "                ",
      "                ",
      "                ",
      "                ",
      "                ",
      "                ",
      "                ",
      "                ",
      "                ",
      "                ",
      "                "
    ],
    [
      "                ",
      "                ",
      "                ",
      "                ",
      "                ",
      "                ",
      "                ",
      "                ",
      "                ",
      "                ",
      "                ",
      "                ",
      "                ",
      "                ",
      "                ",
      "                "
    ],
    [
      "                ",
      "                ",
      "                ",
      "                ",
      "                ",
      "                ",
      "                ",
      "                ",
      "                ",
      "                ",
      "                ",
      "                ",
      "                ",
      "                ",
      "                ",
      "                "
    ],
    [
      "                ",
      "                ",
      "                ",
      "                ",
      "                ",
      "                ",
      "                ",
      "                ",
      "                ",
      "                ",
      "                ",
      "                ",
      "                ",
      "                ",
      "                ",
      "                "
    ],
    [
      "                ",
      "                ",
      "                ",
      "                ",
      "                ",
      "                ",
      "                ",
      "                ",
      "                ",
      "                ",
      "                ",
      "                ",
      "                ",
      "                ",
      "                ",
      "                "
    ]
  ]
}