{
  "xsize": 16,
  "zsize": 16,
  "refpalette": "lostcities:scattered",
  "slices": [
    [
      "                ",
      "                ",
      "                ",
      "                ",
      "                ",
      "                ",
      "      $  $      ",
      "       $$       ",
      "       $$       ",
      "      $  $      ",
      "                ",
      "                ",
      "                ",
      "                ",
      "                ",
      "                "
    ],
    [
      "&&0233333320vvvv",
      "&&0233333322&vvv",
      "&&02333322220vvv",
      "0022222222220&vv",
      "222200000000&&vv",
      "22220&&&&&&0&&&&",
      "33220&&&&&&&0000",
      "322000&v&&&0022v",
      "2200000v&&&0223v",
      "00&002v20&&0233v",
      "0&&&02220&&0233v",
      "00&002220&&0223v",
      "200022200&&0002v",
      "2222222200000&&v",
      "v333332222200&&v",
      "vv33333222220&&v"
    ],
    [
      "    .        #..",
      "   .        #.. ",
      "...          .  ",
      "            .   ",
      "            .   ",
      "           .    ",
      "           .    ",
      "........   .    ",
      "       .   .    ",
      "........   .    ",
      "           .    ",
      "           .    ",
      "            .   ",
      "            .   ",
      "             .  ",
      "             .. "
    ],
    [
      "    .        #..",
      "   .        #.. ",
      "...          .  ",
      "            .   ",
      "            .   ",
      "           .    ",
      "           .    ",
      "           .    ",
      "           .    ",
      "           .    ",
      "           .    ",
      "           .    ",
      "            .   ",
      "            .   ",
      "             .  ",
      "             .. "
    ],
    [
      "    .        #..",
      "   .        #.. ",
      "...          .  ",
      "            .   ",
      "            .   ",
      "           .    ",
      "           .    ",
      "           .    ",
      "           .    ",
      "           .    ",
      "           .    ",
      "           .    ",
      "            .   ",
      "            .   ",
      "             .  ",
      "             .. "
    ],
    [
      "    .        #..",
      "   ..       #.. ",
      "....         .  ",
      "...         .   ",
      "            .   ",
      "           .    ",
      "           .    ",
      "           .    ",
      "           .    ",
      "           .    ",
      "           .    ",
      "           .    ",
      "            .   ",
      "            .   ",
      "             .  ",
      "             .. "
    ],
    [
      "    .        #..",
      "   .        #..#",
      "...          .# ",
      "            .   ",
      "            .   ",
      "           .    ",
      "           .    ",
      "           .    ",
      "           .    ",
      "           .    ",
      "           .    ",
      "           .    ",
      "            .   ",
      "            .   ",
      "             .  ",
      "             .. "
    ],
    [
      "    .        #..",
      "   .         .. ",
      "...          .  ",
      "            .   ",
      "            .   ",
      "           .    ",
      "           .    ",
      "           .    ",
      "           .    ",
      "           .    ",
      "           .    ",
      "           .    ",
      "            .   ",
      "            .   ",
      "             .  ",
      "             .. "
    ],
    [
      "    .        #..",
      "   .         .. ",
      "...          .  ",
      "            .   ",
      "            .   ",
      "           .    ",
      "           .    ",
      "           .    ",
      "           .    ",
      "           .    ",
      "           .    ",
      "           .    ",
      "            .   ",
      "            .   ",
      "             .  ",
      "             .. "
    ],
    [
      "    .        #..",
      "   .         .. ",
      "...          .  ",
      "            .   ",
      "            .   ",
      "           .    ",
      "           .    ",
      "           .    ",
      "           .    ",
      "           .    ",
      "           .    ",
      "           .    ",
      "            .   ",
      "            .   ",
      "             .  ",
      "             .. "
    ],
    [
      "    .        #..",
      "   .         ...",
      "...          ...",
      "            ....",
      "            ....",
      "           .....",
      "           .....",
      "           .....",
      "           .....",
      "           .....",
      "           .....",
      "           .....",
      "            ....",
      "            ....",
      "             ...",
      "             ..."
    ],
    [
      "    .        #..",
      "   .         .. ",
      "...          .  ",
      "            .   ",
      "            .   ",
      "           .    ",
      "           .    ",
      "           .    ",
      "           .    ",
      "           .    ",
      "           .    ",
      "           .    ",
      "            .   ",
      "            .   ",
      "             .  ",
      "             .. "
    ],
    [
      "    .        #..",
      "   .         ..#",
      "...          .  ",
      "            .   ",
      "            .   ",
      "           .    ",
      "           .    ",
      "           .    ",
      "           .    ",
      "           .    ",
      "           .    ",
      "           .    ",
      "            .   ",
      "            .   ",
      "             .  ",
      "             .. "
    ],
    [
      "    .         ..",
      "   .         .. ",
      "...          .  ",
      "            .   ",
      "            .   ",
      "           .    ",
      "           .    ",
      "           .    ",
      "           .    ",
      "           .    ",
      "           .    ",
      "           .    ",
      "            .   ",
      "            .   ",
      "             .  ",
      "             .. "
    ],
    [
      "    .         ..",
      "   .         .. ",
      "...          .  ",
      "            .  #",
      "            .   ",
      "           .    ",
      "           .    ",
      "           .    ",
      "           .    ",
      "           .    ",
      "           .    ",
      "           .    ",
      "            .   ",
      "            .   ",
      "             .  ",
      "             .. "
    ],
    [
      "    .         ..",
      "   ..        .. ",
      "....         .  ",
      "...         .  #",
      "            .   ",
      "           .    ",
      "           .    ",
      "           .    ",
      "           .    ",
      "           .    ",
      "           .    ",
      "           .    ",
      "            .   ",
      "            .   ",
      "             .  ",
      "             .. "
    ],
    [
      "    .       $$..",
      "   .       $$.. ",
      "...       $$$.  ",
      "          $$.  #",
      "          $$.   ",
      "         $$.    ",
      "         $$.    ",
      "         $$.    ",
      "         $$.    ",
      "         $$.    ",
      "         $$.    ",
      "         $$.    ",
      "          $$.   ",
      "          $$.   ",
      "          $$$.  ",
      "           $$.. "
    ],
    [
      "    .         ..",
      "   .         .. ",
      "...          .  ",
      "            .  #",
      "            .   ",
      "           .    ",
      "           .    ",
      "           .    ",
      "           .    ",
      "           .    ",
      "           .    ",
      "           .    ",
      "            .   ",
      "            .   ",
      "             .  ",
      "             .. "
    ],
    [
      "    .         ..",
      "   .         .. ",
      "...          .  ",
      "            .  #",
      "            .   ",
      "           .    ",
      "           .    ",
      "           .    ",
      "           .    ",
      "           .    ",
      "           .    ",
      "           .    ",
      "            .   ",
      "            .   ",
      "             .  ",
      "             .. "
    ],
    [
      "    .        #..",
      "   .         .. ",
      "...          . #",
      "            .  #",
      "            .   ",
      "           .    ",
      "           .    ",
      "           .    ",
      "           .    ",
      "           .    ",
      "           .    ",
      "           .    ",
      "            .   ",
      "            .   ",
      "             .  ",
      "             .. "
    ],
    [
      "    .         ..",
      "   .         .. ",
      "...          . #",
      "            .   ",
      "            .   ",
      "           .    ",
      "           .    ",
      "           .    ",
      "           .    ",
      "           .    ",
      "           .    ",
      "           .    ",
      "            .   ",
      "            .   ",
      "             .  ",
      "             .. "
    ],
    [
      "    .       $$..",
      "   .       $$.. ",
      "...       $$$. #",
      "          $$.   ",
      "          $$.   ",
      "         $$.    ",
      "         $$.    ",
      "         $$.    ",
      "         $$.    ",
      "         $$.    ",
      "         $$.    ",
      "         $$.    ",
      "          $$.   ",
      "          $$.   ",
      "          $$$.  ",
      "           $$.. "
    ],
    [
      "    .        #..",
      "   .         .. ",
      "...          . #",
      "            .   ",
      "            .   ",
      "           .    ",
      "           .    ",
      "           .    ",
      "           .    ",
      "           .    ",
      "           .    ",
      "           .    ",
      "            .   ",
      "            .   ",
      "             .  ",
      "             .. "
    ],
    [
      "    .        #..",
      "   .         ..#",
      "...          .##",
      "            .  #",
      "            .   ",
      "           .    ",
      "           .    ",
      "           .    ",
      "           .    ",
      "           .    ",
      "           .    ",
      "           .    ",
      "            .   ",
      "            .   ",
      "             .  ",
      "             .. "
    ],
    [
      "  ...  .     #..",
      "  ..   .     ...",
      "...    .     ...",
      "       .    ....",
      "       .    ....",
      "       .   .....",
      "       .   .....",
      "       .   .....",
      "       .   .....",
      "       .   .....",
      "       .   .....",
      "       .   .....",
      "       .    ....",
      "       .    ....",
      "       .     ...",
      "       .     ..."
    ],
    [
      "    .        #..",
      "   ..        ..#",
      "....         . #",
      "...         .   ",
      "            .   ",
      "           .    ",
      "           .    ",
      "           .    ",
      "           .    ",
      "           .    ",
      "           .    ",
      "           .    ",
      "            .   ",
      "            .   ",
      "             .  ",
      "             .. "
    ],
    [
      "    .        #..",
      "   .         ..#",
      "...          . #",
      "            .   ",
      "            .   ",
      "           .    ",
      "           .    ",
      "           .    ",
      "           .    ",
      "           .    ",
      "           .    ",
      "           .    ",
      "            .   ",
      "            .   ",
      "             .  ",
      "             .. "
    ],
    [
      "    .        #..",
      "   .         ..#",
      "...          . #",
      "            .   ",
      "            .   ",
      "           .    ",
      "           .    ",
      "           .    ",
      "           .    ",
      "           .    ",
      "           .    ",
      "           .    ",
      "            .   ",
      "            .   ",
      "             .  ",
      "             .. "
    ],
    [
      "    .         ..",
      "   .         ..#",
      "...          . #",
      "            .   ",
      "            .   ",
      "           .    ",
      "           .    ",
      "           .    ",
      "           .    ",
      "           .    ",
      "           .    ",
      "           .    ",
      "            .   ",
      "            .   ",
      "             .  ",
      "             .. "
    ],
    [
      "    .         #.",
      "   .         ..#",
      "...          .  ",
      "            .   ",
      "            .   ",
      "           .    ",
      "           .    ",
      "           .    ",
      "           .    ",
      "           .    ",
      "           .    ",
      "           .    ",
      "            .   ",
      "            .   ",
      "             .  ",
      "             .. "
    ],
    [
      "    .          #",
      "   .            ",
      "...             ",
      "            .   ",
      "            .   ",
      "           .    ",
      "           .    ",
      "           .    ",
      "           .    ",
      "           .    ",
      "           .    ",
      "           .    ",
      "            .   ",
      "            .   ",
      "             .  ",
      "             .. "
    ],
    [
      "    .           ",
      "   .            ",
      "...             ",
      "            .   ",
      "            .   ",
      "           .    ",
      "           .    ",
      "           .    ",
      "           .    ",
      "           .    ",
      "           .    ",
      "           .    ",
      "            .   ",
      "            .   ",
      "             .  ",
      "             .. "
    ],
    [
      "    .           ",
      "   .            ",
      "...       $$    ",
      "          $$.   ",
      "          $$.   ",
      "         $$.    ",
      "         $$.    ",
      "         $$.    ",
      "         $$.    ",
      "         $$.    ",
      "         $$.    ",
      "         $$.    ",
      "          $$.   ",
      "          $$.   ",
      "          $$$.  ",
      "           $$.. "
    ],
    [
      "    .           ",
      "   .            ",
      "...             ",
      "                ",
      "            .   ",
      "          ..    ",
      "           .    ",
      "           .    ",
      "           .    ",
      "           .    ",
      "           .    ",
      "          ..    ",
      "            .   ",
      "            .   ",
      "             .  ",
      "             .. "
    ],
    [
      "    .           ",
      "   .            ",
      "...             ",
      "                ",
      "            .   ",
      "          ..    ",
      "           .    ",
      "           .    ",
      "           .    ",
      "           .    ",
      "           .    ",
      "          ..    ",
      "            .   ",
      "            .   ",
      "             .  ",
      "             .. "
    ],
    [
      "    .           ",
      "   .            ",
      "...             ",
      "                ",
      "             ///",
      "          . ////",
      "            ////",
      "            ////",
      "            ////",
      "            ////",
      "            ////",
      "          . ////",
      "             ///",
      "             ///",
      "              //",
      "               /"
    ],
    [
      "    .           ",
      "   ..           ",
      "....      $$    ",
      "...       $$    ",
      "          $$  / ",
      "         $$   / ",
      "         $$  /  ",
      "         $$  /  ",
      "         $$  /  ",
      "         $$  /  ",
      "         $$  /  ",
      "         $$   / ",
      "          $$  / ",
      "          $$  //",
      "          $$$  /",
      "           $$   "
    ],
    [
      "    .           ",
      "   .            ",
      "...             ",
      "                ",
      "               /",
      "               /",
      "              / ",
      "              / ",
      "              / ",
      "              / ",
      "              / ",
      "               /",
      "               /",
      "                ",
      "                ",
      "                "
    ],
    [
      "    .           ",
      "   .            ",
      "...             ",
      "                ",
      "                ",
      "                ",
      "               /",
      "               /",
      "               /",
      "               /",
      "               /",
      "                ",
      "                ",
      "                ",
      "                ",
      "                "
    ],
    [
      "    .           ",
      "   .            ",
      "...             ",
      "                ",
      "                ",
      "                ",
      "                ",
      "                ",
      "                ",
      "                ",
      "                ",
      "                ",
      "                ",
      "                ",
      "                ",
      "                "
    ],
    [
      "#   .           ",
      "#  .            ",
      "...             ",
      "                ",
      "                ",
      "                ",
      "                ",
      "                ",
      "                ",
      "                ",
      "                ",
      "                ",
      "                ",
      "                ",
      "                ",
      "                "
    ],
    [
      "#   .           ",
      "## .            ",
      "...             ",
      "#               ",
      "                ",
      "                ",
      "                ",
      "                ",
      "                ",
      "                ",
      "                ",
      "                ",
      "                ",
      "                ",
      "                ",
      "                "
    ],
    [
      "    .           ",
      "#  .            ",
      "...             ",
      "#               ",
      "                ",
      "                ",
      "                ",
      "                ",
      "                ",
      "                ",
      "                ",
      "                ",
      "                ",
      "                ",
      "                ",
      "                "
    ],
    [
      "    .           ",
      "   .            ",
      "...             ",
      "                ",
      "                ",
      "                ",
      "                ",
      "                ",
      "                ",
      "                ",
      "                ",
      "                ",
      "                ",
      "                ",
      "                ",
      "                "
    ],
    [
      "    .           ",
      "   .            ",
      "...             ",
      "                ",
      "                ",
      "                ",
      "                ",
      "                ",
      "                ",
      "                ",
      "                ",
      "                ",
      "                ",
      "                ",
      "                ",
      "                "
    ],
    [
      "                ",
      "                ",
      "                ",
      "                ",
      "                ",
      "                ",
      "                ",
      "                ",
      "                ",
      "                ",
      "                ",
      "                ",
      "                ",
      "                ",
      "                ",
      "                "
    ],
    [
      "                ",
      "                ",
      "                ",
      "                ",
      "                ",
      "                ",
      "                ",
      "                ",
      "                ",
      "                ",
      "                ",
      "                ",
      "                ",
      "                ",
      "                ",
      "                "
    ],
    [
      "                ",
      "                ",
      "                ",
      "                ",
      "                ",
      "                ",
      "                ",
      "                ",
      "                ",
      "                ",
      "                ",
      "                ",
      "                ",
      "                ",
      "                ",
      "                "
    ]
  ]
}