{
  "xsize": 16,
  "zsize": 16,
  "refpalette": "lostcities:scattered",
  "slices": [
    [
      "                ",
      " %%             ",
      " %%             ",
      "                ",
      "                ",
      "       #        ",
      "       #        ",
      "                ",
      "     $$         ",
      "    $$$$        ",
      "    $$$$        ",
      "     $$         ",
      "                ",
      "             %% ",
      "             %% ",
      "                "
    ],
    [
      "  v&&&   332&vvv",
      " %%&&v   220&&vv",
      " %%0&vv&0020&&&0",
      "   &&vv&&00&&&02",
      "    vvv&&&&&&&00",
      "    vvvv&&vv&&00",
      "     vvv&vvvv&0&",
      "      vvvvvv&00&",
      "     $$&&&&&0220",
      "    $$$$00023320",
      "    $$$$ 333332&",
      "     $$   33330&",
      "            320&",
      "             %%&",
      "             %% ",
      "                "
    ],
    [
      "  $       $$$$$$",
      " %%       $$$$$$",
      " %%$      $$$$$$",
      "   $     $$$$$$$",
      "    $    $$$$$$$",
      "    $ ## $$$$$$$",
      "     $###$$$$$$$",
      "     #$#        ",
      "     $$$        ",
      "    $$$$$       ",
      "    $$$$ $      ",
      "     $$   $$    ",
      "            $$  ",
      "             %%$",
      "             %% ",
      "                "
    ],
    [
      "  $       $     ",
      " %%       $     ",
      " %%$      $     ",
      "   $      $     ",
      "    $     $     ",
      "    $     $$$$$$",
      "     $##        ",
      "     #$#        ",
      "     $$$        ",
      "    $$$$$       ",
      "    $$$$ $      ",
      "     $$   $$    ",
      "            $$  ",
      "             %%$",
      "             %% ",
      "                "
    ],
    [
      "  $        $    ",
      " %%        $    ",
      " %%$       $    ",
      "   $       $    ",
      "    $      $$$$$",
      "    $           ",
      "     $#         ",
      "     #$#        ",
      "     $$$        ",
      "    $$$$$       ",
      "    $$$$ $      ",
      "     $$   $$    ",
      "            $$  ",
      "             %%$",
      "             %% ",
      "                "
    ],
    [
      "  $         $   ",
      " %%         $   ",
      " %%$        $   ",
      "   $        $$$$",
      "    $           ",
      "    $           ",
      "     $#         ",
      "     #$#        ",
      "     $$$        ",
      "    $$$$$       ",
      "    $$$$ $      ",
      "     $$   $$    ",
      "            $$  ",
      "             %%$",
      "             %% ",
      "                "
    ],
    [
      "  $         $   ",
      " %%         $   ",
      " %%         $   ",
      "            $$$$",
      "                ",
      "    $           ",
      "     $#         ",
      "     #$#        ",
      "     $$$        ",
      "    $$$$$       ",
      "    $$$$ $      ",
      "     $$   $$    ",
      "            $$  ",
      "             %%$",
      "             %% ",
      "                "
    ],
    [
      "  $          $  ",
      " %%          $  ",
      " %%          $$$",
      "                ",
      "                ",
      "                ",
      "      #         ",
      "     #$#        ",
      "     $$$        ",
      "    $$$$$       ",
      "    $$$$ $      ",
      "     $$   $$    ",
      "            $$  ",
      "             %%$",
      "             %% ",
      "                "
    ],
    [
      "  $           $ ",
      " %%           $$",
      " %%             ",
      "                ",
      "                ",
      "                ",
      "      #         ",
      "     ###        ",
      "     $$#        ",
      "    $$$$        ",
      "    $$$$        ",
      "     $$    $    ",
      "            $$  ",
      "             %%$",
      "             %% ",
      "                "
    ],
    [
      "  $            $",
      " %%            #",
      " %%$            ",
      "   $            ",
      "                ",
      "                ",
      "                ",
      "     ##         ",
      "    #$##        ",
      "    $$$$        ",
      "    $$$$        ",
      "     $$         ",
      "             $  ",
      "             %%$",
      "             %% ",
      "                "
    ],
    [
      "  $           #$",
      " %%            #",
      " %%$            ",
      "   $            ",
      "    $           ",
      "                ",
      "                ",
      "     #          ",
      "    #$#         ",
      "    $$$         ",
      "    $$$$        ",
      "     $$         ",
      "                ",
      "              %$",
      "             %% ",
      "                "
    ],
    [
      "  $            #",
      " %%             ",
      " %%$            ",
      "   $            ",
      "    $           ",
      "    $           ",
      "                ",
      "     ##         ",
      "    #$##        ",
      "    $$$#        ",
      "    $$$         ",
      "     $$         ",
      "                ",
      "               $",
      "              % ",
      "                "
    ],
    [
      "                ",
      " %%             ",
      " %%             ",
      "                ",
      "                ",
      "                ",
      "                ",
      "                ",
      "     $#         ",
      "    $$$#        ",
      "    $$$         ",
      "     $$         ",
      "                ",
      "                ",
      "                ",
      "                "
    ],
    [
      "                ",
      " %%             ",
      " %%             ",
      "                ",
      "                ",
      "                ",
      "                ",
      "                ",
      "     $#         ",
      "    $$$#        ",
      "    $$$         ",
      "     $          ",
      "                ",
      "                ",
      "                ",
      "                "
    ],
    [
      "                ",
      "                ",
      "                ",
      "                ",
      "                ",
      "                ",
      "                ",
      "      #         ",
      "     $$#        ",
      "    $$$#        ",
      "    $$$         ",
      "     $          ",
      "                ",
      "                ",
      "                ",
      "                "
    ],
    [
      "                ",
      "                ",
      "                ",
      "                ",
      "                ",
      "                ",
      "                ",
      "      #         ",
      "     $$#        ",
      "    $$$         ",
      "    $$$         ",
      "     $          ",
      "                ",
      "                ",
      "                ",
      "                "
    ],
    [
      "                ",
      "                ",
      "                ",
      "                ",
      "                ",
      "                ",
      "                ",
      "      #         ",
      "     $$#        ",
      "    $$$$        ",
      "    $$$$        ",
      "     $$         ",
      "                ",
      "                ",
      "                ",
      "                "
    ],
    [
      "                ",
      "                ",
      "                ",
      "                ",
      "                ",
      "                ",
      "                ",
      "                ",
      "     $$         ",
      "    $$$$        ",
      "    $$$$        ",
      "     $$         ",
      "                ",
      "                ",
      "                ",
      "                "
    ],
    [
      "                ",
      "                ",
      "                ",
      "                ",
      "                ",
      "                ",
      "                ",
      "     $$         ",
      "    $$$$        ",
      "   $$$$$$       ",
      "   $$$$$$       ",
      "    $$$$        ",
      "     $$         ",
      "                ",
      "                ",
      "                "
    ],
    [
      "                ",
      "                ",
      "                ",
      "                ",
      "                ",
      "                ",
      "                ",
      "                ",
      "    $$$$        ",
      "    $$$$        ",
      "    $$$$        ",
      "    $$$$        ",
      "                ",
      "                ",
      "                ",
      "                "
    ],
    [
      "                ",
      "                ",
      "                ",
      "                ",
      "                ",
      "                ",
      "                ",
      "                ",
      "    $  $        ",
      "                ",
      "                ",
      "    $  $        ",
      "                ",
      "                ",
      "                ",
      "                "
    ],
    [
      "                ",
      "                ",
      "                ",
      "                ",
      "                ",
      "                ",
      "                ",
      "                ",
      "    $  $        ",
      "                ",
      "                ",
      "    $  $        ",
      "                ",
      "                ",
      "                ",
      "                "
    ],
    [
      "                ",
      "                ",
      "                ",
      "                ",
      "                ",
      "                ",
      "                ",
      "                ",
      "    $  $        ",
      "                ",
      "                ",
      "    $  $        ",
      "                ",
      "                ",
      "                ",
      "                "
    ],
    [
      "                ",
      "                ",
      "                ",
      "                ",
      "                ",
      "                ",
      "                ",
      "     $$         ",
      "    $$$$        ",
      "   $$  $$       ",
      "   $$  $$       ",
      "    $$$$        ",
      "     $$         ",
      "                ",
      "                ",
      "                "
    ]
  ]
}