{
  "xsize": 16,
  "zsize": 16,
  "refpalette": "lostcities:scattered",
  "slices": [
    [
      "&&&&&&&&&&&$$$$$",
      "&&&&&&&&&&&&&$$$",
      "&&&&&&&&&&&&&$$$",
      "&&&&&&&&&&&&&$$$",
      "&&&&&&&&&&&&&$$$",
      "&&&&&&&&&&&&&$$$",
      "&&&&&&&&&&&&&$$$",
      "&&&&&&&&&&&&&$$$",
      "&&&&&&&&&&&&&$$$",
      "&&&&&&&&&&&&&$$$",
      "&&&&&&&&&&&&&$$$",
      "&&&&&&&&&&&&&$$$",
      "&&&&&&&&&&&&&$$$",
      "&&&&&&&&&&&&&$$$",
      "&&&&&&&&&&&&&$$$",
      "&&&&&&&&&&&&&$$$"
    ],
    [
      "$$$$$$$c$$Z     ",
      "$$$$$$c$$$&b  j ",
      "$$$$$$c$$$&b    ",
      "$$$$$c$$$$&b    ",
      "$$$cc$$$$$&     ",
      "ccc$$$$$$$&  j  ",
      "$$$$$$$$$$&&    ",
      "$$$$$$$$$&&&    ",
      "&&&&&&&&&&&&    ",
      " bbbbbbb&&&&  j ",
      " bbbbbbb        ",
      "  bbbbbbb       ",
      "  bbbbbb&&&&    ",
      "&&&&&&&&&&&&    ",
      "$$$$$$$$$&&&    ",
      "$$$$$$$$$$&&    "
    ],
    [
      "bbbbbbbbbb      ",
      "bbbbbbbbbbb     ",
      "bbbbbbbbbbbb    ",
      "bb    bbbbbj    ",
      "bbb             ",
      "bbbb            ",
      "bbbbb           ",
      "bbbbbb   &&     ",
      "eeeeeeeee&&     ",
      " bbbbbb         ",
      "  bbbbbb        ",
      "  bbbbbbb       ",
      "  bbbbbbb       ",
      "eeeeeeeee&&     ",
      "   bbbbbb&&     ",
      "j   bbbbbbb     "
    ],
    [
      "bbbbbbb         ",
      "bbbbbbbbb       ",
      "bbbbb           ",
      "bbb             ",
      "bbb             ",
      "bbbb            ",
      "bbbb            ",
      "bbbbb    z{     ",
      " bbbbb   |}     ",
      "  bbbbb         ",
      "  bbbbb         ",
      "  bbbbbb        ",
      "   bbbbb        ",
      " j  bbbbbz{     ",
      "    bbbbb|}     ",
      "     bbbbb      "
    ],
    [
      "bbbbb           ",
      "bbbbb           ",
      "bbbb            ",
      "bbb             ",
      "bbb             ",
      "bbb             ",
      "bbb             ",
      " bb      z{     ",
      "         |}     ",
      "    b           ",
      "   bbb          ",
      "    bb          ",
      "                ",
      "         z{     ",
      "         |}     ",
      "                "
    ],
    [
      "bbbb            ",
      "bbbb            ",
      "bbbb            ",
      "bbb             ",
      "bb              ",
      "bb              ",
      "b               ",
      "         z{     ",
      "         |}     ",
      "                ",
      "                ",
      "                ",
      "                ",
      "         z{     ",
      "         |}     ",
      "                "
    ],
    [
      "bbb             ",
      "bbbb            ",
      "bbb             ",
      "bbb             ",
      "bb              ",
      "b               ",
      "                ",
      "         z{     ",
      "         |}     ",
      "                ",
      "                ",
      "                ",
      "                ",
      "         z{     ",
      "         |}     ",
      "                "
    ],
    [
      "b               ",
      "bbb             ",
      "bbb             ",
      "bbb             ",
      "b               ",
      "b               ",
      "                ",
      "         z{     ",
      "         |}     ",
      "                ",
      "                ",
      "                ",
      "                ",
      "         z{     ",
      "         |}     ",
      "                "
    ],
    [
      "bb              ",
      "bb              ",
      "bb              ",
      "bb              ",
      "b               ",
      "b               ",
      "                ",
      "         z{     ",
      "         |}     ",
      "                ",
      "                ",
      "                ",
      "                ",
      "         z{     ",
      "         |}     ",
      "                "
    ],
    [
      "bb              ",
      "bb              ",
      "bb              ",
      "bb              ",
      "b               ",
      "b               ",
      "                ",
      "         z{     ",
      "         |      ",
      "                ",
      "                ",
      "                ",
      "                ",
      "         z{     ",
      "         |}     ",
      "                "
    ],
    [
      "b               ",
      "bb              ",
      "bb              ",
      "bb              ",
      "bb              ",
      "b               ",
      "                ",
      "         z      ",
      "                ",
      "                ",
      "                ",
      "                ",
      "                ",
      "         z{     ",
      "         |}     ",
      "                "
    ],
    [
      "                ",
      "b               ",
      "bb              ",
      "bb              ",
      "bb              ",
      "b               ",
      "                ",
      "                ",
      "                ",
      "                ",
      "                ",
      "                ",
      "                ",
      "         z      ",
      "         |}     ",
      "                "
    ],
    [
      "                ",
      "b               ",
      "bb              ",
      "bb              ",
      "bb              ",
      "b               ",
      "                ",
      "                ",
      "                ",
      "                ",
      "                ",
      "                ",
      "                ",
      "                ",
      "         |}     ",
      "                "
    ],
    [
      "b               ",
      "bb              ",
      "bb              ",
      "bb              ",
      "bb              ",
      "b               ",
      "                ",
      "                ",
      "                ",
      "                ",
      "                ",
      "                ",
      "                ",
      "                ",
      "                ",
      "                "
    ],
    [
      "b               ",
      "bb              ",
      "bb              ",
      "bb              ",
      "bb              ",
      "bb              ",
      "                ",
      "                ",
      "                ",
      "                ",
      "                ",
      "                ",
      "                ",
      "                ",
      "                ",
      "                "
    ],
    [
      "b          ͱkkkk",
      "bb         Ͱ    ",
      "bb              ",
      "bbb             ",
      "bb              ",
      "bb              ",
      "                ",
      "                ",
      "                ",
      "                ",
      "                ",
      "                ",
      "h               ",
      "&               ",
      "&               ",
      "         &&Ͱ    "
    ],
    [
      "b          zeeee",
      "bb         ͳ    ",
      "bbb             ",
      "bbb             ",
      "bb              ",
      "bb              ",
      "                ",
      "                ",
      "                ",
      "                ",
      "                ",
      "                ",
      "                ",
      "                ",
      "                ",
      "           ͳ    "
    ],
    [
      "b               ",
      "bb              ",
      "bbb             ",
      "bbb             ",
      "bbb             ",
      "bb              ",
      "b               ",
      "                ",
      "                ",
      "                ",
      "                ",
      "                ",
      "                ",
      "                ",
      "                ",
      "                "
    ],
    [
      "b               ",
      "bb              ",
      "bbb             ",
      "bbb             ",
      "bbb             ",
      "bb              ",
      "b               ",
      "                ",
      "                ",
      "                ",
      "                ",
      "                ",
      "                ",
      "                ",
      "                ",
      "                "
    ],
    [
      "b               ",
      "bbb             ",
      "bbb             ",
      "bbb             ",
      "bbb             ",
      "bb              ",
      "b               ",
      "                ",
      "                ",
      "                ",
      "                ",
      "                ",
      "                ",
      "                ",
      "          }     ",
      "                "
    ],
    [
      "b               ",
      "bbb             ",
      "bbb             ",
      "bbb             ",
      "bbb             ",
      "bbb             ",
      "b               ",
      "         z{     ",
      "                ",
      "                ",
      "                ",
      "                ",
      "                ",
      "          {     ",
      "         |}     ",
      "                "
    ],
    [
      "b               ",
      "bbb             ",
      "bbb             ",
      "bbb             ",
      "bbb             ",
      "bbb             ",
      "b               ",
      "         z{     ",
      "         |}     ",
      "                ",
      "                ",
      "                ",
      "                ",
      "         z{     ",
      "         |}     ",
      "                "
    ],
    [
      "                ",
      "bbb             ",
      "bbb             ",
      "bbbb            ",
      "bbb             ",
      "bbb             ",
      "b               ",
      "         z{     ",
      "         |}     ",
      "                ",
      "                ",
      "                ",
      "                ",
      "         z{     ",
      "         |}     ",
      "                "
    ],
    [
      "                ",
      "bbb             ",
      "bbba            ",
      "bbbb            ",
      "bbbb            ",
      "bbb             ",
      "b               ",
      "         z{     ",
      "         |}     ",
      "                ",
      "                ",
      "                ",
      "                ",
      "         z{     ",
      "         |}     ",
      "                "
    ],
    [
      "  a             ",
      "bbba            ",
      "bbbba           ",
      "bbbba           ",
      "bbbb            ",
      "bbb             ",
      "bb              ",
      "         z{     ",
      "         |}     ",
      "                ",
      "                ",
      "                ",
      "                ",
      "         z{     ",
      "         |}     ",
      "                "
    ],
    [
      "aa              ",
      "bbba            ",
      "bbbba           ",
      "bbbba           ",
      "bbbb            ",
      "bbb             ",
      "bb              ",
      "a        z{     ",
      "         |}     ",
      "                ",
      "                ",
      "                ",
      "                ",
      "         z{     ",
      "         |}     ",
      "                "
    ],
    [
      "baaa            ",
      "bbbaa           ",
      "bbbba           ",
      "bbbba           ",
      "bbbb            ",
      "bbbb            ",
      "bb              ",
      "a        z{     ",
      "         |}     ",
      "                ",
      "                ",
      "                ",
      "                ",
      "         z{     ",
      "         |}     ",
      "                "
    ],
    [
      "bbaaa           ",
      "bbbba           ",
      "bbbba           ",
      "bbbbba          ",
      "bbbba           ",
      "bbbb            ",
      "bba             ",
      "aa       z{     ",
      "         |}     ",
      "                ",
      "                ",
      "                ",
      "                ",
      "         z{     ",
      "         |}     ",
      "                "
    ],
    [
      "bbbaa           ",
      "bbbba           ",
      "bbbbb           ",
      "bbbbba          ",
      "bbbbba          ",
      "bbbba           ",
      "bbba            ",
      "aaaaa    z{     ",
      "         |}     ",
      "                ",
      "                ",
      "                ",
      "                ",
      "         z{     ",
      "         |}     ",
      "                "
    ],
    [
      "bbbaaa  aaaa    ",
      "bbbbb   a       ",
      "bbbbba          ",
      "bbbbba          ",
      "bbbbbaa         ",
      "bbbbbaaa        ",
      "bbbba  aa       ",
      "aaaaaa   &&     ",
      " aaaa    &&     ",
      "    a           ",
      "                ",
      "                ",
      "a               ",
      "a        &&     ",
      "         &&     ",
      "                "
    ],
    [
      "bbbbaaaaa&&aa   ",
      "bbbbba aa&&aaa  ",
      "bbbbbbaaa&& aaa ",
      "bbbbbba  && a a ",
      "bbbbbbaa && aaa ",
      "bbbbbaaaa&& aa  ",
      "bbbbaaaa&&&&    ",
      "&&&&&&&&&ͱͱ&    ",
      "&&&&&&&&&ͱͱ&    ",
      "aaaaaaa &&&&    ",
      "aaaaa a         ",
      "aa  aaa         ",
      "aa      &&&&    ",
      "&&&&&&&&&ͱͱ&    ",
      "&&&&&&&&&ͱͱ&    ",
      "        &&&&    "
    ],
    [
      "abbbbaaa$$$$aaaa",
      "bbbbbbaa$$$$aaaa",
      "bbbbbbaa$$$$aaaa",
      "bbbbbbaa$$$$aaaa",
      "bbbbbbaa$$$$aaaa",
      "bbbbbbaa$$$$aaaa",
      "$$$$$$$$$$$$$$$$",
      "$$$$$$$$$$$$$$$$",
      "$$$$$$$$$$$$$$$$",
      "$$$$$$$$$$$$$$$$",
      "$$$$$$$$$$$$$$$$",
      "$$$$$$$$$$$$$$$$",
      "$$$$$$$$$$$$$$$$",
      "$$$$$$$$$$$$$$$$",
      "$$$$$$$$$$$$$$$$",
      "$$$$$$$$$$$$$$$$"
    ],
    [
      "abbbblllllllllll",
      "bbbbllllllllllll",
      "bbllllllllllllll",
      "blllllllllllllll",
      "llllllllllllllll",
      "llllllllllllllll",
      "llllllllllllllll",
      "llllllllllllllll",
      "llllllllllllllll",
      "llllllllllllllll",
      "llllllllllllllll",
      "llllllllllllllll",
      "llllllllllllllll",
      "llllllllllllllll",
      "llllllllllllllll",
      "llllllllllllllll"
    ],
    [
      "abbbaaaaaaaaaaaa",
      "bbbbbaaaaaaaaaaa",
      "bbbbbbaaaaaaaaaa",
      "bbbbbbaaaaaaaaaa",
      "bbbbbbaaaaaaaaaa",
      "bbbbbbaaaaaaaaaa",
      "bbbbbaaaaaaaaaaa",
      "aaaaaaaaaaaaaaa ",
      "aaaaaaaaaaaaaaa ",
      " aaaaaaaaaaa aj ",
      "  aaaaaaaaa aa  ",
      "aaaaaaaaaaaaa   ",
      "a   aaaaaaaaa   ",
      "aaaaaa aaaaa    ",
      "a   aaaaaaa     ",
      "aaaaa   aa      "
    ],
    [
      "aaaaaaaaaaaaaa  ",
      "abbbbaaaaaaa    ",
      "bbbbbaaaaaa     ",
      "bbbbbbaaaaaa    ",
      "bbbbbaaaaaaaa a ",
      "bbbbbaaaaaaaa a ",
      "abbaaaaaaaaaaaa ",
      "aaaaa  aaaaa    ",
      "aaa  aaaaaaa    ",
      "   aaaaaaaa     ",
      "   aaaaaaam     ",
      "    aaaaaa      ",
      "       aaaaa    ",
      " j      aaaj    ",
      "        aa      ",
      "m   j           "
    ],
    [
      "aaaaaaaaaaaaa   ",
      "aaaaaaaaaaaa    ",
      "aabbaaaaaaa     ",
      "abbbaaaaaaa     ",
      "abbbaaaaaaaa    ",
      "aaaaaaaaaaaa    ",
      "aaaaaoaaaaa     ",
      "aaaa  aaaaa     ",
      "aaa  aaaaaa     ",
      "     aaaaa      ",
      "     aa a n     ",
      "        a       ",
      "        ja      ",
      "         a      ",
      "                ",
      "n               "
    ]
  ]
}