{
  "xsize": 16,
  "zsize": 16,
  "refpalette": "lostcities:scattered",
  "slices": [
    [
      "                ",
      "    &&&&&&&     ",
      "    &&    &     ",
      "    &&    &     ",
      "    &&    &     ",
      "    &&    &     ",
      "    &&    &     ",
      "    &&    &     ",
      "    &&    &   vv",
      "    &&    & vvvv",
      "    &&    &vvvvv",
      "    &&    &vvvvv",
      "    &&&&&&&vvvvv",
      "         vvvvvvv",
      "        vvvvvvvv",
      "        vvvvvvvv"
    ],
    [
      "                ",
      "    &&&&&&&&    ",
      "    &     &&&&&&",
      "    &     &&&&&&",
      "    &     &&&&&&",
      "    &     &&&&&&",
      "    &     &&&&&&",
      "    &     &&&&&&",
      "    &     &&&&&&",
      "    &     &&&&&&",
      "    &     &&&&&&",
      "    &     &&&&&&",
      "    &&&&&&&&&&&&",
      "          &&&&&&",
      "          &&&&&&",
      "          &&&&&&"
    ],
    [
      "                ",
      "     &&&&&&&    ",
      "     &    &&&&&&",
      "     &    &&    ",
      "     &    &&    ",
      "     &    &&    ",
      "     &    && '  ",
      "     &    &&    ",
      "     &    &&    ",
      "     &    &&    ",
      "     &#   && '  ",
      "     &    &&    ",
      "     &&&&&&&    ",
      "          &  '  ",
      "          &     ",
      "          &     "
    ],
    [
      "                ",
      "     &&&&&&&&   ",
      "     &    &&&&&&",
      "     &    & &   ",
      "     &    & &   ",
      "     &    & &   ",
      "     &    & &(((",
      "     &    & &(((",
      "     &    & &(((",
      "     &#   & &(((",
      "    #&##  & &(((",
      "    #&#   & &   ",
      "     &&&&&&&&   ",
      "          &  (((",
      "          &  (((",
      "          &  ((("
    ],
    [
      "                ",
      "      &&&&&&&   ",
      "      &   &&&&&&",
      "      &   & &   ",
      "      &   & &   ",
      "      &   & &   ",
      "      &   & &(&&",
      "      &   & &&  ",
      "      &   & &&  ",
      "      &   & &&))",
      "     #&#  & &(&&",
      "     #&   & &   ",
      "      &&&&&&&   ",
      "          &  (&&",
      "          &  &  ",
      "          &  &  "
    ],
    [
      "                ",
      "      &&&&&&&&  ",
      "      &   &&&&&&",
      "      &   &  &  ",
      "      &   &  &  ",
      "      &   &  &  ",
      "      &#  &  (&&",
      "      &   &  &  ",
      "      &   &  &  ",
      "     #&#  &  &  ",
      "     #&#  &  (&&",
      "      &   &  &  ",
      "      &&&&&&&&  ",
      "          &  (&&",
      "          &  &  ",
      "          &  &  "
    ],
    [
      "                ",
      "      &&&&&&&&  ",
      "      &   &&&&&&",
      "      &   &  &  ",
      "      &   &  &  ",
      "      &#  &  &  ",
      "     #&## &  (&&",
      "     #&#  &  &((",
      "      &#  &  &((",
      "     #&## &  &((",
      "      &#  &  (&&",
      "      &   &  &  ",
      "      &&&&&&&&  ",
      "          &  (&&",
      "          &  &((",
      "          &  &(("
    ],
    [
      "                ",
      "       &&&&&&&  ",
      "       &  &&&&&&",
      "       &  &  &  ",
      "       &  &  &  ",
      "      #&# &  &  ",
      "      #&# &  (((",
      "      #&  &  (((",
      "      #&# &  (((",
      "      #&# &  (((",
      "       &  &  (((",
      "       &  &  &  ",
      "       &&&&&&&  ",
      "          &  (((",
      "          &  (((",
      "          &  ((("
    ],
    [
      "                ",
      "       &&&&&&&& ",
      "       &  &&&&&&",
      "       &  &   & ",
      "       &# &   & ",
      "      #&##&   & ",
      "       &# &  '& ",
      "       &# &   & ",
      "      #&##&   & ",
      "       &# &   & ",
      "       &  &  '& ",
      "       &  &   & ",
      "       &&&&&&&& ",
      "          &  '  ",
      "          &     ",
      "          &     "
    ],
    [
      "                ",
      "        &&&&&&& ",
      "        & &&&&&&",
      "        & &   & ",
      "        &#&   & ",
      "       #&#&   & ",
      "        &#&  (((",
      "        & &  (((",
      "       #&#&  (((",
      "        & &  (((",
      "        & &  (((",
      "        & &   & ",
      "        &&&&&&& ",
      "          &  (((",
      "          &  (((",
      "          &  ((("
    ],
    [
      "                ",
      "        &&&&&&&&",
      "        & &&&&&&",
      "        &#&    &",
      "       #&#&    &",
      "       #&#&    &",
      "       #&#&  (&&",
      "        &#&  & &",
      "       #&#&  & &",
      "        & &  &))",
      "        & &  (&&",
      "        & &    &",
      "        &&&&&&&&",
      "          &  (&&",
      "          &  &  ",
      "          &  &  "
    ],
    [
      "                ",
      "         &&&&&&&",
      "         &&&&&&&",
      "         &&    &",
      "        #&&    &",
      "        #&&    &",
      "        #&&  (&&",
      "         &&  & &",
      "        #&&  & &",
      "         &&  & &",
      "         &&  (&&",
      "         &&    &",
      "         &&&&&&&",
      "          &  (&&",
      "          &  &  ",
      "          &  &  "
    ],
    [
      "                ",
      "         &&&&&&&",
      "         &&&&&&&",
      "         &&     ",
      "         &&     ",
      "         &&     ",
      "        #&&  (&&",
      "         &&  &((",
      "         &&  &((",
      "         &&  &((",
      "         &&  (&&",
      "         &&     ",
      "         &&&&&&&",
      "          &  (&&",
      "          &  &((",
      "          &  &(("
    ],
    [
      "                ",
      "         &&&&&&&",
      "         &&&&&&&",
      "         &&     ",
      "         &&     ",
      "         &&     ",
      "        #&&# (((",
      "         &&  (((",
      "         &&  (((",
      "         &&  (((",
      "         &&  (((",
      "         &&     ",
      "         &&&&&&&",
      "          &  (( ",
      "          &  (( ",
      "          &  (  "
    ],
    [
      "                ",
      "          &&&&&&",
      "          &&&&&&",
      "          &     ",
      "          &     ",
      "          &     ",
      "         #&#    ",
      "          &     ",
      "          &     ",
      "          &     ",
      "          &     ",
      "          &     ",
      "          &&&&&&",
      "          &     ",
      "          &     ",
      "          &     "
    ],
    [
      "                ",
      "          &&&&&&",
      "          &&&&&&",
      "          &&&&&&",
      "          &&&&&&",
      "         #&&&&&&",
      "         #&&&&&&",
      "          &&&&&&",
      "          &&&&&&",
      "          &&&&&&",
      "          &&&&&&",
      "          &&&&& ",
      "          &&&&  ",
      "          &&&&  ",
      "          &&&&  ",
      "          &&&&  "
    ],
    [
      "                ",
      "           &&&&&",
      "           &    ",
      "           &    ",
      "           &    ",
      "          #&#   ",
      "          #&#  #",
      "           &    ",
      "           &    ",
      "           &    ",
      "           &    ",
      "           &    ",
      "           &&   ",
      "                ",
      "                ",
      "                "
    ],
    [
      "                ",
      "           &&&&&",
      "           &   &",
      "           &   &",
      "           &   &",
      "          #&###&",
      "           &  #&",
      "           &   &",
      "           &   &",
      "           &   &",
      "           &   &",
      "           &    ",
      "           &    ",
      "                ",
      "                ",
      "                "
    ],
    [
      "                ",
      "           &&&& ",
      "           & && ",
      "           & && ",
      "           &#&&#",
      "          #&#&&#",
      "           &#&&#",
      "           & &&#",
      "           & && ",
      "           & && ",
      "           &  & ",
      "           &    ",
      "                ",
      "                ",
      "                ",
      "                "
    ],
    [
      "                ",
      "            &   ",
      "            &   ",
      "            &   ",
      "            &#  ",
      "           #&###",
      "            &# #",
      "            &   ",
      "            &   ",
      "            &   ",
      "            &   ",
      "                ",
      "                ",
      "                ",
      "                ",
      "                "
    ],
    [
      "                ",
      "                ",
      "                ",
      "                ",
      "                ",
      "            ##  ",
      "                ",
      "                ",
      "                ",
      "                ",
      "                ",
      "                ",
      "                ",
      "                ",
      "                ",
      "                "
    ],
    [
      "                ",
      "                ",
      "                ",
      "                ",
      "                ",
      "                ",
      "                ",
      "                ",
      "                ",
      "                ",
      "                ",
      "                ",
      "                ",
      "                ",
      "                ",
      "                "
    ],
    [
      "                ",
      "                ",
      "                ",
      "                ",
      "                ",
      "                ",
      "                ",
      "                ",
      "                ",
      "                ",
      "                ",
      "                ",
      "                ",
      "                ",
      "                ",
      "                "
    ],
    [
      "                ",
      "                ",
      "                ",
      "                ",
      "                ",
      "                ",
      "                ",
      "                ",
      "                ",
      "                ",
      "                ",
      "                ",
      "                ",
      "                ",
      "                ",
      "                "
    ]
  ]
}