{
  "xsize": 16,
  "zsize": 16,
  "refpalette": "lostcities:scattered",
  "slices": [
    [
      "                ",
      " %%             ",
      " %%             ",
      "                ",
      "         $$     ",
      "        $$$$    ",
      "        $$$$    ",
      "         $$     ",
      "                ",
      "                ",
      "                ",
      "                ",
      "                ",
      "             %% ",
      "             %% ",
      "                "
    ],
    [
      "                ",
      " %%             ",
      "&%%             ",
      "&00&            ",
      "&0200&   $$     ",
      "0222200 $$$$    ",
      "22322002$$$$    ",
      "232200002$$     ",
      "32200&&002      ",
      "3220&&00220     ",
      "32200002220&    ",
      "222222222220    ",
      "2223333222000   ",
      "vvv3333222000%% ",
      "vvvv332220&&0%% ",
      "vvvvv33200&&&0  "
    ],
    [
      "                ",
      " %%             ",
      "$%%             ",
      "  $$            ",
      "    $$   $$     ",
      "      $ $$$$    ",
      "       $$$$$    ",
      "        $$$     ",
      "         $      ",
      "$$$$$$$   $     ",
      "$$$$$$$    $    ",
      "$$$$$$$    $    ",
      "$$$$$$$     $   ",
      "$$$$$$$     $%% ",
      "$$$$$$$      %% ",
      "$$$$$$$      $  "
    ],
    [
      "                ",
      " %%             ",
      "$%%             ",
      "  $$            ",
      "    $$   $$     ",
      "      $ $$$$    ",
      "       $$$$$    ",
      "        $$$     ",
      "         $      ",
      "          $     ",
      "$$$$$$     $    ",
      "     $    #$#   ",
      "     $     #$   ",
      "     $      $%% ",
      "     $       %% ",
      "     $       $  "
    ],
    [
      "                ",
      "#%%             ",
      "$%%             ",
      "  $$            ",
      "    $$   $$     ",
      "      $ $$$$    ",
      "       $$$$$    ",
      "        $$$     ",
      "         $      ",
      "          $     ",
      "           $    ",
      "$$$$$     #$#   ",
      "    $      #$   ",
      "    $       $%% ",
      "    $        %% ",
      "    $        $  "
    ],
    [
      "#               ",
      "#%%             ",
      "$%%             ",
      "# $$            ",
      "    $$   $$     ",
      "      $ $$$$    ",
      "       $$$$$    ",
      "        $$$     ",
      "         $      ",
      "          $#    ",
      "          #$#   ",
      "          #$#   ",
      "$$$$       #$   ",
      "   $        $%% ",
      "   $         %% ",
      "   $         $  "
    ],
    [
      "                ",
      "#%%             ",
      "$%%             ",
      "# $$            ",
      "    $$   $$     ",
      "      $ $$$$    ",
      "       $$$$$    ",
      "        $$$     ",
      "         $#     ",
      "         #$#    ",
      "         ##$#   ",
      "          #$    ",
      "$$$$        $   ",
      "   $        $%% ",
      "   $         %% ",
      "   $         $  "
    ],
    [
      "                ",
      "#%%             ",
      "$%%             ",
      "# $$            ",
      "    $$   $$     ",
      "      $ $$$$    ",
      "       $$$$$    ",
      "        $$$     ",
      "         $#     ",
      "         #$#    ",
      "          #$#   ",
      "           $    ",
      "            $   ",
      "$$$         $%% ",
      "  $          %% ",
      "  $          $  "
    ],
    [
      "                ",
      "#%%             ",
      "$%%             ",
      "# $$            ",
      "    $$   $$     ",
      "      $ $$$$    ",
      "       $$$$$    ",
      "        $$$     ",
      "         $#     ",
      "         #$#    ",
      "          #$    ",
      "           $    ",
      "            $   ",
      "            $%% ",
      "$$           %% ",
      " $           $  "
    ],
    [
      "                ",
      "#%%             ",
      "$%%             ",
      "##$             ",
      "         $$     ",
      "      $ $$$$    ",
      "       $$$$$    ",
      "        $$$     ",
      "         $#     ",
      "         #$#    ",
      "          #$    ",
      "           $    ",
      "                ",
      "                ",
      "             %% ",
      "$            $  "
    ],
    [
      "                ",
      " %%             ",
      "$%%             ",
      " #$             ",
      "         $$     ",
      "      $ $$$$    ",
      "       $$$$$    ",
      "        $$$     ",
      "        #$#     ",
      "        ##$#    ",
      "         ##$    ",
      "           $    ",
      "                ",
      "                ",
      "              % ",
      "$            $  "
    ],
    [
      "                ",
      " %%             ",
      "$%%             ",
      " #$             ",
      "     $   $$     ",
      "      $ $$$$    ",
      "       $$$$$    ",
      "        $$$     ",
      "        #$#     ",
      "         #$     ",
      "           $    ",
      "           $    ",
      "                ",
      "                ",
      "             %% ",
      "             $  "
    ],
    [
      "                ",
      " %%             ",
      "#%%             ",
      " #              ",
      "         $$     ",
      "        $$$$    ",
      "        $$$$    ",
      "         $$#    ",
      "        ####    ",
      "         ##     ",
      "                ",
      "                ",
      "                ",
      "              % ",
      "             %% ",
      "                "
    ],
    [
      "                ",
      " %%             ",
      " %%             ",
      "                ",
      "         $$     ",
      "        $$$$    ",
      "        $$$$    ",
      "        #$$#    ",
      "        ###     ",
      "         #      ",
      "                ",
      "                ",
      "                ",
      "             %% ",
      "             %% ",
      "                "
    ],
    [
      "                ",
      "                ",
      "                ",
      "                ",
      "         $$     ",
      "        $$$$    ",
      "       #$$$$    ",
      "        #$$     ",
      "         #      ",
      "                ",
      "                ",
      "                ",
      "                ",
      "                ",
      "                ",
      "                "
    ],
    [
      "                ",
      "                ",
      "                ",
      "                ",
      "         $$     ",
      "       #$$$$    ",
      "      ##$$$$    ",
      "       ##$$     ",
      "                ",
      "                ",
      "                ",
      "                ",
      "                ",
      "                ",
      "                ",
      "                "
    ],
    [
      "                ",
      "                ",
      "                ",
      "         $$     ",
      "        $$$$    ",
      "       $$$$$$   ",
      "      #$$$$$$   ",
      "       #$$$$    ",
      "         $$     ",
      "                ",
      "                ",
      "                ",
      "                ",
      "                ",
      "                ",
      "                "
    ],
    [
      "                ",
      "                ",
      "                ",
      "                ",
      "        $$$$    ",
      "        $$$$    ",
      "       #$$$$    ",
      "        $$$$    ",
      "                ",
      "                ",
      "                ",
      "                ",
      "                ",
      "                ",
      "                ",
      "                "
    ],
    [
      "                ",
      "                ",
      "                ",
      "                ",
      "        $  $    ",
      "                ",
      "                ",
      "        $  $    ",
      "                ",
      "                ",
      "                ",
      "                ",
      "                ",
      "                ",
      "                ",
      "                "
    ],
    [
      "                ",
      "                ",
      "                ",
      "                ",
      "        $  $    ",
      "                ",
      "                ",
      "        $  $    ",
      "                ",
      "                ",
      "                ",
      "                ",
      "                ",
      "                ",
      "                ",
      "                "
    ],
    [
      "                ",
      "                ",
      "                ",
      "                ",
      "        $  $    ",
      "                ",
      "                ",
      "        $  $    ",
      "                ",
      "                ",
      "                ",
      "                ",
      "                ",
      "                ",
      "                ",
      "                "
    ],
    [
      "                ",
      "                ",
      "                ",
      "         $$     ",
      "        $$$$    ",
      "       $$  $$   ",
      "       $$  $$   ",
      "        $$$$    ",
      "         $$     ",
      "                ",
      "                ",
      "                ",
      "                ",
      "                ",
      "                ",
      "                "
    ],
    [
      "                ",
      "                ",
      "                ",
      "                ",
      "                ",
      "                ",
      "                ",
      "                ",
      "                ",
      "                ",
      "                ",
      "                ",
      "                ",
      "                ",
      "                ",
      "                "
    ],
    [
      "                ",
      "                ",
      "                ",
      "                ",
      "                ",
      "                ",
      "                ",
      "                ",
      "                ",
      "                ",
      "                ",
      "                ",
      "                ",
      "                ",
      "                ",
      "                "
    ]
  ]
}