{
  "xsize": 16,
  "zsize": 16,
  "refpalette": "lostcities:scattered",
  "slices": [
    [
      "                ",
      "       $ $      ",
      "        $       ",
      "       $ $      ",
      "                ",
      "                ",
      "                ",
      "                ",
      "                ",
      "                ",
      "                ",
      "                ",
      "                ",
      "                ",
      "                ",
      "                "
    ],
    [
      "&02333v322000023",
      "&023333333222233",
      "&023333333333333",
      "0233333323333333",
      "2233322222333222",
      "222200 00022 220",
      "000&&&&&&&022200",
      "&&&vvvvv&&&02220",
      "&vvvvvvv&&002220",
      "vvvvvvv&&0022220",
      "vvvvvv&000222220",
      "vvvvv&&02222200&",
      "&vv&&&&0222200&&",
      "&vv&&&&023320&&&",
      "0vv&&v&0233320&&",
      "0vv&vv 02333320&"
    ],
    [
      "                ",
      "                ",
      "                ",
      "                ",
      "                ",
      "                ",
      "                ",
      "                ",
      "                ",
      "               #",
      " #            ##",
      " !!           !!",
      "#!!           !!",
      "#               ",
      "  ..           .",
      "  ..           ."
    ],
    [
      "                ",
      "                ",
      "                ",
      "                ",
      "                ",
      "                ",
      "                ",
      "                ",
      "                ",
      "                ",
      " #            # ",
      " !!           !!",
      "#!!           !!",
      "                ",
      "  .A           .",
      "  .A           ."
    ],
    [
      "                ",
      "                ",
      "                ",
      "                ",
      "                ",
      "                ",
      "                ",
      "                ",
      "                ",
      "                ",
      " #            # ",
      "#!!           !!",
      "#!!           !!",
      "                ",
      "  .X           .",
      "  .X           ."
    ],
    [
      "                ",
      "                ",
      "                ",
      "                ",
      "                ",
      "                ",
      "                ",
      "                ",
      "                ",
      "                ",
      "##            # ",
      "#!!           !!",
      " !!           !!",
      "                ",
      "  ..           .",
      "  ..           ."
    ],
    [
      "                ",
      "                ",
      "                ",
      "                ",
      "                ",
      "                ",
      "                ",
      "                ",
      "                ",
      "                ",
      " #            # ",
      " !!           !!",
      " !!           !!",
      "                ",
      "  '            '",
      "                "
    ],
    [
      "                ",
      "                ",
      "                ",
      "                ",
      "                ",
      "                ",
      "                ",
      "                ",
      "                ",
      "                ",
      " ##           ##",
      " !!           !!",
      " !!           !!",
      "                ",
      "  '            '",
      "                "
    ],
    [
      "                ",
      "                ",
      "                ",
      "                ",
      "                ",
      "                ",
      "                ",
      "                ",
      "                ",
      "                ",
      "               #",
      "  #           !!",
      " !!           !!",
      "                ",
      "  '            '",
      "                "
    ],
    [
      "                ",
      "                ",
      "                ",
      "                ",
      "                ",
      "                ",
      "                ",
      "                ",
      "               #",
      "    ^^^^^^^^^^^^",
      "^## ^^^^^^^^^^^^",
      "^^^^^^^^^^^^^^^^",
      "^^^^^^^^^^^^^^^^",
      "^^^^^^^^^^^^^^^^",
      "^^^^^^^^^^^^^^^^",
      "^^^^^^^^^^^^^^^^"
    ],
    [
      "                ",
      "                ",
      "                ",
      "                ",
      "                ",
      "                ",
      "                ",
      "                ",
      "                ",
      "               #",
      " #  !!!!!!!!!!!!",
      "!!!!!!!!!!!!!!!!",
      "!!!!!!!!!!!!!!!!",
      "!!!!!!!!!!!!!!!!",
      "!!!!!!!!!!!!!!!!",
      "!!!!!!!!!!!!!!!!"
    ],
    [
      "                ",
      "                ",
      "                ",
      "                ",
      "                ",
      "                ",
      "                ",
      "                ",
      "                ",
      "                ",
      "              ##",
      " '#       '     ",
      "            ##  ",
      "             #  ",
      "             #  ",
      "                "
    ],
    [
      "                ",
      "                ",
      "                ",
      "                ",
      "                ",
      "                ",
      "                ",
      "                ",
      "                ",
      "                ",
      "  ##           #",
      "^^^^^^^^^^^^^^^^",
      "              # ",
      "                ",
      "                ",
      "                "
    ],
    [
      "                ",
      "                ",
      "                ",
      "                ",
      "                ",
      "                ",
      "                ",
      "                ",
      "                ",
      "                ",
      "   ##          #",
      "^^^^^^^^^^^^^^^^",
      "              ##",
      "                ",
      "                ",
      "                "
    ],
    [
      "                ",
      "                ",
      "                ",
      "                ",
      "                ",
      "                ",
      "                ",
      "                ",
      "                ",
      "                ",
      "    #          #",
      "^^^^^^^^^^^^^^^^",
      "               #",
      "                ",
      "                ",
      "                "
    ],
    [
      "                ",
      "                ",
      "                ",
      "                ",
      "                ",
      "                ",
      "                ",
      "                ",
      "                ",
      "                ",
      "    #          #",
      " ^^^^^^^^^^^^^^^",
      "               #",
      "                ",
      "                ",
      "                "
    ],
    [
      "                ",
      "                ",
      "                ",
      "                ",
      "                ",
      "                ",
      "                ",
      "                ",
      "                ",
      "                ",
      "                ",
      "  ^^^^^^^^^   ^^",
      "                ",
      "                ",
      "                ",
      "                "
    ],
    [
      "                ",
      "                ",
      "                ",
      "                ",
      "                ",
      "                ",
      "                ",
      "                ",
      "                ",
      "                ",
      "                ",
      "   ^^^^^^^     ^",
      "                ",
      "                ",
      "                ",
      "                "
    ]
  ]
}