{
  "xsize": 16,
  "zsize": 16,
  "refpalette": "lostcities:scattered",
  "slices": [
    [
      "                ",
      "                ",
      "                ",
      "                ",
      "                ",
      "                ",
      "  vvvvvvvvv     ",
      "vvvvvvvvvvvvv vv",
      "vvvvvvvvvvvvvvvv",
      "vvvvvvvvvvvvvvvv",
      "vvvvvvvvvvvvvvvv",
      "vvvvvvvvvvvvvvvv",
      "vvvvvvvvvvvvvvvv",
      "vvvvvvvvvvvvvvvv",
      "vv******vvvvvvvv",
      "**********vvvv**"
    ],
    [
      "                ",
      "                ",
      "&&&&&&&&&&&&&&&&",
      "&&&&&&&&&&&&&&&&",
      "&&&&&&&&&&&&&&&&",
      "&&&&&&&&&&&&&&&&",
      "&&&&&&&&&&&&&&&&",
      "&&&&&&&&&&&&&&&&",
      "&&&&&&&&&&&&&&&&",
      "&&&&&&&&&&&&&&&&",
      "&&&&&&&&&&&&&&&&",
      "&&&&&&&&&&&&&&&&",
      "&&&&&&&&&&&&&&&&",
      "&&&&&&&&&&&&&&&&",
      "&&&&&&&&&&&&&&&&",
      "&&&&&&&&&&&&&&&&"
    ],
    [
      "                ",
      "                ",
      "&&&&&++    &&&&&",
      "                ",
      "                ",
      "                ",
      " '            ' ",
      "                ",
      "                ",
      "                ",
      " '            ' ",
      "                ",
      "                ",
      " '            ' ",
      "                ",
      "                "
    ],
    [
      "                ",
      "                ",
      "&&&&&+    +&&&&&",
      "                ",
      "                ",
      "                ",
      "((            ((",
      "((            ((",
      "((            ((",
      "((            ((",
      "((            ((",
      "                ",
      "                ",
      "((            ((",
      "((            ((",
      "((            (("
    ],
    [
      "                ",
      "                ",
      "&&&&&+    +&&&&&",
      "                ",
      "                ",
      "                ",
      "&(            (&",
      " &            & ",
      " &            & ",
      " &            & ",
      "&(            (&",
      "                ",
      "                ",
      "&(            (&",
      " &            & ",
      " &            & "
    ],
    [
      "                ",
      "                ",
      "&&&&&+   ++&&&&&",
      "                ",
      "                ",
      "                ",
      "&(            (&",
      " &            & ",
      " &            & ",
      " &            & ",
      "&(            (&",
      "                ",
      "                ",
      "&(            (&",
      " &            & ",
      " &            & "
    ],
    [
      "                ",
      "                ",
      "&&&&&+   ++&&&&&",
      "                ",
      "                ",
      "                ",
      "&(            (&",
      "(&            &(",
      "(&            &(",
      "(&            &(",
      "&(            (&",
      "                ",
      "                ",
      "&(            (&",
      "(&            &(",
      "(&            &("
    ],
    [
      "                ",
      "                ",
      "&&&&&+   ++&&&&&",
      "                ",
      "                ",
      "                ",
      "((            ((",
      "((            ((",
      "((            ((",
      "((            ((",
      "((            ((",
      "                ",
      "                ",
      "((            ((",
      "((            ((",
      "((            (("
    ],
    [
      "                ",
      "                ",
      "&&&&&++++++&&&&&",
      "                ",
      "                ",
      "                ",
      " '            ' ",
      "                ",
      "                ",
      "                ",
      " '            ' ",
      "                ",
      "                ",
      " '            ' ",
      "                ",
      "                "
    ],
    [
      "                ",
      "                ",
      "&&&&&++++++&&&&&",
      "                ",
      "                ",
      "                ",
      "((            ((",
      "((            ((",
      "((            ((",
      "((            ((",
      "((            ((",
      "                ",
      "                ",
      "((            ((",
      "((            ((",
      "((            (("
    ],
    [
      "                ",
      "                ",
      "&&&&&&&&&&&&&&&&",
      "                ",
      "                ",
      "                ",
      "&(            (&",
      " &            & ",
      " &            & ",
      " &            & ",
      "&(            (&",
      "                ",
      "                ",
      "&(            (&",
      " &            & ",
      " &            & "
    ],
    [
      "                ",
      "                ",
      "&&&&&&&  &&&&&&&",
      "                ",
      "                ",
      "                ",
      "&(            (&",
      " &            & ",
      " &            & ",
      " &            & ",
      "&(            (&",
      "                ",
      "                ",
      "&(            (&",
      " &            & ",
      " &            & "
    ],
    [
      "                ",
      "&              &",
      "&&&&&&     &&&&&",
      "&              &",
      "&              &",
      "&              &",
      "&(            (&",
      "(&            &(",
      "(&            &(",
      "(&            &(",
      "&(            (&",
      "&              &",
      "&             #&",
      "&(           #(&",
      "(&           #&(",
      "(&           #&("
    ],
    [
      "                ",
      "&              &",
      "&&&&&&&     &&&&",
      "&              &",
      "&              &",
      "&              &",
      "((            ((",
      "((            ((",
      "((            ((",
      "((            ((",
      "((            ((",
      "&              &",
      "&              &",
      " (            # ",
      " (           ##(",
      " (          ##(("
    ],
    [
      "                ",
      "&              &",
      "&&&&&&&      &&&",
      "&              &",
      "&              &",
      "&              &",
      "&              &",
      "&              &",
      "&   #####      &",
      "&       #### ##&",
      "&           ## &",
      "&              &",
      "&               ",
      "                ",
      "             ## ",
      "            ### "
    ],
    [
      "                ",
      "&&            &&",
      "&&&&&&&&    &&&&",
      "&&&&&&&&    &&&&",
      "&&&&&&&&&   &&&&",
      "&&&&&&&&&&&&&&&&",
      "&&&&&&&&&&&&&&&&",
      "&&&&&&&&&&&&&&&&",
      "&&&&&&&&&&&&&&&&",
      "&&&&&&&&&&&&&&&&",
      "&&&&&&&&&&&&&&&&",
      "&&&&&&&&&&&&&#  ",
      " &&&&&&&&&&&    ",
      "  &&&&&&&&&&    ",
      "  &&&&&&&&&&&#  ",
      "  &&&&&&&&&&&&&&"
    ],
    [
      "                ",
      "&&            &&",
      " &            & ",
      " &            & ",
      " &            & ",
      " &            & ",
      "#&###         & ",
      "#&####        &#",
      " &#######    #&#",
      " &  #   #### #&#",
      " &          ##& ",
      " &              ",
      " &              ",
      "                ",
      "                ",
      "            ##  "
    ],
    [
      "                ",
      "&              &",
      "&              &",
      "&              &",
      "&              &",
      "&#             &",
      "&##            &",
      "&####          &",
      "&#  #         #&",
      "&             #&",
      "&               ",
      "&               ",
      "                ",
      "                ",
      "                ",
      "                "
    ],
    [
      "                ",
      "                ",
      "                ",
      "                ",
      "                ",
      "#               ",
      "##              ",
      " #              ",
      "               #",
      "                ",
      "                ",
      "                ",
      "                ",
      "                ",
      "                ",
      "                "
    ],
    [
      "                ",
      "                ",
      "                ",
      "                ",
      "                ",
      "                ",
      "                ",
      "                ",
      "                ",
      "                ",
      "                ",
      "                ",
      "                ",
      "                ",
      "                ",
      "                "
    ],
    [
      "                ",
      "                ",
      "                ",
      "                ",
      "                ",
      "                ",
      "                ",
      "                ",
      "                ",
      "                ",
      "                ",
      "                ",
      "                ",
      "                ",
      "                ",
      "                "
    ],
    [
      "                ",
      "                ",
      "                ",
      "                ",
      "                ",
      "                ",
      "                ",
      "                ",
      "                ",
      "                ",
      "                ",
      "                ",
      "                ",
      "                ",
      "                ",
      "                "
    ],
    [
      "                ",
      "                ",
      "                ",
      "                ",
      "                ",
      "                ",
      "                ",
      "                ",
      "                ",
      "                ",
      "                ",
      "                ",
      "                ",
      "                ",
      "                ",
      "                "
    ],
    [
      "                ",
      "                ",
      "                ",
      "                ",
      "                ",
      "                ",
      "                ",
      "                ",
      "                ",
      "                ",
      "                ",
      "                ",
      "                ",
      "                ",
      "                ",
      "                "
    ]
  ]
}