{
  "xsize": 16,
  "zsize": 16,
  "refpalette": "lostcities:scattered",
  "slices": [
    [
      "      $vvvvvvvvv",
      "      $vvvvvvvvv",
      "       &vvvvvvvv",
      "       2vvvvvvvv",
      "       2vvvvvvvv",
      "       3vvvvvvvv",
      "       2vvvvvvvv",
      "       2vvvvvvvv",
      "       0vvvvvvvv",
      "       &vvvvvvvv",
      "       vvvvvvvvv",
      "       vvvvvvvvv",
      "       vvvvvvvvv",
      "       vvvvvvvvv",
      "       vvvvvvvvv",
      "       &vvvvvvvv"
    ],
    [
      "      $566666776",
      "      $566666777",
      "       566666667",
      "       566666777",
      "       566666777",
      "       566666776",
      "       566666666",
      "       566666666",
      "       566666666",
      "       566666666",
      "       566666666",
      "       566666666",
      "       566666666",
      "       566666676",
      "       566666776",
      "      #566666767"
    ],
    [
      "      $5        ",
      "      $5        ",
      "       5        ",
      "       5        ",
      "       5        ",
      "       5        ",
      "       5        ",
      "       5        ",
      "       5        ",
      "       5        ",
      "       5        ",
      "       5        ",
      "       5        ",
      "       5        ",
      "       5        ",
      "      #5#       "
    ],
    [
      "      $5        ",
      "      $5        ",
      "       5        ",
      "       5        ",
      "       5        ",
      "       5        ",
      "       5        ",
      "       5        ",
      "       5        ",
      "       5        ",
      "       5        ",
      "       5        ",
      "       5        ",
      "       5        ",
      "      #5#       ",
      "       5        "
    ],
    [
      "      $5        ",
      "      $5        ",
      "       5        ",
      "       5        ",
      "       5        ",
      "       5        ",
      "       5        ",
      "       5        ",
      "       5        ",
      "       5        ",
      "       5        ",
      "       5        ",
      "       5        ",
      "       5#       ",
      "      #5#       ",
      "       5        "
    ],
    [
      "       $        ",
      "       $        ",
      "       5        ",
      "       5        ",
      "       5        ",
      "       5        ",
      "       5        ",
      "       5        ",
      "       5        ",
      "       5        ",
      "       5        ",
      "       5        ",
      "       5#       ",
      "      #5##      ",
      "      #5#       ",
      "       5        "
    ],
    [
      "       $5       ",
      "       $5       ",
      "        5       ",
      "        5       ",
      "        5       ",
      "        5       ",
      "        5       ",
      "        5       ",
      "        5       ",
      "        5       ",
      "        5       ",
      "        5       ",
      "        5       ",
      "       #5#      ",
      "       #5       ",
      "        5       "
    ],
    [
      "       $$       ",
      "       $$       ",
      "        5       ",
      "        5       ",
      "        5       ",
      "        5       ",
      "        5       ",
      "        5       ",
      "        5       ",
      "        5       ",
      "        5       ",
      "        5       ",
      "        5#      ",
      "       #5##     ",
      "        5#      ",
      "        5       "
    ],
    [
      "        $5      ",
      "        $5      ",
      "         5      ",
      "         5      ",
      "         5      ",
      "         5      ",
      "         5      ",
      "         5      ",
      "         5      ",
      "         5      ",
      "         5      ",
      "         5      ",
      "         5      ",
      "        #5#     ",
      "         5      ",
      "         5      "
    ],
    [
      "        $$      ",
      "        $$      ",
      "         5      ",
      "         5      ",
      "         5      ",
      "         5      ",
      "         5      ",
      "         5      ",
      "         5      ",
      "         5      ",
      "         5      ",
      "         5      ",
      "         5#     ",
      "        #5##    ",
      "         5#     ",
      "         5      "
    ],
    [
      "         $5     ",
      "         $5     ",
      "          5     ",
      "          5     ",
      "          5     ",
      "          5     ",
      "          5     ",
      "          5     ",
      "          5     ",
      "          5     ",
      "          5     ",
      "          5     ",
      "          5#    ",
      "         #5##   ",
      "          5#    ",
      "          5     "
    ],
    [
      "                ",
      "                ",
      "                ",
      "           5    ",
      "           5    ",
      "           5    ",
      "           5    ",
      "           5    ",
      "           5    ",
      "           5    ",
      "           5    ",
      "           5    ",
      "           5#   ",
      "          #5##  ",
      "           5#   ",
      "           5    "
    ],
    [
      "                ",
      "                ",
      "                ",
      "            5   ",
      "            5   ",
      "            5   ",
      "            5   ",
      "            5   ",
      "            5   ",
      "            5   ",
      "            5   ",
      "            5   ",
      "            5###",
      "           #5## ",
      "            5#  ",
      "            5   "
    ],
    [
      "                ",
      "                ",
      "                ",
      "             5  ",
      "             55 ",
      "             55 ",
      "             55 ",
      "             55 ",
      "             55 ",
      "             55 ",
      "             55 ",
      "             55#",
      "            #55#",
      "            #55#",
      "             55 ",
      "             55 "
    ],
    [
      "                ",
      "                ",
      "                ",
      "                ",
      "                ",
      "               5",
      "               5",
      "               5",
      "               5",
      "               5",
      "               5",
      "               5",
      "             ##5",
      "             # 5",
      "               5",
      "               5"
    ],
    [
      "               $",
      "                ",
      "                ",
      "                ",
      "                ",
      "                ",
      "                ",
      "                ",
      "                ",
      "                ",
      "                ",
      "                ",
      "               #",
      "                ",
      "                ",
      "                "
    ],
    [
      "                ",
      "                ",
      "                ",
      "                ",
      "                ",
      "                ",
      "                ",
      "                ",
      "                ",
      "                ",
      "                ",
      "                ",
      "                ",
      "                ",
      "                ",
      "                "
    ],
    [
      "                ",
      "                ",
      "                ",
      "                ",
      "                ",
      "                ",
      "                ",
      "                ",
      "                ",
      "                ",
      "                ",
      "                ",
      "                ",
      "                ",
      "                ",
      "                "
    ]
  ]
}