{
  "xsize": 16,
  "zsize": 16,
  "refpalette": "lostcities:scattered",
  "slices": [
    [
      "&&&&&&&&&&&&&$$$",
      "&&&&&&&&&&&&&$$$",
      "&&&&&&&&&&&&&$$$",
      "&&&&&&&&&&&&&$$$",
      "&&&&&&&&&&&&&$$$",
      "&&&&&&&&&&&&&$$$",
      "&&&&&&&&&&&&&$$$",
      "&&&&&&&&&&&&&$$$",
      "&&&&&&&&&&&&&$$$",
      "&&&&&&&&&&&&&$$$",
      "&&&&&&&&&&&&&$$$",
      "&&&&&&&&&&&&&$$$",
      "&&&&&&&&&&&$$$$$",
      "&&&&&&&&&&&$$$$$",
      "&&&&&&&&&&&$$$$$",
      "&&&&&&&&&&&$$$$$"
    ],
    [
      "     $$  $$     ",
      "$$$$$$$$$$$$$$$$",
      "$$$$$$$  $$$$$$$",
      " b      &&&&    ",
      "&&&&&&&&&&&&    ",
      "$$$$$$$$$&&&  j ",
      "$$$$$$$$$$&&    ",
      "ccc$$$$$$$&     ",
      "$$$cc$$$$$&     ",
      "$$$$$c$$$$&     ",
      "$$$$$$c$$$&  j  ",
      "$$$$$$c$$$&     ",
      "$$$$$$$c$$Z    m",
      "$$$$$$$c$$Z     ",
      "$$$$$$$c$$Z    j",
      "$$$$$$$c$$Z     "
    ],
    [
      "     $$  $$     ",
      "ddddd$$$$$$ddddd",
      "    $$$  $$$    ",
      "                ",
      "eeeeeeeee&&     ",
      "bbbbb    &&     ",
      "bbbbbm          ",
      "bbbbb    j      ",
      "bbbb            ",
      "bbb             ",
      "baa             ",
      " a              ",
      "               n",
      "    j           ",
      "  bbbb          ",
      "bbbbbbbb        "
    ],
    [
      "     $$         ",
      "ddddd$$$$    ddd",
      "    $$$  $$$    ",
      "                ",
      "         z{     ",
      "bbb      |}     ",
      "bbbb n          ",
      "bbb             ",
      "bb j            ",
      "aaa             ",
      "aaj             ",
      "                ",
      "                ",
      "                ",
      "  bb            ",
      "bbbbbb          "
    ],
    [
      "     $$         ",
      "ddddd$$$       d",
      "    $$$         ",
      "                ",
      "         z{     ",
      "         |}     ",
      "                ",
      "                ",
      "a               ",
      "aa              ",
      "                ",
      "                ",
      "                ",
      "                ",
      "                ",
      "bbbb            "
    ],
    [
      "     $$         ",
      "ddddd$$         ",
      "    $$$         ",
      "                ",
      "         z{     ",
      "         |}     ",
      "                ",
      "                ",
      "                ",
      "                ",
      "                ",
      "                ",
      "                ",
      "                ",
      "                ",
      "bb              "
    ],
    [
      "     $          ",
      "ddddd$$         ",
      "    $$$         ",
      "                ",
      "         z{     ",
      "         |}     ",
      "                ",
      "                ",
      "                ",
      "                ",
      "                ",
      "                ",
      "                ",
      "                ",
      "                ",
      "                "
    ],
    [
      "     $          ",
      "ddddd$          ",
      "    $$$         ",
      "                ",
      "         z      ",
      "         |}     ",
      "                ",
      "                ",
      "                ",
      "                ",
      "                ",
      "                ",
      "                ",
      "                ",
      "                ",
      "b               "
    ],
    [
      "     $          ",
      "ddddd$          ",
      "    $$$         ",
      "                ",
      "         z      ",
      "         |}     ",
      "                ",
      "                ",
      "                ",
      "                ",
      "                ",
      "                ",
      "                ",
      "                ",
      "                ",
      "b               "
    ],
    [
      "     $          ",
      "ddddd$          ",
      "    $$$         ",
      "                ",
      "         z      ",
      "         |}     ",
      "                ",
      "                ",
      "                ",
      "                ",
      "                ",
      "                ",
      "                ",
      "                ",
      "                ",
      "                "
    ],
    [
      "     $          ",
      "ddddd$         d",
      "    $$$         ",
      "                ",
      "         z{     ",
      "         |}     ",
      "                ",
      "                ",
      "                ",
      "                ",
      "                ",
      "                ",
      "                ",
      "                ",
      "                ",
      "                "
    ],
    [
      "     $          ",
      "ddddd$         d",
      "    $$$         ",
      "                ",
      "         z{     ",
      "         |}     ",
      "                ",
      "                ",
      "                ",
      "                ",
      "                ",
      "                ",
      "                ",
      "                ",
      "                ",
      "                "
    ],
    [
      "                ",
      "ddddd$        dd",
      "    $$          ",
      "                ",
      "         z{     ",
      "         |}     ",
      "                ",
      "                ",
      "                ",
      "                ",
      "                ",
      "                ",
      "                ",
      "                ",
      "                ",
      "                "
    ],
    [
      "                ",
      "ddddd$       ddd",
      "    $$          ",
      "                ",
      "         z{     ",
      "         |}     ",
      "                ",
      "                ",
      "                ",
      "                ",
      "                ",
      "                ",
      "                ",
      "                ",
      "                ",
      "                "
    ],
    [
      "                ",
      "ddddd$       ddd",
      "    $$          ",
      "                ",
      "         &&     ",
      "         &&     ",
      "                ",
      "                ",
      "                ",
      "                ",
      "                ",
      "                ",
      "                ",
      "                ",
      "                ",
      "                "
    ],
    [
      "                ",
      "ddddd        ddd",
      "    $$          ",
      "hhhhhhh   h{    ",
      "&&&&&&&&&&&Ͱ    ",
      "&&&&&&&&&&&Ͱ    ",
      "$$$$$$$$$&&Ͱ    ",
      "$$$$$$$$$&&Ͱ    ",
      "$$   $$$$&&Ͱ    ",
      "$      $$&&Ͱ    ",
      "       $$&&Ͱ    ",
      "        $&&Ͱ    ",
      "        $&&ͱhhhh",
      "         &&&&&&&",
      "          &&&&&&",
      "          &&&&&&"
    ],
    [
      "                ",
      "ddddd        ddd",
      "    $$          ",
      "eeeeee     {    ",
      "         ͲͱͰ    ",
      "         |kͰ    ",
      "           ͳ    ",
      "           ͳ    ",
      "           ͳ    ",
      "           ͳ    ",
      "           ͳ    ",
      "           ͳ    ",
      "           |eeee",
      "                ",
      "                ",
      "                "
    ],
    [
      "                ",
      "ddddd        ddd",
      "    $           ",
      "                ",
      "          {     ",
      "         |}     ",
      "                ",
      "                ",
      "                ",
      "                ",
      "                ",
      "                ",
      "                ",
      "                ",
      "                ",
      "                "
    ],
    [
      "                ",
      "ddddd        ddd",
      "    $           ",
      "                ",
      "          {     ",
      "         |}     ",
      "                ",
      "                ",
      "                ",
      "                ",
      "                ",
      "                ",
      "                ",
      "                ",
      "                ",
      "                "
    ],
    [
      "                ",
      "ddddd        ddd",
      "    $           ",
      "                ",
      "          {     ",
      "         |}     ",
      "                ",
      "                ",
      "                ",
      "                ",
      "                ",
      "                ",
      "                ",
      "                ",
      "                ",
      "                "
    ],
    [
      "                ",
      "ddddd        ddd",
      "    $           ",
      "                ",
      "          {     ",
      "         |}     ",
      "                ",
      "                ",
      "                ",
      "                ",
      "                ",
      "                ",
      "                ",
      "                ",
      "                ",
      "                "
    ],
    [
      "                ",
      "ddddd        ddd",
      "    $$          ",
      "                ",
      "         z{     ",
      "         |}     ",
      "                ",
      "                ",
      "                ",
      "                ",
      "                ",
      "                ",
      "                ",
      "                ",
      "                ",
      "                "
    ],
    [
      "a               ",
      "ddddd        ddd",
      "a   $$          ",
      "                ",
      "         z{     ",
      "         |}     ",
      "                ",
      "                ",
      "                ",
      "                ",
      "                ",
      "                ",
      "                ",
      "                ",
      "                ",
      "                "
    ],
    [
      "a               ",
      "ddddd$       ddd",
      "a   $$          ",
      "                ",
      "         z{     ",
      "         |}     ",
      "                ",
      "                ",
      "                ",
      "                ",
      "                ",
      "                ",
      "                ",
      "                ",
      "                ",
      "                "
    ],
    [
      "a               ",
      "ddddd$       ddd",
      "a   $$$         ",
      "                ",
      "         z{     ",
      "         |}     ",
      "                ",
      "                ",
      "                ",
      "                ",
      "                ",
      "                ",
      "                ",
      "                ",
      "                ",
      "                "
    ],
    [
      "     $          ",
      "ddddd$       ddd",
      "    $$$         ",
      "                ",
      "         z{     ",
      "         |}     ",
      "                ",
      "                ",
      "                ",
      "                ",
      "                ",
      "                ",
      "                ",
      "                ",
      "                ",
      "                "
    ],
    [
      "$$$$$$        $$",
      "$$$$$$       $$$",
      "$$$$$$$    $$$$$",
      "                ",
      "         z{     ",
      "         |}     ",
      "                ",
      "                ",
      "                ",
      "                ",
      "                ",
      "                ",
      "                ",
      "                ",
      "                ",
      "aa              "
    ],
    [
      "$$$$$$       $$$",
      "$$$$$$      $$$$",
      "$$$$$$$    $$$$$",
      "                ",
      "         z{     ",
      "         |}     ",
      "                ",
      "                ",
      "                ",
      "                ",
      "                ",
      "                ",
      "                ",
      "                ",
      "                ",
      "aa a            "
    ],
    [
      "    $$          ",
      "    $$          ",
      "   $$$$   $$$   ",
      "                ",
      "         z{     ",
      "         |}     ",
      "                ",
      "                ",
      "                ",
      "                ",
      "                ",
      "                ",
      "                ",
      "                ",
      "                ",
      "a aa            "
    ],
    [
      "    $$$         ",
      "    $$$    $    ",
      "   $$$$  $$$$   ",
      "                ",
      "         &&     ",
      "         &&     ",
      "                ",
      "                ",
      "                ",
      "                ",
      "                ",
      "                ",
      "                ",
      "                ",
      "a aaa a         ",
      "aaaaaaa  aa     "
    ],
    [
      "      $   $$    ",
      "         $$$    ",
      "        &$$&$&&&",
      "        &&&&    ",
      " &&&&&&&&ͱͱ&    ",
      "   &&&&&&ͱͱ&    ",
      "        &&&&    ",
      "         &&     ",
      "         &&     ",
      "       aa&&     ",
      "       aa&&     ",
      "        a&&     ",
      "       aa&&     ",
      "a  aaaa  &&     ",
      "aaaaaaaa &&     ",
      "aaaaaaaaa&&aa   "
    ],
    [
      "        $$$$$$$$",
      "          $$$$$$",
      "           $$$$$",
      "            $$$$",
      "            $$$$",
      "   $$      $$$$$",
      "    $$$$$$$$$$$$",
      "        $$$$    ",
      "       a$$$$    ",
      "      aa$$$$    ",
      "      aa$$$$    ",
      "       a$$$$a   ",
      "   aaaaa$$$$aaa ",
      "aaaaaaaa$$$$aaa ",
      "aaaaaaaa$$$$aaaa",
      "aaaaaaaa$$$$aaaa"
    ],
    [
      "          llllll",
      "            llll",
      "             lll",
      "             lll",
      "             lll",
      "             lll",
      "     l      llll",
      "     lllllllllll",
      "      llllllllll",
      "      alllllllll",
      "      alllllllll",
      "    aaalllllllll",
      "   aaaalllllllll",
      "  aaaaalllllllll",
      "aaaaaaalllllllll",
      "aaaaaallllllllll"
    ],
    [
      "                ",
      "                ",
      "                ",
      "                ",
      "                ",
      "                ",
      "                ",
      "                ",
      "       a        ",
      "       aa  a    ",
      "    aa aaaaaa   ",
      "   aaaaaaaaaaa  ",
      "aaaaaaaaaaaaaaa ",
      "aaaaaaaaaaaaaaa ",
      "aaaaaaaaaaaaaaaa",
      "aaaaaaaaaaaaaaaa"
    ],
    [
      "                ",
      "                ",
      "                ",
      "                ",
      "                ",
      "                ",
      "                ",
      "                ",
      "                ",
      "        a       ",
      "       aaa a    ",
      "aaaaaa aaaaaa   ",
      "aaaaaa aaaaaaa  ",
      "aaaaaaaaaaaaa   ",
      "aaaaaaaaaaaaaa  ",
      "aaaaaaaaaaaaa   "
    ],
    [
      "                ",
      "                ",
      "                ",
      "                ",
      "                ",
      "                ",
      "                ",
      "                ",
      "                ",
      "                ",
      "        a       ",
      "        a  a    ",
      "aaaaa   a  a    ",
      "aaaaaaaaaaaa    ",
      "aaaaaaaaaaaaa   ",
      "aaaaaaaaaaaaa   "
    ]
  ]
}