{
  "xsize": 16,
  "zsize": 16,
  "refpalette": "lostcities:scattered",
  "slices": [
    [
      "                ",
      "                ",
      "                ",
      "                ",
      "                ",
      "                ",
      "                ",
      " $ $            ",
      "  $             ",
      " $ $            ",
      "                ",
      "                ",
      "                ",
      "                ",
      "                ",
      "                "
    ],
    [
      "3333332222333322",
      "3322232202333332",
      "2000022200223332",
      "0&&&02220&022332",
      "&&vv&2220&&02333",
      "&vv&02320&&02333",
      "&vv&033320&02333",
      "&&&&233320022333",
      "&&&022222222222v",
      "&&&00200022220vv",
      "&&&&000v00200vvv",
      "&&&&00&vvvvvvvvv",
      "&&&&&00vvvvvvvvv",
      "0&&&&00vvvvvvvvv",
      "0&&&&&0vvvvvvvvv",
      "0000&&0vvvvvvvvv"
    ],
    [
      "                ",
      "        '       ",
      "                ",
      "                ",
      "     __         ",
      "  $    $        ",
      "  '             ",
      "                ",
      "               #",
      "    #           ",
      "  $### $        ",
      "                ",
      "                ",
      "                ",
      "                ",
      "             #  "
    ],
    [
      "                ",
      "                ",
      "  ``            ",
      "                ",
      "                ",
      "  $    $        ",
      "                ",
      "                ",
      "                ",
      "    #           ",
      "  $### $        ",
      "                ",
      "                ",
      "                ",
      "                ",
      "                "
    ],
    [
      "                ",
      "                ",
      "   ``           ",
      "                ",
      "                ",
      "  $    $        ",
      "                ",
      "                ",
      "                ",
      "    #           ",
      "  $### $        ",
      "                ",
      "                ",
      "                ",
      "                ",
      "                "
    ],
    [
      "   ((((         ",
      "    ...         ",
      "    `..         ",
      "    ...         ",
      "   ((((         ",
      "  ((((((        ",
      " ((((((((       ",
      " ((((((((       ",
      " ((((((((       ",
      " ((((((((       ",
      "  ((((((        ",
      "   ((((         ",
      "                ",
      "                ",
      "                ",
      "                "
    ],
    [
      "   (( (         ",
      "    . .         ",
      "      .         ",
      "    . .         ",
      "   (( (         ",
      "  (    (        ",
      " (      (       ",
      " (              ",
      "        (       ",
      " (  #   (       ",
      "  (### (        ",
      "   (( (         ",
      "                ",
      "                ",
      "                ",
      "                "
    ],
    [
      "   (( (         ",
      "    . .         ",
      "      .         ",
      "    . .         ",
      "   (( (#        ",
      "  (    (        ",
      " (      (       ",
      " (              ",
      "        (       ",
      " (  #   (       ",
      "  (### (        ",
      "   (( (         ",
      "                ",
      "                ",
      "                ",
      "                "
    ],
    [
      "  #((((         ",
      "    ...         ",
      "    ...         ",
      "    ...         ",
      "   ((((#        ",
      "  (    (        ",
      " (      (       ",
      " (      (       ",
      "        (       ",
      " (  #   (       ",
      "  (### (        ",
      "   ((((         ",
      "                ",
      "                ",
      "                ",
      "                "
    ],
    [
      "  #((((        ^",
      "               ^",
      "               ^",
      "       #       ^",
      "   ((((##      ^",
      "  (    (       ^",
      " (      (      ^",
      " (      (      ^",
      " (      (       ",
      " (  ##  (       ",
      "  (####(        ",
      "   ((((         ",
      "                ",
      "                ",
      "                ",
      "                "
    ],
    [
      "  #((((         ",
      "   #            ",
      "                ",
      "       #        ",
      "   ((((##       ",
      "  (    (        ",
      " (      (       ",
      " (      (      #",
      " (      (       ",
      " (   #  (       ",
      "  ( ###(        ",
      "   ((((         ",
      "                ",
      "                ",
      "                ",
      "                "
    ],
    [
      "  #((((         ",
      "   #            ",
      "                ",
      "      ##        ",
      "   ((((##       ",
      "  ( # #(        ",
      " (      (       ",
      " (      (       ",
      " ( #    (       ",
      " ( ###  (       ",
      "  ( ###(        ",
      "   ((((         ",
      "                ",
      "                ",
      "                ",
      "                "
    ],
    [
      "  #((((         ",
      "   #            ",
      "                ",
      "      #         ",
      "   ((((#        ",
      "  ((((((        ",
      " ((((((((       ",
      " ((((((((       ",
      " ((((((((       ",
      " ((((((((       ",
      "  ((((((        ",
      "   ((((         ",
      "                ",
      "                ",
      "                ",
      "                "
    ],
    [
      "   #            ",
      "                ",
      "                ",
      "     ##         ",
      "    ####        ",
      "   ####         ",
      "    #           ",
      "    .           ",
      "   #            ",
      "   ##           ",
      "    ##          ",
      "                ",
      "                ",
      "                ",
      "                ",
      "                "
    ],
    [
      "                ",
      "                ",
      "                ",
      "    ##          ",
      "   ####         ",
      "   ###          ",
      "    #           ",
      "    .           ",
      "                ",
      "                ",
      "                ",
      "                ",
      "                ",
      "                ",
      "                ",
      "                "
    ],
    [
      "    .           ",
      "    .           ",
      "    .           ",
      "    .           ",
      "   #.#          ",
      "    .           ",
      "    .           ",
      "    .           ",
      "                ",
      "                ",
      "                ",
      "                ",
      "                ",
      "                ",
      "                ",
      "                "
    ],
    [
      "                ",
      "                ",
      "                ",
      "                ",
      "    #           ",
      "                ",
      "                ",
      "                ",
      "                ",
      "                ",
      "                ",
      "                ",
      "                ",
      "                ",
      "                ",
      "                "
    ],
    [
      "                ",
      "                ",
      "                ",
      "                ",
      "                ",
      "                ",
      "                ",
      "                ",
      "                ",
      "                ",
      "                ",
      "                ",
      "                ",
      "                ",
      "                ",
      "                "
    ]
  ]
}