{
  "xsize": 16,
  "zsize": 16,
  "refpalette": "lostcities:port",
  "slices": [
    [
      "                ",
      "                ",
      "                ",
      " 7777777777     ",
      "                ",
      "&               ",
      "&&              ",
      "&7777777777     ",
      "                ",
      "                ",
      "                ",
      " 7777777777     ",
      "                ",
      "                ",
      "    &           ",
      " 7777777777     "
    ],
    [
      " =%%%%%%%%=     ",
      " =%%%%%%%%=     ",
      " =%%%%%%%%=     ",
      " =%%%%%%%%=     ",
      " =%%%%%%%%=     ",
      "&=%%%%%%%%=     ",
      "&=%%%%%%%%=     ",
      "&=%%%%%%%%=     ",
      " =%%%%%%%%=     ",
      " =%%%%%%%%=     ",
      " =%%%%%%%%=     ",
      " =%%%%%%%%=     ",
      " =%%%%%%%%=     ",
      " =%%%%%%%%=     ",
      " =%%%%%%%%=     ",
      " ==========     "
    ],
    [
      " % &&     %     ",
      " %        %     ",
      " %        %     ",
      " %        %     ",
      "&%        %     ",
      "&=        =     ",
      "&%        %     ",
      "&%        %     ",
      " %        %     ",
      " %        %     ",
      " %        %     ",
      " %        %     ",
      " %        %     ",
      " %  &     %     ",
      " % &&&    %     ",
      " =%%%%%%%%=     "
    ],
    [
      " %  &     %     ",
      " %        %     ",
      " %        %     ",
      " %        %     ",
      "&%        %     ",
      "&=&       =     ",
      "&%        %     ",
      " %        %     ",
      " %        %     ",
      " %        %     ",
      " %        %     ",
      " %        %     ",
      " %        %     ",
      " %  &&    %     ",
      " % &&&&&  %     ",
      " =%%%%%%%%=     "
    ],
    [
      " %  &&    %     ",
      " %        %     ",
      " %        %     ",
      " %        %     ",
      "&%&       %     ",
      "&=&       =     ",
      " %        %     ",
      " %        %     ",
      " %        %     ",
      " %        %     ",
      " %        %     ",
      " %        %     ",
      " %        %     ",
      " %   &    %     ",
      " %  &&&&  %     ",
      " =%%%%%%%%=     "
    ],
    [
      " %   &&   %     ",
      " %        %     ",
      " %        %     ",
      " %        %     ",
      "&%&       %     ",
      " =        =     ",
      " %        %     ",
      " %        %     ",
      " %        %     ",
      " %        %     ",
      " %        %     ",
      " %        %     ",
      " %   &    %     ",
      " %  &&&   %     ",
      " %  &&&&  %     ",
      " =%%%%%%& =     "
    ]
  ]
}