{
  "xsize": 16,
  "zsize": 16,
  "refpalette": "lostcities:port",
  "slices": [
    [
      "       &        ",
      "                ",
      "     ZZZZZ      ",
      "   ZZZ&& ZZZ    ",
      "  ZZ  &    ZZ   ",
      " ZZ         ZZ  ",
      " Z           Z  ",
      "Z             Z ",
      "      &        Z",
      "     &&&       Z",
      "      &        Z",
      "               Z",
      "               Z",
      "               Z",
      "               Z",
      "               Z"
    ],
    [
      "      ZZZ       ",
      "    ZZZZZZZ     ",
      "   ZZ&&&  ZZ    ",
      "  Z  &&&    Z   ",
      " Z    &      Z  ",
      " Z           Z  ",
      "Z             Z ",
      "               Z",
      "      &&        ",
      "     &&&        ",
      "      &         ",
      "                ",
      "                ",
      "                ",
      "                ",
      "                "
    ],
    [
      "    Z &&&ZZ     ",
      "   Z  &&&  Z    ",
      "  Z  &&&    Z   ",
      " Z    &      Z  ",
      " Z           Z  ",
      "Z             Z ",
      "               Z",
      "       &       Z",
      "      &&&       ",
      "     &&&&       ",
      "      &&        ",
      "                ",
      "                ",
      "                ",
      "                ",
      "                "
    ],
    [
      "   Z  &&&& Z    ",
      "  Z   &&&   Z   ",
      "     &&&    Z   ",
      " Z    &      Z  ",
      "Z             Z ",
      "Z             Z ",
      "               Z",
      "       &  &&&   ",
      "      &&&   &   ",
      "      &&        ",
      "                ",
      "                ",
      "     &          ",
      "  &&            ",
      " &&             ",
      "                "
    ],
    [
      "   Z%  &%%%Z    ",
      "  Z   &%%%%%Z   ",
      " Z%  &%%%%%%%Z  ",
      " Z    &%%%%%%Z  ",
      "Z%     %%%%%%%Z ",
      "%%%     %%%%%%%Z",
      "%%%%    %%%%%%%Z",
      "%%%%   & %%%%%%%",
      "%%%%% &&&%%%%%%%",
      "%%%%%  &  %%%%%%",
      "%%%%%%    %%%%%%",
      "%%%%%%%  %%%%%%%",
      "%%%%%%%%%%%%%%%%",
      "%%%%%%%%%%%%%%%%",
      "%%%%%%%%%%%%%%%%",
      "%%%%%%%%%%%%%%%%"
    ],
    [
      "        &   [   ",
      "       &     [  ",
      " [    &&     [  ",
      "[             [ ",
      "               [",
      "               [",
      "                ",
      "       &  &&&   ",
      "  \\   &&&  &\\&  ",
      "       &    &   ",
      "                ",
      "     &          ",
      "  \\&&\\&  \\  \\   ",
      "&&&&&&          ",
      "&&&&            ",
      "&&\\  \\   \\  \\   "
    ]
  ]
}