{
  "xsize": 16,
  "zsize": 16,
  "refpalette": "lostcities:port",
  "slices": [
    [
      "          $$**  ",
      "$$$$$$$$$$$$**  ",
      "          $$**  ",
      "          $$**  ",
      "          $$**  ",
      "          $$**  ",
      "          $$**  ",
      "          $$**  ",
      "          $$**  ",
      "          $$**  ",
      "          $$**  ",
      "          $$**  ",
      "          $$**  ",
      "          $$**  ",
      "          $$**  ",
      "          $$**  "
    ],
    [
      "           $**  ",
      "$$$$$$$$$$$$**  ",
      "           $**  ",
      "           $**  ",
      "           $**  ",
      "           $**  ",
      "           $**  ",
      "           $**  ",
      "           $**  ",
      "           $**  ",
      "           $**  ",
      "           $**  ",
      "           $**  ",
      "           $**  ",
      "           $**  ",
      "           $**  "
    ],
    [
      "           $**  ",
      "$$$$$$$$$$$$**  ",
      "           $**  ",
      "           $**  ",
      "           $**  ",
      "           $**  ",
      "           $**  ",
      "           $**  ",
      "           $**  ",
      "           $**  ",
      "           $**  ",
      "           $**  ",
      "           $**  ",
      "           $**  ",
      "           $**  ",
      "           $**  "
    ],
    [
      "       &   $**  ",
      "$$$$$$$$$$$$**  ",
      "           $**  ",
      "           $**  ",
      "           $**  ",
      "           $**  ",
      "           $**  ",
      "           $**  ",
      "           $**  ",
      "           $**  ",
      "           $**  ",
      "           $**  ",
      "           $**  ",
      "           $**  ",
      "           $**  ",
      "           $**  "
    ],
    [
      "%%%%%%%%%%%%**  ",
      "%%%%%%%%%%%%**  ",
      "%%%%%%%%%%%%**  ",
      "%%%%%%%%%%%%**  ",
      "%%%%%%%%%%%%**  ",
      "%%%%%%%%%%%%**  ",
      "%%%%%%%%%%%%**  ",
      "%%%%%%%%%%%%**  ",
      "%%%%%%%%%%%%**  ",
      "%%%%%%%%%%%%**  ",
      "%%%%%%%%%%%%**  ",
      "%%%%%%%%%%%%**  ",
      "%%%%%%%%%%%%**  ",
      "%%%%%%%%%%%%**  ",
      "%%%%%%%%%%%%**  ",
      "%%%%%%%%%%%%**  "
    ],
    [
      "      &&&   **  ",
      "   77777777 **  ",
      "   77  & 77 **  ",
      "   7      7 **  ",
      "   7      7 **  ",
      "   7      7 **  ",
      "   7      7 **  ",
      "   77    77 **  ",
      "   77777777 **  ",
      "            **  ",
      "            **  ",
      "            **  ",
      "            **  ",
      "            **  ",
      "            **  ",
      "            **  "
    ]
  ]
}