{
  "xsize": 16,
  "zsize": 16,
  "refpalette": "lostcities:port",
  "slices": [
    [
      "                ",
      "                ",
      "                ",
      "                ",
      "                ",
      "                ",
      "                ",
      "         &      ",
      "        &&&     ",
      "         &      ",
      "                ",
      "                ",
      "                ",
      "                ",
      "                ",
      "                "
    ],
    [
      "                ",
      "               U",
      "                ",
      "                ",
      "                ",
      "                ",
      "                ",
      "         &      ",
      "        &&&     ",
      "         &      ",
      "                ",
      "                ",
      "                ",
      "                ",
      "                ",
      "                "
    ],
    [
      "               U",
      "                ",
      "          ----- ",
      "                ",
      "                ",
      "                ",
      "                ",
      "         &      ",
      "        &&&     ",
      "         &      ",
      "          ----- ",
      "                ",
      "                ",
      "                ",
      "                ",
      "                "
    ],
    [
      "          ----- ",
      "          ----- ",
      "          ----- ",
      "          ----- ",
      "          ----- ",
      "          ----- ",
      "          ----- ",
      "         &----- ",
      "        &&-----U",
      "         &-----U",
      "          -----U",
      "          -----U",
      "               U",
      "               U",
      "               U",
      "                "
    ],
    [
      "          ----- ",
      "          -   -U",
      "          -   -U",
      "          -   -U",
      "          -   -U",
      "          -   -U",
      "          -   -U",
      "         &-   -U",
      "        &U-UUU-U",
      "         U-UUU-U",
      "         U-UUU-U",
      "         U-----U",
      "         UUUUUUU",
      "         UUUUUUU",
      "               U",
      "                "
    ],
    [
      "          -VVV-U",
      "          -   - ",
      "          V   -U",
      "          V   -U",
      "          -   - ",
      "          -     ",
      "          -     ",
      "         &-&  - ",
      "        &&-&  - ",
      "         &-   - ",
      "          -   - ",
      "          -----U",
      "                ",
      "               U",
      "                ",
      "                "
    ]
  ]
}