{
  "xsize": 16,
  "zsize": 16,
  "refpalette": "lostcities:port",
  "slices": [
    [
      "!!!!!!!!!!!!!!!!",
      "!!!!!!!!!!!!!!!!",
      "!!!!!!!!!!!!!!!!",
      "!!!!!!!!!!!!!!!!",
      "!!!!!!!!!!!!!!!!",
      "!!!!!!!!!!!!!!!!",
      "!!!!!!!!!!!!!!!!",
      "!!!!!!!!!!!!!!!!",
      "!!!!!!!!!!!!!!!!",
      "!!!!!!!!!!!!!!!!",
      "!!!!!!!!!!!!!!!!",
      "!!!!!!!!!!!!!!!!",
      "!!!!!!!!!!!!!!!!",
      "!!!!!!!!!!!!!!!!",
      "!!!!!!!!!!!!!!!!",
      "!!!!!!!!!!!!!!!!"
    ],
    [
      "!!!!!!!!!!!!!!!!",
      "!!!!!!!!!!!!!!!!",
      "!!!!!!!!!!!!!!!!",
      "!!!!!!!!!!!!!!!!",
      "!!!!!!!!&&!!!!!!",
      "!!!!!!!!!&&!!!!!",
      "!!!!!!!!!!!!!!!!",
      "!!!!!!!!!!!!!!!!",
      "!!!!!!!!!!!!!!!!",
      "!!!!!!!!!!!!!!!!",
      "!!!!!!!!!!!!!!!!",
      "!!!!!!!!!!!!!!!!",
      "!!!!!!!!!!!!!!!!",
      "!!!!!!!!!!!!!!!!",
      "!!!!!!!!!!!!!!!!",
      "!!!!!!!!!!!!!!!!"
    ],
    [
      "!!!!ZZZZZZZ!!!!!",
      "!!!!ZZZZZZZ!!!!!",
      "!!!!ZZZZZZZ!!!!!",
      "!!!!ZZZZZZZ!!!!!",
      "!!!!ZZZZZZZ!!!!!",
      "!!!!ZZZZZZZ&&!!!",
      "!!!!ZZZZZZZ!&!!!",
      "!!!!ZZZZZZZ!!!!!",
      "!!!!ZZZZZZZ!!!!!",
      "!!!!ZZZZZZZ!!!!!",
      "!!!!ZZZZZZZ!!!!!",
      "!!!!ZZZZZZZ!!!!!",
      "!!!!ZZZZZZZ!!!!!",
      "!!!!ZZZZZZZ!!!!!",
      "!!!!ZZZZZZZ!!!!!",
      "!!!!ZZZZZZZ!!!!!"
    ],
    [
      "!!ZZ       ZZ!!!",
      "!!ZZ       ZZ!!!",
      "!!ZZ       ZZ!!!",
      "!!ZZ    &  ZZ!!!",
      "!!ZZ   &&&&ZZ!!!",
      "!!ZZ    &&&ZZ&!!",
      "!!ZZ      &ZZ&!!",
      "!!ZZ       ZZ!!!",
      "!!ZZ       ZZ!!!",
      "!!ZZ       ZZ!!!",
      "!!ZZ       ZZ!!!",
      "!!ZZ       ZZ!!!",
      "!!ZZ       ZZ!!!",
      "!!ZZ       ZZ!!!",
      "!!ZZ       ZZ!!!",
      "!!ZZ       ZZ!!!"
    ],
    [
      " Z           Z  ",
      " Z           Z  ",
      " Z           Z  ",
      " Z      &&   Z  ",
      " Z     &&&&  Z  ",
      " Z      &&&&&Z  ",
      " Z         &&Z  ",
      " Z          &Z  ",
      " Z           Z  ",
      " Z           Z  ",
      " Z           Z  ",
      " Z           Z  ",
      " Z           Z  ",
      " Z           Z  ",
      " Z           Z  ",
      " Z           Z  "
    ],
    [
      "Z             Z ",
      "Z             Z ",
      "Z             Z ",
      "Z        &    Z ",
      "Z       &&&   Z ",
      "Z        &  & Z ",
      "Z          &&&Z ",
      "Z           & Z ",
      "Z             Z ",
      "Z             Z ",
      "Z             Z ",
      "Z             Z ",
      "Z             Z ",
      "Z             Z ",
      "Z             Z ",
      "Z             Z "
    ]
  ]
}