{
  "xsize": 16,
  "zsize": 16,
  "refpalette": "lostcities:port",
  "slices": [
    [
      "%     0   0   ((",
      "%     0   0     ",
      "%     0   0     ",
      "%     0   0     ",
      "%     0   0     ",
      "%     0   0     ",
      "%     0   0     ",
      "%     0   0     ",
      "%     0   0     ",
      "%     0 & 0     ",
      "%     0 &&0     ",
      "%     0  &0     ",
      "%)))))0   0)))))",
      "****************",
      "                ",
      "                "
    ],
    [
      "%     00000     ",
      "%     00000     ",
      "%     00000     ",
      "%     00000     ",
      "%     00000     ",
      "%     00000     ",
      "%     00000     ",
      "%     00000     ",
      "%     00000     ",
      "%     00000     ",
      "%     00000     ",
      "%     00000     ",
      "%)))))00000)))))",
      "****************",
      "                ",
      "                "
    ],
    [
      "%               ",
      "%               ",
      "%               ",
      "%               ",
      "%               ",
      "%               ",
      "%               ",
      "%               ",
      "%       &       ",
      "%      &&&      ",
      "%       &&&     ",
      "%       &&&&    ",
      "%)))))))))))))))",
      "****************",
      "           &&   ",
      "                "
    ],
    [
      "% ,          ,  ",
      "% ,          ,  ",
      "% ,          ,  ",
      "% ++++++.....+  ",
      "% ,          +  ",
      "% ,          +  ",
      "% ,          +  ",
      "% ,          +  ",
      "% ,...++++...,  ",
      "%      &&&&     ",
      "%       &&&     ",
      "%        &&     ",
      "%))))))))))&&)))",
      "****************",
      "          &&&&  ",
      "           &&   "
    ],
    [
      "%%%%%%%%%%%%%%%%",
      "%%%%%%%%%%%%%%%%",
      "%%%%%%%%%%%%%%%%",
      "%%%%%%%%%%%%%%%%",
      "%%%%%%%%%%%%%%%%",
      "%%%%%%%%%%%%%%%%",
      "%%%%%%%%%%%%%%%%",
      "%%%%%%%%%%%%%%%%",
      "%%%%%%%%%%%%%%%%",
      "       &&&    %%",
      "%%%%%%%%%%&  %%%",
      "        &&      ",
      " %%%%%%%% &     ",
      "%%%%%%%%%%&&&   ",
      "           &&   ",
      "                "
    ],
    [
      "                ",
      "              33",
      "                ",
      "                ",
      "                ",
      "                ",
      "                ",
      "        &       ",
      "       &&&      ",
      "       &&&      ",
      "  8     &&    88",
      "                ",
      "                ",
      "*********       ",
      "                ",
      "                "
    ]
  ]
}