{
  "xsize": 16,
  "zsize": 16,
  "refpalette": "lostcities:port",
  "slices": [
    [
      "          888%%%",
      "          888%  ",
      "                ",
      "                ",
      "                ",
      "                ",
      "          888%  ",
      "          888%% ",
      "          888%% ",
      "          888888",
      "          888888",
      "          888888",
      "                ",
      "                ",
      "                ",
      "                "
    ],
    [
      "           &8   ",
      "           88   ",
      "                ",
      "                ",
      "                ",
      "            8   ",
      "            8   ",
      "            8   ",
      "            8   ",
      "           8888 ",
      "           8   8",
      "                ",
      "                ",
      "                ",
      "                ",
      "                "
    ],
    [
      "          &&&   ",
      "          &8    ",
      "                ",
      "                ",
      "                ",
      "           8    ",
      "                ",
      "                ",
      "                ",
      "           8    ",
      "           8   8",
      "                ",
      "                ",
      "                ",
      "                ",
      "                "
    ],
    [
      "         &&&&   ",
      "         &&8 &  ",
      "          &&&&&&",
      "              & ",
      "                ",
      "           8    ",
      "                ",
      "                ",
      "                ",
      "           8    ",
      "           8   8",
      "                ",
      "                ",
      "                ",
      "                ",
      "                "
    ],
    [
      "          888%%%",
      "         &888%%%",
      "         &888%%%",
      "          888%%%",
      "          888%%%",
      "          888%%%",
      "          888%%%",
      "          888%%%",
      "          888%%%",
      "          888888",
      "          888888",
      "          888888",
      "                ",
      "                ",
      "                ",
      "                "
    ],
    [
      "          6     ",
      "          6  &&&",
      "         &6&&&&&",
      "          6  &&&",
      "          6   & ",
      "          6     ",
      "          6     ",
      "          6     ",
      "          6     ",
      "          6     ",
      "          6     ",
      "          B33333",
      "                ",
      "                ",
      "                ",
      "                "
    ]
  ]
}