{
  "xsize": 16,
  "zsize": 16,
  "refpalette": "lostcities:port",
  "slices": [
    [
      "                ",
      "  8             ",
      "888             ",
      "  R             ",
      "  R             ",
      "  R            K",
      "  R            K",
      "  R             ",
      "  R     &&      ",
      "  R    &&&&     ",
      "  88  8 &&8  88 ",
      "         &      ",
      "                ",
      "                ",
      "                ",
      "                "
    ],
    [
      "  8             ",
      "  8             ",
      "888             ",
      "  8             ",
      "  8             ",
      "  8             ",
      "  8             ",
      "  8             ",
      "  8             ",
      "  8     &&      ",
      "8888888888888888",
      "        &&&     ",
      "         &      ",
      "                ",
      "                ",
      "                "
    ],
    [
      "%%%%%%%%%%%%%%%%",
      "%%%%%%%%%%%%%%%%",
      "%%%%%%%%%%%%%%%%",
      "%%%%%%%%%%%%%%%%",
      "%%%%%%%%%%%%%%%%",
      "%%%%%%%%%%%%    ",
      "%%%%%%%%%%%%    ",
      "%%%%%%%%%%%%%%%%",
      "%%%%%%%%%%%%%%%%",
      "8888888888888888",
      "8888888888888888",
      "8888888888888888",
      "         &      ",
      "                ",
      "                ",
      "                "
    ],
    [
      " 888 888 888 888",
      "                ",
      "                ",
      "8 88      888888",
      "   8      8     ",
      "   8      8     ",
      "   8      8     ",
      "  S8      8     ",
      "  T8      8     ",
      "   8     &8     ",
      "8888888888888888",
      "        &&&     ",
      "         &      ",
      "                ",
      "                ",
      "                "
    ],
    [
      " 888 888 888 888",
      "                ",
      "                ",
      "  88      888888",
      "   8      8     ",
      "   8      8     ",
      "   8      8     ",
      "   8      8     ",
      "   8      8     ",
      "   8     &8     ",
      "  88  8 &88  88 ",
      "         &      ",
      "                ",
      "                ",
      "                ",
      "                "
    ],
    [
      "8888888888888888",
      "                ",
      "                ",
      " 888      888888",
      "   8      8     ",
      "   8      8     ",
      "   8      8     ",
      "   8    & 8    %",
      "   8    &&8    %",
      "   8     &8     ",
      "   8  8 &88  88 ",
      "         &&     ",
      "                ",
      "                ",
      "                ",
      "                "
    ]
  ]
}