{
  "xsize": 16,
  "zsize": 16,
  "refpalette": "lostcities:port",
  "slices": [
    [
      "   **$$         ",
      "   **$$         ",
      "   **$$         ",
      "   **$$         ",
      "   **$$         ",
      "   **$$         ",
      "   **$$        %",
      "   **$$        %",
      "   **$$        %",
      "   **$$        %",
      "   **$$        %",
      "   **$$$$$$$$$$%",
      "   **          %",
      "   **          %",
      "   **          %",
      "   **          %"
    ],
    [
      "   **$          ",
      "   **$          ",
      "   **$          ",
      "   **$          ",
      "   **$          ",
      "   **$          ",
      "   **$         %",
      "   **$         %",
      "   **$         %",
      "   **$         %",
      "   **$         %",
      "   **$$$$$$$$$$%",
      "   **          %",
      "   **          %",
      "   **          %",
      "   **          %"
    ],
    [
      "   **$          ",
      "   **$          ",
      "   **$          ",
      "   **$          ",
      "   **$          ",
      "   **$          ",
      "   **$         %",
      "   **$         %",
      "   **$         %",
      "   **$         %",
      "   **$         %",
      "   **$$$$$$$$$$%",
      "   **          %",
      "   **          %",
      "   **          %",
      "   **          %"
    ],
    [
      "   **$          ",
      "   **$          ",
      "   **$          ",
      "   **$  7      7",
      "   **$          ",
      "   **$          ",
      "   **$         %",
      "   **$         %",
      "   **$         %",
      "   **$         %",
      "   **$         %",
      "   **$$$$$$$$$$%",
      "   **          %",
      "   **          %",
      "   **          %",
      "   **          %"
    ],
    [
      "   **%%%%%%%%%%%",
      "   **%%%%%%%%%%%",
      "   **%%%%%%%%%%%",
      "   **%%%%%%%%%%%",
      "   **%%%%%%%%%%%",
      "   **%%%%%%%%%%%",
      "   **%%%%%%%%%%%",
      "   **%%%%%%%%%%%",
      "   **%%%%%%%%%%%",
      "   **%%%%%%%%%%%",
      "   **%%%%%%%%%%%",
      "   **%%%%%%%%%%%",
      "   **%%%%%%%%%%%",
      "   **%%%%%%%%%%%",
      "   **%%%%%%%%%%%",
      "   **%%%%%%%%%%%"
    ],
    [
      "   **           ",
      "   **           ",
      "   **           ",
      "   **           ",
      "   ** ----------",
      "   **           ",
      "   **           ",
      "   **           ",
      "   **        v  ",
      "   **8     88888",
      "   **      8    ",
      "   **      8    ",
      "   **      8    ",
      "   **      8    ",
      "   **      8    ",
      "   **      8    "
    ]
  ]
}