{
  "xsize": 16,
  "zsize": 16,
  "refpalette": "lostcities:port",
  "slices": [
    [
      "                ",
      "                ",
      "                ",
      "                ",
      "                ",
      "                ",
      "                ",
      "               %",
      "        &      %",
      "       &&&      ",
      " 888    &&    88",
      "                ",
      "                ",
      "*********       ",
      "                ",
      "                "
    ],
    [
      "                ",
      "                ",
      "                ",
      "                ",
      "                ",
      "                ",
      "                ",
      "              %<",
      "        &&    %<",
      "       &&&&     ",
      " 888  8 &&8  888",
      "         &      ",
      "                ",
      "                ",
      "*********       ",
      "                "
    ],
    [
      "                ",
      "                ",
      "                ",
      "                ",
      "                ",
      "                ",
      "                ",
      "             %< ",
      "        &    %< ",
      "        &&      ",
      "8888888888888888",
      "        &&&     ",
      "         &      ",
      "                ",
      "                ",
      "                "
    ],
    [
      "%%%%%%%%%%%%%%%%",
      "%%%%%%%%%%%%%%%%",
      "%%%%%%%%%%%%%%%%",
      "%%%%%%%%%%%%%%%%",
      "%%%%%%%%%%%%%%%%",
      "%%%%%%%%%%%%%%%%",
      "%%%%%%%%%%%%%%%%",
      "%%%%%%%%%%%%%<  ",
      "%%%%%%%%%%%%%<  ",
      "888%%%%%%%%%%   ",
      "8888888888888888",
      "8888888888888888",
      "         &      ",
      "                ",
      "                ",
      "                "
    ],
    [
      " 88             ",
      " 88    HHHH  HHH",
      "888    JJJJ  JJJ",
      "  8             ",
      "  8             ",
      "  8          K% ",
      "  8          K% ",
      "  8     &       ",
      "  8    &&&      ",
      "  L    &&&&     ",
      "8888888888888888",
      "        &&&     ",
      "         &      ",
      "                ",
      "                ",
      "                "
    ],
    [
      "                ",
      " M8             ",
      "888             ",
      "                ",
      "                ",
      "              K%",
      "              K%",
      "                ",
      "        &       ",
      "       &&&      ",
      "  88  8 &&8  88 ",
      "         &      ",
      "                ",
      "                ",
      "                ",
      "                "
    ]
  ]
}