{
  "xsize": 16,
  "zsize": 16,
  "refpalette": "lostcities:port",
  "slices": [
    [
      "          $$**  ",
      "          $$**  ",
      "          $$**  ",
      "          $$**  ",
      "%%        $$**  ",
      "%%        $$**  ",
      "%%        $$**  ",
      "%%        $$**  ",
      "%%        $$**  ",
      "%%        $$**  ",
      "%%        $$**  ",
      "%%$$$$$$$$$$**  ",
      "%%          **  ",
      "%%          **  ",
      "%%          **  ",
      "%%          **  "
    ],
    [
      "           $**  ",
      "           $**  ",
      "           $**  ",
      "           $**  ",
      "%%         $**  ",
      "%%         $**  ",
      "%%        -$**  ",
      "%%        -$**  ",
      "%%         $**  ",
      "%%         $**  ",
      "%%         $**  ",
      "%%$$$$$$$$$$**  ",
      "%%          **  ",
      "%%          **  ",
      "%%          **  ",
      "%%          **  "
    ],
    [
      "           $**  ",
      "           $**  ",
      "           $**  ",
      "           $**  ",
      "%%         $**  ",
      "%%         $**  ",
      "%%        -$**  ",
      "%%        -$**  ",
      "%%         $**  ",
      "%%         $**  ",
      "%%         $**  ",
      "%%$$$$$$$$$$**  ",
      "%%          **  ",
      "%%          **  ",
      "%%          **  ",
      "%%          **  "
    ],
    [
      "           $**  ",
      "           $**  ",
      "       &   $**  ",
      "      &&   $**  ",
      "%%   &&    $**  ",
      "%%  &&     $**  ",
      "%%  &     -$**  ",
      "%% &&     -$**  ",
      "%%&&       $**  ",
      "%%         $**  ",
      "%%         $**  ",
      "%%$$$$$$$$$$**  ",
      "%%          **  ",
      "%%          **  ",
      "%%          **  ",
      "%%          **  "
    ],
    [
      "%%%%%%%%%%%%**  ",
      "%%%%%%%%%%%%**  ",
      "%%%%%%%%%%%%**  ",
      "%%%%%%%%%%%%**  ",
      "%%%%%%%%%%%%**  ",
      "%%%%%%%%%%%%**  ",
      "%%%%%%%%%%%%**  ",
      "%%%%%%%%%%%%**  ",
      "%%%%%%%%%%%%**  ",
      "%%%%%%%%%%%%**  ",
      "%%%%%%%%%%%%**  ",
      "%%%%%%%%%%%%**  ",
      "%%%%%%%%%%%%**  ",
      "%%%%%%%%%%%%**  ",
      "%%%%%%%%%%%%**  ",
      "%%%%%%%%%%%%**  "
    ],
    [
      "            **  ",
      "            **  ",
      "      &&    **  ",
      "     &&&    **  ",
      "----------- **  ",
      "    &&&     **  ",
      "   &&       **  ",
      " &&&&       **  ",
      "&&&v&       **  ",
      "888888     8    ",
      "     8      **  ",
      "     8      **  ",
      "9    8      **  ",
      "6    8      **  ",
      "6    8      **  ",
      "6    8      **  "
    ]
  ]
}