{
  "xsize": 16,
  "zsize": 16,
  "refpalette": "lostcities:port",
  "slices": [
    [
      "    B;     B;   ",
      "                ",
      "    25     25   ",
      "    B;     B;   ",
      "                ",
      "    25     25   ",
      "    B;     B;   ",
      "    &           ",
      "   &25     25   ",
      "   &B;     B;   ",
      "                ",
      "                ",
      "                ",
      "                ",
      "    25&&   25   ",
      "    B;&&&  B;   "
    ],
    [
      "    B;     B    ",
      "                ",
      "    25     25   ",
      "    B;     B;   ",
      "                ",
      "    25     25   ",
      "    B;     B;   ",
      "    &           ",
      "   &25     25   ",
      "  &&B;     B;   ",
      "   &&           ",
      "                ",
      "                ",
      "      &         ",
      "    25&&   25   ",
      "    B;&&&  B;   "
    ],
    [
      "    B;     B    ",
      "                ",
      "    25     25   ",
      "    B;     B;   ",
      "                ",
      "    25     25   ",
      "    B;     B;   ",
      "                ",
      "   &25     25   ",
      "  &&B;     B;   ",
      "   &            ",
      "   &            ",
      "   &&           ",
      "    &&&         ",
      "    25&&   25   ",
      "    B;&&   B;   "
    ],
    [
      "   A--          ",
      "   AAA          ",
      "   AAA          ",
      "   AAA       A  ",
      "   AAA     AAA  ",
      "   A--     --A  ",
      "   A--     --A  ",
      "   AAA     AAA  ",
      "   A--     --A  ",
      "  &A--     --A  ",
      "  &AAA     AAA  ",
      "  &AAA     AAA  ",
      "  &AAA     AAA  ",
      "   AAA     AAA  ",
      "   A--&    --A  ",
      "   A--     --A  "
    ],
    [
      "                ",
      "                ",
      "                ",
      "                ",
      "                ",
      "                ",
      "                ",
      "                ",
      "                ",
      "   &            ",
      "   &            ",
      "   &            ",
      "   &&           ",
      "    &           ",
      "    &&          ",
      "                "
    ],
    [
      "                ",
      "                ",
      "                ",
      "                ",
      "                ",
      "                ",
      "                ",
      "                ",
      "                ",
      "                ",
      "                ",
      "                ",
      "                ",
      "                ",
      "                ",
      "                "
    ]
  ]
}