{
  "xsize": 16,
  "zsize": 16,
  "refpalette": "pomkotsmechs:port",
  "slices": [
    [
      "                ",
      "                ",
      "                ",
      "                ",
      "                ",
      "                ",
      "                ",
      "                ",
      "                ",
      "  88  8   8  88 ",
      " D8             ",
      " E8             ",
      "                ",
      "                ",
      "  8             ",
      "                "
    ],
    [
      "                ",
      "                ",
      "                ",
      "                ",
      "                ",
      "                ",
      "                ",
      "                ",
      "                ",
      "8888888888888888",
      " P8             ",
      " P8             ",
      " P8             ",
      "  8             ",
      "  8             ",
      "  8             "
    ],
    [
      "                ",
      "                ",
      "                ",
      "                ",
      "                ",
      "                ",
      "                ",
      "                ",
      "8888888888888888",
      "8888888888888888",
      "8888888888888888",
      "%%%%%%%%%%%%%%%%",
      "%%%%%%%%%%%%%%%%",
      "%%%%%%%%%%%%%%%%",
      "%%%%%%%%%%%%%%%%",
      "%%%%%%%%%%%%%%%%"
    ],
    [
      "                ",
      "                ",
      "                ",
      "                ",
      "                ",
      "                ",
      "                ",
      "                ",
      "                ",
      "8888888888888888",
      "  8   8   8   8 ",
      "  8N  8N  8N  8N",
      "  8O  8O  8O  8O",
      "  8   8   8   8 ",
      "  8   8   8   8Q",
      "  8   8   8   8Q"
    ],
    [
      "                ",
      "                ",
      "                ",
      "                ",
      "                ",
      "                ",
      "                ",
      "                ",
      "                ",
      "  88  8   8  88 ",
      "  8   8   8   8 ",
      "  8   8   8   8 ",
      "  8   8   8   8 ",
      "  8   8   8   8 ",
      "  8   8   8   8Q",
      "  8   8   8   8Q"
    ],
    [
      "                ",
      "                ",
      "                ",
      "                ",
      "                ",
      "                ",
      "                ",
      "                ",
      "                ",
      "  88  8   8  88 ",
      "  8   8   8   8 ",
      "  8   8   8   8 ",
      "  8   8   8   8 ",
      "  8   8   8   8 ",
      "  8   8   8   8Q",
      "  8   8   8   8Q"
    ]
  ]
}