{
  "xsize": 16,
  "zsize": 16,
  "refpalette": "pomkotsmechs:port",
  "slices": [
    [
      " $$           $$",
      " $$           $$",
      " $$           $$",
      " $$           $$",
      " $$           $$",
      " $$           $$",
      "%$$           $$",
      "%$$$$$$$$$$$$$$$",
      "%               ",
      "%               ",
      "%               ",
      "%               ",
      "%               ",
      "%               ",
      "%             %%",
      "%     00000   %%"
    ],
    [
      " $$           $$",
      " $$           $$",
      " $$           $$",
      " $$           $$",
      " $$           $$",
      " $$           $$",
      "%$$           $$",
      "%$$$$$$$$$$$$$$$",
      "%               ",
      "%               ",
      "%               ",
      "%               ",
      "%               ",
      "%             %%",
      "%             %%",
      "%     00000   (("
    ],
    [
      " $$           $$",
      " $$           $$",
      " $$           $$",
      " $$           $$",
      " $$           $$",
      " $$           $$",
      "%$$           $$",
      "%$$$$$$$$$$$$$$$",
      "%               ",
      "%               ",
      "%               ",
      "%               ",
      "%             %%",
      "%             %%",
      "%             ((",
      "%               "
    ],
    [
      " $$           $$",
      " $$           $$",
      " $$           $$",
      " $$           $$",
      " $$           $$",
      " $$           $$",
      "%$$           $$",
      "%$$$$$$$$$$$$$$$",
      "%               ",
      "%               ",
      "%               ",
      "%             %%",
      "% ....++....,,%%",
      "% ,          ,((",
      "% ,          ,  ",
      "% ,          ,  "
    ],
    [
      "%%%%%%%%%%%%%%%%",
      "%%%%%%%%%%%%%%%%",
      "%%%%%%%%%%%%%%%%",
      "%%%%%%%%%%%%%%%%",
      "%%%%%%%%%%%%%%%%",
      "%%%%%%%%%%%%%%%%",
      "%%%%%%%%%%%%%%%%",
      "%%%%%%%%%%%%%%%%",
      "%%%%%%%%%%%%%%%%",
      "%%%%%%%%%%%%%%%%",
      "%%%%%%%%%%%%%%%%",
      "%%%%%%%%%%%%%%%%",
      "%%%%%%%%%%%%%%((",
      "%%%%%%%%%%%%%%  ",
      "%%%%%%%%%%%%%%  ",
      "%%%%%%%%%%%%%%  "
    ],
    [
      "                ",
      "                ",
      "    --     --   ",
      "    --     --   ",
      "----         ---",
      "                ",
      "                ",
      "                ",
      "                ",
      "8888888   888888",
      "                ",
      "                ",
      "                ",
      "                ",
      "                ",
      "                "
    ]
  ]
}