{
  "xsize": 16,
  "zsize": 16,
  "refpalette": "pomkotsmechs:port",
  "slices": [
    [
      "     8      **  ",
      "            **  ",
      "            **  ",
      "     8      **  ",
      "            **  ",
      "            **  ",
      "     8      **  ",
      "<    8      **  ",
      "<           **  ",
      "            **  ",
      "            **  ",
      "            **  ",
      "            **  ",
      " *************  ",
      "            **  ",
      "                "
    ],
    [
      "     8      **  ",
      "            **  ",
      "            **  ",
      "     8      **  ",
      "            **  ",
      "            **  ",
      "     8      **  ",
      "     8      **  ",
      "            **  ",
      "            **  ",
      "  8         **  ",
      "            **  ",
      "            **  ",
      "            **  ",
      "**************  ",
      "                "
    ],
    [
      "     8          ",
      "     8          ",
      "     8          ",
      "     8          ",
      "     8          ",
      "     8          ",
      "     8          ",
      "     8          ",
      "     8          ",
      "     8          ",
      "888888          ",
      "                ",
      "                ",
      "                ",
      "                ",
      "                "
    ],
    [
      "%%%% 88         ",
      "%%%% 88         ",
      "%%%% 88         ",
      "%%%% 88         ",
      "%%%% 88         ",
      "%%%% 88         ",
      "%%%% 88         ",
      "  %% 88         ",
      "  %% 88         ",
      "  %% 88         ",
      "8888888         ",
      "8888888         ",
      "                ",
      "                ",
      "                ",
      "                "
    ],
    [
      "     8          ",
      "H    8          ",
      "J    8          ",
      "     8          ",
      "     8          ",
      "     8          ",
      "     8          ",
      "     8          ",
      "     8          ",
      "     8          ",
      "888888          ",
      "                ",
      "                ",
      "                ",
      "                ",
      "                "
    ],
    [
      "     8          ",
      "                ",
      "                ",
      "     8          ",
      "                ",
      "                ",
      "     8          ",
      "     8          ",
      "                ",
      "                ",
      " 88  8          ",
      "                ",
      "                ",
      "                ",
      "                ",
      "                "
    ]
  ]
}