{
  "xsize": 16,
  "zsize": 16,
  "refpalette": "pomkotsmechs:port",
  "slices": [
    [
      "                ",
      "                ",
      "                ",
      "                ",
      "                ",
      "                ",
      "                ",
      "      &         ",
      "8888888&        ",
      "8888888    8    ",
      "8888888         ",
      "%%%%888         ",
      "%%%%888         ",
      "%%%%888         ",
      "%%%%888         ",
      "%%%%888         "
    ],
    [
      "                ",
      "                ",
      "                ",
      "                ",
      "                ",
      "                ",
      "                ",
      "     &&         ",
      "    &&&&        ",
      " 8  &8&    8    ",
      "88888&          ",
      "    8           ",
      "    8           ",
      "    88          ",
      "    8           ",
      "    8           "
    ],
    [
      "                ",
      "                ",
      "                ",
      "                ",
      "                ",
      "                ",
      "                ",
      "                ",
      "     &&         ",
      " 8  &8&    8    ",
      "     &          ",
      "                ",
      "                ",
      "     8          ",
      "                ",
      "                "
    ],
    [
      "                ",
      "                ",
      "                ",
      "                ",
      "                ",
      "                ",
      "                ",
      "      &         ",
      "     8&&        ",
      " 8  &888888888  ",
      "   &&&&         ",
      "   &            ",
      "                ",
      "     8          ",
      "                ",
      "                "
    ],
    [
      "                ",
      "                ",
      "                ",
      "                ",
      "                ",
      "                ",
      "                ",
      "     &&         ",
      "8888888&        ",
      "88888888888888  ",
      "8888888         ",
      "%%%%888         ",
      "%%%%888         ",
      "%%%%888         ",
      "%%%%888         ",
      "%%%%888         "
    ],
    [
      "                ",
      "                ",
      "                ",
      "                ",
      "                ",
      "                ",
      "                ",
      "     &&         ",
      "3333335&        ",
      "    &&68   8    ",
      "   && 6         ",
      "   &  6         ",
      "      6         ",
      "      6         ",
      "      6         ",
      "      6         "
    ]
  ]
}