{
  "xsize": 16,
  "zsize": 16,
  "refpalette": "pomkotsmechs:port",
  "slices": [
    [
      "%%%%%%%%%%%%%%%%",
      " %%%%%%%%%%%%%%%",
      " %%%%%%%%%%%%%%%",
      "  %%%%%%%%%%%%%%",
      "  %%%%%%%%%%%%%%",
      "   %%%%%%%%%%%%%",
      "   %%%%%%%%%%%%%",
      "   %%%%%%%%%%%%<",
      "    %%%%%%%%%%%<",
      "   8888888888888",
      "   8888888888888",
      "   8888888888888",
      "         &&     ",
      "                ",
      "                ",
      "                "
    ],
    [
      "                ",
      "                ",
      "               $",
      "    X    X     $",
      "               $",
      "    X    X      ",
      "        &       ",
      "       &&&      ",
      "       &&&&     ",
      "     88888888888",
      "       8&&&8    ",
      "         &&     ",
      "                ",
      "                ",
      "                ",
      "                "
    ],
    [
      "                ",
      "                ",
      "                ",
      "    YYYYYY      ",
      "    YYYYYY      ",
      "    YYYYYY      ",
      "                ",
      "        &&      ",
      "        &&&     ",
      "        &&&     ",
      "       8 &&8    ",
      "                ",
      "                ",
      "                ",
      "                ",
      "                "
    ],
    [
      "          &&&   ",
      "   &&           ",
      "&&&&            ",
      "                ",
      "                ",
      "                ",
      "                ",
      "                ",
      "         &      ",
      "        &&&     ",
      "       8&&&8    ",
      "         &&     ",
      "                ",
      "                ",
      "                ",
      "                "
    ],
    [
      "%%%%%%%%%%%%%%%%",
      "%%%%%%%%%%%%%%%%",
      "%%%%%%%%%%%%%%%%",
      "%%%%%%%%%%%%%%%%",
      "%%%%%%%%%%%%%%%%",
      "%%%%%%%%%%%%%%%%",
      "%%%%%%%%%%%%%%%%",
      "%%%%%%%%%%%%%%%%",
      "%    %%%%%%%%%%%",
      "8    88888888888",
      "8    88888888888",
      "88   88888888888",
      "          &     ",
      "                ",
      "                ",
      "                "
    ],
    [
      "    &&&UUU&&&   ",
      "   &&UUUUUUU    ",
      "&&&&&&&UUU      ",
      "      U U U     ",
      "        U       ",
      "                ",
      "                ",
      "                ",
      "         &      ",
      "         &&     ",
      "         &&&    ",
      "33   33333333333",
      "          &     ",
      "                ",
      "                ",
      "                "
    ]
  ]
}