{
  "xsize": 16,
  "zsize": 16,
  "refpalette": "pomkotsmechs:port",
  "slices": [
    [
      " $$           $$",
      " $$           $$",
      " $$           $$",
      " $$           $$",
      " $$           $$",
      " $$           $$",
      "%$$           $$",
      "%$$$$$$$$$$$$$$$",
      "%       ,,,     ",
      "%               ",
      "%               ",
      "%.             .",
      "%.             .",
      "%.             .",
      "%.             .",
      "%.      $      ."
    ],
    [
      " $$           $$",
      " $$           $$",
      " $$           $$",
      " $$           $$",
      " $$           $$",
      " $$           $$",
      "%$$           $$",
      "%$$$$$$$$$$$$$$$",
      "%               ",
      "%               ",
      "%               ",
      "%               ",
      "%               ",
      "%               ",
      "%               ",
      "%               "
    ],
    [
      " $$           $$",
      " $$           $$",
      " $$           $$",
      " $$           $$",
      " $$           $$",
      " $$           $$",
      "%$$           $$",
      "%$$$$$$$$$$$$$$$",
      "%               ",
      "%               ",
      "%               ",
      "%               ",
      "%               ",
      "%               ",
      "%               ",
      "%               "
    ],
    [
      " $$           $$",
      " $$           $$",
      " $$           $$",
      " $$           $$",
      " $$           $$",
      " $$           $$",
      "%$$           $$",
      "%$$$$$$$$$$$$$$$",
      "%%%%%%%%%%%%%%%%",
      "%%%%%%%%%%%%%%%%",
      "%%%///////////%%",
      "%%%           %%",
      "%%%           %%",
      "%%%           %%",
      "%%%           %%",
      "%%%   00000   %%"
    ],
    [
      " $$           $$",
      " $$           $$",
      " $$           $$",
      " $$           $$",
      " $$           $$",
      " $$           $$",
      "%$$           $$",
      "%$$$$$$$$$$$$$$$",
      "%               ",
      "%               ",
      "%233333333333335",
      "%6             6",
      "%6             6",
      "%6             6",
      "%6             6",
      "%6    00000    6"
    ],
    [
      " $$           $$",
      " $$           $$",
      " $$           $$",
      " $$           $$",
      " $$           $$",
      " $$           $$",
      "%$$           $$",
      "%$$$$$$   $$$$$$",
      "%               ",
      "%               ",
      "%               ",
      "%               ",
      "%               ",
      "%               ",
      "%               ",
      "%     00000   %%"
    ]
  ]
}