{
  "xsize": 16,
  "zsize": 16,
  "refpalette": "lostcities:port",
  "slices": [
    [
      "!!!!!!!!!!!!!!!!",
      "!!!!!!!!!!!!!!!!",
      "!!!!!!!!!!!!!!!!",
      "!!!!!!!!!!!!!!!!",
      "!!!!!!!!!!!!!!!!",
      "!!!!!!!!!!!!!!!!",
      "!!!!!!!!!!!!!!!!",
      "!!!!!!!!!!!!!!!!",
      "!!!!!!!!!!!!!!!!",
      "!!!!!!!!!!!!!!!!",
      "!!!!!!!!!!!!!!!!",
      "!!!!!!!!!!!!!!!!",
      "!!!!!!!!!!!!!!!!",
      "!!!!!!!!!!!!!!!!",
      "!!!!!!!!!!!!!!!!",
      "!!!!!!!!!!!!!!!!"
    ],
    [
      "!!!!!!!!!!!!!!!!",
      "!!!!!!!!!!!!!!!!",
      "!!!!!!!!!!!!!!!!",
      "!!!!!!!!!!!!!!!!",
      "!!!!!!!!!!!!!!!!",
      "!!!!!!!!!!!!!!!!",
      "!!!!!!!!!!!!!!!!",
      "!!!!!!&!!!!!!!!!",
      "!!!!!!&!!!!!!!!!",
      "!!!!!!&!!!!!!!!!",
      "!!!!!!!!!!!!!!!!",
      "!!!!!!!!!!!!!!!!",
      "!!!!!!!!!!!!!!!!",
      "!!!!!!!!!!!!!!!!",
      "!!!!!!!!!!!!!!!!",
      "!!!!!!!!!!!!!!!!"
    ],
    [
      "!!!!!!!!!!!!!!!!",
      "!!!!!!!!!!!!!!!!",
      "!!!!!!!!!!!!!!!!",
      "!!!!!!!!!!!!!!!!",
      "!!!!!!!!!!!!!!!!",
      "!!!!!!&!!!!!!!!!",
      "!!!!!!&!!!!!!!!!",
      "!!!!!&&&!!!!!!!!",
      "!!!!ZZZZZZZ!!!!!",
      "!!!!ZZZZZZZ!!!!!",
      "!!!!ZZZZZZZ!!!!!",
      "!!!!ZZZZZZZ!!!!!",
      "!!!!ZZZZZZZ!!!!!",
      "!!!!ZZZZZZZ!!!!!",
      "!!!!ZZZZZZZ!!!!!",
      "!!!!ZZZZZZZ!!!!!"
    ],
    [
      "!!!!!!!!!!!!!!!!",
      "!!!!!!!!!!!!!!!!",
      "!!!!!!!!!!!!!!!!",
      "!!!!!!!!!!!!!!!!",
      "!!!!!!&!!!!!!!!!",
      "!!!!!&&&!!!!!!!!",
      "!!!!!&ZZZ!!!!!!!",
      "!!!!ZZZZZZZ!!!!!",
      "!!ZZ  &    ZZ!!!",
      "!!ZZ &&&   ZZ!!!",
      "!!ZZ  &    ZZ!!!",
      "!!ZZ       ZZ!!!",
      "!!ZZ       ZZ!!!",
      "!!ZZ       ZZ!!!",
      "!!ZZ       ZZ!!!",
      "!!ZZ       ZZ!!!"
    ],
    [
      "                ",
      "                ",
      "                ",
      "      &         ",
      "     &&&        ",
      "     ZZZZZ      ",
      "   ZZZ&  ZZZ    ",
      "  ZZ  &    ZZ   ",
      " Z    &      Z  ",
      " Z   &&&     Z  ",
      " Z    &      Z  ",
      " Z           Z  ",
      " Z           Z  ",
      " Z           Z  ",
      " Z           Z  ",
      " Z           Z  "
    ],
    [
      "                ",
      "                ",
      "      &         ",
      "     &ZZZ       ",
      "    ZZZZZZZ     ",
      "   ZZ &   ZZ    ",
      "  Z         Z   ",
      " Z           Z  ",
      "Z     &       Z ",
      "Z    &&&      Z ",
      "Z     &       Z ",
      "Z             Z ",
      "Z             Z ",
      "Z             Z ",
      "Z             Z ",
      "Z             Z "
    ]
  ]
}