{
  "xsize": 16,
  "zsize": 16,
  "refpalette": "pomkotsmechs:port",
  "slices": [
    [
      "                ",
      "                ",
      "    25     25   ",
      "    B;     B;   ",
      "                ",
      "                ",
      "                ",
      "                ",
      "                ",
      " 888  8   8  888",
      "                ",
      "                ",
      "                ",
      "                ",
      "                ",
      "                "
    ],
    [
      "                ",
      "                ",
      "    25     25   ",
      "    B;     B;   ",
      "                ",
      "                ",
      "                ",
      "                ",
      "                ",
      " 888  8   8  888",
      "                ",
      "                ",
      "                ",
      "                ",
      "                ",
      "                "
    ],
    [
      "                ",
      "                ",
      "    25     25   ",
      "    B;     B;   ",
      "                ",
      "                ",
      "                ",
      "                ",
      "                ",
      "8888888888888888",
      "                ",
      "                ",
      "                ",
      "                ",
      "                ",
      "                "
    ],
    [
      "   AAA     AAA  ",
      "   AAA     AAA  ",
      "   A--     --A  ",
      "   A--     --A  ",
      "                ",
      "                ",
      "                ",
      "                ",
      "8888888888888888",
      "8888888888888888",
      "888             ",
      "%%%%%%%%%%%%%%%%",
      "%%%%%%%%%%%%%%%%",
      "%%%%%%%%%%%%%%%%",
      "%%%%%%%%%%%%%%%%",
      "%%%%%%%%%%%%%%%%"
    ],
    [
      "                ",
      "                ",
      "                ",
      "                ",
      "                ",
      "                ",
      "                ",
      "                ",
      "                ",
      "8888888888888888",
      "?D8             ",
      " E8             ",
      "  8             ",
      " G8    HHHH  HHH",
      " I8    JJJJ  JJJ",
      " 88             "
    ],
    [
      "                ",
      "                ",
      "                ",
      "                ",
      "                ",
      "                ",
      "                ",
      "                ",
      "                ",
      "  88  8   8  88 ",
      " D8             ",
      " E8             ",
      "                ",
      "                ",
      "  8             ",
      "                "
    ]
  ]
}