{
  "xsize": 16,
  "zsize": 16,
  "refpalette": "lostcities:port",
  "slices": [
    [
      "[%           %[ ",
      "[%           %[ ",
      "[%           %[ ",
      "[%%%%%%%%%%%%%[ ",
      "7[[[[[[[[[[[[[7 ",
      "                ",
      "                ",
      "ZZZZZZZZZZZ     ",
      "                ",
      "                ",
      "                ",
      "                ",
      "                ",
      "                ",
      "                ",
      "                "
    ],
    [
      " %           %  ",
      "                ",
      "                ",
      " %  %  %%  % %  ",
      "7             7 ",
      "                ",
      "                ",
      "Z               ",
      "                ",
      "                ",
      "                ",
      "                ",
      "                ",
      "                ",
      "                ",
      "                "
    ],
    [
      " %        [[ %  ",
      "                ",
      "                ",
      " %  %  %%  % %  ",
      "7             7 ",
      "                ",
      "                ",
      "                ",
      "                ",
      "                ",
      "                ",
      "                ",
      "                ",
      "                ",
      "                ",
      "                "
    ],
    [
      " %        [[ %  ",
      " %           %  ",
      " %           %  ",
      " %%%%%%%%%%%%%  ",
      "7             7 ",
      "                ",
      "                ",
      "                ",
      "                ",
      "                ",
      "                ",
      "                ",
      "                ",
      "                ",
      "                ",
      "                "
    ],
    [
      "[[[[[[[[[[  [[[ ",
      "[[[[[[[[[[[[[[[ ",
      "[[[[[[[[[[[[[[[ ",
      "[[[[[[[[[[[[[[[ ",
      "[[[[[[[[[[[[[[[ ",
      "                ",
      "                ",
      "                ",
      "                ",
      "                ",
      "                ",
      "                ",
      "                ",
      "                ",
      "                ",
      "                "
    ],
    [
      " %%%%%%%%%  %%  ",
      " %%%%%%%%%  %%  ",
      " %%%%%%%%%%%%%  ",
      " %%%%%%%%%%%%%  ",
      "7             7 ",
      "                ",
      "                ",
      "                ",
      "                ",
      "                ",
      "                ",
      "                ",
      "                ",
      "                ",
      "                ",
      "                "
    ]
  ]
}