{
  "xsize": 16,
  "zsize": 16,
  "refpalette": "pomkotsmechs:port",
  "slices": [
    [
      "       &        ",
      "                ",
      "                ",
      "    &           ",
      "   &25     25   ",
      "   &B;     B;   ",
      "                ",
      "                ",
      "                ",
      "                ",
      "    25     25   ",
      "    B;     B;   ",
      "                ",
      "                ",
      "            &   ",
      "           &&&  "
    ],
    [
      "      &&        ",
      "                ",
      "                ",
      "    &           ",
      "   &25     25   ",
      "  &&B;     B;   ",
      "   &&           ",
      "                ",
      "                ",
      "                ",
      "    25     25   ",
      "    B;     B;   ",
      "                ",
      "                ",
      "            &&  ",
      "           &&&  "
    ],
    [
      "                ",
      "    &&          ",
      "    &           ",
      "   &&           ",
      "   &25     25   ",
      "  &&B;     B;   ",
      "   &            ",
      "                ",
      "                ",
      "                ",
      "    25     25   ",
      "    B;     B;   ",
      "                ",
      "             &  ",
      "            &&& ",
      "           &&&& "
    ],
    [
      "   AAA     AAA  ",
      "   AAA&    AAA  ",
      "   AAA     AAA  ",
      "  &AAA     AAA  ",
      "  &A--     --A  ",
      "  &A--     --A  ",
      "   AAA     AAA  ",
      "   AAA     AAA  ",
      "   AAA     AAA  ",
      "   AAA     AAA  ",
      "   A--     --A  ",
      "   A--     --A  ",
      "   AAA     AAA  ",
      "   AAA     AAA  ",
      "   AAA     AAA& ",
      "   AAA     AAA& "
    ],
    [
      "                ",
      "    &&          ",
      "    &           ",
      "   &&           ",
      "   &            ",
      "   &            ",
      "                ",
      "                ",
      "                ",
      "                ",
      "                ",
      "                ",
      "                ",
      "                ",
      "             &  ",
      "             &  "
    ],
    [
      "                ",
      "                ",
      "                ",
      "                ",
      "                ",
      "                ",
      "                ",
      "                ",
      "                ",
      "                ",
      "                ",
      "                ",
      "                ",
      "                ",
      "                ",
      "                "
    ]
  ]
}