{
  "xsize": 16,
  "zsize": 16,
  "refpalette": "lostcities:port",
  "slices": [
    [
      "%%          **  ",
      "%%          **  ",
      "%%          **  ",
      "%%          **  ",
      "%%          **  ",
      "%%          **  ",
      "%%          **  ",
      "%%          **  ",
      "%%          **  ",
      "%%          **  ",
      "%%          **  ",
      "%%          **  ",
      "%%          **  ",
      "**************  ",
      "            **  ",
      "                "
    ],
    [
      "%%          **  ",
      "%%          **  ",
      "%%          **  ",
      "%%          **  ",
      "%%          **  ",
      "%%          **  ",
      "%%          **  ",
      "%%          **  ",
      "%%          **  ",
      "%%          **  ",
      "%%          **  ",
      "%%          **  ",
      "%%          **  ",
      "**************  ",
      "            **  ",
      "                "
    ],
    [
      "%%          **  ",
      "%%          **  ",
      "%%          **  ",
      "%%          **  ",
      "%%          **  ",
      "%%          **  ",
      "%%          **  ",
      "%%          **  ",
      "%%          **  ",
      "%%          **  ",
      "%%          **  ",
      "%%          **  ",
      "%%          **  ",
      "**************  ",
      "            **  ",
      "                "
    ],
    [
      "%%          **  ",
      "%%          **  ",
      "%%          **  ",
      "%%          **  ",
      "%%          **  ",
      "%%          **  ",
      "%%          **  ",
      "%%          **  ",
      "%%           *  ",
      "%%           *  ",
      "%%           *  ",
      "%           **  ",
      "%%          **  ",
      "**************  ",
      "            **  ",
      "                "
    ],
    [
      "%%%%%%%%%%%%**  ",
      "%%%%%%%%%%%%**  ",
      "%%%%%%%%%%%%**  ",
      "%%%%%%%%%%%%**  ",
      "%%%%%%%%%%%%**  ",
      "%%%%%%%%%%%%**  ",
      "%%%%%%%%%%%%**  ",
      "%%%%%%%%%%%%**  ",
      "%%%%    %%%%**  ",
      "%%      %%%%**  ",
      "%%%     %%%%**  ",
      "       %%%%%**  ",
      "     %%%%%%%**  ",
      " %%%%%%%%%%%**  ",
      "            **  ",
      "                "
    ],
    [
      "6    8      **  ",
      ";    8      **  ",
      "     8      **  ",
      "     8      **  ",
      "     8      **  ",
      "     8      **  ",
      "     8      **  ",
      "%<   8      **  ",
      "%<           *  ",
      "             *  ",
      "             *  ",
      "            **  ",
      "            **  ",
      "  ************  ",
      "            **  ",
      "                "
    ]
  ]
}