{
  "xsize": 16,
  "zsize": 16,
  "refpalette": "pomkotsmechs:port",
  "slices": [
    [
      "                ",
      "                ",
      "    7 &777      ",
      "    7    7      ",
      "    7    7      ",
      "                ",
      "                ",
      "    7  777      ",
      "                ",
      "                ",
      "                ",
      "                ",
      "                ",
      "                ",
      "                ",
      "                "
    ],
    [
      "                ",
      "   U            ",
      "    7   77      ",
      "    7    7      ",
      "                ",
      "                ",
      "                ",
      "    7   77      ",
      "                ",
      "                ",
      "                ",
      "                ",
      "                ",
      "                ",
      "                ",
      "                "
    ],
    [
      "   U            ",
      "                ",
      "    7    7      ",
      "                ",
      "                ",
      "                ",
      "                ",
      "    7    7      ",
      "                ",
      "                ",
      "                ",
      "                ",
      "                ",
      "                ",
      "                ",
      "                "
    ],
    [
      "                ",
      "                ",
      "    777777      ",
      "    7    7      ",
      "    7    7      ",
      "    7    7      ",
      "    7    7      ",
      "    777777      ",
      "UUUUUUUUUUU     ",
      "UUUUUUUUUUU     ",
      "UU   UU   U     ",
      "UU   UU   U     ",
      "UU   UU   U     ",
      "UUUUUUUUUUU     ",
      "UUUUUUUUUUU     ",
      "                "
    ],
    [
      "                ",
      "UUUUUUUUUUU     ",
      "UUUU777777U     ",
      "UUUU7    7U     ",
      "UUUU7    7U     ",
      "UUUU7    7U     ",
      "UUUU7    7U     ",
      "UUUU777777U     ",
      "UUUUUUUUUUU     ",
      "UUUUUUUUUUU     ",
      "UUUUUUUUUUU     ",
      "UUUUUUUUUUU     ",
      "UUUU UU   U     ",
      "UUUU UU   U     ",
      "UUUUUUUUUUU     ",
      "                "
    ],
    [
      "   U            ",
      "                ",
      "   U7    7      ",
      "   U            ",
      "                ",
      "                ",
      "                ",
      "    7    7      ",
      "    UUUUUUU     ",
      "    UUUUUUU     ",
      "    UUUUUUU     ",
      "   UUUUUUUU     ",
      "    UUUUUUU     ",
      "   UUUUUUUU     ",
      "    UUUUUUU     ",
      "                "
    ]
  ]
}