{
  "xsize": 16,
  "zsize": 16,
  "refpalette": "pomkotsmechs:port",
  "slices": [
    [
      "       ###$$    ",
      "       ###$$    ",
      "       ###$$    ",
      "       ###$$    ",
      "       ###$$    ",
      "       ###$$    ",
      "       ###$$    ",
      "       ###$$    ",
      "       ###$$    ",
      "       ###$$    ",
      "       ###$$    ",
      "       ###$$    ",
      "       ###$$    ",
      "       ###$$    ",
      "       ###$$    ",
      "       ###$$    "
    ],
    [
      "      ###$$     ",
      "      ###$$     ",
      "      ###$$     ",
      "      ###$$     ",
      "      ###$$     ",
      "      ###$$     ",
      "      ###$$     ",
      "      ###$$     ",
      "      ###$$     ",
      "      ###$$     ",
      "      ###$$     ",
      "      ###$$     ",
      "      ###$$     ",
      "      ###$$     ",
      "      ###$$     ",
      "      ###$$     "
    ],
    [
      "     ###$$      ",
      "     ###$$      ",
      "     ###$$      ",
      "     ###$$      ",
      "     ###$$      ",
      "     ###$$      ",
      "     ###$$      ",
      "     ###$$      ",
      "     ###$$      ",
      "     ###$$      ",
      "     ###$$      ",
      "     ###$$      ",
      "     ###$$      ",
      "     ###$$      ",
      "     ###$$      ",
      "     ###$$      "
    ],
    [
      "    ***$$       ",
      "    ***$$       ",
      "    ***$$       ",
      "    ***$$       ",
      "    ***$$       ",
      "    ***$$       ",
      "    ***$$       ",
      "    ***$$       ",
      "    ***$$       ",
      "    ***$$       ",
      "    ***$$       ",
      "    ***$$       ",
      "    ***$$       ",
      "    ***$$       ",
      "    ***$$       ",
      "    ***$$       "
    ],
    [
      "    **$$        ",
      "    **$$        ",
      "    **$$        ",
      "    **$$        ",
      "    **$$        ",
      "    **$$        ",
      "    **$$        ",
      "    **$$        ",
      "    **$$        ",
      "    **$$        ",
      "    **$$        ",
      "    **$$        ",
      "    **$$        ",
      "    **$$        ",
      "    **$$        ",
      "    **$$        "
    ],
    [
      "    **$         ",
      "    **$         ",
      "    **$         ",
      "    **$         ",
      "    **$         ",
      "    **$         ",
      "    **$         ",
      "    **$         ",
      "    **$         ",
      "    **$         ",
      "    **$         ",
      "    **$         ",
      "    **$         ",
      "    **$         ",
      "    **$         ",
      "    **$         "
    ]
  ]
}