{
  "xsize": 16,
  "zsize": 16,
  "refpalette": "pomkotsmechs:port",
  "slices": [
    [
      "                ",
      "    25     25   ",
      "    B;     B;   ",
      "77              ",
      "             &  ",
      "            &&& ",
      " &           & &",
      "77& 25     25   ",
      "&&& B;     B;   ",
      " &&             ",
      "                ",
      "77              ",
      "                ",
      "    25     25   ",
      "    B;     B;   ",
      "77              "
    ],
    [
      "%               ",
      "%=  25     25   ",
      "%=  B;     B;   ",
      "%               ",
      "%            &  ",
      "            &&& ",
      "%&           & &",
      "%=& 2      25   ",
      "%=& B;     B;   ",
      "%=              ",
      "%=              ",
      "%=              ",
      "%=              ",
      "%=  2      2    ",
      "%=         B    ",
      "==              "
    ],
    [
      " %              ",
      " %  25     25   ",
      "    B;     B;   ",
      "             &  ",
      "            &&& ",
      "            &&&&",
      "             & &",
      "&&  2      25   ",
      "&%& B      B    ",
      "&%              ",
      " %              ",
      " %              ",
      " %              ",
      " %  2      2    ",
      " %         B    ",
      "%=              "
    ],
    [
      " %   A     AAA  ",
      " %   -     --A  ",
      "     -     --A  ",
      "     A     AAA  ",
      "     A     AAA& ",
      "     A     AAA &",
      "           AAA  ",
      "           --A  ",
      "&% A       --   ",
      " % A       A    ",
      " % A       A    ",
      " % A       A    ",
      " % A       A    ",
      " % A            ",
      " %              ",
      "%=              "
    ],
    [
      " %              ",
      " %              ",
      "                ",
      "                ",
      "             &  ",
      "                ",
      "                ",
      "                ",
      "&%              ",
      " %              ",
      " %              ",
      " %              ",
      " %              ",
      " %              ",
      " %              ",
      "%=              "
    ],
    [
      " %              ",
      " %              ",
      " %              ",
      " %              ",
      "                ",
      "                ",
      "                ",
      " %              ",
      " %              ",
      " %              ",
      " %              ",
      " %              ",
      " %              ",
      " %              ",
      " %              ",
      "%=              "
    ]
  ]
}