{
  "xsize": 16,
  "zsize": 16,
  "refpalette": "pomkotsmechs:port",
  "slices": [
    [
      "   **          %",
      "   **          %",
      "   **          %",
      "   **          %",
      "   **          %",
      "   **          %",
      "   **          %",
      "   **          %",
      "   **          %",
      "   **          %",
      "   **          %",
      "   **          %",
      "   **          %",
      "   *************",
      "   **           ",
      "                "
    ],
    [
      "   **          %",
      "   **          %",
      "   **          %",
      "   **          %",
      "   **          %",
      "   **          %",
      "   **          %",
      "   **          %",
      "   **          %",
      "   **          %",
      "   **          %",
      "   **          %",
      "   **          %",
      "   *************",
      "   **           ",
      "                "
    ],
    [
      "   **          %",
      "   **          %",
      "   **          %",
      "   **          %",
      "   **          %",
      "   **          %",
      "   **          %",
      "   **          %",
      "   **          %",
      "   **          %",
      "   **          %",
      "   **          %",
      "   **          %",
      "   *************",
      "   **           ",
      "                "
    ],
    [
      "   **          %",
      "   **     &    %",
      "   **     &    %",
      "   **     &    %",
      "   **    &&    %",
      "   **    &     %",
      "   **          %",
      "   **          %",
      "   **          %",
      "   **          %",
      "   **          %",
      "   **           ",
      "   **          %",
      "   *************",
      "   **           ",
      "                "
    ],
    [
      "   **%%%%%%%%%%%",
      "   **%%%%%%%%%%%",
      "   **%%%%%%%%%%%",
      "   **%%%%%%%%%%%",
      "   *   %%%%%%%%%",
      "   *   %%%%%%%%%",
      "   *  %%%%%%%%%%",
      "   **%%%%%%%%%%%",
      "   **%%%%%%%%%%%",
      "   **%%%%%%%%%  ",
      "   **%%%%%%%%%  ",
      "   **%%   %%    ",
      "   **%%   %%    ",
      "   **%%   %%   %",
      "   **           ",
      "                "
    ],
    [
      "   **     &8    ",
      "   **    &&8&   ",
      "   **     &8    ",
      "   **     &8    ",
      "   *     &&8    ",
      "   *     & 8    ",
      "   *       8    ",
      "   **      8    ",
      "   **      8    ",
      "   **      8    ",
      "   **      88   ",
      "   **           ",
      "   **           ",
      "   ****        *",
      "   **           ",
      "                "
    ]
  ]
}