{
  "xsize": 16,
  "zsize": 16,
  "refpalette": "lostcities:port",
  "slices": [
    [
      "               Z",
      "               Z",
      "         &     Z",
      "        &&&    Z",
      "        &&&    Z",
      "         &  && Z",
      "           &&&&Z",
      "            && Z",
      "               Z",
      "               Z",
      "               Z",
      "               Z",
      "               Z",
      "               Z",
      "               Z",
      "               Z"
    ],
    [
      "                ",
      "                ",
      "         &      ",
      "        &&&     ",
      "         &   &  ",
      "            &&& ",
      "            &&& ",
      "             &  ",
      "                ",
      "                ",
      "                ",
      "                ",
      "                ",
      "                ",
      "                ",
      "                "
    ],
    [
      "                ",
      "                ",
      "         &&     ",
      "        &&&&    ",
      "         &&  &  ",
      "            &&& ",
      "             &  ",
      "                ",
      "                ",
      "                ",
      "                ",
      "                ",
      "                ",
      "                ",
      "                ",
      "                "
    ],
    [
      "                ",
      "                ",
      "          &     ",
      "         &&&    ",
      "          &  &  ",
      "            &&& ",
      "             &  ",
      "                ",
      "                ",
      "                ",
      "                ",
      "                ",
      "                ",
      "                ",
      "                ",
      "                "
    ],
    [
      "%%%%%%%%%%%%%%%%",
      "%%%%%%%%%%%%%  %",
      "%%%%%%%%%%%%   %",
      "%%%%%%%%%%%&   %",
      "%%%%%%%%%%%  & %",
      "%%%%%%%%%%%%&&&%",
      "%%%%%%%%%%%%%&%%",
      "%%%%%%%%%%%%%%%%",
      "%%%%%%%%%%%%%%%%",
      "%%%%%%%%%%%%%%%%",
      "%%%%%%%%%%%%%%%%",
      "%%%%%%%%%%%%%%%%",
      "%%%%%%%%%%%%%%%%",
      "%%%%%%%%%%%%%%%%",
      "%%%%%%%%%%%%%%%%",
      "%%%%%%%%%%%%%%%%"
    ],
    [
      "                ",
      "  \\  \\   \\      ",
      "          &&    ",
      "         &&&    ",
      "  \\  \\   \\&  && ",
      "            &&&&",
      "             && ",
      "                ",
      "  \\  \\   \\  \\   ",
      "                ",
      "                ",
      "  \\  \\   \\  \\   ",
      "                ",
      "                ",
      "                ",
      "  \\  \\   \\  \\   "
    ]
  ]
}