{
  "xsize": 16,
  "zsize": 16,
  "refpalette": "pomkotsmechs:port",
  "slices": [
    [
      "   **$$         ",
      "   **$$         ",
      "   **$$         ",
      "   **$$         ",
      "   **$$         ",
      "   **$$         ",
      "   **$$         ",
      "   **$$         ",
      "   **$$         ",
      "   **$$         ",
      "   **$$         ",
      "   **$$         ",
      "   **$$         ",
      "   **$$         ",
      "   **$$         ",
      "   **$$         "
    ],
    [
      "   **$          ",
      "   **$          ",
      "   **$          ",
      "   **$          ",
      "   **$          ",
      "   **$          ",
      "   **$          ",
      "   **$          ",
      "   **$          ",
      "   **$          ",
      "   **$          ",
      "   **$          ",
      "   **$          ",
      "   **$          ",
      "   **$          ",
      "   **$          "
    ],
    [
      "   **$          ",
      "   **$          ",
      "   **$          ",
      "   **$          ",
      "   **$          ",
      "   **$          ",
      "   **$          ",
      "   **$          ",
      "   **           ",
      "   **           ",
      "   **           ",
      "   **$          ",
      "   **$          ",
      "   **$          ",
      "   **$          ",
      "   **$          "
    ],
    [
      "   **$          ",
      "   **$          ",
      "   **$  7      7",
      "   **$          ",
      "   **$          ",
      "   **$          ",
      "   **$          ",
      "   **$          ",
      "   **$          ",
      "   **$  7      7",
      "   **$          ",
      "   **$          ",
      "   **$          ",
      "   **$          ",
      "   **$          ",
      "   **$          "
    ],
    [
      "   **%%%%%%%%%%%",
      "   **%%%%%%%%%%%",
      "   **%%%%%%%%%%%",
      "   **%% %%%%%%%%",
      "   **%  %%%%%%%%",
      "   **%  %%%%%%%%",
      "   **%  %%%%%%%%",
      "   **   %%%%%%%%",
      "   **   %%%%%%%%",
      "   **  %%%%%%%%%",
      "   **  %%%%%%%%%",
      "   **  %%%%%%%%%",
      "   **  %%%%%%%%%",
      "   **%%%%%%%%%%%",
      "   **%%%%%%%%%%%",
      "   **%%%%%%%%%%%"
    ],
    [
      "   **           ",
      "   **           ",
      "   **           ",
      "   **           ",
      "   **           ",
      "   **           ",
      "   **           ",
      "   **           ",
      "   **           ",
      "   **           ",
      "   **           ",
      "   **           ",
      "   **           ",
      "   **           ",
      "   **    7    7 ",
      "   **           "
    ]
  ]
}