{
  "xsize": 16,
  "zsize": 16,
  "refpalette": "lostcities:port",
  "slices": [
    [
      "%       $       ",
      "%       $       ",
      "%    --'$'--    ",
      "%      '$'      ",
      "%       $       ",
      "%.      $     %%",
      "%.   --'$'--  ((",
      "%.     '$'      ",
      "%.      $       ",
      "%.      $       ",
      "%    --'$'--    ",
      "%      '$'      ",
      "%)))))) $)))))))",
      "################",
      "                ",
      "                "
    ],
    [
      "%               ",
      "%               ",
      "%    --   --    ",
      "%               ",
      "%             %%",
      "%             ((",
      "%    --   --    ",
      "%               ",
      "%               ",
      "%               ",
      "%    --   --   .",
      "%,,,           .",
      "%)))))))))))))))",
      "################",
      "                ",
      "                "
    ],
    [
      "%               ",
      "%               ",
      "%    --   --    ",
      "%             %%",
      "%             ((",
      "%               ",
      "%    --   --    ",
      "%               ",
      "%               ",
      "%               ",
      "%    --   --    ",
      "%               ",
      "%)))))))))))))))",
      "################",
      "                ",
      "                "
    ],
    [
      "%%%   00000   %%",
      "%%%   00000   %%",
      "%%%  -00000-  %%",
      "%%%   00000   ((",
      "%%%   00000     ",
      "%%%   00000     ",
      "%%%  -00000-    ",
      "%%%   00000     ",
      "%%%   00000     ",
      "%%%   00000     ",
      "%%%  -00000-    ",
      "%%%   00000     ",
      "%)))))00000)))))",
      "**************##",
      "                ",
      "                "
    ],
    [
      "%6    0   0    6",
      "%6    0   0   %%",
      "%6    0   0   ((",
      "%6    0   0     ",
      "%6    0   0     ",
      "%6    0   0     ",
      "%6    0   0     ",
      "%6    0   0     ",
      "%6    0   0     ",
      "%6    0   0     ",
      "%6    0   0     ",
      "%6    0   0     ",
      "%)))))0   0)))))",
      "****************",
      "                ",
      "                "
    ],
    [
      "%     0   0   %%",
      "%     0   0   ((",
      "%     0   0     ",
      "%     0   0     ",
      "%     0   0     ",
      "%     0   0     ",
      "%     0   0     ",
      "%     0   0     ",
      "%     0   0     ",
      "%     0   0     ",
      "%     0   0     ",
      "%     0   0     ",
      "%)))))0   0)))))",
      "****************",
      "                ",
      "                "
    ]
  ]
}