{
  "xsize": 16,
  "zsize": 16,
  "refpalette": "lostcities:port",
  "slices": [
    [
      "                ",
      "                ",
      "                ",
      "        77777777",
      "                ",
      "                ",
      "        &       ",
      "   &&  &77777777",
      "        &      &",
      "               &",
      "                ",
      "        77777777",
      "                ",
      "                ",
      "             &  ",
      "        77777777"
    ],
    [
      "        =%%%%%%%",
      "        =%%%%%%%",
      "        =%%%%%%%",
      "        =%%%%%%%",
      "        =%%%%%%%",
      "        =%%%%%%%",
      "        =%%%%%%%",
      "       &=%%%%%%%",
      "        =%%%%%%%",
      "        =%%%%%%%",
      "        =%%%%%%%",
      "        =%%%%%%%",
      "        =%%%%%%%",
      "        =%%%%%%%",
      "        =%%%%%%%",
      "        ========"
    ],
    [
      "        %     % ",
      "        %     % ",
      "        %     % ",
      "        %     % ",
      "        %     % ",
      "        =     = ",
      "        %     % ",
      "       &%&    %&",
      "        %     %&",
      "        %     %&",
      "        %     %&",
      "        %     % ",
      "        %     % ",
      "        %     % ",
      "        %   &&% ",
      "        =%%%%%%%"
    ],
    [
      "        %     % ",
      "        %     % ",
      "        %     % ",
      "        %     % ",
      "        %     % ",
      "        =     = ",
      "       &%&    % ",
      "       &%&    %&",
      "        %     %&",
      "        %     %&",
      "        %     % ",
      "        %     % ",
      "        %     % ",
      "        %     % ",
      "        %   & % ",
      "        =%%%%%%%"
    ],
    [
      "        %     % ",
      "        %     % ",
      "        %     % ",
      "        %     % ",
      "        %     % ",
      "        =     = ",
      "       &%&    % ",
      "        %    &%&",
      "        %    &%&",
      "        %     %&",
      "        %     % ",
      "        %     % ",
      "        %     % ",
      "        %     % ",
      "        %  && % ",
      "        =%%%%%%%"
    ],
    [
      "        %     % ",
      "        %     % ",
      "        %     % ",
      "        %     % ",
      "        %     % ",
      "        =     = ",
      "       &%&    % ",
      "        %    &%&",
      "        %     %&",
      "        %     % ",
      "        %     % ",
      "        %     % ",
      "        %     % ",
      "        %     % ",
      "        %  &  % ",
      "        =%%%%%%%"
    ]
  ]
}