{
  "xsize": 16,
  "zsize": 16,
  "refpalette": "pomkotsmechs:port",
  "slices": [
    [
      "               Z",
      "               Z",
      "               Z",
      "               Z",
      "               Z",
      "               Z",
      "               Z",
      "               Z",
      "               Z",
      "               Z",
      "               Z",
      "               Z",
      "               Z",
      "               Z",
      "               Z",
      "               Z"
    ],
    [
      "                ",
      "                ",
      "                ",
      "                ",
      "                ",
      "                ",
      "                ",
      "                ",
      "                ",
      "                ",
      "                ",
      "                ",
      "                ",
      "                ",
      "                ",
      "                "
    ],
    [
      "                ",
      "                ",
      "                ",
      "                ",
      "                ",
      "                ",
      "                ",
      "                ",
      "                ",
      "                ",
      "                ",
      "                ",
      "                ",
      "                ",
      "                ",
      "                "
    ],
    [
      "                ",
      "&         &&    ",
      "           &    ",
      "                ",
      "                ",
      "                ",
      "               &",
      "                ",
      "                ",
      "                ",
      "                ",
      "                ",
      "                ",
      "                ",
      "                ",
      "                "
    ],
    [
      "%%%%%%%%%%%%%%%%",
      "%%%%%%%%%%%%%%%%",
      "%%%%%%%%%%%%%%%%",
      "%%%%%%%%%%%%%%%%",
      "%%%%%%%%%%%%%%%%",
      "%%%%%%%%%%%%%%%%",
      "%%%%%%%%%%%%%%%%",
      "%%%%%%%%%%%%%%%%",
      "%%%%%%%%%%%%%%%%",
      "%%%%%%%%%%%%%%%%",
      "%%%%%%%%%%%%%%%%",
      "%%%%%%%%%%%%%%%%",
      "%%%%%%%%%%%%%%%%",
      "%%%%%%%%%%%%%%%%",
      "%%%%%%%%%%%%%%%%",
      "%%%%%%%%%%%%%%%%"
    ],
    [
      "&         &&    ",
      "&&       &&&&   ",
      "& \\  \\   \\&&\\&  ",
      "           &&   ",
      "                ",
      "               &",
      "  \\  \\   \\  \\ &&",
      "               &",
      "&               ",
      "7[  [      [ [7 ",
      "&%%%%%%%%%%%%%  ",
      "&%%%%%%%%%%%%%& ",
      " %%%%%%%%%%%%%  ",
      " %%%%%%%%%%%%%  ",
      " %%%%%%%%%%%%%  ",
      " %%%%%%%%%%%%%  "
    ]
  ]
}