{
  "xsize": 16,
  "zsize": 16,
  "refpalette": "pomkotsmechs:base",
  "slices": [
    [
      "                ",
      "                ",
      "                ",
      "                ",
      "                ",
      "                ",
      "                ",
      "                ",
      "                ",
      "                ",
      "    gg    gg    ",
      "   gggg  gggg   ",
      "   g  g  g  g   ",
      "  gg  g  g  g   ",
      "   g  g  g  g   ",
      "   ggg    gg    "
    ],
    [
      "                ",
      "                ",
      "                ",
      "                ",
      "                ",
      "                ",
      "                ",
      "                ",
      "                ",
      "    gg    gg    ",
      "   g  g  g  g   ",
      "   g  g  g  g   ",
      "   g  g  g  g   ",
      "   gggg  gggg   ",
      "  gggg    gg    ",
      "   g            "
    ],
    [
      "                ",
      "                ",
      "                ",
      "                ",
      "                ",
      "                ",
      "                ",
      "    gg    gg    ",
      "   gggg  gggg   ",
      "   g  g  g  g   ",
      "   g  g  g  g   ",
      "   g  g  g  g   ",
      "   gggg  gggg   ",
      "    gg    gg    ",
      "                ",
      "  gg            "
    ],
    [
      "                ",
      "                ",
      "                ",
      "                ",
      "                ",
      "                ",
      "    gg    gg    ",
      "   gggg  gggg   ",
      "   g  g  g  g   ",
      "   g  g  g  g   ",
      "   g  g  g  g   ",
      "    gg    gg    ",
      "                ",
      "                ",
      "                ",
      "                "
    ],
    [
      "                ",
      "                ",
      "                ",
      "                ",
      "    gg    gg    ",
      "   gggg  gggg   ",
      "   g  g  g  g   ",
      "   g  g  g  g   ",
      "   g  g  g  g   ",
      "   gggg  gggg   ",
      "    gg    gg    ",
      "                ",
      "                ",
      "                ",
      "                ",
      "    gg    gg    "
    ],
    [
      "                ",
      "                ",
      "                ",
      "                ",
      "   g  g  g  g   ",
      "   g  g  g  g   ",
      "   g  g  g  g   ",
      "   g  g  g  g   ",
      "   gggg  gggg   ",
      "    gg    gg    ",
      "                ",
      "                ",
      "                ",
      "    gg    gg    ",
      "   gggg  gggg   ",
      "   g  g  g  g   "
    ]
  ]
}