{
  "xsize": 16,
  "zsize": 16,
  "refpalette": "pomkotsmechs:base",
  "slices": [
    [
      "nggggggggggg  gg",
      "gggggggggggggggg",
      " ggggggggggggggg",
      " gg             ",
      " gg          hi ",
      " gg          jk ",
      "ggg             ",
      "ggg             ",
      "ggg             ",
      "ggg             ",
      "ggg             ",
      "ggg             ",
      "ggg             ",
      "ggg             ",
      "ggg             ",
      "ggg             "
    ],
    [
      "gggggggggggg  gg",
      "gggggggggggggggg",
      "gggggggggggggggg",
      "ggg             ",
      "ggg          hi ",
      "ggg          jk ",
      "ggg             ",
      "ggg             ",
      "ggg             ",
      "ggg             ",
      "ggg             ",
      "ggg             ",
      "ggg             ",
      "ggg             ",
      "ggg             ",
      "ggg             "
    ],
    [
      "gg !!!!   gg  gg",
      " goooooooogggggg",
      " g g!g   ggg  gg",
      "ggg             ",
      "ggg          hi ",
      " m           jk ",
      " m              ",
      " m              ",
      " m              ",
      " m              ",
      "!m              ",
      "!m!             ",
      "!m              ",
      " m              ",
      "ggg             ",
      " g              "
    ],
    [
      " g  !!    gg  gg",
      " g !!!    gg  gg",
      " g g!g   ggg  gg",
      "ggg             ",
      "ggg          ff ",
      "             ff ",
      "                ",
      "                ",
      "                ",
      "                ",
      "!!              ",
      "!!!             ",
      "!!              ",
      "                ",
      "ggg             ",
      "                "
    ],
    [
      " g  !!!   gg  gg",
      " g !!!!   gg  gg",
      " gfgfgfffgggffgg",
      "ggg         ffff",
      "gggffffffffffxxf",
      "  fffffffffffxxf",
      "  ffffffffffffff",
      "  f          ff ",
      "  f          ff ",
      "  f          ff ",
      "! f          ff ",
      "!!f          ff ",
      "! f          ff ",
      "  f          ff ",
      "ggg          ff ",
      "             ff "
    ],
    [
      "gggggggggggggggg",
      "gggggggggggggggg",
      "gggggggggggggggg",
      "gggggggggggggggg",
      "gggggggggggggggg",
      "gggggggggggggggg",
      "gggggggggggggggg",
      "ggggͱͱͱͱͱͱͱggggg",
      "ggggͱͱͱͱͱͱͱggggg",
      "ggggͱͱͱͱͱͱͱggggg",
      "ggggͱͱͱͱͱͱͱggggg",
      "ggggͱͱͱͱͱͱͱggggg",
      "ggggͱͱͱͱͱͱͱggggg",
      "ggggͱͱͱͱͱͱͱggggg",
      "ggggͱͱͱͱͱͱͱggggg",
      "ggggͱͱͱͱͱͱͱggggg"
    ]
  ]
}