{
  "xsize": 16,
  "zsize": 16,
  "refpalette": "pomkotsmechs:base",
  "slices": [
    [
      "       g     ! g",
      "       YY  YYYYg",
      "       YYYYYYYYg",
      "       YYYYYYYYg",
      "       ggggggggg",
      "     !!!YYYYYYY ",
      "    !g!YYYYYYYY ",
      "     g!YYYYYYYY ",
      "     g YYYYYYYY ",
      "     g YYYYYYYY ",
      "     g YYYYYYYY ",
      "      gggggggggg",
      "       YYYYYYYYg",
      "       YYYYYYYYg",
      "       YYYYYYYYg",
      "       gg      g"
    ],
    [
      "        g    !!g",
      "        Y  YYYYg",
      "      ggYYYYYYYg",
      "       gYYYYYYYg",
      "        gggggggg",
      "       !YYYYYYY ",
      "     !! YYYYYYY ",
      "        YYYYYYY ",
      "        YYYYYYY ",
      "        YYYYYYY ",
      "        YYYYYYY ",
      "       ggggggggg",
      "       gYYYYYYYg",
      "       gYYYYYYYg",
      "        YYYYYYYg",
      "        g      g"
    ],
    [
      "        g    !!g",
      "        Y  YYYYg",
      "       gYYYYYYYg",
      "       gYYYYYYYg",
      "        gggggggg",
      "        YYYYYYY ",
      "        YYYYYYY ",
      "        YYYYYYY ",
      "        YYYYYYY ",
      "        YYYYYYY ",
      "        YYYYYYY ",
      "        gggggggg",
      "        YYYYYYYg",
      "        YYYYYYYg",
      "        YYYYYYYg",
      "        g      g"
    ],
    [
      "        g     !g",
      "        Y   YYYg",
      "       gYYYYYYYg",
      "       gYYYYYYYg",
      "       ggggggggg",
      "        YYYYYYY ",
      "        YYYYYYY ",
      "        YYYYYYY ",
      "        YYYYYYY ",
      "        YYYYYYY ",
      "        YYYYYYY ",
      "        gggggggg",
      "        YYYYYYYg",
      "        YYYYYYYg",
      "        YYYYYYYg",
      "        g      g"
    ],
    [
      "        g     !g",
      "        Y   YYYg",
      "       gYYYYYYYg",
      "       gYYYYYYYg",
      "       ggggggggg",
      "        YYYYYYY ",
      "        YYYYYYY ",
      "        YYYYYYY ",
      "        YYYYYYY ",
      "        YYYYYYY ",
      "        YYYYYYY ",
      "        gggggggg",
      "        YYYYYYYg",
      "        YYYYYYYg",
      "        YYYYYYYg",
      "        g      g"
    ],
    [
      "        gg    !g",
      "        YY  YYYg",
      "       gYYYYYYYg",
      "       gYYYYYYYg",
      "       ggggggggg",
      "        YYYYYYY ",
      "        YYYYYYY ",
      "         YYYYYY ",
      "         YYYYYY ",
      "        YYYYYYY ",
      "        YYYYYYY ",
      "        gggggggg",
      "        YYYYYYYg",
      "        YYYYYYYg",
      "        YYYYYYYg",
      "        gg     g"
    ]
  ]
}