{
  "xsize": 16,
  "zsize": 16,
  "refpalette": "pomkotsmechs:base",
  "slices": [
    [
      "          f     ",
      "          f     ",
      "          f  ʹff",
      "      ffffffffʹʹ",
      "      f   f  fʹʹ",
      "      f   f  fʹʹ",
      "      f   f  ʹff",
      "      f   f  f !",
      "      f!  f  f  ",
      "     !f!  f  f  ",
      "     !f!  f  f  ",
      "      f   f  f  ",
      "      f   f  f  ",
      "      f   ffffff",
      "      ffffffff  ",
      "                "
    ],
    [
      "          f     ",
      "          f     ",
      "          f  ʹʹʹ",
      "       ffffffʹʹʹ",
      "       f  f  ʹʹʹ",
      "       f  f  ʹʹʹ",
      "       f  f  ʹʹʹ",
      "       f  f  f!!",
      "      !f! f  f !",
      "     !!f! f  f  ",
      "      !f  f  f  ",
      "       f  f  f  ",
      "       f  f  f  ",
      "       f  ffffff",
      "       fffffff  ",
      "                "
    ],
    [
      "          f     ",
      "          f     ",
      "          f  n  ",
      "       ffffffff ",
      "       f  f   f ",
      "       f  f   f ",
      "       f  f  nf!",
      "       f! f   f!",
      "      !f! f   f!",
      "      !f  f   f ",
      "       f  f   f ",
      "       f  f   f ",
      "       f  f   f ",
      "       f  ffffff",
      "       ffffffff ",
      "                "
    ],
    [
      "          f     ",
      "          f     ",
      "          f  ʹʹʹ",
      "        fffffʹʹʹ",
      "        f f  ʹʹʹ",
      "        f f  ʹʹʹ",
      "        f f  ʹʹʹ",
      "       !f!f   f!",
      "      !!f!f   f!",
      "       !f f   f ",
      "        f f   f ",
      "        f f   f ",
      "        f f   f ",
      "        f ffffff",
      "        fffffff ",
      "                "
    ],
    [
      "          f     ",
      "          f     ",
      "          f  ʹff",
      "        ffffffff",
      "        f f  f f",
      "        f f  fͳͳ",
      "        f!f  ʹff",
      "       !f!f    f",
      "       !f f    f",
      "        f f    f",
      "        f f    f",
      "        f f    f",
      "        f f    f",
      "        f ffffff",
      "        ffffffff",
      "                "
    ],
    [
      "          f     ",
      "          f     ",
      "          f  ʹff",
      "         fffffff",
      "         ff  f f",
      "         ff  f f",
      "        !ff  ʹff",
      "       !!ff    f",
      "        !ff    f",
      "         ff    f",
      "         ff    f",
      "         ff    f",
      "         ff    f",
      "         fffffff",
      "         fffffff",
      "                "
    ]
  ]
}