{
  "xsize": 16,
  "zsize": 16,
  "refpalette": "lostcities:base",
  "slices": [
    [
      "ʹʹf! f          ",
      "ffʹ!!f!         ",
      "  !!!!          ",
      " !ff!f fff      ",
      "ffʹ! f   f      ",
      "ʹʹf  f   f      ",
      "ʹʹf  f   f      ",
      "ʹʹf  f  !f!     ",
      "ffʹ  f  !f      ",
      "  f  f   f      ",
      "  f  f   f      ",
      "ffʹ  f   f      ",
      "ʹʹf  f   f      ",
      "ʹʹf  f   f      ",
      "ʹʹffffffff      ",
      "ffʹ  f          "
    ],
    [
      "ʹʹʹ! f          ",
      "ʹʹʹ!!!          ",
      "  !!!           ",
      "  ff!   f       ",
      "ʹʹʹ!    f       ",
      "ʹʹʹ  f  f       ",
      "ʹʹʹ  f  f!      ",
      "ʹʹʹ  f !f!!     ",
      "ʹʹʹ  f !f!      ",
      "  f  f  f       ",
      "  f  f  f       ",
      "ʹʹʹ  f  f       ",
      "ʹʹʹ  f  f       ",
      "ʹʹʹ  f  f       ",
      "ʹʹʹffffff       ",
      "ʹʹʹ  f          "
    ],
    [
      "   !!f          ",
      "  n!!!          ",
      "  !!!           ",
      " fff            ",
      " fn             ",
      " f      f       ",
      " f   f  f       ",
      " f   f  f!      ",
      " fn  f !f!      ",
      " f   f !f!      ",
      " f   f  f       ",
      " fn  f  f       ",
      " f   f  f       ",
      " f   f  f       ",
      " ffffffff       ",
      "  n  f          "
    ],
    [
      "ʹʹʹ !f          ",
      "ʹʹʹ!!!          ",
      "  !!!!          ",
      " ff!!           ",
      "ʹʹʹ             ",
      "ʹʹʹ             ",
      "ʹʹʹ  f f        ",
      "ʹʹʹ  f f        ",
      "ʹʹʹ  f f!       ",
      " f   f!f!!      ",
      " f   f f!       ",
      "ʹʹʹ  f f        ",
      "ʹʹʹ  f f        ",
      "ʹʹʹ  f f        ",
      "ʹʹʹfffff        ",
      "ʹʹʹ  f          "
    ],
    [
      "ͳͳf !f          ",
      "ffʹ!!!          ",
      "   !!!          ",
      "fff !           ",
      "ffʹ             ",
      "f f             ",
      "f f             ",
      "ͳͳf  f f        ",
      "ffʹ  f f        ",
      "f    f!f!       ",
      "f    f!f!       ",
      "ffʹ  f!f!       ",
      "f f  f!f        ",
      "f f  f f        ",
      "ͳͳffffff        ",
      "ffʹ  f          "
    ],
    [
      "  f !f          ",
      "ffʹ!!!!         ",
      "   !!!          ",
      "ffff!           ",
      "ffʹ             ",
      "f f  f          ",
      "f f  f          ",
      "f f  ff         ",
      "ffʹ  ff         ",
      "f    ff!        ",
      "f    ff!        ",
      "ffʹ  ff!!       ",
      "f f  ff!        ",
      "f f  ff         ",
      "fffffff         ",
      "ffʹ  f          "
    ]
  ]
}