{
  "xsize": 16,
  "zsize": 16,
  "refpalette": "pomkotsmechs:base",
  "slices": [
    [
      "Ͷ!       ͶYͶ    ",
      "Ͷ        ͶYͶ    ",
      " Ͷ      ͶYYͶ    ",
      " ͶͶ    ͶͶY  Ͷ   ",
      "   ͶͶͶͶYYY  Ͷ   ",
      "      ͶY     Ͷ  ",
      "      ͶY      Ͷ ",
      "       Y       Ͷ",
      "       Y        ",
      "       Y      ͶͶ",
      "             Ͷ  ",
      "            Ͷ   ",
      "       Y    Ͷ   ",
      "            Ͷ   ",
      "            Ͷ   ",
      "             Ͷ  "
    ],
    [
      "Ͷ        ͶYͶ    ",
      "Ͷ        ͶYͶ    ",
      " Ͷ      ͶYYͶ    ",
      " ͶͶ    ͶͶY  Ͷ   ",
      "   ͶͶͶͶYYY  Ͷ   ",
      "      ͶY     Ͷ  ",
      "      ͶY      Ͷ ",
      "       Y       Ͷ",
      "       Y        ",
      "       Y      ͶͶ",
      "             Ͷ  ",
      "            Ͷ   ",
      "            Ͷ   ",
      "            Ͷ   ",
      "            Ͷ   ",
      "             Ͷ  "
    ],
    [
      "Ͷ        ͶYͶ    ",
      "Ͷ        ͶYͶ    ",
      " Ͷ      ͶYYͶ    ",
      " ͶͶ    ͶͶY  Ͷ   ",
      "   ͶͶͶͶYYY  Ͷ   ",
      "      ͶY     Ͷ  ",
      "      ͶY      Ͷ ",
      "       Y       Ͷ",
      "       Y        ",
      "              ͶͶ",
      "             Ͷ  ",
      "            Ͷ   ",
      "            Ͷ   ",
      "            Ͷ   ",
      "            Ͷ   ",
      "             Ͷ  "
    ],
    [
      "Ͷ        ͶYͶ    ",
      "Ͷ        ͶYͶ    ",
      " Ͷ      ͶYYͶ    ",
      " ͶͶ    ͶͶY  Ͷ   ",
      "   ͶͶͶͶYYY  Ͷ   ",
      "      ͶY     Ͷ  ",
      "      ͶY      Ͷ ",
      "      ͶY       Ͷ",
      "       Y        ",
      "              ͶͶ",
      "             Ͷ  ",
      "            Ͷ   ",
      "            Ͷ   ",
      "            Ͷ   ",
      "            Ͷ   ",
      "             Ͷ  "
    ],
    [
      "Ͷ        ͶYͶ    ",
      "Ͷ        ͶYͶ    ",
      " Ͷ      ͶYYͶ    ",
      " ͶͶ    ͶͶY  Ͷ   ",
      "   ͶͶͶͶYYY  Ͷ   ",
      "      ͶY     Ͷ  ",
      "      ͶY      Ͷ ",
      "      ͶY       Ͷ",
      "      ͶY        ",
      "      ͶY      ͶͶ",
      "       Y     Ͷ  ",
      "            Ͷ   ",
      "            Ͷ   ",
      "            Ͷ   ",
      "            Ͷ   ",
      "             Ͷ  "
    ],
    [
      "Ͷ        ͶYͶ    ",
      "Ͷ        ͶYͶ    ",
      " Ͷ      ͶYYͶ    ",
      " ͶͶ    ͶͶY  Ͷ   ",
      "   ͶͶͶͶYYY  Ͷ   ",
      "      ͶY     Ͷ  ",
      "      ͶY      Ͷ ",
      "      ͶY       Ͷ",
      "      ͶY        ",
      "       Y      ͶͶ",
      "             Ͷ  ",
      "            Ͷ   ",
      "            Ͷ   ",
      "            Ͷ   ",
      "            Ͷ   ",
      "             Ͷ  "
    ]
  ]
}