{
  "xsize": 16,
  "zsize": 16,
  "refpalette": "pomkotsmechs:base",
  "slices": [
    [
      "                ",
      "                ",
      "      g  g      ",
      "    ggg  gg     ",
      "   gggg  gg     ",
      "   gggg  ggg    ",
      "  ggggg  ggggg  ",
      "   !!!      !!  ",
      "    !      !!!! ",
      "      g  ggggg  ",
      "     gg  gggg   ",
      "     gg  gggg   ",
      "     gg  ggg    ",
      "      g  g!     ",
      "                ",
      "                "
    ],
    [
      "                ",
      "                ",
      "      gggg      ",
      "    gggggg      ",
      "   ggggggg      ",
      "   ggggggg      ",
      "  gggggggggggg  ",
      "   !gggggggggg  ",
      "   !!ggggggggg! ",
      "    !ggggggggg  ",
      "     gggggggg   ",
      "     gggggggg   ",
      "    gggggggg    ",
      "      gggg!     ",
      "                ",
      "                "
    ],
    [
      "                ",
      "                ",
      "                ",
      "      ggg       ",
      "     gggg       ",
      "    ggggg       ",
      "   ggggggg      ",
      "    ggggggggg   ",
      "   !ggggggggg!  ",
      "    ggggggggg   ",
      "    gggggggg    ",
      "     gggggg     ",
      "      gggg!!    ",
      "         !!     ",
      "                ",
      "                "
    ],
    [
      "                ",
      "                ",
      "                ",
      "                ",
      "      ggg       ",
      "     ggg        ",
      "    gggg        ",
      "    ggggg  g    ",
      "   !gggggggg    ",
      "    gggggggg    ",
      "     gggggg     ",
      "      gggg!     ",
      "        !!!     ",
      "         !      ",
      "                ",
      "                "
    ],
    [
      "                ",
      "                ",
      "                ",
      "                ",
      "                ",
      "                ",
      "      gg        ",
      "      ggg       ",
      "    !!gggg      ",
      "      gggg      ",
      "        !       ",
      "        !!      ",
      "         !      ",
      "                ",
      "                ",
      "                "
    ],
    [
      "                ",
      "                ",
      "                ",
      "                ",
      "                ",
      "                ",
      "                ",
      "                ",
      "                ",
      "                ",
      "                ",
      "                ",
      "                ",
      "                ",
      "                ",
      "                "
    ]
  ]
}