{
  "xsize": 16,
  "zsize": 16,
  "refpalette": "pomkotsmechs:base",
  "slices": [
    [
      "vvvvvvvvvvvvvvvv",
      "vvvvvvvvvvvvvvvv",
      "vvvvvvvvvvvvvvvv",
      "vvvvvvvvvvvvvvvv",
      "vvvvvvvvvvvvvvvv",
      "vvvvvvvvvvvvvvvv",
      "vvvvvvvvvvvvvvvv",
      "vvvvvvvvvvvvvvvv",
      "vvvvvvvvvvvvvvvv",
      "vvvvvvvvvvvvvvvv",
      "vvvvvvvvvvvvvvvv",
      "vvvvvvvvvvvvvvvv",
      "vvvvvvvvvvvvvvvv",
      "vvvvvvvvvvvvvvvv",
      "vvvvvvvvvvvvvvvv",
      "vvvvvvvvvvvvvvvv"
    ],
    [
      "ffffffff   fffff",
      "ffffffffffffffff",
      "ffffffffffffffff",
      "ffffffffffffffff",
      "ffffffffffffffff",
      "ffffffffffffffff",
      "ffffffffffffffff",
      "ffffffffffffffff",
      "ffffffffffffffff",
      "ffffffffffffffff",
      "ffffffffffffffff",
      "ffffffffffffffff",
      "ffffffffffffffff",
      "ffffffffffffffff",
      "ffffffffffffffff",
      "lfffffffffffffff"
    ],
    [
      " g              ",
      "ggg             ",
      " m              ",
      " m              ",
      " m              ",
      " m              ",
      " m              ",
      " m              ",
      " m              ",
      " m              ",
      " mg          ff ",
      "gggffffffffffff ",
      "ggg             ",
      "gggggggggggg  gg",
      "gggggggggggggggg",
      "gg        gg !gg"
    ],
    [
      " g              ",
      "ggg             ",
      " m              ",
      " m              ",
      " m              ",
      " m              ",
      " m              ",
      " m              ",
      " m              ",
      " m              ",
      "!mg          ff ",
      "gggppppppppppff ",
      "ggg             ",
      " g        gg!!gg",
      " gqqqqqqqqgggggg",
      "ng        gg!!gg"
    ],
    [
      " g              ",
      "ggg             ",
      " m              ",
      " m              ",
      " m              ",
      " m              ",
      " m              ",
      " m              ",
      " m              ",
      " m              ",
      "!mg          hi ",
      "ggg          jk ",
      "ggg             ",
      " g        gg! gg",
      " gqqqqqqqqgggggg",
      " g        gg!!gg"
    ],
    [
      " g              ",
      "ggg             ",
      " m              ",
      " m              ",
      " m              ",
      " m              ",
      " m              ",
      " m              ",
      " m              ",
      " m              ",
      "!mg          hi ",
      "ggg          jk ",
      "ggg             ",
      " g        gg! gg",
      " gqqqqqqqqgggggg",
      " g        gg! gg"
    ]
  ]
}