{
  "xsize": 16,
  "zsize": 16,
  "refpalette": "pomkotsmechs:base",
  "slices": [
    [
      "                ",
      "            Ͷ   ",
      "            Ͷ   ",
      "           Ͷ    ",
      "           Ͷ    ",
      "          Ͷ     ",
      "         Ͷ      ",
      "Ͷ      ͶͶ       ",
      " ͶͶͶͶͶͶ         ",
      "                ",
      "gg     gggg     ",
      "  g   g    g    ",
      "  g   g    g    ",
      "  g   g    g    ",
      "  g   g    g    ",
      "gg     gggg     "
    ],
    [
      "                ",
      "            Ͷ   ",
      "            Ͷ   ",
      "           Ͷ    ",
      "           Ͷ    ",
      "          Ͷ     ",
      "         Ͷ      ",
      "Ͷ      ͶͶ       ",
      " ͶͶͶͶͶͶ         ",
      "                ",
      "g       gg      ",
      " g     g  g     ",
      "  g   g    g    ",
      "  g   g    g    ",
      " g     g  g     ",
      "g       gg      "
    ],
    [
      "                ",
      "            Ͷ   ",
      "            Ͷ   ",
      "           Ͷ    ",
      "           Ͷ    ",
      "          Ͷ     ",
      "         Ͷ      ",
      "Ͷ      ͶͶ       ",
      " ͶͶͶͶͶͶ         ",
      "                ",
      "                ",
      "gg     gggg     ",
      " g     g  g     ",
      " g     g  g     ",
      "gg     gggg     ",
      "                "
    ],
    [
      "            Ͷ   ",
      "            Ͷ   ",
      "            Ͷ   ",
      "           Ͷ    ",
      "           Ͷ    ",
      "          Ͷ     ",
      "         Ͷ      ",
      "Ͷ      ͶͶ       ",
      " ͶͶͶͶͶͶ         ",
      "   YY           ",
      "   YY           ",
      "g  YY   gg      ",
      " g YY  g  g     ",
      " g YY  g  g     ",
      "g  YY   gg      ",
      "   YY           "
    ],
    [
      "            Ͷ   ",
      "            Ͷ   ",
      "            Ͷ   ",
      "           Ͷ    ",
      "           Ͷ    ",
      "          Ͷ     ",
      "         Ͷ      ",
      "Ͷ      ͶͶ       ",
      " ͶͶͶͶͶͶ         ",
      "                ",
      "                ",
      "g       gg      ",
      " g     g  g     ",
      " g     g  g     ",
      "g       gg      ",
      "                "
    ],
    [
      "            Ͷ   ",
      "            Ͷ   ",
      "            Ͷ   ",
      "           Ͷ    ",
      "           Ͷ    ",
      "          Ͷ     ",
      "         Ͷ      ",
      "Ͷ      ͶͶ       ",
      " ͶͶͶͶͶͶ         ",
      "                ",
      "                ",
      "                ",
      "g       gg      ",
      "g       gg      ",
      "                ",
      "                "
    ]
  ]
}