{
  "xsize": 16,
  "zsize": 16,
  "refpalette": "lostcities:base",
  "slices": [
    [
      "vvvvvvvvvvvvvvvv",
      "vvvvvvvvvvvvvvvv",
      "vvvvvvvvvvvvvvvv",
      "vvvvvvvvvvvvvvvv",
      "vvvvvvvvvvvvvvvv",
      "vvvvvvvvvvvvvvvv",
      "vvvvvvvvvvvvvvvv",
      "vvvvvvvvvvvvvvvv",
      "vvvvvvvvvvvvvvvv",
      "vvvvvvvvvvvvvvvv",
      "vvvvvvvvvvvvvvvv",
      "vvvvvvvvvvvvvvvv",
      "vvvvvvvvvvvvvvvv",
      "vvvvvvvvvvvvvvvv",
      "vvvvvvvvvvvvvvvv",
      "vvvvvvvvvvvvvvvv"
    ],
    [
      "                ",
      "                ",
      "                ",
      "                ",
      "                ",
      "                ",
      "                ",
      "                ",
      "             !  ",
      "            !!!#",
      "             !!!",
      "                ",
      "                ",
      "                ",
      "                ",
      "              !!"
    ],
    [
      "                ",
      "                ",
      "                ",
      "                ",
      "                ",
      "                ",
      "                ",
      "                ",
      "              ! ",
      "             !!$",
      "               !",
      "                ",
      "                ",
      "                ",
      "               !",
      "              !!"
    ],
    [
      "                ",
      "                ",
      "                ",
      "                ",
      "                ",
      "                ",
      "                ",
      "              ! ",
      "              ! ",
      "              !$",
      "               !",
      "                ",
      "                ",
      "                ",
      "               !",
      "               !"
    ],
    [
      "                ",
      "                ",
      "               %",
      "               %",
      "               &",
      "               '",
      "              ('",
      "              ('",
      "              ('",
      "              ('",
      "              ('",
      "             )('",
      "             *('",
      "             '('",
      "             '('",
      "             '('"
    ],
    [
      "                ",
      "               +",
      "               v",
      "              ,v",
      "              ''",
      "              ''",
      "              ''",
      "              ''",
      "              ''",
      "             (''",
      "             *''",
      "             *''",
      "             '''",
      "            -'''",
      "            ''''",
      "           (''''"
    ]
  ]
}