{
  "xsize": 16,
  "zsize": 16,
  "refpalette": "lostcities:base",
  "slices": [
    [
      "                ",
      "fffffff         ",
      "fffffff         ",
      "     ff         ",
      "     f          ",
      "                ",
      "ffʹ             ",
      "ʹʹf!            ",
      "ʹʹf! ff         ",
      "ʹʹf  ff         ",
      "ffʹ  ff         ",
      "     ff         ",
      "fffffff         ",
      "ffʹ  f          ",
      "ʹʹf  f          ",
      "ʹʹf  f          "
    ],
    [
      "                ",
      "fffffff         ",
      "fffffff         ",
      "     ff         ",
      "                ",
      "                ",
      "ʹʹʹ             ",
      "ʹʹʹ!            ",
      "ʹʹʹ!            ",
      "ʹʹʹ   f         ",
      "ʹʹʹ  ff         ",
      "     ff         ",
      "fffffff         ",
      "ʹʹʹ  f          ",
      "ʹʹʹ  f          ",
      "ʹʹʹ  f          "
    ],
    [
      "                ",
      "ffffff          ",
      "ffffff          ",
      "     f          ",
      "                ",
      "                ",
      "                ",
      " !!             ",
      "!!!             ",
      " !              ",
      "     f          ",
      "     f          ",
      "ffffff          ",
      "     f          ",
      "     f          ",
      "     f          "
    ],
    [
      "                ",
      "ffffff          ",
      "ffffff          ",
      "ffffff          ",
      "fffff           ",
      "fff             ",
      "ff              ",
      "ff              ",
      "ff!             ",
      "ff              ",
      "                ",
      "   fff          ",
      "  ffff          ",
      "  ffff          ",
      " fffff          ",
      "ffffff          "
    ],
    [
      "                ",
      "fffff           ",
      "    f           ",
      "    f           ",
      "    f           ",
      "                ",
      " !              ",
      "!!!             ",
      "!!!             ",
      " !              ",
      "                ",
      "                ",
      "    f           ",
      "                ",
      "                ",
      "                "
    ],
    [
      "                ",
      "fffff           ",
      "f   f           ",
      "f   f           ",
      "f   f           ",
      "f               ",
      "f!              ",
      "f!!             ",
      "f!              ",
      "f               ",
      "                ",
      "                ",
      "                ",
      "                ",
      "                ",
      "                "
    ]
  ]
}