{
  "xsize": 16,
  "zsize": 16,
  "refpalette": "pomkotsmechs:base",
  "slices": [
    [
      "                ",
      "                ",
      "      !         ",
      "     !ͶͶͶͶ      ",
      "     ͶͶͶͶͶͶ     ",
      "     ͶͶͶͶͶͶ     ",
      "     ͶͶͶͶͶͶ     ",
      "     ͶͶͶͶͶͶ     ",
      "      ͶͶͶͶ      ",
      "       ͲͲ       ",
      "    Ͳ  ͲͲ  Ͳ    ",
      "   ͲͲͲͲͲͲͲͲͲͲ   ",
      "    Ͳ      Ͳ    ",
      "    Ͳ  !   Ͳ    ",
      "   ͲͲͲͲͲͲͲͲͲͲ   ",
      "    Ͳ  !   Ͳ    "
    ],
    [
      "                ",
      "                ",
      "      !         ",
      "     !ͶͶͶͶ      ",
      "     ͶͶͶͶͶͶ     ",
      "     ͶͶͶͶͶͶ     ",
      "     ͶͶͶͶͶͶ     ",
      "     ͶͶͶͶͶͶ     ",
      "      ͶͶͶͶ      ",
      "                ",
      "                ",
      "    Ͳ      Ͳ    ",
      "                ",
      "       !!       ",
      "    Ͳ !!!! Ͳ    ",
      "       !!       "
    ],
    [
      "                ",
      "                ",
      "      !         ",
      "     !ͶͶͶͶ      ",
      "     ͶͶͶͶͶͶ     ",
      "     ͶͶͶͶͶͶ     ",
      "     ͶͶͶͶͶͶ     ",
      "     ͶͶͶͶͶͶ     ",
      "      ͶͶͶͶ      ",
      "                ",
      "                ",
      "    Ͳ      Ͳ    ",
      "                ",
      "        !       ",
      "    Ͳ  !!! Ͳ    ",
      "        !       "
    ],
    [
      "                ",
      "                ",
      "     !!         ",
      "    !!g! g      ",
      "    !g!gggg     ",
      "     !gggg      ",
      "      gggg      ",
      "     g gg g     ",
      "      g  g      ",
      "                ",
      "    Ͳ      Ͳ    ",
      "   ͲͲͲͲͲͲͲͲͲͲ   ",
      "    Ͳ      Ͳ    ",
      "    Ͳ   !  Ͳ    ",
      "   ͲͲͲͲͲͲͲͲͲͲ   ",
      "    Ͳ   !  Ͳ    "
    ],
    [
      "                ",
      "                ",
      "                ",
      "     !ͶͶͶͶ      ",
      "     ͶͶͶͶͶͶ     ",
      "     ͶͶͶͶͶͶ     ",
      "     ͶͶͶͶͶͶ     ",
      "     ͶͶͶͶͶͶ     ",
      "      ͶͶͶͶ      ",
      "                ",
      "                ",
      "    Ͳ      Ͳ    ",
      "                ",
      "        !       ",
      "    Ͳ  !!! Ͳ    ",
      "        !       "
    ],
    [
      "                ",
      "                ",
      "                ",
      "     !ͶͶͶͶ      ",
      "    !ͶͶͶͶͶͶ     ",
      "     ͶͶͶͶͶͶ     ",
      "     ͶͶͶͶͶͶ     ",
      "     ͶͶͶͶͶͶ     ",
      "      ͶͶͶͶ      ",
      "                ",
      "                ",
      "    Ͳ      Ͳ    ",
      "                ",
      "        !       ",
      "    Ͳ  !!! Ͳ    ",
      "        !       "
    ]
  ]
}