{
  "xsize": 16,
  "zsize": 16,
  "refpalette": "pomkotsmechs:base",
  "slices": [
    [
      "vvvvvvvvvvvvvvvv",
      "vvvvvvvvvvvvvvvv",
      "vvvvvvvvvvvvvvvv",
      "vvvvvvvvvvvvvvvv",
      "vvvvvvvvvvvvvvvv",
      "vvvvvvvvvvvvvvvv",
      "vvvvvvvvvvvvvvvv",
      "vvvvvvvvvvvvvvvv",
      "vvvvvvvvvvv vvvv",
      "vvvvvvvvvvv vvvv",
      "vvvvvvvvvv   vvv",
      "vvvvvvvvv     vv",
      "vvvvvvvvvv  vvvv",
      "vvvvvvvvvvvvvvvv",
      "vvvvvvvvvvvvvvvv",
      "vvvvvvvvvvvvvvvv"
    ],
    [
      "                ",
      " n     n      n ",
      "              ! ",
      "  ͳͳ ͳͳ  ͳͳ ͳͳ!!",
      "  ͳͳ ͳͳ  ͳͳ ͳͳ! ",
      "         !      ",
      "  ͳͳ ͳͳ !ͳͳ ͳͳ  ",
      "  ͳͳ ͳͳ  ͳͳ ͳͳ  ",
      "                ",
      "  ͳͳ ͳͳ  ͳ   ͳ  ",
      "  ͳͳ ͳͳ  ͳ      ",
      "  !!!!!         ",
      "  ͳͳ!ͳͳ! ͳ      ",
      "  ͳͳ!ͳͳ  ͳͳ ͳͳ  ",
      " n     n      n ",
      "                "
    ],
    [
      "                ",
      " n     n      n ",
      "              ! ",
      "  ͳͳ ͳͳ  ͳͳ ͳͳ!!",
      "  ͳͳ ͳͳ   ͳ ͳͳ! ",
      "       !!!      ",
      "  ͳͳ ͳͳ!!!ͳ ͳͳ  ",
      "  ͳͳ ͳͳ !ͳͳ ͳͳ  ",
      "                ",
      "  ͳͳ ͳͳ  ͳͳ ͳͳ  ",
      "  ͳͳ!ͳͳ  ͳ      ",
      "  !!! !         ",
      "  ͳ!!!ͳ! ͳ      ",
      "  ͳͳ ͳͳ  ͳͳ ͳͳ  ",
      " n     n      n ",
      "                "
    ],
    [
      "                ",
      " gggggggggggggg ",
      " gggggggggggggg ",
      " ggggggg gggggg!",
      " ggggggg!gggggg ",
      " ggggggg!! gggg ",
      " gggggggggggggg ",
      " gggggggggggggg ",
      " g   gggggggggg ",
      "  gg gggggggggg ",
      "   ! gggggg     ",
      "   ! !!gggg     ",
      " gg  !ggggg     ",
      " ggg ggggggggg  ",
      " ggg gggggggggg ",
      "                "
    ],
    [
      "                ",
      "                ",
      "             !! ",
      "  ͳͳ ͳͳ!  ͳ ͳͳ!!",
      "  ͳͳ ͳͳ!! ͳ ͳͳ! ",
      "      !!!       ",
      "  ͳͳ ͳͳ!! ͳ ͳͳ  ",
      "  ͳͳ ͳͳ  ͳͳ ͳͳ  ",
      "                ",
      "     ͳͳ  ͳͳ ͳ   ",
      "    !!ͳ  ͳͳ     ",
      "    !!!!        ",
      "     !ͳ  ͳͳ     ",
      "  ͳͳ  ͳ  ͳͳ ͳ   ",
      "                ",
      "                "
    ],
    [
      "                ",
      "                ",
      "      !      !  ",
      "  ͳͳ ͳͳ! ͳͳ ͳͳ! ",
      "  ͳͳ ͳͳ!  ͳ ͳͳ! ",
      "      !!     !  ",
      "  ͳͳ ͳͳ  ͳͳ ͳͳ  ",
      "  ͳͳ ͳͳ  ͳͳ ͳͳ  ",
      "                ",
      "     ͳͳ  ͳͳ     ",
      "    !ͳͳ  ͳͳ     ",
      "     !!         ",
      "  ͳ   ͳ  ͳͳ     ",
      "  ͳͳ ͳͳ  ͳͳ ͳ   ",
      "                ",
      "                "
    ]
  ]
}