{
  "xsize": 16,
  "zsize": 16,
  "refpalette": "lostcities:base",
  "slices": [
    [
      "gggggvvvvvvggggg",
      "gggggvvvvvvggggg",
      "ggggggggvvvggggg",
      "gggggvvvvvvggggg",
      "gggggvvvvvvggggg",
      "vvvvvvvvYYvvvgvv",
      "vvvvvYYYgYvvvgvv",
      "vvvvvYgYYYvvvgvv",
      "vvgvvYgYYgYvvvvv",
      "vvgvvYYYYYYvvvvv",
      "vvgvvvvvvvvvvvvv",
      "gggggvvvvvvggggg",
      "gggggvvvvvvggggg",
      "gggggggggggggggg",
      "gggggvvvvvvggggg",
      "gggggvvvvvvggggg"
    ],
    [
      "  g          g  ",
      " ggg        ggg ",
      "gggggYYYYYYggggg",
      " gggg       ggg ",
      "  g          g  ",
      "  Y         !Y! ",
      "  Y    gg    Y  ",
      " !Y   gYYg   Y  ",
      "  Y   gYYg   Y  ",
      "  Y    gg    Y  ",
      "  Y          Y  ",
      "  g          g  ",
      " ggg    !   ggg ",
      "gggggYYYYYYggggg",
      " ggg    !   ggg ",
      "  g          g  "
    ],
    [
      "  g          g  ",
      " ggg        ggg ",
      "gggggYYYYYYggggg",
      " gggg       ggg ",
      "  g          g  ",
      "  Y         !Y! ",
      "  Y    gg    Y  ",
      " !Y   g  g   Y  ",
      "  Y   g  g   Y  ",
      "  Y    gg    Y  ",
      "  Y          Y  ",
      "  g          g  ",
      " ggg    !   ggg ",
      "gggggYYYYYYggggg",
      " ggg    !   ggg ",
      "  g          g  "
    ],
    [
      "  g          g  ",
      " ggg        ggg ",
      "gggggggggggggggg",
      " ggg        ggg ",
      "  g          g  ",
      "  g         !g! ",
      " !g!   gg   !g! ",
      "  g   g  g   g  ",
      "  g   g  g   g  ",
      "  g    gg    g  ",
      "  g          g  ",
      "  g          g  ",
      " ggg    !   ggg ",
      "gggggggggggggggg",
      " ggg    !   ggg ",
      "  g          g  "
    ],
    [
      "  g          g  ",
      " ggg         gg ",
      "gggggYYYY   gggg",
      "  g         ggg ",
      "  g          g  ",
      "  Y          Y  ",
      " !Y!   gg   !Y! ",
      "!!Y!  g  g   Y  ",
      " !Y!  g  g   Y  ",
      "  Y    gg    Y  ",
      "  Y          Y  ",
      "             g  ",
      "  g     !!  ggg ",
      "gggggYYYYYYggggg",
      " ggg    !!  ggg ",
      "  g          g  "
    ],
    [
      "  g          g  ",
      " ggg         gg ",
      "gggggYYY     ggg",
      "  g         ggg ",
      "             g  ",
      "             Y  ",
      "  !    gg   !Y! ",
      "!!Y!  g  g   Y  ",
      " !Y!  g  g   Y  ",
      "  Y    gg    Y  ",
      "  Y          Y  ",
      "                ",
      "         !   g  ",
      "   ggYYYYYYgggg ",
      " ggg     !  ggg ",
      "  g          g  "
    ]
  ]
}