{
  "xsize": 16,
  "zsize": 16,
  "refpalette": "lostcities:base",
  "slices": [
    [
      "                ",
      "                ",
      "fffffq   qqfffff",
      "                ",
      "                ",
      "                ",
      "fʹ            ʹf",
      "ʹf            fʹ",
      "ʹf            fʹ",
      "ʹf            fʹ",
      "fʹ            ʹf",
      "                ",
      "                ",
      "fʹ            ʹf",
      "ʹf            fʹ",
      "ʹf            fʹ"
    ],
    [
      "                ",
      "                ",
      "fffffq   qqfffff",
      "                ",
      "                ",
      "                ",
      "ʹʹ            ʹʹ",
      "ʹʹ            ʹʹ",
      "ʹʹ            ʹʹ",
      "ʹʹ            ʹʹ",
      "ʹʹ            ʹʹ",
      "                ",
      "                ",
      "ʹʹ            ʹʹ",
      "ʹʹ            ʹʹ",
      "ʹʹ            ʹʹ"
    ],
    [
      "                ",
      "                ",
      "fffffqqqqqqfffff",
      "                ",
      "                ",
      "                ",
      " n            n ",
      "                ",
      "                ",
      "                ",
      " n            n ",
      "                ",
      "                ",
      " n            n ",
      "                ",
      "                "
    ],
    [
      "                ",
      "                ",
      "fffffqqqqqqfffff",
      "                ",
      "                ",
      "                ",
      "ʹʹ            ʹʹ",
      "ʹʹ            ʹʹ",
      "ʹʹ            ʹʹ",
      "ʹʹ            ʹʹ",
      "ʹʹ            ʹʹ",
      "                ",
      "                ",
      "ʹʹ            ʹʹ",
      "ʹʹ            ʹʹ",
      "ʹʹ            ʹʹ"
    ],
    [
      "                ",
      "                ",
      "ffffffffffffffff",
      "                ",
      "                ",
      "                ",
      "fʹ            ʹf",
      " f            f ",
      " f            f ",
      " f            f ",
      "fʹ            ʹf",
      "                ",
      "                ",
      "fʹ            ʹf",
      " f            f ",
      " f            f "
    ],
    [
      "                ",
      "                ",
      "fffffff  fffffff",
      "                ",
      "                ",
      "                ",
      "fʹ            ʹf",
      " f            f ",
      " f            f ",
      " f            f ",
      "fʹ            ʹf",
      "                ",
      "                ",
      "fʹ            ʹf",
      " f            f ",
      " f            f "
    ]
  ]
}