{
  "xsize": 16,
  "zsize": 16,
  "refpalette": "pomkotsmechs:base",
  "slices": [
    [
      "͵vvvvvvvv       ",
      "͵͵vvvvvvv       ",
      "͵͵͵vvvvvvv      ",
      "͵͵͵vvfffffff    ",
      "͵͵͵͵vfvvvvff    ",
      "͵͵͵͵vfvvvvff    ",
      "͵͵͵͵vfvvvvff    ",
      "͵͵͵͵vfvvvvff    ",
      "͵͵͵͵vfvvvvff    ",
      "͵͵͵͵vfvvvvff    ",
      "͵͵͵vvfvvvvff    ",
      "͵͵͵vvfvvv ff    ",
      "͵͵vvvfvvv ff    ",
      "͵vvvvfvv  ff    ",
      "vvvvvfffffff    ",
      "vvvvvvv         "
    ],
    [
      "ffffff          ",
      "ffffff!         ",
      "ffffff          ",
      "ffffffffffff    ",
      "ffffff     f    ",
      "ffffff     f    ",
      "ffffff     f    ",
      "ffffff     f    ",
      "ffffff     f    ",
      "ffffff     f    ",
      "ffffff     f    ",
      "ffffff     f    ",
      "ffffff     f    ",
      "ffffff     f    ",
      "ffffffffffff    ",
      "ffffff          "
    ],
    [
      "     f          ",
      " !n!!f!         ",
      "!!!!!f          ",
      "!!!!fffffff     ",
      " !n ff    f     ",
      "    ff    f     ",
      "    ff    f     ",
      "    ff    f     ",
      "  n ff    f     ",
      "    ff    f     ",
      "    ff    f     ",
      "  n ff    f     ",
      "    ff    f     ",
      "    ff    f     ",
      "    fffffff     ",
      "  n  f          "
    ],
    [
      "ʹʹʹ  f          ",
      "ʹʹʹ !f!         ",
      " !!!!f          ",
      " !!ffffffff     ",
      "ʹʹʹf f    f     ",
      "ʹʹʹf f    f     ",
      "ʹʹʹf f    f     ",
      "ʹʹʹf f    f     ",
      "ʹʹʹf f    f     ",
      "   f f    f     ",
      "   f f    f     ",
      "ʹʹʹf f    f     ",
      "ʹʹʹf f    f     ",
      "ʹʹʹf f    f     ",
      "ʹʹʹffffffff     ",
      "ʹʹʹ  f          "
    ],
    [
      "ͳͳf !f          ",
      "ffʹ!!f!         ",
      " !!!!f          ",
      " !!fffffff      ",
      "ffʹf f   f      ",
      "  ff f   f      ",
      "  ff f   f      ",
      "ͳͳff f   f      ",
      "ffʹf f   f      ",
      "   f f   f      ",
      "   f f   f      ",
      "ffʹf f   f      ",
      "  ff f   f      ",
      "  ff f   f      ",
      "ͳͳffffffff      ",
      "ffʹ  f          "
    ],
    [
      "  f !f          ",
      "ffʹ!!f!         ",
      " !!!!f          ",
      " !ffffffff      ",
      "ffʹ  f   f      ",
      "  f  f   f      ",
      "  f  f   f      ",
      "  f  f   f      ",
      "ffʹ  f   f      ",
      "  f  f   f      ",
      "  f  f   f      ",
      "ffʹ  f   f      ",
      "  f  f   f      ",
      "  f  f   f      ",
      "  ffffffff      ",
      "ffʹ  f          "
    ]
  ]
}