{
  "xsize": 16,
  "zsize": 16,
  "refpalette": "pomkotsmechs:base",
  "slices": [
    [
      "gggggggggggggggg",
      "gggggggggggggggg",
      "gggggggggggggggg",
      "                ",
      "                ",
      "                ",
      "                ",
      "                ",
      "                ",
      "                ",
      "                ",
      "                ",
      "                ",
      "                ",
      "                ",
      "                "
    ],
    [
      "gggggggggggggggg",
      "gggggggggggggggg",
      "gggggggggggggggg",
      "                ",
      "                ",
      "                ",
      "                ",
      "                ",
      "                ",
      "                ",
      "                ",
      "                ",
      "                ",
      "                ",
      "                ",
      "                "
    ],
    [
      "g              g",
      "goooooooooooooog",
      "ggg g      g ggg",
      "                ",
      "                ",
      "                ",
      "                ",
      "                ",
      "                ",
      "                ",
      "                ",
      "                ",
      "                ",
      "                ",
      "                ",
      "                "
    ],
    [
      "g              g",
      "g              g",
      "ggg g      g ggg",
      "                ",
      "                ",
      "                ",
      "                ",
      "                ",
      "                ",
      "                ",
      "                ",
      "                ",
      "                ",
      "                ",
      "                ",
      "                "
    ],
    [
      "g              g",
      "g              g",
      "fggffffffffffggf",
      "                ",
      "ffffffffffffffff",
      "ffffffffffffffff",
      "                ",
      "                ",
      "                ",
      "                ",
      "                ",
      "                ",
      "                ",
      "                ",
      "                ",
      "                "
    ],
    [
      "gggggggggggggggg",
      "gggggggggggggggg",
      "gggggggggggggggg",
      "gggggggggggggggg",
      "gggggggggggggggg",
      "gggggggggggggggg",
      "gggggggggggggggg",
      "gͱͱͱͱͱͱͱͱͱͱͱͱͱͱg",
      "gͱͱͱͱͱͱͱͱͱͱͱͱͱͱg",
      "gͱͱͱͱͱͱͱͱͱͱͱͱͱͱg",
      "gͱͱͱͱͱͱͱͱͱͱͱͱͱͱg",
      "gͱͱͱͱͱͱͱͱͱͱͱͱͱͱg",
      "gͱͱͱͱͱͱͱͱͱͱͱͱͱͱg",
      "gͱͱͱͱͱͱͱͱͱͱͱͱͱͱg",
      "gͱͱͱͱͱͱͱͱͱͱͱͱͱͱg",
      "gͱͱͱͱͱͱͱͱͱͱͱͱͱͱg"
    ]
  ]
}