{
  "xsize": 16,
  "zsize": 16,
  "refpalette": "lostcities:base",
  "slices": [
    [
      "ggggggggggggg   ",
      "ggggggggggggg   ",
      "ggggggggggggg   ",
      "gggggggggggg    ",
      "gggggggggggg    ",
      "ggggggggggg     ",
      "gggggggggg      ",
      "ggggggggg       ",
      " gggggg         ",
      "                ",
      "                ",
      "                ",
      "                ",
      "                ",
      "                ",
      "                "
    ],
    [
      "ggggggggggggg   ",
      "ggggggggggggg   ",
      "ggggggggggggg   ",
      "gggggggggggg    ",
      "gggggggggggg    ",
      "ggggggggggg     ",
      "gggggggggg      ",
      "ggggggggg       ",
      " gggggg         ",
      "                ",
      "                ",
      "                ",
      "                ",
      "                ",
      "                ",
      "                "
    ],
    [
      "            Ͷ   ",
      "            Ͷ   ",
      "            Ͷ   ",
      "           Ͷ    ",
      "           Ͷ    ",
      "          Ͷ     ",
      "         Ͷ      ",
      "Ͷ      ͶͶ       ",
      " ͶͶͶͶͶͶ         ",
      "                ",
      "                ",
      "                ",
      "                ",
      "                ",
      "                ",
      "                "
    ],
    [
      "            Ͷ   ",
      "            Ͷ   ",
      "            Ͷ   ",
      "           Ͷ    ",
      "           Ͷ    ",
      "          Ͷ     ",
      "         Ͷ      ",
      "Ͷ      ͶͶ       ",
      " ͶͶͶͶͶͶ         ",
      "                ",
      "                ",
      "                ",
      "                ",
      "                ",
      "                ",
      "                "
    ],
    [
      "            Ͷ   ",
      "            Ͷ   ",
      "            Ͷ   ",
      "           Ͷ    ",
      "           Ͷ    ",
      "          Ͷ     ",
      "         Ͷ      ",
      "Ͷ      ͶͶ       ",
      " ͶͶͶͶͶͶ         ",
      "                ",
      "                ",
      "                ",
      "                ",
      "                ",
      "                ",
      "                "
    ],
    [
      "            Ͷ   ",
      "            Ͷ   ",
      "            Ͷ   ",
      "           Ͷ    ",
      "           Ͷ    ",
      "          Ͷ     ",
      "         Ͷ      ",
      "Ͷ      ͶͶ       ",
      " ͶͶͶͶͶͶ         ",
      "                ",
      "                ",
      "                ",
      "                ",
      "                ",
      "                ",
      "                "
    ]
  ]
}