{
  "xsize": 16,
  "zsize": 16,
  "refpalette": "lostcities:base",
  "slices": [
    [
      "vvvvvvvvvvvvvvvv",
      "vvvvvvvvvvvvvvvv",
      "vvvvvvvvvvvvvvvv",
      "vvvvvvvvvvvvvvvv",
      "vvvvvvvvvvvvvvvv",
      "vvvvvvvvvvvvvvvv",
      "vvvvvvvvvvvvvvvv",
      "vvvvvvvvvvvvvvvv",
      "vvvvvvvvvvvvvvvv",
      "vvvvvvvvvvvvvvvv",
      "vvvvvvvvvvvvvvvv",
      "vvvvvvvvvvvvvvvv",
      "vvvvvvvvvvvvvvvv",
      "vvvvvvvvvvvvvvvv",
      "vvvvvvvvvvvvvvvv",
      "vvvvvvvvvvvvvvvv"
    ],
    [
      "ffffffffffffffff",
      "ffffffffffffffff",
      "ffffffffffffffff",
      "ffffffffffffffff",
      "ffffffffffffffff",
      "ffffffffffffffff",
      "ffffffffffffffff",
      "ffffffffffffffff",
      "ffffffffffffffff",
      "ffffffffffffffff",
      "ffffffffffffffff",
      "ffffffffffffffff",
      "ffffffffffffffff",
      "ffffffffffffffff",
      "ffffffffffffffff",
      "f ffffffffffffff"
    ],
    [
      "              gg",
      "              r ",
      "              r ",
      "              r ",
      "              r ",
      "              r ",
      " ff!!         r ",
      "ffff!!        r ",
      "ffff!         r ",
      " ff!          r ",
      "              r ",
      "              r ",
      "              r ",
      "              r ",
      "              r ",
      "              gg"
    ],
    [
      "              gg",
      "              r ",
      "              r ",
      "              r ",
      "              r ",
      "              r ",
      "              r ",
      " ff!!         r ",
      " ff!!         r ",
      "  !!          r ",
      "              r ",
      "              r ",
      "              r ",
      "              r ",
      "              r ",
      "              gg"
    ],
    [
      "              gg",
      "              r ",
      "              r ",
      "              r ",
      "              r ",
      "              r ",
      "              r ",
      " hi           r ",
      " jk!          r ",
      "  !           r ",
      "              r ",
      "              r ",
      "              r ",
      "              r ",
      "              r ",
      "              gg"
    ],
    [
      "              gg",
      "              r ",
      "              r ",
      "              r ",
      "              r ",
      "              r ",
      "              r ",
      " hi           r ",
      " jk!          r ",
      "  !           r ",
      "              r ",
      "              r ",
      "              r ",
      "              r ",
      "              r ",
      "              gg"
    ]
  ]
}