{
  "xsize": 16,
  "zsize": 16,
  "refpalette": "pomkotsmechs:base",
  "slices": [
    [
      " ggg         gg ",
      "ggggg        ggg",
      "ggggggggg   gggg",
      "  g        ggggg",
      "            ggg ",
      "             g  ",
      "  !    gg   !g! ",
      "!!g!  g  g   g  ",
      "  g   g  g   g  ",
      "  g    gg    g  ",
      "  g             ",
      "                ",
      "    g    ! ggg  ",
      "gggggg  ggggggg ",
      "gggg     ! gggg ",
      " ggg        ggg "
    ],
    [
      "  g          g  ",
      " ggg         gg ",
      "gggggYYYYY  gggg",
      "  g         ggg ",
      "             g  ",
      "  !          Y  ",
      " !Y!   gg   !Y! ",
      "!!Y!  g  g  !Y! ",
      "  Y   g  g   Y  ",
      "  Y    gg    Y  ",
      "  Y             ",
      "  g             ",
      "  gg     !      ",
      "gggg    !YYgggg ",
      " gg      !  ggg ",
      "  g          g  "
    ],
    [
      "  g          g  ",
      " ggg        ggg ",
      "gggggYYYYYYggggg",
      " ggg        ggg ",
      "  g          g  ",
      "  Y          Y  ",
      " !Y!   gg    Y  ",
      " !Y   g  g  !Y! ",
      " !Y   g  g   Y  ",
      "  Y    gg    Y  ",
      "  Y          Y  ",
      "  g          g  ",
      " gg      !  gg  ",
      "gggg    !YYggggg",
      " gg      !  ggg ",
      "  g          g  "
    ],
    [
      "  g          g  ",
      " ggg        ggg ",
      "gggggggggggggggg",
      " ggg        ggg ",
      "  g          g  ",
      "  g          g  ",
      " !g!   gg    g  ",
      "  g   g  g  !g! ",
      "  g   g  g  !g! ",
      " !g    gg    g  ",
      "             g  ",
      "  g          g  ",
      " gg      !  ggg ",
      "ggg     !ggggggg",
      " gg      !  ggg ",
      "             g  "
    ],
    [
      "  g          g  ",
      " ggg        ggg ",
      "gggggYYYYYYggggg",
      " ggg        ggg ",
      "  g          g  ",
      "  Y    YY    Y  ",
      " !Y!  YggY   Y  ",
      "  Y  YgYYgY  Y  ",
      " !Y  YgYYgY !Y! ",
      "  Y   YggY  !Y! ",
      "  Y    YY    Y  ",
      "  g          g  ",
      " gg      !  ggg ",
      "ggg     YYYggggg",
      " gg      !  ggg ",
      "             g  "
    ],
    [
      "  g          g  ",
      " ggg        ggg ",
      "gggggYYYYYYggggg",
      " gggggggggggggg ",
      "  gggggggggggg  ",
      "  Ygggg  ggggY  ",
      "  Yggg gg gggY  ",
      "  Ygg g  g ggY  ",
      " !Ygg g  g ggY  ",
      " !Yggg gg gggY! ",
      " !   gg  ggggY! ",
      "  gggggggggggg  ",
      " gggggggggggggg ",
      "gggggYYYYYYggggg",
      " gg         ggg ",
      "  g          g  "
    ]
  ]
}