{
  "xsize": 16,
  "zsize": 16,
  "refpalette": "pomkotsmechs:base",
  "slices": [
    [
      "                ",
      "                ",
      "                ",
      "                ",
      "                ",
      "                ",
      "  vvvvvvvvv     ",
      "vvvvvvvvvvvvv vv",
      "vvvvvvvvvvvvvvvv",
      "vvvvvvvvvvvvvvvv",
      "vvvvvvvvvvvvvvvv",
      "vvvvvvvvvvvvvvvv",
      "vvvvvvvvvvvvvvvv",
      "vvvvvvvvvvvvvvvv",
      "vv͵͵͵͵͵͵vvvvvvvv",
      "͵͵͵͵͵͵͵͵͵͵vvvv͵͵"
    ],
    [
      "                ",
      "                ",
      "ffffffffffffffff",
      "ffffffffffffffff",
      "ffffffffffffffff",
      "ffffffffffffffff",
      "ffffffffffffffff",
      "ffffffffffffffff",
      "ffffffffffffffff",
      "ffffffffffffffff",
      "ffffffffffffffff",
      "ffffffffffffffff",
      "ffffffffffffffff",
      "ffffffffffffffff",
      "ffffffffffffffff",
      "ffffffffffffffff"
    ],
    [
      "                ",
      "                ",
      "fffffqq    fffff",
      "                ",
      "                ",
      "                ",
      " n            n ",
      "                ",
      "                ",
      "                ",
      " n            n ",
      "                ",
      "                ",
      " n            n ",
      "                ",
      "                "
    ],
    [
      "                ",
      "                ",
      "fffffq    qfffff",
      "                ",
      "                ",
      "                ",
      "ʹʹ            ʹʹ",
      "ʹʹ            ʹʹ",
      "ʹʹ            ʹʹ",
      "ʹʹ            ʹʹ",
      "ʹʹ            ʹʹ",
      "                ",
      "                ",
      "ʹʹ            ʹʹ",
      "ʹʹ            ʹʹ",
      "ʹʹ            ʹʹ"
    ],
    [
      "                ",
      "                ",
      "fffffq    qfffff",
      "                ",
      "                ",
      "                ",
      "fʹ            ʹf",
      " f            f ",
      " f            f ",
      " f            f ",
      "fʹ            ʹf",
      "                ",
      "                ",
      "fʹ            ʹf",
      " f            f ",
      " f            f "
    ],
    [
      "                ",
      "                ",
      "fffffq   qqfffff",
      "                ",
      "                ",
      "                ",
      "fʹ            ʹf",
      " f            f ",
      " f            f ",
      " f            f ",
      "fʹ            ʹf",
      "                ",
      "                ",
      "fʹ            ʹf",
      " f            f ",
      " f            f "
    ]
  ]
}