{
  "xsize": 16,
  "zsize": 16,
  "refpalette": "pomkotsmechs:base",
  "slices": [
    [
      "g            gg ",
      "            !Y! ",
      "            !Y! ",
      "             Y  ",
      "             Y  ",
      "             Y  ",
      "             Y  ",
      "             Y  ",
      "            !Y! ",
      "             Y  ",
      "             Y  ",
      "            ggg ",
      "      !    ggggg",
      "gYYYYYYYYYYggggg",
      "g     !    ggggg",
      "           !ggg "
    ],
    [
      "g            gg ",
      "             Y  ",
      "            !Y! ",
      "            !Y! ",
      "            !Y! ",
      "             Y  ",
      "            !Y! ",
      "            !Y! ",
      "            !Y! ",
      "             Y  ",
      "             Y  ",
      "             g  ",
      "     !!     ggg ",
      "gYYYYYYYYYYggggg",
      "g    !!     ggg ",
      "            !g! "
    ],
    [
      "g            gg ",
      "             Y  ",
      "             Y  ",
      "             Y  ",
      "            !Y! ",
      "            !Y! ",
      "            !Y! ",
      "             Y  ",
      "             Y  ",
      "             Y  ",
      "             Y  ",
      "             g  ",
      "     !      ggg ",
      "gYYYYYYYYYYggggg",
      "g    !      ggg!",
      "            !g! "
    ],
    [
      "g            gg ",
      "             Y  ",
      "             Y  ",
      "             Y  ",
      "             Y! ",
      "            !Y!!",
      "            !Y!!",
      "             Y! ",
      "             Y  ",
      "             Y  ",
      "             Y  ",
      "             g  ",
      "    !!      ggg ",
      "gYYYYYYYYYYggggg",
      "g   !!      ggg!",
      "             g! "
    ],
    [
      "g            gg ",
      "             Y  ",
      "             Y  ",
      "             Y  ",
      "             Y! ",
      "            !Y!!",
      "             Y! ",
      "             Y  ",
      "             Y  ",
      "             Y  ",
      "             Y  ",
      "             g  ",
      "    !       ggg!",
      "gYYYYYYYYYYggggg",
      "g  !!       ggg!",
      "             g! "
    ],
    [
      "g            gg ",
      " g          gY g",
      "             Y  ",
      "             Y! ",
      "             Y!!",
      "            !Y!!",
      "            !Y!!",
      "             Y  ",
      "             Y  ",
      "          !  Y  ",
      "          !  Y! ",
      "             g!!",
      " g  !       ggg!",
      "gYYYYYYYYYYggggg",
      "g !!!!      ggg!",
      " g !!        g  "
    ]
  ]
}