{
  "xsize": 16,
  "zsize": 16,
  "refpalette": "lostcities:base",
  "slices": [
    [
      "vvvvvvvvvvvvvvvv",
      "vvvvvvvvvvvvvvvv",
      "vvvvvvvvvvvvvvvv",
      "vvvvvvvvvvvvvvvv",
      "vvvvvvvvvvvvvvvv",
      "vvvvvvvvvvvvvvvv",
      "vvvvvvvvvvvvvvvv",
      "vvvvvvvvvvvvvvvv",
      "vvvvvvvvvvvvvvvv",
      "vvvvvvvvvvvvvvvv",
      "vvvvvvvvvvvvvvvv",
      "vvvvvvvvvvvvvvvv",
      "vvvvvvvvvvvvvvvv",
      "vvvvvvvvvvvvvvvv",
      "vvvvvvvvvvvvvvvv",
      "vvvvvvvvvvvvvvvv"
    ],
    [
      "     gggggg  !  ",
      "   gggggggggg!! ",
      "  gggggggggggg! ",
      " ggggg    ggggg ",
      " ggg        ggg ",
      "gggg        gggg",
      "ggg          ggg",
      "ggg          ggg",
      "ggg          ggg",
      "ggg          ggg",
      "gggg        gggg",
      " ggg        ggg ",
      " ggggg    ggggg ",
      "  gggggggggggg  ",
      "   gggggggggg   ",
      "     gggggg     "
    ],
    [
      "     gggggg     ",
      "   gggggggggg!  ",
      "  gggggggggggg! ",
      " ggggg    ggggg ",
      " ggg        ggg ",
      "gggg        gggg",
      "ggg   gggg   ggg",
      "ggg   gggg   ggg",
      "ggg   gggg   ggg",
      "ggg   gggg   ggg",
      "gggg        gggg",
      "!ggg        ggg ",
      "!ggggg    ggggg ",
      " !gggggggggggg  ",
      "   gggggggggg   ",
      "     gggggg     "
    ],
    [
      "                ",
      "     gggggg !!  ",
      "    gggggggg!!! ",
      "   ggg    ggg!  ",
      "  gg  gggg  gg  ",
      " ggg gggggg ggg ",
      " gg gggggggg gg ",
      " gg gggggggg gg ",
      " gg gggggggg gg ",
      " gg gggggggg gg ",
      "!ggg gggggg ggg ",
      " !gg  gggg  gg  ",
      " ! ggg    ggg   ",
      "    gggggggg    ",
      "     gggggg     ",
      "                "
    ],
    [
      "                ",
      "     gggggg     ",
      "    gggggggg!!  ",
      "   gggggggggg!  ",
      "  gg gggggg!gg  ",
      " gggggggggggggg ",
      " gggggggggggggg ",
      " gggggggggggggg ",
      " gggggggggggggg ",
      " gggggggggggggg ",
      "!gggggggggggggg ",
      "!!gg gggggg gg  ",
      " ! gggggggggg   ",
      "    gggggggg    ",
      "     gggggg     ",
      "                "
    ],
    [
      "     gggggg     ",
      "   gggggggggg   ",
      "  gggggggggggg  ",
      " gggggggggggg!  ",
      " ggggggggggggg  ",
      "gggggggggggggggg",
      "gggggggggggggggg",
      "gggggggggggggggg",
      "gggggggggggggggg",
      "gggggggggggggggg",
      "gggggggggggggggg",
      "!gggggggggggggg ",
      " gggggggggggggg ",
      "  gggggggggggg  ",
      "   gggggggggg   ",
      "     gggggg     "
    ]
  ]
}