{
  "xsize": 16,
  "zsize": 16,
  "refpalette": "pomkotsmechs:base",
  "slices": [
    [
      "g   gggg   g    ",
      "gYYYYYYYYYYY    ",
      "gYYYYYYYYYYYgg  ",
      "gYYYYYYYYYYYgg  ",
      "ggggggggggg     ",
      " YYYYYYYYY      ",
      " YYYYYYYYY      ",
      " YYYYYYYYY      ",
      " YYYYYYYYYYY    ",
      " YYYYYYYYYYY    ",
      " YYYYYYYYYYY    ",
      "gggggggggggggg  ",
      "gYYYYYYYYYYYgg  ",
      "gYYYYYYYYYYYgg  ",
      "gYYYYYYYYY      ",
      "g   gggg        "
    ],
    [
      "g     gggg g    ",
      "gYYYYYYYYYYY    ",
      "gYYYYYYYYYYYg   ",
      "gYYYYYYYYYYYg   ",
      "ggggggggggg     ",
      " YYYYYYYYY      ",
      " YYYYYYYYY      ",
      " YYYYYYYYY      ",
      " YYYYYYYYYYY    ",
      " YYYYYYYYYYY    ",
      " YYYYYYYYYYY    ",
      "ggggggggggggg   ",
      "gYYYYYYYYYYYg   ",
      "gYYYYYYYYYYYg   ",
      "gYYYYYYYYY      ",
      "g    !ggg       "
    ],
    [
      "g       gggg    ",
      "gYYYYYYYYYYY    ",
      "gYYYYYYYYYYYg   ",
      "gYYYYYYYYYYYgg  ",
      "ggggggggggg     ",
      " YYYYYYYYY      ",
      " YYYYYYYYY      ",
      " YYYYYYYYY      ",
      " YYYYYYYYYY  g  ",
      " YYYYYYYYYYY g  ",
      " YYYYYYYYYYY g  ",
      "gggggggggggggg  ",
      "gYYYYYYYYYYYgg  ",
      "gYYYYYYYYYYYg   ",
      "gYYYYYYYYYY     ",
      "g    !!!gg      "
    ],
    [
      "g        ggg    ",
      "gYYYYYYYYYYY    ",
      "gYYYYYYYYYYYg   ",
      "gYYYYYYYYYYYgg  ",
      "ggggggggggggg   ",
      " YYYYYYYYY      ",
      " YYYYYYYY       ",
      " YYYYYYYYY      ",
      " YYYYYYYYYY  g  ",
      " YYYYYYYYYYY g  ",
      " YYYYYYYYYYY g  ",
      "gggggggggggggg  ",
      "gYYYYYYYYYYYgg  ",
      "gYYYYYYYYYYYg   ",
      "gYYYY!!!YYY     ",
      "g     !         "
    ],
    [
      "g         gg    ",
      "gYYYYYYYYYYY    ",
      "gYYYYYYYYYYYg   ",
      "gYYYYYYYYYYYgg  ",
      "ggggggggggggg   ",
      " YYYYYYYYY      ",
      " YYYYYYYY       ",
      " YYYYYYYY       ",
      " YYYYYYYYYY  g  ",
      " YYYYYYYYYYY g  ",
      " YYYYYYYYYYY g  ",
      "gggggggggggggg  ",
      "gYYYYYYYYYYYgg  ",
      "gYYYYYYYYYYYg   ",
      "gYYYY ! Y Y     ",
      "g               "
    ],
    [
      "g         g     ",
      "gYYYYYYYYYY     ",
      "gYYYYYYYYYYgg   ",
      "gYYYYYYYYYYgg   ",
      "ggggggggggggg   ",
      " YYYYYYYYY      ",
      " YYYYYYYY       ",
      " YYYYYYYY       ",
      " YYYYYYYYY      ",
      " YYYYYYYYYY     ",
      " YYYYYYYYYY     ",
      "ggggggggggggg   ",
      "gYYYYYYYYYYgg   ",
      "gYYYYYYYYYY g   ",
      "gYYY  ! Y       ",
      "g               "
    ]
  ]
}