{
  "xsize": 16,
  "zsize": 16,
  "refpalette": "pomkotsmechs:base",
  "slices": [
    [
      "vvvvvvvvvvvvvvvv",
      "vvvvvvvvvvvvvvvv",
      "vvvvvvvvvvvvvvvv",
      "vvvvvvvvvvvvvvvv",
      "vvvvvvvvvvvvvvvv",
      "vvvvvvvvvvvvvvvv",
      "vvvvvvvvvvvvvvvv",
      "vvvvvvvvvvvvvvvv",
      "vvvvvvvvvvvvvvvv",
      "vvvvvvvvvvvvvvvv",
      "vvvvvvvvvvvvvvvv",
      "vvvvvvvvvvvvvvvv",
      "vvvvvvvvvvvvvvvv",
      "vvvvvvvvvvvvvvvv",
      "vvvvvvvvvvvvvvvv",
      "vvvvvvvvvvvvvvvv"
    ],
    [
      "g    gggggggggg ",
      "g    gggggggggg ",
      "g    gggggggggg ",
      "g    gggggggggg ",
      "g    gggggggggg ",
      "g    7ggggggggg ",
      "g    7ggggggggg ",
      "g    7ggggggggg ",
      "g    gggggggggg ",
      "g    gggggggggg ",
      "                ",
      "                ",
      "                ",
      "             YYY",
      "gggggggggggggggY",
      "gggggggggggggggY"
    ],
    [
      "g    gggggggggg ",
      "g    g  gg    g ",
      "g    g  gg    g ",
      "g    g        g ",
      "g    g        g ",
      "g             g ",
      "g             g ",
      "g             g ",
      "g    g        g ",
      "g    gggggggggg ",
      "                ",
      "                ",
      "                ",
      "             Y Y",
      "ggggggggggggggg ",
      "         ggggggY"
    ],
    [
      "g    g  g  g  g ",
      "     g   gg     ",
      "     g   gg     ",
      "g    g        g ",
      "     g          ",
      "                ",
      "g             g ",
      "                ",
      "     g          ",
      "g    g  g  g  g ",
      "                ",
      "                ",
      "                ",
      "             Y Y",
      "ggggggggggggggg ",
      "         ggggggY"
    ],
    [
      "g    g  g  g  g ",
      "     g    gg    ",
      "     g    gg    ",
      "g    g        g ",
      "     g          ",
      "                ",
      "g             g ",
      "                ",
      "     g          ",
      "g    g  g  g  g ",
      "                ",
      "                ",
      "                ",
      "             Y Y",
      "ggggggggggggggg ",
      "gggggggggggggggY"
    ],
    [
      "g    g  g  g  g ",
      "     g     gg   ",
      "     g     gg   ",
      "g    g        g ",
      "     g          ",
      "     g          ",
      "g    g        g ",
      "     g          ",
      "     g          ",
      "g    g  g  g  g ",
      "                ",
      "                ",
      "                ",
      "             Y Y",
      "ggggggggggggggg ",
      "gggggggggggggggY"
    ]
  ]
}