{
  "xsize": 16,
  "zsize": 16,
  "refpalette": "pomkotsmechs:base",
  "slices": [
    [
      "              g ",
      "             ggg",
      "              r ",
      "              r ",
      "              r ",
      "              r ",
      "              r ",
      "              r ",
      "             !r!",
      "              r ",
      "  i          gr ",
      " jk          ggg",
      "             ggg",
      "gg  gg       !g ",
      "gggggg qqqqqqqg!",
      "gg           !gn"
    ],
    [
      "              g ",
      "             ggg",
      "              r ",
      "              r ",
      "              r ",
      "              r ",
      "              r ",
      "              r ",
      "             !r!",
      "              r ",
      "             gr ",
      "  k          ggg",
      "             ggg",
      "gg  gg       !g ",
      "gggggg qqqqqqqg ",
      "gg           !! "
    ],
    [
      "              g ",
      "             ggg",
      "              r ",
      "              r ",
      "              r ",
      "              r ",
      "              r ",
      "              r ",
      "             !r!",
      "              r ",
      "             gr ",
      "  k          ggg",
      "            !ggg",
      "    gg      !!g!",
      "gggggg qqqqqqqg ",
      "gg           !  "
    ],
    [
      "              g ",
      "             ggg",
      "              r ",
      "              r ",
      "              r ",
      "              r ",
      "              r ",
      "             !r!",
      "             !r!",
      "              r ",
      "  i          gr ",
      "  k          ggg",
      "            !ggg",
      "    gg       !! ",
      " ggggg qqqqqq!  ",
      "gg              "
    ],
    [
      "              g ",
      "             ggg",
      "              r ",
      "              r ",
      "              r ",
      "              r ",
      "              r ",
      "             !r!",
      "              r ",
      "              r ",
      " hi          gr ",
      "  k          ggg",
      "            !ggg",
      "    gg       !  ",
      " ggggg qqqqq    ",
      " g              "
    ],
    [
      "                ",
      "                ",
      "              r ",
      "              r ",
      "              r ",
      "              r ",
      "             !r!",
      "             !r!",
      "              r ",
      "              r ",
      " hi          gr ",
      " jk          ggg",
      "            !ggg",
      "    gg       !  ",
      " ggggg qqqqq    ",
      " g              "
    ]
  ]
}