{
  "xsize": 16,
  "zsize": 16,
  "refpalette": "pomkotsmechs:base",
  "slices": [
    [
      "                ",
      "           Ygggg",
      "           YYY  ",
      "                ",
      "     ͲͲͲͲͲͲͲͲͲͲͲ",
      "       Ͳ   ͲͲ   ",
      "        Ͳ Ͳ  Ͳ Ͳ",
      "        Ͳ Ͳ  Ͳ Ͳ",
      "       Ͳ   ͲͲ   ",
      "                ",
      "      ͲͲ   ͲͲ   ",
      "    ͲͲ  Ͳ Ͳ  Ͳ Ͳ",
      "    ͲͲ  Ͳ Ͳ  Ͳ Ͳ",
      "    Ͳ ͲͲ   ͲͲ   ",
      "    ͲͲͲͲͲͲͲͲͲͲͲͲ",
      "                "
    ],
    [
      "                ",
      "            gggg",
      "           Y Y  ",
      "                ",
      "       ͲͲͲͲͲͲͲͲͲ",
      "       ͲͲͲͲͲͲͲͲͲ",
      "        ͲͲͲ  ͲͲͲ",
      "        ͲͲͲ  ͲͲͲ",
      "       ͲͲͲͲͲͲͲͲͲ",
      "       ͲͲͲͲͲͲͲͲͲ",
      "     ͲͲͲͲͲͲͲͲͲͲͲ",
      "    ͲͲ  ͲͲͲ  ͲͲͲ",
      "    ͲͲ  ͲͲ   ͲͲͲ",
      "    ͲͲͲͲͲͲͲͲͲͲͲͲ",
      "    ͲͲͲͲͲͲͲͲͲͲͲͲ",
      "                "
    ],
    [
      "               g",
      "            gggg",
      "           Y Y  ",
      "                ",
      "                ",
      "       Ͳ   ͲͲ   ",
      "        Ͳ Ͳ  Ͳ Ͳ",
      "        Ͳ Ͳ  Ͳ Ͳ",
      "       Ͳ   ͲͲ   ",
      "                ",
      "      ͲͲ   ͲͲ   ",
      "     Ͳ  Ͳ    Ͳ Ͳ",
      "     Ͳ  Ͳ    Ͳ Ͳ",
      "            Ͳ   ",
      "                ",
      "                "
    ],
    [
      "                ",
      "                ",
      "           Y Y  ",
      "                ",
      "                ",
      "       Ͳ   ͲͲ   ",
      "        Ͳ Ͳ  Ͳ Ͳ",
      "        Ͳ Ͳ  Ͳ Ͳ",
      "       Ͳ   ͲͲ   ",
      "                ",
      "      ͲͲ   Ͳ    ",
      "     Ͳ  Ͳ    Ͳ Ͳ",
      "     Ͳ  Ͳ    Ͳ Ͳ",
      "            Ͳ   ",
      "                ",
      "                "
    ],
    [
      "           YYY  ",
      "           Y Y  ",
      "           YYY  ",
      "                ",
      "                ",
      "      ͲͲ   ͲͲ   ",
      "     Ͳ  Ͳ Ͳ  Ͳ Ͳ",
      "     Ͳ  Ͳ Ͳ  Ͳ Ͳ",
      "      ͲͲ   ͲͲ   ",
      "                ",
      "      ͲͲ   ͲͲ   ",
      "     Ͳ  Ͳ    Ͳ Ͳ",
      "     Ͳ  Ͳ    Ͳ Ͳ",
      "      ͲͲ    Ͳ   ",
      "                ",
      "                "
    ],
    [
      "                ",
      "                ",
      "                ",
      "                ",
      "                ",
      "      ͲͲ   ͲͲ   ",
      "     Ͳ  Ͳ Ͳ  Ͳ Ͳ",
      "     Ͳ  Ͳ Ͳ  Ͳ Ͳ",
      "      ͲͲ   ͲͲ   ",
      "                ",
      "      ͲͲ   ͲͲ   ",
      "     Ͳ  Ͳ Ͳ  Ͳ Ͳ",
      "     Ͳ  Ͳ Ͳ  Ͳ Ͳ",
      "      ͲͲ   ͲͲ   ",
      "                ",
      "                "
    ]
  ]
}