{
  "xsize": 16,
  "zsize": 16,
  "refpalette": "pomkotsmechs:base",
  "slices": [
    [
      "ͶͶ     ͶͶͶͶ     ",
      "                ",
      "                ",
      "                ",
      "                ",
      "           !    ",
      "g    g    !!! g ",
      "       YY!!!!   ",
      "       YY !!    ",
      "                ",
      "                ",
      "                ",
      "                ",
      "                ",
      "                ",
      "g    g        g "
    ],
    [
      "gg     gggg     ",
      "                ",
      "                ",
      "                ",
      "                ",
      "          !!    ",
      "g    g   !!!! g ",
      "      YY !!!    ",
      "      YY  !     ",
      "                ",
      "                ",
      "                ",
      "                ",
      "                ",
      "                ",
      "g    g        g "
    ],
    [
      "gg     gggg     ",
      "                ",
      "                ",
      "                ",
      "                ",
      "          !!    ",
      "g    gggggggggg ",
      "g    gY  !!YYYg ",
      "g    gY   !YYYg ",
      "g    gYYYYYYYYg ",
      "g    gYYYYYYYYg ",
      "g    gYYYYYYYYg ",
      "g    gYYYYYYYYg ",
      "g    gYYYYYYYYg ",
      "g    gYYYYYYYYg ",
      "g    gggggggggg "
    ],
    [
      "gg     gggg     ",
      "                ",
      "                ",
      "                ",
      "                ",
      "           !    ",
      "g    g    !!! g ",
      "         !!YY   ",
      "          !YY   ",
      "                ",
      "                ",
      "                ",
      "                ",
      "                ",
      "                ",
      "g    g        g "
    ],
    [
      "g       gg      ",
      "                ",
      "                ",
      "                ",
      "                ",
      "                ",
      "g    g    !!  g ",
      "         !YY    ",
      "          YY    ",
      "                ",
      "                ",
      "                ",
      "                ",
      "                ",
      "                ",
      "g    g        g "
    ],
    [
      "                ",
      "                ",
      "                ",
      "                ",
      "                ",
      "          !     ",
      "g    g   !!!  g ",
      "         YY!    ",
      "         YY     ",
      "                ",
      "                ",
      "                ",
      "                ",
      "                ",
      "                ",
      "g    g        g "
    ]
  ]
}