{
  "xsize": 16,
  "zsize": 16,
  "refpalette": "lostcities:base",
  "slices": [
    [
      " ggg         !  ",
      "ggggg       !!!g",
      "gggggYYYYYYYYYYg",
      "ggggg      !!!  ",
      " ggg        !   ",
      "  Y         !   ",
      "  Y        !!!  ",
      "  Y         !   ",
      "  Y             ",
      "  Y             ",
      " !Y!            ",
      "  Y             ",
      "  Y             ",
      " !Y!            ",
      " !Y!            ",
      " gg            g"
    ],
    [
      "  g         !!  ",
      " ggg       !!!!g",
      "gggggYYYYYYYYYYg",
      " ggg        !   ",
      "  g             ",
      "  Y         !   ",
      "  Y        !!!  ",
      "  Y         !   ",
      "  Y             ",
      "  Y             ",
      " !Y!            ",
      "  Y             ",
      "  Y             ",
      "  Y             ",
      " !Y!            ",
      " gg            g"
    ],
    [
      "  g         !   ",
      " ggg       !!! g",
      "gggggYYYYYYYY! g",
      " ggg        !   ",
      "  g             ",
      "  Y         !   ",
      "  Y        !!!  ",
      "  Y         !   ",
      "  Y             ",
      "  Y             ",
      " !Y!            ",
      "  Y             ",
      "  Y             ",
      "  Y             ",
      " !Y!            ",
      "!gg!           g"
    ],
    [
      "  g        !!!  ",
      " ggg       !!!  ",
      "gggggYYYYYYY!! g",
      " ggg        !   ",
      "  g         !   ",
      "  Y        !!!  ",
      "  Y        !!!  ",
      "  Y         !   ",
      "  Y             ",
      "  Y             ",
      " !Y!            ",
      "  Y             ",
      "  Y             ",
      "  Y             ",
      " !Y             ",
      "!gg            g"
    ],
    [
      "  g        !!!  ",
      " ggg       !!!  ",
      "gggggYYYYYY!!!  ",
      " ggg        !   ",
      "  g         !   ",
      "  Y        !!!  ",
      "  Y         !   ",
      "  Y             ",
      "  Y             ",
      " !Y             ",
      "!!Y!            ",
      " !Y             ",
      "  Y             ",
      "  Y             ",
      " !Y             ",
      "!gg            g"
    ],
    [
      "  g        !!!  ",
      " ggg       !!!  ",
      "gggggYYYYYY !   ",
      " ggg            ",
      "  g         !   ",
      "  Y        !!!  ",
      "  Y        !!   ",
      "  Y!            ",
      " !Y!            ",
      "!!Y             ",
      "!!Y             ",
      "!!Y             ",
      "  Y             ",
      "  Y             ",
      "g Yg          g ",
      "!gg            g"
    ]
  ]
}