{
  "xsize": 16,
  "zsize": 16,
  "refpalette": "pomkotsmechs:base",
  "slices": [
    [
      "vvvvvvv         ",
      "vvvvvv          ",
      "vvvvv           ",
      "vvvv fffffff    ",
      "vv   f    ff    ",
      "     f    ff    ",
      "     f    ff    ",
      "     f    ff    ",
      "     f    ff    ",
      "     f    ff    ",
      "     f    ff    ",
      "     f    ff    ",
      "     f    ff    ",
      "     f    ff    ",
      "     fffffff    ",
      "                "
    ],
    [
      "ffffff          ",
      "ffffff          ",
      "ffffff          ",
      "ffffffffffff    ",
      "ffffff     f    ",
      "ffffff     f    ",
      "ffffff     f    ",
      "ffffff     f    ",
      "ffffff     f    ",
      "ffffff     f    ",
      "ffffff     f    ",
      "ffffff     f    ",
      "ffffff     f    ",
      "ffffff     f    ",
      "    ffffffff    ",
      "                "
    ],
    [
      "     f          ",
      "     f          ",
      "  n  f          ",
      "    fffffff     ",
      "    ff    f     ",
      "    ff    f     ",
      "  n ff    f     ",
      "    ff    f     ",
      "    ff    f     ",
      "    ff    f     ",
      "    ff    f     ",
      "    ff    f     ",
      "    ff    f     ",
      "ffffff    f     ",
      "    fffffff     ",
      "                "
    ],
    [
      "     f          ",
      "     f          ",
      "ʹʹʹ  f          ",
      "ʹʹʹffffffff     ",
      "ʹʹʹf f    f     ",
      "ʹʹʹf f    f     ",
      "ʹʹʹf f    f     ",
      "   f f    f     ",
      "   f f    f     ",
      "   f f    f     ",
      "   f f    f     ",
      "   f f    f     ",
      "   f f    f     ",
      "ffffff    f     ",
      "   ffffffff     ",
      "                "
    ],
    [
      "     f          ",
      "     f          ",
      "ffʹ  f          ",
      "  ffffffff      ",
      "  ff f   f      ",
      "ͳͳff f   f      ",
      "ffʹf f   f      ",
      "   f f   f      ",
      "   f f   f      ",
      "   f f   f      ",
      "   f f   f      ",
      "   f f   f      ",
      "   f f   f      ",
      "ffffff   f      ",
      "   fffffff      ",
      "                "
    ],
    [
      "     f          ",
      "     f          ",
      "ffʹ  f          ",
      "  ffffffff      ",
      "  f  f   f      ",
      "  f  f   f      ",
      "ffʹ  f   f      ",
      "  f  f   f      ",
      "  f  f   f      ",
      "  f  f   f      ",
      "  f  f   f      ",
      "  f  f   f      ",
      "  f  f  !f!     ",
      "ffffff   f      ",
      "  ffffffff      ",
      "                "
    ]
  ]
}