{
  "xsize": 16,
  "zsize": 16,
  "refpalette": "lostcities:base",
  "slices": [
    [
      "g    gggggggggg ",
      "g    g      ggg ",
      "g    g      ggg ",
      "g    g        g ",
      "g    g        g ",
      "g    g        g ",
      "g    g        g ",
      "g    g        g ",
      "g    g        g ",
      "g    gggggggggg ",
      "                ",
      "                ",
      "                ",
      "             YYY",
      "gggggggggggggggY",
      "              gY"
    ],
    [
      "g    gggggggggg ",
      "g    g       gg ",
      "g    g       gg ",
      "g    g        g ",
      "g    g        g ",
      "g    g        g ",
      "g    g        g ",
      "g    g        g ",
      "g    g        g ",
      "g    gggggggggg ",
      "                ",
      "                ",
      "                ",
      "             Y Y",
      "ggggggggggggggg ",
      "              gY"
    ],
    [
      "g    gggggggggg ",
      "g    gYYYY    g ",
      "g    gYYYY    g ",
      "g    gYYYYYYYYg ",
      "g    gYYYYYYYYg ",
      "g    gYYYYYYYYg ",
      "g    gYYYYYYYYg ",
      "g    gYYYYYYYYg ",
      "g    gYYYYYYYYg ",
      "g    gggggggggg ",
      "                ",
      "                ",
      "                ",
      "             Y Y",
      "ggggggggggggggg ",
      "gggggggggggggggY"
    ],
    [
      "g    g        g ",
      "                ",
      "                ",
      "                ",
      "                ",
      "                ",
      "                ",
      "           YY   ",
      "           YY   ",
      "g    g        g ",
      "                ",
      "                ",
      "                ",
      "             Y Y",
      "                ",
      "             Y Y"
    ],
    [
      "g    g        g ",
      "                ",
      "                ",
      "                ",
      "                ",
      "                ",
      "                ",
      "          YY    ",
      "          YY    ",
      "g    g        g ",
      "                ",
      "                ",
      "                ",
      "             YYY",
      "             Y Y",
      "             YYY"
    ],
    [
      "g    g        g ",
      "                ",
      "                ",
      "                ",
      "                ",
      "                ",
      "                ",
      "         YY     ",
      "         YY     ",
      "g    g        g ",
      "                ",
      "                ",
      "                ",
      "                ",
      "                ",
      "gg     gggg     "
    ]
  ]
}