{
  "xsize": 16,
  "zsize": 16,
  "refpalette": "pomkotsmechs:base",
  "slices": [
    [
      "vvvvvvvvvvvvvvvv",
      "vvvvvvvvvvvvvvvv",
      "vvvvvvvvvvvvvvvv",
      "vvvvvvvvvvvvvvvv",
      "vvvvvvvvvvvvvvvv",
      "vvvvvvvvvvvvvvvv",
      "vvvvvvvvvvvvvvvv",
      "vvvvvvvvvvvvvvvv",
      "vvvvvvvvvvvvvvvv",
      "vvvvvvvvvvvvvvvv",
      "vvvvvvvvvvvvvvvv",
      "vvvvvvvvvvvvvvvv",
      "vvvvvvvvvvvvvvvv",
      "vvvvvvvvvvvvvvvv",
      "vvvvvvvvvvvvvvvv",
      "vvvvvvvvvvvvvvvv"
    ],
    [
      "   fffffffffffff",
      "   fffffffffffff",
      "   fffffffffffff",
      "   fffffffffffff",
      "   fffffffffffff",
      "  ffffffffffffff",
      " fffffffffffffff",
      "ffffffffffffffff",
      "ffffffffffffffff",
      "ffffffffffffffff",
      "ffffffffffffffff",
      "ffffffffffffffff",
      "ffffffffffffffff",
      "ffffffffffffffff",
      "ffffffffffffffff",
      "fffffffffffffffl"
    ],
    [
      "              g ",
      "             ggg",
      "              r ",
      "              r ",
      "              r ",
      "              r ",
      "              r ",
      "              r ",
      "             !r!",
      "              r ",
      " ff          gr ",
      " ffffffffffffggg",
      "             ggg",
      "gg  gggggggggggg",
      "gggggggggggggggg",
      "gg  gg      !!gg"
    ],
    [
      "              g ",
      "             ggg",
      "              r ",
      "              r ",
      "              r ",
      "              r ",
      "              r ",
      "              r ",
      "             !r!",
      "              r ",
      " ff          gr ",
      " ffppppppppppggg",
      "             ggg",
      "gg  gg        g ",
      "ggggggqqqqqqqqg ",
      "gg  gg       !gn"
    ],
    [
      "              g ",
      "             ggg",
      "              r ",
      "              r ",
      "              r ",
      "              r ",
      "              r ",
      "              r ",
      "             !r!",
      "              r ",
      " hi          gr ",
      " jk          ggg",
      "             ggg",
      "gg  gg        g ",
      "ggggggqqqqqqqqg ",
      "gg  gg       !g!"
    ],
    [
      "              g ",
      "             ggg",
      "              r ",
      "              r ",
      "              r ",
      "              r ",
      "              r ",
      "              r ",
      "             !r!",
      "              r ",
      " hi          gr ",
      " jk          ggg",
      "             ggg",
      "gg  gg        g ",
      "ggggggqqqqqqqqg ",
      "gg  gg       !g!"
    ]
  ]
}