{
  "xsize": 16,
  "zsize": 16,
  "refpalette": "pomkotsmechs:base",
  "slices": [
    [
      "ggg             ",
      "ggg             ",
      "ggg             ",
      "ggg             ",
      "ggg             ",
      "ggg             ",
      "ggg             ",
      "ggg             ",
      "ggg             ",
      "ggg             ",
      "ggg          hi ",
      "ggg          jk ",
      "ggg             ",
      "gggggggggggggggg",
      "gggggggggggggggg",
      "nggggggggg!!! gg"
    ],
    [
      "ggg             ",
      "ggg             ",
      "ggg             ",
      "ggg             ",
      "ggg             ",
      "ggg             ",
      "ggg             ",
      "ggg             ",
      "ggg             ",
      "ggg             ",
      "ggg          hi ",
      "ggg          jk ",
      "ggg             ",
      "gggggggggggggggg",
      "gggggggggggggggg",
      "gggggggggggg! gg"
    ],
    [
      " g              ",
      "ggg             ",
      " m              ",
      " m              ",
      " m              ",
      " m              ",
      " m              ",
      "!m!             ",
      " m              ",
      " m              ",
      " m           hi ",
      "ggg          jk ",
      "ggg      !      ",
      " g g g  !ggg  gg",
      " gqqqqqqqqgggggg",
      "gg     !!!gg! gg"
    ],
    [
      "                ",
      "ggg             ",
      "                ",
      "                ",
      "                ",
      "                ",
      " !              ",
      "!!!             ",
      " !              ",
      "                ",
      "             ff ",
      "ggg          ff ",
      "ggg      !      ",
      " g g g  !ggg  gg",
      " g      !!gg  gg",
      " g      !!gg! gg"
    ],
    [
      "             ff ",
      "ggg          ff ",
      "  f          ff ",
      "  f          ff ",
      "  f          ff ",
      "  f          ff ",
      "!!f          ff ",
      "!!f          ff ",
      "!!f          ff ",
      "  ffffffffffffff",
      "  fffffffffffxxf",
      "gggffffffffffxxf",
      "ggg         ffff",
      " gfgfgfffgggffgg",
      " g     !!!gg  gg",
      " g     !!!gg! gg"
    ],
    [
      "ggggͱͱͱͱͱͱͱggggg",
      "ggggͱͱͱͱͱͱͱggggg",
      "ggggͱͱͱͱͱͱͱggggg",
      "ggggͱͱͱͱͱͱͱggggg",
      "ggggͱͱͱͱͱͱͱggggg",
      "ggggͱͱͱͱͱͱͱggggg",
      "ggggͱͱͱͱͱͱͱggggg",
      "ggggͱͱͱͱͱͱͱggggg",
      "ggggͱͱͱͱͱͱͱggggg",
      "gggggggggggggggg",
      "gggggggggggggggg",
      "gggggggggggggggg",
      "gggggggggggggggg",
      "gggggggggggggggg",
      "gggggggggggggggg",
      "gggggggggggggggg"
    ]
  ]
}