{
  "xsize": 16,
  "zsize": 16,
  "refpalette": "lostcities:base",
  "slices": [
    [
      "Ͷ        ͶYg    ",
      "Ͷ!       ͶYg    ",
      "!Ͷ!     ͶY g    ",
      " ͶͶ    ͶͶY  g   ",
      "   ͶͶͶͶYY   g   ",
      "             g  ",
      "              g ",
      "               g",
      "                ",
      "              gg",
      "             ggg",
      "            gggg",
      "            gggg",
      "            gggg",
      "            gggg",
      "      ͳY     ggg"
    ],
    [
      "Ͷ        ͶYg    ",
      "Ͷ!       ͶYg    ",
      "!Ͷ!     ͶYYg    ",
      " ͶͶ    ͶͶY  g   ",
      "   ͶͶͶͶYYY  g   ",
      "      ͶY     g  ",
      "      ͶY      g ",
      "      ͶY       g",
      "      ͶY        ",
      "      ͶY      ͶͶ",
      "      ͶY     Ͷ  ",
      "      ͶY    Ͷ   ",
      "      ͶY    Ͷ   ",
      "      ͶY    Ͷ   ",
      "      ͶY    Ͷ   ",
      "      ͶY     Ͷ  "
    ],
    [
      "Ͷ        ͶYg    ",
      "Ͷ!       ͶYg    ",
      "!Ͷ!     ͶYYg    ",
      " ͶͶ    ͶͶY  g   ",
      "   ͶͶͶͶYYY  g   ",
      "      ͶY     g  ",
      "      ͶY      g ",
      "      ͶY       g",
      "      ͶY        ",
      "      ͶY      ͶͶ",
      "      ͶY     Ͷ  ",
      "      ͶY    Ͷ   ",
      "      ͶY    Ͷ   ",
      "      ͶY    Ͷ   ",
      "      ͶY    Ͷ   ",
      "      ͶY     Ͷ  "
    ],
    [
      "Ͷ        ͶYggggg",
      "Ͷ!       ͶYggggg",
      "!Ͷ!     ͶYYggggg",
      " ͶͶ    ͶͶY  gggg",
      "   ͶͶͶͶYYY  gggg",
      "      ͶY     ggg",
      "      ͶY      gg",
      "      ͶY       g",
      "      ͶY        ",
      "      ͶY      ͶͶ",
      "      ͶY     Ͷ  ",
      "      ͶY    Ͷ   ",
      "      ͶY    Ͷ   ",
      "      ͶY    Ͷ   ",
      "      ͶY    Ͷ   ",
      "      ͶY     Ͷ  "
    ],
    [
      "Ͷ        ͶYͶ    ",
      "Ͷ!       ͶYͶ    ",
      "!Ͷ!     ͶYYͶ    ",
      " ͶͶ    ͶͶY  Ͷ   ",
      "   ͶͶͶͶYYY  Ͷ   ",
      "      ͶY     Ͷ  ",
      "      ͶY      Ͷ ",
      "      ͶY       Ͷ",
      "      ͶY        ",
      "      ͶY      ͶͶ",
      "      ͶY     Ͷ  ",
      "      ͶY    Ͷ   ",
      "      ͶY    Ͷ   ",
      "      ͶY    Ͷ   ",
      "      ͶY    Ͷ   ",
      "      ͶY     Ͷ  "
    ],
    [
      "Ͷ        ͶYͶ    ",
      "Ͷ!       ͶYͶ    ",
      "!Ͷ!     ͶYYͶ    ",
      " ͶͶ    ͶͶY  Ͷ   ",
      "   ͶͶͶͶYYY  Ͷ   ",
      "      ͶY     Ͷ  ",
      "      ͶY      Ͷ ",
      "      ͶY       Ͷ",
      "      ͶY        ",
      "      ͶY      ͶͶ",
      "      ͶY     Ͷ  ",
      "      ͶY    Ͷ   ",
      "      ͶY    Ͷ   ",
      "      ͶY    Ͷ   ",
      "      ͶY    Ͷ   ",
      "      ͶY     Ͷ  "
    ]
  ]
}