{
  "xsize": 16,
  "zsize": 16,
  "refpalette": "pomkotsmechs:base",
  "slices": [
    [
      "    vvvvvvvvvvvv",
      "    vvvvvvvvvvvv",
      "     vvvvvvvvvvv",
      "     vvvvvvvvvvv",
      "    vvvvvvvvvvvv",
      "vvvvvvvvvvvvvvvv",
      "vvvvvvvvvvvvvvvv",
      "vvvvvvvvvvvvvvvv",
      "vvvvvvvvvvvvvvvv",
      "vvvvvvvvvvvvvvvv",
      "vvvvvvvvvvvvvvvv",
      "vvvvvvvvvvvvvvvv",
      "vvvvvvvvvvvvvvvv",
      "vvvvvvvvvvvvvvvv",
      "vvvvvvvvvvvvvvvv",
      "vvvvvvvvvvvvvvvv"
    ],
    [
      "       ggggggggg",
      "       ggggggggg",
      "       ggggggggg",
      "       ggggggggg",
      "       ggggggggg",
      "       7gggggggg",
      "       7gggggggg",
      "       7gggggggg",
      "      !ggggggggg",
      "     !!ggggggggg",
      "      !!        ",
      "                ",
      "                ",
      "                ",
      "gggggggggggggggg",
      "gggggggggggggggg"
    ],
    [
      "       ggggggggg",
      "       g  gg    ",
      "       g  gg    ",
      "       g        ",
      "       g        ",
      "                ",
      "                ",
      "       !        ",
      "      !g!       ",
      "      !ggggggggg",
      "                ",
      "                ",
      "                ",
      "                ",
      "gggggggggggggggg",
      "                "
    ],
    [
      "       g  g  g  ",
      "       g   gg   ",
      "       g   gg   ",
      "       g        ",
      "       g        ",
      "                ",
      "                ",
      "       !        ",
      "      !g!       ",
      "       g  g  g  ",
      "                ",
      "                ",
      "                ",
      "                ",
      "gggggggggggggggg",
      "                "
    ],
    [
      "       g  g  g  ",
      "       g    gg  ",
      "       g    gg  ",
      "       g        ",
      "       g        ",
      "                ",
      "       !        ",
      "      !!!       ",
      "      !g!       ",
      "       g  g  g  ",
      "                ",
      "                ",
      "                ",
      "                ",
      "gggggggggggggggg",
      "gggggggggggggggg"
    ],
    [
      "       g  g  g  ",
      "       g     gg ",
      "       g     gg ",
      "       g        ",
      "       g        ",
      "       g        ",
      "       g        ",
      "      !g!       ",
      "       g        ",
      "       g  g  g  ",
      "                ",
      "                ",
      "                ",
      "                ",
      "gggggggggggggggg",
      "gggggggggggggggg"
    ]
  ]
}