{
  "xsize": 16,
  "zsize": 16,
  "refpalette": "lostcities:base",
  "slices": [
    [
      "ffffffffffffffff",
      "ffffffffffffffff",
      "ffffffffffffffff",
      "fffggggggggggggg",
      "fffggggggggggggg",
      "fffggggggggggggg",
      "fffggggggggggggg",
      "fffggggggggggggg",
      "fffggggggggggggg",
      "fffggggggggggggg",
      "fffggggggggggggg",
      "fffggggggggggggg",
      "fffggggggggggggg",
      "fffggggggggggggg",
      "fffggggggggggggg",
      "fffggggggggggggg"
    ],
    [
      "ff              ",
      "ff              ",
      "                ",
      "                ",
      "                ",
      "                ",
      "                ",
      "                ",
      "                ",
      "               #",
      "                ",
      "                ",
      "              !!",
      "             !!!",
      "             !!!",
      "             !!!"
    ],
    [
      "ff              ",
      "ff              ",
      "                ",
      "                ",
      "                ",
      "                ",
      "                ",
      "                ",
      "                ",
      "               $",
      "              !!",
      "              !!",
      "             !!!",
      "             !!!",
      "              !!",
      "              !!"
    ],
    [
      "hi              ",
      "jk              ",
      "                ",
      "                ",
      "                ",
      "                ",
      "                ",
      "                ",
      "                ",
      "              !$",
      "             !!!",
      "             !!!",
      "             !!!",
      "              !!",
      "               !",
      "                "
    ],
    [
      "hi              ",
      "jk              ",
      "               %",
      "               %",
      "               &",
      "               '",
      "              ('",
      "              ('",
      "              ('",
      "             !('",
      "            !!('",
      "             )('",
      "             *('",
      "             '('",
      "             '('",
      "             '('"
    ],
    [
      "hi              ",
      "jk             +",
      "               v",
      "              ,v",
      "              ''",
      "              ''",
      "              ''",
      "              ''",
      "             !''",
      "            !(''",
      "            !*''",
      "             *''",
      "             '''",
      "            -'''",
      "            ''''",
      "         ! (''''"
    ]
  ]
}