{
  "xsize": 16,
  "zsize": 16,
  "refpalette": "pomkotsmechs:base",
  "slices": [
    [
      "             Ͷ  ",
      "            Ͷ   ",
      "            Ͷ   ",
      "            Ͷ   ",
      "            Ͷ   ",
      "             Ͷ  ",
      "              ͶͶ",
      "                ",
      "               Ͷ",
      "              Ͷ ",
      "             Ͷ  ",
      "   ͶͶͶͶYYY  Ͷ   ",
      " ͶͶ    ͶͶY  Ͷ   ",
      " Ͷ      ͶYYͶ    ",
      "Ͷ        ͶYͶ    ",
      "Ͷ        ͶYͶ    "
    ],
    [
      "             Ͷ  ",
      "            Ͷ   ",
      "            Ͷ   ",
      "            Ͷ   ",
      "            Ͷ   ",
      "             Ͷ  ",
      "              ͶͶ",
      "                ",
      "               Ͷ",
      "              Ͷ ",
      "             Ͷ  ",
      "   ͶͶͶͶYYY  Ͷ   ",
      " ͶͶ    ͶͶY  Ͷ   ",
      " Ͷ      ͶYYͶ    ",
      "Ͷ        ͶYͶ    ",
      "Ͷ        ͶYͶ    "
    ],
    [
      "             Ͷ  ",
      "            Ͷ   ",
      "            Ͷ   ",
      "            Ͷ   ",
      "            Ͷ   ",
      "             Ͷ  ",
      "              ͶͶ",
      "                ",
      "               Ͷ",
      "              Ͷ ",
      "             Ͷ  ",
      "   ͶͶͶͶYYY  Ͷ   ",
      " ͶͶ    ͶͶY  Ͷ   ",
      " Ͷ      ͶYYͶ    ",
      "Ͷ        ͶYͶ    ",
      "Ͷ        ͶYͶ    "
    ],
    [
      "             Ͷ  ",
      "            Ͷ   ",
      "            Ͷ   ",
      "            Ͷ   ",
      "            Ͷ   ",
      "             Ͷ  ",
      "              ͶͶ",
      "                ",
      "               g",
      "              gg",
      "             ggg",
      "   ͶͶͶͶYYY  gggg",
      " ͶͶ    ͶͶY  gggg",
      " Ͷ      ͶYYggggg",
      "Ͷ        ͶYggggg",
      "Ͷ        ͶYggggg"
    ],
    [
      "             Ͷ  ",
      "            Ͷ   ",
      "            Ͷ   ",
      "            Ͷ   ",
      "            Ͷ   ",
      "             Ͷ  ",
      "              ͶͶ",
      "                ",
      "               g",
      "              gg",
      "             ggg",
      "   ͶͶͶͶYYY  gggg",
      " ͶͶ    ͶͶY  gggg",
      " Ͷ      ͶYYggggg",
      "Ͷ        ͶYggggg",
      "Ͷ        ͶYggggg"
    ],
    [
      "             Ͷ  ",
      "            Ͷ   ",
      "            Ͷ   ",
      "            Ͷ   ",
      "            Ͷ   ",
      "             Ͷ  ",
      "              ͶͶ",
      "                ",
      "               Ͷ",
      "              Ͷ ",
      "             Ͷ  ",
      "     ͶͶYYY  Ͷ   ",
      " Ͷ     ͶͶY  Ͷ   ",
      " Ͷ      ͶYYͶ    ",
      "Ͷ        ͶYͶ    ",
      "Ͷ        ͶYͶ    "
    ]
  ]
}