{
  "xsize": 16,
  "zsize": 16,
  "refpalette": "pomkotsmechs:base",
  "slices": [
    [
      "vvvvvvvvvvvvvvvv",
      "vvvvvvvvvvvvvvvv",
      "vvvvvvvvvvvvvvvv",
      "vvvvvvvvvvvvvvvv",
      "vvvvvvvvvvvvvvvv",
      "vvvvvvvvvvvvvvvv",
      "vvvvvvvvvvvvvvvv",
      "vvvvvvvvvvvvvvvv",
      "vvvvvvvvvvvvvvvv",
      "vvvvvvvvvvvvvvvv",
      "vvvvvvvvvvvvvvvv",
      "vvvvvvvvvvvvvvvv",
      "vvvvvvvvvvvvvvvv",
      "vvvvvvvvvvvvvvvv",
      "vvvvvvvvvvvvvvvv",
      "vvvvvvvvvvvvvvvv"
    ],
    [
      "gggggggggggggggY",
      "gggggggggggggggY",
      "             YYY",
      "                ",
      "                ",
      "                ",
      "g    gggggggggg ",
      "g    gggggggggg ",
      "g    7ggggggggg ",
      "g    7ggggggggg ",
      "g    7ggggggggg ",
      "g    gggggggggg ",
      "g    gggggggggg ",
      "g    gggggggggg ",
      "g    gggggggggg ",
      "g    gggggggggg "
    ],
    [
      "         ggggggY",
      "ggggggggggggggg ",
      "             Y Y",
      "                ",
      "                ",
      "                ",
      "g    gggggggggg ",
      "g    g        g ",
      "g             g ",
      "g             g ",
      "g             g ",
      "g    g        g ",
      "g    g        g ",
      "g    g  gg    g ",
      "g    g  gg    g ",
      "g    gggggggggg "
    ],
    [
      "         ggggggY",
      "ggggggggggggggg ",
      "             Y Y",
      "                ",
      "                ",
      "                ",
      "g    g  g  g  g ",
      "     g          ",
      "                ",
      "g             g ",
      "                ",
      "     g          ",
      "g    g        g ",
      "     g   gg     ",
      "     g   gg     ",
      "g    g  g  g  g "
    ],
    [
      "gggggggggggggggY",
      "ggggggggggggggg ",
      "             Y Y",
      "                ",
      "                ",
      "              ! ",
      "g    g  g  g !g!",
      "     g        ! ",
      "                ",
      "g             g ",
      "                ",
      "     g          ",
      "g    g        g ",
      "     g    gg    ",
      "     g    gg    ",
      "g    g  g  g  g "
    ],
    [
      "gggggggggggggggY",
      "ggggggggggggggg ",
      "             Y Y",
      "                ",
      "                ",
      "              ! ",
      "g    g  g  g !g!",
      "     g        ! ",
      "     g          ",
      "g    g        g ",
      "     g          ",
      "     g          ",
      "g    g        g ",
      "     g     gg   ",
      "     g     gg   ",
      "g    g  g  g  g "
    ]
  ]
}