{
  "xsize": 16,
  "zsize": 16,
  "refpalette": "pomkotsmechs:base",
  "slices": [
    [
      "vvvvvvvvvvvvvvvv",
      "vvvvvvvvvvvvvvvv",
      "vvvvvvvvvvvvvvvv",
      "vvvvvvvvvvvvvvvv",
      "vvvvvvvvvvvvvvvv",
      "vvvvvvvvvvvvvvvv",
      "vvvvvvvvvvvvvvvv",
      "vvvvvvvvvvvvvvvv",
      "vvvvvvvvvvvvvvvv",
      "vvvvvvvvvvvvvvvv",
      "vvvvvvvvvvvvvvvv",
      "vvvvvvvvvvvvvvvv",
      "vvvvvvvvvvvvvvvv",
      "vvvvvvvvvvvvvvvv",
      "vvvvvvvvvvvvvvvv",
      "vvvvvvvvvvvvvvvv"
    ],
    [
      "gggggggggggggggg",
      "gYYYYYYYYYYYYYYg",
      "gYYYYYYYYYYYYYYg",
      "gYYYYYYYYYYYYYYg",
      "gggggggggggggggg",
      "gYYYYYYYYYYYYYY ",
      "gYYYYYYYYYYYYYY ",
      "gYYYYYYYYYYYYYY ",
      "gYYYYYYYYYYYYYY ",
      "gYYYYYYYYYYYYYY ",
      "gYYYYYYYYYYYYYY ",
      "gggggggggggggggg",
      "gYYYYYYYYYYYYYYg",
      "gYYYYYYYYYYYYYYg",
      "gYYYYYYYYYYYYYYg",
      "gggggggggggggggg"
    ],
    [
      "gg             g",
      "gY             g",
      "gYgggggggggggggg",
      "gYgggggggggggggg",
      "gggggggggggggggg",
      "gY              ",
      "gY              ",
      "gY              ",
      "gY              ",
      "gY              ",
      "gY              ",
      "gggggggggggggggg",
      "gYgggggggggggggg",
      "gYgggggggggggggg",
      "gY             g",
      "gg             g"
    ],
    [
      " ggggggggggggggg",
      " YYYYYYYYYYYYYYg",
      "gYYYYYYYYYYYYYYg",
      "gYYYYYYYYYYYYYYg",
      "gggggggggggggggg",
      " YYYYYYYYYYYYYY ",
      " YYYYYYYYYYYYYY ",
      " YYYYYYYYYYYYYY ",
      " YYYYYYYYYYYYYY ",
      " YYYYYYYYYYYYYY ",
      " YYYYYYYYYYYYYY ",
      "gggggggggggggggg",
      "gYYYYYYYYYYYYYYg",
      "gYYYYYYYYYYYYYYg",
      " YYYYYYYYYYYYYYg",
      " ggggggggggggggg"
    ],
    [
      " g             g",
      " YYYYYYYYYYYYYYg",
      "gYYYYYYYYYYYYYYg",
      "gYYYYYYYYYYYYYYg",
      "gggggggggggggggg",
      " YYYYYYYYYYYYYY ",
      " YYYYYYYYYYYYYY ",
      " YYYYYYYYYYYYYY ",
      " YYYYYYYYYYYYYY ",
      " YYYYYYYYYYYYYY ",
      " YYYYYYYYYYYYYY ",
      "gggggggggggggggg",
      "gYYYYYYYYYYYYYYg",
      "gYYYYYYYYYYYYYYg",
      " YYYYYYYYYYYYYYg",
      " g             g"
    ],
    [
      " gg            g",
      " YYYYYYYYYYYYYYg",
      "gYYYYYYYYYYYYYYg",
      "gYYYYYYYYYYYYYYg",
      "gggggggggggggggg",
      " YYYYYYYYYYYYYY ",
      " YYYYYYYYYYYYYY ",
      " YYYYYYYYYYYYYY ",
      " YYYYYYYYYYYYYY ",
      " YYYYYYYYYYYYYY ",
      " YYYYYYYYYYYYYY ",
      "gggggggggggggggg",
      "gYYYYYYYYYYYYYYg",
      "gYYYYYYYYYYYYYYg",
      " YYYYYYYYYYYYYYg",
      " gg            g"
    ]
  ]
}