{
  "xsize": 16,
  "zsize": 16,
  "refpalette": "lostcities:base",
  "slices": [
    [
      "ʹf            fʹ",
      "fʹ            ʹf",
      "                ",
      "                ",
      "fʹ            ʹf",
      "ʹf            fʹ",
      "ʹf            fʹ",
      "ʹf            fʹ",
      "fʹ            ʹf",
      "                ",
      "                ",
      "fʹ            ʹf",
      "ʹf            fʹ",
      "ʹf            fʹ",
      "ʹf            fʹ",
      "fʹ            ʹf"
    ],
    [
      "ʹʹ            ʹʹ",
      "ʹʹ            ʹʹ",
      "                ",
      "                ",
      "ʹʹ            ʹʹ",
      "ʹʹ            ʹʹ",
      "ʹʹ            ʹʹ",
      "ʹʹ            ʹʹ",
      "ʹʹ            ʹʹ",
      "                ",
      "                ",
      "ʹʹ            ʹʹ",
      "ʹʹ            ʹʹ",
      "ʹʹ            ʹʹ",
      "ʹʹ            ʹʹ",
      "ʹʹ            ʹʹ"
    ],
    [
      "                ",
      " n            n ",
      "                ",
      "                ",
      " n            n ",
      "                ",
      "                ",
      "                ",
      " n            n ",
      "                ",
      "                ",
      " n            n ",
      "                ",
      "                ",
      "                ",
      " n            n "
    ],
    [
      "ʹʹ            ʹʹ",
      "ʹʹ            ʹʹ",
      "                ",
      "                ",
      "ʹʹ            ʹʹ",
      "ʹʹ            ʹʹ",
      "ʹʹ            ʹʹ",
      "ʹʹ            ʹʹ",
      "ʹʹ            ʹʹ",
      "                ",
      "                ",
      "ʹʹ            ʹʹ",
      "ʹʹ            ʹʹ",
      "ʹʹ            ʹʹ",
      "ʹʹ            ʹʹ",
      "ʹʹ            ʹʹ"
    ],
    [
      " f            f ",
      "fʹ            ʹf",
      "                ",
      "                ",
      "fʹ            ʹf",
      " f            f ",
      " f            f ",
      " f            f ",
      "fʹ            ʹf",
      "                ",
      "                ",
      "fʹ            ʹf",
      " f            f ",
      " f            f ",
      " f            f ",
      "fʹ            ʹf"
    ],
    [
      " f            f ",
      "fʹ            ʹf",
      "                ",
      "                ",
      "fʹ            ʹf",
      " f            f ",
      " f            f ",
      " f            f ",
      "fʹ            ʹf",
      "                ",
      "                ",
      "fʹ            ʹf",
      " f            f ",
      " f            f ",
      " f            f ",
      "fʹ            ʹf"
    ]
  ]
}