{
  "xsize": 16,
  "zsize": 16,
  "refpalette": "pomkotsmechs:base",
  "slices": [
    [
      "      ffff      ",
      "     f    f     ",
      "    f      f    ",
      "   gf      fg   ",
      "    ffffffff    ",
      "   !f!     f    ",
      "   !ff    ff    ",
      "    f ffff f    ",
      "    f ffff f    ",
      "    ff    ff    ",
      "    f    !!f!   ",
      "    ffffffff    ",
      "   gf      fg   ",
      "           f    ",
      "     f    f     ",
      "      ffff      "
    ],
    [
      "      ffff      ",
      "     f    f     ",
      "    f      f    ",
      "   gf      fg   ",
      "    ffffffff    ",
      "    f      f    ",
      "   !ff!!  ff    ",
      "    f  fff f    ",
      "    f ffff f    ",
      "    ff  !!ff    ",
      "        !!!f!   ",
      "       fffff    ",
      "         !!fg   ",
      "           f    ",
      "     f    f     ",
      "      ffff      "
    ],
    [
      "       ff       ",
      "     ff  ff     ",
      "     f    f     ",
      "   gf      fg   ",
      "    ffffffff    ",
      "    ff!!  ff    ",
      "   !fff!!fff    ",
      "    !!!ff  f    ",
      "      !ff! f    ",
      "    fff!!fff    ",
      "       !!!ff    ",
      "      !fffff    ",
      "       !!! fg   ",
      "          f     ",
      "      f  ff     ",
      "       ff       "
    ],
    [
      "                ",
      "      ffff      ",
      "     ff  ff     ",
      "    gf    fg    ",
      "     ffffff     ",
      "     ff  ff     ",
      "    !ffffff     ",
      "      !!  f     ",
      "     !!!! f     ",
      "     ffffff     ",
      "      !!!ff     ",
      "       ffff     ",
      "          fg    ",
      "         ff     ",
      "      ffff      ",
      "                "
    ],
    [
      "                ",
      "                ",
      "       ff       ",
      "    ggffffgg    ",
      "      ffff      ",
      "      ffff      ",
      "      ffff      ",
      "      ffff      ",
      "     !ffff      ",
      "     !ffff      ",
      "      !fff      ",
      "       fff      ",
      "       fffgg    ",
      "       ff       ",
      "                ",
      "                "
    ],
    [
      "                ",
      "                ",
      "                ",
      "      gggg      ",
      "                ",
      "                ",
      "                ",
      "                ",
      "      !         ",
      "      !!        ",
      "       !!       ",
      "                ",
      "      gggg      ",
      "                ",
      "                ",
      "                "
    ]
  ]
}