{
  "xsize": 16,
  "zsize": 16,
  "refpalette": "lostcities:base",
  "slices": [
    [
      "vvvvvvvvvvvvvvvv",
      "vvvvvvvvvvvvvvvv",
      "vvvvvvvvvvvvvvvv",
      "vvvvvvvvvvvvvvvv",
      "vvvvvvvvvvvvvvvv",
      "vvvvvvvvvvvvvvvv",
      "vvvvvvvvvvvvvvvv",
      "vvvvvvvvvvvvvvvv",
      "vvvvvvvvvvvvvvvv",
      "vvvvvvvvvvvvvvvv",
      "vvvvvvvvvvvvvvvv",
      "vvvvvvvvvvvvvvvv",
      "vvvvvvvvvvvvvvvv",
      "vvvvvvvvvvvvvvvv",
      "vvvvvvvvvvvvvvvv",
      "vvvvvvvvvvvvvvvv"
    ],
    [
      "lfffffffffffffff",
      "ffffffffffffffff",
      "ffffffffffffffff",
      "ffffffffffffffff",
      "ffffffffffffffff",
      " fffffffffffffff",
      " f fffffffffffff",
      " f fffffffffffff",
      " f fffffffffffff",
      " f ffffffffff  f",
      " f ffffffffff   ",
      " f ffffffffff   ",
      "fffffffffffff   ",
      "fffffffffffff   ",
      "fffffffffffff   ",
      "fffffffffffff   "
    ],
    [
      "gg        gg  gg",
      "gggggggggggggggg",
      "gggggggggggg  gg",
      "ggg             ",
      " ggffffffffffff ",
      "  g          ff ",
      "                ",
      "                ",
      "                ",
      "                ",
      " m              ",
      " m              ",
      " m              ",
      " m              ",
      "ggg             ",
      " g              "
    ],
    [
      "ng        gg  gg",
      " goooooooogggggg",
      " g        gg  gg",
      "ggg             ",
      "gggppppppppppff ",
      " mg          ff ",
      "                ",
      "                ",
      "                ",
      "                ",
      "                ",
      "                ",
      "                ",
      "                ",
      " gg             ",
      " g              "
    ],
    [
      " g        gg  gg",
      " goooooooogggggg",
      " g        gg  gg",
      "ggg             ",
      "ggg          hi ",
      "!mg          jk ",
      " m              ",
      " m              ",
      " m              ",
      " m              ",
      " m              ",
      "                ",
      "                ",
      "                ",
      "                ",
      "                "
    ],
    [
      " g        gg  gg",
      " goooooooogggggg",
      " g        gg  gg",
      "ggg             ",
      "ggg          hi ",
      "!mg          jk ",
      " m              ",
      " m              ",
      " m              ",
      " m              ",
      " m              ",
      "                ",
      "                ",
      "                ",
      "  g             ",
      "                "
    ]
  ]
}