{
  "xsize": 16,
  "zsize": 16,
  "refpalette": "pomkotsmechs:base",
  "slices": [
    [
      "         vvvvvvv",
      "          vvvvvv",
      "           vvvvv",
      "    fffffff vvvv",
      "    ff    f   vv",
      "    ff    f     ",
      "    ff    f     ",
      "    ff    f     ",
      "    ff    f     ",
      "    ff    f     ",
      "    ff    f     ",
      "    ff    f     ",
      "    ff    f     ",
      "    ff    f     ",
      "    fffffff     ",
      "                "
    ],
    [
      "          ffffff",
      "          ffffff",
      "          ffffff",
      "    ffffffffffff",
      "    f     ffffff",
      "    f     ffffff",
      "    f     ffffff",
      "    f     ffffff",
      "    f     ffffff",
      "    f     ffffff",
      "    f     ffffff",
      "    f     ffffff",
      "    f     ffffff",
      "    f     ffffff",
      "    ffffffff    ",
      "                "
    ],
    [
      "          f     ",
      "          f     ",
      "          f  n  ",
      "     fffffff    ",
      "     f    ff    ",
      "     f    ff    ",
      "     f    ff n  ",
      "     f    ff    ",
      "     f    ff    ",
      "     f    ff    ",
      "     f    ff    ",
      "     f    ff    ",
      "     f    ff    ",
      "     f    ffffff",
      "     fffffff    ",
      "                "
    ],
    [
      "          f     ",
      "          f     ",
      "          f  ʹʹʹ",
      "     ffffffffʹʹʹ",
      "     f    f fʹʹʹ",
      "     f    f fʹʹʹ",
      "     f    f fʹʹʹ",
      "     f    f f   ",
      "     f    f f   ",
      "     f    f f   ",
      "     f    f f   ",
      "    !f!   f f   ",
      "     f    f f   ",
      "     f    ffffff",
      "     ffffffff   ",
      "                "
    ],
    [
      "          f     ",
      "          f     ",
      "          f  ʹff",
      "      ffffffff  ",
      "      f   f ff  ",
      "      f   f ffͳͳ",
      "      f   f fʹff",
      "      f   f f   ",
      "      f   f f   ",
      "      f   f f   ",
      "     !f   f f   ",
      "    !!f!  f f   ",
      "     !f   f f   ",
      "      f   ffffff",
      "      fffffff   ",
      "                "
    ],
    [
      "          f     ",
      "          f     ",
      "          f  ʹff",
      "      ffffffff  ",
      "      f   f  f  ",
      "      f   f  f  ",
      "      f   f  ʹff",
      "      f   f  f  ",
      "      f   f  f  ",
      "      f   f  f  ",
      "     !f!  f  f  ",
      "     !f!  f  f  ",
      "      f   f  f  ",
      "      f   ffffff",
      "      ffffffff  ",
      "                "
    ]
  ]
}