{
  "xsize": 16,
  "zsize": 16,
  "refpalette": "pomkotsmechs:base",
  "slices": [
    [
      " f            f ",
      " f            f ",
      " f            f ",
      " f            f ",
      " f     !      f ",
      " f    !!!     f ",
      " f    !!!     f ",
      " f     !      f ",
      "gggggggggggggggg",
      "gggggggggggggggg",
      " f            f ",
      " f           !f!",
      " ffffffffffffff ",
      " ffffffffffffff ",
      " ffffffffffffff ",
      "   g        g   "
    ],
    [
      " f            f ",
      " f            f ",
      " f            f ",
      " f            f ",
      " f    !!      f ",
      " f    !!!     f ",
      " f     !      f ",
      " f    !!      f ",
      "gggggggggggggggg",
      "gggggggggggggggg",
      " f            f ",
      " f           !f!",
      " ffffffffffffff ",
      " ffffffffffffff ",
      " ffffffffffffff ",
      "  g          g  "
    ],
    [
      " f            f ",
      " f            f ",
      " f            f ",
      " f    !!      f ",
      " f   !!!!     f ",
      " f    !!!     f ",
      " f     !      f ",
      " f   !!       f ",
      "gggggggggggggggg",
      "gggggggggggggggg",
      " f            f ",
      " f           !f!",
      " ffffffffffffff ",
      " ffffffffffffff ",
      " ffffffffffffff ",
      "  g          g  "
    ],
    [
      " f            f ",
      " f            f ",
      " f              ",
      " f    !       f ",
      " f   !!!      f ",
      " f    !!      f ",
      " f            f ",
      " f  !!        f ",
      "gggggggggggggggg",
      "gggggggggggggggg",
      " f           !f!",
      " f           !f!",
      " ffffffffffffff ",
      " ffffffffffffff ",
      " ffffffffffffff ",
      "  g          g  "
    ],
    [
      " f              ",
      " f              ",
      " f              ",
      " f    !         ",
      " f   !!!        ",
      " f    !       f ",
      " f            f ",
      " f            f ",
      "gggggggggggggggg",
      "gggggggggggggggg",
      " f           !f!",
      " f            f ",
      " ffffffffffffff ",
      " ffffffffffffff ",
      " ffffffffffffff ",
      "  g          g  "
    ],
    [
      " f              ",
      " f              ",
      " f    !         ",
      " f   !!!        ",
      " f   !!!        ",
      " f    !       f ",
      " f            f ",
      " f            f ",
      "gggggggggggggggg",
      "gggggggggggggggg",
      " f          !!f!",
      " f           !f ",
      " ffffffffffffff ",
      " ffffffffffffff ",
      " ffffffffffffff ",
      "   g        g   "
    ]
  ]
}