{
  "xsize": 16,
  "zsize": 16,
  "refpalette": "lostcities:base",
  "slices": [
    [
      "                ",
      "  ffffffff      ",
      "ffffff   f      ",
      "  f  f   f      ",
      "  f  f!! f      ",
      "  f  f!! f      ",
      "ffʹ !f!  f      ",
      "ʹʹf!!f   f      ",
      "ʹʹf!!f   f      ",
      "ʹʹf  f   f      ",
      "ffʹ  f   f      ",
      "  f  f   f      ",
      "  ffffffff      ",
      "ffʹ  f          ",
      "ʹʹf  f          ",
      "ʹʹf  f          "
    ],
    [
      "                ",
      "  fffffff       ",
      "ffffff  f       ",
      "  f  f!!f       ",
      "  f  f!!f       ",
      "  f !f!!f       ",
      "ʹʹʹ!!f! f       ",
      "ʹʹʹ!!f  f       ",
      "ʹʹʹ!!f  f       ",
      "ʹʹʹ  f  f       ",
      "ʹʹʹ  f  f       ",
      "  f  f  f       ",
      "  fffffff       ",
      "ʹʹʹ  f          ",
      "ʹʹʹ  f          ",
      "ʹʹʹ  f          "
    ],
    [
      "                ",
      " ffffffff       ",
      "ffffff  f       ",
      " f   f !f!      ",
      " f   f!!f       ",
      " f  !f!!f       ",
      " fn !f! f       ",
      " f! !f  f       ",
      " f!! f  f       ",
      " f!  f  f       ",
      " fn  f  f       ",
      " f   f  f       ",
      " ffffffff       ",
      "  n  f          ",
      "     f          ",
      "     f          "
    ],
    [
      "                ",
      " fffffff        ",
      "ffffff f!       ",
      " f   f!f!!      ",
      " f    !f!       ",
      " f   ! !        ",
      "ʹʹʹ  ! f        ",
      "ʹʹʹ  f f        ",
      "ʹʹʹ! f f        ",
      "ʹʹʹ  f f        ",
      "ʹʹʹ  f f        ",
      " f   f f        ",
      " fffffff        ",
      "ʹʹʹ  f          ",
      "ʹʹʹ  f          ",
      "ʹʹʹ  f          "
    ],
    [
      "                ",
      "ffffffff        ",
      "ffffff f        ",
      "f    f!f!       ",
      "f      !        ",
      "f               ",
      "ffʹ             ",
      "f f  f f        ",
      "f!f! f f        ",
      "ͳͳf  f f        ",
      "ffʹ  f f        ",
      "f    f f        ",
      "ffffffff        ",
      "ffʹ  f          ",
      "  f  f          ",
      "  f  f          "
    ],
    [
      "                ",
      "fffffff         ",
      "fffffff         ",
      "f    f !        ",
      "f               ",
      "f               ",
      "ffʹ             ",
      "f f  f          ",
      "f!f! ff         ",
      "f f  ff         ",
      "ffʹ  ff         ",
      "f    ff         ",
      "fffffff         ",
      "ffʹ  f          ",
      "  f  f          ",
      "  f  f          "
    ]
  ]
}