{
  "xsize": 16,
  "zsize": 16,
  "refpalette": "pomkotsmechs:base",
  "slices": [
    [
      "gggggggggggggggg",
      "gggggggggggggggg",
      "gggggggggggggggg",
      "gggggggggggggggg",
      "gggggggggggggggg",
      "gggggggggggggggg",
      "gggggggggggggggg",
      "gggggggggggggggg",
      "gggggggggggggggg",
      "gggggggggggggggg",
      "gggggggggggggggg",
      "gggggggggggggggg",
      "gggggggggggggggg",
      "gggggggggggggggg",
      "gggggggggggggggg",
      "gggggggggggggggg"
    ],
    [
      "g            gg ",
      " g          gY g",
      "             Y  ",
      "             Y  ",
      "             Y!!",
      "            !Y!!",
      "           !!Y!!",
      "            !Y! ",
      "             Y  ",
      "          ! !Y! ",
      "         !!!!Y! ",
      "          !  g!!",
      " g !        ggg!",
      "gYYYYYYYYYYggggg",
      "g !!!       ggg ",
      " g !         g  "
    ],
    [
      "g            gg ",
      "             Y  ",
      "             Y  ",
      "             Y  ",
      "            !Y  ",
      "           !!Y  ",
      "           !!Y! ",
      "            !Y  ",
      "             Y  ",
      "          ! !Y! ",
      "         !!! Y  ",
      "          !  g  ",
      "  !!        ggg ",
      "gYYYYYYYYYYggggg",
      "g !!        ggg ",
      "             g  "
    ],
    [
      "g            gg ",
      "             Y  ",
      "             Y  ",
      "             Y  ",
      "            !Y  ",
      "           !!Y  ",
      "            !Y! ",
      "            !Y! ",
      "          ! !Y! ",
      "         !!!!Y! ",
      "         !!! Y  ",
      "          !  g  ",
      "  !         ggg ",
      "gYYYYYYYYYYggggg",
      "g !         ggg ",
      "             g  "
    ],
    [
      "g            gg ",
      "             Y  ",
      "             Y  ",
      "             Y  ",
      "            !Y  ",
      "           !!Y  ",
      "            !Y  ",
      "            !Y! ",
      "          !  Y  ",
      "         !!! Y  ",
      "          !  Y  ",
      "             g  ",
      "  !          gg ",
      "gYYYYYYYYY  gggg",
      "g !          gg ",
      "             g  "
    ],
    [
      "g            gg ",
      "             Y  ",
      "             Y  ",
      "             Y  ",
      "            !Y  ",
      "           !!Y  ",
      "            !Y  ",
      "            !Y! ",
      "          ! !Y! ",
      "         !!! Y  ",
      "          !  Y  ",
      "             g  ",
      " !!          gg ",
      "gYYYYYYYY    ggg",
      "g!!           g ",
      "                "
    ]
  ]
}