{
  "xsize": 16,
  "zsize": 16,
  "refpalette": "pomkotsmechs:base",
  "slices": [
    [
      "                ",
      "                ",
      "      !         ",
      "     !ͶͶͶͶ      ",
      "     ͶͶͶͶͶͶ     ",
      "     ͶͶͶͶͶͶ     ",
      "     ͶͶͶͶͶͶ     ",
      "     ͶͶͶͶͶͶ     ",
      "      ͶͶͶͶ      ",
      "       ͲͲ       ",
      "    Ͳ  ͲͲ  Ͳ    ",
      "   ͲͲͲͲͲͲͲͲͲͲ   ",
      "    Ͳ      Ͳ    ",
      "    Ͳ    ! Ͳ    ",
      "   ͲͲͲͲͲͲͲͲͲͲ   ",
      "    Ͳ    ! Ͳ    "
    ],
    [
      "                ",
      "                ",
      "      !         ",
      "     !ͶͶͶͶ      ",
      "     ͶͶͶͶͶͶ     ",
      "     ͶͶͶͶͶͶ     ",
      "     ͶͶͶͶͶͶ     ",
      "     ͶͶͶͶͶͶ     ",
      "      ͶͶͶͶ      ",
      "                ",
      "                ",
      "                ",
      "                ",
      "                ",
      "         !      ",
      "                "
    ],
    [
      "                ",
      "                ",
      "      !         ",
      "     !gggg      ",
      "     g!   g     ",
      "     g    g     ",
      "     g    g     ",
      "     g    g     ",
      "      gggg      ",
      "                ",
      "                ",
      "                ",
      "                ",
      "                ",
      "                ",
      "                "
    ],
    [
      "                ",
      "                ",
      "      !         ",
      "     !ͶͶͶͶ      ",
      "     ͶͶͶͶͶͶ     ",
      "     ͶͶͶͶͶͶ     ",
      "     ͶͶͶͶͶͶ     ",
      "     ͶͶͶͶͶͶ     ",
      "      ͶͶͶͶ      ",
      "                ",
      "                ",
      "                ",
      "                ",
      "                ",
      "                ",
      "                "
    ],
    [
      "                ",
      "                ",
      "      !!        ",
      "     !!ͶͶ       ",
      "      ͶͶͶͶ      ",
      "     ͶͶͶͶͶͶ     ",
      "     ͶͶͶͶͶͶ     ",
      "      ͶͶͶͶ      ",
      "       ͶͶ       ",
      "                ",
      "                ",
      "                ",
      "                ",
      "                ",
      "                ",
      "                "
    ],
    [
      "                ",
      "                ",
      "       !        ",
      "      !!!       ",
      "      ͶͶͶͶ      ",
      "      ͶͶͶͶ      ",
      "      ͶͶͶͶ      ",
      "      ͶͶͶͶ      ",
      "                ",
      "                ",
      "                ",
      "                ",
      "                ",
      "                ",
      "                ",
      "                "
    ]
  ]
}