{
  "xsize": 16,
  "zsize": 16,
  "refpalette": "pomkotsmechs:base",
  "slices": [
    [
      "g            gg ",
      "             Y  ",
      "             Y  ",
      "            !Y  ",
      "           !!Y  ",
      "           !!Y  ",
      "            !Y  ",
      "             Y  ",
      "          ! !Y! ",
      "         !!! Y  ",
      "          !  Y  ",
      "             gg ",
      " !           ggg",
      "gYYYYYYYY   gggg",
      "g!           ggg",
      "             gg "
    ],
    [
      "g            gg ",
      "             Y  ",
      "             Y  ",
      "            !Y  ",
      "           !!Y  ",
      "            !Y  ",
      "             Y  ",
      "             Y  ",
      "          ! !Y! ",
      "         !!!!Y! ",
      "          !  Y  ",
      "             g  ",
      "!!           gg ",
      "gYYYYYYYYY  gggg",
      "g!           gg ",
      "!            g  "
    ],
    [
      "g            g  ",
      "             Y  ",
      "             Y  ",
      "            !Y  ",
      "           !!Y  ",
      "            !Y  ",
      "             Y  ",
      "             Y  ",
      "          !  Y  ",
      "         !!!!Y! ",
      "          !  Y  ",
      "             g  ",
      "            ggg ",
      "gYYYYYYYYYYggggg",
      "g!          ggg ",
      "!            g  "
    ],
    [
      "g            g  ",
      "                ",
      "             Y  ",
      "            !Y  ",
      "           !!Y  ",
      "            !Y  ",
      "             Y  ",
      "          !  Y  ",
      "         !!! Y  ",
      "         !!!!Y! ",
      "          !  Y  ",
      "             g  ",
      "            ggg ",
      "gYYYYYYYYYYggggg",
      "g!          ggg ",
      "!            g  "
    ],
    [
      "g               ",
      "                ",
      "            !   ",
      "           !!Y  ",
      "           !!Y  ",
      "            !Y  ",
      "             Y  ",
      "          !  Y  ",
      "         !!!!Y! ",
      "          ! !Y! ",
      "             Y  ",
      "             g  ",
      "            ggg ",
      "gYYYYYYYYYYggggg",
      "g           ggg ",
      "             g  "
    ],
    [
      "g        !      ",
      " g       !      ",
      "         !! !   ",
      "          !!!Y  ",
      "            !Y!!",
      "             Y !",
      "             Y !",
      "          !  Y!!",
      "         !!!!Y!!",
      "          !  Y! ",
      "             Y  ",
      "             g  ",
      " g          ggg ",
      "gYYYYYYYYYYggggg",
      "            ggg ",
      "             g  "
    ]
  ]
}