{
  "xsize": 16,
  "zsize": 16,
  "refpalette": "pomkotsmechs:base",
  "slices": [
    [
      "ʹf            fʹ",
      "fʹ            ʹf",
      "                ",
      "f              f",
      "fʹ            ʹf",
      "ʹf            fʹ",
      "ʹf            fʹ",
      "ʹf            fʹ",
      "fʹ            ʹf",
      "f              f",
      "f              f",
      "fʹ            ʹf",
      "ʹf            fʹ",
      "ʹf            fʹ",
      "ʹf            fʹ",
      "fʹ            ʹf"
    ],
    [
      " ʹ           !ʹʹ",
      " ʹ            ʹʹ",
      "                ",
      "f              f",
      "ʹʹ            ʹʹ",
      "ʹʹ            ʹʹ",
      "ʹʹ            ʹʹ",
      "ʹʹ            ʹʹ",
      "ʹʹ            ʹʹ",
      "f              f",
      "f              f",
      "ʹʹ            ʹʹ",
      "ʹʹ            ʹʹ",
      "ʹʹ            ʹʹ",
      "ʹʹ            ʹʹ",
      "ʹʹ            ʹʹ"
    ],
    [
      "           !!!  ",
      "          !!!!! ",
      "          !   !!",
      "f              f",
      "f              f",
      "f              f",
      "f              f",
      "f              f",
      "f              f",
      "f              f",
      "f              f",
      "f              f",
      "f              f",
      "f              f",
      "f              f",
      "                "
    ],
    [
      " fffffffffffffff",
      " fffffffffffffff",
      "ffffffffffffffff",
      "ffffffffffffffff",
      "ffffffffffffffff",
      "ffffffffffffffff",
      "ffffffffffffffff",
      "ffffffffffffffff",
      "ffffffffffffffff",
      "ffffffffffffffff",
      "ffffffffffffffff",
      "ffffffffffffffff",
      "ffffffffffffffff",
      "ffffffffffffffff",
      "ffffffffffffffff",
      "fffffffffffffff "
    ],
    [
      "           !!!  ",
      "          !!!!!!",
      "          !   !!",
      "ff            ff",
      " f            f ",
      " f            f ",
      " f            f ",
      " f            f ",
      " f            f ",
      " f            f ",
      "!f!           f ",
      " f            f ",
      " f            f ",
      " f            f ",
      "ff            ff",
      "                "
    ],
    [
      "            !   ",
      "                ",
      "               !",
      "f              f",
      "f              f",
      "f              f",
      "f              f",
      "f              f",
      "f              f",
      "f!             f",
      "f!!            f",
      "f!             f",
      "f              f",
      "f              f",
      "f              f",
      "                "
    ]
  ]
}