{
  "xsize": 16,
  "zsize": 16,
  "refpalette": "lostcities:base",
  "slices": [
    [
      "          f  fʹʹ",
      "          f  ʹff",
      "          f     ",
      "         fffffff",
      "         ff  ʹff",
      "         ff  fʹʹ",
      "         ff  fʹʹ",
      "        !ff  fʹʹ",
      "         ff  ʹff",
      "         ff     ",
      "         ff     ",
      "         ff  ʹff",
      "         ff  fʹʹ",
      "         ff  fʹʹ",
      "         fffffʹʹ",
      "          f  ʹff"
    ],
    [
      "          f  ʹ  ",
      "          f     ",
      "          f     ",
      "         ff   ff",
      "             ʹʹʹ",
      "             ʹʹʹ",
      "         ff  ʹʹʹ",
      "        !ff  ʹʹʹ",
      "        !ff  ʹʹʹ",
      "         ff     ",
      "         ff     ",
      "         ff  ʹʹʹ",
      "         ff  ʹʹʹ",
      "         ff  ʹʹʹ",
      "         ffffʹʹʹ",
      "          f  ʹʹʹ"
    ],
    [
      "          f     ",
      "          f     ",
      "                ",
      "              ff",
      "                ",
      "                ",
      "          f     ",
      "         !f     ",
      "        !!f!    ",
      "         !f!    ",
      "          f     ",
      "          f     ",
      "          f     ",
      "          f     ",
      "          ffffff",
      "          f   !!"
    ],
    [
      "          ffff  ",
      "          ff    ",
      "                ",
      "             fff",
      "            ffff",
      "           fffff",
      "          ffffff",
      "          ffffff",
      "         !ffffff",
      "         !ffffff",
      "          ffffff",
      "          ffffff",
      "          ffffff",
      "          ffffff",
      "          ffffff",
      "          ffffff"
    ],
    [
      "                ",
      "                ",
      "                ",
      "             fff",
      "                ",
      "           f    ",
      "           f    ",
      "           f    ",
      "          !f    ",
      "         !!f!   ",
      "         !!f!  !",
      "          !f    ",
      "           f    ",
      "           f   !",
      "           fffff",
      "              !!"
    ],
    [
      "                ",
      "                ",
      "                ",
      "           fffff",
      "           f   f",
      "           f   f",
      "           f   f",
      "           f   f",
      "           f   f",
      "          !f   f",
      "          !f!!!f",
      "           f  !f",
      "           f   f",
      "           f   f",
      "           fffff",
      "               !"
    ]
  ]
}