{
  "xsize": 16,
  "zsize": 16,
  "refpalette": "lostcities:base",
  "slices": [
    [
      " ggg            ",
      "gggg     !!    g",
      "gggggYYYYYYYYYYg",
      "gggg     !!     ",
      " ggg            ",
      "  Y             ",
      "  Y             ",
      "  Y             ",
      "  Y             ",
      "  Y             ",
      "  Y             ",
      "  Y             ",
      " !Y!            ",
      " !Y!            ",
      "  Y             ",
      " gg            g"
    ],
    [
      "  g             ",
      " ggg      !!   g",
      "gggggY YYYYYYYYg",
      " ggg      !!    ",
      "  g             ",
      "  Y             ",
      "  Y             ",
      "  Y             ",
      "  Y             ",
      "  Y             ",
      "  Y             ",
      "  Y             ",
      "  Y             ",
      " !Y!            ",
      "  Y             ",
      " gg            g"
    ],
    [
      "  g             ",
      " ggg       !   g",
      "gggggY  YYYYYYYg",
      " ggg       !    ",
      "  g             ",
      "  Y             ",
      "  Y             ",
      "  Y             ",
      "  Y             ",
      "  Y             ",
      "  Y             ",
      "  Y             ",
      "  Y             ",
      " !Y!            ",
      "  Y             ",
      " gg            g"
    ],
    [
      "  g             ",
      " ggg       !   g",
      "gggggY   YYYYYYg",
      " ggg       !    ",
      "  g             ",
      "  Y             ",
      "  Y             ",
      "  Y             ",
      "  Y             ",
      "  Y             ",
      "  Y             ",
      "  Y             ",
      "  Y             ",
      " !Y!            ",
      " !Y             ",
      " gg            g"
    ],
    [
      "  g             ",
      " gg        !!  g",
      "ggg       !YYYYg",
      " ggg       !!   ",
      "  g             ",
      "  Y             ",
      "  Y             ",
      "  Y             ",
      "  Y             ",
      "  Y             ",
      "  Y             ",
      "  Y             ",
      " !Y             ",
      "!!Y!            ",
      "!!Y             ",
      " gg            g"
    ],
    [
      "  g        !! g ",
      " gg         !! g",
      "ggg        YYYYg",
      " ggg          g ",
      "  g         !   ",
      "  Y         !   ",
      "  Y         !   ",
      "  Y         !   ",
      "  Y             ",
      "  Y             ",
      "  Y             ",
      "  Y             ",
      "  Y             ",
      "!!Y             ",
      "g!Yg          g!",
      "!gg            g"
    ]
  ]
}