{
  "xsize": 16,
  "zsize": 16,
  "refpalette": "pomkotsmechs:base",
  "slices": [
    [
      "                ",
      "                ",
      "                ",
      "                ",
      "                ",
      "                ",
      "g    g   !    g ",
      "        !!YY    ",
      "        !!YY    ",
      "      !         ",
      "     !!!        ",
      "     !!!        ",
      "      !         ",
      "                ",
      "                ",
      "g    g        g "
    ],
    [
      "                ",
      "                ",
      "                ",
      "                ",
      "                ",
      "                ",
      "g    g   !!   g ",
      "        !YY!    ",
      "         YY     ",
      "     !!         ",
      "    !!!!        ",
      "     !!         ",
      "                ",
      "                ",
      "                ",
      "g    g        g "
    ],
    [
      "                ",
      "                ",
      "                ",
      "                ",
      "                ",
      "                ",
      "g    g   !    g ",
      "        YY!     ",
      "        YY      ",
      "     !          ",
      "    !!!         ",
      "     !          ",
      "                ",
      "                ",
      "                ",
      "g    g        g "
    ],
    [
      "                ",
      "                ",
      "                ",
      "                ",
      "                ",
      "                ",
      "g    g   !!   g ",
      "       YY!!     ",
      "     ! YY!      ",
      "    !!!         ",
      "    !!!         ",
      "     !          ",
      "                ",
      "                ",
      "                ",
      "g    g        g "
    ],
    [
      "                ",
      "                ",
      "                ",
      "                ",
      "                ",
      "          !     ",
      "g    g   !!!  g ",
      "      YY!!!!    ",
      "     !YY !!     ",
      "    !!!         ",
      "     !          ",
      "     !          ",
      "                ",
      "                ",
      "                ",
      "g    g        g "
    ],
    [
      "                ",
      "                ",
      "                ",
      "                ",
      "                ",
      "          !     ",
      "g    gggggggggg ",
      "g    gY  !!YYYg ",
      "g    gY    YYYg ",
      "g   !gYYYYYYYYg ",
      "g   !gYYYYYYYYg ",
      "g   !gYYYYYYYYg ",
      "g    gYYYYYYYYg ",
      "g    gYYYYYYYYg ",
      "g    gYYYYYYYYg ",
      "g    gggggggggg "
    ]
  ]
}