{
  "xsize": 16,
  "zsize": 16,
  "refpalette": "lostcities:base",
  "slices": [
    [
      "vvvvvvvvvvvvvvvv",
      "vvvvvvvvvvvvvvvv",
      "vvvvvvvvvvvvvvvv",
      "vvvvvvvvvvvvvvvv",
      "vvvvvvvvvvvvvvvv",
      "vvvvvvvvvvvvvvvv",
      "vvvvvvvvvvvvvvvv",
      "vvvvvvvvvvvvvvvv",
      "vvvvvvvvvvvvvvvv",
      "vvvvvvvvvvvvvvvv",
      "vvvvvvvvvvvvvvvv",
      "vvvvvvvvvvvvvvvv",
      "vvvvvvvvvvvvvvvv",
      "vvvvvvvvvvvvvvvv",
      "vvvvvvvvvvvvvvvv",
      "vvvvvvvvvvvvvvvv"
    ],
    [
      "           !!   ",
      " gͺͺg     !gͺͺg ",
      " ͻ  ͻ      ͻ! ͻ ",
      " ͻ  ͻ      ͻ  ͻ ",
      " gͺͺg      gͺͺg ",
      "                ",
      "                ",
      "                ",
      "                ",
      "                ",
      "      gg        ",
      " gͺͺg      gͺͺg ",
      " ͻ  ͻ      ͻ  ͻ!",
      " ͻ  ͻ      ͻ  ͻ!",
      " gͺͺg      gͺͺg!",
      "                "
    ],
    [
      "           !    ",
      " hppi     !hppi ",
      " z  z      z  z ",
      " z  z      z  z ",
      " jppk      jppk ",
      "                ",
      "                ",
      "                ",
      "                ",
      "                ",
      "       gg       ",
      " hppi      hppi ",
      " z  z      z  z!",
      " z  z      z  z!",
      " jppk      jppk!",
      "                "
    ],
    [
      "           !    ",
      "  |{      !!|{  ",
      " ͼ  ͼ      ͼ  ͼ ",
      " ͽ  ͽ      ͽ  ͽ ",
      "  |{        |{  ",
      "                ",
      "                ",
      "                ",
      "                ",
      "                ",
      "        gg      ",
      "  |{        |{  ",
      " ͼ  ͼ      ͼ  ͼ!",
      " ͽ  ͽ      ͽ  ͽ!",
      "  |{        |{!!",
      "              !!"
    ],
    [
      "           !    ",
      " hppi     !hppi ",
      " z  z     !z! z ",
      " z  z      z  z ",
      " jppk      jppk ",
      "                ",
      "                ",
      "                ",
      "                ",
      "                ",
      "         gg     ",
      " hppi      hppi ",
      " z  z      z  z ",
      " z  z      z  z!",
      " jppk      jppk!",
      "              ! "
    ],
    [
      "           !!   ",
      "  |{      !!|{  ",
      " ͼ  ͼ     !ͼ! ͼ ",
      " ͽ  ͽ      ͽ  ͽ ",
      "  |{        |{  ",
      "                ",
      "                ",
      "                ",
      "                ",
      "                ",
      "          gg    ",
      "  |{      ! |{  ",
      " ͼ  ͼ      ͼ  ͼ ",
      " ͽ  ͽ      ͽ  ͽ ",
      "  |{        |{!!",
      "              ! "
    ]
  ]
}