{
  "xsize": 16,
  "zsize": 16,
  "refpalette": "pomkotsmechs:base",
  "slices": [
    [
      "  Ͷ   Ͷ    Ͷ!   ",
      "   Ͷ Ͷ     !Ͷ!  ",
      "   Ͷ Ͷ      Ͷ   ",
      "   Ͷ Ͷ      Ͷ   ",
      "   Ͷ Ͷ      Ͷ   ",
      "  Ͷ   Ͷ    Ͷ    ",
      "ͶͶ     ͶͶͶͶ     ",
      " ͶͶͶͶͶͶ         ",
      "Ͷ      ͶͶ       ",
      "         Ͷ      ",
      "          Ͷ     ",
      "           Ͷ    ",
      "           Ͷ    ",
      "            Ͷ   ",
      "            Ͷ   ",
      "            Ͷ   "
    ],
    [
      "  Ͷ   Ͷ    Ͷ!   ",
      "   Ͷ Ͷ     !Ͷ!  ",
      "   Ͷ Ͷ      Ͷ   ",
      "   Ͷ Ͷ      Ͷ   ",
      "   Ͷ Ͷ      Ͷ   ",
      "  Ͷ   Ͷ    Ͷ    ",
      "ͶͶ     ͶͶͶͶ     ",
      " ͶͶͶͶͶͶ         ",
      "Ͷ      ͶͶ       ",
      "         Ͷ      ",
      "          Ͷ     ",
      "           Ͷ    ",
      "           Ͷ    ",
      "            Ͷ   ",
      "            Ͷ   ",
      "            Ͷ   "
    ],
    [
      "  Ͷ   Ͷ    Ͷ!   ",
      "   Ͷ Ͷ     !Ͷ!  ",
      "   Ͷ Ͷ      Ͷ   ",
      "   Ͷ Ͷ      Ͷ   ",
      "   Ͷ Ͷ      Ͷ   ",
      "  Ͷ   Ͷ    Ͷ    ",
      "ͶͶ     ͶͶͶͶ     ",
      " ͶͶͶͶͶͶ         ",
      "Ͷ      ͶͶ       ",
      "         Ͷ      ",
      "          Ͷ     ",
      "           Ͷ    ",
      "           Ͷ    ",
      "            Ͷ   ",
      "            Ͷ   ",
      "            Ͷ   "
    ],
    [
      "  Ͷ   Ͷ    Ͷ!   ",
      "   Ͷ Ͷ     !Ͷ!  ",
      "   Ͷ Ͷ      Ͷ   ",
      "   Ͷ Ͷ      Ͷ   ",
      "   Ͷ Ͷ      Ͷ   ",
      "  Ͷ   Ͷ    Ͷ    ",
      "ͶͶ     ͶͶͶͶ     ",
      " ͶͶͶͶͶͶ         ",
      "Ͷ      ͶͶ       ",
      "         Ͷ      ",
      "          Ͷ     ",
      "           Ͷ    ",
      "           Ͷ    ",
      "            Ͷ   ",
      "            Ͷ   ",
      "            Ͷ   "
    ],
    [
      "  Ͷ   Ͷ    Ͷ!   ",
      "   Ͷ Ͷ     !Ͷ!  ",
      "   Ͷ Ͷ      Ͷ   ",
      "   Ͷ Ͷ      Ͷ   ",
      "   Ͷ Ͷ      Ͷ   ",
      "  Ͷ   Ͷ    Ͷ    ",
      "ͶͶ     ͶͶͶͶ     ",
      " ͶͶͶͶͶͶ         ",
      "Ͷ      ͶͶ       ",
      "         Ͷ      ",
      "          Ͷ     ",
      "           Ͷ    ",
      "           Ͷ    ",
      "            Ͷ   ",
      "            Ͷ   ",
      "            Ͷ   "
    ],
    [
      "  Ͷ   Ͷ    Ͷ!   ",
      "   Ͷ Ͷ     !Ͷ!  ",
      "   Ͷ Ͷ     !Ͷ!  ",
      "   Ͷ Ͷ      Ͷ   ",
      "   Ͷ Ͷ      Ͷ   ",
      "  Ͷ   Ͷ    Ͷ    ",
      "ͶͶ     ͶͶͶͶ     ",
      " ͶͶͶͶͶͶ         ",
      "Ͷ      ͶͶ       ",
      "         Ͷ      ",
      "          Ͷ     ",
      "           Ͷ    ",
      "           Ͷ    ",
      "            Ͷ   ",
      "            Ͷ   ",
      "            Ͷ   "
    ]
  ]
}