{
  "xsize": 16,
  "zsize": 16,
  "refpalette": "lostcities:base",
  "slices": [
    [
      "ʹʹʹʹʹʹʹʹ    ʹʹʹʹ",
      "ʹʹʹʹʹʹʹʹ    ʹʹʹʹ",
      "ʹʹʹʹʹʹʹʹ    ʹʹʹʹ",
      "ʹʹʹʹʹʹʹʹ   ʹʹʹʹ ",
      "ʹʹʹʹʹʹʹʹ ʹʹʹʹ!  ",
      "ʹʹʹʹʹʹʹʹʹʹʹʹʹ!! ",
      "ʹʹʹʹʹʹʹʹʹʹʹʹʹʹʹ ",
      "ʹʹʹʹʹʹʹʹʹʹʹʹʹʹʹʹ",
      "ʹʹʹ ʹʹʹʹʹʹʹʹʹʹʹʹ",
      "ʹ   ʹʹʹʹʹʹʹʹʹʹʹʹ",
      "ʹ   ʹʹʹʹʹʹʹʹʹʹʹʹ",
      "ʹ   ʹʹʹʹʹʹʹʹʹʹʹʹ",
      "ʹ   ʹʹʹʹʹʹʹʹʹʹʹʹ",
      "  ʹʹʹʹʹʹʹʹʹʹʹʹʹʹ",
      "     !ʹʹʹʹʹʹʹʹʹʹ",
      "      ʹʹʹʹʹʹʹʹʹʹ"
    ],
    [
      "gppppppp    pppg",
      "z              z",
      "z              z",
      "z    ʹʹ        z",
      "z   fff  fff !  ",
      "z  ʹfff  fffʹ!! ",
      "z  ʹffffffffʹ!  ",
      "z   ffffffff   z",
      "z     ffffff   z",
      "z   f ffffffʹ  z",
      "    ffffffffʹ  z",
      "     fffffff!  z",
      "     ʹʹ  ʹʹ !  z",
      "    !!!    !!  z",
      "     !     !!  z",
      "gppp ppppppppppg"
    ],
    [
      "g              g",
      "                ",
      "                ",
      "     ʹʹ         ",
      "    fff  fff !  ",
      "   ʹf      fʹ!! ",
      "   ʹf      fʹ!  ",
      "           f    ",
      "           f    ",
      "           fʹ   ",
      "      !    fʹ   ",
      "     fffffff    ",
      "    !ʹʹ! ʹʹ     ",
      "   !!!!         ",
      "    !!          ",
      "g          !!  g"
    ],
    [
      "                ",
      "                ",
      "                ",
      "      ʹ  ʹ      ",
      "    f      f !! ",
      "            !!!!",
      "             !! ",
      "           f    ",
      "           f    ",
      "                ",
      "      !!        ",
      "    f!!ff  f    ",
      "    !!!!        ",
      "   !!!!         ",
      "   !!!          ",
      "    !           "
    ],
    [
      "                ",
      "                ",
      "                ",
      "    ʹʹʹʹʹʹʹʹ    ",
      "   ʹffffffffʹ ! ",
      "   ʹf      fʹ!!!",
      "           fʹ ! ",
      "           fʹ   ",
      "           fʹ   ",
      "      !!   fʹ   ",
      "    f!!!!  fʹ   ",
      "   ʹffffffffʹ   ",
      "    ʹ!! ʹʹʹʹ    ",
      "   !!!!         ",
      "  !!!!          ",
      "   !!           "
    ],
    [
      "                ",
      "                ",
      "                ",
      "     ʹ    ʹ     ",
      "    ffffffff  ! ",
      "   ʹffffffffʹ!!!",
      "    ffffffff  ! ",
      "      ffffff !! ",
      "      ffffff !  ",
      "     fffffff    ",
      "   ʹffffffffʹ   ",
      "      !!  ff    ",
      "    !     ʹ     ",
      "   !!!          ",
      "  !!!           ",
      "   !            "
    ]
  ]
}