{
  "xsize": 16,
  "zsize": 16,
  "refpalette": "pomkotsmechs:base",
  "slices": [
    [
      "     g         g",
      "        !!YYYYYg",
      "     YYYYYYYYYYg",
      "    !YYYYYYYYYYg",
      "   !!ggggggggggg",
      "    !YYYYYYYYYY ",
      "     YYYYYYYYYY ",
      "     YYYYYYYYYY ",
      "     YYYYYYYYYY ",
      "     YYYYYYYYYY ",
      "     YYYYYYYYYY ",
      "    gggggggggggg",
      "    gYYYYYYYYYYg",
      "    gYYYYYYYYYYg",
      "     YYYY   YYYg",
      "     g         g"
    ],
    [
      "     g   !     g",
      "      Y !!YYYYYg",
      "     YYYYYYYYYYg",
      "    !YYYYYYYYYYg",
      "   !gggggggggggg",
      "    !YYYYYYYYYY ",
      "     YYYYYYYYYY ",
      "     YYYYYYYYYY ",
      "     YYYYYYYYYY ",
      "     YYYYYYYYYY ",
      "     YYYYYYYYYY ",
      "    gggggggggggg",
      "    gYYYYYYYYYYg",
      "    gYYYYYYYYYYg",
      "     YYYY    YYg",
      "     g         g"
    ],
    [
      "     g   !!    g",
      "      Y !!YYYYYg",
      "     YYYYYYYYYYg",
      "    !YYYYYYYYYYg",
      "   !gggggggggggg",
      "    !YYYYYYYYYY ",
      "     YYYYYYYYYY ",
      "     YYYYYYYYYY ",
      "     YYYYYYYYYY ",
      "     YYYYYYYYYY ",
      "     YYYYYYYYYY ",
      "    gggggggggggg",
      "    gYYYYYYYYYYg",
      "    gYYYYYYYYYYg",
      "     YYYYY   YYg",
      "     g         g"
    ],
    [
      "     gg   !    g",
      "      Y  !YYYYYg",
      "     YYYYYYYYYYg",
      "    !YYYYYYYYYYg",
      "   !gggggggggggg",
      "    !YYYYYYYYYY ",
      "     YYYYYYYYYY ",
      "     YYYYYYYYYY ",
      "     YYYYYYYYYY ",
      "     YYYYYYYYYY ",
      "     YYYYYYYYYY ",
      "    gggggggggggg",
      "    gYYYYYYYYYYg",
      "    gYYYYYYYYYYg",
      "     YYYYY   YYg",
      "     gg        g"
    ],
    [
      "      g   !!   g",
      "         !YYYYYg",
      "      YYYYYYYYYg",
      "     gYYYYYYYYYg",
      "    gggggggggggg",
      "    !!YYYYYYYYY ",
      "     !YYYYYYYYY ",
      "      YYYYYYYYY ",
      "      YYYYYYYYY ",
      "      YYYYYYYYY ",
      "      YYYYYYYYY ",
      "    gggggggggggg",
      "    ggYYYYYYYYYg",
      "    ggYYYYYYYYYg",
      "      YYYY   YYg",
      "      g        g"
    ],
    [
      "      g   !!!  g",
      "          YYYYYg",
      "      YYYYYYYYYg",
      "      YYYYYYYYYg",
      "     ggggggggggg",
      "     !YYYYYYYYY ",
      "      YYYYYYYYY ",
      "      YYYYYYYYY ",
      "      YYYYYYYYY ",
      "      YYYYYYYYY ",
      "      YYYYYYYYY ",
      "     ggggggggggg",
      "     gYYYYYYYYYg",
      "     gYYYYYYYYYg",
      "      YYYY    Yg",
      "      g        g"
    ]
  ]
}