{
  "xsize": 16,
  "zsize": 16,
  "refpalette": "lostcities:base",
  "slices": [
    [
      "     g   ggggggg",
      "    gg    gggggg",
      "gggggg   ggggggg",
      "gggggg!!!ggggggg",
      "gggggggggggggggg",
      "gggggggggggggggg",
      "gggggggggggggggg",
      "gggggggggggggggg",
      "gggggggggggggggg",
      "gggggggggggggggg",
      "gggggggggggggggg",
      "gggggggggggggggg",
      "gggggggggggggggg",
      "gggggggggggggggg",
      "gggggggggggggggg",
      "gggggggggggggggg"
    ],
    [
      "            !g!!",
      "            ggg!",
      "gYYYYY!!!YYggggg",
      " g   !!!!!  ggg ",
      "     !!!!    g  ",
      "      !!     Y  ",
      "             Y  ",
      "             Y  ",
      "             Y  ",
      "             Y  ",
      "             Y  ",
      "             Y  ",
      "             Y  ",
      "             Y  ",
      " g          gY!g",
      "g           !gg!"
    ],
    [
      "            !g! ",
      "       !!!!!ggg ",
      "gYYYYY!!!YYggggg",
      "      !!!!!!ggg ",
      "      !!!    g  ",
      "             Y  ",
      "             Y  ",
      "             Y  ",
      "             Y  ",
      "             Y  ",
      "             Y  ",
      "             Y  ",
      "             Y  ",
      "            !Y! ",
      "            !Y! ",
      "g            gg!"
    ],
    [
      "           !!g! ",
      "       !! !!ggg ",
      "gYYYYYYYYYYggggg",
      "       !!  !ggg ",
      "             g  ",
      "             Y  ",
      "             Y  ",
      "             Y  ",
      "             Y  ",
      "             Y  ",
      "             Y  ",
      "             Y  ",
      "            !Y! ",
      "            !Y! ",
      "             Y  ",
      "g            gg "
    ],
    [
      "           !!g! ",
      "g      !   !ggg ",
      "gYYYYYYYYYYggggg",
      "       !    ggg ",
      "             g  ",
      "             Y  ",
      "             Y  ",
      "             Y  ",
      "             Y  ",
      "             Y  ",
      "             Y  ",
      "             Y  ",
      "            !Y! ",
      "             Y  ",
      "             Y  ",
      "g            gg "
    ],
    [
      "            !g  ",
      "g           ggg ",
      "gYYYYYYYYYYggggg",
      "            ggg ",
      "             g  ",
      "             Y  ",
      "             Y  ",
      "             Y  ",
      "             Y  ",
      "             Y  ",
      "             Y  ",
      "             Y  ",
      "            !Y! ",
      "             Y  ",
      "             Y  ",
      "g            gg "
    ]
  ]
}