{
  "xsize": 16,
  "zsize": 16,
  "refpalette": "pomkotsmechs:base",
  "slices": [
    [
      "gggggggggggggggg",
      "gggggggggggggggg",
      "gggggggggggggggg",
      "gggggggggggggggg",
      "gggggggggggggggg",
      "gggggggggggggggg",
      "gggggggggggggggg",
      "gggggggggggggggg",
      "gggggggggggggggg",
      "gggggggggggggggg",
      "gggggggggggggggg",
      "gggggggggggggggg",
      "gggggggggggggggg",
      "gggggggggggggggg",
      "gggggggggggggggg",
      "gggggggggggggggg"
    ],
    [
      "  g  !!       g ",
      " ggg!!!        g",
      "gggggYYYYYYYYYYg",
      " ggg !!       g ",
      "  g             ",
      "  Y             ",
      "  Y             ",
      "  Y             ",
      "  Y             ",
      "  Y             ",
      " !Y             ",
      "!!Y!         !!!",
      " !Y         !!  ",
      "  Y        !!   ",
      "g Yg      !!  g ",
      " gg            g"
    ],
    [
      "  g             ",
      " ggg !!        g",
      "gggggYYYYYYYYYYg",
      " ggg  !         ",
      "  g             ",
      "  Y             ",
      "  Y             ",
      "  Y             ",
      "  Y             ",
      "  Y             ",
      "  Y             ",
      " !Y!            ",
      " !Y!            ",
      "  Y             ",
      "  Y             ",
      " gg            g"
    ],
    [
      "  g             ",
      " ggg  !!       g",
      "gggggYYYYYYYYYYg",
      " ggg  !!        ",
      "  g             ",
      "  Y             ",
      "  Y             ",
      "  Y             ",
      "  Y             ",
      "  Y             ",
      "  Y             ",
      "  Y             ",
      " !Y!            ",
      "  Y             ",
      "  Y             ",
      " gg            g"
    ],
    [
      "  g             ",
      " ggg   !!      g",
      "gggggYYYYYYYYYYg",
      " ggg   !!       ",
      "  g             ",
      "  Y             ",
      "  Y             ",
      "  Y             ",
      "  Y             ",
      "  Y             ",
      "  Y             ",
      "  Y             ",
      " !Y!            ",
      "  Y             ",
      "  Y             ",
      " gg            g"
    ],
    [
      "  g             ",
      " ggg    !!     g",
      "gggggYYYYYYYYYYg",
      " ggg    !!      ",
      "  g             ",
      "  Y             ",
      "  Y             ",
      "  Y             ",
      "  Y             ",
      "  Y             ",
      "  Y             ",
      "  Y             ",
      " !Y!            ",
      "  Y             ",
      "  Y             ",
      " gg            g"
    ]
  ]
}