{
  "xsize": 16,
  "zsize": 16,
  "refpalette": "lostcities:base",
  "slices": [
    [
      "             ggg",
      "             ggg",
      "             ggg",
      "             ggg",
      "             ggg",
      "             ggg",
      "             ggg",
      " hi          ggg",
      " jk          ggg",
      "             ggg",
      "             ggg",
      "             ggg",
      "             ggg",
      "             ggg",
      "             ggg",
      "             ggg"
    ],
    [
      "             ggg",
      "             ggg",
      "             ggg",
      "             ggg",
      "             ggg",
      "             ggg",
      "             ggg",
      " hi          ggg",
      " jk          ggg",
      "             ggg",
      "             ggg",
      "             ggg",
      "             ggg",
      "             ggg",
      "             ggg",
      "             ggg"
    ],
    [
      "             ggg",
      "              r ",
      "              r ",
      "              r ",
      "              r ",
      "              r ",
      "              r ",
      " hi           r ",
      " jk           r ",
      "              r ",
      "              r ",
      "              r ",
      "              r ",
      "              r ",
      "              r ",
      "             ggg"
    ],
    [
      "             ggg",
      "                ",
      "                ",
      "                ",
      "                ",
      "                ",
      "                ",
      " ff             ",
      " ff             ",
      "                ",
      "                ",
      "                ",
      "                ",
      "                ",
      "                ",
      "             ggg"
    ],
    [
      " ff          ggg",
      " ff          f  ",
      " ff          f  ",
      " ff          f  ",
      " ff          f  ",
      " ff          f  ",
      "ffff         f  ",
      "fxxfffffffffff  ",
      "fxxfffffffff f  ",
      "ffff         f  ",
      " ff          f  ",
      " ff          f  ",
      " ff          f  ",
      " ff          f  ",
      " ff          f  ",
      " ff          ggg"
    ],
    [
      "gggggͱͱͱͱͱͱͱgggg",
      "gggggͱͱͱͱͱͱͱgggg",
      "gggggͱͱͱͱͱͱͱgggg",
      "gggggͱͱͱͱͱͱͱgggg",
      "gggggͱͱͱͱͱͱͱgggg",
      "gggggggggggggggg",
      "gggggggggggggggg",
      "gggggggggggggggg",
      "gggggggggggggggg",
      "gggggggggggggggg",
      "gggggggggggggggg",
      "gggggͱͱͱͱͱͱͱgggg",
      "gggggͱͱͱͱͱͱͱgggg",
      "gggggͱͱͱͱͱͱͱgggg",
      "gggggͱͱͱͱͱͱͱgggg",
      "gggggͱͱͱͱͱͱͱgggg"
    ]
  ]
}