{
  "xsize": 16,
  "zsize": 16,
  "refpalette": "pomkotsmechs:base",
  "slices": [
    [
      "g         g     ",
      "gYYYYYYYYYY     ",
      "gYYYYYYYYYY     ",
      "gYYYYYYYYYY     ",
      "ggggggggggg     ",
      " YYYYYYYY!      ",
      " YYYYYYYY       ",
      " YYYYYYYY       ",
      " YYYYYYYYY      ",
      " YYYYYYYYYY     ",
      " YYYYYYYYYY     ",
      "gggggggggggg    ",
      "gYYYYYYYYYYg    ",
      "gYYYYYYYYYY     ",
      "gYYY !!YY       ",
      "g               "
    ],
    [
      "g         g     ",
      "gYYYYYYYYYY     ",
      "gYYYYYYYYYY     ",
      "gYYYYYYYYYY     ",
      "gggggggggg!     ",
      " YYYYYYYY!      ",
      " YYYYYYYY       ",
      " YYYYYYYY       ",
      " YYYYYYYYY      ",
      " YYYYYYYYYY     ",
      " YYYYYYYYYY     ",
      "gggggggggggg    ",
      "gYYYYYYYYYYg    ",
      "gYYYYYYYYYYg    ",
      "gYY  ! Y        ",
      "g               "
    ],
    [
      "g         g     ",
      "gYYYYYYYYYY     ",
      "gYYYYYYYYYY     ",
      "gYYYYYYYYYY     ",
      "gggggggggg!     ",
      " YYYYYYYY!!     ",
      " YYYYYYYY!      ",
      " YYYYYYYY       ",
      " YYYYYYYYY      ",
      " YYYYYYYYYY     ",
      " YYYYYYYYYY     ",
      "gggggggggggg    ",
      "gYYYYYYYYYYg    ",
      "gYYYYYYYYYYg    ",
      "gYY  !YY        ",
      "g               "
    ],
    [
      "g        gg     ",
      "gYYYYYYYYYY     ",
      "gYYYYYYYYYY     ",
      "gYYYYYYYYYY     ",
      "ggggggggggg     ",
      " YYYYYYYY!!     ",
      " YYYYYYY !      ",
      " YYYYYYYY       ",
      " YYYYYYYYY      ",
      " YYYYYYYYYY     ",
      " YYYYYYYYYY     ",
      "gggggggggggg    ",
      "gYYYYYYYYYYg    ",
      "gYYYYYYYYYYg    ",
      "gYY  !YY Y      ",
      "g               "
    ],
    [
      "g        g      ",
      "gYYYYYYYYY      ",
      "gYYYYYYYYYg     ",
      "gYYYYYYYYY      ",
      "gggggggggg      ",
      " YYYYYYY!!!     ",
      " YYYYYYY !      ",
      " YYYYYYY        ",
      " YYYYYYYY       ",
      " YYYYYYYYY      ",
      " YYYYYYYYY      ",
      "gggggggggggg    ",
      "gYYYYYYYYYgg    ",
      "gYYYYYYYYY g    ",
      "gY   !YY        ",
      "g               "
    ],
    [
      "g        g      ",
      "gYYYYYYYYY      ",
      "gYYYYYYYYY      ",
      "gYYYYYYYYY      ",
      "gggggggggg      ",
      " YYYYYY!!!!     ",
      " YYYYYYY!!!     ",
      " YYYYYYY !      ",
      " YYYYYYYY       ",
      " YYYYYYYYY      ",
      " YYYYYYYYY      ",
      "ggggggggggg     ",
      "gYYYYYYYYYg     ",
      "gYYYYYYYYYg     ",
      "gY   !YYYY      ",
      "g        g      "
    ]
  ]
}