{
  "xsize": 16,
  "zsize": 16,
  "refpalette": "pomkotsmechs:base",
  "slices": [
    [
      "   !            ",
      " gppppppp     g ",
      " z !!         z ",
      " z !!gg  g    z ",
      " z !ggg  ggg  z ",
      " z gggg  gggg z ",
      " z gggggggggg z ",
      " z  gggggggg  z ",
      " z  gggggggg  z ",
      " z gggggggggg z ",
      " z gggggggggg z ",
      " z  gggggggg  z ",
      " z   gg  gg     ",
      " z              ",
      "!gppppppppp     ",
      " !              "
    ],
    [
      "                ",
      "   !            ",
      "                ",
      "    !gg         ",
      "   !ggg  ggg    ",
      "   gg!     gg   ",
      "   gg      gg   ",
      "    g      g    ",
      "    g      g    ",
      "   gg      gg   ",
      "   gg      gg   ",
      "    gggggggg    ",
      "     gg  gg     ",
      " !              ",
      "!!!             ",
      " !              "
    ],
    [
      "                ",
      "                ",
      "                ",
      "    !           ",
      "   !g!     g    ",
      "  !!!!          ",
      "   !!           ",
      "    g      g    ",
      "    g      g    ",
      "                ",
      "                ",
      "    g  gg  g    ",
      "                ",
      " !              ",
      "!!!             ",
      " !              "
    ],
    [
      "                ",
      "                ",
      "                ",
      "           g    ",
      "   !ggggggggg   ",
      "  !gg      gg   ",
      "   gg!!    gg   ",
      "   gg      gg   ",
      "   gg      gg   ",
      "   gg      gg   ",
      "   gg      gg   ",
      "   ggggggggg    ",
      "   !ggggg       ",
      " ! !            ",
      "!!!             ",
      " !              "
    ],
    [
      "                ",
      "          ggggg ",
      "          ggggg ",
      "        ggggggg ",
      " g !!  gggggggg ",
      " ggg!!ggggggggg ",
      " gggggggggggggg ",
      " gggggggggggggg ",
      " gggggggggggggg ",
      " gggggggggggggg ",
      " gggggggg     g ",
      " gggggggg       ",
      " ggggggg        ",
      " gggggggg       ",
      "!ggggggggggg    ",
      " !              "
    ],
    [
      "                ",
      "       pppppppg ",
      "              z ",
      "              z ",
      " z            z ",
      " z !!         z ",
      " z  !!!       z ",
      " z     gg     z ",
      " z     gg     z ",
      " z            z ",
      " z              ",
      " z              ",
      " z!!!!          ",
      " z!!!           ",
      "!gppppppppp     ",
      " !!             "
    ]
  ]
}