{
  "xsize": 16,
  "zsize": 16,
  "refpalette": "pomkotsmechs:base",
  "slices": [
    [
      "             gg ",
      "g            ggg",
      "gYYYYYYY   ggggg",
      "           ggggg",
      "            ggg ",
      "             Y  ",
      "             Y  ",
      "             Y  ",
      "             Y  ",
      "             Y  ",
      "             Y  ",
      "            !Y! ",
      "            !Y! ",
      "             Y  ",
      "             Y  ",
      "g            gg "
    ],
    [
      "                ",
      "g    !!       g ",
      "gYYYYYYY     ggg",
      "     !!     ggg ",
      "             g  ",
      "             Y  ",
      "             Y  ",
      "             Y  ",
      "             Y  ",
      "             Y  ",
      "             Y  ",
      "            !Y! ",
      "             Y  ",
      "             Y  ",
      "             Y  ",
      "g            gg "
    ],
    [
      "                ",
      "g     !         ",
      "gYYYYYYYY    ggg",
      "      !     ggg ",
      "             g  ",
      "             Y  ",
      "             Y  ",
      "             Y  ",
      "             Y  ",
      "             Y  ",
      "             Y  ",
      "            !Y! ",
      "             Y  ",
      "             Y  ",
      "             Y  ",
      "g            gg "
    ],
    [
      "                ",
      "g     !!        ",
      "gYYYYYYYYY   gg ",
      "      !!    gg  ",
      "             g  ",
      "             Y  ",
      "             Y  ",
      "             Y  ",
      "             Y  ",
      "             Y  ",
      "             Y  ",
      "            !Y! ",
      "             Y  ",
      "             Y  ",
      "             Y  ",
      "g            gg "
    ],
    [
      "                ",
      "g      !        ",
      " YYYYYYYYY   g  ",
      "       !    g   ",
      "                ",
      "             Y  ",
      "             Y  ",
      "             Y  ",
      "             Y  ",
      "             Y  ",
      "            !Y! ",
      "            !Y! ",
      "             Y  ",
      "             Y  ",
      "             Y  ",
      "g            gg "
    ],
    [
      " g     !!       ",
      "g     !!!       ",
      "gYYYYYYYYYY gg  ",
      "       !    g   ",
      "                ",
      "                ",
      "                ",
      "                ",
      "         !!!    ",
      "           !!Y!!",
      "            !Y!!",
      "             Y! ",
      "             Y  ",
      "             Y  ",
      " g           Y g",
      "g            gg "
    ]
  ]
}