{
  "xsize": 16,
  "zsize": 16,
  "refpalette": "lostcities:base",
  "slices": [
    [
      "    gg     !! gͰ",
      "gg gggooooooo!g ",
      "gg  gg   !!!! g ",
      "        !!!!  gg",
      " ff     !!!  ggg",
      " ff      !   gr ",
      "              r ",
      "              r ",
      "              r ",
      "              r ",
      "              r ",
      "             !r!",
      "              r ",
      "              r ",
      "             ggg",
      "                "
    ],
    [
      "    gg     !  g ",
      "gg gggoooooo! g ",
      "gg  gg    !!  g ",
      "htttttttttttt gg",
      "wffffffffffffggg",
      "wffffffffffffgr ",
      "wff           r ",
      "wff           r ",
      "wff           r ",
      "wff           r ",
      "wff           r ",
      "wff          !r!",
      "wff           r ",
      "wff           r ",
      "wff             ",
      "wff             "
    ],
    [
      "    gg        g ",
      "gg gggoooooo  g ",
      "gg  gg    !!! g ",
      "httpppppppppp gg",
      "wxu       !! ggg",
      "wyk          gr ",
      "z             r ",
      "z             r ",
      "z             r ",
      "z             r ",
      "z             r ",
      "z            !r!",
      "z             r ",
      "z             r ",
      "z               ",
      "z               "
    ],
    [
      "    gg        g ",
      "gg gggoooooo  g ",
      "gg  gg    !!! g ",
      "          !!  gg",
      " hi          ggg",
      " jk          gr ",
      "              r ",
      "              r ",
      "              r ",
      "              r ",
      "             !r!",
      "             !r!",
      "              r ",
      "              r ",
      "                ",
      "                "
    ],
    [
      "    gg        gg",
      "gg gggoooooo!!g ",
      "gg  gg    !!!!g ",
      "           !!ggg",
      " hi          ggg",
      " jk          gr ",
      "              r ",
      "              r ",
      "              r ",
      "              r!",
      "             !r!",
      "              r!",
      "              r ",
      "              r ",
      "             gg ",
      "                "
    ],
    [
      "    gg      !! n",
      "gg gggoooooo!!g ",
      "gg  gg     !!!g ",
      "            !ggg",
      " hi          ggg",
      " jk          gr ",
      "              r ",
      "              r ",
      "              r ",
      "              r!",
      "              r!",
      "              r!",
      "              r ",
      "              r ",
      "             gg ",
      "              g "
    ]
  ]
}