{
  "xsize": 16,
  "zsize": 16,
  "refpalette": "pomkotsmechs:base",
  "slices": [
    [
      "            !   ",
      " gͺͺg      gͺͺg ",
      " ͻ  ͻ      ͻ! ͻ ",
      " ͻ  ͻ      ͻ  ͻ ",
      " gͺͺggggggggͺͺg ",
      "    gg     g    ",
      "    g      g    ",
      "    g      g    ",
      "    g      g    ",
      "    g      g    ",
      "    gg     g    ",
      " gͺͺggggggggͺͺg ",
      " ͻ  ͻ     !ͻ  ͻ ",
      " ͻ  ͻ     !ͻ!!ͻ ",
      " gͺͺg     !gͺͺg ",
      "           !!!  "
    ],
    [
      "            !!  ",
      " hppi      hppi ",
      " z  z      z!!z ",
      " z  z      z  z ",
      " jppk      jppk ",
      "                ",
      "                ",
      "                ",
      "                ",
      "                ",
      "     gg         ",
      " hppi      hppi ",
      " z  z      z  z ",
      " z  z     !z! z ",
      " jppk     !jppk ",
      "           !!   "
    ],
    [
      "             !  ",
      "  |{        |{! ",
      " ͼ  ͼ      ͼ !ͼ ",
      " ͽ  ͽ      ͽ  ͽ ",
      "  |{        |{  ",
      "                ",
      "                ",
      "                ",
      "                ",
      "                ",
      "      gg        ",
      "  |{        |{  ",
      " ͼ  ͼ      ͼ  ͼ ",
      " ͽ  ͽ     !ͽ! ͽ ",
      "  |{       !|{  ",
      "                "
    ],
    [
      "             !  ",
      " hppi      hppi ",
      " z  z      z !z ",
      " z  z      z  z ",
      " jppk      jppk ",
      "                ",
      "                ",
      "                ",
      "                ",
      "                ",
      "       gg       ",
      " hppi      hppi ",
      " z  z      z  z ",
      " z  z     !z! z ",
      " jppk     !jppk ",
      "           !    "
    ],
    [
      "             !! ",
      "  |{        |{! ",
      " ͼ  ͼ      ͼ !ͼ ",
      " ͽ  ͽ      ͽ  ͽ ",
      "  |{        |{  ",
      "                ",
      "                ",
      "                ",
      "                ",
      "                ",
      "        gg      ",
      "  |{        |{  ",
      " ͼ  ͼ      ͼ  ͼ ",
      " ͽ  ͽ      ͽ  ͽ ",
      "  |{      !!|{  ",
      "          !!    "
    ],
    [
      "            !!!!",
      " gͺͺg      gͺͺg ",
      " ͻ  ͻ      ͻ !ͻ ",
      " ͻ  ͻ      ͻ  ͻ ",
      " gͺͺg      gͺͺg ",
      "                ",
      "                ",
      "                ",
      "                ",
      "                ",
      "         gg     ",
      " g  g !    gͺͺg ",
      " ͻ  ͻ !    ͻ  ͻ ",
      " ͻ  ͻ !    ͻ  ͻ ",
      " gͺͺg  ! !!g! g ",
      "       ! !!!!   "
    ]
  ]
}