{
  "xsize": 16,
  "zsize": 16,
  "refpalette": "pomkotsmechs:base",
  "slices": [
    [
      "gggggggggggggggg",
      "gggggggggggggggg",
      "gggggggggggggggg",
      "gggggggggggggggg",
      "gggggggggggggggg",
      "gggggggggggggggg",
      "gggggggggggggggg",
      "gggggggggggggggg",
      "gggggggggggggggg",
      "gggggggggggggggg",
      "gggggggggggggggg",
      "gggggggggggggggg",
      "gggggggggggggggg",
      "gggggggggggggggg",
      "gggggggggggggggg",
      "gggggggggggggggg"
    ],
    [
      " gg   !!       g",
      "g!Yg !!       g ",
      "!!Y!!!          ",
      "!!Y!!           ",
      "!!Y             ",
      "!!Y!            ",
      " !Y             ",
      "  Y             ",
      "  Y             ",
      "  Y             ",
      "  Y             ",
      "  g             ",
      " ggg      ! ! g ",
      "gggggYYYYYYYYYYg",
      " ggg     !!!!! g",
      "  g    !! !!! g "
    ],
    [
      " gg            g",
      "!!Y!            ",
      "!!Y!            ",
      " !Y             ",
      "  Y             ",
      " !Y!            ",
      "  Y             ",
      "  Y             ",
      "  Y             ",
      "  Y             ",
      "  Y             ",
      "  g             ",
      " ggg      ! !   ",
      "gggggYYYYYYYYYYg",
      " ggg      !!!  g",
      "  g        !    "
    ],
    [
      " gg            g",
      " !Y!            ",
      " !Y             ",
      "  Y             ",
      "  Y             ",
      " !Y!            ",
      "  Y             ",
      "  Y             ",
      "  Y             ",
      "  Y             ",
      "  Y             ",
      "  g             ",
      " ggg      ! !!  ",
      "gggggYYYYYYYYYYg",
      " ggg      ! !! g",
      "  g             "
    ],
    [
      " gg            g",
      " !Y!            ",
      "  Y             ",
      "  Y             ",
      "  Y             ",
      " !Y!            ",
      "  Y             ",
      "  Y             ",
      "  Y             ",
      "  Y             ",
      "  Y             ",
      "  g             ",
      " ggg      !  !  ",
      "gggggYYYYYYYYYYg",
      " ggg      !  ! g",
      "  g             "
    ],
    [
      " gg            g",
      " !Y!            ",
      "  Y             ",
      "  Y             ",
      "  Y             ",
      " !Y!            ",
      "  Y             ",
      "  Y             ",
      "  Y             ",
      "  Y             ",
      "  Y             ",
      "  g             ",
      " ggg      !! !  ",
      "gggggYYYYYYYYYYg",
      " ggg      !! ! g",
      "  g             "
    ]
  ]
}