{
  "xsize": 16,
  "zsize": 16,
  "refpalette": "lostcities:base",
  "slices": [
    [
      "            g   ",
      "            g   ",
      "            g   ",
      "           g    ",
      "          !g    ",
      "         !g!    ",
      "         g!     ",
      "g      gg       ",
      " gggggg         ",
      "gg     gggg     ",
      "ggg   gggggg    ",
      "gggg gggggggg   ",
      "gggg gggggggg   ",
      "gggg gggggggg   ",
      "gggg gggggggg   ",
      "ggg   gggggg    "
    ],
    [
      "            g   ",
      "            g   ",
      "            g   ",
      "           g    ",
      "          !g    ",
      "         !g!    ",
      "         g!     ",
      "g      gg       ",
      " gggggg         ",
      "ͶͶ     ͶͶͶͶ     ",
      "  Ͷ   Ͷ    Ͷ    ",
      "   Ͷ Ͷ      Ͷ   ",
      "   Ͷ Ͷ      Ͷ   ",
      "   Ͷ Ͷ      Ͷ   ",
      "   Ͷ Ͷ      Ͷ   ",
      "  Ͷ   Ͷ    Ͷ    "
    ],
    [
      "            g   ",
      "            g   ",
      "            g   ",
      "           g    ",
      "          !g!   ",
      "         !g!!   ",
      "         g!!    ",
      "g      gg       ",
      " gggggg         ",
      "ͶͶ     ͶͶͶͶ     ",
      "  Ͷ   Ͷ    Ͷ    ",
      "   Ͷ Ͷ      Ͷ   ",
      "   Ͷ Ͷ      Ͷ   ",
      "   Ͷ Ͷ      Ͷ   ",
      "   Ͷ Ͷ      Ͷ   ",
      "  Ͷ   Ͷ    Ͷ    "
    ],
    [
      "ggggggggggggg   ",
      "ggggggggggggg   ",
      "ggggggggggggg   ",
      "gggggggggggg    ",
      "gggggggggggg!   ",
      "ggggggggggg!    ",
      "gggggggggg      ",
      "ggggggggg       ",
      " gggggg         ",
      "ͶͶ     ͶͶͶͶ     ",
      "  Ͷ   Ͷ    Ͷ    ",
      "   Ͷ Ͷ      Ͷ   ",
      "   Ͷ Ͷ      Ͷ   ",
      "   Ͷ Ͷ      Ͷ   ",
      "   Ͷ Ͷ      Ͷ   ",
      "  Ͷ   Ͷ    Ͷ    "
    ],
    [
      "            Ͷ   ",
      "            Ͷ   ",
      "            Ͷ   ",
      "           Ͷ    ",
      "          !Ͷ!   ",
      "          Ͷ!    ",
      "         Ͷ      ",
      "Ͷ      ͶͶ       ",
      " ͶͶͶͶͶͶ         ",
      "ͶͶ     ͶͶͶͶ     ",
      "  Ͷ   Ͷ    Ͷ    ",
      "   Ͷ Ͷ      Ͷ   ",
      "   Ͷ Ͷ      Ͷ   ",
      "   Ͷ Ͷ      Ͷ   ",
      "   Ͷ Ͷ      Ͷ   ",
      "  Ͷ   Ͷ    Ͷ    "
    ],
    [
      "            Ͷ   ",
      "            Ͷ   ",
      "            Ͷ   ",
      "           Ͷ    ",
      "          !Ͷ!   ",
      "          Ͷ!    ",
      "         Ͷ      ",
      "Ͷ      ͶͶ       ",
      " ͶͶͶͶͶͶ         ",
      "ͶͶ     ͶͶͶͶ     ",
      "  Ͷ   Ͷ    Ͷ    ",
      "   Ͷ Ͷ      Ͷ   ",
      "   Ͷ Ͷ      Ͷ   ",
      "   Ͷ Ͷ      Ͷ   ",
      "   Ͷ Ͷ      Ͷ   ",
      "  Ͷ   Ͷ    Ͷ    "
    ]
  ]
}