{
  "xsize": 16,
  "zsize": 16,
  "refpalette": "lostcities:base",
  "slices": [
    [
      "gggggggggg!     ",
      "gggggggggg!     ",
      "ggggggggggg!!!  ",
      "ggggggggggggg!!!",
      "gggggggggggggggg",
      "gggggggg ggggggg",
      "gggggg    gggggg",
      "gggggg    !ggggg",
      "gggggg   !gggggg",
      "ggggggg  ggggggg",
      "gggggggggggggggg",
      "gggggggggggggggg",
      "gggggggggggggggg",
      "gggggggggggggggg",
      " ggggggggggggggg",
      "  gggggggggggggg"
    ],
    [
      "        !!!     ",
      "         !!     ",
      "         !!!!!  ",
      "         !!!!!! ",
      "          !!!!!!",
      "               !",
      "               !",
      "          !!  !!",
      "         !!gggg ",
      "         gggggg ",
      "        ggggggg ",
      "        ggggggg ",
      "        ggggggg ",
      "        ggggggg ",
      "        ggggggg ",
      "                "
    ],
    [
      "         !      ",
      "                ",
      "          !     ",
      "          !!!!  ",
      "                ",
      "                ",
      "                ",
      "           !    ",
      "          !gggg ",
      "         !ggggg ",
      "        !gggggg ",
      "       !ggggggg ",
      "       !ggggggg ",
      "        ggggggg ",
      "        ggggggg ",
      "                "
    ],
    [
      "                ",
      "                ",
      "                ",
      "                ",
      "                ",
      "                ",
      "                ",
      "                ",
      "          !!    ",
      "         !gggg  ",
      "        !ggggg  ",
      "       !!ggggg  ",
      "        !ggggg  ",
      "         ggggg  ",
      "                ",
      "                "
    ],
    [
      "                ",
      "                ",
      "                ",
      "                ",
      "                ",
      "                ",
      "                ",
      "                ",
      "         !!     ",
      "        !ggggg  ",
      "        !ggggg  ",
      "        !ggggg  ",
      "         ggggg  ",
      "         ggggg  ",
      "                ",
      "                "
    ],
    [
      "                ",
      "                ",
      "                ",
      "                ",
      "                ",
      "                ",
      "                ",
      "                ",
      "                ",
      "         !!     ",
      "         !      ",
      "                ",
      "                ",
      "                ",
      "                ",
      "                "
    ]
  ]
}