{
  "xsize": 16,
  "zsize": 16,
  "refpalette": "pomkotsmechs:base",
  "slices": [
    [
      "                ",
      "                ",
      "                ",
      "                ",
      "                ",
      "             Ͷ  ",
      "              ͶͶ",
      "                ",
      "               Ͷ",
      "              Ͷ ",
      "             Ͷ  ",
      "            Ͷ   ",
      "     ͶͶͶY   Ͷ   ",
      " ͱ  ͶͶͶͶͶY Ͷ    ",
      " ͱͱͶͶͶͶͶͶͶYͶ    ",
      "  ͶͶͶͶͶͶͶͶYͶ    "
    ],
    [
      "              gg",
      "               g",
      "                ",
      "             g g",
      "             ggg",
      "             ggg",
      "              gg",
      "                ",
      "               Ͷ",
      "              Ͷ ",
      "             Ͷ  ",
      "            Ͷ   ",
      "     ͶͶͶY   Ͷ   ",
      "  ͱͶͶͶͶͶͶY Ͷ    ",
      "  ͱͶͶͶͶͶͶͶYͶ    ",
      "   ͶͶͶͶͶͶͶYͶ    "
    ],
    [
      "              gg",
      "              gg",
      "             ggg",
      "             ggg",
      "             ggg",
      "             ggg",
      "              gg",
      "                ",
      "               Ͷ",
      "              Ͷ ",
      "             Ͷ  ",
      "            Ͷ   ",
      "       YY   Ͷ   ",
      "    ͶͶͶͶͶY Ͷ    ",
      "   ͶͶͶͶͶͶͶYͶ    ",
      "   ͶͶͶͶͶͶͶYͶ    "
    ],
    [
      "              gg",
      "              gg",
      "                ",
      "               g",
      "              gg",
      "             ggg",
      "              gg",
      "                ",
      "               Ͷ",
      "              Ͷ ",
      "             Ͷ  ",
      "            Ͷ   ",
      "       YY   Ͷ   ",
      "     ͶͶͶͶY Ͷ    ",
      "    ͶͶͶͶͶͶYͶ    ",
      "    ͶͶͶͶͶͶYͶ    "
    ],
    [
      "              g ",
      "                ",
      "                ",
      "                ",
      "                ",
      "             gg ",
      "               g",
      "                ",
      "               Ͷ",
      "              Ͷ ",
      "             Ͷ  ",
      "            Ͷ   ",
      "       YY   Ͷ   ",
      "      ͶͶͶY Ͷ    ",
      "     ͶͶͶͶͶYͶ    ",
      "    ͶͶͶͶͶͶYͶ    "
    ],
    [
      "              gg",
      "                ",
      "                ",
      "                ",
      "                ",
      "              gg",
      "                ",
      "                ",
      "               Ͷ",
      "              Ͷ ",
      "             Ͷ  ",
      "            Ͷ   ",
      "       YY   Ͷ   ",
      "       ͶͶY Ͷ    ",
      "      ͶͶͶͶYͶ    ",
      "     ͶͶͶͶͶYͶ    "
    ]
  ]
}