{
  "xsize": 16,
  "zsize": 16,
  "refpalette": "lostcities:base",
  "slices": [
    [
      "vvvvvvvvvvvvvvvv",
      "vvvvvvvvvvvvvvvv",
      "vvvvvvvvvvvvvvvv",
      "vvvvvvvvvvvvvvvv",
      "vvvvvvvvvvvvvvvv",
      "vvvvvvvvvvvvvvvv",
      "vvvvvvvvvvvvvvvv",
      "vvvvvvvvvvvvvvvv",
      "vvvvvvvvvvvvvvvv",
      "vvvvvvvvvvvvvvvv",
      "vvvvvvvvvvvvvvvv",
      "vvvvvvvvvvvvvvvv",
      "vvvvvvvvvvvvvvvv",
      "vvvvvvvvvvvvvvvv",
      "vvvvvvvvvvvvvvvv",
      "vvvvvvvvvvvvvvvv"
    ],
    [
      "gggggggggggggggg",
      "gggggggggggggggg",
      "                ",
      "                ",
      "ͲͲͲͲͲ           ",
      "ͲͲ  Ͳ           ",
      "  Ͳ Ͳ  ggggggggg",
      "  Ͳ Ͳ  ggggggggg",
      "ͲͲ  Ͳ  7gggggggg",
      "    Ͳ  7gggggggg",
      "ͲͲ  Ͳ  7gggggggg",
      "  Ͳ Ͳ  ggggggggg",
      "  Ͳ Ͳ  ggggggggg",
      "ͲͲ  Ͳ  ggggggggg",
      "ͲͲͲͲͲ  ggggggggg",
      "       ggggggggg"
    ],
    [
      "                ",
      "gggggggggggggggg",
      "                ",
      "                ",
      "ͲͲͲͲͲ           ",
      "ͲͲ  Ͳ           ",
      "  Ͳ Ͳ  ggggggggg",
      "  Ͳ Ͳ  g        ",
      "ͲͲ  Ͳ           ",
      "    Ͳ           ",
      "ͲͲ  Ͳ  !        ",
      "  Ͳ Ͳ !g!       ",
      "  Ͳ Ͳ !g!       ",
      "ͲͲ  Ͳ  g  gg    ",
      "ͲͲͲͲͲ  g  gg    ",
      "       ggggggggg"
    ],
    [
      "                ",
      "gggggggggggggggg",
      "                ",
      "                ",
      "ͲͲͲͲͲ           ",
      "ͲͲ  Ͳ           ",
      "  Ͳ Ͳ  g  g  g  ",
      "  Ͳ Ͳ  g        ",
      "ͲͲ  Ͳ           ",
      "    Ͳ           ",
      "ͲͲ  Ͳ !!        ",
      "  Ͳ Ͳ!!g!       ",
      "  Ͳ Ͳ!!g!       ",
      "ͲͲ  Ͳ !g   gg   ",
      "ͲͲͲͲͲ  g   gg   ",
      "       g  g  g  "
    ],
    [
      "gggggggggggggggg",
      "gggggggggggggggg",
      "                ",
      "                ",
      "ͲͲͲͲͲ           ",
      "ͲͲ  Ͳ           ",
      "  Ͳ Ͳ  g  g  g  ",
      "  Ͳ Ͳ  g        ",
      "ͲͲ  Ͳ           ",
      "    Ͳ           ",
      "ͲͲ  Ͳ           ",
      "  Ͳ Ͳ!!g        ",
      "  Ͳ Ͳ!!g        ",
      "ͲͲͲ Ͳ!!g    gg  ",
      "ͲͲͲͲͲ  g    gg  ",
      "       g  g  g  "
    ],
    [
      "gggggggggggggggg",
      "gggggggggggggggg",
      "                ",
      "                ",
      "ͲͲͲͲͲ           ",
      "ͲͲ  Ͳ           ",
      "  Ͳ Ͳ  g  g  g  ",
      "  Ͳ Ͳ  g        ",
      "ͲͲ  Ͳ  g        ",
      "    Ͳ  g        ",
      "ͲͲ  Ͳ  g        ",
      "  Ͳ Ͳ! g        ",
      "  Ͳ Ͳ!!g        ",
      "ͲͲ  Ͳ! g     gg ",
      "ͲͲͲͲͲ  g     gg ",
      "       g  g  g  "
    ]
  ]
}