{
  "xsize": 16,
  "zsize": 16,
  "refpalette": "lostcities:base",
  "slices": [
    [
      "                ",
      "                ",
      "                ",
      "                ",
      "                ",
      "                ",
      "                ",
      "                ",
      "                ",
      "!               ",
      "                ",
      "                ",
      "                ",
      "                ",
      "                ",
      "                "
    ],
    [
      "                ",
      "                ",
      "  !             ",
      "!!!             ",
      "!               ",
      "                ",
      "                ",
      "                ",
      "                ",
      "                ",
      "                ",
      "                ",
      "                ",
      "                ",
      "                ",
      "                "
    ],
    [
      "gggggggggggggggg",
      "gggggggggggggggg",
      "gggggggggggggggg",
      "gggggggggggggggg",
      "gggggggggggggggg",
      "gggggggggggggggg",
      "gggggggggggggggg",
      "gggggggggggggggg",
      "gggggggggggggggg",
      "gggggggggggggggg",
      "gggggggggggggggg",
      "gggggggggggggggg",
      "gggggggggggggggg",
      "gggggggggggggggg",
      "gggggggggggggggg",
      "gggggggggggggggg"
    ],
    [
      "    YY         Y",
      "  !Y  Y         ",
      " !!Y  Y      YY ",
      "!!! YY      Y  Y",
      "!           Y  Y",
      "!            YY ",
      "                ",
      "                ",
      "                ",
      "                ",
      "             Y  ",
      "            Y Y ",
      "             Y  ",
      "             Y  ",
      "            Y Y ",
      "             Y  "
    ],
    [
      "    YY         Y",
      " !!YYYY         ",
      "!!!Y YY      YY ",
      " !! YY      YYYY",
      "            Y YY",
      "             YY ",
      "                ",
      "                ",
      "                ",
      "                ",
      "             Y  ",
      "            Y Y ",
      "             Y  ",
      "             Y  ",
      "            Y Y ",
      "             Y  "
    ],
    [
      " ͶͶͶͶͶͶͶͶ  ggggg",
      " ͶͶͶͶͶͶͶͶ  ggggg",
      "!!ͶͶͶͶͶͶ   ggggg",
      " ! ͶͶͶͶ     gggg",
      "            gggg",
      "             ggg",
      "              gg",
      "               g",
      "                ",
      "              gg",
      "             ggg",
      "            gggg",
      "            gggg",
      "            gggg",
      "            gggg",
      "             ggg"
    ]
  ]
}