{
  "xsize": 16,
  "zsize": 16,
  "refpalette": "lostcities:base",
  "slices": [
    [
      "                ",
      "                ",
      "                ",
      "                ",
      "                ",
      "                ",
      "                ",
      "                ",
      "                ",
      "                ",
      "                ",
      "                ",
      "                ",
      "                ",
      "                ",
      "                "
    ],
    [
      "                ",
      "                ",
      "                ",
      "                ",
      "                ",
      "                ",
      "                ",
      "                ",
      "                ",
      "                ",
      "                ",
      "                ",
      "                ",
      "                ",
      "                ",
      "                "
    ],
    [
      "                ",
      "                ",
      "                ",
      "                ",
      "                ",
      "                ",
      "                ",
      "                ",
      "                ",
      "                ",
      "                ",
      "                ",
      "                ",
      "                ",
      "                ",
      "                "
    ],
    [
      "                ",
      "                ",
      "                ",
      "                ",
      "                ",
      "                ",
      "                ",
      "                ",
      "                ",
      "                ",
      "                ",
      "                ",
      "                ",
      "                ",
      "                ",
      "                "
    ],
    [
      "                ",
      "                ",
      "                ",
      "                ",
      "                ",
      "                ",
      "                ",
      "ffffffffffffffff",
      "ffffffffffffffff",
      "                ",
      "                ",
      "                ",
      "                ",
      "                ",
      "                ",
      "                "
    ],
    [
      "gͱͱͱͱͱͱͱͱͱͱͱͱͱͱg",
      "gͱͱͱͱͱͱͱͱͱͱͱͱͱͱg",
      "gͱͱͱͱͱͱͱͱͱͱͱͱͱͱg",
      "gͱͱͱͱͱͱͱͱͱͱͱͱͱͱg",
      "gͱͱͱͱͱͱͱͱͱͱͱͱͱͱg",
      "gggggggggggggggg",
      "gggggggggggggggg",
      "gggggggggggggggg",
      "gggggggggggggggg",
      "gggggggggggggggg",
      "gggggggggggggggg",
      "gͱͱͱͱͱͱͱͱͱͱͱͱͱͱg",
      "gͱͱͱͱͱͱͱͱͱͱͱͱͱͱg",
      "gͱͱͱͱͱͱͱͱͱͱͱͱͱͱg",
      "gͱͱͱͱͱͱͱͱͱͱͱͱͱͱg",
      "gͱͱͱͱͱͱͱͱͱͱͱͱͱͱg"
    ]
  ]
}