{
  "xsize": 16,
  "zsize": 16,
  "refpalette": "pomkotsmechs:base",
  "slices": [
    [
      "gggggggggggggggg",
      "gggggggggggggggg",
      "gggggggggggggggg",
      "gggggggggggggggg",
      "gggggggggggggggg",
      "gggggggggggggggg",
      "gggggggggggggggg",
      "gggggggggggggggg",
      "gggggggggggggggg",
      "gggggggggggggggg",
      "gggggggggggggggg",
      "gggggggggggggggg",
      "ggggggggg  ggggg",
      "ggggggggg   gggg",
      "ggggggggg       ",
      "ggggggggg       "
    ],
    [
      "                ",
      "                ",
      "                ",
      "                ",
      "                ",
      "                ",
      "      gggg      ",
      "      gggg      ",
      "!     gggg   !  ",
      "!!    gggg  !!! ",
      "!            !!!",
      "!               ",
      "!               ",
      "                ",
      "                ",
      "                "
    ],
    [
      "                ",
      "                ",
      "                ",
      "                ",
      "                ",
      "                ",
      "      g  g      ",
      "       gg       ",
      "!!     gg    !  ",
      "!!!   g  g  !!! ",
      "!!           !  ",
      "!!              ",
      "!               ",
      "                ",
      "                ",
      "                "
    ],
    [
      "                ",
      "                ",
      "                ",
      "                ",
      "                ",
      "                ",
      "       gg       ",
      "      gYYg      ",
      " !    gYYg   !  ",
      "!!!    gg   !!! ",
      "!!!          !  ",
      "!!              ",
      "                ",
      "                ",
      "                ",
      "                "
    ],
    [
      "                ",
      "                ",
      "                ",
      "                ",
      "                ",
      "                ",
      "                ",
      "       YY       ",
      "       YY    !  ",
      " !!         !!! ",
      "!!!!         !  ",
      " !!             ",
      "                ",
      "                ",
      "                ",
      "                "
    ],
    [
      "                ",
      "                ",
      "                ",
      "                ",
      "                ",
      "                ",
      "                ",
      "       YY       ",
      "       YY    !  ",
      "  !         !!! ",
      " !!!         !  ",
      "  !             ",
      "                ",
      "                ",
      "                ",
      "                "
    ]
  ]
}