{
  "xsize": 16,
  "zsize": 16,
  "refpalette": "lostcities:base",
  "slices": [
    [
      "vvvvvvvvvvvvvvvv",
      "vvvvvvvvvvvvvvvv",
      "vvvvvvvvvvvvvvvv",
      "vvvvvvvvvvvvvvvv",
      "vvvvvvvvvvvvvvvv",
      "vvvvvvvvvvvvvvvv",
      "vvvvvvvvvvvvvvvv",
      "vvvvvvvvvvvvvvvv",
      "vvvvvvvvvvvvvvvv",
      "vvvvvvvvvvvvvvvv",
      "vvvvvvvvvvvvvvvv",
      "vvvvvvvvvvvvvvvv",
      "vvvvvvvvvvvvvvvv",
      "vvvvvvvvvvvvvvvv",
      "vvvvvvvvvvvvvvvv",
      "vvvvvvvvvvvvvvvv"
    ],
    [
      "                ",
      "                ",
      "  gYg      gYg  ",
      "  gYg      gYg  ",
      "  gYg      gYg  ",
      "                ",
      "                ",
      "                ",
      "                ",
      "                ",
      "                ",
      "  gYg      gYg  ",
      "  gYg      gYg  ",
      "  gYg      gYg  ",
      "                ",
      "                "
    ],
    [
      "                ",
      "  gYg      gYg  ",
      "   Y        Y   ",
      "   Y        Y   ",
      "   Y        Y   ",
      "  gYg      gYg  ",
      "                ",
      "                ",
      "                ",
      "                ",
      "  gYg      gYg  ",
      "   Y        Y   ",
      "   Y        Y   ",
      "   Y        Y   ",
      "  gYg      gYg  ",
      "                "
    ],
    [
      "                ",
      "                ",
      "  gYg      gYg  ",
      " !gYg      gYg  ",
      "  gYg      gYg  ",
      "                ",
      "                ",
      "                ",
      "                ",
      "                ",
      "                ",
      "  gYg      gYg  ",
      "  gYg      gYg  ",
      "  gYg      gYg  ",
      "                ",
      "                "
    ],
    [
      "                ",
      " gggggggggggggg ",
      " gggggggggggggg ",
      "!gggggggggggggg ",
      " gggggggggggggg ",
      " gggggggggggggg ",
      " gggggggggggggg ",
      " gggggggggggggg ",
      " gggggggggggggg ",
      " gggggggggggggg ",
      " gggggggggggggg ",
      " gggggggggggggg ",
      " gggggggggggggg ",
      " gggggggggggggg ",
      " gggggggggggggg ",
      "                "
    ],
    [
      "                ",
      "                ",
      " !g gg    gg g  ",
      "!!!             ",
      " !g          g  ",
      "  g          g  ",
      "  g          g  ",
      "                ",
      "                ",
      "                ",
      "  g          g  ",
      "  g          g  ",
      "                ",
      "  g gg    gg g  ",
      "                ",
      "                "
    ]
  ]
}