{
  "xsize": 16,
  "zsize": 16,
  "refpalette": "lostcities:base",
  "slices": [
    [
      "     f          ",
      "  !  f          ",
      "ffʹ  f          ",
      "ʹʹfffff         ",
      "ʹʹf  ff         ",
      "ʹʹf  ff         ",
      "ffʹ  ff         ",
      "     ff         ",
      "     ff!        ",
      "     ff!!       ",
      "     ff!        ",
      "     ff         ",
      "     ff         ",
      "fffffff         ",
      "fffffff         ",
      "                "
    ],
    [
      "  !! f          ",
      "!!!! f          ",
      "ʹʹʹ! f          ",
      "ʹʹʹffff         ",
      "ʹʹʹ  ff         ",
      "ʹʹʹ  ff         ",
      "ʹʹʹ  ff         ",
      "     ff         ",
      "     ff!        ",
      "    !ff!!       ",
      "     ff!        ",
      "     ff         ",
      "     ff         ",
      "fffffff         ",
      "fffffff         ",
      "                "
    ],
    [
      "  !!!f          ",
      "!!!!!f          ",
      "!!!! f          ",
      "ffffff          ",
      "!!   f          ",
      "!    f          ",
      "     f          ",
      "     f          ",
      "!!!! f          ",
      "   !!f!!        ",
      "     f          ",
      "     f          ",
      "     f          ",
      "ffffff          ",
      "ffffff          ",
      "                "
    ],
    [
      "  !fff          ",
      "  !!ff          ",
      "!   ff          ",
      "!!  ff          ",
      "ffffff          ",
      "ffffff          ",
      "ffffff          ",
      "ffffff          ",
      "ffffff          ",
      "ffffff!         ",
      "ffffff          ",
      "ffffff          ",
      "ffffff          ",
      "ffffff          ",
      "ffffff          ",
      "                "
    ],
    [
      "   !!           ",
      "                ",
      "                ",
      "!               ",
      "!!              ",
      "!!  f           ",
      "!   f           ",
      "!               ",
      "!!!!            ",
      "!!!!!!          ",
      "!!  f           ",
      "    f           ",
      "    f           ",
      "    f           ",
      "fffff           ",
      "                "
    ],
    [
      "                ",
      "                ",
      "                ",
      "                ",
      "f               ",
      "f!              ",
      "f               ",
      "f               ",
      "f!              ",
      "f!!             ",
      "f!              ",
      "f   f           ",
      "f   f           ",
      "f   f           ",
      "fffff           ",
      "                "
    ]
  ]
}