{
  "xsize": 16,
  "zsize": 16,
  "refpalette": "lostcities:base",
  "slices": [
    [
      "ggggggggggg     ",
      " gggggggggg     ",
      "  gggggggggggg  ",
      "   ggggggggggg  ",
      "   gggggggggg   ",
      "g gggggggggggg  ",
      "gggggggggggggg  ",
      "gggggggggg!!    ",
      "gggggggggg!!!!!g",
      "gggggggggg!!!ggg",
      "gggggggggggggggg",
      "gggggggggggggggg",
      "gggggggggggggggg",
      "gggggggggggggggg",
      "ggggggggggg gggg",
      "ggggg        ggg"
    ],
    [
      "       !!!      ",
      "       !gggg    ",
      "        gggggg  ",
      "        gggggg  ",
      "        gggggg  ",
      "        gggggg  ",
      "        gggggg  ",
      "        gg      ",
      "         !!!    ",
      "           !!!!!",
      "              !!",
      "                ",
      "                ",
      "                ",
      "                ",
      "                "
    ],
    [
      "        !!!     ",
      "        gggg    ",
      "        gggg    ",
      "        gggggg  ",
      "        gggggg  ",
      "        gggggg  ",
      "        gggggg  ",
      "        ggg     ",
      "                ",
      "                ",
      "                ",
      "                ",
      "                ",
      "                ",
      "                ",
      "                "
    ],
    [
      "          !     ",
      "         !!!    ",
      "        !ggg    ",
      "         ggggg  ",
      "         ggggg  ",
      "         ggggg  ",
      "         ggggg  ",
      "                ",
      "                ",
      "                ",
      "                ",
      "                ",
      "                ",
      "                ",
      "                ",
      "                "
    ],
    [
      "                ",
      "          !     ",
      "         gg     ",
      "         ggg    ",
      "         ggggg  ",
      "         ggggg  ",
      "         ggggg  ",
      "                ",
      "                ",
      "                ",
      "                ",
      "                ",
      "                ",
      "                ",
      "                ",
      "                "
    ],
    [
      "                ",
      "                ",
      "                ",
      "                ",
      "                ",
      "                ",
      "                ",
      "                ",
      "                ",
      "                ",
      "                ",
      "                ",
      "                ",
      "                ",
      "                ",
      "                "
    ]
  ]
}