{
  "xsize": 16,
  "zsize": 16,
  "refpalette": "pomkotsmechs:base",
  "slices": [
    [
      "ʹʹʹʹʹʹʹʹʹ  ʹʹʹʹʹ",
      "ʹʹʹʹʹʹʹʹ    ʹʹʹʹ",
      "ʹʹʹʹʹʹʹʹ     ʹʹʹ",
      "ʹʹʹʹʹʹʹʹ    !ʹʹʹ",
      "ʹʹʹʹʹʹʹʹʹʹʹʹʹʹʹʹ",
      "ʹʹʹʹʹʹʹʹʹʹʹʹʹʹʹʹ",
      "ʹʹʹʹʹʹʹʹʹʹʹʹʹʹʹʹ",
      "ʹʹʹʹʹʹʹʹʹʹ  ʹʹʹʹ",
      "ʹʹʹʹʹʹʹʹʹʹ  ʹʹʹʹ",
      "ʹʹʹʹʹʹʹʹʹʹ  ʹʹʹʹ",
      "ʹʹʹʹʹʹʹʹʹʹ  ʹʹʹʹ",
      "ʹʹʹʹʹʹʹʹʹʹ  ʹʹʹʹ",
      "ʹʹʹʹʹʹʹʹʹʹʹʹʹʹʹʹ",
      " ʹʹʹʹʹʹʹʹʹʹʹʹʹʹʹ",
      " ʹʹʹʹ!  ʹʹʹʹʹʹʹʹ",
      " ʹʹʹ!   ʹʹʹʹʹʹʹʹ"
    ],
    [
      "g              g",
      " ffffff       f ",
      " ffffff      !!!",
      " ffffff     !!! ",
      " ffffff    ffff ",
      " ffffffffffffff ",
      " ffffffffffffff ",
      " fffffffff  fff ",
      " fffffffff  fff ",
      " fffffffff  fff ",
      " ffffff     fff ",
      " fffff      fff ",
      " ffff       fff ",
      "  fff!    fffff ",
      "  ff!!!  ffffff ",
      "    !!         g"
    ],
    [
      "gʹʹʹʹʹʹʹ     ʹʹg",
      "ʹffffff         ",
      "ʹf           !  ",
      "ʹf          !!! ",
      "ʹf           !fʹ",
      "ʹf            fʹ",
      "ʹf            fʹ",
      "ʹf            fʹ",
      "ʹf            fʹ",
      "ʹf            fʹ",
      "ʹf            fʹ",
      "ʹf            fʹ",
      "ʹf            fʹ",
      "     !        fʹ",
      "   f!!!   fffffʹ",
      "   ʹ !! ʹʹʹʹʹʹ g"
    ],
    [
      "g              g",
      " f  f           ",
      "             !  ",
      "            !!! ",
      " f           !f ",
      "                ",
      "                ",
      " f            f ",
      " f            f ",
      "                ",
      "                ",
      " f            f ",
      "                ",
      "     !!         ",
      "    !!!!   f  f ",
      "     !!!       g"
    ],
    [
      "g              g",
      " f  f  f        ",
      "             !! ",
      "            !!!!",
      " f           !!!",
      "              ! ",
      "                ",
      " f            f ",
      " f            f ",
      "                ",
      "                ",
      " f            f ",
      "                ",
      "                ",
      "     !!    f  f ",
      "     !!!       g"
    ],
    [
      "g              g",
      " ffffffff       ",
      " ffffffff       ",
      " ffffffffff  !! ",
      " ffffffffffffff!",
      " ffffffffffffff ",
      " ffffffffffffff ",
      " fffffffff  fff ",
      " ffffffffffffff ",
      " ffffffffffffff ",
      " ffffffffffffff ",
      " ffffffffffffff ",
      " ffff   fffffff ",
      "  ff    fffffff ",
      "      !!fffffff ",
      "     !!!!      g"
    ]
  ]
}