{
  "xsize": 16,
  "zsize": 16,
  "refpalette": "pomkotsmechs:base",
  "slices": [
    [
      "            Ͷ   ",
      "            Ͷ   ",
      "           !Ͷ   ",
      "          !Ͷ!   ",
      "           Ͷ    ",
      "          Ͷ     ",
      "         Ͷ      ",
      "Ͷ      ͶͶ       ",
      " ͶͶͶͶͶͶ         ",
      "ͶͶ     ͶͶͶͶ     ",
      "  Ͷ   Ͷ    Ͷ    ",
      "   Ͷ Ͷ      Ͷ   ",
      "   Ͷ Ͷ      Ͷ   ",
      "   Ͷ Ͷ      Ͷ   ",
      "   Ͷ Ͷ      Ͷ   ",
      "  Ͷ   Ͷ    Ͷ    "
    ],
    [
      "            Ͷ   ",
      "            Ͷ   ",
      "           !Ͷ   ",
      "          !Ͷ!   ",
      "           Ͷ    ",
      "          Ͷ     ",
      "         Ͷ      ",
      "Ͷ      ͶͶ       ",
      " ͶͶͶͶͶͶ         ",
      "ͶͶ     ͶͶͶͶ     ",
      "  Ͷ   Ͷ    Ͷ    ",
      "   Ͷ Ͷ      Ͷ   ",
      "   Ͷ Ͷ      Ͷ   ",
      "   Ͷ Ͷ      Ͷ   ",
      "   Ͷ Ͷ      Ͷ   ",
      "  Ͷ   Ͷ    Ͷ    "
    ],
    [
      "            Ͷ   ",
      "            Ͷ   ",
      "           !Ͷ   ",
      "          !Ͷ!   ",
      "           Ͷ    ",
      "          Ͷ     ",
      "         Ͷ      ",
      "Ͷ      ͶͶ       ",
      " ͶͶͶͶͶͶ         ",
      "ͶͶ     ͶͶͶͶ     ",
      "  Ͷ   Ͷ    Ͷ    ",
      "   Ͷ Ͷ      Ͷ   ",
      "   Ͷ Ͷ      Ͷ   ",
      "   Ͷ Ͷ      Ͷ   ",
      "   Ͷ Ͷ      Ͷ   ",
      "  Ͷ   Ͷ    Ͷ    "
    ],
    [
      "            Ͷ   ",
      "            Ͷ   ",
      "           !Ͷ   ",
      "          !Ͷ!   ",
      "           Ͷ    ",
      "          Ͷ     ",
      "         Ͷ      ",
      "Ͷ      ͶͶ       ",
      " ͶͶͶͶͶͶ         ",
      "ͶͶ     ͶͶͶͶ     ",
      "  Ͷ   Ͷ    Ͷ    ",
      "   Ͷ Ͷ      Ͷ   ",
      "   Ͷ Ͷ      Ͷ   ",
      "   Ͷ Ͷ      Ͷ   ",
      "   Ͷ Ͷ      Ͷ   ",
      "  Ͷ   Ͷ    Ͷ    "
    ],
    [
      "            Ͷ   ",
      "            Ͷ   ",
      "           !Ͷ   ",
      "          !Ͷ!   ",
      "           Ͷ    ",
      "          Ͷ     ",
      "         Ͷ      ",
      "Ͷ      ͶͶ       ",
      " ͶͶͶͶͶͶ         ",
      "ͶͶ     ͶͶͶͶ     ",
      "  Ͷ   Ͷ    Ͷ    ",
      "   Ͷ Ͷ      Ͷ   ",
      "   Ͷ Ͷ      Ͷ   ",
      "   Ͷ Ͷ      Ͷ   ",
      "   Ͷ Ͷ      Ͷ   ",
      "  Ͷ   Ͷ    Ͷ    "
    ],
    [
      "            Ͷ   ",
      "            Ͷ   ",
      "           !Ͷ!  ",
      "          !Ͷ!!  ",
      "           Ͷ!   ",
      "          Ͷ     ",
      "         Ͷ      ",
      "Ͷ      ͶͶ       ",
      " ͶͶͶͶͶͶ         ",
      "ͶͶ     ͶͶͶͶ     ",
      "  Ͷ   Ͷ    Ͷ    ",
      "   Ͷ Ͷ      Ͷ   ",
      "   Ͷ Ͷ      Ͷ   ",
      "   Ͷ Ͷ      Ͷ   ",
      "   Ͷ Ͷ      Ͷ   ",
      "  Ͷ   Ͷ    Ͷ    "
    ]
  ]
}