{
  "xsize": 16,
  "zsize": 16,
  "refpalette": "pomkotsmechs:base",
  "slices": [
    [
      "                ",
      "         fffffff",
      "         fffffff",
      "         ff     ",
      "         ff     ",
      "         ff     ",
      "        !ff  ʹff",
      "         ff  fʹʹ",
      "         ff  fʹʹ",
      "         ff  fʹʹ",
      "         ff  ʹff",
      "         ff     ",
      "         fffffff",
      "          f  ʹff",
      "          f  fʹʹ",
      "          f  fʹʹ"
    ],
    [
      "                ",
      "         fffffff",
      "         fffffff",
      "         ff     ",
      "         ff     ",
      "         ff     ",
      "        !ff! ʹʹʹ",
      "         ff  ʹʹʹ",
      "         ff  ʹʹʹ",
      "         ff  ʹʹʹ",
      "         ff  ʹʹʹ",
      "         ff     ",
      "         fffffff",
      "          f  ʹʹ ",
      "          f  ʹʹ ",
      "          f  ʹ  "
    ],
    [
      "                ",
      "          ffffff",
      "          ffffff",
      "          f     ",
      "          f     ",
      "          f     ",
      "         !f!    ",
      "          f     ",
      "          f     ",
      "          f     ",
      "          f     ",
      "          f     ",
      "          ffffff",
      "          f     ",
      "          f     ",
      "          f     "
    ],
    [
      "                ",
      "          ffffff",
      "          ffffff",
      "          ffffff",
      "          ffffff",
      "         !ffffff",
      "         !ffffff",
      "          ffffff",
      "          ffffff",
      "          ffffff",
      "          ffffff",
      "          fffff ",
      "          ffff  ",
      "          ffff  ",
      "          ffff  ",
      "          ffff  "
    ],
    [
      "                ",
      "           fffff",
      "           f    ",
      "           f    ",
      "           f    ",
      "          !f!   ",
      "          !f!  !",
      "           f    ",
      "           f    ",
      "           f    ",
      "           f    ",
      "           f    ",
      "           ff   ",
      "                ",
      "                ",
      "                "
    ],
    [
      "                ",
      "           fffff",
      "           f   f",
      "           f   f",
      "           f   f",
      "          !f!!!f",
      "           f  !f",
      "           f   f",
      "           f   f",
      "           f   f",
      "           f   f",
      "           f    ",
      "           f    ",
      "                ",
      "                ",
      "                "
    ]
  ]
}