{
  "xsize": 16,
  "zsize": 16,
  "refpalette": "lostcities:base",
  "slices": [
    [
      "                ",
      "                ",
      "       ͳͳ       ",
      "      gͶͶg      ",
      "     gͶͶͶͶg!    ",
      "    ͳͶͶͶͶͶͶͳ!   ",
      "    ͳͶͶͶͶͶͶͳ    ",
      "    !gͶͶͶͶg     ",
      "     !gͶͶg      ",
      "       ͳͳ       ",
      "    Ͳ      Ͳ    ",
      "   ͲͲͲͲͲͲͲͲͲͲ   ",
      "   !Ͳ!     Ͳ    ",
      "   !Ͳ      Ͳ    ",
      "  !ͲͲͲͲͲͲͲͲͲͲ   ",
      "   !Ͳ      Ͳ    "
    ],
    [
      "                ",
      "                ",
      "       ͳͳ       ",
      "      gͶͶg      ",
      "     gͶͶͶͶg!    ",
      "    ͳͶͶͶͶͶͶͳ!   ",
      "    ͳͶͶͶͶͶͶͳ    ",
      "    !gͶͶͶͶg     ",
      "     !gͶͶg      ",
      "       ͳͳ       ",
      "                ",
      "    Ͳ      Ͳ    ",
      "   !!!          ",
      "   !!!          ",
      "   !Ͳ      Ͳ    ",
      "                "
    ],
    [
      "                ",
      "                ",
      "                ",
      "      gͶͶg      ",
      "     gͶͶͶͶg!    ",
      "     ͶͶͶͶͶͶ!!   ",
      "     ͶͶͶͶͶͶ!    ",
      "    !gͶͶͶͶg     ",
      "     !gͶͶg      ",
      "                ",
      "                ",
      "    Ͳ      Ͳ    ",
      "    !           ",
      "   !!!          ",
      "    Ͳ      Ͳ    ",
      "                "
    ],
    [
      "                ",
      "                ",
      "                ",
      "      gͶͶg      ",
      "     gͶͶͶͶg     ",
      "     ͶͶͶͶͶͶ!    ",
      "     ͶͶͶͶͶͶ     ",
      "     gͶͶͶͶg     ",
      "      gͶͶg      ",
      "                ",
      "    Ͳ      Ͳ    ",
      "   ͲͲͲͲͲͲͲͲͲͲ   ",
      "    Ͳ      Ͳ    ",
      "   !Ͳ!     Ͳ    ",
      "   ͲͲͲͲͲͲͲͲͲͲ   ",
      "    Ͳ      Ͳ    "
    ],
    [
      "                ",
      "                ",
      "                ",
      "      ͶͶͶͶ      ",
      "     ͶͶͶͶͶͶ     ",
      "     ͶͶͶͶͶͶ!    ",
      "     ͶͶͶͶͶͶ!    ",
      "     ͶͶͶͶͶͶ     ",
      "      ͶͶͶͶ      ",
      "                ",
      "                ",
      "    Ͳ      Ͳ    ",
      "    !           ",
      "   !!!          ",
      "   !Ͳ      Ͳ    ",
      "                "
    ],
    [
      "                ",
      "                ",
      "                ",
      "      ͶͶͶͶ      ",
      "     ͶͶͶͶͶͶ     ",
      "     ͶͶͶͶͶͶ     ",
      "     ͶͶͶͶͶͶ!    ",
      "     ͶͶͶͶͶͶ     ",
      "      ͶͶͶͶ      ",
      "                ",
      "                ",
      "    Ͳ      Ͳ    ",
      "   !!           ",
      "  !!!!          ",
      "  !!Ͳ!     Ͳ    ",
      "   !!!          "
    ]
  ]
}