{
  "xsize": 16,
  "zsize": 16,
  "refpalette": "lostcities:base",
  "slices": [
    [
      "Ͷ        ͶYͶ    ",
      "Ͷ!       ͶYͶ    ",
      "!Ͷ!     ͶYYͶ    ",
      " ͶͶ    ͶͶY  Ͷ   ",
      "   ͶͶͶͶYYY  Ͷ   ",
      "      ͶY     Ͷ  ",
      "      ͶY      Ͷ ",
      "      ͶY       Ͷ",
      "      ͶY        ",
      "      ͶY      ͶͶ",
      "      ͶY     Ͷ  ",
      "      ͶY    Ͷ   ",
      "      ͶY    Ͷ   ",
      "      ͶY    Ͷ   ",
      "      ͶY    Ͷ   ",
      "       Y     Ͷ  "
    ],
    [
      "Ͷ!       ͶYͶ    ",
      "Ͷ!!      ͶYͶ    ",
      "!Ͷ!     ͶYYͶ    ",
      " ͶͶ    ͶͶY  Ͷ   ",
      "   ͶͶͶͶYYY  Ͷ   ",
      "      ͶY     Ͷ  ",
      "      ͶY      Ͷ ",
      "      ͶY       Ͷ",
      "      ͶY        ",
      "      ͶY      ͶͶ",
      "      ͶY     Ͷ  ",
      "      ͶY    Ͷ   ",
      "      ͶY    Ͷ   ",
      "      ͶY    Ͷ   ",
      "       Y    Ͷ   ",
      "             Ͷ  "
    ],
    [
      "Ͷ        ͶYͶ    ",
      "Ͷ!       ͶYͶ    ",
      "!Ͷ      ͶYYͶ    ",
      " ͶͶ    ͶͶY  Ͷ   ",
      "   ͶͶͶͶYYY  Ͷ   ",
      "      ͶY     Ͷ  ",
      "      ͶY      Ͷ ",
      "      ͶY       Ͷ",
      "      ͶY        ",
      "      ͶY      ͶͶ",
      "      ͶY     Ͷ  ",
      "      ͶY    Ͷ   ",
      "      ͶY    Ͷ   ",
      "      ͶY    Ͷ   ",
      "       Y    Ͷ   ",
      "             Ͷ  "
    ],
    [
      "Ͷ        ͶYͶ    ",
      "Ͷ!       ͶYͶ    ",
      "!Ͷ      ͶYYͶ    ",
      " ͶͶ    ͶͶY  Ͷ   ",
      "   ͶͶͶͶYYY  Ͷ   ",
      "      ͶY     Ͷ  ",
      "      ͶY      Ͷ ",
      "      ͶY       Ͷ",
      "      ͶY        ",
      "      ͶY      ͶͶ",
      "      ͶY     Ͷ  ",
      "      ͶY    Ͷ   ",
      "      ͶY    Ͷ   ",
      "       Y    Ͷ   ",
      "            Ͷ   ",
      "             Ͷ  "
    ],
    [
      "Ͷ!       ͶYͶ    ",
      "Ͷ!       ͶYͶ    ",
      "!Ͷ      ͶYYͶ    ",
      " ͶͶ    ͶͶY  Ͷ   ",
      "   ͶͶͶͶYYY  Ͷ   ",
      "      ͶY     Ͷ  ",
      "      ͶY      Ͷ ",
      "      ͶY       Ͷ",
      "       Y        ",
      "       Y      ͶͶ",
      "      ͶY     Ͷ  ",
      "      ͶY    Ͷ   ",
      "      ͶY    Ͷ   ",
      "       Y    Ͷ   ",
      "            Ͷ   ",
      "             Ͷ  "
    ],
    [
      "Ͷ!       ͶYͶ    ",
      "Ͷ        ͶYͶ    ",
      " Ͷ      ͶYYͶ    ",
      " ͶͶ    ͶͶY  Ͷ   ",
      "   ͶͶͶͶYYY  Ͷ   ",
      "      ͶY     Ͷ  ",
      "      ͶY      Ͷ ",
      "       Y       Ͷ",
      "       Y        ",
      "       Y      ͶͶ",
      "       Y     Ͷ  ",
      "       Y    Ͷ   ",
      "       Y    Ͷ   ",
      "            Ͷ   ",
      "            Ͷ   ",
      "             Ͷ  "
    ]
  ]
}