{
  "xsize": 16,
  "zsize": 16,
  "refpalette": "lostcities:base",
  "slices": [
    [
      "vvvvvvvvvvvvvvvv",
      "vvvvvvvvvvvvvvvv",
      "vvvvvvvvvvvvvvvv",
      "vvvvvvvvvvvvvvvv",
      "vvvvvvvvvvvvvvvv",
      "vvvvvvvvvvvvvvvv",
      "vvvvvvvvvvvvvvvv",
      "vvvvvvvvvvvvvvvv",
      "vvvvvvvvvvvvvvvv",
      "vvvvvvvvvvvvvvvv",
      "vvvvvvvvvvvvvvvv",
      "vvvvvvvvvvvvvvvv",
      "vvvvvvvvvvvvvvvv",
      "vvvvvvvvvvvvvvvv",
      "vvvvvvvvvvvvvvvv",
      "vvvvvvvvvvvvvvvv"
    ],
    [
      "                ",
      "                ",
      "                ",
      "                ",
      "                ",
      "                ",
      "gggggggggggggggg",
      "gggggggggggggggg",
      "                ",
      "                ",
      "             !  ",
      "            !!!!",
      "             ! !",
      "                ",
      "                ",
      "                "
    ],
    [
      "                ",
      "     ffffff     ",
      "     ffffff     ",
      "     ffffff     ",
      "     ffffff     ",
      "     ffffff     ",
      "gggggggggggggggg",
      "gggggggggggggggg",
      "     ffffff     ",
      "     ffffff     ",
      "     ffffff  !! ",
      "     ffffff !!! ",
      "     ffffff  !  ",
      "     ffffff     ",
      "     ffffff     ",
      "     ffffff     "
    ],
    [
      "      gggg      ",
      "    ffffffff    ",
      "    ffffffff    ",
      "    ffffffff    ",
      "    f      f    ",
      "    f      f    ",
      "gggggggggggggggg",
      "gggggggggggggggg",
      "    f      f    ",
      "    f      f  ! ",
      "    f      f !!!",
      "    f      f!!!!",
      "    f      f !! ",
      "    f      f    ",
      "    f      f    ",
      "    f      f    "
    ],
    [
      "    gg    gg    ",
      "   ffffffffff   ",
      "   ffffffffff   ",
      "   ffffffffff   ",
      "   f        f   ",
      "   f        f   ",
      "gggggggggggggggg",
      "gggggggggggggggg",
      "   f        f   ",
      "   f        f ! ",
      "   f        f!!!",
      "   f        f!! ",
      "   f        f   ",
      "   f        f   ",
      "   f        f   ",
      "   f        f   "
    ],
    [
      "   g        g   ",
      "  ffffffffffff  ",
      "  ffffffffffff  ",
      "  ffffffffffff  ",
      "  f          f  ",
      "  f          f  ",
      "gggggggggggggggg",
      "gggggggggggggggg",
      "  f          f  ",
      "  f          f! ",
      "  f          f!!",
      "  f          f! ",
      "  f          f  ",
      "  f          f  ",
      "  f          f  ",
      "  f          f  "
    ]
  ]
}