{
  "xsize": 16,
  "zsize": 16,
  "refpalette": "pomkotsmechs:base",
  "slices": [
    [
      "sg  !     gg  gg",
      " goooooooogggggg",
      " g  !     gg  gg",
      "ggg             ",
      "ggg          ff ",
      " mg          ff ",
      " m              ",
      " m              ",
      "!m!             ",
      "!m!             ",
      " m              ",
      " m              ",
      " m              ",
      " m              ",
      "ggg             ",
      " g              "
    ],
    [
      " g  !     gg  gg",
      " goooooooogggggg",
      " g  !     gg  gg",
      "gggtttttttttttti",
      "gggffffff fffffu",
      " mgfffff   ffffu",
      " m           ffu",
      " m           ffu",
      " m           ffu",
      "!m!          ffu",
      " m           ffu",
      " m           ffu",
      " m           ffu",
      " m           ffu",
      "ggg          ffu",
      " g           ffu"
    ],
    [
      " g  !     gg  gg",
      " goooooooogggggg",
      " g  !     gg  gg",
      "gggpppppp ppptti",
      " gg          wxu",
      "             jyu",
      "               z",
      " m             z",
      " m             z",
      "!m!            z",
      "!m!            z",
      " m             z",
      " m             z",
      " m             z",
      "ggg            z",
      " g             z"
    ],
    [
      " g  !     gg  gg",
      " goooooooogggggg",
      " g  !     gg  gg",
      "ggg             ",
      " gg          hi ",
      "             jk ",
      "                ",
      " m              ",
      " m              ",
      " m              ",
      "!m!             ",
      " m              ",
      " m              ",
      " m              ",
      "ggg             ",
      " g              "
    ],
    [
      "gg  !!    gg  gg",
      " goooooooogggggg",
      " g  !     gg  gg",
      " gg             ",
      " gg          hi ",
      "             jk ",
      "                ",
      " m              ",
      " m              ",
      " m              ",
      "!m!             ",
      "!m              ",
      " m              ",
      " m              ",
      "ggg             ",
      " g              "
    ],
    [
      "ng  !!!   gg  gg",
      " goooooooogggggg",
      "    !!    gg  gg",
      " gg             ",
      " gg          hi ",
      "  g          jk ",
      " m              ",
      " m              ",
      " m              ",
      "!m              ",
      "!m!             ",
      "!m              ",
      "!m              ",
      " m              ",
      "ggg             ",
      " g              "
    ]
  ]
}