{
  "xsize": 16,
  "zsize": 16,
  "refpalette": "lostcities:base",
  "slices": [
    [
      "ggg   gggggg    ",
      "gggg gggggggg   ",
      "gggg gggggggg   ",
      "gggg gggggggg   ",
      "gggg gggggggg   ",
      "ggg   gggggg    ",
      "gg     gggg     ",
      " gggggg         ",
      "g      gg       ",
      "         g      ",
      "          g     ",
      "           g    ",
      "           g    ",
      "            g   ",
      "            g   ",
      "            g   "
    ],
    [
      "  Ͷ   Ͷ   !Ͷ    ",
      "   Ͷ Ͷ      Ͷ   ",
      "   Ͷ Ͷ      Ͷ   ",
      "   Ͷ Ͷ      Ͷ   ",
      "   Ͷ Ͷ      Ͷ   ",
      "  Ͷ   Ͷ    Ͷ    ",
      "ͶͶ     ͶͶͶͶ     ",
      " gggggg         ",
      "g      gg       ",
      "         g      ",
      "          g     ",
      "           g    ",
      "           g    ",
      "            g   ",
      "            g   ",
      "            g   "
    ],
    [
      "  Ͷ   Ͷ   !Ͷ    ",
      "   Ͷ Ͷ      Ͷ   ",
      "   Ͷ Ͷ      Ͷ   ",
      "   Ͷ Ͷ      Ͷ   ",
      "   Ͷ Ͷ      Ͷ   ",
      "  Ͷ   Ͷ    Ͷ    ",
      "ͶͶ     ͶͶͶͶ     ",
      " gggggg         ",
      "g      gg       ",
      "         g      ",
      "          g     ",
      "           g    ",
      "           g    ",
      "            g   ",
      "            g   ",
      "            g   "
    ],
    [
      "  Ͷ   Ͷ   !Ͷ    ",
      "   Ͷ Ͷ      Ͷ   ",
      "   Ͷ Ͷ      Ͷ   ",
      "   Ͷ Ͷ      Ͷ   ",
      "   Ͷ Ͷ      Ͷ   ",
      "  Ͷ   Ͷ    Ͷ    ",
      "ͶͶ     ͶͶͶͶ     ",
      " gggggg         ",
      "ggggggggg       ",
      "gggggggggg      ",
      "ggggggggggg     ",
      "gggggggggggg    ",
      "gggggggggggg    ",
      "ggggggggggggg   ",
      "ggggggggggggg   ",
      "ggggggggggggg   "
    ],
    [
      "  Ͷ   Ͷ   !Ͷ    ",
      "   Ͷ Ͷ      Ͷ   ",
      "   Ͷ Ͷ      Ͷ   ",
      "   Ͷ Ͷ      Ͷ   ",
      "   Ͷ Ͷ      Ͷ   ",
      "  Ͷ   Ͷ    Ͷ    ",
      "ͶͶ     ͶͶͶͶ     ",
      " ͶͶͶͶͶͶ         ",
      "Ͷ      ͶͶ       ",
      "         Ͷ      ",
      "          Ͷ     ",
      "           Ͷ    ",
      "           Ͷ    ",
      "            Ͷ   ",
      "            Ͷ   ",
      "            Ͷ   "
    ],
    [
      "  Ͷ   Ͷ   !Ͷ!   ",
      "   Ͷ Ͷ     !Ͷ   ",
      "   Ͷ Ͷ      Ͷ   ",
      "   Ͷ Ͷ      Ͷ   ",
      "   Ͷ Ͷ      Ͷ   ",
      "  Ͷ   Ͷ    Ͷ    ",
      "ͶͶ     ͶͶͶͶ     ",
      " ͶͶͶͶͶͶ         ",
      "Ͷ      ͶͶ       ",
      "         Ͷ      ",
      "          Ͷ     ",
      "           Ͷ    ",
      "           Ͷ    ",
      "            Ͷ   ",
      "            Ͷ   ",
      "            Ͷ   "
    ]
  ]
}