{
  "xsize": 16,
  "zsize": 16,
  "refpalette": "pomkotsmechs:base",
  "slices": [
    [
      "                ",
      "                ",
      "fʹ            ʹf",
      "ʹf            fʹ",
      "ʹf!           fʹ",
      "ʹf!!          fʹ",
      "fʹ!    !      ʹf",
      "      !!!       ",
      "      !!!       ",
      "       !        ",
      "                ",
      "                ",
      "!               ",
      "ffff       fffff",
      "!               ",
      "                "
    ],
    [
      "                ",
      "                ",
      "ʹʹ            ʹʹ",
      "ʹʹ            ʹʹ",
      "ʹʹ!           ʹʹ",
      "ʹʹ!!          ʹʹ",
      "ʹʹ!!          ʹʹ",
      "!!!    !        ",
      "      !!!       ",
      "       !        ",
      "                ",
      "                ",
      "!               ",
      "ffff       fffff",
      "!               ",
      "                "
    ],
    [
      "                ",
      "                ",
      " n            n ",
      "                ",
      "                ",
      " !!             ",
      "!n!!          n ",
      "!!!    !        ",
      "!!    !!!       ",
      "       !        ",
      "                ",
      "                ",
      "!               ",
      "fffff      fffff",
      "!               ",
      "                "
    ],
    [
      "                ",
      "                ",
      "ʹʹ            ʹʹ",
      "ʹʹ            ʹʹ",
      "ʹʹ            ʹʹ",
      "ʹʹ!           ʹʹ",
      "ʹʹ!!          ʹʹ",
      "!!!!   !        ",
      "!!!   !!!       ",
      "!      !        ",
      "                ",
      "                ",
      "!               ",
      "fffffff    fffff",
      "!               ",
      "                "
    ],
    [
      "                ",
      "                ",
      "fʹ            ʹf",
      " f            f ",
      " f            f ",
      " f!!          f ",
      "fʹ!!!         ʹf",
      "!!!!!  !        ",
      "!!!!  !!!       ",
      "! !   !!!       ",
      "       !        ",
      "                ",
      "!               ",
      "ffffffff    ffff",
      "!!              ",
      "!               "
    ],
    [
      "                ",
      "                ",
      "fʹ            ʹf",
      " f            f ",
      " f            f ",
      " f            f ",
      "fʹ!!          ʹf",
      "!!!!!           ",
      "!!!!   !        ",
      "!!!   !!!       ",
      "!      !        ",
      "                ",
      "                ",
      "ffffffff    ffff",
      "!!              ",
      "!               "
    ]
  ]
}