{
  "xsize": 16,
  "zsize": 16,
  "refpalette": "pomkotsmechs:base",
  "slices": [
    [
      "                ",
      "        g       ",
      "      !!        ",
      "     !ffff      ",
      "     f!!  f     ",
      "    f      f    ",
      "  g f      f    ",
      "    f      f g  ",
      "    f!     f    ",
      "    !f!   f     ",
      "     !ffff      ",
      "                ",
      "       g        ",
      "                ",
      "                ",
      "                "
    ],
    [
      "                ",
      "        g       ",
      "      !         ",
      "     !ffff      ",
      "     f!   f     ",
      "    f      f    ",
      "  g f      f    ",
      "    f      f g  ",
      "    f!     f    ",
      "    !f!   f     ",
      "     !ffff      ",
      "                ",
      "       g        ",
      "                ",
      "                ",
      "                "
    ],
    [
      "                ",
      "        g       ",
      "      !         ",
      "     !ffff      ",
      "     f!   f     ",
      "    f      f    ",
      "  g f      f    ",
      "    f      f g  ",
      "    f      f    ",
      "     f    f     ",
      "      ffff      ",
      "                ",
      "       g        ",
      "                ",
      "                ",
      "                "
    ],
    [
      "                ",
      "        g       ",
      "     !!         ",
      "    !!ffff      ",
      "    !f!   f     ",
      "    f!!    f    ",
      "  g f      f    ",
      "    f      f g  ",
      "    f      f    ",
      "     f    f     ",
      "      ffff      ",
      "                ",
      "       g        ",
      "                ",
      "                ",
      "                "
    ],
    [
      "                ",
      "        g       ",
      "                ",
      "     !ffff      ",
      "    !ffffff     ",
      "    ffffffff    ",
      "  g ffffffff    ",
      "    ffffffff g  ",
      "    ffffffff    ",
      "     ffffff     ",
      "      ffff      ",
      "                ",
      "       g        ",
      "                ",
      "                ",
      "                "
    ],
    [
      "                ",
      "        g       ",
      "        g       ",
      "        g       ",
      "     !  g       ",
      "     !!gg       ",
      "  gggggggg      ",
      "      gggggggg  ",
      "       gg       ",
      "       g        ",
      "       g        ",
      "       g        ",
      "       g        ",
      "                ",
      "                ",
      "                "
    ]
  ]
}