{
  "xsize": 16,
  "zsize": 16,
  "refpalette": "pomkotsmechs:base",
  "slices": [
    [
      "vvvvvvvvvvvvvvvv",
      "vvvvvvvvvvvvvvvv",
      "vvvvvvvvvvvvvvvv",
      "vvvvvvvvvvvvvvvv",
      "vvvvvvvvvvvvvvvv",
      "vvvvvvvvvvvvvvvv",
      "vvvvvvvvvvvvvvvv",
      "vvvvvvvvvvvvvvvv",
      "vvvvvvvvvvvvvvvv",
      "vvvvvvvvvvvvvvvv",
      "vvvvvvvvvvvvvvvv",
      "vvvvvvvvvvvvvvvv",
      "vvvvvvvvvvvvvvvv",
      "vvvvvvvvvvvvvvvv",
      "vvvvvvvvvvvvvvvv",
      "vvvvvvvvvvvvvvvv"
    ],
    [
      "                ",
      "                ",
      "                ",
      "                ",
      "                ",
      "                ",
      "                ",
      "                ",
      "  #             ",
      "                ",
      "                ",
      "                ",
      "                ",
      " !              ",
      "!!!!            ",
      "!!!!            "
    ],
    [
      "                ",
      "                ",
      "                ",
      "                ",
      "@               ",
      "A@              ",
      "A@              ",
      "AQ              ",
      "AAR             ",
      "AQ              ",
      "AQ              ",
      "AQ              ",
      "AQ              ",
      "AQ              ",
      "AQ!             ",
      "AQ              "
    ],
    [
      "                ",
      "                ",
      "                ",
      "                ",
      "AS              ",
      "AA              ",
      "GA              ",
      ";T              ",
      " A              ",
      "AA              ",
      "                ",
      "!               ",
      "                ",
      " A              ",
      "AA!             ",
      "AA              "
    ],
    [
      "                ",
      "                ",
      "                ",
      "                ",
      "                ",
      ";I              ",
      " ;              ",
      ";T              ",
      " A              ",
      "AA              ",
      "                ",
      "                ",
      "                ",
      " A              ",
      "AA!             ",
      "AA              "
    ],
    [
      "                ",
      "                ",
      "                ",
      "                ",
      "                ",
      "                ",
      "I               ",
      "AI              ",
      "AU              ",
      "AU              ",
      "!A              ",
      " A              ",
      " A              ",
      "!U              ",
      "AU!             ",
      "II              "
    ]
  ]
}