{
  "xsize": 16,
  "zsize": 16,
  "refpalette": "pomkotsmechs:base",
  "slices": [
    [
      "gggggggggggggggg",
      "gggggggggggggggg",
      "gggggggggggggggg",
      "gggggggggggggggg",
      "gggggggggggggggg",
      "gggggggggggggggg",
      "gggggggggggggggg",
      "gggggggggggggggg",
      "gggggggggggggggg",
      "gggggggggggggggg",
      "gggggggggggggggg",
      "gggggggggggggggg",
      "gggggggggggggggg",
      "gggggggggggggggg",
      "gggggggggggggggg",
      "gggggggggggggggg"
    ],
    [
      " gg        !!!!g",
      "g Yg       !!!g ",
      "  Y      !!!    ",
      "  Y     !!      ",
      "  Y    !!       ",
      "  Y   !!        ",
      "  Y!!!!         ",
      " !Y!!           ",
      "  Y!            ",
      "  Y             ",
      "  Y           !!",
      "  Y          !! ",
      "  Y        !!!  ",
      "  Y       !!    ",
      "g Yg     !!   g ",
      " gg    !!!     g"
    ],
    [
      " gg         !! g",
      "  Y             ",
      "  Y             ",
      "  Y             ",
      "  Y             ",
      "  Y             ",
      "  Y             ",
      " !Y!            ",
      "  Y             ",
      "  Y             ",
      "  Y             ",
      "  Y             ",
      "  Y             ",
      "  Y             ",
      "  Y             ",
      " gg            g"
    ],
    [
      " gg            g",
      "  Y             ",
      "  Y             ",
      "  Y             ",
      "  Y             ",
      "  Y             ",
      " !Y!            ",
      " !Y!            ",
      "  Y             ",
      "  Y             ",
      "  Y             ",
      "  Y             ",
      "  Y             ",
      "  Y             ",
      "  Y             ",
      " gg            g"
    ],
    [
      "!gg!           g",
      " !Y!            ",
      "  Y             ",
      "  Y             ",
      "  Y             ",
      "  Y             ",
      " !Y!            ",
      "  Y             ",
      "  Y             ",
      "  Y             ",
      "  Y             ",
      "  Y             ",
      "  Y             ",
      "  Y             ",
      "  Y             ",
      " gg            g"
    ],
    [
      " gg            g",
      " !Y!            ",
      " !Y!            ",
      " !Y!            ",
      "  Y             ",
      "  Y             ",
      " !Y!            ",
      "  Y             ",
      "  Y             ",
      "  Y             ",
      "  Y             ",
      "  Y             ",
      "  Y             ",
      "  Y             ",
      "  Y             ",
      " gg            g"
    ]
  ]
}