{
  "xsize": 16,
  "zsize": 16,
  "refpalette": "pomkotsmechs:base",
  "slices": [
    [
      "vvvvvvvvvvvvvvvv",
      "vvvvvvvvvvvvvvvv",
      "vvvvvvvvvvvvvvvv",
      "vvvvvvvvvvvvvvvv",
      "vvvvvvvvvvvvvvvv",
      "vvvvvvvvvvvvvvvv",
      "vvvvvvvvvvvvvvvv",
      "vvvvvvvvvvvvvvvv",
      "vvvvvvvvvvvvvvvv",
      "vvvvvvvvvvvvvvvv",
      "vvvvvvvvvvvvvvvv",
      "vvvvvvvvvvvvvvvv",
      "vvvvvvvvvvvvvvvv",
      "vvvvvvvvvvvvvvvv",
      "vvvvvvvvvvvvvvvv",
      "vvvvvvvvvvvvvvvv"
    ],
    [
      "             !!!",
      "             !!!",
      "              ! ",
      "             #  ",
      "                ",
      "                ",
      "                ",
      "                ",
      "                ",
      "          !     ",
      "         !!!    ",
      "         !!!    ",
      "         !!     ",
      "                ",
      "                ",
      "                "
    ],
    [
      "              !!",
      "              !!",
      "                ",
      "             $  ",
      "                ",
      "                ",
      "                ",
      "                ",
      "                ",
      "                ",
      "          !     ",
      "         !!!    ",
      "        !!!!    ",
      "         !!     ",
      "                ",
      "                "
    ],
    [
      "               !",
      "                ",
      "                ",
      "             $  ",
      "                ",
      "                ",
      "                ",
      "                ",
      "                ",
      "                ",
      "                ",
      "         !!     ",
      "        !!!     ",
      "        !!!     ",
      "         !      ",
      "                "
    ],
    [
      "             '('",
      "             '('",
      "             '('",
      "             '('",
      "             '('",
      "             '('",
      "             '('",
      "             ./'",
      "             ./'",
      "             ./(",
      "           !!02 ",
      "           !!02 ",
      "         !!!    ",
      "        !!!     ",
      "        !!!     ",
      "         !      "
    ],
    [
      "         (((''''",
      "       (((((''''",
      "      ((((((''''",
      "      ((((((''3'",
      "      ((((((''3'",
      "       (((((''''",
      "       (((  ''''",
      "            '56'",
      "            '56'",
      "           -'56-",
      "          --'78 ",
      "         ---!78 ",
      "        ----!   ",
      "        ---!    ",
      "        !--     ",
      "         !      "
    ]
  ]
}