{
  "xsize": 16,
  "zsize": 16,
  "refpalette": "lostcities:base",
  "slices": [
    [
      "  Ͷ   Ͷ !!!!    ",
      "   Ͷ Ͷ  !!!     ",
      "   Ͷ Ͷ          ",
      "   Ͷ Ͷ          ",
      "   Ͷ Ͷ      Ͷ   ",
      "  Ͷ   Ͷ    Ͷ    ",
      "ͶͶ     ͶͶͶͶ     ",
      " ͶͶͶͶͶͶ         ",
      "Ͷ      ͶͶ       ",
      "         Ͷ      ",
      "          Ͷ     ",
      "           Ͷ    ",
      "           Ͷ    ",
      "           !Ͷ   ",
      "          !!Ͷ!  ",
      "          !!Ͷ!  "
    ],
    [
      "ggg   ggggg!    ",
      "gggg gggggg     ",
      "gggg ggggggg    ",
      "gggg ggggggg    ",
      "gggg gggggggg   ",
      "ggg   gggggg    ",
      "gg     gggg     ",
      " ͶͶͶͶͶͶ         ",
      "Ͷ      ͶͶ       ",
      "         Ͷ      ",
      "          Ͷ     ",
      "           Ͷ    ",
      "           Ͷ    ",
      "            Ͷ   ",
      "           !Ͷ!  ",
      "           !Ͷ!  "
    ],
    [
      "ggg   ggggg!!   ",
      "gggg gggggg!    ",
      "gggg ggggggg    ",
      "gggg ggggggg    ",
      "gggg gggggggg   ",
      "ggg   gggggg    ",
      "gg     gggg     ",
      " ͶͶͶͶͶͶ         ",
      "Ͷ      ͶͶ       ",
      "         Ͷ      ",
      "          Ͷ     ",
      "           Ͷ    ",
      "           Ͷ    ",
      "                ",
      "            !   ",
      "            !   "
    ],
    [
      "ggg   ggggg!!   ",
      "gggg gggggg!    ",
      "gggg ggggggg    ",
      "gggg ggggggg    ",
      "gggg gggggggg   ",
      "ggg   gggggg    ",
      "gg     gggg     ",
      " ͶͶͶͶͶͶ         ",
      "Ͷ      ͶͶ       ",
      "         Ͷ      ",
      "          Ͷ     ",
      "           Ͷ    ",
      "                ",
      "                ",
      "                ",
      "                "
    ],
    [
      " gg   gg !g!    ",
      "  g   g   !     ",
      "   g g          ",
      "   g g      g   ",
      "  g   g    g    ",
      " gg   gg  gg    ",
      "g       gg      ",
      " ͶͶͶͶͶͶ         ",
      "Ͷ      ͶͶ       ",
      "         Ͷ      ",
      "          Ͷ     ",
      "                ",
      "                ",
      "                ",
      "                ",
      "                "
    ],
    [
      "gg     gggg!    ",
      "  g   g   !g    ",
      "  g   g    g    ",
      "  g   g    g    ",
      "  g   g    g    ",
      "gg     gggg     ",
      "                ",
      " ͶͶͶͶͶͶ         ",
      "Ͷ      ͶͶ       ",
      "         Ͷ      ",
      "          Ͷ     ",
      "                ",
      "                ",
      "                ",
      "                ",
      "                "
    ]
  ]
}