{
  "xsize": 16,
  "zsize": 16,
  "refpalette": "pomkotsmechs:base",
  "slices": [
    [
      "                ",
      "                ",
      "                ",
      "                ",
      "                ",
      "      ͲͲ   ͲͲ   ",
      "     Ͳ  Ͳ Ͳ  Ͳ Ͳ",
      "     Ͳ  Ͳ Ͳ  Ͳ Ͳ",
      "      ͲͲ   ͲͲ   ",
      "                ",
      "      ͲͲ   ͲͲ   ",
      "     Ͳ  Ͳ Ͳ  Ͳ Ͳ",
      "     Ͳ  Ͳ Ͳ  Ͳ Ͳ",
      "      ͲͲ   ͲͲ   ",
      "                ",
      "                "
    ],
    [
      "                ",
      "                ",
      "                ",
      "                ",
      "                ",
      "      ͲͲ   ͲͲ   ",
      "     Ͳ  Ͳ Ͳ  Ͳ Ͳ",
      "     Ͳ  Ͳ Ͳ  Ͳ Ͳ",
      "      ͲͲ   ͲͲ   ",
      "                ",
      "      ͲͲ   ͲͲ   ",
      "     Ͳ  Ͳ Ͳ  Ͳ Ͳ",
      "     Ͳ  Ͳ Ͳ  Ͳ Ͳ",
      "      ͲͲ   ͲͲ   ",
      "                ",
      "                "
    ],
    [
      "                ",
      "                ",
      "                ",
      "                ",
      "                ",
      "      ͲͲ   ͲͲ   ",
      "     Ͳ  Ͳ Ͳ  Ͳ Ͳ",
      "     Ͳ  Ͳ Ͳ  Ͳ  ",
      "      ͲͲ   ͲͲ   ",
      "                ",
      "      ͲͲ   ͲͲ  !",
      "     Ͳ  Ͳ Ͳ  Ͳ!Ͳ",
      "     Ͳ  Ͳ Ͳ  Ͳ Ͳ",
      "      ͲͲ   ͲͲ   ",
      "                ",
      "                "
    ],
    [
      "                ",
      "                ",
      "                ",
      "                ",
      "                ",
      "      ͲͲ   ͲͲ   ",
      "     Ͳ  Ͳ Ͳ  Ͳ  ",
      "     Ͳ  Ͳ Ͳ  Ͳ  ",
      "      ͲͲ   ͲͲ   ",
      "                ",
      "      ͲͲ   ͲͲ !!",
      "     Ͳ  Ͳ Ͳ  Ͳ!Ͳ",
      "     Ͳ  Ͳ Ͳ  Ͳ!Ͳ",
      "      ͲͲ   ͲͲ  !",
      "                ",
      "                "
    ],
    [
      "                ",
      "                ",
      "                ",
      "                ",
      "                ",
      "      ͲͲ   ͲͲ   ",
      "     Ͳ  Ͳ Ͳ  Ͳ  ",
      "     Ͳ  Ͳ Ͳ  Ͳ  ",
      "      ͲͲ   ͲͲ   ",
      "                ",
      "      ͲͲ   ͲͲ !!",
      "     Ͳ  Ͳ Ͳ  Ͳ!Ͳ",
      "     Ͳ  Ͳ Ͳ !Ͳ!Ͳ",
      "      ͲͲ   ͲͲ!!!",
      "               !",
      "                "
    ],
    [
      "                ",
      "                ",
      "                ",
      "                ",
      "                ",
      "      gg   gg   ",
      "     gggg ggg   ",
      "     gggg ggg   ",
      "      gg   gg   ",
      "                ",
      "      gg   gg   ",
      "     gggg gggg!g",
      "     gggg gggg!g",
      "      gg   gg! !",
      "                ",
      "                "
    ]
  ]
}