{
  "xsize": 16,
  "zsize": 16,
  "refpalette": "lostcities:base",
  "slices": [
    [
      "             ggg",
      "             ggg",
      "             ggg",
      "             ggg",
      "              g!",
      "             !g!",
      "            !!!!",
      "           !!gg ",
      "           !!gg ",
      "           !!gg ",
      " hi        !!gg ",
      " jk        !!gg ",
      "           !!ggg",
      "gggggggggggggggg",
      "gggggggggggggggg",
      "gg  g    ggggggn"
    ],
    [
      "             ggg",
      "             ggg",
      "             ggg",
      "             ggg",
      "             ggg",
      "             gg!",
      "             gg ",
      "            !gg ",
      "            !gg ",
      "           !!gg ",
      " hi        !!gg ",
      " jk        !!gg ",
      "          !!!ggg",
      "gggggggggggggggg",
      "gggggggggggggggg",
      "gg  g    ggggggg"
    ],
    [
      "              g ",
      "             ggg",
      "             !r!",
      "             !r!",
      "              r!",
      "              r ",
      "              r ",
      "              r ",
      "                ",
      "           !!   ",
      " hi       !!!!  ",
      " jk       !!!gg ",
      "           !!ggg",
      "gg  ggg   g!g g ",
      "ggggggqqqqqqqqg ",
      "gg  gg     !! gg"
    ],
    [
      "               !",
      "             ggg",
      "             !!!",
      "              !!",
      "                ",
      "                ",
      "                ",
      "                ",
      "                ",
      "                ",
      " ff        !!   ",
      " ff       !!!ggg",
      "          !!!ggg",
      "gg  ggg   g!g g ",
      "gg  gg    !!  g ",
      "gg  gg        g "
    ],
    [
      " ff            !",
      " ff          ggg",
      " ff          f!!",
      " ff          f  ",
      " ff          f  ",
      " ff          f  ",
      " ff          f  ",
      " ff          f  ",
      " ff          f  ",
      "ffffffffffffff  ",
      "fxxfffffffffff  ",
      "fxxffffffffffggg",
      "ffff      !! ggg",
      "ggffgggfffgfgfg ",
      "gg  gg   !!!  g ",
      "gg  gg    !   g "
    ],
    [
      "gggggͱͱͱͱͱͱͱgggg",
      "gggggͱͱͱͱͱͱͱgggg",
      "gggggͱͱͱͱͱͱͱgggg",
      "gggggͱͱͱͱͱͱͱgggg",
      "gggggͱͱͱͱͱͱͱgggg",
      "gggggͱͱͱͱͱͱͱgggg",
      "gggggͱͱͱͱͱͱͱgggg",
      "gggggͱͱͱͱͱͱͱgggg",
      "gggggͱͱͱͱͱͱͱgggg",
      "gggggggggggggggg",
      "gggggggggggggggg",
      "gggggggggggggggg",
      "gggggggggggggggg",
      "gggggggggggggggg",
      "gggggggggggggggg",
      "gggggggggggggggg"
    ]
  ]
}