{
  "xsize": 16,
  "zsize": 16,
  "refpalette": "pomkotsmechs:base",
  "slices": [
    [
      "gg       g      ",
      "gYYYYYYYYY      ",
      "gYYYYYYYYY      ",
      "gYYYYYYYYY      ",
      "gggggggggg      ",
      " YYYYYY!!!      ",
      " YYYYYY!!!!     ",
      " YYYYYY !!      ",
      " YYYYYYYY       ",
      " YYYYYYYYY      ",
      " YYYYYYYYY      ",
      "ggggggggggg     ",
      "gYYYYYYYYYg     ",
      "gYYYYYYYYYg     ",
      "gYY  !YYYY      ",
      "gg       g      "
    ],
    [
      "gggg    gg      ",
      "gYYYYYYYYY      ",
      "gYYYYYYYYY      ",
      "gYYYYYYYYY      ",
      "ggggggggg       ",
      " YYYYYY!!!!     ",
      " YYYYYY!!!!!    ",
      " YYYYYY !!!     ",
      " YYYYYYY        ",
      " YYYYYYYYY      ",
      " YYYYYYYYY      ",
      "ggggggggggg     ",
      "gYYYYYYYYYg     ",
      "gYYYYYYYYYg     ",
      "gYYY !YYYY      ",
      "ggg     gg      "
    ],
    [
      "ggggg   g       ",
      "gYYYYYYYY       ",
      "gYYYYYYYYg      ",
      "gYYYYYYYYg      ",
      "gggggggg        ",
      " YYYYYY!!!!     ",
      " YYYYYY!!!!!    ",
      " YYYYYY !!!!    ",
      " YYYYYY   !     ",
      " YYYYYYYY       ",
      " YYYYYYYY       ",
      "ggggggggggg     ",
      "gYYYYYYYYgg     ",
      "gYYYYYYYYgg     ",
      "gYYY ! YY       ",
      "ggg     g       "
    ],
    [
      "g  gggg g       ",
      "gYYYYYYYY       ",
      "gYYYYYYYY       ",
      "gYYYYYYYY       ",
      "gggggggg        ",
      " YYYYYYY !      ",
      " YYYYYY!!!!     ",
      " YYYYYY  !!!    ",
      " YYYYYY   !     ",
      " YYYYYYYY       ",
      " YYYYYYYY       ",
      "gggggggggg      ",
      "gYYYYYYYYg      ",
      "gYYYYYYYYg      ",
      "gYYYY!Y Y       ",
      "g       g       "
    ],
    [
      "g    gggg       ",
      "gYYYYYYYY       ",
      "gYYYYYYYY       ",
      "gYYYYYYYY       ",
      "gggggggg        ",
      " YYYYYYY !      ",
      " YYYYYY!!!!     ",
      " YYYYYY!!!!!    ",
      " YYYYYY  !g     ",
      " YYYYYYYY g     ",
      " YYYYYYYY g     ",
      "ggggggggggg     ",
      "gYYYYYYYYgg     ",
      "gYYYYYYYYg      ",
      "gYY  !YYY       ",
      "g       g       "
    ],
    [
      "g     ggg       ",
      "gYYYYYYYY       ",
      "gYYYYYYYY       ",
      "gYYYYYYYY       ",
      "ggggggggg       ",
      " YYYYYY         ",
      " YYYYYY! !!     ",
      " YYYYYY!!!g!    ",
      " YYYYYYYY!g!    ",
      " YYYYYYYY g     ",
      " YYYYYYYY g     ",
      "ggggggggggg     ",
      "gYYYYYYYYgg     ",
      "gYYYYYYYYg      ",
      "gYY  ! YY       ",
      "g       g       "
    ]
  ]
}