{
  "xsize": 16,
  "zsize": 16,
  "refpalette": "pomkotsmechs:base",
  "slices": [
    [
      "ggggggggggg     ",
      "ggggggggggggggg ",
      "gggggggggggggggg",
      "gggggggggggggggg",
      "gggggggggggggggg",
      "gggggggggggggggg",
      "gggggggggggggggg",
      "gggggggggggggggg",
      "gggggggggggggggg",
      "gggggggggggggggg",
      "gggggggggggggggg",
      "gggggggggggggggg",
      "gggggggggggggggg",
      "gggggggggggggggg",
      "gggggggggggggggg",
      "gggggggggggggggg"
    ],
    [
      " g              ",
      "g               ",
      "gYYYYYYYYYYYYYYg",
      " g            g ",
      "                ",
      "                ",
      "                ",
      "                ",
      "                ",
      "                ",
      "      !!        ",
      "    !!!         ",
      "   !!           ",
      " !!!            ",
      "!g            g ",
      "g              g"
    ],
    [
      "                ",
      "g              g",
      "gYYYYYYYYYYYYYYg",
      "                ",
      "                ",
      "                ",
      "                ",
      "                ",
      "                ",
      "                ",
      "                ",
      "                ",
      "                ",
      "                ",
      "                ",
      "g              g"
    ],
    [
      "                ",
      "g              g",
      "gYYYYYYYYYYYYYYg",
      "                ",
      "                ",
      "                ",
      "                ",
      "                ",
      "                ",
      "                ",
      "                ",
      "                ",
      "                ",
      "                ",
      "                ",
      "g              g"
    ],
    [
      "                ",
      "g              g",
      "gYYYYYYYYYYYYY g",
      "                ",
      "                ",
      "                ",
      "                ",
      "                ",
      "                ",
      "                ",
      "                ",
      "                ",
      "                ",
      "                ",
      "                ",
      "g              g"
    ],
    [
      "                ",
      "g              g",
      "gYYYYYYYYYYYYY g",
      "                ",
      "                ",
      "                ",
      "                ",
      "                ",
      "                ",
      "                ",
      "                ",
      "                ",
      "                ",
      "                ",
      "                ",
      "g              g"
    ]
  ]
}