{
  "xsize": 16,
  "zsize": 16,
  "refpalette": "pomkotsmechs:base",
  "slices": [
    [
      "Ͷ        ͶYͶ    ",
      "Ͷ        ͶYͶ    ",
      " Ͷ      ͶYYͶ    ",
      " ͶͶ    ͶͶY  Ͷ   ",
      "   ͶͶͶͶYYY  Ͷ!  ",
      "            !Ͷ! ",
      "             !Ͷ ",
      "               Ͷ",
      "                ",
      "              ͶͶ",
      "             Ͷ  ",
      "            Ͷ   ",
      "            Ͷ   ",
      "            Ͷ   ",
      "            Ͷ   ",
      "             Ͷ  "
    ],
    [
      "Ͷ        ͶYͶ    ",
      "Ͷ        ͶYͶ    ",
      " Ͷ      ͶYYͶ    ",
      " ͶͶ    ͶͶY  Ͷ   ",
      "   ͶͶͶͶYYY !Ͷ!  ",
      "      ggg  !!Ͷ! ",
      "      ggg   !!Ͷ ",
      "      ggg      Ͷ",
      "      ggg       ",
      "      ggg     ͶͶ",
      "      ggg    Ͷ  ",
      "      ggg   Ͷ   ",
      "      ggg   Ͷ   ",
      "      ggg   Ͷ   ",
      "      ggg   Ͷ   ",
      "      ggg    Ͷ  "
    ],
    [
      "Ͷ        ͶYͶ    ",
      "Ͷ        ͶYͶ    ",
      " Ͷ      ͶYYͶ    ",
      " ͶͶ    ͶͶY  Ͷ   ",
      "   ͶͶͶͶYYY !Ͷ!  ",
      "            !Ͷ  ",
      "              Ͷ ",
      "               Ͷ",
      "                ",
      "              ͶͶ",
      "             Ͷ  ",
      "            Ͷ   ",
      "            Ͷ   ",
      "            Ͷ   ",
      "            Ͷ   ",
      "             Ͷ  "
    ],
    [
      "Ͷ        ͶYͶ    ",
      "Ͷ        ͶYͶ    ",
      " Ͷ      ͶY Ͷ    ",
      " ͶͶ    ͶͶY  Ͷ   ",
      "   ͶͶͶͶ Y  !Ͷ!  ",
      "            !Ͷ  ",
      "              Ͷ ",
      "               Ͷ",
      "                ",
      "              ͶͶ",
      "             Ͷ  ",
      "            Ͷ   ",
      "            Ͷ   ",
      "            Ͷ   ",
      "            Ͷ   ",
      "             Ͷ  "
    ],
    [
      "ͶͶͶ    ͶͶͶYͶ    ",
      "ͶͶ     ͶͶͶYͶ    ",
      " ͶͶͶͶͶͶͶͶY Ͷ    ",
      "  ͶͶͶͶͶͶY   Ͷ   ",
      "    ͶͶ     !Ͷ!  ",
      "            !Ͷ  ",
      "              Ͷ ",
      "               Ͷ",
      "                ",
      "              ͶͶ",
      "             Ͷ  ",
      "            Ͷ   ",
      "            Ͷ   ",
      "            Ͷ   ",
      "            Ͷ   ",
      "             Ͷ  "
    ],
    [
      " ͶͶͶͶͶͶͶͶͶYͶ    ",
      " Ͷ ͶͶͶͶͶͶͶYͶ    ",
      " ͱͶͶͶͶͶͶͶY Ͷ    ",
      "   ͶͶͶͶͶY  !Ͷ   ",
      "           !Ͷ!  ",
      "            !Ͷ  ",
      "              Ͷ ",
      "               Ͷ",
      "                ",
      "              ͶͶ",
      "             Ͷ  ",
      "            Ͷ   ",
      "            Ͷ   ",
      "            Ͷ   ",
      "            Ͷ   ",
      "             Ͷ  "
    ]
  ]
}