{
  "xsize": 16,
  "zsize": 16,
  "refpalette": "pomkotsmechs:base",
  "slices": [
    [
      "vvvvvvvvvvvvvvvv",
      "vvvvvvvvvvvvvvvv",
      "vvvvvvvvvvvvvvvv",
      "vvvvvvvvvvvvvvvv",
      "vvvvvvvvvvvvvvvv",
      "vvvvvvvvvvvvvvvv",
      "vvvvvvvvvvvvvvvv",
      "vvvvvvvvvvvvvvvv",
      "vvvvvvvvvvvvvvvv",
      "vvvvvvvvvvvvvvvv",
      "vvvvvvvvvvvvvvvv",
      "vvvvvvvvvvvvvvvv",
      "vvvvvvvvvvvvvvvv",
      "vvvvvvvvvvvvvvvv",
      "vvvvvvvvvvvvvvvv",
      "vvvvvvvvvvvvvvvv"
    ],
    [
      "gʹ  ʹ      ʹ  ʹg",
      " ffffffffffffff ",
      " ffffffffffffff ",
      " ffffffffffffff ",
      " ffffffffffffff ",
      " ffffffffffffff ",
      " ffffffffffffff ",
      " ffffffffffffff ",
      " ffffffffffffff ",
      " ffffffffffffff ",
      " ffffffffffffff ",
      " ffffffffffffff ",
      " ffffffffffffff ",
      " ffffffffffffff ",
      " ffffffffffffff ",
      "g              g"
    ],
    [
      "gʹʹʹʹ      ʹʹʹʹg",
      "ʹffff      ffffʹ",
      "ʹf            fʹ",
      "ʹf            fʹ",
      "ʹf            fʹ",
      "ʹf            fʹ",
      "ʹf            fʹ",
      "ʹf            fʹ",
      "ʹf        ʹʹ  fʹ",
      "ʹf        ʹʹ  fʹ",
      "ʹf            fʹ",
      "ʹf            fʹ",
      "ʹf            fʹ",
      "ʹf            fʹ",
      "ʹffffffffffffffʹ",
      "gʹʹʹʹʹʹʹʹʹʹʹʹʹ g"
    ],
    [
      "g              g",
      " f  f      f  f ",
      "                ",
      "                ",
      " f            f ",
      "                ",
      "                ",
      " f            f ",
      " f            f ",
      "          ʹʹ    ",
      "          ʹʹ    ",
      " f            f ",
      "                ",
      "                ",
      " f  f  ff  f  f ",
      "g              g"
    ],
    [
      "g              g",
      " f  f      f  f ",
      "                ",
      "                ",
      " f            f ",
      "                ",
      "                ",
      " f            f ",
      " f            f ",
      "                ",
      "          ʹʹ    ",
      " f        ʹʹ  f ",
      "                ",
      "    !           ",
      " f !f! ff  f  f ",
      "g   !          g"
    ],
    [
      "g              g",
      " ffffffff  ffff ",
      " f            f!",
      " f           !f ",
      " f            f ",
      " f            f ",
      " f            f ",
      " f            f ",
      " f            f ",
      " f            f ",
      " f            f ",
      " f        ʹʹ  f ",
      " f            f ",
      " f !!         f ",
      " ffff! ffffffff ",
      "g  !!          g"
    ]
  ]
}