{
  "xsize": 16,
  "zsize": 16,
  "refpalette": "lostcities:base",
  "slices": [
    [
      "                ",
      "        !!      ",
      "fffffffffff!    ",
      "        !!!fff  ",
      "           ! f  ",
      "             f  ",
      "             f  ",
      "             f  ",
      "             f  ",
      "   !         f  ",
      "             f  ",
      "           !!f  ",
      "          !fff  ",
      " ffffffffff!!   ",
      "                ",
      "                "
    ],
    [
      "                ",
      "         !!!    ",
      "ffffff  !ff!!   ",
      "         !!ff   ",
      "           !f   ",
      "           !f   ",
      "            f   ",
      "            f   ",
      "            f   ",
      "   !        f   ",
      "   !        f   ",
      "           !f   ",
      "          !ff   ",
      "  fffffffff!    ",
      "                ",
      "                "
    ],
    [
      "                ",
      "          !     ",
      "fffff    ff!    ",
      "          !f!   ",
      "          !f!   ",
      "          !f!   ",
      "        !!!f    ",
      "        !  f    ",
      "   !!!!!!  f    ",
      "   !    !! f    ",
      "   !     ! f    ",
      "         !!f    ",
      "         !!f!   ",
      "  fffffffff!    ",
      "          !     ",
      "                "
    ],
    [
      "                ",
      "                ",
      "fffff    ff     ",
      "fffff    ff!    ",
      "fffff   fff!    ",
      "fffffffffff!!   ",
      "fffffffffff!    ",
      "fffffffffff     ",
      " ffffffffff     ",
      "  fffffffff     ",
      "   ffffffff     ",
      "   ffffffff     ",
      "  fffffffff!    ",
      "  fffffffff!    ",
      "         !!     ",
      "                "
    ],
    [
      "                ",
      "                ",
      "                ",
      "                ",
      "                ",
      "          !!    ",
      "        !!!     ",
      "        !       ",
      "                ",
      "                ",
      "                ",
      "                ",
      "                ",
      "          !     ",
      "                ",
      "                "
    ],
    [
      "                ",
      "                ",
      "                ",
      "                ",
      "                ",
      "                ",
      "                ",
      "                ",
      "                ",
      "                ",
      "                ",
      "                ",
      "                ",
      "                ",
      "                ",
      "                "
    ]
  ]
}