{
  "xsize": 16,
  "zsize": 16,
  "refpalette": "lostcities:base",
  "slices": [
    [
      "                ",
      "                ",
      "                ",
      "                ",
      "                ",
      "   g  g  g  g   ",
      "   gggg  gggg   ",
      "    gg    gg    ",
      "                ",
      "                ",
      "                ",
      "                ",
      "    gg    gg    ",
      "   gggg  gggg   ",
      "   g  g  g  g   ",
      "   g  g  g  g   "
    ],
    [
      "                ",
      "                ",
      "                ",
      "                ",
      "                ",
      "    gg    gg    ",
      "    gg    gg    ",
      "                ",
      "                ",
      "                ",
      "                ",
      "    gg    gg    ",
      "   g  g  g  g   ",
      "   g  g  g  g   ",
      "   g  g  g  g   ",
      "   gggg  gggg   "
    ],
    [
      "                ",
      "                ",
      "                ",
      "                ",
      "                ",
      "                ",
      "                ",
      "                ",
      "                ",
      "    gg    gg    ",
      "   gggg  gggg   ",
      "   g  g  g  g   ",
      "   g  g  g  g   ",
      "   g  g  g  g   ",
      "   gggg  gggg   ",
      "    gg    gg    "
    ],
    [
      "                ",
      "                ",
      "                ",
      "                ",
      "                ",
      "                ",
      "                ",
      "                ",
      "    gg    gg    ",
      "   gggg  gggg   ",
      "   g  g  g  g   ",
      "   g  g  g  g   ",
      "   g  g  g  g   ",
      "    gg    gg    ",
      "                ",
      "                "
    ],
    [
      "                ",
      "                ",
      "                ",
      "                ",
      "                ",
      "                ",
      "    gg    gg    ",
      "   gggg  gggg   ",
      "   g  g  g  g   ",
      "   g  g  g  g   ",
      "   g  g  g  g   ",
      "   gggg  gggg   ",
      "    gg    gg    ",
      "                ",
      "                ",
      "                "
    ],
    [
      "                ",
      "                ",
      "                ",
      "                ",
      "                ",
      "                ",
      "   g  g  g  g   ",
      "   g  g  g  g   ",
      "   g  g  g  g   ",
      "   g  g  g  g   ",
      "   gggg  gggg   ",
      "    gg    gg    ",
      "                ",
      "                ",
      "                ",
      "                "
    ]
  ]
}