{
  "xsize": 16,
  "zsize": 16,
  "refpalette": "pomkotsmechs:base",
  "slices": [
    [
      "  gg           g",
      "  YYYYYYYYYYYYYg",
      " gYYYYYYYYYYYYYg",
      " gYYYYYYYYYYYYYg",
      " ggggggggggggggg",
      "  YYYYYYYYYYYYY ",
      "  YYYYYYYYYYYYY ",
      "  YYYYYYYYYYYYY ",
      "  YYYYYYYYYYYYY ",
      "  YYYYYYYYYYYYY ",
      "  YYYYYYYYYYYYY ",
      " ggggggggggggggg",
      " gYYYYYYYYYYYYYg",
      " gYYYYYYYYYYYYYg",
      "  YYYY   YYYYYYg",
      "  gg           g"
    ],
    [
      "   g           g",
      "   YYYYYYYYYYYYg",
      " ggYYYYYYYYYYYYg",
      " ggYYYYYYYYYYYYg",
      " ggggggggggggggg",
      "   YYYYYYYYYYYY ",
      "   YYYYYYYYYYYY ",
      "   YYYYYYYYYYYY ",
      "   YYYYYYYYYYYY ",
      "   YYYYYYYYYYYY ",
      "   YYYYYYYYYYYY ",
      " ggggggggggggggg",
      " ggYYYYYYYYYYYYg",
      " ggYYYYYYYYYYYYg",
      "   YYY   YYYYYYg",
      "   g           g"
    ],
    [
      "   g           g",
      "   YYYYYYYYYYYYg",
      "  gYYYYYYYYYYYYg",
      "  gYYYYYYYYYYYYg",
      "  gggggggggggggg",
      "   YYYYYYYYYYYY ",
      "   YYYYYYYYYYYY ",
      "   YYYYYYYYYYYY ",
      "   YYYYYYYYYYYY ",
      "   YYYYYYYYYYYY ",
      "   YYYYYYYYYYYY ",
      "  gggggggggggggg",
      "  gYYYYYYYYYYYYg",
      "  gYYYYYYYYYYYYg",
      "   YYY   YYYYYYg",
      "   g           g"
    ],
    [
      "   g         ggg",
      "   YYYYYYYYYYYYg",
      "  gYYYYYYYYYYYYg",
      "  gYYYYYYYYYYYYg",
      "  gggggggggggggg",
      "   YYYYYYYYYYYY ",
      "   YYYYYYYYYYYY ",
      "   YYYYYYYYYYYY ",
      "   YYYYYYYYYYYY ",
      "   YYYYYYYYYYYY ",
      "   YYYYYYYYYYYY ",
      "  gggggggggggggg",
      "  gYYYYYYYYYYYYg",
      "  gYYYYYYYYYYYYg",
      "   YYY    YYYYYg",
      "   g         ggg"
    ],
    [
      "   g        gggg",
      "   YYYYYYYYYYYYg",
      "  gYYYYYYYYYYYYg",
      "  gYYYYYYYYYYYYg",
      "  gggggggggggggg",
      "   YYYYYYYYYYYY ",
      "   YYYYYYYYYYYY ",
      "   YYYYYYYYYYYY ",
      "   YYYYYYYYYYYY ",
      "   YYYYYYYYYYYY ",
      "   YYYYYYYYYYYY ",
      "  gggggggggggggg",
      "  gYYYYYYYYYYYYg",
      "  gYYYYYYYYYYYYg",
      "   YYYY   YYYYYg",
      "   g        gggg"
    ],
    [
      "   gg     gggg g",
      "   YYYYYYYYYYYYg",
      "  gYYYYYYYYYYYYg",
      "  gYYYYYYYYYYYYg",
      "  gggggggggggggg",
      "   YYYYYYYYYYYY ",
      "   YYYYYYYYYYYY ",
      "   YYYYYYYYYYYY ",
      "   YYYYYYYYYYYY ",
      "   YYYYYYYYYYYY ",
      "   YYYYYYYYYYYY ",
      "  gggggggggggggg",
      "  gYYYYYYYYYYYYg",
      "  gYYYYYYYYYYYYg",
      "   YYYY   YYYYYg",
      "   gg      ggg g"
    ]
  ]
}