{
  "xsize": 16,
  "zsize": 16,
  "refpalette": "lostcities:base",
  "slices": [
    [
      "              g ",
      "              g ",
      "              g ",
      "              g ",
      "              g ",
      "              g ",
      "              g ",
      "              g ",
      "              g ",
      "              g ",
      "              g ",
      "              g ",
      "              g ",
      "              g ",
      "              g ",
      "              g "
    ],
    [
      "              g ",
      "              g ",
      "              g ",
      "              g ",
      "              g ",
      "              g ",
      "         !!   g ",
      "          !!  g ",
      "              g ",
      "              g ",
      "              g ",
      "              g ",
      "              g ",
      "              g ",
      "              g ",
      "              g "
    ],
    [
      "ggggggggggggggg ",
      "ggggggggggggggg ",
      "ggggggggggggggg ",
      "ggggggggggggggg ",
      "ggggggggggggggg ",
      "ggggggggggggggg ",
      "ggggggggggggggg ",
      "ggggggggggggggg ",
      "ggggggggggggggg ",
      "ggggggggggggggg ",
      "ggggggggggggggg ",
      "ggggggggggggggg ",
      "ggggggggggggggg ",
      "ggggggggggggggg ",
      "ggggggggggggggg ",
      "ggggggggggggggg "
    ],
    [
      "  Y  Y  Y       ",
      "YY    YY        ",
      "         YY     ",
      "        Y  Y    ",
      "        Y !Y    ",
      "   YY    YY!    ",
      "  Y  Y  !!!!    ",
      "  Y  Y   !!!    ",
      "   YY           ",
      "                ",
      "  Y   Y    Y    ",
      " Y Y Y Y  Y Y   ",
      "  Y   Y    Y    ",
      "  Y   Y    Y    ",
      " Y Y Y Y  Y Y   ",
      "  Y   Y    Y    "
    ],
    [
      " YY  YY Y       ",
      "YY    YY        ",
      "         YY     ",
      "        YYYY    ",
      "        YY!Y    ",
      "   YY    YY!    ",
      "  YYYY   !!     ",
      "  Y YY          ",
      "   YY           ",
      "                ",
      "  Y   Y    Y    ",
      " Y Y Y Y  Y Y   ",
      "  Y   Y    Y    ",
      "  Y   Y    Y    ",
      " Y Y Y Y  Y Y   ",
      "  Y   Y    Y    "
    ],
    [
      "ggggggggggggg   ",
      "ggggggggggggg   ",
      "ggggggggggggg   ",
      "gggggggggggg    ",
      "gggggggggggg    ",
      "ggggggggggg!    ",
      "gggggggggg!     ",
      "ggggggggg       ",
      " gggggg         ",
      "gg     gggg     ",
      "ggg   gggggg    ",
      "gggg gggggggg   ",
      "gggg gggggggg   ",
      "gggg gggggggg   ",
      "gggg gggggggg   ",
      "ggg   gggggg    "
    ]
  ]
}