{
  "xsize": 16,
  "zsize": 16,
  "refpalette": "lostcities:base",
  "slices": [
    [
      "vvvvvvvvvvvvvvvv",
      "vvvvvvvvvvvvvvvv",
      "vvvvvvvvvvvvvvvv",
      "vvvvvvvvvvvvvvvv",
      "vvvvvvvvvvvvvvvv",
      "vvvvvvvvvvvvvvvv",
      "vvvvvvvvvvvvvvvv",
      "vvvvvvvvvvvvvvvv",
      "vvvvvvvvvvvvvvvv",
      "vvvvvvvvvvvvvvvv",
      "vvvvvvvvvvvvvvvv",
      "vvvvvvvvvvvvvvvv",
      "vvvvvvvvvvvvvvvv",
      "vvvvvvvvvvvvvvvv",
      "vvvvvvvvvvvvvvvv",
      "vvvvvvvvvvvvvvvv"
    ],
    [
      "gggggggggggggggg",
      "gYYYYYYYYYYYYYYg",
      "gYYYYYYYYYYYYYYg",
      "gYYYYYYYYYYYYYYg",
      "gggggggggggggggg",
      " YYYYYYYYYYYYYYg",
      " YYYYYYYYYYYYYYg",
      " YYYYYYYYYYYYYYg",
      " YYYYYYYYYYYYYYg",
      " YYYYYYYYYYYYYYg",
      " YYYYYYYYYYYYYYg",
      "gggggggggggggggg",
      "gYYYYYYYYYYYYYYg",
      "gYYYYYYYYYYYYYYg",
      "gYYYYYYYYYYYYYYg",
      "gggggggggggggggg"
    ],
    [
      "g             gg",
      "g             Yg",
      "ggggggggggggggYg",
      "ggggggggggggggYg",
      "gggggggggggggggg",
      "              Yg",
      "              Yg",
      "              Yg",
      "              Yg",
      "              Yg",
      "              Yg",
      "gggggggggggggggg",
      "ggggggggggggggYg",
      "ggggggggggggggYg",
      "g             Yg",
      "g             gg"
    ],
    [
      "ggggggggggggggg ",
      "gYYYYYYYYYYYYYY ",
      "gYYYYYYYYYYYYYYg",
      "gYYYYYYYYYYYYYYg",
      "gggggggggggggggg",
      " YYYYYYYYYYYYYY ",
      " YYYYYYYYYYYYYY ",
      " YYYYYYYYYYYYYY ",
      " YYYYYYYYYYYYYY ",
      " YYYYYYYYYYYYYY ",
      " YYYYYYYYYYYYYY ",
      "gggggggggggggggg",
      "gYYYYYYYYYYYYYYg",
      "gYYYYYYYYYYYYYYg",
      "gYYYYYYYYYYYYYY ",
      "ggggggggggggggg "
    ],
    [
      "g             g ",
      "gYYYYYYYYYYYYYY ",
      "gYYYYYYYYYYYYYYg",
      "gYYYYYYYYYYYYYYg",
      "gggggggggggggggg",
      " YYYYYYYYYYYYYY ",
      " YYYYYYYYYYYYYY ",
      " YYYYYYYYYYYYYY ",
      " YYYYYYYYYYYYYY ",
      " YYYYYYYYYYYYYY ",
      " YYYYYYYYYYYYYY ",
      "gggggggggggggggg",
      "gYYYYYYYYYYYYYYg",
      "gYYYYYYYYYYYYYYg",
      "gYYYYYYYYYYYYYY ",
      "g             g "
    ],
    [
      "g            gg ",
      "gYYYYYYYYYYYYYY ",
      "gYYYYYYYYYYYYYYg",
      "gYYYYYYYYYYYYYYg",
      "gggggggggggggggg",
      " YYYYYYYYYYYYYY ",
      " YYYYYYYYYYYYYY ",
      " YYYYYYYYYYYYYY ",
      " YYYYYYYYYYYYYY ",
      " YYYYYYYYYYYYYY ",
      " YYYYYYYYYYYYYY ",
      "gggggggggggggggg",
      "gYYYYYYYYYYYYYYg",
      "gYYYYYYYYYYYYYYg",
      "gYYYYYYYYYYYYYY ",
      "g            gg "
    ]
  ]
}