{
  "xsize": 16,
  "zsize": 16,
  "refpalette": "pomkotsmechs:base",
  "slices": [
    [
      "                ",
      "                ",
      "                ",
      "                ",
      "                ",
      "                ",
      "                ",
      "                ",
      "                ",
      "                ",
      "                ",
      "                ",
      "                ",
      "gggggggggggggggg",
      "gggggggggggggggg",
      "gggggggggggggggg"
    ],
    [
      "                ",
      "                ",
      "                ",
      "                ",
      "                ",
      "                ",
      "                ",
      "                ",
      "                ",
      "                ",
      "                ",
      "                ",
      "                ",
      "gggggggggggggggg",
      "gggggggggggggggg",
      "gggggggggggggggg"
    ],
    [
      "                ",
      "                ",
      "                ",
      "                ",
      "                ",
      "                ",
      "                ",
      "                ",
      "                ",
      "                ",
      "                ",
      "                ",
      "                ",
      "ggg g      g ggg",
      "gqqqqqqqqqqqqqqg",
      "g              g"
    ],
    [
      "                ",
      "                ",
      "                ",
      "                ",
      "                ",
      "                ",
      "                ",
      "                ",
      "                ",
      "                ",
      "                ",
      "                ",
      "                ",
      "ggg g      g ggg",
      "g              g",
      "g              g"
    ],
    [
      "                ",
      "                ",
      "                ",
      "                ",
      "                ",
      "                ",
      "                ",
      "                ",
      "                ",
      "                ",
      "ffffffffffffffff",
      "ffffffffffffffff",
      "                ",
      "fggffffffffffggf",
      "g              g",
      "g              g"
    ],
    [
      "gͱͱͱͱͱͱͱͱͱͱͱͱͱͱg",
      "gͱͱͱͱͱͱͱͱͱͱͱͱͱͱg",
      "gͱͱͱͱͱͱͱͱͱͱͱͱͱͱg",
      "gͱͱͱͱͱͱͱͱͱͱͱͱͱͱg",
      "gͱͱͱͱͱͱͱͱͱͱͱͱͱͱg",
      "gͱͱͱͱͱͱͱͱͱͱͱͱͱͱg",
      "gͱͱͱͱͱͱͱͱͱͱͱͱͱͱg",
      "gͱͱͱͱͱͱͱͱͱͱͱͱͱͱg",
      "gͱͱͱͱͱͱͱͱͱͱͱͱͱͱg",
      "gggggggggggggggg",
      "gggggggggggggggg",
      "gggggggggggggggg",
      "gggggggggggggggg",
      "gggggggggggggggg",
      "gggggggggggggggg",
      "gggggggggggggggg"
    ]
  ]
}