{
  "xsize": 16,
  "zsize": 16,
  "refpalette": "lostcities:base",
  "slices": [
    [
      " gggggggggggggg ",
      " gggggggggggggg ",
      " gggggggggggggg ",
      " gggggggggggggg ",
      " gggggggggggggg ",
      " gggggggggggggg ",
      " gggggggggggggg ",
      " gggggggggggggg ",
      " gggggggggggggg ",
      " gggggggggggggg ",
      " gggggggggggggg ",
      " gggggggggggggg!",
      " gggggggggggggg ",
      " gggggggggggggg ",
      " gggggggggggggg ",
      "                "
    ],
    [
      "            !   ",
      "           !!   ",
      "          !!    ",
      "         !!!    ",
      "      !   !     ",
      "  Y  !!!     Y  ",
      "  Y  !!!     Y  ",
      " YY   !      YY ",
      " YY          YY ",
      " YY gg    gg YY ",
      " YYgggg  ggggYY!",
      "  Yg  g  g  gY!!",
      "  Yg  g  g  gY! ",
      " g            g ",
      " gg          gg ",
      "                "
    ],
    [
      "                ",
      "                ",
      "          !!    ",
      "         !!!!   ",
      "          !!    ",
      "  Y   !      Y  ",
      " YY  !!!     YY ",
      "  Y   !      Y  ",
      "  Y gg    gg Y  ",
      "  Ygggg  ggggY! ",
      "  Yg  g  g  gY!!",
      " YYg  g  g  gYY ",
      "  Ygggg  ggggY  ",
      " g            g ",
      " gg          gg ",
      "                "
    ],
    [
      "                ",
      "                ",
      "           !    ",
      "          !!!   ",
      "           !    ",
      "      !         ",
      " YY gg!!  gg YY ",
      " YYgggg! ggggYY ",
      " YYg  g  g  gYY ",
      " YYg  g  g  gYY ",
      " YYg  g  g  gYY!",
      " YYgggg  ggggYY ",
      "    gg    gg    ",
      "                ",
      "                ",
      "                "
    ],
    [
      "                ",
      "           !    ",
      "          !!!   ",
      "          !!!   ",
      "           !    ",
      "    gg    gg    ",
      " YYgggg  ggggYY ",
      "  Yg !g! g  gY  ",
      "  Yg  g  g  gY  ",
      "  Yg  g  g  gY! ",
      "  Y gg    gg!Y!!",
      " YY gg    gg YY ",
      "                ",
      "                ",
      "                ",
      "                "
    ],
    [
      "                ",
      "           !!   ",
      "          !!!!  ",
      "           !!   ",
      "    gg    gg    ",
      "   g  g  g  g   ",
      "   g  g  g  g   ",
      " YYg !g! g  gYY ",
      "  Ygggg  ggggY  ",
      "  Y gg    gg!Y! ",
      " YY          YY ",
      "                ",
      "                ",
      "                ",
      "                ",
      "                "
    ]
  ]
}