{
  "xsize": 16,
  "zsize": 16,
  "refpalette": "pomkotsmechs:base",
  "slices": [
    [
      "      ͳY      gg",
      "       Y        ",
      "                ",
      "                ",
      "                ",
      "ͲͲ     !        ",
      "  Ͳ   !g!       ",
      "  Ͳ    !  YY    ",
      "ͲͲ        YY    ",
      "                ",
      "ͲͲ              ",
      "  Ͳ             ",
      " !Ͳ             ",
      "ͲͲ!!            ",
      " !!             ",
      "       g        "
    ],
    [
      "      ͳY      ͶͶ",
      "       Y        ",
      "                ",
      "                ",
      "                ",
      "ͲͲ     !        ",
      "  Ͳ   !g!       ",
      "  Ͳ   !!!YY     ",
      "ͲͲ     ! YY     ",
      "                ",
      "ͲͲ              ",
      "  Ͳ             ",
      " !Ͳ             ",
      "ͲͲ!             ",
      " !              ",
      "       g        "
    ],
    [
      "      ͳY      ͶͶ",
      "       Y        ",
      "                ",
      "                ",
      "                ",
      "ͲͲ              ",
      "  Ͳ    g        ",
      "  Ͳ   !!YY      ",
      " Ͳ    !!YY      ",
      "       !!       ",
      "ͲͲ      !!      ",
      "! Ͳ      !      ",
      " !Ͳ             ",
      "ͲͲ!             ",
      " !              ",
      "       g        "
    ],
    [
      "      ͳY      ͶͶ",
      "       Y        ",
      "                ",
      "                ",
      "                ",
      " Ͳ              ",
      "  Ͳ    ggggggggg",
      "       gY    YYY",
      "      !gY    YYY",
      "      !gYYYYYYYY",
      "ͲͲ     gYYYYYYYY",
      "! Ͳ    gYYYYYYYY",
      "!!Ͳ    gYYYYYYYY",
      "ͲͲ!    gYYYYYYYY",
      "!!     gYYYYYYYY",
      "       ggggggggg"
    ],
    [
      "      ͳY      ͶͶ",
      "       Y        ",
      "                ",
      "                ",
      "                ",
      " Ͳ              ",
      "  Ͳ    g        ",
      "             YY ",
      "       !     YY ",
      "       !!       ",
      "ͲͲ      !!      ",
      "! Ͳ     !!!     ",
      "! Ͳ     !!      ",
      "ͲͲ              ",
      "!               ",
      "       g        "
    ],
    [
      "       Y      ͶͶ",
      "                ",
      "                ",
      "                ",
      "                ",
      "                ",
      " g     g        ",
      "            YY  ",
      "            YY  ",
      "                ",
      " g      !!      ",
      "ggg    !!!!     ",
      "ggg    !!!      ",
      "gg      !       ",
      "!               ",
      "       g        "
    ]
  ]
}