{
  "xsize": 16,
  "zsize": 16,
  "refpalette": "lostcities:base",
  "slices": [
    [
      "          f     ",
      "          f     ",
      "          f  ʹff",
      "         fffffʹʹ",
      "         ff  fʹʹ",
      "        !ff  fʹʹ",
      "       !!ff  ʹff",
      "        !ff     ",
      "         ff     ",
      "         ff    !",
      "         ff     ",
      "         ff     ",
      "         ff     ",
      "         fffffff",
      "         fffffff",
      "                "
    ],
    [
      "          f     ",
      "          f     ",
      "          f  ʹʹʹ",
      "         ffffʹʹʹ",
      "         ff  ʹʹʹ",
      "        !ff  ʹʹʹ",
      "       !!ff  ʹʹʹ",
      "        !ff     ",
      "         ff     ",
      "         ff    !",
      "         ff    !",
      "         ff     ",
      "         ff     ",
      "         fffffff",
      "         fffffff",
      "                "
    ],
    [
      "          f  !! ",
      "          f  !  ",
      "          f     ",
      "         !ffffff",
      "        !!f     ",
      "       !!!f!    ",
      "       !!!f!    ",
      "        !!!     ",
      "                ",
      "                ",
      "          f     ",
      "          f     ",
      "          f     ",
      "          ffffff",
      "          ffffff",
      "               !"
    ],
    [
      "          ffffff",
      "          ffffff",
      "          ffffff",
      "          ffffff",
      "         !ffffff",
      "        !!ffffff",
      "        !!ffffff",
      "          ! ffff",
      "                ",
      "                ",
      "          fffff ",
      "          ffffff",
      "          ffffff",
      "          ffffff",
      "          ffffff",
      "               !"
    ],
    [
      "             !! ",
      "            !!! ",
      "            !!! ",
      "           fffff",
      "           f    ",
      "          !f!   ",
      "          !f    ",
      "                ",
      "                ",
      "                ",
      "                ",
      "           f    ",
      "           f   !",
      "           f   !",
      "           fffff",
      "               !"
    ],
    [
      "                ",
      "            !!  ",
      "           !!!! ",
      "           fffff",
      "           f!  f",
      "          !f!  f",
      "           f   f",
      "               f",
      "                ",
      "                ",
      "                ",
      "           f   f",
      "           f   f",
      "           f   f",
      "           fffff",
      "               !"
    ]
  ]
}