{
  "xsize": 16,
  "zsize": 16,
  "refpalette": "pomkotsmechs:base",
  "slices": [
    [
      "                ",
      " ʹʹʹʹʹʹʹʹʹʹʹʹʹʹ ",
      " ʹʹʹʹʹʹʹʹʹʹʹʹʹʹ ",
      " ʹʹʹʹʹʹʹʹʹʹʹʹʹʹ ",
      " ʹʹʹʹʹʹʹʹʹʹʹʹʹʹ ",
      " ʹʹʹʹʹʹʹʹʹʹʹʹʹʹ ",
      " ʹʹʹʹʹʹʹʹʹʹʹʹʹʹ ",
      " ʹʹʹʹʹʹʹʹʹʹʹʹʹʹ!",
      " ʹʹʹʹʹʹʹʹʹʹʹʹʹʹ ",
      " ʹʹʹʹʹʹʹʹʹʹʹʹʹʹ ",
      " ʹʹʹʹʹʹʹʹʹʹʹʹʹʹ ",
      "     !ʹʹʹʹʹʹʹʹʹ ",
      "       ʹʹʹʹʹʹʹʹ ",
      "      ʹʹʹʹʹʹʹʹʹ ",
      "     ʹʹʹʹʹʹʹʹʹʹ ",
      "                "
    ],
    [
      "                ",
      " fppppppppppppf ",
      " z            z ",
      " z            z ",
      " z            z ",
      " z            z ",
      " z            z ",
      " z     ʹʹ    !z!",
      " z    !ʹʹ    !z ",
      " z   !!       z ",
      " z   !        z ",
      "              z ",
      "              z ",
      "              z ",
      "    ppppppppppf ",
      "                "
    ],
    [
      "                ",
      "              Y ",
      "                ",
      "                ",
      "                ",
      "                ",
      "                ",
      "       ʹʹ     ! ",
      "       ʹʹ       ",
      "                ",
      "                ",
      "                ",
      "                ",
      "                ",
      "                ",
      "                "
    ],
    [
      "                ",
      "              Y ",
      "                ",
      "                ",
      "                ",
      "                ",
      "                ",
      "       ʹʹ       ",
      "       ʹʹ       ",
      "                ",
      "                ",
      "                ",
      "                ",
      "                ",
      "                ",
      "                "
    ],
    [
      "                ",
      "              Y ",
      "                ",
      "                ",
      "                ",
      "                ",
      "                ",
      "       ʹʹ       ",
      "       ʹʹ       ",
      "                ",
      "                ",
      "                ",
      "                ",
      "                ",
      "                ",
      "                "
    ],
    [
      "                ",
      "              Y ",
      "                ",
      "                ",
      "                ",
      "                ",
      "                ",
      "       ʹʹ       ",
      "       ʹʹ       ",
      "                ",
      "                ",
      "                ",
      "                ",
      "                ",
      "                ",
      "                "
    ]
  ]
}