{
  "xsize": 16,
  "zsize": 16,
  "refpalette": "lostcities:base",
  "slices": [
    [
      "vvvvvvvvvvvvvvvv",
      "vvvvvvvvvvvvvvvv",
      "vvvvvvvvvvvvvvvv",
      "vvvvvvvvvvvvvvvv",
      "vvvvvvvvvvvvvvvv",
      "vvvvvvvvvvvvvvvv",
      "vvvvvvvvvvvvvvvv",
      "vvvvvvvvvvvvvvvv",
      "vvvvvvvvvvvvvvvv",
      "vvvvvvvvvvvvvvvv",
      "vvvvvvvvvvvvvvvv",
      "vvvvvvvvvvvvvvvv",
      "vvvvvvvvvvvvvvvv",
      "vvvvvvvvvvvvvvvv",
      "vvvvvvvvvvvvvvvv",
      "vvvvvvvvvvvvvvvv"
    ],
    [
      "                ",
      "                ",
      "                ",
      "                ",
      "                ",
      "                ",
      "                ",
      "                ",
      "!!              ",
      "!               ",
      "                ",
      "                ",
      "   !!           ",
      "  !!            ",
      " !!             ",
      "!!              "
    ],
    [
      "                ",
      "                ",
      "                ",
      "                ",
      "                ",
      "                ",
      "                ",
      "                ",
      "!               ",
      "!               ",
      "                ",
      "                ",
      "                ",
      "                ",
      "!!              ",
      "!!              "
    ],
    [
      "                ",
      "                ",
      "                ",
      "                ",
      "                ",
      "                ",
      "                ",
      "                ",
      "!               ",
      "!               ",
      "                ",
      "                ",
      "                ",
      "!!              ",
      "!!!             ",
      "!!              "
    ],
    [
      "                ",
      "                ",
      "                ",
      "                ",
      "                ",
      "                ",
      "(               ",
      "(               ",
      "(               ",
      "(               ",
      "(               ",
      "()              ",
      "(*              ",
      "('!             ",
      "('!             ",
      "('              "
    ],
    [
      "                ",
      "                ",
      "                ",
      ",               ",
      "'               ",
      "'               ",
      "'               ",
      "'               ",
      "'9              ",
      "'(              ",
      "'*              ",
      "'*              ",
      "''!             ",
      "''-!            ",
      "'''             ",
      "'''(            "
    ]
  ]
}