{
  "xsize": 16,
  "zsize": 16,
  "refpalette": "pomkotsmechs:base",
  "slices": [
    [
      "       Y     Ͷ  ",
      "      ͶY    Ͷ   ",
      "      ͶY    Ͷ   ",
      "      ͶY    Ͷ   ",
      "      ͶY    Ͷ   ",
      "      ͶY     Ͷ  ",
      "     !ͶY      ͶͶ",
      "      ͶY        ",
      "      ͶY       Ͷ",
      "      ͶY      Ͷ ",
      "      ͶY     Ͷ  ",
      "   ͶͶͶͶYYY  Ͷ   ",
      " ͶͶ    ͶͶY  Ͷ   ",
      " Ͷ      ͶYYͶ    ",
      "Ͷ        ͶYͶ    ",
      "Ͷ        ͶYͶ    "
    ],
    [
      "             Ͷ  ",
      "       Y    Ͷ   ",
      "      ͶY    Ͷ   ",
      "      ͶY    Ͷ   ",
      "      ͶY    Ͷ   ",
      "      ͶY     Ͷ  ",
      "     !ͶY      ͶͶ",
      "      ͶY        ",
      "      ͶY       Ͷ",
      "      ͶY      Ͷ ",
      "      ͶY     Ͷ  ",
      "   ͶͶͶͶYYY  Ͷ   ",
      " ͶͶ    ͶͶY  Ͷ   ",
      " Ͷ      ͶYYͶ    ",
      "Ͷ        ͶYͶ    ",
      "Ͷ        ͶYͶ    "
    ],
    [
      "             Ͷ  ",
      "       Y    Ͷ   ",
      "      ͶY    Ͷ   ",
      "      ͶY    Ͷ   ",
      "      ͶY    Ͷ   ",
      "      ͶY     Ͷ  ",
      "     !ͶY      ͶͶ",
      "      ͶY        ",
      "      ͶY       Ͷ",
      "      ͶY      Ͷ ",
      "      ͶY     Ͷ  ",
      "   ͶͶͶͶYYY  Ͷ   ",
      " ͶͶ    ͶͶY  Ͷ   ",
      " Ͷ      ͶYYͶ    ",
      "Ͷ        ͶYͶ    ",
      "Ͷ        ͶYͶ    "
    ],
    [
      "             Ͷ  ",
      "            Ͷ   ",
      "       Y    Ͷ   ",
      "      ͶY    Ͷ   ",
      "      ͶY    Ͷ   ",
      "      ͶY     Ͷ  ",
      "     !ͶY      ͶͶ",
      "      ͶY        ",
      "      ͶY       Ͷ",
      "      ͶY      Ͷ ",
      "      ͶY     Ͷ  ",
      "   ͶͶͶͶYYY  Ͷ   ",
      " ͶͶ    ͶͶY  Ͷ   ",
      " Ͷ      ͶYYͶ    ",
      "Ͷ        ͶYͶ    ",
      "Ͷ        ͶYͶ    "
    ],
    [
      "             Ͷ  ",
      "            Ͷ   ",
      "       Y    Ͷ   ",
      "      ͶY    Ͷ   ",
      "      ͶY    Ͷ   ",
      "      ͶY     Ͷ  ",
      "     !ͶY      ͶͶ",
      "     !ͶY        ",
      "      ͶY       Ͷ",
      "      ͶY      Ͷ ",
      "      ͶY     Ͷ  ",
      "   ͶͶͶͶYYY  Ͷ   ",
      " ͶͶ    ͶͶY  Ͷ   ",
      " Ͷ      ͶYYͶ    ",
      "Ͷ        ͶYͶ    ",
      "Ͷ        ͶYͶ    "
    ],
    [
      "             Ͷ  ",
      "            Ͷ   ",
      "            Ͷ   ",
      "       Y    Ͷ   ",
      "      ͶY    Ͷ   ",
      "      ͶY     Ͷ  ",
      "      ͶY      ͶͶ",
      "     !ͶY        ",
      "      ͶY       Ͷ",
      "      ͶY      Ͷ ",
      "      ͶY     Ͷ  ",
      "   ͶͶͶͶYYY  Ͷ   ",
      " ͶͶ    ͶͶY  Ͷ   ",
      " Ͷ      ͶYYͶ    ",
      "Ͷ        ͶYͶ    ",
      "Ͷ        ͶYͶ    "
    ]
  ]
}