{
  "xsize": 16,
  "zsize": 16,
  "refpalette": "lostcities:base",
  "slices": [
    [
      "ʹʹf  f          ",
      "ffʹ !f!         ",
      "   !!!!         ",
      "ffffff          ",
      "ffʹ  f          ",
      "ʹʹf  ff         ",
      "ʹʹf  ff         ",
      "ʹʹf  ff         ",
      "ffʹ  ff         ",
      "     ff         ",
      "     ff         ",
      "ffʹ  ff!        ",
      "ʹʹf  ff!        ",
      "ʹʹf  ff         ",
      "ʹʹfffff         ",
      "ffʹ  f          "
    ],
    [
      "ʹʹʹ  f          ",
      "ʹʹʹ  f          ",
      "    !f!         ",
      "fffffff         ",
      "ʹʹʹ  ff         ",
      "ʹʹʹ  ff         ",
      "ʹʹʹ  ff         ",
      "ʹʹʹ  ff         ",
      "ʹʹʹ  ff         ",
      "     ff         ",
      "     ff         ",
      "ʹʹʹ  ff         ",
      "ʹʹʹ  ff!        ",
      "ʹʹʹ  ff!        ",
      "ʹʹʹffff         ",
      "ʹʹʹ  f          "
    ],
    [
      "     f          ",
      "     f          ",
      "    !f!         ",
      "ffffff          ",
      "     f          ",
      "     f          ",
      "     f          ",
      "     f          ",
      "     f          ",
      "     f          ",
      "     f          ",
      "     f          ",
      "     f!         ",
      "    !f!!        ",
      "ffffff!         ",
      "   !!f          "
    ],
    [
      "ffffff          ",
      "ffffff          ",
      "ffffff!         ",
      "ffffff          ",
      "ffffff          ",
      "ffffff          ",
      "ffffff          ",
      "ffffff          ",
      "ffffff          ",
      "ffffff          ",
      "ffffff          ",
      "ffffff          ",
      "ffffff          ",
      "ffffff!         ",
      "ffffff!         ",
      "   fff!         "
    ],
    [
      "                ",
      "!               ",
      "!!  !!          ",
      "fffff!          ",
      "!   f           ",
      "   !f!          ",
      "    f           ",
      "    f           ",
      "    f           ",
      "    f           ",
      "    f           ",
      "    f           ",
      "    f           ",
      "    f!          ",
      "  fff!          ",
      "    !!          "
    ],
    [
      "                ",
      "                ",
      "!!  !!          ",
      "fffff!!         ",
      "f! !f!          ",
      "f  !f!          ",
      "f   f           ",
      "f   f           ",
      "f   f           ",
      "f   f           ",
      "f   f           ",
      "f   f           ",
      "f   f           ",
      "f   f           ",
      "fffff           ",
      "                "
    ]
  ]
}