{
  "xsize": 16,
  "zsize": 16,
  "refpalette": "pomkotsmechs:base",
  "slices": [
    [
      "gggggggggggggggg",
      "gggggggggggggggg",
      "gggggggggggggggg",
      "gggggggggggggggg",
      "gggggggggggggggg",
      "gggggggggggggggg",
      "gggggggggggggggg",
      "gggggggggggggggg",
      "gggggggggggggggg",
      "ggggggggggggg  g",
      "ggggggggggg    g",
      "gggggggggg      ",
      "gggggggggg      ",
      "gggggggggg     g",
      "gggggggggg     g",
      "gggggggggggggggg"
    ],
    [
      "gppppppppppppppg",
      "z !!!!         z",
      "z  !!!!        z",
      "z   !gg  gg    z",
      "z   ggg  ggg   z",
      "z  gggg  gggg  z",
      "z  gggggggggg  z",
      "z   gggggggg   z",
      "z   gggggggg   z",
      "z  gggggggggg  z",
      "z  gggggggg    z",
      "z   gggggg      ",
      "z!   gg  g      ",
      "z!!             ",
      "z!              ",
      "gpppppppppp    g"
    ],
    [
      "g !!          !g",
      "    !          !",
      "   !!!          ",
      "    !gg  gg     ",
      "    ggg  ggg    ",
      "   gg      gg   ",
      "   gg      gg   ",
      "    g      g    ",
      "    g      g    ",
      "   gg      gg   ",
      "   gg      g    ",
      "    ggggggg     ",
      " !   gg  g      ",
      "!!!             ",
      "!!!             ",
      "g!              "
    ],
    [
      "    !          !",
      "   !!!          ",
      "   !!!          ",
      "    ! g  g      ",
      "    g      g    ",
      "                ",
      "                ",
      "    g      g    ",
      "    g      g    ",
      "                ",
      "                ",
      "    g  gg       ",
      "                ",
      " !              ",
      "!!!             ",
      " !              "
    ],
    [
      "   !!           ",
      "  !!!!          ",
      "   !!           ",
      "    gggggggg    ",
      "   gggggggggg   ",
      "   gg      gg   ",
      "   gg      gg   ",
      "   gg      gg   ",
      "   gg      gg   ",
      "   gg      gg   ",
      "   gg      gg   ",
      "   gggggggg     ",
      "    gggggg      ",
      " !              ",
      "!!!             ",
      " !              "
    ],
    [
      "   !!           ",
      " gggggggggg   g ",
      " gggggggggg  gg ",
      " ggggggggggg gg ",
      " gggggggggggggg ",
      " gggggggggggggg ",
      " gggggggggggggg ",
      " gggggggggggggg ",
      " gggggggggggggg ",
      " gggggggggggggg ",
      " gggggggggggggg ",
      " gggggggggg     ",
      " gggggggggg     ",
      " ggggggggg      ",
      "!ggggggggg      ",
      " !              "
    ]
  ]
}