{
  "xsize": 16,
  "zsize": 16,
  "refpalette": "pomkotsmechs:base",
  "slices": [
    [
      "vvvvvvvvvvvvvvvv",
      "vvvvvvvvvvvvvvvv",
      "vvvvvvvvvvvvvvvv",
      "vvvvvvvvvvvvvvvv",
      "vvvvvvvvvvvvvvvv",
      "vvvvvvvvvvvvvvvv",
      "vvvvvvvvvvvvvvvv",
      "vvvvvvvvvvvvvvvv",
      "vvvvvvvvvvvvvvvv",
      "vvvvvvvvvvvvvvvv",
      "vvvvvvvvvvvvvvvv",
      "vvvvvvvvvvvvvvvv",
      "vvvvvvvvvvvvvvvv",
      "vvvvvvvvvvvvvvvv",
      "vvvvvvvvvvvvvvvv",
      "vvvvvvvvvvvvvvvv"
    ],
    [
      "                ",
      "                ",
      "                ",
      "                ",
      "                ",
      "                ",
      "                ",
      "                ",
      "            #   ",
      "                ",
      "                ",
      "             !!!",
      "            !!! ",
      "           !!!!!",
      "           ! !! ",
      "                "
    ],
    [
      "                ",
      "                ",
      "                ",
      "                ",
      "              @@",
      "             @AA",
      "             BAA",
      "             BAA",
      "            DAAA",
      "             BAA",
      "             BAA",
      "             BAA",
      "            !BAA",
      "             BAA",
      "             BAA",
      "             BAA"
    ],
    [
      "                ",
      "                ",
      "                ",
      "                ",
      "             EAA",
      "             AAA",
      "             AGA",
      "             H; ",
      "             A  ",
      "             AAA",
      "              !!",
      "             !!!",
      "             !!!",
      "             A  ",
      "             AAA",
      "             AAA"
    ],
    [
      "                ",
      "                ",
      "                ",
      "                ",
      "                ",
      "             I;;",
      "             ;  ",
      "             H; ",
      "             A  ",
      "             AAA",
      "             !! ",
      "            !!!!",
      "             !! ",
      "             A  ",
      "             AAA",
      "             AAA"
    ],
    [
      "                ",
      "                ",
      "                ",
      "                ",
      "                ",
      "                ",
      "              II",
      "             IAA",
      "             JAA",
      "             JAA",
      "             A!!",
      "            !A! ",
      "             A  ",
      "             J  ",
      "             JAA",
      "             IIA"
    ]
  ]
}