{
  "xsize": 16,
  "zsize": 16,
  "refpalette": "pomkotsmechs:base",
  "slices": [
    [
      "gggggggggggggggg",
      "gggggggggggggggg",
      "gggggggggggggggg",
      "gggggggggggggggg",
      "ggggggggggg     ",
      "ggggggggggg     ",
      "gggggggggg g    ",
      "gggggggggg ggg  ",
      "!!!ggggg g ggggg",
      "    gggggg΅ggggg",
      "    ggggͿ΀Ͳggggg",
      "gggggggggggggggg",
      "gggggggggggggggg",
      "gggggggggggggggg",
      "gggggggggggggggg",
      "gggggggggggggggg"
    ],
    [
      "nnn          nnn",
      "ngn          ngn",
      "nngg gg gg ggnnn",
      "  gg gg gg gg   ",
      "                ",
      "  gg!gg gg g    ",
      " !gg!gg΂gg g    ",
      "!!!!!!!ggg      ",
      "   !  gzgg gg   ",
      "   g ggggg!gg   ",
      "         !!!!   ",
      "  gg gg gg!gg   ",
      " ggg gg gg gg   ",
      "nnn          nnn",
      "ngn          ngn",
      "nnn          nnn"
    ],
    [
      " n            n ",
      "ngn          ngn",
      " nͳͳ ͳͳ ͳͳ ͳͳ n ",
      "  ͳͳ ͳͳ ͳͳ ͳͳ   ",
      "      !         ",
      "  ͳͳ!ͳͳ!ͳͳ ͳ    ",
      " !ͳ!!!ͳ!ͳͳ ͳ    ",
      "  !!! ! pi      ",
      "       zͳͳ ͳͳ   ",
      "      ͳjͳͳ!ͳͳ   ",
      "         !!!!   ",
      "  ͳͳ ͳͳ ͳͳ!ͳͳ   ",
      "  ͳͳ ͳͳ ͳͳ ͳͳ!  ",
      " n          ! n ",
      "ngn          ngn",
      " n            n "
    ],
    [
      "                ",
      " g            g ",
      "  ͳͳ ͳͳ ͳͳ ͳͳ   ",
      "  ͳͳ ͳͳ ͳͳ ͳͳ   ",
      "      !         ",
      "  ͳͳ ͳͳ!ͳͳ ͳ    ",
      " !ͳ!! ! ͳͳͲͳ    ",
      "  !!    pi;     ",
      "        ͳͳ ͳͳ   ",
      "      ͳͽͳͳ!ͳͳ   ",
      "         !!!    ",
      "  ͳͳ ͳͳ ͳͳ!ͳͳ   ",
      "  ͳͳ ͳͳ ͳͳ!ͳͳ!  ",
      "            !   ",
      " g            g ",
      "                "
    ],
    [
      "                ",
      " g            g ",
      "  ͳͳ ͳͳ ͳͳ ͳͳ   ",
      "  ͳͳ ͳͳ ͳͳ ͳͳ   ",
      "     !!         ",
      "  ͳͳ!ͳͳ!ͳͳ ͳ    ",
      "  !! !! ͳͳ ͳ    ",
      "        pi΅     ",
      "       zͳͳ;ͳ    ",
      "      ͳjͳͳ ͳͳ   ",
      "          !!    ",
      "  ͳͳ ͳͳ ͳͳ!ͳͳ   ",
      "  ͳͳ ͳͳ ͳͳ!ͳͳ!  ",
      "           !!   ",
      " g            g ",
      "                "
    ],
    [
      " n            n ",
      "ngn          ngn",
      " nͳͳ ͳͳ ͳͳ ͳͳ n ",
      "  ͳͳ ͳͳ ͳͳ ͳͳ   ",
      "    !!          ",
      "   ͳ!ͳͳ ͳͳ ͳ    ",
      "    !!ͳ ͳͳ      ",
      "        pi      ",
      "      ͳzͳͳ΅ͳ    ",
      "     ͳͳjͳͳ;ͳͳ   ",
      "         !n!    ",
      "   ͳ ͳͳ ͳͳ!ͳͳ   ",
      "  ͳͳ ͳͳ ͳͳ!!!   ",
      " n         !  n ",
      "ngn          ngn",
      " n            n "
    ]
  ]
}