{
  "xsize": 16,
  "zsize": 16,
  "refpalette": "pomkotsmechs:base",
  "slices": [
    [
      "                ",
      "                ",
      "fʹ            ʹf",
      "ʹf            fʹ",
      "ʹf            fʹ",
      "ʹf            fʹ",
      "fʹ !          ʹf",
      "f !!!          f",
      "f!!!!  !       f",
      "f!!!  !!!      f",
      "f!!    !       f",
      "f              f",
      "f              f",
      "ffffffff    ffff",
      "f!             f",
      "!               "
    ],
    [
      "                ",
      "                ",
      "ʹʹ            ʹʹ",
      "ʹʹ            ʹʹ",
      "ʹʹ            ʹʹ",
      "ʹʹ            ʹʹ",
      "ʹʹ            ʹʹ",
      "f  !!          f",
      "f !!!! !       f",
      "f!!!! !!!      f",
      "f!!!  !!!      f",
      "f!     !       f",
      "f              f",
      "fffffff     ffff",
      "f!             f",
      "!               "
    ],
    [
      "                ",
      "                ",
      "               !",
      "f              f",
      "f              f",
      "f              f",
      "f              f",
      "f   !      !!! f",
      "f  !!!         f",
      "f!!!!!!!       f",
      "f!!!! !!!      f",
      "f! !   !       f",
      "f              f",
      "ffffff      ffff",
      "f!             f",
      "!               "
    ],
    [
      "fffffffffffffff ",
      "fffffffffffffff ",
      "fffffffffffffff ",
      "ffffffffffffffff",
      "ffffffffffffffff",
      "ffffffffffffffff",
      "ffffffffffffffff",
      "ffffffffffffffff",
      "   fffffffffffff",
      " ! !ffffffffffff",
      "!!!fffffffffffff",
      "ffffff!!   fffff",
      "ffffff     fffff",
      "ffffff      ffff",
      "ff            ff",
      "                "
    ],
    [
      "                ",
      "                ",
      "                ",
      "ff            ff",
      " f            f!",
      " f            f!",
      " f           !f!",
      " f         !!!f ",
      "            !!f!",
      "    !!!      !f!",
      " ! !  !!      f ",
      "!f!           f ",
      "!f!           f ",
      "!f            f ",
      "ff            ff",
      "                "
    ],
    [
      "                ",
      "                ",
      "                ",
      "f              f",
      "f              f",
      "f              f",
      "f              f",
      "f            !!f",
      "             !!f",
      "              !f",
      "               f",
      "f!             f",
      "f!             f",
      "f!             f",
      "f!             f",
      "!               "
    ]
  ]
}