{
  "xsize": 16,
  "zsize": 16,
  "refpalette": "pomkotsmechs:base",
  "slices": [
    [
      "                ",
      "gggggggggggggggg",
      "                ",
      "                ",
      "ͲͲͲͲͲ           ",
      "ͲͲ  Ͳ           ",
      "  Ͳ Ͳ  ggggggggg",
      "  Ͳ Ͳ  g        ",
      "ͲͲ  Ͳ  g        ",
      "    Ͳ  g        ",
      "ͲͲ  Ͳ  g        ",
      "  Ͳ Ͳ! g        ",
      "  Ͳ!Ͳ!!g        ",
      "ͲͲ !Ͳ!!g      gg",
      "ͲͲͲͲͲ! g      gg",
      "       ggggggggg"
    ],
    [
      "                ",
      "gggggggggggggggg",
      "                ",
      "                ",
      "ͲͲͲͲͲ           ",
      "ͲͲͲͲͲ           ",
      "  ͲͲͲ  ggggggggg",
      "  ͲͲͲ  g        ",
      "ͲͲͲͲͲ  g        ",
      "ͲͲͲͲͲ  g        ",
      "ͲͲͲͲͲ  g        ",
      "  ͲͲͲ  g        ",
      "  ͲͲͲ! g        ",
      "ͲͲͲͲͲ! g       g",
      "ͲͲͲͲͲ !g!      g",
      "       ggggggggg"
    ],
    [
      "gggggggggggggggg",
      "gggggggggggggggg",
      "                ",
      "                ",
      "                ",
      "ͲͲ              ",
      "  Ͳ    ggggggggg",
      "  Ͳ   !gYYYYYYYY",
      "ͲͲ    !gYYYYYYYY",
      "      !gYYYYYYYY",
      "ͲͲ    !gYYYYYYYY",
      "  Ͳ!  !gYYYYYYYY",
      "  Ͳ!! !gYYYYYYYY",
      "ͲͲ !! !gYYYY    ",
      "      !gYYYY    ",
      "       ggggggggg"
    ],
    [
      "                ",
      "                ",
      "                ",
      "                ",
      "                ",
      "ͲͲ     !        ",
      "  Ͳ   !g!       ",
      "  Ͳ   !!!    YY ",
      "ͲͲ     !     YY ",
      "       !        ",
      "ͲͲ     !        ",
      "  Ͳ!   !        ",
      " !Ͳ!!  !        ",
      "ͲͲ!!   !        ",
      "       !        ",
      "       g        "
    ],
    [
      "                ",
      "                ",
      "                ",
      "                ",
      "                ",
      "ͲͲ     !        ",
      "  Ͳ   !g!       ",
      "  Ͳ    !    YY  ",
      "ͲͲ          YY  ",
      "                ",
      "ͲͲ              ",
      "  Ͳ             ",
      " !Ͳ!            ",
      "ͲͲ!             ",
      "                ",
      "       g        "
    ],
    [
      "              gg",
      "                ",
      "                ",
      "                ",
      "                ",
      "ͲͲ     !        ",
      "  Ͳ   !g!       ",
      "  Ͳ    !   YY   ",
      "ͲͲ         YY   ",
      "                ",
      "ͲͲ              ",
      "  Ͳ             ",
      " !Ͳ!            ",
      "ͲͲ!!            ",
      "  !             ",
      "       g        "
    ]
  ]
}