{
  "xsize": 16,
  "zsize": 16,
  "refpalette": "pomkotsmechs:base",
  "slices": [
    [
      "vvvvvvvvvvvvvvvv",
      "vvvvvvvvvvvvvvvv",
      "vvvvvvvvvvvvvvvv",
      "vvvvvvvvvvvvvvvv",
      "vvvvvvvvvvvvvvvv",
      "vvvvvvvvvvvvvvvv",
      "vvvvvvvvvvvvvvvv",
      "vvvvvvvvvvvvvvvv",
      "vvvvvvvvvvvvvvvv",
      "vvvvvvvvvvvvvvvv",
      "vvvvvvvvvvvvvvvv",
      "vvvvvvvvvvvvvvvv",
      "vvvvvvvvvvvvvvvv",
      "vvvvvvvvvvvvvvvv",
      "vvvvvvvvvvvvvvvv",
      "vvvvvvvvvvvvvvvv"
    ],
    [
      "                ",
      "       f     !f ",
      "      ffffffffff",
      "      f      ! f",
      "     ff        f",
      "      f        f",
      "      f        f",
      "      f        f",
      "      f        f",
      "      f        f",
      "      f        f",
      "     ff        f",
      "    !!f        f",
      "     !ffffffffff",
      "       f      f ",
      "                "
    ],
    [
      "                ",
      "       f     !f ",
      "      ffffffffff",
      "      f      ! f",
      "     ff        f",
      "      f        f",
      "      f        f",
      "      f        f",
      "      f        f",
      "      f        f",
      "      f        f",
      "     ff        f",
      "    !!f!       f",
      "     !ffffffffff",
      "      !f      f ",
      "                "
    ],
    [
      "                ",
      "       f     !f ",
      "      ffffffffff",
      "      f      ! f",
      "     ff        f",
      "      f        f",
      "      f        f",
      "      f        f",
      "      f        f",
      "      f        f",
      "      f        f",
      "     ff        f",
      "     !f        f",
      "     !ffffffffff",
      "      !f      f ",
      "                "
    ],
    [
      "                ",
      "       f     !f ",
      "      ffffffffff",
      "      f      ! f",
      "     ff        f",
      "      f        f",
      "      f        f",
      "      f        f",
      "      f        f",
      "      f        f",
      "      f        f",
      "     ff        f",
      "      f        f",
      "     !ffffffffff",
      "      !f      f ",
      "                "
    ],
    [
      "                ",
      "       f    !!f ",
      "      ffffffffff",
      "      f     !! f",
      "     ff        f",
      "      f        f",
      "      f        f",
      "      f        f",
      "      f        f",
      "      f        f",
      "      f        f",
      "     ff        f",
      "      f        f",
      "     !ffffffffff",
      "      !f      f ",
      "                "
    ]
  ]
}