{
  "xsize": 16,
  "zsize": 16,
  "refpalette": "pomkotsmechs:base",
  "slices": [
    [
      "                ",
      "      ffffffff  ",
      "      f   ffffff",
      "      f   f  f  ",
      "      f   f  f  ",
      "      f!  f  f  ",
      "     !f!! f  ʹff",
      "     !f!  f  fʹʹ",
      "      f!  f  fʹʹ",
      "     !f!! f  fʹʹ",
      "      f!  f  ʹff",
      "      f   f  f  ",
      "      ffffffff  ",
      "          f  ʹff",
      "          f  fʹʹ",
      "          f  fʹʹ"
    ],
    [
      "                ",
      "       fffffff  ",
      "       f  ffffff",
      "       f  f  f  ",
      "       f  f  f  ",
      "      !f! f  f  ",
      "      !f! f  ʹʹʹ",
      "      !f  f  ʹʹʹ",
      "      !f! f  ʹʹʹ",
      "      !f! f  ʹʹʹ",
      "       f  f  ʹʹʹ",
      "       f  f  f  ",
      "       fffffff  ",
      "          f  ʹʹʹ",
      "          f  ʹʹʹ",
      "          f  ʹʹʹ"
    ],
    [
      "                ",
      "       ffffffff ",
      "       f  ffffff",
      "       f  f   f ",
      "       f! f   f ",
      "      !f!!f   f ",
      "       f! f  nf ",
      "       f! f   f ",
      "      !f!!f   f ",
      "       f! f   f ",
      "       f  f  nf ",
      "       f  f   f ",
      "       ffffffff ",
      "          f  n  ",
      "          f     ",
      "          f     "
    ],
    [
      "                ",
      "        fffffff ",
      "        f ffffff",
      "        f f   f ",
      "        f!f   f ",
      "       !f!f   f ",
      "        f!f  ʹʹʹ",
      "        f f  ʹʹʹ",
      "       !f!f  ʹʹʹ",
      "        f f  ʹʹʹ",
      "        f f  ʹʹʹ",
      "        f f   f ",
      "        fffffff ",
      "          f  ʹʹʹ",
      "          f  ʹʹʹ",
      "          f  ʹʹʹ"
    ],
    [
      "                ",
      "        ffffffff",
      "        f ffffff",
      "        f!f    f",
      "       !f!f    f",
      "       !f!f    f",
      "       !f!f  ʹff",
      "        f!f  f f",
      "       !f!f  f f",
      "        f f  fͳͳ",
      "        f f  ʹff",
      "        f f    f",
      "        ffffffff",
      "          f  ʹff",
      "          f  f  ",
      "          f  f  "
    ],
    [
      "                ",
      "         fffffff",
      "         fffffff",
      "         ff    f",
      "        !ff    f",
      "        !ff    f",
      "        !ff  ʹff",
      "         ff  f f",
      "        !ff  f f",
      "         ff  f f",
      "         ff  ʹff",
      "         ff    f",
      "         fffffff",
      "          f  ʹff",
      "          f  f  ",
      "          f  f  "
    ]
  ]
}