{
  "xsize": 16,
  "zsize": 16,
  "refpalette": "pomkotsmechs:base",
  "slices": [
    [
      "vvvvvvvvvvvvvvvv",
      "vvvvvvvvvvvvvvvv",
      "vvvvvvvvvvvvvvvv",
      "vvvvvvvvvvvvvvvv",
      "vvvvvvvvvvvvvvvv",
      "vvvvvvvvvvvvvvvv",
      "vvvvvvvvvvvvvvvv",
      "vvvvvvvvvvvvvvvv",
      "vvvvvvvvvvvvvvvv",
      "vvvvvvvvvvvvvvvv",
      "vvvvvvvvvvvvvvvv",
      "vvvvvvvvvvvvvvvv",
      "vvvvvvvvvvvvvvvv",
      "vvvvvvvvvvvvvvvv",
      "vvvvvvvvvvvvvvvv",
      "vvvvvvvvvvvvvvvv"
    ],
    [
      "ffffffffffffff  ",
      "ffffffffffffff  ",
      "ffffffffffffff  ",
      "fffffffffffffff ",
      "ffffffffffffffff",
      "ffffffffffffffff",
      "ffffffffffffffff",
      "ffffffffffffffff",
      "ffffffffffffffff",
      "ffffffffffff   f",
      "fffffffffff    f",
      "ffffffffff    ff",
      "ffffffffff   fff",
      "ffffffffff   fff",
      "fffffffff    fff",
      "ffffffff    ffff"
    ],
    [
      "gg              ",
      " m              ",
      " m              ",
      " m              ",
      " m           !  ",
      " m          !!! ",
      " m          !ff ",
      " m          ffff",
      " m              ",
      " m              ",
      " m              ",
      " m              ",
      " m              ",
      " m              ",
      " m              ",
      "gg              "
    ],
    [
      "gg              ",
      " m              ",
      " m              ",
      " m              ",
      " m              ",
      " m           !  ",
      " m          !!! ",
      " m           ff ",
      " m           ff ",
      " m              ",
      " m              ",
      " m              ",
      " m              ",
      " m              ",
      " m              ",
      "gg              "
    ],
    [
      "                ",
      "                ",
      "                ",
      " m              ",
      " m              ",
      " m           !  ",
      " m          !!! ",
      " m           hi ",
      " m           jk ",
      " m              ",
      " m              ",
      " m              ",
      " m              ",
      " m              ",
      " m              ",
      "gg              "
    ],
    [
      "                ",
      "                ",
      "                ",
      " m              ",
      " m              ",
      " m           !  ",
      " m          !!! ",
      " m           hi ",
      " m           jk ",
      " m              ",
      " m              ",
      " m              ",
      " m              ",
      " m              ",
      " m              ",
      "gg              "
    ]
  ]
}