{
  "xsize": 16,
  "zsize": 16,
  "refpalette": "pomkotsmechs:base",
  "slices": [
    [
      "g    g        g ",
      "                ",
      "                ",
      "                ",
      "                ",
      "                ",
      "                ",
      "        YY      ",
      "        YY      ",
      "g    g        g ",
      "                ",
      "                ",
      "                ",
      "                ",
      "                ",
      "          !!    "
    ],
    [
      "g    g        g ",
      "                ",
      "                ",
      "                ",
      "                ",
      "                ",
      "                ",
      "       YY       ",
      "       YY       ",
      "g    g        g ",
      "                ",
      "                ",
      "                ",
      "                ",
      "                ",
      "                "
    ],
    [
      "g    g        g ",
      "                ",
      "                ",
      "                ",
      "                ",
      "                ",
      "                ",
      "      YY        ",
      "      YY        ",
      "g    g        g ",
      "                ",
      "                ",
      "                ",
      "                ",
      "                ",
      "                "
    ],
    [
      "g    gggggggggg ",
      "gYYYYgYYYYYYYYg ",
      "gYYYYgYYYYYYYYg ",
      "gYYYYgYYYYYYYYg ",
      "gYYYYgYYYYYYYYg ",
      "gYYYYgYYYYYYYYg ",
      "gYYYYgYYYYYYYYg ",
      "gYYYYgY    YYYg ",
      "gYYYYgY    YYYg ",
      "gYYYYgggggggggg ",
      "ggggggggg       ",
      "   YY           ",
      "   YY           ",
      "   YY           ",
      "   YY           ",
      "   YY           "
    ],
    [
      "g    g        g ",
      "                ",
      "                ",
      "                ",
      "                ",
      "                ",
      "                ",
      "           YY   ",
      "           YY   ",
      "g    g        g ",
      "                ",
      "                ",
      "                ",
      "                ",
      "                ",
      "                "
    ],
    [
      "g    g        g ",
      "                ",
      "                ",
      "                ",
      "                ",
      "                ",
      "                ",
      "          YY    ",
      "          YY    ",
      "g    g        g ",
      "                ",
      "                ",
      "                ",
      "                ",
      "                ",
      "                "
    ]
  ]
}