{
  "xsize": 16,
  "zsize": 16,
  "refpalette": "pomkotsmechs:base",
  "slices": [
    [
      "gggggggggggggggg",
      "gggggggggggggggg",
      "gggggggggggggggg",
      "gggggggggggggggg",
      "gggggggggggggggg",
      "gggggggggggggggg",
      "gggggggggggggggg",
      "gggggggggggggggg",
      "gggggggggggggggg",
      "gggggggggggggggg",
      "gggggggggggggggg",
      "gggggggggggggggg",
      "gggggggggggggggg",
      "gggggggggggggggg",
      "gggggggggggggggg",
      "gggggggggggggggg"
    ],
    [
      " g           g !",
      "g           ggg!",
      "gYYYYYYYYYYggggg",
      " g          ggg!",
      "            !g! ",
      "            !Y! ",
      "             Y  ",
      "             Y  ",
      "             Y! ",
      "            !Y!!",
      "             Y! ",
      "             Y  ",
      " !!          Y  ",
      "!!           Y  ",
      " g          gY g",
      "g            gg "
    ],
    [
      "             g  ",
      "g           ggg!",
      "gYYYYYYYYYYggggg",
      "            ggg!",
      "            !g!!",
      "            !Y! ",
      "             Y  ",
      "             Y  ",
      "             Y  ",
      "            !Y! ",
      "             Y  ",
      "             Y  ",
      "             Y  ",
      "             Y  ",
      "             Y  ",
      "g            gg "
    ],
    [
      "             g  ",
      "g           ggg!",
      "gYYYYYYYYYYggggg",
      "            ggg!",
      "            !g!!",
      "            !Y! ",
      "             Y  ",
      "             Y  ",
      "             Y  ",
      "            !Y! ",
      "             Y  ",
      "             Y  ",
      "             Y  ",
      "             Y  ",
      "             Y  ",
      "g            gg "
    ],
    [
      "             g  ",
      "g           ggg ",
      "gYYYYYYYYYYggggg",
      "            ggg!",
      "             g!!",
      "             Y! ",
      "             Y  ",
      "             Y  ",
      "             Y  ",
      "            !Y! ",
      "            !Y! ",
      "             Y  ",
      "             Y  ",
      "             Y  ",
      "             Y  ",
      "g            gg "
    ],
    [
      "             g  ",
      "g           ggg ",
      "gYYYYYYYYYYggggg",
      "            ggg!",
      "             g!!",
      "            !Y!!",
      "            !Y! ",
      "             Y  ",
      "             Y  ",
      "             Y  ",
      "            !Y! ",
      "             Y  ",
      "             Y  ",
      "             Y  ",
      "             Y  ",
      "g            gg "
    ]
  ]
}