{
  "xsize": 16,
  "zsize": 16,
  "refpalette": "lostcities:base",
  "slices": [
    [
      "g           gg  ",
      "gYYYYYYYYYYYYY  ",
      "gYYYYYYYYYYYYYg ",
      "gYYYYYYYYYYYYYg ",
      "ggggggggggggggg ",
      " YYYYYYYYYYYYY  ",
      " YYYYYYYYYYYYY  ",
      " YYYYYYYYYYYYY  ",
      " YYYYYYYYYYYYY  ",
      " YYYYYYYYYYYYY  ",
      " YYYYYYYYYYYYY  ",
      "ggggggggggggggg ",
      "gYYYYYYYYYYYYYg ",
      "gYYYYYYYYYYYYYg ",
      "gYYYYYYYYYYYYY  ",
      "g           gg  "
    ],
    [
      "g           g   ",
      "gYYYYYYYYYYYY   ",
      "gYYYYYYYYYYYYgg ",
      "gYYYYYYYYYYYYgg ",
      "ggggggggggggggg ",
      " YYYYYYYYYYYY   ",
      " YYYYYYYYYYYY   ",
      " YYYYYYYYYYYY   ",
      " YYYYYYYYYYYY   ",
      " YYYYYYYYYYYY   ",
      " YYYYYYYYYYYY   ",
      "ggggggggggggggg ",
      "gYYYYYYYYYYYYgg ",
      "gYYYYYYYYYYYYgg ",
      "gYYYYYYYYYYYY   ",
      "g           g   "
    ],
    [
      "g           g   ",
      "gYYYYYYYYYYYY   ",
      "gYYYYYYYYYYYYg  ",
      "gYYYYYYYYYYYYg  ",
      "gggggggggggggg  ",
      " YYYYYYYYYYY    ",
      " YYYYYYYYYYY    ",
      " YYYYYYYYYYY    ",
      " YYYYYYYYYYYY   ",
      " YYYYYYYYYYYY   ",
      " YYYYYYYYYYYY   ",
      "gggggggggggggg  ",
      "gYYYYYYYYYYYYg  ",
      "gYYYYYYYYYYYYg  ",
      "gYYYYYYYYYYYY   ",
      "g           g   "
    ],
    [
      "ggg         g   ",
      "gYYYYYYYYYYYY   ",
      "gYYYYYYYYYYYYg  ",
      "gYYYYYYYYYYYYg  ",
      "gggggggggggggg  ",
      " YYYYYYYYYYY    ",
      " YYYYYYYYYYY    ",
      " YYYYYYYYYYY    ",
      " YYYYYYYYYYYY   ",
      " YYYYYYYYYYYY   ",
      " YYYYYYYYYYYY   ",
      "gggggggggggggg  ",
      "gYYYYYYYYYYYYg  ",
      "gYYYYYYYYYYYYg  ",
      "gYYYYYYYYYYYY   ",
      "ggg         g   "
    ],
    [
      "gggg        g   ",
      "gYYYYYYYYYYYY   ",
      "gYYYYYYYYYYYYg  ",
      "gYYYYYYYYYYYYg  ",
      "gggggggggggggg  ",
      " YYYYYYYYYYY    ",
      " YYYYYYYYYY     ",
      " YYYYYYYYYYY    ",
      " YYYYYYYYYYYY   ",
      " YYYYYYYYYYYY   ",
      " YYYYYYYYYYYY   ",
      "gggggggggggggg  ",
      "gYYYYYYYYYYYYg  ",
      "gYYYYYYYYYYYYg  ",
      "gYYYYYYYYYYYY   ",
      "gggg        g   "
    ],
    [
      "g gggg     gg   ",
      "gYYYYYYYYYYYY   ",
      "gYYYYYYYYYYYYg  ",
      "gYYYYYYYYYYYYg  ",
      "gggggggggggg    ",
      " YYYYYYYYYY     ",
      " YYYYYYYYYY     ",
      " YYYYYYYYYY     ",
      " YYYYYYYYYYYY   ",
      " YYYYYYYYYYYY   ",
      " YYYYYYYYYYYY   ",
      "gggggggggggggg  ",
      "gYYYYYYYYYYYYg  ",
      "gYYYYYYYYYYYYg  ",
      "gYYYYYYYYY YY   ",
      "g gggg          "
    ]
  ]
}