{
  "xsize": 16,
  "zsize": 16,
  "refpalette": "pomkotsmechs:base",
  "slices": [
    [
      "    g   gggg   g",
      "  !  YYYYYYYYYYg",
      " !g!YYYYYYYYYYYg",
      "  ggYYYYYYYYYYYg",
      "  gggggggggggggg",
      "    YYYYYYYYYYY ",
      "    YYYYYYYYYYY ",
      "    YYYYYYYYYYY ",
      "    YYYYYYYYYYY ",
      "    YYYYYYYYYYY ",
      "    YYYYYYYYYYY ",
      "  gggggggggggggg",
      "  ggYYYYYYYYYYYg",
      "  ggYYYYYYYYYYYg",
      "    YYY  YYYYYYg",
      "    g      g   g"
    ],
    [
      "    g gggg     g",
      "  !  YYYYYYYYYYg",
      " !!! YYYYYYYYYYg",
      " !!gYYYYYYYYYYYg",
      "  !ggggggggggggg",
      "    YYYYYYYYYYY ",
      "    YYYYYYYYYYY ",
      "    YYYYYYYYYYY ",
      "    YYYYYYYYYYY ",
      "    YYYYYYYYYYY ",
      "    YYYYYYYYYYY ",
      "   ggggggggggggg",
      "   gYYYYYYYYYYYg",
      "   gYYYYYYYYYYYg",
      "    YYYYY   YYYg",
      "    g g        g"
    ],
    [
      "    gggg       g",
      "     YYYYYYYYYYg",
      "  !  YYYYYYYYYYg",
      " !!gYYYYYYYYYYYg",
      "  gggggggggggggg",
      "  g YYYYYYYYYYY ",
      "  g YYYYYYYYYYY ",
      "  g YYYYYYYYYYY ",
      "  g YYYYYYYYYYY ",
      "  g YYYYYYYYYYY ",
      "  g YYYYYYYYYYY ",
      "  gggggggggggggg",
      "  ggYYYYYYYYYYYg",
      "   gYYYYYYYYYYYg",
      "    YYYY    YYYg",
      "    gggg       g"
    ],
    [
      "    ggg        g",
      "     YYYYYYYYYYg",
      "  !!!YYYYYYYYYYg",
      " !!!YYYYYYYYYYYg",
      " !gggggggggggggg",
      "  g YYYYYYYYYYY ",
      "  g YYYYYYYYYYY ",
      "  g YYYYYYYYYYY ",
      "  g YYYYYYYYYYY ",
      "  g YYYYYYYYYYY ",
      "  g YYYYYYYYYYY ",
      "  gggggggggggggg",
      "  ggYYYYYYYYYYYg",
      "   gYYYYYYYYYYYg",
      "    YYYYY   YYYg",
      "    ggg        g"
    ],
    [
      "    gg  !      g",
      "     YYYYYYYYYYg",
      "    !YYYYYYYYYYg",
      "  !!YYYYYYYYYYYg",
      "  ! gggggggggggg",
      "  g YYYYYYYYYYY ",
      "  g YYYYYYYYYYY ",
      "  g YYYYYYYYYYY ",
      "  g YYYYYYYYYYY ",
      "  g YYYYYYYYYYY ",
      "  g YYYYYYYYYYY ",
      "  gggggggggggggg",
      "  ggYYYYYYYYYYYg",
      "   gYYYYYYYYYYYg",
      "    YYYYY   YYYg",
      "    gg         g"
    ],
    [
      "     g  !      g",
      "       !!YYYYYYg",
      "    !YYYYYYYYYYg",
      "   !!YYYYYYYYYYg",
      "   !gggggggggggg",
      "    !YYYYYYYYYY ",
      "     YYYYYYYYYY ",
      "     YYYYYYYYYY ",
      "     YYYYYYYYYY ",
      "     YYYYYYYYYY ",
      "     YYYYYYYYYY ",
      "   ggggggggggggg",
      "   ggYYYYYYYYYYg",
      "   ggYYYYYYYYYYg",
      "     YYYY   YYYg",
      "     g         g"
    ]
  ]
}