{
  "xsize": 16,
  "zsize": 16,
  "refpalette": "pomkotsmechs:base",
  "slices": [
    [
      "                ",
      "                ",
      "                ",
      "                ",
      "              r ",
      "              r ",
      "             !r!",
      "              r ",
      "              r ",
      "              r ",
      " ff          gr ",
      " ff          ggg",
      "            !ggg",
      " g  gg      !!! ",
      " ggggg qqqqq!!  ",
      "                "
    ],
    [
      "wff             ",
      "wff             ",
      "wff             ",
      "wff             ",
      "wff           r ",
      "wff           r ",
      "wff          !r!",
      "wff           r ",
      "wff           r ",
      "wff           r ",
      "wffffffffffffgr ",
      "wffffffffffffggg",
      "jyyyyyyyyyyyyggg",
      "gg  gg     !!!! ",
      " ggggg qqqqq!!  ",
      "            !   "
    ],
    [
      "z               ",
      "z               ",
      "z               ",
      "z               ",
      "z             r ",
      "z             r ",
      "z            !r!",
      "z             r ",
      "z             r ",
      "z             r ",
      "wti          gr ",
      "wxu          ggg",
      "jyyppppppppppggg",
      "gg  gg      !!  ",
      " g ggg qqqqqq!  ",
      "            !   "
    ],
    [
      "              g ",
      "             ggg",
      "              r ",
      "              r ",
      "              r ",
      "             !r!",
      "             !r!",
      "              r ",
      "              r ",
      "              r ",
      " hi          gr ",
      " jk          ggg",
      "             ggg",
      "gg  gg      !   ",
      " g ggg qqqqqqqg ",
      "            ! g "
    ],
    [
      "              g ",
      "             ggg",
      "              r ",
      "              r ",
      "             !r ",
      "            !!r!",
      "            !!r ",
      "            !!r ",
      "            ! r ",
      "              r ",
      " hi          gr ",
      " jk          ggg",
      "             ggg",
      "g   gg      ! g ",
      "gg ggg  qqqqqqg ",
      "           !! gg"
    ],
    [
      "              g ",
      "             ggg",
      "              r ",
      "              r ",
      "              !!",
      "             !!!",
      "            !!! ",
      "           !!!! ",
      "           !!!  ",
      "            ! r ",
      " hi         !gr ",
      " jk         !ggg",
      "             ggg",
      "g   gg      ! g ",
      "gg ggg  qqqqqqg ",
      "g         !!!!gn"
    ]
  ]
}