{
  "xsize": 16,
  "zsize": 16,
  "refpalette": "pomkotsmechs:base",
  "slices": [
    [
      "                ",
      "     gggggg     ",
      "    gggggggg    ",
      "   ggg    gg    ",
      "   g  gggg  g   ",
      "  gg!gggggg!g!  ",
      " !!!gggggggg!!  ",
      "   !  gggggg!g  ",
      "       ggggg g  ",
      "        gggg g  ",
      "        ggg gg  ",
      "         g  gg  ",
      "          ggg   ",
      "     ggggggg    ",
      "     gggggg!!   ",
      "           !    "
    ],
    [
      "                ",
      "     gggggg     ",
      "    gggggggg    ",
      "   ggggggggg    ",
      "   g gggggg g   ",
      "  ggggggggggg   ",
      "  !gggggggggg!  ",
      "   !ggggggggggg ",
      "      gggggggggg",
      "       ggggggggg",
      "         ggggggg",
      "        ggg ggg ",
      "         gggg g ",
      "     ggggggg    ",
      "     gggggg!!   ",
      "           !    "
    ],
    [
      "     gggggg     ",
      "   gggggggggg   ",
      "  gggggggggggg  ",
      "  ggggggggggggg ",
      "  gggggggggggg  ",
      "  gggggggggggg  ",
      "  !gggggggggg!  ",
      "   !!gggggggg!  ",
      "      gggggggggg",
      "       ggggggggg",
      "       ggggggggg",
      "       gggggggg ",
      "    g ggggggggg ",
      "    gggggggggg  ",
      "    ggggggggg   ",
      "     gggggg!    "
    ],
    [
      "     gggggg     ",
      "   gggggggggg   ",
      "  gggggggggggg  ",
      " ggggggggggggg  ",
      "   ggggggggggg  ",
      "   gggggggggg   ",
      "   !ggggggggg   ",
      "    !  gggggg!  ",
      "        ggggg!  ",
      "        gggggg  ",
      "        gggggg  ",
      "       ggggggg  ",
      "     ggggggggg  ",
      "     ggggggggg  ",
      "    ggggggggg   ",
      "     gggggg!    "
    ],
    [
      "                ",
      "                ",
      "      g  g      ",
      "    ggg  gg     ",
      "   gggg  ggg    ",
      "   gggg  gggg   ",
      "   !ggg  ggggg  ",
      "    !      !!   ",
      "          !!!!  ",
      "         ggggg  ",
      "         gggg   ",
      "      g  gggg   ",
      "     gg  ggg    ",
      "      g  g!!    ",
      "          !!    ",
      "                "
    ],
    [
      "                ",
      "                ",
      "      g  g      ",
      "    ggg  gg     ",
      "   gggg  gg     ",
      "   gggg  ggg    ",
      "   gggg  ggggg  ",
      "    !       !   ",
      "           !!!  ",
      "         ggggg  ",
      "     gg  gggg   ",
      "     gg  gggg   ",
      "     gg  ggg    ",
      "      g  g!     ",
      "                ",
      "                "
    ]
  ]
}