{
  "xsize": 16,
  "zsize": 16,
  "refpalette": "pomkotsmechs:base",
  "slices": [
    [
      " g              ",
      "ggg             ",
      " m              ",
      " m              ",
      " m              ",
      " m              ",
      " m              ",
      " m              ",
      "!m!             ",
      "!m!             ",
      " mg!!        ff ",
      "ggg!!!! !    ff ",
      "ggg!!!!!!!      ",
      " g  !!!!!!gg  gg",
      " gqqqq!!!qgggggg",
      "}g     !! gg! gg"
    ],
    [
      " g           ffu",
      "ggg          ffu",
      " m           ffu",
      " m           ffu",
      " m           ffu",
      " m           ffu",
      " m           ffu",
      "!m!          ffu",
      "!m!          ffu",
      " !           ffu",
      "    fffffffffffu",
      "  gffffffffffffu",
      "gggyy!!!!!yyyyyk",
      " g  !!!!!!gg  gg",
      " gqqq!!!!!gggggg",
      " g    !!!!!g! gg"
    ],
    [
      " g             z",
      "ggg            z",
      " m             z",
      " m             z",
      " m             z",
      " m             z",
      " m             z",
      "!m!            z",
      " !             z",
      "               z",
      "             htu",
      "  g   !      wxu",
      " ggppp!!  pppyyk",
      " g  !!!!!!gg  gg",
      " gqqqq!!!!!ggggg",
      " g    !!!  !  gg"
    ],
    [
      " g              ",
      "ggg             ",
      " m              ",
      " m              ",
      " m              ",
      " m              ",
      " m              ",
      "!m!             ",
      " m              ",
      "                ",
      "             hi ",
      "  g          jk ",
      " gg   !!        ",
      " g   !!!! gg  gg",
      " gqqqqqq!! ggggg",
      " g    !!!     gg"
    ],
    [
      " g              ",
      "ggg             ",
      " m              ",
      " m              ",
      " m              ",
      " m              ",
      " m              ",
      "!m!             ",
      " m              ",
      " m              ",
      "  g          hi ",
      " gg          jk ",
      " gg             ",
      " g     !!!gg  gg",
      " gqqqqqqq!gggggg",
      "gg    !!!!!   gg"
    ],
    [
      " g              ",
      "ggg             ",
      " m              ",
      " m              ",
      " m              ",
      " m              ",
      "!m              ",
      "!m!             ",
      "!m              ",
      " m              ",
      " mg          hi ",
      "ggg          jk ",
      "ggg             ",
      " g       !gg  gg",
      " gqqqqqqq!gggggg",
      "ng     !!!!!  gg"
    ]
  ]
}