{
  "xsize": 16,
  "zsize": 16,
  "refpalette": "pomkotsmechs:base",
  "slices": [
    [
      "                ",
      "                ",
      "                ",
      "                ",
      "                ",
      "          !     ",
      "g    g   !!!  g ",
      "        YY!     ",
      "        YY      ",
      "                ",
      "                ",
      "                ",
      "                ",
      "                ",
      "                ",
      "g    g        g "
    ],
    [
      "                ",
      "                ",
      "                ",
      "                ",
      "                ",
      "          !     ",
      "g    g  !!!!  g ",
      "       YY!!     ",
      "       YY!      ",
      "        !       ",
      "                ",
      "                ",
      "                ",
      "                ",
      "                ",
      "g    g        g "
    ],
    [
      "                ",
      "                ",
      "                ",
      "                ",
      "                ",
      "        !!!     ",
      "g    g !!!!!  g ",
      "      YY!!!     ",
      "      YY!!      ",
      "    !!  !       ",
      "     !          ",
      "                ",
      "                ",
      "                ",
      "                ",
      "g    g        g "
    ],
    [
      "   YY           ",
      "   YY           ",
      "   YY           ",
      "   YY           ",
      "   YY           ",
      "   gg    !!     ",
      "gYYYYgggggggggg ",
      "gYYYYgY !!!YYYg ",
      "gYYYYgY!!! YYYg ",
      "gYYYYgYYYYYYYYg ",
      "gYYYYgYYYYYYYYg ",
      "gYYYYgYYYYYYYYg ",
      "gYYYYgYYYYYYYYg ",
      "gYYYYgYYYYYYYYg ",
      "gYYYYgYYYYYYYYg ",
      "g    gggggggggg "
    ],
    [
      "                ",
      "                ",
      "                ",
      "                ",
      "                ",
      "                ",
      "g    g   !!   g ",
      "        !!!YY   ",
      "       !!!!YY   ",
      "    !!  !!      ",
      "    !!!         ",
      "     !          ",
      "                ",
      "                ",
      "                ",
      "g    g        g "
    ],
    [
      "                ",
      "                ",
      "                ",
      "                ",
      "                ",
      "                ",
      "g    g   !    g ",
      "        !!YY    ",
      "     !  !!YY    ",
      "    !!!         ",
      "    !!!         ",
      "     !          ",
      "                ",
      "                ",
      "                ",
      "g    g        g "
    ]
  ]
}