{
  "xsize": 16,
  "zsize": 16,
  "refpalette": "lostcities:base",
  "slices": [
    [
      "       vvvvvvvv͵",
      "       vvvvvvv͵͵",
      "      vvvvvvv͵͵͵",
      "    fffffffvv͵͵͵",
      "    ffvvvvfv͵͵͵͵",
      "    ffvvvvfv͵͵͵͵",
      "    ffvvvvfv͵͵͵͵",
      "    ffvvvvfv͵͵͵͵",
      "    ffvvvvfv͵͵͵͵",
      "    ffvvvvfv͵͵͵͵",
      "    ffvvvvfvv͵͵͵",
      "    ff vvvfvv͵͵͵",
      "    ff vvvfvvv͵͵",
      "    ff  vvfvvvv͵",
      "    fffffffvvvvv",
      "         vvvvvvv"
    ],
    [
      "          ffffff",
      "          ffffff",
      "          ffffff",
      "    ffffffffffff",
      "    f     ffffff",
      "    f     ffffff",
      "    f     ffffff",
      "    f     ffffff",
      "    f     ffffff",
      "    f     ffffff",
      "    f     ffffff",
      "    f     ffffff",
      "    f     ffffff",
      "    f     ffffff",
      "    ffffffffffff",
      "          ffffff"
    ],
    [
      "          f     ",
      "          f  n  ",
      "          f     ",
      "     fffffff    ",
      "     f    ff n  ",
      "     f    ff    ",
      "     f    ff    ",
      "     f    ff    ",
      "     f    ff n  ",
      "     f    ff    ",
      "     f    ff    ",
      "     f    ff n  ",
      "     f    ff    ",
      "     f    ff    ",
      "     fffffff    ",
      "          f  n  "
    ],
    [
      "          f  ʹʹʹ",
      "          f  ʹʹʹ",
      "          f     ",
      "     ffffffff   ",
      "     f    f fʹʹʹ",
      "     f    f fʹʹʹ",
      "     f    f fʹʹʹ",
      "     f    f fʹʹʹ",
      "     f    f fʹʹʹ",
      "     f    f f   ",
      "     f    f f   ",
      "     f    f fʹʹʹ",
      "     f    f fʹʹʹ",
      "     f    f fʹʹʹ",
      "     ffffffffʹʹʹ",
      "          f  ʹʹʹ"
    ],
    [
      "          f  fͳͳ",
      "          f  ʹff",
      "          f     ",
      "      fffffff   ",
      "      f   f fʹff",
      "      f   f ff  ",
      "      f   f ff  ",
      "      f   f ffͳͳ",
      "      f   f fʹff",
      "      f   f f   ",
      "      f   f f   ",
      "      f   f fʹff",
      "      f   f ff  ",
      "      f   f ff  ",
      "      ffffffffͳͳ",
      "          f  ʹff"
    ],
    [
      "          f  f  ",
      "          f  ʹff",
      "          f     ",
      "      ffffffff  ",
      "      f   f  ʹff",
      "      f   f  f  ",
      "      f   f  f  ",
      "      f   f  f  ",
      "      f   f  ʹff",
      "      f   f  f  ",
      "      f   f  f  ",
      "      f   f  ʹff",
      "      f   f  f  ",
      "      f   f  f  ",
      "      ffffffff  ",
      "          f  ʹff"
    ]
  ]
}