{
  "xsize": 16,
  "zsize": 16,
  "refpalette": "pomkotsmechs:base",
  "slices": [
    [
      "              g ",
      "              g ",
      "              g ",
      "              g ",
      "              g ",
      "              g ",
      "              g ",
      "              g ",
      "              g ",
      "              g ",
      "              g ",
      "              g ",
      "              g ",
      "              g ",
      "              g ",
      "              g "
    ],
    [
      "              g ",
      "              g ",
      "              g ",
      "              g ",
      "              g ",
      "              g ",
      "              g ",
      "              g ",
      "              g ",
      "              g ",
      "              g ",
      "              g ",
      "              g ",
      "              g ",
      "              g ",
      "              g "
    ],
    [
      "ggggggggggggggg ",
      "ggggggggggggggg ",
      "ggggggggggggggg ",
      "ggggggggggggggg ",
      "ggggggggggggggg ",
      "ggggggggggggggg ",
      "ggggggggggggggg ",
      "ggggggggggggggg ",
      "ggggggggggggggg ",
      "ggggggggggggggg ",
      "ggggggggggggggg ",
      "ggggggggggggggg ",
      "ggggggggggggggg ",
      "ggggggggggggggg ",
      "ggggggggggggggg ",
      "ggggggggggggggg "
    ],
    [
      "  Y   Y    Y    ",
      " Y Y Y Y  Y Y   ",
      "  Y   Y    Y    ",
      "  Y   Y    Y    ",
      " Y Y Y Y  Y Y   ",
      "  Y   Y    Y    ",
      "                ",
      "   YY           ",
      "  Y  Y          ",
      "  Y  Y          ",
      "   YY    YY     ",
      "        Y  Y    ",
      "        Y  Y    ",
      "         YY     ",
      "YY    YY        ",
      "  Y  Y  Y       "
    ],
    [
      "  Y   Y    Y    ",
      " Y Y Y Y  Y Y   ",
      "  Y   Y    Y    ",
      "  Y   Y    Y    ",
      " Y Y Y Y  Y Y   ",
      "  Y   Y    Y    ",
      "                ",
      "   YY           ",
      "  YYYY          ",
      "  YYYY          ",
      "   YY    YY     ",
      "        YYYY    ",
      "        YYYY    ",
      "         YY     ",
      "YY    YY        ",
      "YYY  YYYY       "
    ],
    [
      "ggg   gggggg    ",
      "gggg gggggggg   ",
      "gggg gggggggg   ",
      "gggg gggggggg   ",
      "gggg gggggggg   ",
      "ggg   gggggg    ",
      "gg     gggg     ",
      " gggggg         ",
      "ggggggggg       ",
      "gggggggggg      ",
      "ggggggggggg     ",
      "gggggggggggg    ",
      "gggggggggggg    ",
      "ggggggggggggg   ",
      "ggggggggggggg   ",
      "ggggggggggggg   "
    ]
  ]
}