{
  "xsize": 16,
  "zsize": 16,
  "refpalette": "lostcities:base",
  "slices": [
    [
      "vvvvvvvvvvvvvvvv",
      "vvvvvvvvvvvvvvvv",
      "vvvvvvvvvvvvvvvv",
      "vvvvvvvvvvvvvvvv",
      "vvvvvvvvvvvvvvvv",
      "vvvvvvvvvvvvvvvv",
      "vvvvvvvvvvvvvvvv",
      "vvvvvvvvvvvvvvvv",
      "vvvvvvvvvvvvvvvv",
      "vvvvvvvvvvvvvvvv",
      "vvvvvvvvvvvvvvvv",
      "vvvvvvvvvvvvvvvv",
      "vvvvvvvvvvvvvvvv",
      "vvvvvvvvvvvvvvvv",
      "vvvvvvvvvvvvvvvv",
      "vvvvvvvvvvvvvvvv"
    ],
    [
      "                ",
      "                ",
      "                ",
      "    g      g    ",
      "     !!         ",
      "   !!!!!        ",
      "  !! !!         ",
      "                ",
      "                ",
      "                ",
      "                ",
      "                ",
      "    g      g    ",
      "                ",
      "                ",
      "                "
    ],
    [
      "                ",
      "                ",
      "                ",
      "    n gggg n    ",
      "     !          ",
      "    !!!         ",
      "     !          ",
      "                ",
      "                ",
      "                ",
      "                ",
      "                ",
      "    n gggg n    ",
      "                ",
      "                ",
      "                "
    ],
    [
      "                ",
      "                ",
      "       ff       ",
      "    ggffffgg    ",
      "     !ffff      ",
      "    !!ffff      ",
      "     !ffff      ",
      "      ffff      ",
      "      ffff      ",
      "      ffff      ",
      "      ffff      ",
      "      ffff      ",
      "    ggffffgg    ",
      "       ff       ",
      "                ",
      "                "
    ],
    [
      "                ",
      "      ffff      ",
      "     ff  ff     ",
      "    gf    fg    ",
      "    !ffffff     ",
      "   !!ff  ff     ",
      "    !ffffff     ",
      "     f    f     ",
      "     f    f     ",
      "     ffffff     ",
      "     ff  ff     ",
      "     ffffff     ",
      "    gf    fg    ",
      "     ff  ff     ",
      "      ffff      ",
      "                "
    ],
    [
      "       ff       ",
      "     ff  ff     ",
      "     f    f     ",
      "   gf      fg   ",
      "    ffffffff    ",
      "   !ff    ff    ",
      "    fff  fff    ",
      "    f  ff  f    ",
      "    f  ff  f    ",
      "    fff  fff    ",
      "    ff    ff    ",
      "    ffffffff    ",
      "   gf      fg   ",
      "     f    f     ",
      "     ff  ff     ",
      "       ff       "
    ]
  ]
}