{
  "xsize": 16,
  "zsize": 16,
  "refpalette": "pomkotsmechs:base",
  "slices": [
    [
      "vvvvvvvvvvvvvvvv",
      "vvvvvvvvvvvvvvvv",
      "vvvvvvvvvvvvvvvv",
      "vvvvvvvvvvvvvvvv",
      "vvvvvvvvvvvvvvvv",
      "vvvvvvvvvvvvvvvv",
      "vvvvvvvvvvvvvvvv",
      "vvvvvvvvvvvvvvvv",
      "vvvvvvvvvvvvvvvv",
      "vvvvvvvvvvvvvvvv",
      "vvvvvvvvvvvvvvvv",
      "vvvvvvvvvvvvvvvv",
      "vvvvvvvvvvvvvvvv",
      "vvvvvvvvvvvvvvvv",
      "vvvvvvvvvvvvvvvv",
      "vvvvvvvvvvvvvvvv"
    ],
    [
      "  Yggggggggggggg",
      "  Yggggggggggggg",
      "  YYY      YYY  ",
      "                ",
      "    ͲͲͲͲͲͲͲͲͲͲͲͲ",
      "    Ͳ ͲͲ   ͲͲ   ",
      "    ͲͲ  Ͳ Ͳ  Ͳ Ͳ",
      "    ͲͲ  Ͳ Ͳ  Ͳ Ͳ",
      "    Ͳ ͲͲ   ͲͲ   ",
      "    Ͳ           ",
      "    Ͳ ͲͲ   ͲͲ   ",
      "    ͲͲ  Ͳ Ͳ  Ͳ Ͳ",
      "    ͲͲ  Ͳ Ͳ  Ͳ Ͳ",
      "    Ͳ ͲͲ   ͲͲ   ",
      "    ͲͲͲͲͲͲͲͲͲͲͲͲ",
      "                "
    ],
    [
      "  Ygggg    !!   ",
      "   ggggggggggggg",
      "  Y Y      Y Y  ",
      "                ",
      "    ͲͲͲͲͲͲͲͲͲͲͲͲ",
      "    Ͳ ͲͲ   ͲͲ   ",
      "    ͲͲ  Ͳ Ͳ  Ͳ Ͳ",
      "    ͲͲ  Ͳ Ͳ  Ͳ Ͳ",
      "    Ͳ ͲͲ   ͲͲ   ",
      "    Ͳ           ",
      "    Ͳ ͲͲ   ͲͲ   ",
      "    ͲͲ  Ͳ Ͳ  Ͳ Ͳ",
      "    ͲͲ  Ͳ Ͳ  Ͳ Ͳ",
      "    Ͳ ͲͲ   ͲͲ   ",
      "    ͲͲͲͲͲͲͲͲͲͲͲͲ",
      "                "
    ],
    [
      "  Ygggg !!!!    ",
      "   ggggggggggggg",
      "  Y Y      Y Y  ",
      "                ",
      "    ͲͲͲͲͲͲͲͲͲͲͲͲ",
      "    Ͳ ͲͲ   ͲͲ   ",
      "    ͲͲ  Ͳ Ͳ  Ͳ Ͳ",
      "    ͲͲ  Ͳ Ͳ  Ͳ Ͳ",
      "    Ͳ ͲͲ   ͲͲ   ",
      "    Ͳ           ",
      "    Ͳ ͲͲ   ͲͲ   ",
      "    ͲͲ  Ͳ Ͳ  Ͳ Ͳ",
      "    ͲͲ  Ͳ Ͳ  Ͳ Ͳ",
      "    Ͳ ͲͲ   ͲͲ   ",
      "    ͲͲͲͲͲͲͲͲͲͲͲͲ",
      "                "
    ],
    [
      "  Yggggggggggggg",
      "   ggggggggggggg",
      "  Y Y      Y Y  ",
      "                ",
      "    ͲͲͲͲͲͲͲͲͲͲͲͲ",
      "      ͲͲ   ͲͲ   ",
      "     Ͳ  Ͳ Ͳ  Ͳ Ͳ",
      "     Ͳ  Ͳ Ͳ  Ͳ Ͳ",
      "      ͲͲ   ͲͲ   ",
      "    Ͳ           ",
      "    Ͳ ͲͲ   ͲͲ   ",
      "    ͲͲ  Ͳ Ͳ  Ͳ Ͳ",
      "    ͲͲ  Ͳ Ͳ  Ͳ Ͳ",
      "    Ͳ ͲͲ   ͲͲ   ",
      "    ͲͲͲͲͲͲͲͲͲͲͲͲ",
      "                "
    ],
    [
      "  YYY   !! Ygg g",
      "  Y Y       gggg",
      "  YYY      Y Y  ",
      "                ",
      "     ͲͲͲͲͲͲͲͲͲͲͲ",
      "       Ͳ   ͲͲ   ",
      "     Ͳ  Ͳ Ͳ  Ͳ Ͳ",
      "     Ͳ  Ͳ Ͳ  Ͳ Ͳ",
      "       Ͳ   ͲͲ   ",
      "                ",
      "    Ͳ ͲͲ   ͲͲ   ",
      "    ͲͲ  Ͳ Ͳ  Ͳ Ͳ",
      "    ͲͲ  Ͳ Ͳ  Ͳ Ͳ",
      "    Ͳ ͲͲ   ͲͲ   ",
      "    ͲͲͲͲͲͲͲͲͲͲͲͲ",
      "                "
    ]
  ]
}