{
  "xsize": 16,
  "zsize": 16,
  "refpalette": "pomkotsmechs:base",
  "slices": [
    [
      "vvvvvvvvvvvvvvvv",
      "vvvvvvvvvvvvvvvv",
      "vvvvvvvvvvvvvvvv",
      "vvvvvvvvvvvvvvvv",
      "vvvvvvvvvvvvvvvv",
      "vvvvvvvvvvvvvvvv",
      "vvvvvvvvvvvvvvvv",
      "vvvvvvvvvvvvvvvv",
      "vvvvvvvvvvvvvvvv",
      "vvvvvvvvvvvvvvvv",
      "vvvvvvvvvvvvvvvv",
      "vvvvvvvvvvvvvvvv",
      "vvvvvvvvvvvvvvvv",
      "vvvvvvvvvvvvvvvv",
      "vvvvvvvvvvvvvvvv",
      "vvvvvvvvvvvvvvvv"
    ],
    [
      "   ggggggggggggg",
      "   ggggggggggggg",
      "   ggggggggggggg",
      "   Ygggggggggggg",
      "   Ygggggggggggg",
      "   Ygggggggggggg",
      "   Ygggggggggggg",
      "   ggggggggggggg",
      "   ggggggggggggg",
      "   ggggggggggggg",
      "   ggggggggggggg",
      "   ggggggggggggg",
      "   gggg   gggggg",
      "   ggg      gggg",
      "   ggg      gggg",
      "   ggg      gggg"
    ],
    [
      "   gggg         ",
      "   gggg         ",
      "   gggg         ",
      "    Y           ",
      "    Y           ",
      "    Y           ",
      "    Y           ",
      "   gggg         ",
      "   gggg         ",
      "   gggg         ",
      "   gggg         ",
      "   gggg         ",
      "   ggg          ",
      "   ggg          ",
      "   ggg          ",
      "    gg          "
    ],
    [
      "   gggg         ",
      "   gggg         ",
      "   gggg         ",
      "     Y          ",
      "     Y          ",
      "     Y          ",
      "     Y          ",
      "   gggg         ",
      "   gggg         ",
      "   gggg         ",
      "   gggg         ",
      "   gggg         ",
      "   gggg         ",
      "   ggg          ",
      "    g           ",
      "                "
    ],
    [
      "   ggggggggggggg",
      "   ggggggggggggg",
      "   ggggggggggggg",
      "      gggggggggg",
      "      gggggggggg",
      "      gggggggggg",
      "      gggggggggg",
      "   ggggggggggggg",
      "   ggggggggggggg",
      "   ggggggggggggg",
      "   ggggggggggggg",
      "   ggggggg   ggg",
      "   g           g",
      "               g",
      "               g",
      "               g"
    ],
    [
      "          !!gggg",
      "            gggg",
      "            gggg",
      "           Ygggg",
      "           Ygggg",
      "           Ygggg",
      "           Ygggg",
      "            gggg",
      "            gggg",
      "             g g",
      "                ",
      "                ",
      "                ",
      "                ",
      "                ",
      "               g"
    ]
  ]
}