{
  "xsize": 16,
  "zsize": 16,
  "refpalette": "lostcities:base",
  "slices": [
    [
      "                ",
      "                ",
      "        Ͳ       ",
      "                ",
      "      ffff!     ",
      "     f  !!f!    ",
      "    f  !!!!f    ",
      "  Ͳ f  !!! f    ",
      "    f!!    f Ͳ  ",
      "   !f!!    f    ",
      "    !f    f     ",
      "      ffff      ",
      "                ",
      "       Ͳ        ",
      "                ",
      "                "
    ],
    [
      "                ",
      "                ",
      "                ",
      "                ",
      "      ffff!     ",
      "     f  !!f!    ",
      "    f   !!!f    ",
      "  Ͳ f!!    f    ",
      "    f!!!   f Ͳ  ",
      "    f!!    f    ",
      "     f    f     ",
      "      ffff      ",
      "                ",
      "       Ͳ        ",
      "                ",
      "                "
    ],
    [
      "                ",
      "                ",
      "                ",
      "                ",
      "      f         ",
      "     f   !!     ",
      "    f           ",
      "  Ͳ f !!!       ",
      "    f!!!!  f Ͳ  ",
      "    f!!!   f    ",
      "     f    f     ",
      "      ffff      ",
      "                ",
      "       Ͳ        ",
      "                ",
      "                "
    ],
    [
      "                ",
      "                ",
      "                ",
      "                ",
      "      f         ",
      "     f          ",
      "    f  !!       ",
      "  Ͳ f !!!!      ",
      "    f !!!  f Ͳ  ",
      "    f  !   f    ",
      "     f    f     ",
      "      ffff      ",
      "                ",
      "       Ͳ        ",
      "                ",
      "                "
    ],
    [
      "                ",
      "                ",
      "                ",
      "                ",
      "                ",
      "     f          ",
      "    ffff!!      ",
      "  Ͳ fffff!!     ",
      "    ffffffff Ͳ  ",
      "    ffffffff    ",
      "     ffffff     ",
      "      ffff      ",
      "                ",
      "       Ͳ        ",
      "                ",
      "                "
    ],
    [
      "                ",
      "                ",
      "                ",
      "                ",
      "                ",
      "                ",
      "        !!      ",
      "  ͲͲͲͲͲͲͲͲ!     ",
      "      ͲͲͲͲͲͲͲͲ  ",
      "       ͲͲ       ",
      "       Ͳ        ",
      "       Ͳ        ",
      "       Ͳ        ",
      "       Ͳ        ",
      "                ",
      "                "
    ]
  ]
}