{
  "xsize": 16,
  "zsize": 16,
  "refpalette": "lostcities:base",
  "slices": [
    [
      "                ",
      "            !   ",
      "    gg    gg!!  ",
      "   gggg  gggg   ",
      "   g  g  g  g   ",
      "   g  g  g  g   ",
      "   g  g  g  g   ",
      " YYgggg! ggggYY ",
      "  Y gg!   gg Y! ",
      "  Y         !Y!!",
      " YY          YY ",
      "                ",
      "    gg    gg    ",
      "   gggg  gggg   ",
      "                ",
      "                "
    ],
    [
      "                ",
      "    gg    gg!   ",
      "   gggg  gggg!  ",
      "   g  g  g  g   ",
      "   g  g  g !g   ",
      "   g  g  g !g   ",
      "    gg!   gg    ",
      " YY  !!!     YY ",
      " YY   !      YY ",
      " YY          YY!",
      " YY          YY ",
      "    gg    gg    ",
      "   gggg  gggg   ",
      "   g  g  g  g   ",
      "   g  g  g  g   ",
      "                "
    ],
    [
      "   gggg  gggg   ",
      "   g  g  g  g   ",
      "   g  g  g !g!  ",
      "   g  g  g !g!  ",
      "   gggg  gggg!  ",
      "    gg    gg!   ",
      "      !    !    ",
      " YY  !!!   !!YY ",
      " YY  !!!     YY!",
      " YY   !      YY!",
      " YY gg    gg YY ",
      "   gggg  gggg   ",
      "   g  g  g  g   ",
      "   g  g  g  g   ",
      "   gggg  gggg   ",
      "                "
    ],
    [
      "   g  g  g  g   ",
      "   g  g  g  g   ",
      "   g  g  g !g!  ",
      "   gggg  gggg!  ",
      "    gg    gg!!  ",
      "          !!!   ",
      "          !!!   ",
      " YY   !   !!!YY ",
      " YY gg!!  gg!YY!",
      " YYgggg  ggggYY ",
      " YYg  g  g  gYY ",
      "   g  g  g  g   ",
      "   g  g  g  g   ",
      "   gggg  gggg   ",
      "    gg    gg    ",
      "                "
    ],
    [
      "   g  g  g  g   ",
      "   gggg  gggg   ",
      "    gg    gg!   ",
      "            !   ",
      "           !!   ",
      "          !!!!  ",
      "          !!!!  ",
      "    gg!   gg!!! ",
      "   gggg! gggg!!!",
      "   g  g  g  g!! ",
      "   g  g  g  g   ",
      "   g  g  g  g   ",
      "    gg    gg    ",
      "    gg    gg    ",
      "                ",
      "                "
    ],
    [
      "   gggg  gggg   ",
      "    gg    gg    ",
      "                ",
      "                ",
      "            !   ",
      "           !!!  ",
      "    gg    gg!!  ",
      "   g  g  g !g!  ",
      "   g !g! g  g!! ",
      "   g !g! g  g   ",
      "   gggg  gggg   ",
      "    gg    gg    ",
      "                ",
      "                ",
      "                ",
      "                "
    ]
  ]
}