{
  "xsize": 16,
  "zsize": 16,
  "refpalette": "pomkotsmechs:base",
  "slices": [
    [
      "         g    gg",
      "         Y  YYYg",
      "       ggYYYYYYg",
      "       ggYYYYYYg",
      "         ggggggg",
      "          YYYYY ",
      "          YYYYY ",
      "          YYYYY ",
      "          YYYYY ",
      "          YYYYY ",
      "         YYYYYY ",
      "        gggggggg",
      "       !gYYYYYYg",
      "       !gYYYYYYg",
      "        !YYYYYYg",
      "         g    gg"
    ],
    [
      "         g   ggg",
      "         Y  YYYg",
      "        gYYYYYYg",
      "         YYYYYYg",
      "         ggggggg",
      "          YYYYY ",
      "          YYYYY ",
      "          YYYYY ",
      "          YYYYY ",
      "         YYYYYY ",
      "         YYYYYY ",
      "        !ggggggg",
      "       !!YYYYYYg",
      "        !YYYYYYg",
      "         YYYYYYg",
      "         g   ggg"
    ],
    [
      "             g!g",
      "         Y  YYYg",
      "        gYYYYYYg",
      "         YYYYYYg",
      "         ggggggg",
      "          YYYYY ",
      "          YYYYY ",
      "          YYYYY ",
      "          YYYYY ",
      "         YYYYYY ",
      "         YYYYYY ",
      "        !ggggggg",
      "        !YYYYYYg",
      "         YYYYYYg",
      "         YYYYYYg",
      "         g  gg g"
    ],
    [
      "              !g",
      "         YYYYYYg",
      "        gYYYYYYg",
      "         YYYYYYg",
      "         ggggggg",
      "          YYYYY ",
      "          YYYYY ",
      "          YYYYY ",
      "          YYYYY ",
      "          YYYYY ",
      "         !YYYYY ",
      "        !ggggggg",
      "         YYYYYYg",
      "         YYYYYYg",
      "         YYYYYYg",
      "         gggg  g"
    ],
    [
      "              !g",
      "          YY YYg",
      "         gYYYYYg",
      "         gYYYYYg",
      "         ggggggg",
      "           YYYY ",
      "           YYYY ",
      "           YYYY ",
      "           YYYY ",
      "        g!YYYYY ",
      "         !!YYYY ",
      "        !ggggggg",
      "         gYYYYYg",
      "         gYYYYYg",
      "          YYYYYg",
      "          gg   g"
    ],
    [
      "          g    g",
      "          YYYYYg",
      "          YYYYYg",
      "         gYYYYYg",
      "           ggggg",
      "           YYYY ",
      "           YYYY ",
      "           YYYY ",
      "        g!YYYYY ",
      "        g!YYYYY ",
      "         !!YYYY ",
      "         ggggggg",
      "         gYYYYYg",
      "         gYYYYYg",
      "          YYYYYg",
      "          g    g"
    ]
  ]
}