{
  "xsize": 16,
  "zsize": 16,
  "refpalette": "pomkotsmechs:base",
  "slices": [
    [
      "    gggggggg !!n",
      "gg ggggggggggggg",
      "gggggggggggggggg",
      "             ggg",
      " hi          ggg",
      " jk          ggg",
      "             ggg",
      "             ggg",
      "             ggg",
      "             ggg",
      "             ggg",
      "             ggg",
      "             ggg",
      "             ggg",
      "             ggg",
      "             ggg"
    ],
    [
      "gg  gggggggg !!g",
      "gggggggggggggggg",
      "gggggggggggggggg",
      "             ggg",
      " hi          ggg",
      " jk          ggg",
      "             ggg",
      "             ggg",
      "             ggg",
      "             ggg",
      "             ggg",
      "             ggg",
      "             ggg",
      "             ggg",
      "             ggg",
      "             ggg"
    ],
    [
      "gg  gg       !gg",
      "ggggggoooooooog!",
      "gg  ggg   g g g ",
      "             ggg",
      " hi          ggg",
      " jk           r ",
      "              r ",
      "              r ",
      "              r!",
      "             !r!",
      "              r!",
      "              r ",
      "              r ",
      "              r ",
      "             ggg",
      "              g "
    ],
    [
      "gg  gg       !g!",
      "gg  gg        g ",
      "gg  ggg   g g g ",
      "             ggg",
      " ff          ggg",
      " ff             ",
      "                ",
      "                ",
      "              !!",
      "             !!!",
      "              !!",
      "                ",
      "                ",
      "                ",
      "             ggg",
      "                "
    ],
    [
      "gg  gg       !g!",
      "gg  gg        g!",
      "ggffgggfffgfgfg ",
      "ffff         ggg",
      "fxxffffffffffggg",
      "fxxfffffffffff  ",
      "ffffffffffffff  ",
      " ff          f  ",
      " ff          f !",
      " ff          f!!",
      " ff          f !",
      " ff          f  ",
      " ff          f  ",
      " ff          f  ",
      " ff          ggg",
      " ff             "
    ],
    [
      "gggggggggggggggg",
      "gggggggggggggggg",
      "gggggggggggggggg",
      "gggggggggggggggg",
      "gggggggggggggggg",
      "gggggggggggggggg",
      "gggggggggggggggg",
      "gggggͱͱͱͱͱͱͱgggg",
      "gggggͱͱͱͱͱͱͱgggg",
      "gggggͱͱͱͱͱͱͱgggg",
      "gggggͱͱͱͱͱͱͱgggg",
      "gggggͱͱͱͱͱͱͱgggg",
      "gggggͱͱͱͱͱͱͱgggg",
      "gggggͱͱͱͱͱͱͱgggg",
      "gggggͱͱͱͱͱͱͱgggg",
      "gggggͱͱͱͱͱͱͱgggg"
    ]
  ]
}