{
  "xsize": 16,
  "zsize": 16,
  "refpalette": "pomkotsmechs:base",
  "slices": [
    [
      "ffffffffffffffff",
      "ffffffffffffffff",
      "ffffffffffffffff",
      "fffggggggggggggg",
      "fffggggggggggggg",
      "fffggggggggggggg",
      "fffggggggggggggg",
      "fffggggggggggggg",
      "fffggggggggggggg",
      "fffggggggggggggg",
      "fffggggggggggggg",
      "fffggggggggggggg",
      "fffggggggggggggg",
      "fffggggggggggggg",
      "fffggggggggggggg",
      "fffggggggggggggg"
    ],
    [
      "ff              ",
      "ff              ",
      "                ",
      "                ",
      "                ",
      "                ",
      "           !!!  ",
      "             !! ",
      "             !!!",
      "             !!#",
      "              ! ",
      "                ",
      "                ",
      "                ",
      "                ",
      "                "
    ],
    [
      "ff              ",
      "ff              ",
      "                ",
      "                ",
      "                ",
      "                ",
      "                ",
      "                ",
      "             !! ",
      "            !!!$",
      "             !! ",
      "                ",
      "                ",
      "                ",
      "                ",
      "                "
    ],
    [
      "hi              ",
      "jk              ",
      "                ",
      "                ",
      "                ",
      "                ",
      "                ",
      "                ",
      "             !  ",
      "            !!!$",
      "             !  ",
      "                ",
      "                ",
      "                ",
      "                ",
      "                "
    ],
    [
      "hi              ",
      "jk              ",
      "               %",
      "               %",
      "               &",
      "               '",
      "              ('",
      "              ('",
      "             !('",
      "            !!('",
      "            !!('",
      "             )('",
      "             *('",
      "             '('",
      "             '('",
      "             '('"
    ],
    [
      "hi              ",
      "jk             +",
      "               v",
      "              ,v",
      "              ''",
      "              ''",
      "              ''",
      "              ''",
      "              ''",
      "             (''",
      "            !*''",
      "            !*''",
      "             '''",
      "            -'''",
      "            ''''",
      "           (''''"
    ]
  ]
}