{
  "xsize": 16,
  "zsize": 16,
  "refpalette": "pomkotsmechs:base",
  "slices": [
    [
      "      gggg      ",
      " gggggggggggggg ",
      " gggggggggggggg ",
      "!gggggggggggggg ",
      "!gggggggggggggg ",
      " gggggggggggggg ",
      " gggggggggggggg ",
      " gggggggggggggg ",
      " gggggggggggggg ",
      " gggggggggggggg ",
      " gggggggggggggg ",
      " gggggggggggggg ",
      " gggggggggggggg ",
      " gggggggggggggg ",
      " gggggggggggggg ",
      "                "
    ],
    [
      "       ͳͳ       ",
      " gg    ͳͳ    gg ",
      " g     ͳͳ     g ",
      " !!   gͶͶg      ",
      " !!! gͶͶͶͶg     ",
      " !ͳͳͳͶͶͶͶͶͶͳͳͳ  ",
      "  ͳͳͳͶͶͶͶͶͶͳͳͳ  ",
      "     gͶͶͶͶg     ",
      "      gͶͶg      ",
      "       ͳͳ       ",
      "       ͳͳ       ",
      "    Ͳ  ͳͳ  Ͳ    ",
      "                ",
      " g            g ",
      " gg Ͳ      Ͳ gg ",
      "                "
    ],
    [
      "       ͳͳ       ",
      "       ͳͳ       ",
      "       ͳͳ       ",
      "      gͶͶg!     ",
      "  !  gͶͶͶͶg!    ",
      " !ͳͳͳͶͶͶͶͶͶͳͳͳ  ",
      "  ͳͳͳͶͶͶͶͶͶͳͳͳ  ",
      "     gͶͶͶͶg     ",
      "      gͶͶg      ",
      "       ͳͳ       ",
      "       ͳͳ       ",
      "    Ͳ  ͳͳ  Ͳ    ",
      "    !           ",
      "                ",
      "   !Ͳ      Ͳ    ",
      "                "
    ],
    [
      "                ",
      "       ͳͳ       ",
      "       ͳͳ       ",
      "      gͶͶg!     ",
      "  !! gͶͶͶͶg!    ",
      " !!ͳͳͶͶͶͶͶͶͳͳ   ",
      "  !ͳͳͶͶͶͶͶͶͳͳ   ",
      "   ! gͶͶͶͶg     ",
      "      gͶͶg      ",
      "       ͳͳ       ",
      "    Ͳ  ͳͳ  Ͳ    ",
      "   ͲͲͲͲͲͲͲͲͲͲ   ",
      "   !Ͳ!     Ͳ    ",
      "   !Ͳ      Ͳ    ",
      "  !ͲͲͲͲͲͲͲͲͲͲ   ",
      "   !Ͳ      Ͳ    "
    ],
    [
      "                ",
      "                ",
      "       ͳͳ       ",
      "      gͶͶg!!    ",
      "     gͶͶͶͶg!!   ",
      "  !!ͳͶͶͶͶͶͶͳ!   ",
      "  !!ͳͶͶͶͶͶͶͳ    ",
      "   !!gͶͶͶͶg     ",
      "     !gͶͶg      ",
      "       ͳͳ       ",
      "                ",
      "    Ͳ      Ͳ    ",
      "   !!!          ",
      "  !!!!          ",
      "  !!Ͳ      Ͳ    ",
      "   !            "
    ],
    [
      "                ",
      "                ",
      "       ͳͳ       ",
      "      gͶͶg      ",
      "     gͶͶͶͶg!    ",
      "    ͳͶͶͶͶͶͶͳ!   ",
      "   !ͳͶͶͶͶͶͶͳ    ",
      "    !gͶͶͶͶg     ",
      "     !gͶͶg      ",
      "       ͳͳ       ",
      "                ",
      "    Ͳ      Ͳ    ",
      "   !!!          ",
      "  !!!           ",
      "  !!Ͳ      Ͳ    ",
      "   !            "
    ]
  ]
}