{
  "xsize": 16,
  "zsize": 16,
  "refpalette": "lostcities:base",
  "slices": [
    [
      "ggggggggggggg!  ",
      "ggggggggggggg!  ",
      "gggggggggg  !  g",
      "gggggggggg    g ",
      "ggggggggggg!!   ",
      "gggggggggggggggg",
      "gggggggggggggggg",
      "gggggggggggggggg",
      "gggggggggggggggg",
      "gggggggggggggggg",
      "gggggggggggggggg",
      "gggggggggggggggg",
      "gggggggggggggggg",
      "gggggggggggggggg",
      "gggggggggggggggg",
      "gggggggggggggggg"
    ],
    [
      "            !   ",
      " ggggggg    !   ",
      " ggggggg        ",
      " ggggggg        ",
      " ggggggg        ",
      " ggggggg   !!   ",
      " ggggggg   !    ",
      " ggggggg        ",
      " !!!            ",
      "!!              ",
      "!               ",
      "                ",
      "                ",
      "                ",
      "                ",
      "               !"
    ],
    [
      "                ",
      " ggggggg        ",
      " ggggggg        ",
      " ggggggg        ",
      " ggggggg        ",
      " ggggggg        ",
      " ggggggg        ",
      " ggggggg        ",
      "                ",
      "                ",
      "                ",
      "                ",
      "                ",
      "                ",
      "                ",
      "                "
    ],
    [
      "                ",
      "                ",
      "  ggggg         ",
      "  ggggg         ",
      "  ggggg         ",
      "  ggggg         ",
      "  ggggg         ",
      "                ",
      "                ",
      "                ",
      "                ",
      "                ",
      "                ",
      "                ",
      "                ",
      "                "
    ],
    [
      "                ",
      "                ",
      "  ggggg         ",
      "  ggggg         ",
      "  ggggg         ",
      "  ggggg         ",
      "  ggggg         ",
      "                ",
      "                ",
      "                ",
      "                ",
      "                ",
      "                ",
      "                ",
      "                ",
      "                "
    ],
    [
      "                ",
      "                ",
      "                ",
      "                ",
      "                ",
      "                ",
      "                ",
      "                ",
      "                ",
      "                ",
      "                ",
      "                ",
      "                ",
      "                ",
      "                ",
      "                "
    ]
  ]
}