{
  "xsize": 16,
  "zsize": 16,
  "refpalette": "lostcities:base",
  "slices": [
    [
      " gg            g",
      " !Y!            ",
      "  Y             ",
      "  Y             ",
      "  Y             ",
      " !Y!            ",
      "  Y             ",
      "  Y             ",
      "  Y             ",
      "  Y             ",
      "  Y             ",
      " ggg            ",
      "ggggg      ! !  ",
      "gggggYYYYYYYYYYg",
      "ggggg      ! ! g",
      " ggg            "
    ],
    [
      " gg            g",
      " !Y!            ",
      "  Y             ",
      "  Y             ",
      "  Y             ",
      " !Y!            ",
      "  Y             ",
      "  Y             ",
      "  Y             ",
      "  Y             ",
      "  Y             ",
      "  g             ",
      " ggg         !  ",
      "gggggYYYYYYYYYYg",
      " ggg         ! g",
      "  g             "
    ],
    [
      "!gg!           g",
      " !Y!            ",
      "  Y             ",
      "  Y             ",
      "  Y             ",
      " !Y!            ",
      "  Y             ",
      "  Y             ",
      "  Y             ",
      "  Y             ",
      "  Y             ",
      "  g             ",
      " ggg         !  ",
      "gggggYYYYYYYYYYg",
      " ggg         ! g",
      "  g             "
    ],
    [
      "!gg            g",
      " !Y             ",
      "  Y             ",
      "  Y             ",
      "  Y             ",
      " !Y!            ",
      " !Y!            ",
      "  Y             ",
      "  Y             ",
      "  Y             ",
      "  Y             ",
      "  g             ",
      " ggg         !  ",
      "gggggYYYY YYYYYg",
      " ggg         ! g",
      "  g             "
    ],
    [
      "!gg            g",
      " !Y             ",
      "  Y             ",
      "  Y             ",
      "  Y             ",
      " !Y             ",
      "!!Y!            ",
      " !Y             ",
      "  Y             ",
      "  Y             ",
      "  Y             ",
      "  g             ",
      " ggg         !! ",
      "gggggYY     YYYg",
      " ggg         !!g",
      "  g             "
    ],
    [
      "!gg         !! g",
      "g!Yg       !! g ",
      "  Y             ",
      "  Y             ",
      "  Y             ",
      "!!Y             ",
      "!!Y!!!          ",
      "!!Y             ",
      "  Y             ",
      "  Y             ",
      "  Y            !",
      "  g           !!",
      " ggg          g ",
      "gggggYY     YYYg",
      " ggg         !!g",
      "  g          !g "
    ]
  ]
}