{
  "xsize": 16,
  "zsize": 16,
  "refpalette": "lostcities:base",
  "slices": [
    [
      "͵͵͵͵͵͵͵͵͵͵͵vvv͵͵",
      "͵͵͵͵͵͵͵͵͵͵͵͵vv͵͵",
      "͵͵͵͵͵͵͵͵͵͵͵͵͵v͵͵",
      "͵͵͵͵͵͵͵͵͵͵͵͵͵v͵͵",
      "͵͵͵͵͵͵͵͵͵͵͵͵͵͵͵͵",
      "͵͵͵͵͵͵͵͵͵͵͵͵͵͵͵͵",
      "͵͵͵͵͵͵͵͵͵͵͵͵͵͵͵͵",
      "͵͵͵͵͵͵͵͵͵͵͵͵͵͵͵͵",
      "͵͵͵͵͵͵͵͵͵͵͵͵͵͵͵͵",
      "͵͵͵͵͵͵͵͵͵͵͵͵͵͵͵͵",
      "͵͵͵͵͵͵͵͵͵͵͵͵͵v͵͵",
      "͵͵͵͵͵͵͵͵͵͵͵͵͵v͵͵",
      "͵͵͵͵͵͵͵͵͵͵͵͵vv͵͵",
      "͵͵͵͵͵͵͵͵͵͵͵vvv͵͵",
      "͵͵͵͵͵͵͵͵͵͵vvvv͵͵",
      "vv͵͵͵͵͵͵vvvvvvvv"
    ],
    [
      "ffffffffffffffff",
      "ffffffffffffffff",
      "ffffffffffffffff",
      "ffffffffffffffff",
      "ffffffffffffffff",
      "ffffffffffffffff",
      "ffffffffffffffff",
      "ffffffffffffffff",
      "ffffffffffffffff",
      "ffffffffffffffff",
      "ffffffffffffffff",
      "ffffffffffffffff",
      "ffffffffffffffff",
      "ffffffffffffffff",
      "ffffffffffffffff",
      "ffffffffffffffff"
    ],
    [
      "                ",
      " n            n ",
      "                ",
      "                ",
      " n            n ",
      "                ",
      "                ",
      "                ",
      " n            n ",
      "                ",
      "                ",
      " n            n ",
      "                ",
      "                ",
      "                ",
      " n            n "
    ],
    [
      "ʹʹ            ʹʹ",
      "ʹʹ            ʹʹ",
      "                ",
      "                ",
      "ʹʹ            ʹʹ",
      "ʹʹ            ʹʹ",
      "ʹʹ            ʹʹ",
      "ʹʹ            ʹʹ",
      "ʹʹ            ʹʹ",
      "                ",
      "                ",
      "ʹʹ            ʹʹ",
      "ʹʹ            ʹʹ",
      "ʹʹ            ʹʹ",
      "ʹʹ            ʹʹ",
      "ʹʹ            ʹʹ"
    ],
    [
      " f            f ",
      "fʹ            ʹf",
      "                ",
      "                ",
      "fʹ            ʹf",
      " f            f ",
      " f            f ",
      " f            f ",
      "fʹ            ʹf",
      "                ",
      "                ",
      "fʹ            ʹf",
      " f            f ",
      " f            f ",
      " f            f ",
      "fʹ            ʹf"
    ],
    [
      " f            f ",
      "fʹ            ʹf",
      "                ",
      "                ",
      "fʹ            ʹf",
      " f            f ",
      " f            f ",
      " f            f ",
      "fʹ            ʹf",
      "                ",
      "                ",
      "fʹ            ʹf",
      " f            f ",
      " f            f ",
      " f            f ",
      "fʹ            ʹf"
    ]
  ]
}