{
  "xsize": 16,
  "zsize": 16,
  "refpalette": "lostcities:base",
  "slices": [
    [
      "    gg    gg    ",
      "                ",
      "                ",
      "                ",
      "    gg    gg!   ",
      "   gggg  gggg!  ",
      "   g  g  g  g   ",
      "   g  g  g  g   ",
      "   g !g! g  g   ",
      "   gggg! gggg   ",
      "    gg!   gg    ",
      "                ",
      "                ",
      "                ",
      "                ",
      "                "
    ],
    [
      "                ",
      "                ",
      "                ",
      "    gg    gg    ",
      "   gggg  gggg   ",
      "   g  g  g !g!  ",
      "   g  g  g  g   ",
      "   g !g  g  g   ",
      "    gg!!  gg    ",
      "     !!         ",
      "                ",
      "                ",
      "                ",
      "                ",
      "                ",
      "                "
    ],
    [
      "   g            ",
      "    gg    gg    ",
      "   gggg  gggg   ",
      "   g  g  g  g   ",
      "   g  g  g  g   ",
      "   g !g  g !g!  ",
      "   gggg  gggg   ",
      "    gg!   gg    ",
      "    !!!         ",
      "     !          ",
      "                ",
      "                ",
      "                ",
      "                ",
      "                ",
      "                "
    ],
    [
      "  g gg    gg    ",
      "   gggg  gggg   ",
      "   g  g  g  g   ",
      "   g  g  g  g   ",
      "   g !g! g  g   ",
      "   gggg! gggg!  ",
      "    gg!   gg!   ",
      "    !!!         ",
      "    !!!         ",
      "     !          ",
      "                ",
      "                ",
      "                ",
      "                ",
      "                ",
      "                "
    ],
    [
      "   gggg  gggg   ",
      "  gg  g  g  g   ",
      "   g  g  g  g   ",
      "   gggg! gggg   ",
      "    gg!!  gg    ",
      "     !!     !   ",
      "     !          ",
      "     !          ",
      "     !          ",
      "                ",
      "                ",
      "                ",
      "                ",
      "                ",
      "                ",
      "                "
    ],
    [
      "   g  g  g  g   ",
      "   g  g  g  g   ",
      "  ggggg! gggg   ",
      "     !!!        ",
      "    g !    g    ",
      "                ",
      "                ",
      "                ",
      "                ",
      "                ",
      "                ",
      "                ",
      "                ",
      "                ",
      "                ",
      "                "
    ]
  ]
}