{
  "xsize": 16,
  "zsize": 16,
  "refpalette": "pomkotsmechs:base",
  "slices": [
    [
      "gg!!! g         ",
      "gYYYYY          ",
      "gYYYYYY         ",
      "gYYYYYYg        ",
      "ggggggggg       ",
      " YYYYY          ",
      " YYYYY          ",
      " YYYYY!         ",
      " YYYYY!!        ",
      " YYYYYY!        ",
      " YYYYYY         ",
      "ggggggggg       ",
      "gYYYYYYgg       ",
      "gYYYYYYgg       ",
      "gYYYYYY         ",
      "gg  ! g         "
    ],
    [
      "ggg!! g         ",
      "gYYYYY          ",
      "gYYYYYY         ",
      "gYYYYYY         ",
      "gggggggg        ",
      " YYYYYY         ",
      " YYYYY          ",
      " YYYYY          ",
      " YYYYY!         ",
      " YYYYYY!        ",
      " YYYYYY         ",
      "gggggggg        ",
      "gYYYYYYg        ",
      "gYYYYYYg        ",
      "gYYYYYY         ",
      "ggg!!!g         "
    ],
    [
      "g gg! g         ",
      "gYYYYY          ",
      "gYYYYYY         ",
      "gYYYYYY         ",
      "gggggggg        ",
      " YYYYYY         ",
      " YYYYY          ",
      " YYYYY          ",
      " YYYYY!         ",
      " YYYYYY!        ",
      " YYYYYY!        ",
      "gggggggg        ",
      "gYYYYYYg        ",
      "gYYYYYYg        ",
      "gYYYYYY         ",
      "g gg!!g         "
    ],
    [
      "g !gggg         ",
      "gYYYYY          ",
      "gYYYYY          ",
      "gYYYYYY         ",
      "gggggggg        ",
      " YYYYY          ",
      " YYYYY          ",
      " YYYYY          ",
      " YYYYY!!        ",
      " YYYYYY!!       ",
      " YYYYYY!!       ",
      "gggggggg        ",
      "gYYYYYYg        ",
      "gYYYYYYg        ",
      "gYYYYYY         ",
      "g !gggg         "
    ],
    [
      "g !!gg          ",
      "gYYYY           ",
      "gYYYYY          ",
      "gYYYYYg         ",
      "gggggg          ",
      " YYYY           ",
      " YYYY           ",
      " YYYY           ",
      " YYYY           ",
      " YYYYY!g        ",
      " YYYYY!g!       ",
      "gggggggg        ",
      "gYYYYYgg        ",
      "gYYYYYgg        ",
      "gYYYYY          ",
      "g !!gg          "
    ],
    [
      "g  ! g          ",
      "gYYYYY          ",
      "gYYYYY          ",
      "gYYYYY          ",
      "gggggg          ",
      " YYYY           ",
      " YYYY           ",
      " YYYY           ",
      " YYYY!!         ",
      " YYYYY!g        ",
      " YYYYY!g!       ",
      "gggggggg        ",
      "gYYYYYgg        ",
      "gYYYYYg         ",
      "gYYYYY          ",
      "g  ! g          "
    ]
  ]
}