{
  "xsize": 16,
  "zsize": 16,
  "refpalette": "pomkotsmechs:base",
  "slices": [
    [
      "                ",
      "     fffffff    ",
      "     f    ff    ",
      "     f    ff    ",
      "     f    ff    ",
      "     f    ff    ",
      "     f    ff    ",
      "     f    ff    ",
      "vv   f    ff    ",
      "vvvv f    ff    ",
      "vvvvvf    ff    ",
      "vvvvvf    ff    ",
      "vvvvvfffffff    ",
      "vvvvvvv         ",
      "vvvvvvvv        ",
      "vvvvvvvv        "
    ],
    [
      "                ",
      "    ffffffff    ",
      "ffffff     f    ",
      "ffffff     f    ",
      "ffffff     f    ",
      "ffffff     f    ",
      "ffffff!    f    ",
      "ffffff     f    ",
      "ffffff     f    ",
      "ffffff     f    ",
      "ffffff     f    ",
      "ffffff     f    ",
      "ffffffffffff    ",
      "ffffff          ",
      "ffffff          ",
      "ffffff          "
    ],
    [
      "                ",
      "    fffffff     ",
      "ffffff    f     ",
      "    ff    f     ",
      "    ff    f     ",
      "    ff!   f     ",
      "  n ff!   f     ",
      "    ff    f     ",
      "    ff    f     ",
      "    ff    f     ",
      "  n ff    f     ",
      "    ff    f     ",
      "    fffffff     ",
      "  n  f          ",
      "     f          ",
      "     f          "
    ],
    [
      "                ",
      "   ffffffff     ",
      "ffffff    f     ",
      "   f f    f     ",
      "   f f!   f     ",
      "   f!f!!  f     ",
      "ʹʹʹf!f!   f     ",
      "ʹʹʹf f    f     ",
      "ʹʹʹf f    f     ",
      "ʹʹʹf f    f     ",
      "ʹʹʹf f    f     ",
      "   f f    f     ",
      "   ffffffff     ",
      "ʹʹʹ  f          ",
      "ʹʹʹ  f          ",
      "ʹʹʹ  f          "
    ],
    [
      "                ",
      "   fffffff      ",
      "ffffff   f      ",
      "   f f   f      ",
      "   f f!  f      ",
      "   f f!! f      ",
      "ffʹf!f!  f      ",
      "  ff!f   f      ",
      "  ff!f   f      ",
      "ͳͳff f   f      ",
      "ffʹf f   f      ",
      "   f f   f      ",
      "   fffffff      ",
      "ffʹ  f          ",
      "  f  f          ",
      "  f  f          "
    ],
    [
      "                ",
      "  ffffffff      ",
      "ffffff   f      ",
      "  f  f   f      ",
      "  f  f!  f      ",
      "  f  f!! f      ",
      "ffʹ!!f!  f      ",
      "  f!!f   f      ",
      " !f!!f   f      ",
      "  f! f   f      ",
      "ffʹ  f   f      ",
      "  f  f   f      ",
      "  ffffffff      ",
      "ffʹ  f          ",
      "  f  f          ",
      "  f  f          "
    ]
  ]
}