{
  "xsize": 16,
  "zsize": 16,
  "refpalette": "lostcities:base",
  "slices": [
    [
      "     gggggg     ",
      "   gggggggggg   ",
      "  ggggggggggg   ",
      " ggggggggggg!   ",
      "!gggggggggg!!   ",
      "ggggggggggg!   g",
      "g!g ggggg!!    g",
      "g g ggg !      g",
      "g!g gg         g",
      "g!g!gg       ggg",
      "ggggggg   gggggg",
      "!gggggggggggggg ",
      " gggggggggggggg ",
      "  gggggggggggg  ",
      "   gggggggggg   ",
      "     gggggg     "
    ],
    [
      "                ",
      "                ",
      "      gggg      ",
      "    gg    g     ",
      " ! g    !!!!    ",
      "!!!g   !!!!!!   ",
      "!!     !!!!!    ",
      "        !!      ",
      "                ",
      " !!             ",
      "!! g        g   ",
      "   g        g   ",
      "    gg    gg    ",
      "      gggg      ",
      "                ",
      "                "
    ],
    [
      "                ",
      "                ",
      "      gggg      ",
      "    gg    g     ",
      " ! g     !!!    ",
      "!!!g    !!!!!   ",
      "!!!     !!!!    ",
      " !       !      ",
      "                ",
      "             g  ",
      "   g        g   ",
      "   g        g   ",
      "    gg    gg    ",
      "      gggg      ",
      "                ",
      "                "
    ],
    [
      "                ",
      "                ",
      "      gggg      ",
      "    gg    g     ",
      "   g      !!    ",
      " ! g     !!!!   ",
      "!!!     !!!! g  ",
      " !       !!  g  ",
      "             g  ",
      "             g  ",
      "            g   ",
      "            g   ",
      "    gg    gg    ",
      "      gggg      ",
      "                ",
      "                "
    ],
    [
      "     gggggg     ",
      "   gggggggggg   ",
      "  gggggggggggg  ",
      " ggggg    gg    ",
      " ggg      !!!   ",
      "gggg!    !!!!!  ",
      "!!!!     !!!!g  ",
      " !        !! g  ",
      "             g  ",
      "             g  ",
      "            gg  ",
      "            gg  ",
      "     g    gggg  ",
      "   ggggggggggg  ",
      "   gggggggggg   ",
      "     gggggg     "
    ],
    [
      "     gggggg     ",
      "   gggggggggg   ",
      "  gggggggggggg  ",
      " ggggg    ggg   ",
      " ggg       !g   ",
      "gggg!     !!g!  ",
      "!gg!  g  g!!!   ",
      " !g        ! g  ",
      "             g  ",
      "             g  ",
      "            gg  ",
      "            gg  ",
      "          gggg  ",
      "    gggggggggg  ",
      "   gggggggggg   ",
      "     gggggg!    "
    ]
  ]
}