{
  "xsize": 16,
  "zsize": 16,
  "refpalette": "pomkotsmechs:base",
  "slices": [
    [
      "fffggggggggggggg",
      "fffggggggggggggg",
      "fffggggggggggggg",
      "fffggggggggggggg",
      "fffggggggggggggg",
      "fffggggggggggggg",
      "fffggggggggggggg",
      "fffggggggggggggg",
      "fffggggggggggggg",
      "fffggggggggggggg",
      "fffggggggggggggg",
      "fffggggggggggggg",
      "fffggggggggggggg",
      "ffffffffffffffff",
      "ffffffffffffffff",
      "ffffffffffffffff"
    ],
    [
      "             !!!",
      "        !    !!!",
      "        !!    ! ",
      "         !!! #  ",
      "           !!   ",
      "            !!  ",
      "            !!!!",
      "             !!!",
      "              !!",
      "               !",
      "                ",
      "                ",
      "                ",
      "                ",
      "ff              ",
      "ff              "
    ],
    [
      "              ! ",
      "              ! ",
      "                ",
      "           !!$  ",
      "            !!  ",
      "            !!! ",
      "            !!!!",
      "             !!!",
      "              !!",
      "                ",
      "                ",
      "                ",
      "                ",
      "                ",
      "ff              ",
      "ff              "
    ],
    [
      "                ",
      "          !     ",
      "          !!!   ",
      "          !!!$  ",
      "           !!!! ",
      "            !!! ",
      "             !! ",
      "              !!",
      "                ",
      "                ",
      "                ",
      "                ",
      "                ",
      "                ",
      "hi              ",
      "jk              "
    ],
    [
      "         !!  '('",
      "         !!! '('",
      "         !!!!'('",
      "          !!!'('",
      "           !!'('",
      "             '('",
      "             '('",
      "             ./'",
      "             ./'",
      "             ./(",
      "             02 ",
      "             02 ",
      "                ",
      "                ",
      "hi              ",
      "jk              "
    ],
    [
      "        !(((''''",
      "       (((((''''",
      "      ((((((''''",
      "      ((((((''3'",
      "      ((((((''3'",
      "       (((((''''",
      "       (((  ''''",
      "            '56'",
      "            '56'",
      "           -'56-",
      "          --'78 ",
      "         --- 78 ",
      "        ----    ",
      "        ---     ",
      "hi       --     ",
      "jk              "
    ]
  ]
}