{
  "xsize": 16,
  "zsize": 16,
  "refpalette": "pomkotsmechs:base",
  "slices": [
    [
      "gggg        gggg",
      "gggg        gggg",
      "gggggg      gggg",
      "ggggggggg gggggg",
      "gggggggggggggggg",
      "gggggggggggggggg",
      "gggggggggggggggg",
      "gggggggggggggggg",
      "gggggggggggggggg",
      "gggggggggggggggg",
      "gggggggggggggggg",
      "gggggggggggggggg",
      "gggggggggggggggg",
      "gggggggggggggggg",
      "gggggggggggggggg",
      "gggggggggggggg  "
    ],
    [
      "!!              ",
      " !n            n",
      "!!!!          !!",
      " !!ͳͳ ͳ      ͳͳ!",
      "   ͳͳ!ͳͳ!!ͳͳ ͳͳ!",
      "    !!!!!       ",
      "   ͳͳ!ͳͳ  ͳͳ ͳͳ ",
      "   ͳͳ!ͳͳ  ͳͳ ͳͳ ",
      "                ",
      "   ͳͳ ͳͳ  ͳͳ ͳͳ ",
      "   ͳͳ ͳͳ  ͳͳ ͳͳ ",
      "                ",
      "   ͳͳ ͳͳ  ͳͳ ͳͳ ",
      "   ͳͳ ͳͳ  ͳͳ ͳͳ ",
      "  n     n!     n",
      "        !!!     "
    ],
    [
      "!               ",
      "  n            n",
      " !!!          ! ",
      "  !ͳͳ!ͳ !!! !!ͳ!",
      "   ͳͳ!ͳ!!!!ͳ!ͳͳ ",
      "    !!!!!!!     ",
      "   ͳͳ!ͳͳ! ͳͳ ͳͳ ",
      "   ͳͳ ͳͳ  ͳͳ ͳͳ ",
      "                ",
      "   ͳͳ ͳͳ  ͳͳ ͳͳ ",
      "   ͳͳ ͳͳ  ͳͳ ͳͳ ",
      "           !    ",
      "   ͳͳ ͳͳ  ͳͳ ͳͳ ",
      "   ͳͳ ͳͳ !ͳͳ ͳͳ ",
      "  n     n!!    n",
      "        !!!     "
    ],
    [
      "                ",
      "  ggggg        g",
      " !ggggg     !!!g",
      "  gggggg  !!!!g!",
      "  ggggg!!!!!!!g ",
      "  ggg!!!! !!!  g",
      "  gggggg  gggggg",
      "  gggggggggggggg",
      "  gggggggggggggg",
      "  gggggggggggggg",
      "  gggggggggggggg",
      "  gggggggggggggg",
      "  gggggggggggggg",
      "  gggggggggggggg",
      "  gggggggggggggg",
      "         !      "
    ],
    [
      "                ",
      "  !!            ",
      " !!!!!          ",
      "  !ͳͳ!ͳ     !!! ",
      "   ͳͳ!!!  !!!   ",
      "     !!!        ",
      "   ͳͳ!!!      ͳ ",
      "   ͳͳ ͳͳ  ͳͳ ͳͳ ",
      "                ",
      "   ͳͳ ͳͳ  ͳͳ ͳͳ ",
      "   ͳͳ ͳͳ  ͳͳ!ͳͳ ",
      "          !!!   ",
      "   ͳͳ ͳͳ  ͳͳ!ͳͳ ",
      "   ͳͳ ͳͳ !ͳͳ ͳͳ ",
      "        !!!!    ",
      "         !!     "
    ],
    [
      "                ",
      "                ",
      "  !!!           ",
      "  !ͳͳ!ͳͳ        ",
      "   ͳͳ!ͳ!        ",
      "      !!        ",
      "   ͳͳ!ͳͳ! ͳͳ  ͳ ",
      "   ͳͳ ͳͳ! ͳͳ ͳͳ ",
      "       !  !!    ",
      "   ͳͳ ͳͳ !ͳͳ!ͳͳ ",
      "   ͳͳ ͳͳ  ͳͳ!ͳͳ ",
      "          !!    ",
      "   ͳͳ ͳͳ !ͳͳ!ͳͳ ",
      "   ͳͳ ͳͳ !ͳͳ ͳͳ ",
      "         !!     ",
      "                "
    ]
  ]
}