{
  "xsize": 16,
  "zsize": 16,
  "refpalette": "pomkotsmechs:base",
  "slices": [
    [
      "gg     gggg!!   ",
      "  g   g   !g!   ",
      "  g   g    g    ",
      "  g   g    g    ",
      "  g   g    g    ",
      "gg     gggg     ",
      "                ",
      " ͶͶͶͶͶͶ         ",
      "Ͷ      ͶͶ       ",
      "         Ͷ      ",
      "          Ͷ     ",
      "                ",
      "                ",
      "                ",
      "                ",
      "                "
    ],
    [
      "g       gg!!    ",
      " g     g !g!!   ",
      "  g   g   !g    ",
      "  g   g    g    ",
      " g     g  g     ",
      "g       gg      ",
      "                ",
      " ͶͶͶͶͶͶ         ",
      "Ͷ      ͶͶ       ",
      "         Ͷ      ",
      "          Ͷ     ",
      "                ",
      "                ",
      "                ",
      "                ",
      "                "
    ],
    [
      "          !     ",
      "gg     gggg!    ",
      " g     g  g     ",
      " g     g  g     ",
      "gg     gggg     ",
      "                ",
      "                ",
      " ͶͶͶͶͶͶ         ",
      "Ͷ      ͶͶ       ",
      "         Ͷ      ",
      "          Ͷ     ",
      "                ",
      "                ",
      "                ",
      "                ",
      "                "
    ],
    [
      "   YY           ",
      "g  YY   gg!     ",
      " g YY  g  g     ",
      " g YY  g  g     ",
      "g  YY   gg      ",
      "   YY           ",
      "   YY           ",
      " ͶͶͶͶͶͶ         ",
      "Ͷ      ͶͶ       ",
      "         Ͷ      ",
      "          Ͷ     ",
      "           Ͷ    ",
      "                ",
      "                ",
      "                ",
      "                "
    ],
    [
      "                ",
      "g       gg      ",
      " g     g  g     ",
      " g     g  g     ",
      "g       gg      ",
      "                ",
      "                ",
      " ͶͶͶͶͶͶ         ",
      "Ͷ      ͶͶ       ",
      "         Ͷ      ",
      "          Ͷ     ",
      "           Ͷ    ",
      "           Ͷ    ",
      "                ",
      "            Ͷ   ",
      "            Ͷ   "
    ],
    [
      "                ",
      "                ",
      "g       gg      ",
      "g       gg      ",
      "                ",
      "                ",
      "                ",
      " ͶͶͶͶͶͶ         ",
      "Ͷ      ͶͶ       ",
      "         Ͷ      ",
      "          Ͷ     ",
      "           Ͷ    ",
      "           Ͷ    ",
      "            Ͷ   ",
      "            Ͷ   ",
      "            Ͷ   "
    ]
  ]
}