{
  "xsize": 16,
  "zsize": 16,
  "refpalette": "pomkotsmechs:base",
  "slices": [
    [
      "vvvvvvvvvvvvvvvv",
      "vvvvvvvvvvvvvvvv",
      "vvvvvvvvvvvvvvvv",
      "vvvvvvvvvvvvvvvv",
      "vvvvvvvvvvvvvvvv",
      "vvvvvvvvvvvvvvvv",
      "vvvvvvvvvvvvvvvv",
      "vvvvvvvvvvvvvvvv",
      "vvvvvvvvvvvvvvvv",
      "vvvvvvvvvvvvvvvv",
      "vvvvvvvvvvvvvvvv",
      "vvvvvvvvvvvvvvvv",
      "vvvvvvvvvvvvvvvv",
      "vvvvvvvvvvvvvvvv",
      "vvvvvvvvvvvvvvvv",
      "vvvvvvvvvvvvvvvv"
    ],
    [
      "                ",
      "                ",
      "                ",
      "                ",
      "                ",
      "                ",
      "                ",
      "        !       ",
      "gggggggggggggggg",
      "gggggggggggggggg",
      "            !!  ",
      "           !!!!!",
      "            !! !",
      "                ",
      "                ",
      "                "
    ],
    [
      "     ffffff     ",
      "     ffffff     ",
      "     ffffff     ",
      "     ffffff     ",
      "     ffffff     ",
      "     ffffff     ",
      "     ffffff     ",
      "     ffffff     ",
      "gggggggggggggggg",
      "gggggggggggggggg",
      "     ffffff  !  ",
      "     ffffff !!! ",
      "     ffffff  !  ",
      "     ffffff     ",
      "     ffffff     ",
      "                "
    ],
    [
      "    f      f    ",
      "    f      f    ",
      "    f      f    ",
      "    f      f    ",
      "    f      f    ",
      "    f   !  f    ",
      "    f  !!! f    ",
      "    f  !!! f    ",
      "gggggggggggggggg",
      "gggggggggggggggg",
      "    f      f !  ",
      "    f      f!!! ",
      "    ffffffff !  ",
      "    ffffffff    ",
      "    ffffffff    ",
      "      gggg      "
    ],
    [
      "   f        f   ",
      "   f        f   ",
      "   f        f   ",
      "   f        f   ",
      "   f        f   ",
      "   f   !!   f   ",
      "   f  !!!!  f   ",
      "   f   !!   f   ",
      "gggggggggggggggg",
      "gggggggggggggggg",
      "   f        f!  ",
      "   f        f!! ",
      "   ffffffffff!  ",
      "   ffffffffff   ",
      "   ffffffffff   ",
      "    gg    gg    "
    ],
    [
      "  f          f  ",
      "  f          f  ",
      "  f          f  ",
      "  f          f  ",
      "  f          f  ",
      "  f    !     f  ",
      "  f   !!!    f  ",
      "  f    !     f  ",
      "gggggggggggggggg",
      "gggggggggggggggg",
      "  f          f! ",
      "  f         !f!!",
      "  ffffffffffff! ",
      "  ffffffffffff  ",
      "  ffffffffffff  ",
      "   g        g   "
    ]
  ]
}