{
  "xsize": 16,
  "zsize": 16,
  "refpalette": "pomkotsmechs:base",
  "slices": [
    [
      "vvvvvvvvvvvvvvvv",
      "vvvvvvvvvvvvvvvv",
      "vvvvvvvvvvvvvvvv",
      "vvvvvvvvvvvvvvvv",
      "vvvvvvvvvvvvvvvv",
      "vvvvvvvvvvvvvvvv",
      "vvvvvvvvvvvvvvvv",
      "vvvvvvvvvvvvvvvv",
      "vvvvvvvvvvvvvvvv",
      "vvvvvvvvvvvvvvvv",
      "vvvvvvvvvvvvvvvv",
      "vvvvvvvvvvvvvvvv",
      "vvvvvvvvvvvvvvvv",
      "vvvvvvvvvvvvvvvv",
      "vvvvvvvvvvvvvvvv",
      "vvvvvvvvvvvvvvvv"
    ],
    [
      "                ",
      "                ",
      "  n   n  n   n  ",
      "      !!        ",
      "     !!!!       ",
      "      !!        ",
      "  n   n  n   n! ",
      "              ! ",
      "             !! ",
      "  n   n  n  !n!!",
      "             !!!",
      "              ! ",
      "                ",
      "  n   n  n   n  ",
      "                ",
      "                "
    ],
    [
      "                ",
      "                ",
      "  ʹʹʹʹʹ  ʹʹʹʹʹ  ",
      "  ʹʹʹʹʹ! ʹʹʹʹʹ  ",
      "  ʹʹʹʹʹ! ʹʹ ʹʹ  ",
      "  ʹʹʹʹʹ  ʹʹʹʹʹ  ",
      "  ʹʹʹʹʹ  ʹʹʹʹʹ  ",
      "                ",
      "             !  ",
      "  ʹʹʹʹʹ  ʹʹʹʹʹ! ",
      "  ʹʹʹʹʹ  ʹʹʹʹʹ! ",
      "  ʹʹʹʹʹ  ʹʹʹʹʹ  ",
      "  ʹʹʹʹʹ  ʹʹʹʹʹ  ",
      "  ʹʹʹʹʹ  ʹʹʹʹʹ  ",
      "                ",
      "                "
    ],
    [
      "                ",
      "                ",
      "  ʹf  !  ʹfffʹ  ",
      "  f  !!! f   f  ",
      "  f !!f! f   f  ",
      "  f ͳͳf  f   f  ",
      "  ʹfffʹ  ʹfffʹ  ",
      "     !       !  ",
      "     !       !  ",
      "  ʹfffʹ  ʹfffʹ! ",
      "  f   f  f   f  ",
      "  f ͳͳf  f ͳͳf  ",
      "  ffͳͳf  ffͳͳf  ",
      "  ʹfffʹ  ʹfffʹ  ",
      "                ",
      "                "
    ],
    [
      "                ",
      "                ",
      "  ʹf     ʹfffʹ  ",
      "  f   !  f   f  ",
      "  f  !f  f   f  ",
      "  f !!f  f   f  ",
      "  ʹfffʹ  ʹfffʹ  ",
      "    !!!     !!! ",
      "    !!!     !!! ",
      "  ʹfffʹ  ʹfffʹ! ",
      "  f  !f  f  !f  ",
      "  f   f  f   f  ",
      "  fffff  fffff  ",
      "  ʹfffʹ  ʹfffʹ  ",
      "                ",
      "                "
    ],
    [
      "                ",
      "                ",
      "  ʹʹ     ʹʹ ʹʹ  ",
      "  ʹʹ            ",
      "  ʹʹ !ʹ         ",
      "  ʹʹʹʹʹ  ʹ   ʹ  ",
      "  ʹʹʹʹʹ  ʹʹ ʹʹ! ",
      "    !!!     !!! ",
      "     !      !!! ",
      "  ʹʹʹʹʹ  ʹʹʹʹʹ! ",
      "  ʹʹʹʹʹ  ʹʹʹʹʹ  ",
      "  ʹʹʹʹʹ  ʹʹʹʹʹ  ",
      "  ʹʹʹʹʹ  ʹʹʹʹʹ  ",
      "  ʹʹʹʹʹ  ʹʹʹʹʹ  ",
      "                ",
      "                "
    ]
  ]
}