{
  "xsize": 16,
  "zsize": 16,
  "slices": [
    [
      "################",
      "################",
      "################",
      "################",
      "################",
      "################",
      "################",
      "################",
      "################",
      "#######l########",
      "################",
      "################",
      "################",
      "################",
      "################",
      "################"
    ],
    [
      "##a#a#a##a#a#a##",
      "#              #",
      "a $$$$    $$$$ a",
      "# $QQ$    $QQ$ #",
      "a $QQ$    $QQ$ a",
      "# $$$$    $$$$ #",
      "a              a",
      "#              #",
      "#              #",
      "a      l       a",
      "#:::::###::::::#",
      "a              a",
      "#L            F#",
      "a             Fa",
      "#              #",
      "##a#a#a##a#a#a##"
    ],
    [
      "##a#a#a##a#a#a##",
      "#              #",
      "a ++++    ++++ a",
      "# +W≈+    +≈W+ #",
      "a +≈W+    +W≈+ a",
      "# ++++    ++++ #",
      "a              a",
      "#              #",
      "#              #",
      "a      l       a",
      "#:::::###::::::#",
      "a              a",
      "#L             #",
      "a              a",
      "#              #",
      "##a#a#a##a#a#a##"
    ],
    [
      "################",
      "#              #",
      "# ++++    ++++ #",
      "# +WW+    +WW+ #",
      "# +WW+    +WW+ #",
      "# ++++    ++++ #",
      "#              #",
      "#              #",
      "#              #",
      "#      l       #",
      "#:::::###::::::#",
      "#              #",
      "#              #",
      "#              #",
      "#              #",
      "################"
    ],
    [
      "##a#a#a##a#a#a##",
      "#              #",
      "a ++++    ++++ a",
      "# +WW+    +WW+ #",
      "a +WW+    +WW+ a",
      "# ++++    ++++ #",
      "a              a",
      "#              #",
      "#              #",
      "a      l       a",
      "#:::::###::::::#",
      "a       E      a",
      "#              #",
      "a              a",
      "#              #",
      "##a#a#a##a#a#a##"
    ],
    [
      "##a#a#a##a#a#a##",
      "#              #",
      "a ++++    ++++ a",
      "# +WW+    +WW+ #",
      "a +WW+    +WW+ a",
      "# ++++    ++++ #",
      "a              a",
      "#              #",
      "#              #",
      "a      l       a",
      "#:::::###::::::#",
      "a       {      a",
      "#              #",
      "a              a",
      "#              #",
      "##a#a#a##a#a#a##"
    ]
  ]
}
