{
  "xsize": 16,
  "zsize": 16,
  "slices": [
    [
      "################",
      "################",
      "################",
      "################",
      "################",
      "################",
      "################",
      "################",
      "################",
      "#######l########",
      "################",
      "################",
      "################",
      "################",
      "################",
      "################"
    ],
    [
      "##a#a#a##a#a#a##",
      "#  #        #  #",
      "a  #F       #  a",
      "#  #F      L#  #",
      "a  #$      L#  a",
      "#  #        #  #",
      "a              a",
      "#  #        #  #",
      "#  #        #  #",
      "a  #   l    #  a",
      "#  ##########  #",
      "a              a",
      "#              #",
      "a              a",
      "#    F    F    #",
      "##a#a#a##a#a#a##"
    ],
    [
      "##a#a#a##a#a#a##",
      "#  #        #  #",
      "a  #        #  a",
      "#  #       L#  #",
      "a  #*      L#  a",
      "#  #        #  #",
      "a              a",
      "#  #        #  #",
      "#  #        #  #",
      "a  #   l    #  a",
      "#  ##########  #",
      "a              a",
      "#              #",
      "a              a",
      "#              #",
      "##a#a#a##a#a#a##"
    ],
    [
      "################",
      "#  #        #  #",
      "#  #        #  #",
      "#  #        #  #",
      "#  #        #  #",
      "#  #        #  #",
      "#  #        #  #",
      "#  #        #  #",
      "#  #        #  #",
      "#  #   l    #  #",
      "#  ##########  #",
      "#              #",
      "#              #",
      "#              #",
      "#              #",
      "################"
    ],
    [
      "##a#a#a##a#a#a##",
      "#  #        #  #",
      "a  #        #  a",
      "#  #        #  #",
      "a  #        #  a",
      "#  #        #  #",
      "a  #        #  a",
      "#  #        #  #",
      "#  #        #  #",
      "a  #   l    #  a",
      "#  ##########  #",
      "a       E      a",
      "#              #",
      "a              a",
      "#              #",
      "##a#a#a##a#a#a##"
    ],
    [
      "##a#a#a##a#a#a##",
      "#  #        #  #",
      "a  #        #  a",
      "#  #        #  #",
      "a  #        #  a",
      "#  #        #  #",
      "a  #        #  a",
      "#  #        #  #",
      "#  #        #  #",
      "a  #   l    #  a",
      "#  ##########  #",
      "a       {      a",
      "#              #",
      "a              a",
      "#              #",
      "##a#a#a##a#a#a##"
    ]
  ]
}
