{
  "xsize": 16,
  "zsize": 16,
  "slices": [
    [
      "################",
      "################",
      "################",
      "################",
      "################",
      "################",
      "################",
      "################",
      "################",
      "#######l########",
      "################",
      "################",
      "################",
      "################",
      "################",
      "################"
    ],
    [
      "##a#a#a##a#a#a##",
      "#              #",
      "a              a",
      "#              #",
      "a   QQQLCQQQ   a",
      "#   Q#####1Q   #",
      "a   Q#    #Q   a",
      "#   F#         #",
      "#   F#         #",
      "a   Q# l  #Q   a",
      "#   Q#####1Q   #",
      "a   QQQFFQQQ   a",
      "#              #",
      "a              a",
      "#              #",
      "##a#a#a##a#a#a##"
    ],
    [
      "##a#a#a##a#a#a##",
      "#              #",
      "a              a",
      "#              #",
      "a   *     *e   a",
      "#    ######    #",
      "a    #    #*   a",
      "#    #         #",
      "#    #         #",
      "a    # l  #*   a",
      "#    ######    #",
      "a   *    *     a",
      "#              #",
      "a              a",
      "#              #",
      "##a#a#a##a#a#a##"
    ],
    [
      "################",
      "#              #",
      "#              #",
      "#              #",
      "#              #",
      "#    ######    #",
      "#    #    #    #",
      "#    #    #    #",
      "#    #    #    #",
      "#    # l  #    #",
      "#    ######    #",
      "#              #",
      "#              #",
      "#              #",
      "#              #",
      "################"
    ],
    [
      "##a#a#a##a#a#a##",
      "#              #",
      "a              a",
      "#              #",
      "a              a",
      "#    ######    #",
      "a    #    #    a",
      "#    #    #    #",
      "#    #    #    #",
      "a    # l  #    a",
      "#    ######    #",
      "a              a",
      "#  E           #",
      "a              a",
      "#              #",
      "##a#a#a##a#a#a##"
    ],
    [
      "##a#a#a##a#a#a##",
      "#              #",
      "a              a",
      "#              #",
      "a              a",
      "#    ######    #",
      "a    #    #    a",
      "#    #    #    #",
      "#    #    #    #",
      "a    # l  #    a",
      "#    ######    #",
      "a              a",
      "#  {           #",
      "a              a",
      "#              #",
      "##a#a#a##a#a#a##"
    ]
  ]
}
