{
  "xsize": 16,
  "zsize": 16,
  "slices": [
    [
      "################",
      "################",
      "################",
      "################",
      "################",
      "################",
      "################",
      "################",
      "################",
      "#######l########",
      "################",
      "################",
      "################",
      "################",
      "################",
      "################"
    ],
    [
      "##a#a#a##a#a#a##",
      "#              #",
      "a              a",
      "#              #",
      "a              a",
      "#              #",
      "a    ## ##     a",
      "#    #   #     #",
      "#    #   #     #",
      "a   *# l #     a",
      "## #############",
      "a     FFF      a",
      "#              #",
      "a              a",
      "#              #",
      "##a#a#a##a#a#a##"
    ],
    [
      "##a#a#a##a#a#a##",
      "#              #",
      "a              a",
      "#              #",
      "a              a",
      "#              #",
      "a    ## ##     a",
      "#    #   #     #",
      "#    #   #     #",
      "a    # l #     a",
      "## ########aaa##",
      "a              a",
      "#              #",
      "a              a",
      "#              #",
      "##a#a#a##a#a#a##"
    ],
    [
      "################",
      "#              #",
      "#          ### #",
      "#          ### #",
      "#          ### #",
      "#              #",
      "#    #####     #",
      "#    #   #     #",
      "#    #   #     #",
      "#    # l #     #",
      "################",
      "#              #",
      "#              #",
      "#              #",
      "#              #",
      "################"
    ],
    [
      "##a#a#a##a#a#a##",
      "#              #",
      "a          { { a",
      "#           C  #",
      "a          { { a",
      "#              #",
      "a    #####     a",
      "#    #  E#     #",
      "#    #   #     #",
      "a    # l #     a",
      "###########aaa##",
      "a              a",
      "#              #",
      "a              a",
      "#              #",
      "##a#a#a##a#a#a##"
    ],
    [
      "##a#a#a##a#a#a##",
      "#              #",
      "a          { { a",
      "#              #",
      "a          { { a",
      "#              #",
      "a    #####     a",
      "#    #  {#     #",
      "#    #   #     #",
      "a    # l #     a",
      "#####1##########",
      "a    #         a",
      "#    :         #",
      "a    :         a",
      "#    #         #",
      "##a#a#a##a#a#a##"
    ]
  ]
}
