{
  "xsize": 16,
  "zsize": 16,
  "slices": [
    [
      "################",
      "################",
      "################",
      "################",
      "################",
      "################",
      "################",
      "################",
      "################",
      "#######l########",
      "################",
      "################",
      "################",
      "################",
      "################",
      "################"
    ],
    [
      "##a#a#a##a#a#a##",
      "#  F      QQQ  #",
      "a              a",
      "#              #",
      "a              a",
      "#             F#",
      "a              a",
      "#              #",
      "#              #",
      "a      l       a",
      "############  ##",
      "a              a",
      "#              #",
      "a              a",
      "#              #",
      "##a#a#a##a#a#a##"
    ],
    [
      "##a#a#a##a#a#a##",
      "#         **   #",
      "a              a",
      "#              #",
      "a              a",
      "#              #",
      "a              a",
      "#              #",
      "#              #",
      "a      l       a",
      "##::########  ##",
      "a              a",
      "#              #",
      "a              a",
      "#              #",
      "##a#a#a##a#a#a##"
    ],
    [
      "################",
      "#              #",
      "#              #",
      "#              #",
      "#              #",
      "#              #",
      "#              #",
      "#              #",
      "#              #",
      "#      l       #",
      "##::############",
      "#              #",
      "#              #",
      "#              #",
      "#              #",
      "################"
    ],
    [
      "##a#a#a##a#a#a##",
      "#              #",
      "a              a",
      "#              #",
      "a              a",
      "#              #",
      "a              a",
      "#              #",
      "#              #",
      "a    E l       a",
      "##::############",
      "a    E         a",
      "#              #",
      "a              a",
      "#              #",
      "##a#a#a##a#a#a##"
    ],
    [
      "##a#a#a##a#a#a##",
      "#              #",
      "a              a",
      "#              #",
      "a              a",
      "#              #",
      "a              a",
      "#              #",
      "#              #",
      "a    { l       a",
      "################",
      "a    {         a",
      "#              #",
      "a              a",
      "#              #",
      "##a#a#a##a#a#a##"
    ]
  ]
}
