{
  "xsize": 16,
  "zsize": 16,
  "slices": [
    [
      "################",
      "################",
      "################",
      "################",
      "################",
      "################",
      "################",
      "################",
      "################",
      "#######l########",
      "################",
      "################",
      "################",
      "################",
      "################",
      "################"
    ],
    [
      "##a#a#a##a#a#a##",
      "# QQ #    #   F#",
      "a    #    #    a",
      "#             F#",
      "a    #    #    a",
      "### ##    ## ###",
      "a    ## ##     a",
      "#    #   #     #",
      "#    #         #",
      "a    # l #     a",
      "#::::####1## ###",
      "a    :   L#    a",
      "#    :    #  . #",
      "a    :       . a",
      "#C C :    #    #",
      "##a#a#a##a#a#a##"
    ],
    [
      "##a#a#a##a#a#a##",
      "# ** #    #    #",
      "a    #    #    a",
      "#              #",
      "a    #    #    a",
      "### ##    ## ###",
      "a    ## ##     a",
      "#    #   #     #",
      "#    #         #",
      "a    # l #     a",
      "#::::####### ###",
      "a    :   L#    a",
      "#    :    #  - #",
      "a    :       - a",
      "#    :    #    #",
      "##a#a#a##a#a#a##"
    ],
    [
      "################",
      "#    #    #    #",
      "#    #    #    #",
      "#    #    #    #",
      "#    #    #    #",
      "######    ######",
      "#    #####     #",
      "#    #   #     #",
      "#    #   #     #",
      "#    # l #     #",
      "#::::###########",
      "#    :    #    #",
      "#    :    #    #",
      "#    :    #    #",
      "#    :    #    #",
      "################"
    ],
    [
      "##a#a#a##a#a#a##",
      "#    #    #    #",
      "a    #    #    a",
      "#    #    # E  #",
      "a    #    #    a",
      "######    ######",
      "a    #####     a",
      "#    #  E#     #",
      "#    #   #     #",
      "a    # l #     a",
      "################",
      "a    #    #    a",
      "#    #    #    #",
      "a    #    #    a",
      "#    #    #    #",
      "##a#a#a##a#a#a##"
    ],
    [
      "##a#a#a##a#a#a##",
      "#    #    #    #",
      "a    #    #    a",
      "#    #    # {  #",
      "a    #    #    a",
      "######    ######",
      "a    #####     a",
      "#    #  {#     #",
      "#    #   #     #",
      "a    # l #     a",
      "#####1##########",
      "a    #    #    a",
      "#    #    #    #",
      "a    #    #    a",
      "#    #    #    #",
      "##a#a#a##a#a#a##"
    ]
  ]
}
