{
  "xsize": 16,
  "zsize": 16,
  "slices": [
    [
      "################",
      "################",
      "################",
      "################",
      "################",
      "################",
      "################",
      "################",
      "################",
      "#######l########",
      "################",
      "################",
      "################",
      "################",
      "################",
      "################"
    ],
    [
      "##a#a#a##a#a#a##",
      "#    :    :    #",
      "a  l :    : l  a",
      "#  # :    : #  #",
      "a    :    :    a",
      "#:: ::    :: ::#",
      "a              a",
      "#              #",
      "#              #",
      "a      l       a",
      "###########    #",
      "a  FFF    #    a",
      "#F             #",
      "a              a",
      "#         #    #",
      "##a#a#a##a#a#a##"
    ],
    [
      "##a#a#a##a#a#a##",
      "#    :    :    #",
      "a  l :    : l  a",
      "#  # :    : #  #",
      "a    :    :    a",
      "#:: ::    :: ::#",
      "a              a",
      "#              #",
      "#              #",
      "a      l       a",
      "###########    #",
      "a         #    a",
      "#              #",
      "a              a",
      "#         #    #",
      "##a#a#a##a#a#a##"
    ],
    [
      "################",
      "######    ######",
      "###l##    ##l###",
      "######    ######",
      "######    ######",
      "######    ######",
      "#              #",
      "#              #",
      "#              #",
      "#      l       #",
      "###########    #",
      "#         #    #",
      "#         #    #",
      "#         #    #",
      "#         #    #",
      "################"
    ],
    [
      "##a#a#a##a#a#a##",
      "#    :    :    #",
      "a    :    :    a",
      "# 1  :    :  1 #",
      "a  C :    : C  a",
      "#:::::    :::::#",
      "a              a",
      "#              #",
      "#              #",
      "a      l       a",
      "###########    #",
      "a         #    a",
      "#  E      #    #",
      "a         #    a",
      "#         #    #",
      "##a#a#a##a#a#a##"
    ],
    [
      "##a#a#a##a#a#a##",
      "#    :    :    #",
      "a    :    :    a",
      "#    :    :    #",
      "a    :    :    a",
      "#:::::    :::::#",
      "a              a",
      "#              #",
      "#              #",
      "a      l       a",
      "###########    #",
      "a         #    a",
      "#  {      #    #",
      "a         #    a",
      "#         #    #",
      "##a#a#a##a#a#a##"
    ]
  ]
}
