{
  "xsize": 16,
  "zsize": 16,
  "slices": [
    [
      "                ",
      "      v  v      ",
      "                ",
      "   v        v   ",
      "                ",
      "                ",
      " v            v ",
      "                ",
      "                ",
      " v            v ",
      "                ",
      "                ",
      "   v        v   ",
      "                ",
      "      v  v      ",
      "                "
    ],
    [
      "                ",
      "      w  w      ",
      "                ",
      "   w        w   ",
      "                ",
      "                ",
      " w            w ",
      "                ",
      "                ",
      " w            w ",
      "                ",
      "                ",
      "   w        w   ",
      "                ",
      "      w  w      ",
      "                "
    ],
    [
      "                ",
      "      w  w      ",
      "                ",
      "   w        w   ",
      "                ",
      "                ",
      " w            w ",
      "                ",
      "                ",
      " w            w ",
      "                ",
      "                ",
      "   w        w   ",
      "                ",
      "      w  w      ",
      "                "
    ],
    [
      "                ",
      "      w  w      ",
      "      E  E      ",
      "   w        w   ",
      "                ",
      "                ",
      " wE          Ew ",
      "                ",
      "                ",
      " wE          Ew ",
      "                ",
      "                ",
      "   w        w   ",
      "      E  E      ",
      "      w  w      ",
      "                "
    ],
    [
      "                ",
      "      ____      ",
      "    ________    ",
      "   ___uuuu___   ",
      "  ___uuuuuu___  ",
      "  __uuuuuuuu__  ",
      " __uuuuuuuuuu__ ",
      " __uuuuuuuuuu__ ",
      " __uuuuuuuuuu__ ",
      " __uuuuuuuuuu__ ",
      "  __uuuuuuuu__  ",
      "  ___uuuuuu___  ",
      "   ___uuuu___   ",
      "    ________    ",
      "      ____      ",
      "                "
    ],
    [
      "                ",
      "                ",
      "                ",
      "                ",
      "                ",
      "       __       ",
      "      ____      ",
      "     ______     ",
      "     ______     ",
      "      ____      ",
      "       __       ",
      "                ",
      "                ",
      "                ",
      "                ",
      "                "
    ]
  ]
}