{
  "xsize": 16,
  "zsize": 16,
  "slices": [
    [
      "################",
      "SSSSSSSSSSSSSSS#",
      "SSSSSSSSSSSSSSS#",
      "#############SS#",
      "QQQQQQQQQQQQ#SS#",
      "QQQQQQQQQQQQ#SS#",
      "QQQQQQQQQQQQ#SS#",
      "QQQQQQQQQQQQ#SS#",
      "QQQQQQQQQQQQ#SS#",
      "QQQQQQQQQQQQ#SS#",
      "QQQQQQQQQQQQ#SS#",
      "QQQQQQQQQQQQ#SS#",
      "QQQQQQQQQQQQ#SS#",
      "QQQQQQQQQQQQ#SS#",
      "QQQQQQQQQQQQ#SS#",
      "QQQQQQQQQQQQ#SS#"
    ],
    [
      "aaa#aaaa#aaaa#aa",
      "               a",
      "               #",
      "               a",
      "               a",
      "               a",
      "               a",
      "               #",
      "               a",
      "               a",
      "               a",
      "               a",
      "               #",
      "               a",
      "               a",
      "               a"
    ],
    [
      "aaa#aaaa#aaaa#aa",
      "               a",
      "               #",
      "               a",
      "               a",
      "               a",
      "               a",
      "               #",
      "               a",
      "               a",
      "               a",
      "               a",
      "               #",
      "               a",
      "               a",
      "               a"
    ],
    [
      "aaa#aaaa#aaaa#aa",
      "               a",
      "               #",
      "               a",
      "               a",
      "               a",
      "               a",
      "               #",
      "               a",
      "               a",
      "               a",
      "               a",
      "               #",
      "               a",
      "               a",
      "               a"
    ],
    [
      "################",
      "               #",
      "               #",
      "               #",
      "               #",
      "               #",
      "               #",
      "               #",
      "               #",
      "               #",
      "               #",
      "               #",
      "               #",
      "               #",
      "               #",
      "               #"
    ],
    [
      "################",
      "################",
      "################",
      "################",
      "################",
      "################",
      "################",
      "################",
      "################",
      "################",
      "################",
      "################",
      "################",
      "################",
      "################",
      "################"
    ]
  ]
}