{
  "meta": [
    {
      "key": "dontconnect",
      "boolean": true
    }
  ],
  "xsize": 16,
  "zsize": 16,
  "palette": {
    "palette": [
      {
        "char": "P",
        "blocks": [
          {
            "random": 64,
            "block": "minecraft:oak_sapling[stage=1]"
          },
          {
            "random": 32,
            "block": "minecraft:spruce_sapling[stage=1]"
          },
          {
            "random": 1000,
            "block": "minecraft:birch_sapling[stage=1]"
          }
        ]
      }
    ]
  },
  "slices": [
    [
      "################",
      "#SSSSSSSSSS#SSSS",
      "#SSSSSSSSS#SSSSS",
      "#SSSSSSSS#SSS###",
      "#SSSSSSS#SSS#QQQ",
      "#SSSSSS#SSS#QQQQ",
      "#SSSSS#SSS#QQQQQ",
      "#SSSS#SSS#QQQQQQ",
      "#SSS#SSS#QQQQ((Q",
      "#SS#SSS#QQQQQ  Q",
      "#S#SSS#QQQQQQ  Q",
      "##SSS#QQQQQQQ  Q",
      "#SSS#QQQQQQQQ  Q",
      "#SS#QQQQQQQQQ  Q",
      "#SS#QQQQQQQQQQQQ",
      "#SS#QQQQQQQQQQQQ"
    ],
    [
      "#######     #aaa",
      "#GGGGG#    +    ",
      "#GGGG#    +     ",
      "#GGG#    +      ",
      "#GG#    #       ",
      "#G#    +        ",
      "##    +         ",
      "     +          ",
      "    #       w  w",
      "   +        w  w",
      "  +         w  w",
      " +          w  w",
      "#           w  w",
      "a           w((w",
      "a               ",
      "a               "
    ],
    [
      "            #aaa",
      " KKKKK     +    ",
      " KPKK     +     ",
      " KKK     +      ",
      " KK     #       ",
      " K     +        ",
      "      +         ",
      "     +          ",
      "    #       :  :",
      "   +        :  :",
      "  +         :  :",
      " +          :  :",
      "#           :((:",
      "a           :  :",
      "a               ",
      "a               "
    ],
    [
      "            #aaa",
      "           +    ",
      "          +     ",
      "         +      ",
      "        #       ",
      "       +        ",
      "      +         ",
      "     +          ",
      "    #       :  :",
      "   +        :  :",
      "  +         :  :",
      " +          :((:",
      "#           :  :",
      "a           :  :",
      "a               ",
      "a               "
    ],
    [
      "            ####",
      "           #    ",
      "          #     ",
      "         #      ",
      "        #       ",
      "       #        ",
      "      #         ",
      "     #          ",
      "    #       :  :",
      "   #        :  :",
      "  #         :((:",
      " #          :  :",
      "#           :  :",
      "#           :  :",
      "#               ",
      "#               "
    ],
    [
      "            ####",
      "           #####",
      "          ######",
      "         #######",
      "        ########",
      "       #########",
      "      ##########",
      "     ###########",
      "    #########  #",
      "   ##########((#",
      "  ###########  #",
      " ############  #",
      "#############  #",
      "#############  #",
      "################",
      "################"
    ]
  ]
}
