{
  "meta": [
    {
      "key": "dontconnect",
      "boolean": true
    }
  ],
  "xsize": 16,
  "zsize": 16,
  "slices": [
    [
      "            ####",
      "           #SSSS",
      "          #SSSSS",
      "         #SSS###",
      "        #SSS#QQQ",
      "       #SSS#QQQQ",
      "      #SSS#QQQQQ",
      "     #SSS#QQQQQQ",
      "    #SSS#QQQQ((Q",
      "   #SSS#QQQQQ  Q",
      "  #SSS#QQQQQQ  Q",
      " #SSS#QQQQQQQ  Q",
      "#SSS#QQQQQQQQ  Q",
      "#SS#QQQQQQQQQ  Q",
      "#SS#QQQQQQQQQQQQ",
      "#SS#QQQQQQQQQQQQ"
    ],
    [
      "            #aaa",
      "           +    ",
      "          +     ",
      "         +      ",
      "        #       ",
      "       +        ",
      "      +         ",
      "     +          ",
      "    #       w  w",
      "   +        w  w",
      "  +         w  w",
      " +          w  w",
      "#           w  w",
      "a           w((w",
      "a               ",
      "a               "
    ],
    [
      "            #aaa",
      "           +    ",
      "          +     ",
      "         +      ",
      "        #       ",
      "       +        ",
      "      +         ",
      "     +          ",
      "    #       :  :",
      "   +        :  :",
      "  +         :  :",
      " +          :  :",
      "#           :((:",
      "a           :  :",
      "a               ",
      "a               "
    ],
    [
      "            #aaa",
      "           +    ",
      "          +     ",
      "         +      ",
      "        #       ",
      "       +        ",
      "      +         ",
      "     +          ",
      "    #       :  :",
      "   +        :  :",
      "  +         :  :",
      " +          :((:",
      "#           :  :",
      "a           :  :",
      "a               ",
      "a               "
    ],
    [
      "            ####",
      "           #    ",
      "          #     ",
      "         #      ",
      "        #       ",
      "       #        ",
      "      #         ",
      "     #          ",
      "    #       :  :",
      "   #        :  :",
      "  #         :((:",
      " #          :  :",
      "#           :  :",
      "#           :  :",
      "#               ",
      "#               "
    ],
    [
      "            ####",
      "           #####",
      "          ######",
      "         #######",
      "        ########",
      "       #########",
      "      ##########",
      "     ###########",
      "    #########  #",
      "   ##########((#",
      "  ###########  #",
      " ############  #",
      "#############  #",
      "#############  #",
      "################",
      "################"
    ]
  ]
}
