{
  "xsize": 16,
  "zsize": 16,
  "slices": [
    [
      "            ####",
      "           #####",
      "          ######",
      "         #######",
      "        ########",
      "       #########",
      "      ##########",
      "     ###########",
      "    #########((#",
      "   ##########  #",
      "  ###########  #",
      " ############  #",
      "#############  #",
      "#############  #",
      "################",
      "################"
    ],
    [
      "                ",
      "                ",
      "                ",
      "                ",
      "                ",
      "                ",
      "                ",
      "            #  #",
      "            +  +",
      "            +  +",
      "     uu     +  +",
      "     ww     #  #",
      "   uw       +  +",
      "   uw       +  +",
      "            +  +",
      "            #++#"
    ],
    [
      "                ",
      "                ",
      "                ",
      "                ",
      "                ",
      "                ",
      "                ",
      "            #  #",
      "            +  +",
      "            +  +",
      "     ::     +  +",
      "     ::     #  #",
      "   ::       +  +",
      "   ::       +  +",
      "            +  +",
      "            #++#"
    ],
    [
      "                ",
      "                ",
      "                ",
      "                ",
      "                ",
      "                ",
      "                ",
      "            ####",
      "            ####",
      "            ####",
      "      :     ####",
      "     :      ####",
      "    :       ####",
      "   :        ####",
      "            ####",
      "            ####"
    ],
    [
      "                ",
      "                ",
      "                ",
      "                ",
      "                ",
      "                ",
      "                ",
      "                ",
      "                ",
      "                ",
      "      :         ",
      "     :          ",
      "    g           ",
      "   :            ",
      "                ",
      "                "
    ],
    [
      "                ",
      "                ",
      "                ",
      "                ",
      "                ",
      "                ",
      "                ",
      "                ",
      "                ",
      "                ",
      "      g         ",
      "                ",
      "                ",
      "                ",
      "                ",
      "                "
    ]
  ]
}
