{
  "xsize": 16,
  "zsize": 16,
  "slices": [
    [
      "            ####",
      "           #####",
      "          ######",
      "         #######",
      "        ########",
      "       #########",
      "      ##########",
      "     ###########",
      "    #########((#",
      "   ##########  #",
      "  ###########  #",
      " ############  #",
      "#############  #",
      "#############  #",
      "################",
      "################"
    ],
    [
      "            #aa#",
      "           +   :",
      "          +    :",
      "         +     :",
      "        #     *#",
      "       +        ",
      "      +         ",
      "     +          ",
      "    #          #",
      "   +           :",
      "  +            :",
      " +             :",
      "#              :",
      "a              :",
      "a   *          :",
      "#:::#       #::#"
    ],
    [
      "            #aa#",
      "           +   :",
      "          +    :",
      "         +     :",
      "        #      #",
      "       +        ",
      "      +         ",
      "     +          ",
      "    #       E  #",
      "   +           :",
      "  +            :",
      " +             :",
      "#              :",
      "a              :",
      "a              :",
      "#:::#       #::#"
    ],
    [
      "            ####",
      "           #####",
      "          ######",
      "         #######",
      "        ########",
      "       #########",
      "      ##########",
      "     ###########",
      "    ############",
      "   #############",
      "  ##############",
      " ###############",
      "################",
      "################",
      "################",
      "################"
    ]
  ]
}
