{
  "refpalette": "lcmt:center_interior",
  "xsize": 16,
  "zsize": 16,
  "slices": [
    [
      "                ",
      "                ",
      "                ",
      "                ",
      "                ",
      "                ",
      "                ",
      "                ",
      "                ",
      "                ",
      "                ",
      "                ",
      "                ",
      "                ",
      "                ",
      "                "
    ],
    [
      "                ",
      "                ",
      "                ",
      "     mjn        ",
      "                ",
      "     r r        ",
      "     I I        ",
      "    QQQQQ  uuu  ",
      "    QkkkQVVuuu  ",
      "    QkkkQ  uuu  ",
      "    QkkkQVVuuu  ",
      "    QQQQQ  uuu  ",
      "                ",
      "                ",
      "                ",
      "                "
    ],
    [
      "                ",
      "                ",
      "            r   ",
      "     ZZZ    I   ",
      "            I   ",
      "     j j    I   ",
      "            I   ",
      "    `````  uuu  ",
      "    `333`  :H:  ",
      "    `333`  :H:  ",
      "    `333`  :H:  ",
      "    `````  uuu  ",
      "                ",
      "                ",
      "                ",
      "                "
    ],
    [
      "                ",
      "                ",
      "            j   ",
      "                ",
      "                ",
      "     j j        ",
      "                ",
      "    `````  uuu  ",
      "    `333`  uuu  ",
      "    `333`  uuu  ",
      "    `333`  uuu  ",
      "    `````  uuu  ",
      "                ",
      "                ",
      "                ",
      "                "
    ],
    [
      "                ",
      "                ",
      "      E     j   ",
      "                ",
      "                ",
      "     j j        ",
      "                ",
      "    `````       ",
      "    `333`   j   ",
      "    `333`       ",
      "    `333`   j   ",
      "    `````       ",
      "                ",
      "                ",
      "                ",
      "                "
    ]
  ]
}
