{
  "xsize": 16,
  "zsize": 16,
  "slices": [
    [
      "##SQSQSQSQSQSQSQ",
      "##QSQSQSQSQSQSQS",
      "##SQSQSQSQSQSQSQ",
      "##QSQSQSQSQSQSQS",
      "##SQSQSQSQSQSQSQ",
      "##QSQSQSQSQSQSQS",
      "#QSQSQSQSQSQSQSQ",
      "#SQSQSQSQSQSQSQS",
      "#QSQSQSQSQSQSQSQ",
      "#SQSQSQSQSQSQSQS",
      "##SQSQSQSQSQSQSQ",
      "##QSQSQSQSQSQSQS",
      "##SQSQSQSQSQSQSQ",
      "##QSQSQSQSQSQSQS",
      "######SQSQ######",
      "################"
    ],
    [
      "##              ",
      "##              ",
      "##              ",
      "##              ",
      "##              ",
      "##              ",
      "#               ",
      "#               ",
      "#               ",
      "#               ",
      "##              ",
      "##              ",
      "##              ",
      "##              ",
      "######    ######",
      "################"
    ],
    [
      "##              ",
      "##              ",
      "##              ",
      "##              ",
      "##              ",
      "##              ",
      "#               ",
      "#               ",
      "#               ",
      "#               ",
      "##              ",
      "##              ",
      "##              ",
      "##              ",
      "######    ######",
      "################"
    ],
    [
      "##              ",
      "##              ",
      "##              ",
      "##              ",
      "##              ",
      "##              ",
      "#               ",
      "#               ",
      "#               ",
      "#               ",
      "##              ",
      "##              ",
      "##              ",
      "##              ",
      "######    ######",
      "################"
    ],
    [
      "##              ",
      "##              ",
      "##              ",
      "##              ",
      "##              ",
      "##              ",
      "#               ",
      "#       E       ",
      "#               ",
      "#               ",
      "##              ",
      "##              ",
      "##              ",
      "##              ",
      "######    ######",
      "################"
    ],
    [
      "################",
      "################",
      "################",
      "################",
      "################",
      "################",
      "################",
      "################",
      "################",
      "################",
      "################",
      "################",
      "################",
      "################",
      "################",
      "################"
    ]
  ]
}