{
  "refpalette": "lostcities:center_interior",
  "xsize": 16,
  "zsize": 16,
  "slices": [
    [
      "                ",
      "                ",
      "                ",
      "                ",
      "                ",
      "  k k    k k    ",
      "  k k    k k    ",
      "                ",
      "  k k    k k    ",
      "  k k    k k    ",
      "                ",
      "  k k    k k    ",
      "  k k    k k    ",
      "                ",
      "                ",
      "                "
    ],
    [
      "                ",
      "                ",
      "                ",
      "                ",
      "  QoQ    QoQ    ",
      "  ZHZ    ZHZ    ",
      "  ZHZ    ZHZ    ",
      "  QoQ    QoQ    ",
      "  ZHZ    ZHZ    ",
      "  ZHZ    ZHZ    ",
      "  QoQ    QoQ    ",
      "  ZHZ    ZHZ    ",
      "  ZHZ    ZHZ    ",
      "  QoQ    QoQ    ",
      "                ",
      "                "
    ],
    [
      "                ",
      "                ",
      "                ",
      "                ",
      "  jrj    jrj    ",
      "  ZHZ    ZHZ    ",
      "  ZHZ    ZHZ    ",
      "  jjj    jjj    ",
      "  ZHZ    ZHZ    ",
      "  ZHZ    ZHZ    ",
      "  jjj    jjj    ",
      "  ZHZ    ZHZ    ",
      "  ZHZ    ZHZ    ",
      "  jqj    jqj    ",
      "                ",
      "                "
    ],
    [
      "                ",
      "                ",
      "                ",
      "                ",
      "  jrj    jrj    ",
      "  ZHZ    ZHZ    ",
      "  ZHZ    ZHZ    ",
      "  jjj    jjj    ",
      "  ZHZ    ZHZ    ",
      "  ZHZ    ZHZ    ",
      "  jjj    jjj    ",
      "  ZHZ    ZHZ    ",
      "  ZHZ    ZHZ    ",
      "  jqj    jqj    ",
      "                ",
      "                "
    ],
    [
      "                ",
      "                ",
      "                ",
      "   E      E     ",
      "  jrj    jrj    ",
      "  ZHZ    ZHZ    ",
      "  ZHZ    ZHZ    ",
      "  jjj    jjj    ",
      "  ZHZ    ZHZ    ",
      "  ZHZ    ZHZ    ",
      "  jjj    jjj    ",
      "  ZHZ    ZHZ    ",
      "  ZHZ    ZHZ    ",
      "  jqj    jqj    ",
      "                ",
      "                "
    ]
  ]
}
