{
  "xsize": 16,
  "zsize": 16,
  "refpalette": "lcmt:center_interior",
  "slices": [
    [
      "                ",
      "                ",
      "                ",
      "    k k    k k  ",
      "    k k    k k  ",
      "                ",
      "    k k    k k  ",
      "    k k    k k  ",
      "                ",
      "    k k    k k  ",
      "    k k    k k  ",
      "                ",
      "                ",
      "                ",
      "                ",
      "                "
    ],
    [
      "                ",
      "                ",
      "    QoQ    QoQ  ",
      "    ZHZ    ZHZ  ",
      "    ZHZ    ZHZ  ",
      "    QoQ    QoQ  ",
      "    ZHZ    ZHZ  ",
      "    ZHZ    ZHZ  ",
      "    QoQ    QoQ  ",
      "    ZHZ    ZHZ  ",
      "    ZHZ    ZHZ  ",
      "    QoQ    QoQ  ",
      "                ",
      "                ",
      "                ",
      "                "
    ],
    [
      "                ",
      "                ",
      "    jrj    jrj  ",
      "    ZHZ    ZHZ  ",
      "    ZHZ    ZHZ  ",
      "    jjj    jjj  ",
      "    ZHZ    ZHZ  ",
      "    ZHZ    ZHZ  ",
      "    jjj    jjj  ",
      "    ZHZ    ZHZ  ",
      "    ZHZ    ZHZ  ",
      "    jqj    jqj  ",
      "                ",
      "                ",
      "                ",
      "                "
    ],
    [
      "                ",
      "                ",
      "    jrj    jrj  ",
      "    ZHZ    ZHZ  ",
      "    ZHZ    ZHZ  ",
      "    jjj    jjj  ",
      "    ZHZ    ZHZ  ",
      "    ZHZ    ZHZ  ",
      "    jjj    jjj  ",
      "    ZHZ    ZHZ  ",
      "    ZHZ    ZHZ  ",
      "    jqj    jqj  ",
      "                ",
      "                ",
      "                ",
      "                "
    ],
    [
      "                ",
      "                ",
      "    jrj    jrj  ",
      "    ZHZ    ZHZ  ",
      "    ZHZ    ZHZ  ",
      "    jjj    jjj  ",
      "    ZHZ    ZHZ  ",
      "    ZHZ    ZHZ  ",
      "    jjj    jjj  ",
      "    ZHZ    ZHZ  ",
      "    ZHZ    ZHZ  ",
      "    jqj    jqj  ",
      "     E      E   ",
      "                ",
      "                ",
      "                "
    ]
  ]
}
