{
  "xsize": 16,
  "zsize": 16,
  "slices": [
    [
      "################",
      "######QSQS######",
      "##SQSQSQSQSQSQSQ",
      "##QSQSQSQSQSQSQS",
      "##SQSQSQSQSQSQSQ",
      "##QSQSQSQSQSQSQS",
      "#QSQSQSQSQSQSQSQ",
      "#SQSQSQSQSQSQSQS",
      "#QSQSQSQSQSQSQSQ",
      "#SQSQSQSQSQSQSQS",
      "##SQSQSQSQSQS  Q",
      "##QSQSQSQSQSQ  S",
      "##SQSQSQSQSQS  Q",
      "##QSQSQSQSQSQ  S",
      "##SQSQSQSQSQS))Q",
      "##QSQSQSQSQSQSQS"
    ],
    [
      "################",
      "######    ######",
      "##              ",
      "##              ",
      "##              ",
      "##              ",
      "#               ",
      "#               ",
      "#               ",
      "#            )) ",
      "##          Q  Q",
      "##          Q  Q",
      "##          Q  Q",
      "##          Q  Q",
      "##          Q  Q",
      "##              "
    ],
    [
      "################",
      "######    ######",
      "##              ",
      "##              ",
      "##              ",
      "##              ",
      "#               ",
      "#               ",
      "#               ",
      "#               ",
      "##          #))#",
      "##          #  #",
      "##          #  #",
      "##          #  #",
      "##          #  #",
      "##              "
    ],
    [
      "################",
      "######    ######",
      "##              ",
      "##              ",
      "##              ",
      "##              ",
      "#               ",
      "#               ",
      "#               ",
      "#               ",
      "##          #  #",
      "##          #))#",
      "##          #  #",
      "##          #  #",
      "##          #  #",
      "##              "
    ],
    [
      "################",
      "######    ######",
      "##              ",
      "##              ",
      "##              ",
      "##              ",
      "#               ",
      "#               ",
      "#               ",
      "#               ",
      "##          #  #",
      "##          #  #",
      "##          #))#",
      "##          #  #",
      "##          #  #",
      "##              "
    ],
    [
      "################",
      "################",
      "################",
      "################",
      "################",
      "################",
      "################",
      "################",
      "################",
      "################",
      "#############  #",
      "#############  #",
      "#############  #",
      "#############))#",
      "#############  #",
      "################"
    ]
  ]
}