{
  "xsize": 16,
  "zsize": 16,
  "slices": [
    [
      "SQSQSQSQSQSQSQ##",
      "Q          SQS##",
      "S          QSQ##",
      "Q          SQS##",
      "S          QSQ##",
      "Q          SQS##",
      "S          QSQS#",
      "Q          SQSQ#",
      "S          QSQS#",
      "Q          SQSQ#",
      "S          QSQ##",
      "QSQSQSQSQSQSQS##",
      "SQSQSQSQSQSQSQ##",
      "QSQSQSQSQSQSQS##",
      "######SQSQ######",
      "################"
    ],
    [
      "::::::::::::  ##",
      ":          :  ##",
      ":          :  ##",
      ":          :  ##",
      ":          :  ##",
      ":          :  ##",
      ":          :   #",
      ":          :   #",
      ":          :   #",
      ":          :   #",
      ":          :  ##",
      "::::::::::::  ##",
      "              ##",
      "             *##",
      "######    ######",
      "################"
    ],
    [
      "              ##",
      "              ##",
      "              ##",
      "              ##",
      "              ##",
      "              ##",
      "               #",
      "               #",
      "               #",
      "               #",
      "              ##",
      "              ##",
      "              ##",
      "              ##",
      "######    ######",
      "################"
    ],
    [
      "              ##",
      "              ##",
      "              ##",
      "              ##",
      "              ##",
      "              ##",
      "               #",
      "               #",
      "               #",
      "               #",
      "              ##",
      "              ##",
      "              ##",
      "              ##",
      "######    ######",
      "################"
    ],
    [
      "              ##",
      "              ##",
      "              ##",
      "              ##",
      "              ##",
      "              ##",
      "               #",
      "               #",
      "               #",
      "               #",
      "           E  ##",
      "              ##",
      "              ##",
      "              ##",
      "######    ######",
      "################"
    ],
    [
      "################",
      "#          #####",
      "#          #####",
      "#          #####",
      "#          #####",
      "#          #####",
      "#          #####",
      "#          #####",
      "#          #####",
      "#          #####",
      "#          #####",
      "################",
      "################",
      "################",
      "################",
      "################"
    ]
  ]
}