{
  "refpalette": "lostcities:center_interior",
  "xsize": 16,
  "zsize": 16,
  "slices": [
    [
      "                ",
      "                ",
      "                ",
      "    k k    k k  ",
      "    k k    k k  ",
      "    k k    k k  ",
      "    k k    k k  ",
      "    k k    k k  ",
      "                ",
      "                ",
      "                ",
      "                ",
      "                ",
      "                ",
      "                ",
      "                "
    ],
    [
      "                ",
      "                ",
      "    QoQ    QoQ  ",
      "    ZHZ    ZHZ  ",
      "    ZHZ    ZHZ  ",
      "    ZHZ    ZHZ  ",
      "    ZHZ    ZHZ  ",
      "    ZHZ    ZHZ  ",
      "    QoQ    QoQ  ",
      "                ",
      "                ",
      "    mjn    mjn  ",
      "                ",
      "                ",
      "                ",
      "                "
    ],
    [
      "                ",
      "                ",
      "    jrj    jrj  ",
      "    ZHZ    ZHZ  ",
      "    ZHZ    ZHZ  ",
      "    ZHZ    ZHZ  ",
      "    ZHZ    ZHZ  ",
      "    ZHZ    ZHZ  ",
      "    jjj    jjj  ",
      "                ",
      "                ",
      "    ZZZ    ZZZ  ",
      "                ",
      "                ",
      "                ",
      "                "
    ],
    [
      "                ",
      "                ",
      "    jrj    jrj  ",
      "    ZHZ    ZHZ  ",
      "    ZHZ    ZHZ  ",
      "    ZHZ    ZHZ  ",
      "    ZHZ    ZHZ  ",
      "    ZHZ    ZHZ  ",
      "    jjj    jjj  ",
      "                ",
      "                ",
      "                ",
      "                ",
      "                ",
      "                ",
      "                "
    ],
    [
      "                ",
      "                ",
      "    jrj    jrj  ",
      "    ZHZ    ZHZ  ",
      "    ZHZ    ZHZ  ",
      "    ZHZ    ZHZ  ",
      "    ZHZ    ZHZ  ",
      "    ZHZ    ZHZ  ",
      "    jjj    jjj  ",
      "                ",
      "                ",
      "                ",
      "     E      E   ",
      "                ",
      "                ",
      "                "
    ]
  ]
}
