{
  "xsize": 16,
  "zsize": 16,
  "refpalette": "lostcities:rails",
  "slices": [
    [
      "      yyIyy     ",
      "      yyIyy     ",
      "      yyIyy     ",
      "yyyyyyyyIyy     ",
      "yyyyyyyyIyy     ",
      "IIIIIIIIIyy     ",
      "yyyyyyyyyyy     ",
      "yyyyyyyyyyy     ",
      "yyyyyyyyyyy     ",
      "IIIIIIIIIyy     ",
      "yyyyyyyyIyy     ",
      "yyyyyyyyIyy     ",
      "      yyIyy     ",
      "      yyIyy     ",
      "      yyIyy     ",
      "      yyIyy     "
    ],
    [
      "      yJkJy     ",
      "      yJkJy     ",
      "      yJkJy     ",
      "yyyyyyyJkJy     ",
      "JJJJJJJgmJy     ",
      "eeeeeeefrJy     ",
      "JJJJJJJJJJy     ",
      "yyyyyyyyyyy     ",
      "JJJJJJJJJJy     ",
      "eeeeeeefsJy     ",
      "JJJJJJJgmJy     ",
      "yyyyyyyJkJy     ",
      "      yJkJy     ",
      "      yJkJy     ",
      "      yJkJy     ",
      "      yJkJy     "
    ],
    [
      "      y~~~y     ",
      "      y~~~y     ",
      "      y~~~y     ",
      "yyyyyyy~~~y     ",
      "~~~~~~~~~~y     ",
      "~~~~~~~~~~y     ",
      "~~~~~~~~~~y     ",
      "~~~~~~~~yyy     ",
      "~~~~~~~~~~y     ",
      "~~~~~~~~~~y     ",
      "~~~~~~~~~~y     ",
      "yyyyyyy~~~y     ",
      "      y~~~y     ",
      "      y~~~y     ",
      "      y~~~y     ",
      "      y~~~y     "
    ],
    [
      "      y~~~y     ",
      "      y~~~y     ",
      "      y~~~y     ",
      "yyyyyyy~~~y     ",
      "~~~~~~~~~~y     ",
      "~~~~~~~~~~y     ",
      "~~~~~~~~~~y     ",
      "~~~~~~~~yyy     ",
      "~~~~~~~~~~y     ",
      "~~~~~~~~~~y     ",
      "~~~~~~~~~~y     ",
      "yyyyyyy~~~y     ",
      "      y~~~y     ",
      "      y~~~y     ",
      "      y~~~y     ",
      "      y~~~y     "
    ],
    [
      "      y~~~y     ",
      "      y~~~y     ",
      "      y~~~y     ",
      "yyyyyyy~~~y     ",
      "~~~~~~~~~~y     ",
      "~~~~~~~~~~y     ",
      "~~~~~~~~~~y     ",
      "~~~~~~~~yyy     ",
      "~~~~~~~~~~y     ",
      "~~~~~~~~~~y     ",
      "~~~~~~~~~~y     ",
      "yyyyyyy~~~y     ",
      "      y~~~y     ",
      "      y~~~y     ",
      "      y~~~y     ",
      "      y~~~y     "
    ],
    [
      "      yyyyy     ",
      "      yyyyy     ",
      "      yyyyy     ",
      "yyyyyyyyyyy     ",
      "yyyyyyyyyyy     ",
      "yyyyyyyyyyy     ",
      "yyyyyyyyyyy     ",
      "yyyyyyyyyyy     ",
      "yyyyyyyyyyy     ",
      "yyyyyyyyyyy     ",
      "yyyyyyyyyyy     ",
      "yyyyyyyyyyy     ",
      "      yyyyy     ",
      "      yyyyy     ",
      "      yyyyy     ",
      "      yyyyy     "
    ]
  ]
}