{
  "xsize": 16,
  "zsize": 16,
  "refpalette": "lostcities:factory",
  "slices": [
    [
      "    5         55",
      "   5         55 ",
      "555          5  ",
      "            5  &",
      "            5   ",
      "           5    ",
      "           5    ",
      "           5    ",
      "           5    ",
      "           5    ",
      "           5    ",
      "           5    ",
      "            5   ",
      "            5   ",
      "             5  ",
      "             55 "
    ],
    [
      "    5        &55",
      "   5         55 ",
      "555          5 &",
      "            5  &",
      "            5   ",
      "           5    ",
      "           5    ",
      "           5    ",
      "           5    ",
      "           5    ",
      "           5    ",
      "           5    ",
      "            5   ",
      "            5   ",
      "             5  ",
      "             55 "
    ],
    [
      "    5         55",
      "   5         55 ",
      "555          5 &",
      "            5   ",
      "            5   ",
      "           5    ",
      "           5    ",
      "           5    ",
      "           5    ",
      "           5    ",
      "           5    ",
      "           5    ",
      "            5   ",
      "            5   ",
      "             5  ",
      "             55 "
    ],
    [
      "    5       !!55",
      "   5       !!55 ",
      "555       !!!5 &",
      "          !!5   ",
      "          !!5   ",
      "         !!5    ",
      "         !!5    ",
      "         !!5    ",
      "         !!5    ",
      "         !!5    ",
      "         !!5    ",
      "         !!5    ",
      "          !!5   ",
      "          !!5   ",
      "          !!!5  ",
      "           !!55 "
    ],
    [
      "    5        &55",
      "   5         55 ",
      "555          5 &",
      "            5   ",
      "            5   ",
      "           5    ",
      "           5    ",
      "           5    ",
      "           5    ",
      "           5    ",
      "           5    ",
      "           5    ",
      "            5   ",
      "            5   ",
      "             5  ",
      "             55 "
    ],
    [
      "    5        &55",
      "   5         55&",
      "555          5&&",
      "            5  &",
      "            5   ",
      "           5    ",
      "           5    ",
      "           5    ",
      "           5    ",
      "           5    ",
      "           5    ",
      "           5    ",
      "            5   ",
      "            5   ",
      "             5  ",
      "             55 "
    ]
  ]
}