{
  "refpalette": "lostcities:factory_common",
  "xsize": 16,
  "zsize": 16,
  "slices": [
    [
      "                ",
      "                ",
      "                ",
      "                ",
      "                ",
      "                ",
      "                ",
      "     1          ",
      "                ",
      "                ",
      "                ",
      "                ",
      "                ",
      "                ",
      "                ",
      "                "
    ],
    [
      "                ",
      "                ",
      "  #::::  ::::#  ",
      "  :          :  ",
      "  : uuu: uuu :  ",
      "  : uuu: uuu :  ",
      "  :          :  ",
      "  : uuu  uuu :  ",
      "  : uuu  uuu :  ",
      "  :          :  ",
      "  : uuu :uuu :  ",
      "  : uuu :uuu :  ",
      "  :          :  ",
      "  #::::  ::::#  ",
      "                ",
      "                "
    ],
    [
      "                ",
      "                ",
      "  #::::  ::::#  ",
      "  :          :  ",
      "  : MMMg MMM :  ",
      "  : MMM  MMM :  ",
      "  :          :  ",
      "  : MMM  MMM :  ",
      "  : MMM  MMM :  ",
      "  :          :  ",
      "  : MMM  MMM :  ",
      "  : MMM gMMM :  ",
      "  :          :  ",
      "  #::::  ::::#  ",
      "                ",
      "                "
    ],
    [
      "                ",
      "                ",
      "  #::::::::::#  ",
      "  :          :  ",
      "  :  V    V  :  ",
      "  :          :  ",
      "  :          :  ",
      "  :  V    V  :  ",
      "  :          :  ",
      "  :          :  ",
      "  :  V    V  :  ",
      "  :          :  ",
      "  :          :  ",
      "  #::::::::::#  ",
      "                ",
      "                "
    ],
    [
      "                ",
      "                ",
      "  #::::::::::#  ",
      "  :          :  ",
      "  :  V    V  :  ",
      "  :          :  ",
      "  :          :  ",
      "  :  V    V  :  ",
      "  :          :  ",
      "  :          :  ",
      "  :  V    V  :  ",
      "  :          :  ",
      "  :          :  ",
      "  #::::::::::#  ",
      "                ",
      "                "
    ]
  ]
}
