{
  "meta": [
    {
      "key": "dontconnect",
      "boolean": true
    }
  ],
  "xsize": 16,
  "zsize": 16,
  "refpalette": "lcmt:factory_common",
  "slices": [
    [
      "$##$ $aaaa$ $ $ ",
      "#mf#a#    #a####",
      "#ff             ",
      "#ff             ",
      "#ff             ",
      "#ff             ",
      "#ff             ",
      "#ff             ",
      "#ff             ",
      "#ff             ",
      "#ff             ",
      "#ff             ",
      "#ff             ",
      "#ff             ",
      "#ff             ",
      "#ff             "
    ],
    [
      "$##$ $aaaa$ $ $ ",
      "#m:#a#    #a####",
      "# :             ",
      "# :             ",
      "# :             ",
      "# :             ",
      "# :             ",
      "# :             ",
      "# :             ",
      "# :             ",
      "# :             ",
      "# :             ",
      "# :             ",
      "# :             ",
      "# :             ",
      "# :             "
    ],
    [
      "$##$ $aaaa$ $ $ ",
      "#m #a#    #a####",
      "#               ",
      "#               ",
      "#               ",
      "#               ",
      "#               ",
      "#               ",
      "#               ",
      "#               ",
      "#               ",
      "#               ",
      "#               ",
      "#               ",
      "#               ",
      "#               "
    ],
    [
      "$##$ $aaaa$ $ $ ",
      "#m #a#    #a####",
      "#               ",
      "#               ",
      "#               ",
      "a               ",
      "a               ",
      "#               ",
      "#               ",
      "a               ",
      "a               ",
      "#               ",
      "#               ",
      "a               ",
      "a               ",
      "#               "
    ],
    [
      "$##$ $aaaa$ $ $ ",
      "#m #a#    #a####",
      "#               ",
      "#               ",
      "#               ",
      "#               ",
      "#               ",
      "#               ",
      "#               ",
      "#               ",
      "#               ",
      "#               ",
      "#               ",
      "#               ",
      "#               ",
      "#               "
    ],
    [
      "$##$ $aaaa$ $ $ ",
      "#m #a#    #a####",
      "#               ",
      "#               ",
      "#               ",
      "#               ",
      "#               ",
      "#               ",
      "#               ",
      "#               ",
      "#               ",
      "#               ",
      "#               ",
      "#               ",
      "#               ",
      "#               "
    ]
  ]
}
