{
  "xsize": 16,
  "zsize": 16,
  "refpalette": "pomkotsmechs:factory",
  "slices": [
    [
      "vvvvvvvvvvvvvvvv",
      "vvvvvvvvvvvvvvvv",
      "vvvvvvvvvvvvvvvv",
      "JJJJJJJJJJJJJJJJ",
      "JJJJJJJJJJJJJJJJ",
      "JJJJJJJJJJJJJJJJ",
      "JJJJJJJJJJJJJJJJ",
      "JJJJJJJJJJJJJJJJ",
      "JJJJJJJJJJJJJJJJ",
      "JJJJJJJJJJJJJJJJ",
      "JJJJJJJJJJJJJJJJ",
      "JJJJJJJJJJJJJJJJ",
      "JJJJJJJJJJJJJJJJ",
      "JJJJJJJJJJJJJJJJ",
      "JJJJJJJJJJJJJJJJ",
      "JJJJJJJJJJJJJJJJ"
    ],
    [
      "!              !",
      "!              !",
      "!              !",
      "!              !",
      "!              !",
      "                ",
      "                ",
      "                ",
      "                ",
      "                ",
      "                ",
      "            &&  ",
      "  &&         && ",
      " &&           &&",
      "&&           &&&",
      "!&&           !!"
    ],
    [
      "                ",
      "                ",
      "!              !",
      "                ",
      "                ",
      "                ",
      "                ",
      "                ",
      "                ",
      "                ",
      "                ",
      "                ",
      "                ",
      "                ",
      "              &&",
      "&&            !!"
    ],
    [
      "                ",
      "                ",
      "!              !",
      "                ",
      "                ",
      "                ",
      "                ",
      "                ",
      "                ",
      "                ",
      "                ",
      "                ",
      "                ",
      "                ",
      "&             &&",
      "!&           &!!"
    ],
    [
      "                ",
      "                ",
      "!              !",
      "                ",
      "                ",
      "                ",
      "                ",
      "                ",
      "                ",
      "                ",
      "                ",
      "                ",
      "                ",
      "                ",
      "&             &&",
      "&&           &!!"
    ],
    [
      "                ",
      "                ",
      "!              !",
      "                ",
      "                ",
      "                ",
      "                ",
      "                ",
      "                ",
      "                ",
      "                ",
      "                ",
      "                ",
      "                ",
      "              &&",
      "&            &!!"
    ]
  ]
}