{
  "xsize": 16,
  "zsize": 16,
  "refpalette": "pomkotsmechs:factory",
  "slices": [
    [
      " OVVVO OVVVO  i ",
      "             &i&",
      "              i ",
      " OVVVO OVVVO  i ",
      " VOOOV VOOOV  i ",
      " VOOOV VOOOV  i ",
      " VOOOV VOOOV  i ",
      " OVVVO OVVVO  i ",
      "              i ",
      "              i ",
      "/            !i ",
      "3            !!!",
      "             !!!",
      "              ! ",
      "!!!!!!dddddddd! ",
      "!!  !!        ! "
    ],
    [
      " OOOOO OOOOO  i ",
      "             &i&",
      "              i ",
      " OOOOO OOOOO  i ",
      " OOOOO OOOOO  i ",
      " OOOOO OOOOO  i ",
      " OOOOO OOOOO  i ",
      " OOOOO OOOOO  i ",
      "              i ",
      "              i ",
      "/            !i ",
      "3            !!!",
      "             !!!",
      "              ! ",
      "!!!!!!dddddddd! ",
      "!!  !!        !!"
    ],
    [
      " $   $ $   $ &i&",
      "             &i&",
      "              i ",
      " $   $ $   $  i ",
      "              i ",
      "              i ",
      "              i ",
      " $   $ $   $  i ",
      "              i ",
      "              i ",
      "/            !i ",
      "3            !!!",
      "             !!!",
      "              ! ",
      "!!!!!!dddddddd! ",
      "!!  !!        ! "
    ],
    [
      " OOOOO OOOOO &i&",
      "              i ",
      "              i ",
      " OOOOO OOOOO  i ",
      " OOOOO OOOOO  i ",
      " OOOOO OOOOO  i ",
      " OOOOO OOOOO  i ",
      " OOOOO OOOOO  i ",
      "              i ",
      "              i ",
      "/            !i ",
      "3            !!!",
      "             !!!",
      "              ! ",
      "!!!!!!dddddddd! ",
      "!!  !!        ! "
    ],
    [
      " OVVVO OVVVO &i&",
      "              i ",
      "              i ",
      " OVVVO OVVVO  i ",
      " V   V V   V  i ",
      " V <<V V <<V  i ",
      " VV<<V VV<<V  i ",
      " OVVVO OVVVO  i ",
      "              i ",
      "              i ",
      "/            !i ",
      "3            !!!",
      "             !!!",
      "              ! ",
      "!!!!!!dddddddd! ",
      "!!  !!        !!"
    ],
    [
      " OVVVO OVVVO &i&",
      "              i ",
      "           &  i ",
      " OVVVO OVVVO  i ",
      " V   V V   V  i ",
      " V   V V   V  i ",
      " VVVVV VVVVV  i ",
      " OVVVO OVVVO  i ",
      "              i ",
      "              i ",
      "V            !i ",
      "V            !!!",
      "             !!!",
      "              ! ",
      "!!!!!!dddddddd! ",
      "!!  !!        !I"
    ]
  ]
}