{
  "xsize": 16,
  "zsize": 16,
  "refpalette": "pomkotsmechs:factory",
  "slices": [
    [
      "55              ",
      " 55             ",
      "  5             ",
      "   5            ",
      "   5            ",
      "   55           ",
      "    5           ",
      "    5           ",
      "    5           ",
      "    5          &",
      "    5          &",
      "    5           ",
      "   55&&&&&&&&&& ",
      "   5      &&    ",
      "   5            ",
      "  5             "
    ],
    [
      "55  555555555555",
      " 555555555555555",
      "  55555555555555",
      "   5555555555555",
      "   5555555555555",
      "   5555555555555",
      "   5555555555555",
      "   5555555555555",
      "   5555555555555",
      "   5555555555555",
      "   5555555555555",
      "   5555555555555",
      "   5555555555555",
      "   5555555555555",
      "   5555555555555",
      "  55555555555555"
    ],
    [
      "55              ",
      " 55            5",
      "  5             ",
      "   5           5",
      "   5            ",
      "   55          5",
      "    5           ",
      "    5          5",
      "    5           ",
      "    5    5     5",
      "    5         &&",
      "    5&       &&5",
      "   55&&&&&&&&&&&",
      "   5&&    &&  &5",
      "   5            ",
      "  5            5"
    ],
    [
      "55             Ͳ",
      " 55            5",
      "  5            Ͳ",
      "   5           5",
      "   5           Ͳ",
      "   55          5",
      "    5          Ͳ",
      "    5          5",
      "    5          Ͳ",
      "    5    5     5",
      "    5          Ͳ",
      "    5         &5",
      "   55&        &Ͳ",
      "   5&          5",
      "   5           Ͳ",
      "  5            5"
    ],
    [
      "55              ",
      " 55             ",
      "  5             ",
      "   5            ",
      "   5            ",
      "   55           ",
      "    5           ",
      "    5           ",
      "    5           ",
      "    5    5      ",
      "    5           ",
      "    5          &",
      "   55&          ",
      "   5&           ",
      "   5            ",
      "  5             "
    ],
    [
      "55              ",
      " 55             ",
      "  5             ",
      "   5            ",
      "   5            ",
      "   55           ",
      "    5           ",
      "    5           ",
      "    5           ",
      "    5    5      ",
      "    5           ",
      "    5           ",
      "   55&          ",
      "   5&&          ",
      "   5&           ",
      "  5             "
    ]
  ]
}