{
  "xsize": 16,
  "zsize": 16,
  "refpalette": "pomkotsmechs:factory",
  "slices": [
    [
      "                ",
      "  ͳ,,,,,,,,,,q  ",
      "                ",
      "  $   $  $   $  ",
      "                ",
      "                ",
      "          &     ",
      "  $   $  $&& $  ",
      "          &     ",
      "                ",
      "                ",
      "                ",
      "                ",
      "                ",
      "  ͳ,,,,,,,,,,q  ",
      "                "
    ],
    [
      "                ",
      "                ",
      "                ",
      "  OOOOO  OOOOO  ",
      "  OOOOO  OOOOO  ",
      "  OOOOO  OOOOO  ",
      "  OOOOO  OOOOO  ",
      "  OOOOO &OOOOO  ",
      "         &&     ",
      "                ",
      "                ",
      "                ",
      "                ",
      "                ",
      "                ",
      "                "
    ],
    [
      "                ",
      "                ",
      "                ",
      "  OVVVO  OVVVO  ",
      "  V  <V  V <<V  ",
      "  V  <V  V <<V  ",
      "  V   V  V  VV  ",
      "  OVVVO &OVVVO  ",
      "         &      ",
      "                ",
      "                ",
      "                ",
      "                ",
      "                ",
      "                ",
      "                "
    ],
    [
      "                ",
      "                ",
      "                ",
      "  OVVVO  OVVVO  ",
      "  V   V  V  VV  ",
      "  V   V  V  VV  ",
      "      V  V  VV  ",
      "    VVO &OVVVO  ",
      "         &      ",
      "                ",
      "                ",
      "                ",
      "                ",
      "                ",
      "                ",
      "                "
    ],
    [
      "                ",
      "                ",
      "                ",
      "  OVVVO  OVVVO  ",
      "  VOOOV  VOOOV  ",
      "  VOOOV  VOOOV  ",
      "   OOOV  VOOOV  ",
      "    VVO &OVVVO  ",
      "         &&     ",
      "                ",
      "                ",
      "                ",
      "                ",
      "                ",
      "                ",
      "                "
    ],
    [
      "                ",
      "                ",
      "                ",
      "  OOOOO  OOOOO  ",
      "  OOOOO  OOOOO  ",
      "  OOOOO  OOOOO  ",
      "  &OOOO  OOOOO  ",
      "   &OOO  OOOOO  ",
      "          &     ",
      "                ",
      "                ",
      "                ",
      "                ",
      "                ",
      "                ",
      "                "
    ]
  ]
}