{
  "xsize": 16,
  "zsize": 16,
  "refpalette": "lostcities:factory",
  "slices": [
    [
      "                ",
      "     &&         ",
      "    55&&    55  ",
      "   5555&   5555 ",
      "   5555    5555 ",
      "    55      55  ",
      "                ",
      "                ",
      "                ",
      "    OO      OO&&",
      "   O  O    O &O&",
      "   O  O    O  O&",
      "    OO      OO  ",
      "                ",
      "                ",
      "                "
    ],
    [
      "     &          ",
      "    !!&     !!  ",
      "   !OO!    !OO! ",
      "  !O &O!  !O  O!",
      "  !O  O!  !O  O!",
      "   !OO!    !OO! ",
      "    !!      !!  ",
      "                ",
      "    !!      !!  ",
      "   !OO!    !OO!&",
      "  !O  O!  !O &O!",
      "  !O  O!  !O  O!",
      "   !OO!    !OO! ",
      "    !!      !!  ",
      "      !!!!!!    ",
      "    !!      !!  "
    ],
    [
      "     &          ",
      "    &&&         ",
      "    OO&     OO  ",
      "   O &O    O  O ",
      "   O  O    O  O ",
      "    OO      OO  ",
      "                ",
      "                ",
      "             &  ",
      "    OO      OO&&",
      "   O  O    O&&O&",
      "   O  O    O &O&",
      "    OO      OO  ",
      "                ",
      "                ",
      "                "
    ],
    [
      "     &          ",
      "    &&&         ",
      "   &OO&     OO  ",
      "   O &O    O  O ",
      "   O  O    O  O ",
      "    OO      OO  ",
      "                ",
      "                ",
      "            &&  ",
      "    OO     &OO& ",
      "   O  O    O&&O&",
      "   O  O    O  O ",
      "    OO      OO  ",
      "                ",
      "                ",
      "                "
    ],
    [
      "    &&          ",
      "   &&&&         ",
      "  &&OO      OO  ",
      "  &O& O    O  O ",
      "   O  O    O  O ",
      "    OO      OO  ",
      "                ",
      "                ",
      "            &   ",
      "    OO     &OO  ",
      "   O  O    O& O ",
      "   O  O!!!!O  O ",
      "    OO!!!!!!OO  ",
      "      !!!!!!    ",
      "      !!!!!!    ",
      "      !!!!!!    "
    ],
    [
      "                ",
      "    &&          ",
      "   &OO      OO  ",
      "  &O& O    O  O ",
      "   O  O    O  O ",
      "    OO      OO  ",
      "                ",
      "                ",
      "            &   ",
      "    OO     &OO  ",
      "   O  O    O& O ",
      "   O  O    O  O ",
      "    OO      OO  ",
      "                ",
      "                ",
      "                "
    ]
  ]
}