{
  "xsize": 16,
  "zsize": 16,
  "refpalette": "pomkotsmechs:factory",
  "slices": [
    [
      "V             i ",
      "V             i ",
      "V             i ",
      "VVVVVV        i ",
      "VVVVVV        i ",
      "VVVVVV        i ",
      "mmmnVV        i ",
      "  &kVV        i ",
      "   kVV        i ",
      "   kVV       &i&",
      "   kVV        i ",
      "   kVV        i ",
      "   kVVVVVVVVV!i ",
      "   kVVVVVVVVV!!!",
      "   2mmmmmmmmm!!!",
      "              ! "
    ],
    [
      "              i ",
      "              i ",
      "              i ",
      "              i ",
      "              i ",
      "              i ",
      ",,,/          i ",
      "  &0&         i ",
      "!  0          i ",
      "!  0         &i&",
      "!  0          i ",
      "!  0          i ",
      "   kj/       !i ",
      "   knn       !!!",
      "   2mm,,,,,,,!!!",
      "              ! "
    ],
    [
      "              i ",
      "              i ",
      "              i ",
      "              i ",
      "              i ",
      "              i ",
      "              i ",
      "   &          i ",
      "              i ",
      "             &i&",
      "              i ",
      "              i ",
      "    +/       !i ",
      "    23       !!!",
      "             !!!",
      "              ! "
    ],
    [
      "              i ",
      "              i ",
      "              i ",
      "              i ",
      "              i ",
      "              i ",
      "              i ",
      "              i ",
      "              i&",
      "             &i&",
      "              i ",
      "              i ",
      "    +/       !i ",
      "    23       !!!",
      "             !!!",
      "              ! "
    ],
    [
      "              i ",
      "              i ",
      "              i ",
      "              i ",
      "              i ",
      "              i ",
      "              i ",
      "              i&",
      "              i&",
      "             &i&",
      "              i&",
      "              i ",
      "    +/       !i ",
      "    23       !!!",
      "             !!!",
      "              ! "
    ],
    [
      "              i ",
      "              i ",
      "              i ",
      "              i ",
      "              i ",
      "              i ",
      "              i ",
      "              i&",
      "              i&",
      "              i&",
      "              i ",
      "              i ",
      "    +/       !i ",
      "    23       !!!",
      "             !!!",
      "              ! "
    ]
  ]
}