{
  "xsize": 16,
  "zsize": 16,
  "refpalette": "pomkotsmechs:factory",
  "slices": [
    [
      "    V  &   V    ",
      "    V  &&  V    ",
      "    V   &  V&   ",
      "    V  &&  V&& &",
      "    V  &&  V&   ",
      "    V  &&& V    ",
      "    V &&&VVV    ",
      "    V &&&VVV    ",
      "    VJJJJJJV    ",
      "   JJ    &&JJ   ",
      "  J       &  J  ",
      " J            J ",
      "VJ           &JV",
      "J             &J",
      "J              J",
      "J              J"
    ],
    [
      "    VVVVVVVV!   ",
      "      VVVVVV!   ",
      "       VVVVV!   ",
      "      VVVVVV!&  ",
      "    V VVVVVV!   ",
      "    V  VVVVV!   ",
      "      &VVVVV!   ",
      "       VVVVV!   ",
      "   !! JJJJJV!   ",
      "   JJ    &&JJ   ",
      "  J       &  J  ",
      "!J            J ",
      "VJ           &J&",
      "J             &J",
      "J              J",
      "J              J"
    ],
    [
      "       &   !    ",
      "       &&  !    ",
      "        &  !    ",
      "       &&  !&   ",
      "       &&  !    ",
      "       &&& !    ",
      "       &&& !    ",
      "        &&&!    ",
      "       JJJJ!    ",
      "   J     &&JJ   ",
      "  J       &  J  ",
      " J            J ",
      "!J           &J&",
      "J             & ",
      "J              J",
      "J              J"
    ],
    [
      "                ",
      "                ",
      "                ",
      "                ",
      "                ",
      "        &       ",
      "                ",
      "         &      ",
      "      JJJJJ     ",
      "   JJ    &&JJ   ",
      "  J       &  J  ",
      " J            J ",
      " J           &J&",
      "J             &J",
      "J              J",
      "J              J"
    ],
    [
      "                ",
      "                ",
      "                ",
      "                ",
      "                ",
      "                ",
      "                ",
      "         &      ",
      "     JJJJJJ     ",
      "   JJ    &&JJ   ",
      "  J       &  J  ",
      " J            J ",
      " J           &J&",
      "J             &J",
      "J              J",
      "J              J"
    ],
    [
      "                ",
      "                ",
      "                ",
      "                ",
      "                ",
      "                ",
      "                ",
      "         &      ",
      "     JJJJJJ     ",
      "   JJ   &&&JJ   ",
      "  J      &&  J  ",
      " J            J ",
      " J           &J&",
      "J             &J",
      "J              J",
      "J              J"
    ]
  ]
}