{
  "xsize": 16,
  "zsize": 16,
  "refpalette": "pomkotsmechs:factory",
  "slices": [
    [
      " JJ             ",
      " JJ&            ",
      "  JJ&           ",
      "  JJ            ",
      "   JJ           ",
      "   r            ",
      "   JJ           ",
      "   JJ           ",
      "   JJ           ",
      "   JJ           ",
      "   r            ",
      "   JJ           ",
      "  JJ            ",
      "  JJ&           ",
      " JJ&            ",
      " JJ             "
    ],
    [
      " JJ             ",
      " JJ&            ",
      "  JJ&           ",
      "  JJ            ",
      "   JJ           ",
      "   r            ",
      "   JJ           ",
      "   JJ           ",
      "   JJ           ",
      "   JJ           ",
      "   r            ",
      "   JJ           ",
      "  JJ            ",
      "  JJ&           ",
      " JJ&            ",
      " JJ             "
    ],
    [
      "!!!             ",
      "!!!&            ",
      "!!!!&           ",
      "!!!!            ",
      "!!!!!           ",
      "!!!!!           ",
      "!!!!!           ",
      "!!!!!           ",
      "!!!!!           ",
      "!!!!!           ",
      "!!!!!           ",
      "!!!!!           ",
      "!!!!&           ",
      "!!!!&&          ",
      "!!!&&           ",
      "!!!             "
    ],
    [
      " JJ             ",
      " JJ&            ",
      "  JJ&           ",
      "  JJ            ",
      "   JJ           ",
      "   r            ",
      "   JJ           ",
      "   JJ           ",
      "   JJ           ",
      "   JJ           ",
      "   r            ",
      "   JJ           ",
      "  JJ&           ",
      "  JJ&&          ",
      " JJ&&           ",
      " JJ             "
    ],
    [
      " JJ             ",
      " JJ&            ",
      "  JJ&           ",
      "  JJ            ",
      "   JJ           ",
      "&& r            ",
      "   JJ           ",
      "   JJ           ",
      "   JJ           ",
      "   JJ           ",
      "   r            ",
      "   JJ           ",
      "  JJ            ",
      "  JJ&           ",
      " JJ&            ",
      " JJ             "
    ],
    [
      "!JJ             ",
      "!JJ&            ",
      "!!JJ&           ",
      "!!JJ            ",
      "!!!JJ           ",
      "!!!!!           ",
      "!!!JJ           ",
      "!!!JJ           ",
      "!!!JJ           ",
      "!!!JJ           ",
      "!!!!!           ",
      "!!!JJ           ",
      "!!JJ            ",
      "!!JJ&           ",
      "!JJ&            ",
      "!JJ             "
    ]
  ]
}