{
  "xsize": 16,
  "zsize": 16,
  "refpalette": "lcmt:factory_common",
  "slices": [
    [
      "                ",
      "                ",
      "                ",
      "                ",
      "                ",
      "                ",
      "                ",
      "                ",
      "         1      ",
      "                ",
      "                ",
      "                ",
      "                ",
      "                ",
      "                ",
      "                "
    ],
    [
      "                ",
      "                ",
      "                ",
      "   ##########   ",
      "   #  %     #   ",
      "   # #    # #   ",
      "   # #ffff# #   ",
      "   : #QQQQ#%    ",
      "   : #QQQQ#     ",
      "   # #ffff# #   ",
      "   # #  % #%#   ",
      "   #        #   ",
      "   ##########   ",
      "                ",
      "                ",
      "                "
    ],
    [
      "                ",
      "                ",
      "                ",
      "   ##########   ",
      "   #    %   #   ",
      "   # #    # #   ",
      "   # #c CJ# #   ",
      "   : #QQQQ#     ",
      "   : #QQQQ#     ",
      "   # #  jJ#%#   ",
      "   # #    # #   ",
      "   #        #   ",
      "   ##########   ",
      "                ",
      "                ",
      "                "
    ],
    [
      "                ",
      "                ",
      "                ",
      "   ##########   ",
      "   #        #   ",
      "   # #    # #   ",
      "   # #ffff# #   ",
      "   # #QQQQ# #   ",
      "   # #QQQQ# #   ",
      "   # #ffff# #   ",
      "   # #    # #   ",
      "   #        #   ",
      "   ##########   ",
      "                ",
      "                ",
      "                "
    ],
    [
      "                ",
      "                ",
      "                ",
      "   ##########   ",
      "   #        #   ",
      "   # #    # #   ",
      "   # #M e # #   ",
      "   # #QQQQ# #   ",
      "   # #QQQQ# #   ",
      "   # # **!# #   ",
      "   # #    # #   ",
      "   #        #   ",
      "   ##########   ",
      "                ",
      "                ",
      "                "
    ]
  ]
}
