{
  "xsize": 16,
  "zsize": 16,
  "refpalette": "pomkotsmechs:factory",
  "slices": [
    [
      "                ",
      "                ",
      "                ",
      "                ",
      "                ",
      "     &        &&",
      "    &!!      &&!",
      "     !ddddddddd!",
      "     !         !",
      "     !  &&     !",
      "     ! &&&&    !",
      "     !  &&     !",
      "     !   &&    !",
      "     !  &&&&   !",
      "     !   &&    !",
      "     !         !"
    ],
    [
      "                ",
      "                ",
      "                ",
      "                ",
      "                ",
      "     &       && ",
      "    &!!     &&&!",
      "     !ddddddddd!",
      "     !         !",
      "     !  &      !",
      "     ! &&&     !",
      "     !  &      !",
      "     !   &     !",
      "     !  &&&    !",
      "     !   &     !",
      "     !         !"
    ],
    [
      "                ",
      "                ",
      "                ",
      "                ",
      "                ",
      "     &       &  ",
      "    &!!     &&&!",
      "    &!ddddddddd!",
      "     !  &      !",
      "     ! &&&     !",
      "     ! &&&     !",
      "     !  &&     !",
      "     !  &&&    !",
      "     !  &&&    !",
      "     !   &     !",
      "     !         !"
    ],
    [
      "                ",
      "                ",
      "                ",
      "                ",
      "                ",
      "            &&  ",
      "     !!    &&&&!",
      "    &!ddddddddd!",
      "     !&&&      !",
      "     !&&&&     !",
      "       &&      !",
      "        &&     !",
      "       &&&&    !",
      "     !  &&     !",
      "     !         !",
      "     !         !"
    ],
    [
      "                ",
      "                ",
      "                ",
      "                ",
      "                ",
      "     &     &&   ",
      "    &!!!!!!!!!!!",
      "    &!!!!!!!!!!!",
      "     !!!!!!!!!!!",
      "      &!!!!!!!!!",
      "       &!!!!!!!!",
      "        &!!!!!!!",
      "       &!!!!!!!!",
      "      !!!!!!!!!!",
      "     !!!!!!!!!!!",
      "     !!!!!!!!!!!"
    ],
    [
      "                ",
      "                ",
      "                ",
      "                ",
      "                ",
      "           &&   ",
      "     &!!!!!!!!!!",
      "    &&!!!!!!!!!!",
      "     &!!!!!!!!!!",
      "      && !!!!!!!",
      "          !!!!!!",
      "          !!!!!!",
      "        &&!!!!!!",
      "       &&!!!!!!!",
      "      !!!!!!!!!!",
      "      !!!!!!!!!!"
    ]
  ]
}