{
  "xsize": 16,
  "zsize": 16,
  "refpalette": "lostcities:factory",
  "slices": [
    [
      " JJ   &&        ",
      " JJ&            ",
      "  JJ&           ",
      "  JJ            ",
      "   JJ           ",
      "   r            ",
      "   JJ           ",
      "   JJ           ",
      "   JJ           ",
      "   JJ           ",
      "   r            ",
      "   JJ           ",
      "  JJ            ",
      "  JJ&           ",
      " JJ& &&&        ",
      " JJ  &&&&&      "
    ],
    [
      " JJ             ",
      " JJ&            ",
      "  JJ&           ",
      "  JJ            ",
      "   JJ           ",
      "   r            ",
      "   JJ           ",
      "   JJ           ",
      "   JJ           ",
      "   JJ           ",
      "   r            ",
      "   JJ           ",
      "  JJ            ",
      "  JJ&           ",
      " JJ&   &&       ",
      " JJ   &&&&&     "
    ],
    [
      "JJJ       JJ    ",
      "JJJ&      JJ    ",
      "JJJJ&     JJJ   ",
      "JJJJ       JJ   ",
      "JJJJJ      JJ   ",
      "JJJr       JJ   ",
      "JJJJJ      JJ   ",
      "JJJJJJ     JJ   ",
      "JJJJJJ     JJ   ",
      "JJJJJ      JJ   ",
      "JJJr       JJ   ",
      "JJJJJ     JJJ   ",
      "JJJJ      JJ    ",
      "JJJJ&     JJ    ",
      "JJJ&    & JJ    ",
      "JJJ    &&JJ     "
    ],
    [
      " JJ       JJ    ",
      " JJ&      JJ    ",
      "  JJ&     JJJ   ",
      "  JJ&      JJ   ",
      "   JJ      JJ   ",
      "   r       JJ   ",
      "   JJ      JJ   ",
      "   JJJ     JJ   ",
      "   JJJ     JJ   ",
      "   JJ      JJ   ",
      "   r       JJ   ",
      "   JJ     JJJ   ",
      "  JJ      JJ    ",
      "  JJ&     JJ    ",
      " JJ&      JJ    ",
      " JJ     &JJ     "
    ],
    [
      " r              ",
      " r &            ",
      "  r&&           ",
      "  r&&           ",
      "   r            ",
      "   r            ",
      "   r            ",
      "   r            ",
      "   r            ",
      "   r            ",
      "   r            ",
      "   r            ",
      "  r&            ",
      "  r&&           ",
      " r &            ",
      " r              "
    ],
    [
      " JJ             ",
      " JJ&            ",
      "  JJ&           ",
      "  JJ            ",
      "   JJ           ",
      "   r            ",
      "   JJ           ",
      "   JJ           ",
      "   JJ           ",
      "   JJ           ",
      "   r            ",
      "   JJ           ",
      "  JJ            ",
      "  JJ&           ",
      " JJ&            ",
      " JJ             "
    ]
  ]
}