{
  "xsize": 16,
  "zsize": 16,
  "refpalette": "pomkotsmechs:factory",
  "slices": [
    [
      "                ",
      " !!!!!!!!!!     ",
      "         &&&    ",
      "        &&&     ",
      "        &       ",
      " !!!!!!!!!!     ",
      "&&&    &        ",
      " &              ",
      "                ",
      " !!!!!!!!!!     ",
      "                ",
      "                ",
      "          &     ",
      " !!!!!!!!!!&    ",
      "        &&&&    ",
      "      &&& &     "
    ],
    [
      "                ",
      " OOOOOOOOOO     ",
      " OVVVVVVVVO&    ",
      " OVVVVVVVVO     ",
      " OVVVVVVVVO     ",
      " OVVVVVVVVO     ",
      "&OVVVVVVVVO     ",
      " OVVVVVVVVO     ",
      " OVVVVVVVVO     ",
      " OVVVVVVVVO     ",
      " OVVVVVVVVO     ",
      " OVVVVVVVVO     ",
      " OVVVVVVVVO     ",
      " OVVVVVVVVO     ",
      " OVVVVVVVVO&    ",
      " OVVVVVVVVO     "
    ],
    [
      "                ",
      " OVVVVVVVVO     ",
      " V       &V&    ",
      " V      &&V     ",
      " V      & V     ",
      " V     && V     ",
      "&V&   &&& V     ",
      "&V&    &  V     ",
      " V        V     ",
      " V        V     ",
      " V        V     ",
      " O        O     ",
      " V        V     ",
      " V      &&V     ",
      " V    &&&&V&    ",
      " V   &&&&&V     "
    ],
    [
      "                ",
      " OVVVVVV        ",
      " V        &     ",
      " V        V     ",
      " V        V     ",
      " V     && V     ",
      " V    &&&&V     ",
      "&V&    && V     ",
      " V        V     ",
      " V        V     ",
      " V        V     ",
      " O        O     ",
      " V        V     ",
      " V       &V     ",
      " V    & &&V&    ",
      " V   &&& &V     "
    ],
    [
      "                ",
      " OVVVVVV        ",
      " V              ",
      " V              ",
      " V        V     ",
      " V      & V     ",
      " V     &&&V     ",
      "&V&     & V     ",
      " V        V     ",
      " V        V     ",
      " V        V     ",
      " O        O     ",
      " V        V     ",
      " V       &V     ",
      " V    & &&V&    ",
      " V   &&&&&V     "
    ],
    [
      "                ",
      " OVVVVVV        ",
      " V              ",
      " V              ",
      " V      & V     ",
      " V     &&&V     ",
      " V     &&&V     ",
      "&V&     & V     ",
      "&V&       V     ",
      " V        V     ",
      " V        V     ",
      " O        O     ",
      " V        V     ",
      " V        V     ",
      " V       &V&    ",
      " V    &&&&V&    "
    ]
  ]
}