{
  "xsize": 16,
  "zsize": 16,
  "refpalette": "pomkotsmechs:factory",
  "slices": [
    [
      "                ",
      "                ",
      "                ",
      "                ",
      "                ",
      "                ",
      "                ",
      "                ",
      "                ",
      "                ",
      "   J JJ   J     ",
      " JJJrJJJJ JJJ & ",
      "JJJ        JJJJ&",
      "J            JJJ",
      "               J",
      "                "
    ],
    [
      "                ",
      "                ",
      "                ",
      "                ",
      "                ",
      "                ",
      "                ",
      "                ",
      "                ",
      "                ",
      "   J      J     ",
      " JJJrrrrrrJJJ & ",
      "JJJ        JJJJ&",
      "J            JJJ",
      "               J",
      "                "
    ],
    [
      "                ",
      "                ",
      "                ",
      "                ",
      "                ",
      "                ",
      "                ",
      "                ",
      "                ",
      "                ",
      "   !!!!!!!!     ",
      " !!!!!!!!!!!! &&",
      "!!!!!!!!!!!!JJ!&",
      "!!!!!!!!!!JJ!!!!",
      "!!!!!!!!JJ!!!!!!",
      "!!!!!!JJ!!!!!!!!"
    ],
    [
      "                ",
      "                ",
      "                ",
      "                ",
      "                ",
      "                ",
      "                ",
      "                ",
      "                ",
      "                ",
      "   J JJJJ J     ",
      " JJJrJJJJrJJJ   ",
      "JJJ        JJJJ&",
      "J         JJ JJJ",
      "        JJ     J",
      "      JJ        "
    ],
    [
      "                ",
      "                ",
      "                ",
      "                ",
      "                ",
      "                ",
      "                ",
      "                ",
      "                ",
      "                ",
      "   J JJJJ J     ",
      " JJJrJJJJrJJJ   ",
      "JJJ        JJJJ&",
      "J            JJJ",
      "   &           J",
      "   &            "
    ],
    [
      "                ",
      "                ",
      "                ",
      "                ",
      "                ",
      "                ",
      "                ",
      "                ",
      "                ",
      "                ",
      "   !!!!!!!J     ",
      " !!!!!!!!!JJJ   ",
      "!!!!!!!!!!!JJJJ&",
      "!!!!!!!!!!!!!JJJ",
      "!!!!!!!!!!!!!!!J",
      "!!!!!!!!!!!!!!!!"
    ]
  ]
}