{
  "meta": [
    {
      "key": "dontconnect",
      "boolean": true
    }
  ],
  "xsize": 16,
  "zsize": 16,
  "refpalette": "lcmt:factory_common",
  "slices": [
    [
      "################",
      "SSSSSSSSSSSSSSm#",
      "SSSSSSSSSSSSSSS#",
      "SSSSSSSSSSSSSSS#",
      "SSSSSSSSSSSSSSS#",
      "SSSSSSSSSSSSSSS#",
      "SSSSSSSSSSSSSSS#",
      "SSSSSSSSSSSSSSS#",
      "SSSSSSSSSSSSSSS#",
      "SSSSSSSSSSSSSSS#",
      "SSSSSSSSSSSSSSS#",
      "SSSSSSSSSSSSSSS#",
      "SSSSSSSSSSSSSSS#",
      "SSSSSSSSSSSSSSS#",
      "SSSSSSSSSSSSSSS#",
      "SSSSSSSSSSSSSSS#"
    ],
    [
      "################",
      "#             m#",
      "#              #",
      "#              #",
      "#              #",
      "#              #",
      "#              #",
      "               #",
      "               #",
      "#              #",
      "#              #",
      "#              #",
      "#              #",
      "#              #",
      "#              #",
      "#######  #######"
    ],
    [
      "################",
      "#             m#",
      "#              #",
      "#              #",
      "#              #",
      "#              #",
      "#              #",
      "               #",
      "               #",
      "#              #",
      "#              #",
      "#              #",
      "#              #",
      "#              #",
      "#              #",
      "#######  #######"
    ],
    [
      "################",
      "#             m#",
      "#              #",
      "#              #",
      "#              #",
      "#              #",
      "#              #",
      "#              #",
      "#              #",
      "#              #",
      "#              #",
      "#              #",
      "#              #",
      "#              #",
      "#              #",
      "################"
    ],
    [
      "################",
      "#             m#",
      "#              #",
      "#              #",
      "#              #",
      "#              #",
      "#              #",
      "#              #",
      "#              #",
      "#              #",
      "#              #",
      "#              #",
      "#              #",
      "#              #",
      "#              #",
      "################"
    ],
    [
      "################",
      "##############m#",
      "################",
      "################",
      "################",
      "################",
      "################",
      "################",
      "################",
      "################",
      "################",
      "################",
      "################",
      "################",
      "################",
      "################"
    ]
  ]
}
