{
  "xsize": 16,
  "zsize": 16,
  "refpalette": "lostcities:factory",
  "slices": [
    [
      "    &           ",
      "   &&           ",
      "   &            ",
      "   &            ",
      "                ",
      "                ",
      "  &&  !  !      ",
      "   &   !!       ",
      "   &   !!       ",
      "   &  !  !      ",
      "   &            ",
      "                ",
      "                ",
      "                ",
      "                ",
      "                "
    ],
    [
      "vVVVvVVVVVvvz|||",
      "VVVvvVVVVVvvvvzz",
      "vVVvVVVVVVvvvvvV",
      "vVVvVvvVVVvvvvvv",
      "vVVVVvVVzzvvvvvv",
      "vVVVVVVz||vvvvvv",
      "vzvvVVzz||vvvvvv",
      "v||vzzz|||vvvvvv",
      "v||v|||zz|vvvvvv",
      "v}}v}|zzVVvvvvvz",
      "v}}v}|zVVVvvvvvz",
      "v}}}}|zVVVvvvvv|",
      "v}}}}}|zzzvvvvv}",
      "v}}}}||zz|vvvvv}",
      "v||}||zz||vvvvv}",
      "vz||zzVzz|vvvvv|"
    ],
    [
      "    &        55 ",
      "   &&       !!55",
      "   &        !! 5",
      "   &            ",
      "                ",
      "  &             ",
      " &&&            ",
      "  &&            ",
      "   &            ",
      "  &&            ",
      "  &&&           ",
      "   &            ",
      "            !!  ",
      "            !! &",
      "              &5",
      "              55"
    ],
    [
      "             55 ",
      "              55",
      "               5",
      "                ",
      "  &             ",
      " &&&            ",
      " &&&            ",
      "  &             ",
      "  &             ",
      " &&&            ",
      " &&&&           ",
      "  &&            ",
      "                ",
      "                ",
      "               5",
      "              55"
    ],
    [
      "             55 ",
      "              55",
      "               5",
      "                ",
      "  &             ",
      " &&&            ",
      "  &             ",
      "                ",
      "  &             ",
      " &&&            ",
      "  &&            ",
      "                ",
      "                ",
      "                ",
      "               5",
      "              55"
    ],
    [
      "             55&",
      "              55",
      "              &5",
      "               &",
      " &&             ",
      "&&&&            ",
      " &&             ",
      "                ",
      "  &             ",
      " &&&            ",
      "  &             ",
      "                ",
      "                ",
      "                ",
      "               5",
      "              55"
    ]
  ]
}