{
  "xsize": 16,
  "zsize": 16,
  "refpalette": "pomkotsmechs:factory",
  "slices": [
    [
      "Vo    VVVV   &kV",
      "Vo    VVVV    kV",
      "Vn5   VVVV    kV",
      "Vo    VVVV    kV",
      "Vo    VVVV    kV",
      "Vo    VVVV    kV",
      "Vo    VVVV    kV",
      "m3    VVVV    2m",
      "      VVVV      ",
      "      VVVV      ",
      "j/    VVVV    +j",
      "Vo    VVVV    kV",
      "Vo    VVVV    kV",
      "Vo    VVVV    kV",
      "Vo    VVVV    kV",
      "Vo    VVVV    kV"
    ],
    [
      " 0    0  0   &0 ",
      " 0    0  0    0 ",
      " k5   0  0    0 ",
      " 0    0  0    0 ",
      " 0    0  0    0 ",
      "jo    0  0    kj",
      "no    0  0    kn",
      "m3    0  0    2m",
      "      0  0      ",
      "      0  0      ",
      "j/    0  0    +j",
      "no    0  0    kn",
      "mo    0  0    km",
      " 0    0  0    0 ",
      " 0    0  0    0 ",
      " 0    0  0    0 "
    ],
    [
      "                ",
      "                ",
      "  5             ",
      "                ",
      "                ",
      "/              +",
      "3              2",
      "                ",
      "                ",
      "                ",
      "                ",
      "/              +",
      "3              2",
      "                ",
      "                ",
      "                "
    ],
    [
      "                ",
      "                ",
      "  5             ",
      "                ",
      "                ",
      "/              +",
      "3              2",
      "                ",
      "                ",
      "                ",
      "                ",
      "/              +",
      "3              2",
      "                ",
      "                ",
      "                "
    ],
    [
      "                ",
      "                ",
      "  5             ",
      "                ",
      "                ",
      "/              +",
      "3              2",
      "                ",
      "                ",
      "                ",
      "                ",
      "/              +",
      "3              2",
      "                ",
      "                ",
      "                "
    ],
    [
      "                ",
      "                ",
      "  5             ",
      "                ",
      "                ",
      "/              +",
      "3              2",
      "                ",
      "                ",
      "                ",
      "                ",
      "/              +",
      "3              2",
      "                ",
      "                ",
      "                "
    ]
  ]
}