{
  "xsize": 16,
  "zsize": 16,
  "refpalette": "lostcities:factory",
  "slices": [
    [
      "                ",
      "                ",
      "                ",
      "                ",
      "                ",
      "                ",
      "      !  !      ",
      "       !!       ",
      "       !!       ",
      "      !  !      ",
      "                ",
      "                ",
      "        &&&&    ",
      "       &&     & ",
      "              & ",
      "    &           "
    ],
    [
      "                ",
      "                ",
      "vvvvv}}}}|zVvvvV",
      "|||}}}}}}|Vvvvvv",
      "}}|||}}}}zVvvvvV",
      "}|||||}}|zVvvvvV",
      "||zzzz|||zVvvvVV",
      "||zzVz||zVVvvvVV",
      "||zzzz||zVVvvvvV",
      "}|||||||zVvvvvvv",
      "|}}}}}|zVVvvvvvv",
      "z|}}}}|zVVvvvvVV",
      "Vz|}}}|zvvvvVzz|",
      "vVz||||vvVVVz|v}",
      "vVVz||zzVVVz||v}",
      "vvVzvzzzVVVzz|}}"
    ],
    [
      "                ",
      "                ",
      "                ",
      "                ",
      "                ",
      "            !!  ",
      "            !!  ",
      "                ",
      "                ",
      "                ",
      "                ",
      "                ",
      "     &&&&&&&    ",
      "   5555555    &&",
      " 55&&&&&  55 &&&",
      "5  &&&      55& "
    ],
    [
      "                ",
      "                ",
      "                ",
      "                ",
      "                ",
      "                ",
      "                ",
      "                ",
      "                ",
      "                ",
      "                ",
      "                ",
      "    &&         &",
      "   5555555    &&",
      " 55&&&    55 &&&",
      "5   &       55&&"
    ],
    [
      "                ",
      "                ",
      "                ",
      "                ",
      "                ",
      "                ",
      "                ",
      "                ",
      "                ",
      "                ",
      "                ",
      "                ",
      "               &",
      "   5&& 555    &&",
      " 55 &     55  &&",
      "5           55  "
    ],
    [
      "                ",
      "                ",
      "                ",
      "                ",
      "                ",
      "                ",
      "                ",
      "                ",
      "                ",
      "                ",
      "                ",
      "                ",
      "               &",
      "        55    &&",
      " 55       55   &",
      "5           55  "
    ]
  ]
}