{
  "xsize": 16,
  "zsize": 16,
  "refpalette": "pomkotsmechs:factory",
  "slices": [
    [
      "                ",
      "                ",
      "                ",
      "                ",
      "                ",
      "  &             ",
      "  &   !  !      ",
      "       !!       ",
      "       !!       ",
      "      !  !      ",
      "                ",
      "                ",
      "                ",
      "                ",
      "                ",
      "                "
    ],
    [
      "zzVvvvvvvvvv}|Vv",
      "|zzzvvvvv||||zVv",
      "|zzzz||}}||zzVVV",
      "|zVVVz|}||zVVVzz",
      "zzVvVVz|||zVVz||",
      "zVvvvVz||zzVVz|}",
      "VVvvvVVzzzzVVz||",
      "zzVVVVVzzzVVVzzz",
      "|zzVVVVVVVVVVVVV",
      "|zzzzzzVVVVVVVvv",
      "                ",
      "                ",
      "                ",
      "                ",
      "                ",
      "                "
    ],
    [
      "                ",
      "                ",
      "5              5",
      "55 &          55",
      "  555      555  ",
      " &&&55555555    ",
      "  &&!5    5   !!",
      "    !           ",
      "                ",
      "                ",
      "                ",
      "                ",
      "                ",
      "                ",
      "                ",
      "                "
    ],
    [
      "                ",
      "                ",
      "5              5",
      "55 &          55",
      "  555      555  ",
      "  &&55555555    ",
      "     5    5     ",
      "                ",
      "                ",
      "                ",
      "                ",
      "                ",
      "                ",
      "                ",
      "                ",
      "                "
    ],
    [
      "                ",
      "                ",
      "5              5",
      "55 &&         55",
      "  555&     555  ",
      "   &55555555    ",
      "    &5    5     ",
      "                ",
      "                ",
      "                ",
      "                ",
      "                ",
      "                ",
      "                ",
      "                ",
      "                "
    ],
    [
      "                ",
      "                ",
      "5              5",
      "55            55",
      "  555      555  ",
      "   &55555555    ",
      "    &5    5     ",
      "                ",
      "                ",
      "                ",
      "                ",
      "                ",
      "                ",
      "                ",
      "                ",
      "                "
    ]
  ]
}