{
  "xsize": 16,
  "zsize": 16,
  "refpalette": "lostcities:factory",
  "slices": [
    [
      "                ",
      "                ",
      "                ",
      "     !!         ",
      "     !!&        ",
      "      &         ",
      "                ",
      "          &     ",
      "QQQQ     &&&  ! ",
      " QQQQ     &!! ! ",
      "    QQ     !! ! ",
      "     QQ         ",
      "  &   QQ        ",
      " &&&  QQ        ",
      "  &   QQ        ",
      "    &  Q        "
    ],
    [
      "                ",
      "                ",
      "                ",
      "     !!         ",
      "     !!&        ",
      "      &         ",
      "QQ              ",
      "QQQQQ     &     ",
      "    QQ   &&&  ! ",
      "     QQ   &!!   ",
      "      QQ   !! ! ",
      "  &    QQ       ",
      " &&&    Q       ",
      " &&&    Q       ",
      "  &     QQ      ",
      "    &   QQ      "
    ],
    [
      "                ",
      "                ",
      "                ",
      "!!!! !!         ",
      "   !!!!&        ",
      "QQ    !!        ",
      "  QQQ  !!       ",
      "     QQ !!&     ",
      "      QQ !!&  ! ",
      "       QQ&!!! ! ",
      "        Q &!! ! ",
      "  &      Q !    ",
      " &&&     Q !!   ",
      "  &      Q  !   ",
      "          Q !   ",
      "    &     Q !   "
    ],
    [
      "                ",
      "                ",
      "                ",
      "!!!! !!         ",
      "QQ !!!!&        ",
      "  QQQ !!        ",
      "     QQ!!       ",
      "       Q!!      ",
      "        Q!!&  ! ",
      "         Q!!!   ",
      "         Q !! ! ",
      "  &       Q!    ",
      " &&&      Q!!   ",
      "  &       Q !   ",
      "           Q!   ",
      "    &      Q!   "
    ],
    [
      "                ",
      "                ",
      "                ",
      "     !!         ",
      "QQQQQ!!&        ",
      "     QQ         ",
      "       Q        ",
      "        Q       ",
      "         Q && ! ",
      "          Q!!&! ",
      "          Q!! ! ",
      "  &        Q    ",
      " &&&       Q    ",
      "  &        Q    ",
      "           Q    ",
      "           Q    "
    ],
    [
      "                ",
      "                ",
      "                ",
      "QQQQ !!         ",
      "    QQ!&        ",
      "      QQ        ",
      "        Q       ",
      "         Q      ",
      "          Q&& ! ",
      "          Q!!&  ",
      "           Q! ! ",
      "  &        Q    ",
      " &&&        Q   ",
      "  &         Q   ",
      "            Q   ",
      "            Q   "
    ]
  ]
}