{
  "xsize": 16,
  "zsize": 16,
  "refpalette": "pomkotsmechs:factory",
  "slices": [
    [
      "VVV!!!!!!!!!!VVV",
      "VVV!!!!!!!!!!VVV",
      "VVV!!!!!!!!!!VVV",
      "VVV!!!!!!!!!!VVV",
      "VVV!!!!!!!!!!VVV",
      "VVV!!!!!!!!!!VVV",
      "VVV!!!!!!!!!!VVV",
      "VVV!!!!!!!!!!VVV",
      "VVV!!!!!!!!!!VVV",
      "VVV!!!!!!!!!!VVV",
      "VVV!!!!!!!!!!VVV",
      "VVV!!!!!!!!!!VVV",
      "VVV!!!!!!!!!!VVV",
      "VVV!!!!!!!!!!VVV",
      "VVV!!!!!!!!!!VVV",
      "VVV!!!!!!!!!!VVV"
    ],
    [
      "               J",
      "               J",
      "                ",
      "                ",
      "                ",
      "                ",
      " !            !J",
      "               J",
      "               J",
      "               J",
      "               J",
      "                ",
      "JJ           JJJ",
      " V           JJV",
      "JJ           JJJ",
      "                "
    ],
    [
      "               X",
      "               J",
      "                ",
      "                ",
      "                ",
      "                ",
      " !            !J",
      "              &X",
      "               X",
      "               X",
      "               J",
      "                ",
      "JJ           JJJ",
      "VV           JJ ",
      "JJ           JJJ",
      "                "
    ],
    [
      "                ",
      "               J",
      "                ",
      "                ",
      "                ",
      "                ",
      " !            !J",
      "              &&",
      "               &",
      "                ",
      "               J",
      "                ",
      "JJ           JJJ",
      " J          &JJJ",
      "JJ          &JJJ",
      "             &  "
    ],
    [
      "               J",
      "               J",
      "                ",
      "                ",
      "                ",
      "                ",
      " !            !J",
      "              &J",
      "               J",
      "               J",
      "               J",
      "                ",
      "JJ           && ",
      " J          &&J&",
      "JJ           && ",
      "                "
    ],
    [
      "               X",
      "               J",
      "                ",
      "                ",
      "                ",
      "               &",
      " !            !J",
      "              &X",
      "               X",
      "               X",
      "               J",
      "                ",
      "JJ            & ",
      "JJ           &J&",
      "JJ            & ",
      "                "
    ]
  ]
}