{
  "xsize": 16,
  "zsize": 16,
  "refpalette": "pomkotsmechs:factory",
  "slices": [
    [
      " JJ      JJ   0 ",
      "              ! ",
      "    J  J &  J 0 ",
      "    J  J&&& J 0 ",
      "         &    0 ",
      " JJ      JJ   0 ",
      "         &&&  0 ",
      "          &&  0 ",
      "              0&",
      "             &0&",
      "            &&0&",
      "         !  &&0 ",
      "VVVVVVVVVV!&& 0 ",
      "VVVVVVVVVV&&  0 ",
      "VVVVVVVVVV&   ! ",
      "VVVVVVVVVV    0 "
    ],
    [
      " XX      XX   0 ",
      "XXXX    XXXX  ! ",
      "X  XX  XX& XX 0 ",
      "X  XX  XX&&XX 0 ",
      "XXXX    XXXX  0 ",
      " XX      XX   0 ",
      "         &&&  0 ",
      "          &   0 ",
      "              0 ",
      "             &0&",
      "             &0 ",
      "         !    0 ",
      "VVVVVVVVVV!   0 ",
      "         V&   0 ",
      "& &&    &V&   ! ",
      "&&&      V    0 "
    ],
    [
      " XX      XX     ",
      "XXXX    XXXX  $ ",
      "X  XX  XX& XX   ",
      "X  XX  XX&&XX   ",
      "XXXX    XXXX    ",
      " XX      XX&    ",
      "         &&&    ",
      "          &     ",
      "                ",
      "              & ",
      "                ",
      "         !      ",
      "VVVVVVVVVV!     ",
      "        &V&&    ",
      "        &V&   $ ",
      "&   &&&  V      "
    ],
    [
      " XX      X      ",
      "XXXX    XX    ! ",
      "X  XX  XX& XX   ",
      "X  XX  XX&&XX   ",
      "XXXX    XXXX    ",
      " XX      XX&    ",
      "          &     ",
      "                ",
      "                ",
      "                ",
      "                ",
      "         !&     ",
      "VVVVVVVVVV!&    ",
      "         V&&    ",
      "     &&  V&   ! ",
      "&   &&&& V      "
    ],
    [
      " XX             ",
      "XXXX&   X       ",
      "X&&XX& XX&  X   ",
      "X& XX  XX&&XX   ",
      "XXXX    XXXX    ",
      " XX      XX&    ",
      "          &     ",
      "                ",
      "                ",
      "                ",
      "                ",
      "         !&     ",
      "VVVVVVVVVV!&    ",
      "         V&     ",
      "      &&&V      ",
      "&    &&&&V      "
    ],
    [
      "                ",
      " XX&            ",
      "XXXX&   X&      ",
      "XXXX    XXXX    ",
      "&XX     &XX&    ",
      "         &&&    ",
      "          &     ",
      "                ",
      "                ",
      "                ",
      "                ",
      "         !&     ",
      "VVV      V!&    ",
      "       &&V&     ",
      "&     &&&V      ",
      "&&    &&&V      "
    ]
  ]
}