{
  "xsize": 16,
  "zsize": 16,
  "refpalette": "pomkotsmechs:factory",
  "slices": [
    [
      "                ",
      "                ",
      "   !!!!!!!!!!   ",
      "  &&&   &&      ",
      "  &&&    &&     ",
      "   &      &     ",
      "   !!!!!!!!!!   ",
      "           &&&  ",
      "            &   ",
      "                ",
      "   !!!!!!!!!!   ",
      "                ",
      "                ",
      "                ",
      "   !!!!!!!!!!   ",
      "                "
    ],
    [
      "   OVVVVVVVVO   ",
      "   OVVVVVVVVO   ",
      "   OVVVVVVVVO   ",
      "   OVVVVVVVVO   ",
      "  &OVVVVVVVVO   ",
      "   OVVVVVVVVO   ",
      "   OVVVVVVVVO&  ",
      "   OVVVVVVVVO&  ",
      "   OVVVVVVVVO   ",
      "   OVVVVVVVVO   ",
      "   OVVVVVVVVO   ",
      "   OVVVVVVVVO   ",
      "   OVVVVVVVVO   ",
      "   OVVVVVVVVO   ",
      "   OOOOOOOOOO   ",
      "                "
    ],
    [
      "   V        V   ",
      "   V        V   ",
      "   V    &&  V   ",
      "   V   &&&  V   ",
      "  &O&   &&&&O   ",
      "  &V&    &&&V   ",
      "   V      &&V&  ",
      "   V        V   ",
      "   V        V   ",
      "   V        V   ",
      "   V        V   ",
      "   V        V   ",
      "   V        V   ",
      "   V        V   ",
      "   OVVVVVVVVO   ",
      "                "
    ],
    [
      "   V        V   ",
      "   V    &&  V   ",
      "   V   &&&& V   ",
      "   V   &&& &V   ",
      "   O    & &&O   ",
      "  &V&     &&V&  ",
      "   V       &V&  ",
      "   V        V   ",
      "   V        V   ",
      "   V        V   ",
      "   V        V   ",
      "   V        V   ",
      "   V        V   ",
      "   V        V   ",
      "   OVVVVVVVVO   ",
      "                "
    ],
    [
      "   V        V   ",
      "   V     &  V   ",
      "   V    &&& V   ",
      "   V    && &V   ",
      "   O      &&O&  ",
      "  &V&      &V&  ",
      "   V        V   ",
      "   V        V   ",
      "   V        V   ",
      "   V        V   ",
      "   V        V   ",
      "   V        V   ",
      "   V        V   ",
      "   V        V   ",
      "   OVVVVVVVVO   ",
      "                "
    ],
    [
      "   V        V   ",
      "   V     && V   ",
      "   V    &&& V   ",
      "   V     &  V   ",
      "   O       &O&  ",
      "  &V&      &V&  ",
      "  &V&       V   ",
      "   V        V   ",
      "   V        V   ",
      "   V        V   ",
      "   V            ",
      "   V            ",
      "   V        V   ",
      "   V        V   ",
      "   OVVVVVVVVO   ",
      "                "
    ]
  ]
}