{
  "xsize": 16,
  "zsize": 16,
  "refpalette": "pomkotsmechs:factory",
  "slices": [
    [
      "                ",
      "                ",
      "          !     ",
      "          & XXXX",
      "         &XX    ",
      "        XX&  && ",
      "     ! X     &&&",
      "      X       &&",
      "     X         &",
      "    &X&&        ",
      "  ! X&&&&       ",
      "    X &&&&      ",
      "   X    &&&     ",
      "   X     &      ",
      "   X            ",
      "   X            "
    ],
    [
      "                ",
      "                ",
      "          !     ",
      "          & XXXX",
      "         &XX && ",
      "        XX& &&&&",
      "     ! X     &&&",
      "      X      &&&",
      "     X        &&",
      "    &X&         ",
      "  ! X&&&&&      ",
      "    X &&&&&     ",
      "   X    &&&     ",
      "   X     &      ",
      "   X            ",
      "   X            "
    ],
    [
      "                ",
      "                ",
      "          !     ",
      "          & XXXX",
      "         &XX &  ",
      "        XX& &&& ",
      "     ! X     &&&",
      "      X       &&",
      "     X          ",
      "    &X&         ",
      "  ! X&&&&       ",
      "    X &&&&      ",
      "   X    &&      ",
      "   X            ",
      "   X            ",
      "   X            "
    ],
    [
      "                ",
      "                ",
      "          !     ",
      "          & XXXX",
      "         &XX &  ",
      "        XX& &&& ",
      "     ! X     &&&",
      "      X       & ",
      "    &X&         ",
      "   &&X&&        ",
      "  ! X&&&&       ",
      "    X &&&&      ",
      "   X    &       ",
      "   X            ",
      "   X            ",
      "   X            "
    ],
    [
      "                ",
      "                ",
      "          !     ",
      "         &&&XXXX",
      "         &XX&&& ",
      "        XX& &&& ",
      "     ! X     &&&",
      "      X       & ",
      "    &X&         ",
      "   &&X&&        ",
      "  ! X&& &       ",
      "    X  &&&      ",
      "   X    &       ",
      "   X            ",
      "   X            ",
      "   X            "
    ],
    [
      "                ",
      "                ",
      "          !     ",
      "         &&&XXXX",
      "          XX&&& ",
      "        XX   && ",
      "     ! X     &&&",
      "      X       & ",
      "    &X          ",
      "   &&X&         ",
      "  ! X&  &       ",
      "    X  &&&      ",
      "   X    &       ",
      "   X            ",
      "   X            ",
      "   X            "
    ]
  ]
}