{
  "xsize": 16,
  "zsize": 16,
  "refpalette": "lostcities:factory",
  "slices": [
    [
      "            X!  ",
      "            X!  ",
      "            X!  ",
      "            X!  ",
      "           X!   ",
      "           X!!  ",
      "      &   X!    ",
      "     &&&  X!    ",
      "      &&  !     ",
      "          !     ",
      "      X         ",
      "    XX!!        ",
      "XXXX!!          ",
      "!!!!&!          ",
      "   &&           ",
      "                "
    ],
    [
      "            X!  ",
      "            X!  ",
      "            X!  ",
      "            X!  ",
      "           X!   ",
      "           X!!  ",
      "      &&   !    ",
      "     &&&& X!    ",
      "      &&& !     ",
      "       &  !     ",
      "      X         ",
      "    XX!!        ",
      "XXXX!!          ",
      "!!!!&!          ",
      "   &            ",
      "                "
    ],
    [
      "XXXXXXXXXXXXX   ",
      "XXXXXXXXXXXXX   ",
      "XXXXXXXXXXXXX   ",
      "XXXXXXXXXXXXX   ",
      "XXXXXXXXXX X    ",
      "XXXXXXXXX       ",
      "XXXXXXXX        ",
      "XXXXXXXX        ",
      "XXXXXXX&&       ",
      "XXXXXXX&        ",
      "XXXXXXX         ",
      "XXXXXX          ",
      "XXXX            ",
      " &&&&           ",
      "  &&            ",
      "                "
    ],
    [
      "XXXXXXXXXXXX    ",
      "XXXXXXXXXXXX    ",
      "XXXXXXXXXXXX    ",
      "XXXXXXXXXXX     ",
      "XXXXXXXXX       ",
      "XXXXXXXXX       ",
      "XXXXXXXX        ",
      "XXXXXXXX        ",
      "XXXXXXXX&       ",
      "XXXXXXX&        ",
      "XXXXXX&         ",
      "XXX&            ",
      " &&&            ",
      "  &&            ",
      "                ",
      "                "
    ],
    [
      "XXXXXXXXXXX     ",
      "XXXXXXXXXXX     ",
      "XXXXXXXXXXX     ",
      "XXXXXXXXXX      ",
      "XXXXX&&         ",
      "XXXX&&          ",
      "XXXX&           ",
      "XXXX&&XX        ",
      "XXXXXXX&        ",
      "XXXXXX&&        ",
      "XXX  &&         ",
      "&&&             ",
      " &&             ",
      "                ",
      "                ",
      "                "
    ],
    [
      " &&&&&&         ",
      "&& &&           ",
      "    &&          ",
      "     &          ",
      "    &&          ",
      "    &           ",
      "                ",
      "                ",
      "     &          ",
      "&    &&         ",
      "&&              ",
      " &              ",
      "                ",
      "                ",
      "                ",
      "                "
    ]
  ]
}