{
  "xsize": 16,
  "zsize": 16,
  "refpalette": "pomkotsmechs:factory",
  "slices": [
    [
      "                ",
      "&&              ",
      " &              ",
      " &&&            ",
      "                ",
      "                ",
      "      !  !      ",
      "       !!       ",
      "       !!       ",
      "      !  !      ",
      "                ",
      "                ",
      "    &           ",
      "    &           ",
      "    &           ",
      "                "
    ],
    [
      "zVvvvVz||}}||   ",
      "vvvvvVz|}}}}|   ",
      "VvvvvVz|}}}}}   ",
      "zvvvVVz|}}}}|   ",
      "zVVvVVz|}}}|v   ",
      "zVVvVVz|}}||v   ",
      "vzVVVVz||||zv   ",
      "vvzzzzzz||zvv   ",
      "vvvv|||zzzzvv   ",
      "vvvvvv|zzzzvv   ",
      "vvvv}|zzVVzzv   ",
      "vvvv}|zVVVz||   ",
      "z|||v|VVVz|||   ",
      "zzz|vzVVVz|||   ",
      "zVVzvzzzzzzzz   ",
      "VVVVVzzz||zVv   "
    ],
    [
      "&               ",
      "&&              ",
      "&&              ",
      " &&&            ",
      "                ",
      "       !!       ",
      "       !!       ",
      "                ",
      "                ",
      "                ",
      "       !!       ",
      "    && !!       ",
      "   &&&&         ",
      "    &&          ",
      "    &           ",
      "                "
    ],
    [
      "&&              ",
      "&&&             ",
      "&&              ",
      "                ",
      "                ",
      "                ",
      "ͱͱͱͱͱͱͱͱͱͱ      ",
      "ͱͱͱͱͱͱͱͱͱͱ      ",
      "ͱͱͱͱͱͱͱͱͱͱ      ",
      "ͱͱͱͱͱͱͱͱͱͱ      ",
      "ͱͱͱͱͱͱͱͱͱͱ      ",
      "     &          ",
      "    &&&         ",
      "     &          ",
      "                ",
      "                "
    ],
    [
      " &              ",
      "&&&             ",
      " &              ",
      "                ",
      "                ",
      "ͱͱͱͱͱͱͱͱͱͱ      ",
      "         ͱ      ",
      "         ͱ      ",
      "         ͱ      ",
      "         ͱ      ",
      "         ͱ      ",
      "ͱͱͱͱͱͱͱͱͱͱ      ",
      "    &&&&        ",
      "     &&         ",
      "                ",
      "                "
    ],
    [
      "ͱͱͱͱͱͱͱͱͱͱ      ",
      "&&&             ",
      " &              ",
      "                ",
      "ͱͱͱͱͱͱͱͱͱͱ      ",
      "         ͱ      ",
      "         ͱ      ",
      "         ͱ      ",
      "         ͱ      ",
      "         ͱ      ",
      "         ͱ      ",
      "      &  ͱ      ",
      "ͱͱͱͱͱͱͱͱͱͱ      ",
      "      &         ",
      "                ",
      "                "
    ]
  ]
}