{
  "xsize": 16,
  "zsize": 16,
  "refpalette": "pomkotsmechs:factory",
  "slices": [
    [
      "                ",
      "                ",
      "                ",
      "                ",
      "                ",
      "                ",
      "      !  !      ",
      "       !!       ",
      "       !!       ",
      "      !  !      ",
      "                ",
      "                ",
      "                ",
      "                ",
      "                ",
      "                "
    ],
    [
      "vVvVVzzzVVzzz   ",
      "zVVVVzzzVVVVV   ",
      "||zVVVzVVVVVV   ",
      "}|zVVVVVVvvVz   ",
      "}}zVvvVVvvvVz   ",
      "}|zVvvVVVVVzv   ",
      "}|zVvvVVVzz|v   ",
      "|zVVvVz|||||v   ",
      "zzVVVV||}}}|v   ",
      "VVVVVz||}}||v   ",
      "VVVVVzz||||zv   ",
      "vVVzzzzzzzVVv   ",
      "vVz||||zzVVVv   ",
      "vV|}}}||zVVVv   ",
      "Vz|}}}||zzzzv   ",
      "Vz|}}||zzz||v   "
    ],
    [
      " 555            ",
      "      !!        ",
      "      !!        ",
      "                ",
      "                ",
      "                ",
      "                ",
      "                ",
      "                ",
      "                ",
      "                ",
      "                ",
      "      !!        ",
      "      !!        ",
      "                ",
      "                "
    ],
    [
      " 555            ",
      "                ",
      "                ",
      "                ",
      "                ",
      "                ",
      "                ",
      "                ",
      "                ",
      "                ",
      "                ",
      "                ",
      "                ",
      "                ",
      "                ",
      "                "
    ],
    [
      " 555            ",
      "                ",
      "                ",
      "                ",
      "                ",
      "                ",
      "                ",
      "                ",
      "                ",
      "                ",
      "                ",
      "                ",
      "                ",
      "                ",
      "                ",
      "                "
    ],
    [
      " 555            ",
      "                ",
      "                ",
      "                ",
      "                ",
      "                ",
      "                ",
      "                ",
      "                ",
      "                ",
      "                ",
      "                ",
      "                ",
      "                ",
      "                ",
      "                "
    ]
  ]
}