{
  "xsize": 16,
  "zsize": 16,
  "refpalette": "lostcities:factory_common",
  "slices": [
    [
      "                ",
      "                ",
      "                ",
      "                ",
      "                ",
      "                ",
      "                ",
      "      1         ",
      "                ",
      "                ",
      "                ",
      "                ",
      "                ",
      "                ",
      "                ",
      "                "
    ],
    [
      "                ",
      "                ",
      "                ",
      "   ##########   ",
      "   #%       #   ",
      "   # #  % # #   ",
      "   # #ffff# #   ",
      "     #QQQQ# :   ",
      "     #QQQQ# :   ",
      "   # #ffff# #   ",
      "   # # %  # #   ",
      "   #       %#   ",
      "   ##########   ",
      "                ",
      "                ",
      "                "
    ],
    [
      "                ",
      "                ",
      "                ",
      "   ##########   ",
      "   #        #   ",
      "   # #    # #   ",
      "   # #*  c# #   ",
      "     #QQQQ# :   ",
      "     #QQQQ# :   ",
      "   # # !! # #   ",
      "   # #    # #   ",
      "   #        #   ",
      "   ##########   ",
      "                ",
      "                ",
      "                "
    ],
    [
      "                ",
      "                ",
      "                ",
      "   ##########   ",
      "   #        #   ",
      "   # #    # #   ",
      "   # #ffff# #   ",
      "   # #QQQQ# #   ",
      "   # #QQQQ# #   ",
      "   # #ffff# #   ",
      "   # #    # #   ",
      "   #        #   ",
      "   ##########   ",
      "                ",
      "                ",
      "                "
    ],
    [
      "                ",
      "                ",
      "                ",
      "   ##########   ",
      "   #        #   ",
      "   # #    # #   ",
      "   # # MM # #   ",
      "   # #QQQQ# #   ",
      "   # #QQQQ# #   ",
      "   # #e*  # #   ",
      "   # #    # #   ",
      "   #        #   ",
      "   ##########   ",
      "                ",
      "                ",
      "                "
    ]
  ]
}
