{
  "xsize": 16,
  "zsize": 16,
  "refpalette": "pomkotsmechs:factory",
  "slices": [
    [
      "    VVVVVVVV    ",
      "    VVVVVVVV    ",
      "    VVVVVVVV   J",
      "    VVVVVVVV&& J",
      "    VVVVVVVV&&& ",
      "    VVVVVVVV&&  ",
      "    VVVVVVVV    ",
      "    VVVVVVVV    ",
      "    VJJJJJJV    ",
      "   JJ     &JJ   ",
      "  J      &&& J  ",
      " J        &   J ",
      "VJ           &JV",
      "J             &J",
      "J              J",
      "J              J"
    ],
    [
      "    V      V    ",
      "    V      V    ",
      "    V      V   X",
      "    V      V &&X",
      "    V     &V&&& ",
      "    V      V &  ",
      "    V      V    ",
      "    V      V    ",
      "    VJJJJJJV    ",
      "   JJ     &JJ   ",
      "  J      &&& J  ",
      " J        &   J ",
      "VJ           &JV",
      "J             &J",
      "J              J",
      "J             &J"
    ],
    [
      "    V      V    ",
      "    V      V    ",
      "    V      V  &X",
      "    V      V &&X",
      "    V     &V&&&&",
      "    V      V && ",
      "    V      V    ",
      "    V      V    ",
      "    VJJJJJJV    ",
      "   JJ     &JJ   ",
      "  J      &&& J  ",
      " J        &   J ",
      "VJ           &JV",
      "J             &J",
      "J              J",
      "J             &J"
    ],
    [
      "    V      V    ",
      "    V      V    ",
      "    V      V  &X",
      "    V      V &&X",
      "    V     &V&&&&",
      "    V      V    ",
      "    V      V    ",
      "    V &    V    ",
      "    VJJJJJJV    ",
      "   JJ &   &JJ   ",
      "  J      &&& J  ",
      " J        &   J ",
      "VJ           &JV",
      "J             &J",
      "J              J",
      "J             &J"
    ],
    [
      "    V      V    ",
      "    V      V    ",
      "    V      V   X",
      "    V      V& &X",
      "    V     &V&  &",
      "    V      V    ",
      "    V      V    ",
      "    V &&   V    ",
      "    VJJJJJJV    ",
      "   JJ && &&JJ   ",
      "  J      &&& J  ",
      " J        &   J ",
      "VJ           &JV",
      "J             &J",
      "J              J",
      "J             &J"
    ],
    [
      "    V      V    ",
      "    V      V    ",
      "    V      V&  &",
      "    V     &V&&&&",
      "    V     &V&  &",
      "    V      V    ",
      "    V  &   V    ",
      "    V &&&  V    ",
      "    VJJJJJJV    ",
      "   JJ  & &&JJ   ",
      "  J       &  J  ",
      " J            J ",
      "VJ           &JV",
      "J             &J",
      "J              J",
      "J             &J"
    ]
  ]
}