{
  "xsize": 16,
  "zsize": 16,
  "refpalette": "lostcities:factory",
  "slices": [
    [
      "     5       5  ",
      " !!   5   & 5   ",
      "!!!    55555    ",
      "!!!     555     ",
      "!!!             ",
      "!!!            +",
      "!!!            2",
      "!!!             ",
      " !!      5      ",
      " !!             ",
      "!!!             ",
      "!!!            +",
      "!!!            2",
      "!!!       JJJ   ",
      "!!! OOOOO JJJ   ",
      "!!! OOOOO JJJ   "
    ],
    [
      "     5       5  ",
      "  !   5   & 5   ",
      " !!    555555555",
      "!!!     555     ",
      "!!!      5      ",
      "!!!      5     +",
      "!!!      5     2",
      "!!!      5      ",
      " !!      5      ",
      " !!             ",
      "!!!             ",
      "!!!            +",
      "!!!            2",
      "!!!             ",
      "!!! $   $       ",
      "!!!             "
    ],
    [
      "     5       5  ",
      "      5   & 5   ",
      "       55555    ",
      " ]      555     ",
      " ]!             ",
      "!!!            +",
      "!!!            2",
      "!!!             ",
      " !              ",
      " !              ",
      "!!!             ",
      "!!!            +",
      "!!!            2",
      "&]!             ",
      "&]  OOOOO       ",
      " ]  OOOOO       "
    ],
    [
      "     5       5  ",
      "      5   & 5   ",
      "       55555    ",
      "          &     ",
      "  !             ",
      "!!!            V",
      "!!!            V",
      "!!!             ",
      "                ",
      "                ",
      "!!!             ",
      "!!!            V",
      "!!!            V",
      "&&!             ",
      "&   OVVVO       ",
      "    V   V       "
    ],
    [
      "     5       5 V",
      "      5   & 5  V",
      "       55555   V",
      "  V       &    V",
      "  !           VV",
      "!!VVVVVVVVVVVVVn",
      "!!!VVVVVVVVVVVVn",
      "!!!           VV",
      "  V             ",
      "  V             ",
      "!!!           VV",
      "!!!VVVVVVVVVVVVn",
      "!!VVVVVVVVVVVVVn",
      "&&!&&         VV",
      "&&V OVVVO      V",
      "  V V   V      V"
    ],
    [
      "     5       5r!",
      "    rr5   & 5rr!",
      "    rrr55555rrr!",
      " !!!rrrrrrrrrrr!",
      "!!!!!!!!!!!!!!!!",
      "!!!!!!!!!!!!!!!!",
      "!!!!!!!!!!!!!!!!",
      "!!!!!!!!!!!!!!!!",
      "!!!rrrrrrrrrrrrr",
      "!!!rrrrrrrrrrrrr",
      "!!!!!!!!!!!!!!!!",
      "!!!!!!!!!!!!!!!!",
      "!!!!!!!!!!!!!!!!",
      "!!!!!!!!!!!!!!!!",
      "!!!!OVVVO!rrrrr!",
      "!!!!VOOOV!rrrrr!"
    ]
  ]
}