{
  "xsize": 16,
  "zsize": 16,
  "refpalette": "pomkotsmechs:factory",
  "slices": [
    [
      "                ",
      "                ",
      "                ",
      "                ",
      "                ",
      "                ",
      "      !  !      ",
      "       !!       ",
      "       !!       ",
      "      !  !      ",
      "                ",
      "               &",
      "               &",
      "                ",
      "                ",
      "                "
    ],
    [
      "     v||zzVVVz|}",
      "     v||zVvvVz}}",
      "     vv|zVvvVz}}",
      "     vv|zVvvVz|}",
      "     vv}|zVVVVz|",
      "     vv}}|zVVzzz",
      "     vv}}}||zzzz",
      "     vv|||||||zz",
      "     vvzzz||||zz",
      "     vvVVz||||zV",
      "     vvVzz||||zz",
      "     vz|||||||zv",
      "     v||}}}}|||v",
      "     v|||}|||||}",
      "     Vzz|||||||}",
      "     VVVVzzzzz||"
    ],
    [
      "                ",
      "                ",
      "                ",
      "               5",
      "              5 ",
      "              5 ",
      "              5 ",
      "               5",
      "                ",
      "                ",
      "        !!      ",
      "        !!     &",
      "               &",
      "                ",
      "                ",
      "                "
    ],
    [
      "                ",
      "                ",
      "                ",
      "               5",
      "              5 ",
      "              5 ",
      "              5 ",
      "               5",
      "                ",
      "               &",
      "                ",
      "                ",
      "                ",
      "                ",
      "                ",
      "                "
    ],
    [
      "                ",
      "                ",
      "                ",
      "               5",
      "              5 ",
      "              5 ",
      "              5 ",
      "               5",
      "                ",
      "               &",
      "                ",
      "                ",
      "                ",
      "                ",
      "                ",
      "                "
    ],
    [
      "                ",
      "                ",
      "               5",
      "              55",
      "             55 ",
      "             55 ",
      "             55 ",
      "              55",
      "               5",
      "               &",
      "                ",
      "                ",
      "                ",
      "                ",
      "                ",
      "                "
    ]
  ]
}