{
  "refpalette": "lcmt:factory_common",
  "xsize": 16,
  "zsize": 16,
  "slices": [
    [
      "                ",
      "                ",
      "                ",
      "                ",
      "                ",
      "                ",
      "                ",
      "                ",
      "                ",
      "                ",
      "                ",
      "                ",
      "                ",
      "                ",
      "                ",
      "                "
    ],
    [
      "                ",
      "                ",
      "  #::::  ::::#  ",
      "  :          :  ",
      "  : NN    NN :  ",
      "  : NN    NN :  ",
      "  : NN    NN :  ",
      "  : NN    NN :  ",
      "  : kk    kk :  ",
      "  : NN    NN :  ",
      "  : NN    NN :  ",
      "  : NN    NN :  ",
      "  :          :  ",
      "  #::::  ::::#  ",
      "                ",
      "                "
    ],
    [
      "                ",
      "                ",
      "  #::::  ::::#  ",
      "  :          :  ",
      "  : ++    ++ :  ",
      "  : ++    ++ :  ",
      "  : ++    ++ :  ",
      "  : ++    ++ :  ",
      "  :          :  ",
      "  : ++    ++ :  ",
      "  : ++    ++ :  ",
      "  : ++    ++ :  ",
      "  :          :  ",
      "  #::::  ::::#  ",
      "                ",
      "                "
    ],
    [
      "                ",
      "                ",
      "  #::::::::::#  ",
      "  :          :  ",
      "  : 22    22 :  ",
      "  : 22    22 :  ",
      "  : 22    22 :  ",
      "  : 22    22 :  ",
      "  :          :  ",
      "  : 22    22 :  ",
      "  : 22    22 :  ",
      "  : 22    22 :  ",
      "  :          :  ",
      "  #::::::::::#  ",
      "                ",
      "                "
    ],
    [
      "                ",
      "                ",
      "  #::::::::::#  ",
      "  :          :  ",
      "  :          :  ",
      "  :          :  ",
      "  :          :  ",
      "  :          :  ",
      "  :          :  ",
      "  :          :  ",
      "  :          :  ",
      "  :          :  ",
      "  :          :  ",
      "  #::::::::::#  ",
      "                ",
      "                "
    ]
  ]
}
