{
  "xsize": 16,
  "zsize": 16,
  "refpalette": "pomkotsmechs:factory",
  "slices": [
    [
      "vvvvvvvvvvvvvvvv",
      "vvvvvvvvvvvvvvvv",
      "vvvvvvvvvvvvvvvv",
      "JJJJJJJJJJJJvvvv",
      "JJJJJJJJJJJJvvvv",
      "JJJJJJJJJJJJvvvv",
      "JJJJJJJJJJJJvvvv",
      "JJJJJJJJJJJJvvvv",
      "JJJJJJJJJJJJvvvv",
      "JJJJJJJJJJJJvvvv",
      "JJJJJJJJJJJJvvvv",
      "JJJJJJJJJJJJvvvv",
      "JJJJJJJJJJJJvvvv",
      "JJJJJJJJJJJJvvvv",
      "JJJJJJJJJJJJvvvv",
      "JJJJJJJJJJJJvvvv"
    ],
    [
      "!!!!       !!!!!",
      "!!!!   !   !!!!!",
      "!!!!!!!!!!!!!!!!",
      "!!!!       !!!!!",
      "!!!!       !!!!!",
      "             !  ",
      "  JJJJJJ     !  ",
      "  J!JJ!J     !  ",
      "  JJrrJJ     !! ",
      "  JJrrJJ     !  ",
      "  J!JJ!J     !  ",
      "  JJJJJJ     !  ",
      "           !!!!!",
      "           !!!!!",
      "&          !!!!!",
      "!          !!!!!"
    ],
    [
      " !           !  ",
      "!!!    !    !!! ",
      "!!!!JJJJJJJ!!!!!",
      "!!!         !!! ",
      " !           !  ",
      "             J  ",
      "             J  ",
      "   !JJ!      J  ",
      "   JrrJ      J! ",
      "   JrrJ      J  ",
      "   !JJ!      J  ",
      "             J  ",
      "             !  ",
      "            !!! ",
      "           !!!!!",
      "!           !!! "
    ],
    [
      " !           !  ",
      "!!!  & !    !!! ",
      "!!!!JJJJJJJ!!!!!",
      "!!!  &      !!! ",
      " !           !  ",
      "             J  ",
      "             J  ",
      "   !  !      J  ",
      "    rr       J! ",
      "    rr       J  ",
      "   !  !      J  ",
      "             J  ",
      "             !  ",
      "            !!! ",
      "           !!!!!",
      "!           !!! "
    ],
    [
      " !           !  ",
      "!!!  & !  & !!! ",
      "!!!!!!!!!!!!!!!!",
      "!!!  &    & !!! ",
      " !           !  ",
      "             !  ",
      "             !  ",
      "   !  !      !  ",
      "    rr       !! ",
      "    rr       !  ",
      "   !  !      !  ",
      "             !  ",
      "             !  ",
      "            !!! ",
      "           !!!!!",
      "!           !!! "
    ],
    [
      " !           !  ",
      "!!!  & !  & !!! ",
      "!!!!JJJJJJJ!!!!!",
      "!!!  &    & !!! ",
      " !           !  ",
      "             J  ",
      "             J  ",
      "   !  !      J  ",
      "    rr       J! ",
      "    rr       J  ",
      "   !  !      J  ",
      "             J  ",
      "             !  ",
      "            !!! ",
      "           !!!!!",
      "!           !!! "
    ]
  ]
}