{
  "xsize": 16,
  "zsize": 16,
  "refpalette": "lostcities:factory",
  "slices": [
    [
      "              & ",
      "              &&",
      "                ",
      "                ",
      "                ",
      "                ",
      "      !  !      ",
      "       !!       ",
      "       !!       ",
      "      !  !      ",
      "                ",
      "                ",
      "                ",
      "                ",
      "                ",
      "                "
    ],
    [
      "     vvVVVVVVVvz",
      "     vvVVVVVVVvv",
      "     VVVVVVVVVzV",
      "     zVVVVVVzzzz",
      "     vzVVVVz||||",
      "     vzVVVz|}}}|",
      "     zzVVVz|}}}|",
      "     zVVVVz|}}||",
      "     VVVVzz|}||z",
      "     Vzzzzz||||z",
      "     zz||zzz|||z",
      "     ||||zzzz||z",
      "     }}||zVVz||z",
      "     }}|zzVzz||z",
      "     }}|zzzz||zz",
      "     }}||z|||zzV"
    ],
    [
      "              &&",
      "              &&",
      "             !!!",
      "             !!!",
      "             !!!",
      "                ",
      "                ",
      "         !!     ",
      "         !!     ",
      "                ",
      "                ",
      "                ",
      "                ",
      "                ",
      "                ",
      "                "
    ],
    [
      "                ",
      "              &&",
      "             &&&",
      "              ! ",
      "                ",
      "                ",
      "                ",
      "                ",
      "                ",
      "                ",
      "                ",
      "                ",
      "                ",
      "                ",
      "                ",
      "                "
    ],
    [
      "                ",
      "              & ",
      "             &&&",
      "             &!&",
      "             && ",
      "                ",
      "                ",
      "                ",
      "                ",
      "                ",
      "                ",
      "                ",
      "                ",
      "                ",
      "                ",
      "                "
    ],
    [
      "               5",
      "               5",
      "             &&5",
      "            &&!5",
      "            &&&!",
      "             & 5",
      "               5",
      "               5",
      "               5",
      "               5",
      "               5",
      "               5",
      "               5",
      "               5",
      "               5",
      "               5"
    ]
  ]
}