{
  "xsize": 16,
  "zsize": 16,
  "refpalette": "pomkotsmechs:factory",
  "slices": [
    [
      "                ",
      "                ",
      "                ",
      "                ",
      "                ",
      "                ",
      "                ",
      "                ",
      "55             &",
      "  555        555",
      "     55555555  &",
      "                ",
      "                ",
      "                ",
      "                ",
      "                "
    ],
    [
      "                ",
      "                ",
      "                ",
      "                ",
      "                ",
      "                ",
      "                ",
      "                ",
      "55             &",
      "  555        555",
      "     55555555  &",
      "                ",
      "                ",
      "                ",
      "                ",
      "                "
    ],
    [
      "                ",
      "                ",
      "                ",
      "                ",
      "                ",
      "                ",
      "               &",
      "               &",
      "55             &",
      "  555        555",
      "     55555555  &",
      "                ",
      "                ",
      "                ",
      "                ",
      "                "
    ],
    [
      "!!!!!!!!!!!!!!!!",
      "!!!!!!!!!!!!!!!!",
      "!!!!!!!!!!!!!!!!",
      "!!!!!!!!!!!!!!!!",
      "!!!!!!!!!!!!!!!!",
      "!!!!!!!!!!!!!!!!",
      "!!!!!!!!!!!!!!!!",
      "!!!!!!!!!!!!!!!!",
      "!!!!!!!!!!!!!!!!",
      "  !!!!!!!!!!!!!!",
      "     !!!!!!!!  &",
      "                ",
      "                ",
      "                ",
      "                ",
      "                "
    ],
    [
      "!!!!!!!!!!!!!!!!",
      "!!!!!!!!!!!!!!!!",
      " !!!!!!!!!!!!!!!",
      " !!!!!!!!!!!!!!!",
      "!!!!!!!!!!!!!!!!",
      "!!!!!!!!!!!!!!!!",
      " !!!!!!!!!!!!!!!",
      "   !!!!!!!!!!!!&",
      "     55!!!!55  &",
      "      !    !   &",
      "                ",
      "                ",
      "                ",
      "                ",
      "                ",
      "                "
    ],
    [
      "  !!!!!!!!!!!!!!",
      "  !!!!!!!!!!!!!!",
      "  !!!!!!!!!!!!!!",
      " !!!!!!!!!!!!!!!",
      "  !!!!!!!!!!!!!!",
      "    !!!!!!!!!! &",
      "     55    55  &",
      "     55    55   ",
      "                ",
      "      !    !    ",
      "                ",
      "                ",
      "                ",
      "                ",
      "                ",
      "                "
    ]
  ]
}