{
  "xsize": 16,
  "zsize": 16,
  "refpalette": "pomkotsmechs:factory",
  "slices": [
    [
      "JJJJJJJJJJJJvvvv",
      "JJJJJJJJJJJJvvvv",
      "JJJJJJJJJJJJvvvv",
      "JJJJJJJJJJJJvvvv",
      "JJJJJJJJJJJJvvvv",
      "JJJJJJJJJJJJvvvv",
      "JJJJJJJJJJJJvvvv",
      "JJJJJJJJJJJJvvvv",
      "JJJJJJJJJJJJvvvv",
      "JJJJJJJJJJJJvvvv",
      "JJJJJJJJJJJJvvvv",
      "JJJJJJJJJJJJvvvv",
      "vvvvvvvvvvvvvvvv",
      "vvvvvvvvvvvvvvvv",
      "vvvvvvvvvvvvvvvv",
      "vvvvvvvvvvvvvvvv"
    ],
    [
      "!          !!!!!",
      "           !!!!!",
      "  JJJJJJ   !!!!!",
      "  J!JJ!J   !!!!!",
      "  JJrrJJ     !  ",
      "  JJrrJJ     !  ",
      "  J!JJ!J     !  ",
      "  JJJJJJ     !! ",
      "             !  ",
      "     &       !  ",
      "    &&&      !  ",
      "!!!!&&&    !!!!!",
      "!!!!&&&    !!!!!",
      "!!!!!!!!!!!!!!!!",
      "!!!! &&!   !!!!!",
      "!!!!  &    !!!!!"
    ],
    [
      "!           !!! ",
      "           !!!!!",
      "            !!! ",
      "   !JJ!      !  ",
      "   JrrJ      J  ",
      "   JrrJ      J  ",
      "   !JJ!      J  ",
      "             J! ",
      "             J  ",
      "     &       J  ",
      "    &&&      J  ",
      " !  &&&      !  ",
      "!!! &&&     !!! ",
      "!!!!JJJJJJJ!!!!!",
      "!!!   &!    !!! ",
      " !           !  "
    ],
    [
      "!           !!! ",
      "           !!!!!",
      "            !!! ",
      "   !  !      !  ",
      "    rr      &J& ",
      "    rr       J  ",
      "   !  !      J  ",
      "             J! ",
      "             J  ",
      "             J  ",
      "     &       J  ",
      " !  &&&      !  ",
      "!!! &&&     !!! ",
      "!!!!JJJJJJJ!!!!!",
      "!!!   &!    !!! ",
      " !           !  "
    ],
    [
      "!           !!! ",
      "           !!!!!",
      "            !!! ",
      "   !  !      !  ",
      "    rr      &!& ",
      "    rr       !  ",
      "   !  !      !  ",
      "             !! ",
      "             !  ",
      "             !  ",
      "     &       !  ",
      " !  &&&      !  ",
      "!!! &&&     !!! ",
      "!!!!!!!!!!!!!!!!",
      "!!!  &&!    !!! ",
      " !           !  "
    ],
    [
      "!           !!! ",
      "           !!!!!",
      "            !!! ",
      "   !  !      !  ",
      "    rr      &J& ",
      "    rr       J  ",
      "   !  !      J  ",
      "             J! ",
      "             J  ",
      "             J  ",
      "     &       J  ",
      " !  &&&      !  ",
      "!!! &&&     !!! ",
      "!!!!JJJJJJJ!!!!!",
      "!!!  &      !!! ",
      " !           !  "
    ]
  ]
}