{
  "xsize": 16,
  "zsize": 16,
  "refpalette": "lostcities:factory",
  "slices": [
    [
      "tttttttttttttttt",
      "t      P5P     t",
      "t     VVVV &   t",
      "t   VV    VV&  t",
      "t  V       &V  t",
      "t  V     &  V  t",
      "tPV     &&&&    ",
      "t5V     &&&&&   ",
      "tPV     &&&& V  ",
      "t&V&    &&   V  ",
      "t &V    &   V  t",
      "t  V   &&&  V  t",
      "t   VV&&&&VV   t",
      "t     VVVV     t",
      "t     P5P      t",
      "tttttttttttttttt"
    ],
    [
      "t              t",
      "       P5P      ",
      "      VVVV &    ",
      "   &VV    VV&   ",
      "  &V&    &&&V   ",
      "   V    &&& V   ",
      " PV     &&&&&   ",
      " 5V      &&&&&  ",
      " PV      & &&V  ",
      " &V&    &    V  ",
      "  &V   &&&  V   ",
      "   V   &&&  V   ",
      "    VV && VV    ",
      "      VVVV      ",
      "      P5P       ",
      "t              t"
    ],
    [
      "t              t",
      "       P5P      ",
      "    & VVVV &    ",
      "   &VV    VV&   ",
      "  &V&&   &&&V   ",
      "   V&   &&&&V   ",
      " PV      && &V  ",
      " 5V        &&V& ",
      " PV     &&  &V  ",
      " &V&   &&&   V  ",
      "  &V   &&&  V   ",
      "        &   V   ",
      "    VV    VV    ",
      "      VVVV      ",
      "      P5P       ",
      "t              t"
    ],
    [
      "t              t",
      "       P5P      ",
      "    & VVVV&&    ",
      "   &VV   &VV&   ",
      "   V&    &&&V   ",
      "   V     && V   ",
      " PV          V  ",
      " 5V      &  &V& ",
      " PV     &&& &V& ",
      " &V&   &&&&  V  ",
      "  &     &&  V   ",
      "            V   ",
      "    VV    VV    ",
      "      VVVV      ",
      "      P5P       ",
      "t              t"
    ],
    [
      "t              t",
      "    &  P5P      ",
      "   &&&VVVV      ",
      "   &VV    &&    ",
      "   V&     &     ",
      "   V        V   ",
      " PV      &&  V  ",
      " 5V     &&&  V  ",
      " PV     &&& &V& ",
      "&&&&    &&   VP ",
      " &&         V   ",
      "            V   ",
      "     V    VV    ",
      "      VVVV      ",
      "      P5P       ",
      "t              t"
    ],
    [
      "t              t",
      "    &!!!!!!     ",
      "   &!!VVVV      ",
      "   !VV          ",
      "  !V         !  ",
      " !!V     && V!! ",
      " !V     &&&& V! ",
      " !V     &&&  V! ",
      " !V      &  &V!&",
      "&!&          V! ",
      " &          V!! ",
      "            V!  ",
      "    VV    VV!   ",
      "    !!VVVV!!    ",
      "     !!!!!!     ",
      "t              t"
    ]
  ]
}