{
  "xsize": 16,
  "zsize": 16,
  "refpalette": "pomkotsmechs:factory",
  "slices": [
    [
      "!!!!!!!!!!!!!!!!",
      "!!!!!!!!!!!!!!!!",
      "!!!!!!!  !!!!!!!",
      "!!!!!!    !!!!!!",
      "!!!!!    &!!!!!!",
      "!!!!!    &&!!!!!",
      "!!!!!     &!!!!!",
      "!!!!!!  !! !!!!!",
      "!  !!! !!! !!!!!",
      "     !!!!! !!!!!",
      "     !!!!!8!!!!!",
      "     !!!!!!!!!!!",
      "!!!!!!!!!!!!!!!!",
      "!!!!!!!!!!!!!!!!",
      "!!!!!!!!!!!!!!!!",
      "!!!!!!!!!!!!!!!!"
    ],
    [
      ">?@          $$$",
      "A!A         &$!$",
      "EHI !!!  !!!&$$$",
      "   !!     &!!   ",
      "  !!      &&!!  ",
      "&&!      &&& !&&",
      "  !       & &!&&",
      "  !!!    !   !& ",
      "     !   !   !  ",
      "     ! !&!&  !  ",
      "     !  &&&  !  ",
      "     !   &&&!!  ",
      " !   !   &&!J   ",
      ">?@ !!   &!J&$$$",
      "A!A J!!!!!J&&$!$",
      "E?I    &&  & $$$"
    ],
    [
      " $            $ ",
      "$!$        &&$!$",
      " M  55555555&&$ ",
      "   55    &&55   ",
      "  55     &&&55  ",
      "  5     &&&& 5  ",
      "  5      && &5& ",
      "  555    /   5  ",
      "         0   5  ",
      "        ,3&  5  ",
      "         &   5  ",
      "     5    & 55  ",
      "     5   &&55   ",
      " $  55  &&5&& $ ",
      "$!$  55555&& $!$",
      " $            $ "
    ],
    [
      "                ",
      " !         &  ! ",
      "    55555555&   ",
      "   55    &&55   ",
      "  55     && 55  ",
      "        &&&  5  ",
      "         &5 &5& ",
      "  555    /6  5  ",
      "         &   5  ",
      "        &7&  5  ",
      "        &&&  5  ",
      "         &  55  ",
      "         &&55   ",
      "     5  &&55&   ",
      " !   55555&&  ! ",
      "          &     "
    ],
    [
      "                ",
      " !        &&  ! ",
      "    55555555&   ",
      "   55    &&55   ",
      "  55    &&& 55  ",
      "  5     &&&  5  ",
      "  5      &  &5& ",
      "  555    /8  5  ",
      "          6  5  ",
      "         3   5  ",
      "        &&&  5  ",
      "         &  55  ",
      "         & 55   ",
      "        &&55    ",
      " !   55555&&  ! ",
      "         &&     "
    ],
    [
      " $            $ ",
      "$!$       && $!$",
      " N  !!!!!!!!& $ ",
      "   !!    &&!!   ",
      "  !!    &&& !!  ",
      "  !      &   !  ",
      "  !         &!& ",
      "  !!!    /   !  ",
      "         08  !  ",
      "         36  !  ",
      "        &&&  !  ",
      "        &&& !!  ",
      "         & !J   ",
      " $       &!J  $ ",
      "$!$    !!!J& $!$",
      " $       &&   $ "
    ]
  ]
}