{
  "xsize": 16,
  "zsize": 16,
  "refpalette": "lostcities:factory",
  "slices": [
    [
      "                ",
      "                ",
      "                ",
      "/              +",
      "3              2",
      "                ",
      "                ",
      "                ",
      "                ",
      "/              +",
      "3              2",
      "                ",
      "                ",
      "                ",
      "                ",
      "                "
    ],
    [
      "                ",
      "                ",
      "                ",
      "/              +",
      "3              2",
      "                ",
      "                ",
      "                ",
      "                ",
      "/              +",
      "3              2",
      "                ",
      "                ",
      "                ",
      "                ",
      "                "
    ],
    [
      "                ",
      "                ",
      "                ",
      "/              +",
      "3              2",
      "                ",
      "                ",
      "                ",
      "                ",
      "/              +",
      "3              2",
      "                ",
      "                ",
      "                ",
      "                ",
      "                "
    ],
    [
      "                ",
      "                ",
      "                ",
      "V              V",
      "V              V",
      "                ",
      "                ",
      "                ",
      "                ",
      "V              V",
      "V              V",
      "                ",
      "                ",
      "                ",
      "                ",
      "                "
    ],
    [
      "V              V",
      "V              V",
      "VV            VV",
      "nV            Vn",
      "nV            Vn",
      "VV            VV",
      "                ",
      "                ",
      "VV            VV",
      "nV            Vn",
      "nV            Vn",
      "VV            VV",
      "V              V",
      "V              V",
      "V              V",
      "V              V"
    ],
    [
      "rrrrrrrrrrrrrrrr",
      "rrrrrrrrrrrrrrrr",
      "!!!!!!!!!!!!!!!!",
      "!!!!!!!!!!!!!!!!",
      "!!!!!!!!!!!!!!!!",
      "!!!!!!!!!!!!!!!!",
      "rrrrrrrrrrrrrrrr",
      "rrrrrrrrrrrrrrrr",
      "!!!!!!!!!!!!!!!!",
      "!!!!!!!!!!!!!!!!",
      "!!!!!!!!!!!!!!!!",
      "!!!!!!!!!!!!!!!!",
      "!!rrrrrrrrrrrr!!",
      "!!rrrrrrrrrrrr!!",
      "!!rrrrrrrrrrrr!!",
      "!!rrrrrrrrrrrr!!"
    ]
  ]
}