{
  "xsize": 16,
  "zsize": 16,
  "refpalette": "lostcities:factory",
  "slices": [
    [
      "                ",
      "                ",
      "                ",
      "                ",
      "                ",
      "                ",
      "                ",
      "                ",
      "                ",
      "                ",
      "/              +",
      "3              2",
      "                ",
      "                ",
      "!!!!!!!!!!!!!!!!",
      "!!!!!!!!!!!!!!!!"
    ],
    [
      "                ",
      "                ",
      "                ",
      "                ",
      "                ",
      "                ",
      "                ",
      "                ",
      "                ",
      "                ",
      "/              +",
      "3              2",
      "                ",
      "                ",
      "!!!!!!!!!!!!!!!!",
      "!!!!!!!!!!!!!!!!"
    ],
    [
      "                ",
      "                ",
      "                ",
      "                ",
      "                ",
      "                ",
      "                ",
      "                ",
      "                ",
      "                ",
      "/              +",
      "3              2",
      "                ",
      "                ",
      "!!ddddddddddddd!",
      "!!             !"
    ],
    [
      "                ",
      "                ",
      "                ",
      "                ",
      "                ",
      "                ",
      "                ",
      "                ",
      "                ",
      "                ",
      "V              V",
      "V              V",
      "                ",
      "                ",
      "!!             !",
      "!!             !"
    ],
    [
      "V              V",
      "V              V",
      "V              V",
      "V              V",
      "V              V",
      "V              V",
      "V              V",
      "V              V",
      "V              V",
      "VV            VV",
      "nV&           Vn",
      "nV            Vn",
      "VV            VV",
      "                ",
      "!!             !",
      "!!             !"
    ],
    [
      "!!rrrrrrrrrrrr!!",
      "!!rrrrrrrrrrrr!!",
      "!!rrrrrrrrrrrr!!",
      "!!rrrrrrrrrrrr!!",
      "!!rrrrrrrrrrrr!!",
      "!!rrrrrrrrrrrr!!",
      "!!rrrrrrrrrrrr!!",
      "!!rrrrrrrrrrrr!!",
      "!!rrrrrrrrrrrr!!",
      "!!!!!!!!!!!!!!!!",
      "!!!!!!!!!!!!!!!!",
      "!!!!!!!!!!!!!!!!",
      "!!!!    !!!!!!!!",
      "rrr      rrrrrrr",
      "!!!      !!!!!!!",
      "!!!      !!!!!!!"
    ]
  ]
}