{
  "xsize": 16,
  "zsize": 16,
  "refpalette": "pomkotsmechs:factory",
  "slices": [
    [
      "  &&&     &     ",
      "   & !!! &!&    ",
      "          &     ",
      "                ",
      "     !    !     ",
      "     !    !     ",
      "     !!!  !     ",
      "                ",
      "                ",
      "                ",
      "                ",
      "                ",
      "                ",
      "                ",
      "                ",
      "                "
    ],
    [
      "  &&      &     ",
      "     ! !!&!&    ",
      "          &     ",
      "     !    !     ",
      "     !    !     ",
      "                ",
      "     ! !! !     ",
      "                ",
      "                ",
      "                ",
      "                ",
      "                ",
      "                ",
      "                ",
      "                ",
      "                "
    ],
    [
      " &&&&     &     ",
      "    &!  !!!&    ",
      "     !    !     ",
      "     !    !     ",
      "                ",
      "                ",
      "     !  !!!     ",
      "                ",
      "                ",
      "                ",
      "                ",
      "                ",
      "                ",
      "                ",
      "                ",
      "                "
    ],
    [
      "X&&&X&    &     ",
      "   &&!&  !!&    ",
      "    &!   &!&    ",
      "          &     ",
      "                ",
      "                ",
      "     !   !!     ",
      "                ",
      "                ",
      "                ",
      "                ",
      "                ",
      "                ",
      "                ",
      "                ",
      "                "
    ],
    [
      "  &&&&          ",
      "   &&!    !&    ",
      "    &    &&&&   ",
      "          &&    ",
      "                ",
      "                ",
      "     !    !     ",
      "                ",
      "                ",
      "                ",
      "                ",
      "                ",
      "                ",
      "                ",
      "                ",
      "                "
    ],
    [
      " &&&&           ",
      "  &&&!!!!!!&    ",
      "     !    !&&   ",
      "     !    !&    ",
      "     !    !     ",
      "     !    !     ",
      "     !!!!!!     ",
      "XXXXXXXXXXXX    ",
      "XXXXXXXXXXXX    ",
      "XXX&  XX   X    ",
      "XXX   XX   X    ",
      "XXX   XX   X    ",
      "XXXXXXXXXXXX    ",
      "XXXXXXXXXXXX    ",
      "                ",
      "                "
    ]
  ]
}