{
  "xsize": 16,
  "zsize": 16,
  "refpalette": "lostcities:factory",
  "slices": [
    [
      "        &       ",
      "  ͳ,,,,,,,,,,   ",
      "  !    &&&      ",
      "        &       ",
      "      OOOO      ",
      "   & O  & O     ",
      "  &&O      O    ",
      "   &       O    ",
      "    O      O    ",
      "    O      O    ",
      "     O    O     ",
      "      OOOO      ",
      "                ",
      "  !          !  ",
      "  ͳ,,    ͳ,,,q  ",
      "                "
    ],
    [
      "                ",
      "        &       ",
      "  !     &       ",
      "        &       ",
      "      OOOO      ",
      "  && O  & O     ",
      " &&&O      O    ",
      "  &&O      O    ",
      "    O      O    ",
      "    O      O    ",
      "     O    O     ",
      "      OOOO      ",
      "                ",
      "  !          !  ",
      "                ",
      "                "
    ],
    [
      "                ",
      "                ",
      "  !     &&   !  ",
      "       &&&      ",
      "      OOOO      ",
      "  &  O  & O     ",
      " &&&O      O    ",
      " &&&O      O    ",
      "  & O      O    ",
      "    O      O    ",
      "     O    O     ",
      "      OOOO      ",
      "                ",
      "  !          !  ",
      "                ",
      "                "
    ],
    [
      "                ",
      "        &&      ",
      "  !    &&&&  !  ",
      "       &&&      ",
      "      OOOO      ",
      "     OOOOOO     ",
      "  & OOOOOOOO    ",
      " &&&OOOOOOOO    ",
      "  & OOOOOOOO    ",
      "    OOOOOOOO    ",
      "     OOOOOO     ",
      "      OOOO      ",
      "                ",
      "             !  ",
      "                ",
      "                "
    ],
    [
      "         &      ",
      "        &&&     ",
      "  !     &&&  !  ",
      "        &&&     ",
      "      OOOO      ",
      "     OOOOOO     ",
      " &&&OOOOOOOO    ",
      "&&&&OOOOOOOO    ",
      " && OOOOOOOO    ",
      "    OOOOOOOO    ",
      "     OOOOOO     ",
      "      OOOO      ",
      "                ",
      "             !  ",
      "                ",
      "                "
    ],
    [
      "!!     !!&&   !!",
      "!tttttttttttttt!",
      " t!tttttttttt!t ",
      " tttttttttttttt ",
      " tttttttttttttt ",
      " tttttttttttttt ",
      " ttttttttttttt  ",
      "&ttttttttttttt  ",
      " tttttttttttt   ",
      " ttttttttttttt  ",
      " tttttttttttttt ",
      " tttttttttttttt ",
      "    ttttttttttt ",
      "     tttttttt!t ",
      "     tttttttttt!",
      "       !!     !!"
    ]
  ]
}