{
  "xsize": 16,
  "zsize": 16,
  "refpalette": "pomkotsmechs:factory",
  "slices": [
    [
      "vvvvvvvvvvvvvvvv",
      "vvvvvvvvvvvvvvvv",
      "vvvvvvvvvvvvvvvv",
      "vvvvvvvvvvvvvvvv",
      "vvvvvvvvvvvvvvv ",
      "vvvvvvvvvvvvvv  ",
      "vvvvvvvvvvvvvv  ",
      "vvvvvvvvvvvvvv& ",
      "vvvvvvvvvvvvvv  ",
      "vvvvvvvvvvvvvvv ",
      "vvvvvvvvvvvvvvvv",
      "vvvvvvvvvvvvvvvv",
      "vvvvvvvvvvvvvvvv",
      "vvvvvvvvvvvvvvvv",
      "vvvvvvvvvvvvvvvv",
      "vvvvvvvvvvvvvvvv"
    ],
    [
      "                ",
      "   !        !   ",
      "                ",
      "                ",
      "                ",
      "   !        !   ",
      "           &    ",
      "    &     &&&&  ",
      "   &&& &&  &    ",
      "    & &&&       ",
      "   !   &    !   ",
      "                ",
      "                ",
      "  &             ",
      " &&!        !   ",
      " &&&            "
    ],
    [
      "                ",
      "   !!!!!!!!!!   ",
      "                ",
      "                ",
      "                ",
      "   !!!!!!!!!    ",
      "          &&&   ",
      "    &     &&&   ",
      "   &&& &   &    ",
      "   &&&&&&       ",
      "   !!!!!!!!!!   ",
      "                ",
      "                ",
      "                ",
      "  &!!!!!!!!!!   ",
      " &&&            "
    ],
    [
      "   OVVVVVVVVO   ",
      "   OVVVVVVVVO   ",
      "   OVVVVVVVV    ",
      "   OVVVVVVVV    ",
      "   OVVVVVVVV    ",
      "   OOOOOOOOO&   ",
      "          &&&&  ",
      "           &&   ",
      "   &&  &&       ",
      "  &&&&&&&&      ",
      "   OOOOOOOOOO   ",
      "   OVVVVVVVVO   ",
      "   OVVVVVVVVO   ",
      "   OVVVVVVVVO   ",
      "  &OVVVVVVVVO   ",
      " &&OVVVVVVVVO   "
    ],
    [
      "   V        V   ",
      "   V            ",
      "   V            ",
      "   V            ",
      "   V            ",
      "   OVVVVVVVV&   ",
      "           &&&  ",
      "            &   ",
      "   &    &       ",
      "  &&&  &&&      ",
      "  &OVVVVVVVVO   ",
      "   V        V   ",
      "   V        V   ",
      "   V        V   ",
      "   V        V   ",
      "  &V        V   "
    ],
    [
      "   V            ",
      "   V            ",
      "   V            ",
      "   V            ",
      "   V        &   ",
      "   OVVVVVVVV&&  ",
      "           &&&  ",
      "            &   ",
      "        &       ",
      "   &   &&&      ",
      "  &OVVVVVVVVO   ",
      "   V        V   ",
      "   V        V   ",
      "   V        V   ",
      "   V        V   ",
      "  &V        V   "
    ]
  ]
}