{
  "xsize": 16,
  "zsize": 16,
  "refpalette": "pomkotsmechs:factory",
  "slices": [
    [
      "!!!!!!!!!!!!!!!!",
      "!!!!!!!!!!!!!!!!",
      "!!!!!!!!!!!!!!!!",
      "                ",
      "/              +",
      "3              2",
      "                ",
      "                ",
      "  5             ",
      "                ",
      "                ",
      "                ",
      "                ",
      "                ",
      "                ",
      "                "
    ],
    [
      "!!!!!!!!!!     !",
      "!!!!!!!!!!!!!!!!",
      "!!!!!!!!!!!!  !!",
      "                ",
      "/              +",
      "3              2",
      "                ",
      "                ",
      "555             ",
      "                ",
      "                ",
      "                ",
      "ssssssssssssssss",
      "5555555555555555",
      "                ",
      "                "
    ],
    [
      "!!              ",
      "!![[[[[[[[      ",
      "!!! !   !      !",
      "                ",
      "/              +",
      "3              2",
      "                ",
      "                ",
      "                ",
      "                ",
      "                ",
      "                ",
      "                ",
      "                ",
      "                ",
      "                "
    ],
    [
      "!!              ",
      "!!              ",
      "!!! !   !  !   !",
      "                ",
      "V              V",
      "V              V",
      "                ",
      "                ",
      "                ",
      "                ",
      "                ",
      "                ",
      "                ",
      "                ",
      "                ",
      "                "
    ],
    [
      "!!              ",
      "!!             !",
      "!V!VVVVV!VVVVV!V",
      "VV            VV",
      "nV            Vn",
      "nV            Vn",
      "VV            VV",
      "V              V",
      "V              V",
      "V              V",
      "V              V",
      "V              V",
      "V              V",
      "V              V",
      "V              V",
      "V              V"
    ],
    [
      "!!!!!!!!!!!!!!!!",
      "!!!!!!!!!!!!!!!!",
      "!!!!!!!!!!!!!!!!",
      "!!!!!!!!!!!!!!!!",
      "!!!!!!!!!!!!!!!!",
      "!!!!!!!!!!!!!!!!",
      "!!!!!!!!!!!!!!!!",
      "!!rrrrrrrrrrrr!!",
      "!!rrrrrrrrrrrr!!",
      "!!rrrrrrrrrrrr!!",
      "!!rrrrrrrrrrrr!!",
      "!!rrrrrrrrrrrr!!",
      "!!rrrrrrrrrrrr!!",
      "!!rrrrrrrrrrrr!!",
      "!!rrrrrrrrrrrr!!",
      "!!rrrrrrrrrrrr!!"
    ]
  ]
}