{
  "xsize": 16,
  "zsize": 16,
  "refpalette": "pomkotsmechs:factory",
  "slices": [
    [
      " !           !  ",
      "!!! &  !&&  !!! ",
      "!!!!JJJJJJJ!!!!!",
      "!!! &   &&  !!! ",
      " !           !  ",
      "             J  ",
      "             J  ",
      "   !  !      J  ",
      "    rr       J! ",
      "    rr       J  ",
      "   !  !      J  ",
      "             J  ",
      "             !  ",
      "            !!! ",
      "           !!!!!",
      "!           !!! "
    ],
    [
      "!!           !  ",
      "!!! &  !&   !!! ",
      "!!!!!!!!!!!!!!!!",
      "!!! &   &   !!! ",
      "!!           !  ",
      "             !  ",
      "             !  ",
      "   !  !      !  ",
      "    rr       !! ",
      "    rr       !  ",
      "   !  !      !  ",
      "             !  ",
      "             !  ",
      "            !!! ",
      "           !!!!!",
      "!          !!!!!"
    ],
    [
      "!!     &     !  ",
      "!!!&& &!&   !!! ",
      "!!!!JJJJJJJ!!!!!",
      "!!!&&  &&   !!! ",
      "!!     &     !  ",
      "             J  ",
      "             J  ",
      "   !  !      J  ",
      "    rr       J! ",
      "    rr       J  ",
      "   !  !   &  J  ",
      "         &&  J  ",
      "         &   !  ",
      "         &  !!! ",
      "           !!!!!",
      "!          !!!!!"
    ],
    [
      "!!     &     !  ",
      "!!!&  &!&   !!! ",
      "!!!!JJJJJJJ!!!!!",
      "!!!!!!!!!!!!!!! ",
      "!!!!!!!!!!!!!!  ",
      "!!!!!!!!!!!!!J  ",
      "!!!!!!!!!!!!!J  ",
      "!!!!  !!!!!!!J  ",
      "    rr !!!!!!J! ",
      "    rr !!!!!!J  ",
      "  &!  !!!!!!!J  ",
      " &&   !!!!!!!J  ",
      " &    !!!!!!!!  ",
      "&&    !!!!!!!!! ",
      "  &   !!!!!!!!!!",
      "! &   !!!!!!!!!!"
    ],
    [
      "!!     &     !  ",
      "!!!   &!&   !!! ",
      "!!!!!!!!!!!!!!!!",
      "!!!   &&    !!! ",
      "!!   &&&&    !  ",
      "!!!!!!!!!    !  ",
      "!!!!!!!!!    !  ",
      "!!!!!!!!!    !  ",
      "!!!!!!!!!    !! ",
      "!!!!!!!!!    !  ",
      "!!!!!!!!! &  !  ",
      "!!!!!!!!!&&  !  ",
      "!!!!!!!!!&   !  ",
      "!!!!!!!!!&& !!! ",
      "!!!!!!!!!& !!!!!",
      "!!!!!!!!!  !!!!!"
    ],
    [
      "!!     &     !  ",
      "!!!   &!&   !!! ",
      "!!!!   &  J!!!!!",
      "!!!         !!! ",
      "!!    &&     !  ",
      "      &         ",
      "     &&&        ",
      "   ! &!&        ",
      "  & rr&       ! ",
      " &&&rr          ",
      " &&!  !         ",
      " &&             ",
      "&&&&    &&   !  ",
      "&&&&   &&&  !!! ",
      "!&&&  &&&  !!!!!",
      "!!&& &&&&  !!!!!"
    ]
  ]
}