{
  "xsize": 16,
  "zsize": 16,
  "refpalette": "pomkotsmechs:factory",
  "slices": [
    [
      "vvvJJJJJJJJJJJJJ",
      "vvvJJJJJJJJJJJJJ",
      "vvvJJJJJJJJJJJJJ",
      "vvvJJJJJJJJJJJJJ",
      "vvvJJJJJJJJJJJJJ",
      "vvvJJJJJJJJJJJJJ",
      "vvvJJJJJJJJJJJJJ",
      "vvvJJJJJJJJJJJJJ",
      "vvvJJJJJJJJJJJJJ",
      "vvvJJJJJJJJJJJJJ",
      "vvvJJJJJJJJJJJJJ",
      "vvvJJJJJJJJJJJJJ",
      "vvvJJJJJJJJJJJJJ",
      "vvvJJJJJJJJJJJJJ",
      "vvvJJJJJJJJJJJJJ",
      "vvvJJJJJJJJJJJJJ"
    ],
    [
      "!!!!!       !!!!",
      "            !!!!",
      "             !!!",
      "                ",
      "                ",
      "                ",
      "                ",
      "                ",
      "                ",
      "                ",
      "                ",
      "                ",
      "               &",
      "               &",
      "             !!!",
      "!!!!!        ! !"
    ],
    [
      "  !          !!!",
      "             !!!",
      "               &",
      "                ",
      "                ",
      "                ",
      "                ",
      "                ",
      "                ",
      "                ",
      "                ",
      "                ",
      "                ",
      "              &&",
      "             !!!",
      "  !          !&!"
    ],
    [
      "  !         !!!!",
      "            !!!!",
      "             !!!",
      "                ",
      "                ",
      "                ",
      "                ",
      "                ",
      "                ",
      "                ",
      "                ",
      "                ",
      "                ",
      "              & ",
      "             !!!",
      "  !          !&!"
    ],
    [
      "  !          !!!",
      "             !!!",
      "                ",
      "                ",
      "                ",
      "                ",
      "                ",
      "                ",
      "                ",
      "                ",
      "                ",
      "                ",
      "                ",
      "              & ",
      "             !!!",
      "  !          !&!"
    ],
    [
      "  !          !!!",
      "             !!!",
      "                ",
      "                ",
      "                ",
      "                ",
      "                ",
      "                ",
      "                ",
      "                ",
      "                ",
      "                ",
      "                ",
      "              & ",
      "             !!!",
      "  !          !&!"
    ]
  ]
}