{
  "xsize": 16,
  "zsize": 16,
  "refpalette": "pomkotsmechs:factory",
  "slices": [
    [
      "                ",
      "   OOOOO  OOOOO ",
      "   OOOOO  OOOOO ",
      "   OOOOO  OOOOO&",
      "   OOOOO  OOOOO ",
      "   OOOOO &OOOOO ",
      "          &     ",
      "          &     ",
      "   OOOOO &OOOOO ",
      "   OOOOO  OOOOO ",
      "  &OOOOO  OOOOO ",
      "   OOOOO  OOOOO ",
      "   OOOOO  OOOOO ",
      "             &&&",
      "              & ",
      "   << <<  << << "
    ],
    [
      "                ",
      "   $   $  $   $ ",
      "              & ",
      "             &&&",
      "          &   & ",
      "   $   $ &$&  $ ",
      "          &     ",
      "          &     ",
      "   $   $ &$&  $ ",
      "   &&&    &     ",
      "  &&&           ",
      "   &          & ",
      "   $   $  $  &$&",
      "             &&&",
      "              & ",
      "                "
    ],
    [
      "                ",
      "   OOOOO  OOOOO ",
      "   OOOOO  OOOOO ",
      "   OOOOO  OOOOO&",
      "   OOOOO  OOOOO ",
      "   OOOOO &OOOOO ",
      "          &     ",
      "          &     ",
      "   OOOOO &OOOOO ",
      "   OOOOO  OOOOO ",
      "  &OOOOO  OOOOO ",
      "   OOOOO  OOOOO ",
      "   OOOOO  OOOOO&",
      "              & ",
      "                ",
      "                "
    ],
    [
      "                ",
      "   OVVVO  OVVVO ",
      "   V   V  V   V ",
      "   V   V  V  &V&",
      "   V <<V  V <<V ",
      "   OVVVO  OVVVO ",
      "                ",
      "          &     ",
      "   OVVVO &OVVVO ",
      "    &&&V  V   V ",
      "   &&&<V  V <<V ",
      "    V<<V  VV<<V&",
      "   OVVVO  OVVVO&",
      "              & ",
      "                ",
      "                "
    ],
    [
      "                ",
      "   OVVVO  OVVVO ",
      "   V   V  V   V ",
      "   V   V  V  &V&",
      "   V   V  V  &V&",
      "   OVVVO  OVVVO ",
      "                ",
      "          &     ",
      "   OVVVO &OVVVO ",
      "   &&&&V  V   V ",
      "    && V  V   V ",
      "     VVV  VVVVV&",
      "    VVVO  OVVVO ",
      "                ",
      "                ",
      "                "
    ],
    [
      "                ",
      "   OVVVO  OVVVO ",
      "   VOOOV  VOOOV ",
      "   VOOOV  VOOOV ",
      "   VOOOV  VOOOV&",
      "   OVVVO  OVVVO ",
      "                ",
      "          &     ",
      "   OVVVO &OVVVO ",
      "   &OOOV  VOOOV ",
      "    &&OV  VOOOV ",
      "    OOOV  VOOOV&",
      "    VVVO  OVVVO ",
      "                ",
      "                ",
      "                "
    ]
  ]
}