{
  "xsize": 16,
  "zsize": 16,
  "refpalette": "lostcities:factory",
  "slices": [
    [
      "                ",
      " OVVVV          ",
      " V              ",
      " V              ",
      " V      &&V     ",
      " V     &&&V     ",
      " V      &&V     ",
      " V        V     ",
      "&V&       V     ",
      " V        V     ",
      " V        V     ",
      " O        O     ",
      " V        V     ",
      " V        V     ",
      " V        V     ",
      " V     & &V&    "
    ],
    [
      "                ",
      " OVVVV          ",
      " V              ",
      " V              ",
      " V       &V     ",
      " V      &&V     ",
      " V      &&V     ",
      " V     && V     ",
      "&V&    &  V     ",
      " V    &&  V     ",
      " V&   &   V     ",
      " O&&  &   O     ",
      " V &  &   V     ",
      " V &&&&   V     ",
      " V  &&    V     ",
      " V   &&&  &     "
    ],
    [
      "                ",
      " OOOOO          ",
      " OVVV           ",
      " OVVV           ",
      " OVVVVVV&&      ",
      " OVVVVVVVVO     ",
      " OVVVVVVVVO     ",
      " OVVVVVVVVO     ",
      "&OVVVVVVVVO     ",
      "&OVVVVVVVVO     ",
      "&OVVVVVVVVO     ",
      " OOOOOOOOOO     ",
      " OVVVVVVVVO     ",
      " OVVVVVVVVO     ",
      " OVVVVVVVVO     ",
      " OVVVVVV        "
    ],
    [
      "                ",
      "                ",
      "                ",
      "                ",
      "                ",
      "        &&      ",
      "        &       ",
      "       &&       ",
      " &     &        ",
      " &    &&        ",
      " &&   &         ",
      "  &&  &         ",
      "   &  &         ",
      "   &&&&         ",
      "    &&          ",
      "     &&         "
    ],
    [
      "                ",
      "                ",
      "                ",
      "                ",
      "                ",
      "                ",
      "                ",
      "                ",
      "                ",
      "                ",
      "                ",
      "                ",
      "                ",
      "                ",
      "                ",
      "                "
    ],
    [
      "                ",
      "                ",
      "                ",
      "                ",
      "                ",
      "                ",
      "                ",
      "                ",
      "                ",
      "                ",
      "                ",
      "                ",
      "                ",
      "                ",
      "                ",
      "                "
    ]
  ]
}