{
  "xsize": 16,
  "zsize": 16,
  "refpalette": "pomkotsmechs:factory",
  "slices": [
    [
      "vvvvvvvvvvvvvvvv",
      "vvvvvvvvvvvvvvvv",
      "vvvvvvvvvvvvvvvv",
      "vvvvvvvvvvvvvvvv",
      "vvvvvvvvvvvvvvvv",
      "vvvvvvvvvv    vv",
      "vvvvvvvvvv&    v",
      "vvvvvvvvv&&&   v",
      "vvvvvvvvv&&&   v",
      "vvvvvvvvvv && vv",
      "vvvvvvvvvvv&vvvv",
      "vvvvvvvvvvvvvvvv",
      "vvvvvvvvvvvvvvvv",
      "vvvvvvvvvvvvvvvv",
      "vvvvvvvvvvvvvvvv",
      "vvvvvvvvvvvvvvvv"
    ],
    [
      "                ",
      "                ",
      "                ",
      "                ",
      "                ",
      "         &      ",
      "        &&&     ",
      "         &&     ",
      "                ",
      "                ",
      "         &  &   ",
      "        &&&&&   ",
      "         &&&    ",
      "     !          ",
      "                ",
      "                "
    ],
    [
      "                ",
      "                ",
      "                ",
      "                ",
      "                ",
      "         &      ",
      "        &&&     ",
      "        &&&     ",
      "         &      ",
      "                ",
      "        &&      ",
      "       &&&&     ",
      "        &&      ",
      "     !          ",
      "                ",
      "                "
    ],
    [
      "                ",
      "                ",
      "                ",
      "                ",
      "                ",
      "             !  ",
      "         &      ",
      "        &&&     ",
      "         &      ",
      "                ",
      "        &       ",
      "       &&&      ",
      "        &       ",
      "     !          ",
      "                ",
      "                "
    ],
    [
      "                ",
      "                ",
      "                ",
      "                ",
      "                ",
      "             !  ",
      "         &      ",
      "        &&&     ",
      "         &      ",
      "                ",
      "        &       ",
      "       &&&      ",
      "       &&&      ",
      "     !  &       ",
      "                ",
      "                "
    ],
    [
      "             !  ",
      "             !  ",
      "             !  ",
      "             !  ",
      "    &&      !   ",
      "     &&&    !!  ",
      "       &&&      ",
      "        &&&     ",
      "         &      ",
      "                ",
      "                ",
      "      !!&       ",
      "    !!&&&&      ",
      "!!!! ! &&       ",
      "                ",
      "                "
    ]
  ]
}