{
  "xsize": 16,
  "zsize": 16,
  "refpalette": "pomkotsmechs:factory",
  "slices": [
    [
      "                ",
      "&               ",
      "&&              ",
      " &&             ",
      "  &             ",
      "                ",
      "      !  !      ",
      "       !!       ",
      "       !!       ",
      "      !  !      ",
      "                ",
      "                ",
      "                ",
      "                ",
      "                ",
      "                "
    ],
    [
      "||||zVVV|}}}|zVV",
      "v|||zVVVz|}||zzz",
      "vv||zVvVV||||zz|",
      "zvv|zVVVV||}||||",
      "zzv|zzVVz|}}}}}}",
      "VzzzzVVVz|}}}}}}",
      "VVVVVVVVz|||||||",
      "vvvVVVVVzzzzz|||",
      "vvvvVVVzzzzVzzzz",
      "VvvvVzzzzzVVVVVV",
      "vvvVz||||zzVVVvv",
      "vvvvV||}||zvvvvv",
      "vvvvvvvvvvvvvvvv",
      "vvvvvvvvvvvvvvvv",
      "vvvvvvvvvvvvvvvv",
      "vvvvvvvvvvvvvvvv"
    ],
    [
      "&               ",
      "&&              ",
      "&&              ",
      " &&             ",
      "  &             ",
      "                ",
      "                ",
      "                ",
      "                ",
      "            !!  ",
      "            !!  ",
      "                ",
      "                ",
      "             &  ",
      "            !!&&",
      "5           !!  "
    ],
    [
      "&               ",
      "&               ",
      "                ",
      "                ",
      "                ",
      "                ",
      "                ",
      "                ",
      "                ",
      "                ",
      "           ͱͱͱͱͱ",
      "           ͱͱͱͱͱ",
      "           ͱͱͱͱͱ",
      "           ͱͱͱͱͱ",
      "           ͱͱͱͱͱ",
      "5            &&&"
    ],
    [
      "&               ",
      "                ",
      "                ",
      "                ",
      "                ",
      "                ",
      "                ",
      "                ",
      "                ",
      "           ͱͱͱͱͱ",
      "           ͱ    ",
      "           ͱ    ",
      "           ͱ &  ",
      "           ͱ&&&&",
      "           ͱ &&&",
      "5          ͱͱͱͱͱ"
    ],
    [
      "                ",
      "                ",
      "                ",
      "                ",
      "                ",
      "                ",
      "                ",
      "                ",
      "           ͱͱͱͱͱ",
      "           ͱ    ",
      "           ͱ    ",
      "           ͱ    ",
      "           ͱ &  ",
      "           ͱ&&&&",
      "           ͱ &&&",
      "5          ͱ   &"
    ]
  ]
}