{
  "xsize": 16,
  "zsize": 16,
  "refpalette": "pomkotsmechs:factory",
  "slices": [
    [
      "!!!!!!!!!!!!!!!!",
      "!!!!!!!!!!!!!!!!",
      "!!!!!!!!!!!!!!!!",
      "!!!!!!!!!!!!!!!!",
      "!!!!!!!!!!!!!!!!",
      "!!!!!!!!!!!!!!!!",
      "!!!!!!!!!!&&!!!!",
      "!!!!!!!!!!&!!!!!",
      "!!!!!!!!!!&!!!!!",
      "!!!!!!!!!!8!!!!!",
      "!!!!!!!!!!!!!!!!",
      "!!!!!!!!!!!!!!  ",
      "!!!!!!!!!!!!!   ",
      "!!!!!!!!!!!!!   ",
      "!!!!!!!!!!!!!   ",
      "!!!!!!!!!!!!!   "
    ],
    [
      "!,,,,!    !,,,,!",
      "0              0",
      "0   JJ         0",
      "0              0",
      "0 J    J       !",
      "! J    J        ",
      "    &           ",
      "   &JJ   &&&&   ",
      "   &&&  &&      ",
      "   &JJ &&&      ",
      "!  &&  &&&     !",
      "0 J    J&      0",
      "0 J    J       0",
      "0               ",
      "0   JJ          ",
      "!,,,,!    !,,,  "
    ],
    [
      "$              $",
      "                ",
      "    XX          ",
      "   XXX          ",
      "  XX  XX        ",
      "  XX  XX        ",
      "   XXXX         ",
      "   &XX          ",
      "    &           ",
      "   &XX  &       ",
      "  &XXXX&&&      ",
      "  XX& XX&       ",
      "  XX  XX        ",
      "   XXXX         ",
      "    XX          ",
      "$               "
    ],
    [
      "                ",
      "                ",
      "                ",
      "   XX           ",
      "  XX            ",
      "  XX  XX        ",
      "   XXXX         ",
      "   &XX          ",
      "   &&&          ",
      "   &XX &&       ",
      "  &XXXX&&&      ",
      " &XX& XX&       ",
      " &XX  XX        ",
      "  &XXXX         ",
      "    XX          ",
      "                "
    ],
    [
      "                ",
      "                ",
      "                ",
      "   X            ",
      "  XX            ",
      "  XX   X        ",
      "   XXXX         ",
      "    XX          ",
      "   &&&          ",
      "  &&XX          ",
      "  &XXXX&&       ",
      " &XX& XX&       ",
      " &XX &XX&       ",
      "  &XXXX&        ",
      "    XX          ",
      "                "
    ],
    [
      "                ",
      "                ",
      "    X           ",
      "   X            ",
      "  X             ",
      "  X             ",
      "   X  X         ",
      "    XX          ",
      "   &&           ",
      "  &&XX          ",
      " &&X& X         ",
      " &X&&  X        ",
      "  X&   X&       ",
      "   X  X&        ",
      "    XX          ",
      "                "
    ]
  ]
}