{
  "xsize": 16,
  "zsize": 16,
  "refpalette": "pomkotsmechs:factory",
  "slices": [
    [
      "55         ͱͱͱͱͱ",
      " 55             ",
      "  5             ",
      "   5            ",
      "   5       ͱͱͱͱͱ",
      "   55      ͱ    ",
      "    5      ͱ    ",
      "    5      ͱ    ",
      "    5      ͱ    ",
      "    5      ͱ    ",
      "    5      ͱ    ",
      "    5      ͱ    ",
      "   55      ͱͱͱͱͱ",
      "   5            ",
      "   5            ",
      "  5             "
    ],
    [
      "55         ͱͱͱͱͱ",
      " 55             ",
      "  5             ",
      "   5            ",
      "   5       ͱͱͱͱͱ",
      "   55      ͱ    ",
      "    5      ͱ    ",
      "    5      ͱ    ",
      "    5      ͱ    ",
      "    5      ͱ    ",
      "    5      ͱ    ",
      "    5      ͱ    ",
      "   55      ͱͱͱͱͱ",
      "   5            ",
      "   5            ",
      "  5             "
    ],
    [
      "55         ͱͱͱͱͱ",
      " 55             ",
      "  5             ",
      "   5            ",
      "   5       ͱͱͱͱͱ",
      "   55      ͱ    ",
      "    5      ͱ    ",
      "    5      ͱ    ",
      "    5      ͱ    ",
      "    5      ͱ    ",
      "    5      ͱ    ",
      "    5      ͱ    ",
      "   55      ͱͱͱͱͱ",
      "   5            ",
      "   5            ",
      "  5             "
    ],
    [
      "55         ͱͱͱͱͱ",
      " 55             ",
      "  5             ",
      "   5            ",
      "   5       ͱͱͱͱͱ",
      "   55      ͱ    ",
      "    5      ͱ    ",
      "    5      ͱ    ",
      "    5      ͱ    ",
      "    5      ͱ    ",
      "    5      ͱ    ",
      "    5      ͱ    ",
      "   55      ͱͱͱͱͱ",
      "   5            ",
      "   5            ",
      "  5             "
    ],
    [
      "55              ",
      " 55             ",
      "  5             ",
      "   5            ",
      "   5            ",
      "   55      ͱͱͱͱͱ",
      "    5      ͱ    ",
      "    5      ͱ    ",
      "    5      ͱ    ",
      "    5      ͱ    ",
      "    5      ͱ    ",
      "    5      ͱͱͱͱͱ",
      "   55           ",
      "   5            ",
      "   5            ",
      "  5             "
    ],
    [
      "55              ",
      " 55             ",
      "  5             ",
      "   5            ",
      "   5            ",
      "   55           ",
      "    5      ͱͱͱͱͱ",
      "    5      ͱͱͱͱͱ",
      "    5      ͱͱͱͱͱ",
      "    5      ͱͱͱͱͱ",
      "    5      ͱͱͱͱͱ",
      "    5           ",
      "   55           ",
      "   5            ",
      "   5            ",
      "  5             "
    ]
  ]
}