{
  "xsize": 16,
  "zsize": 16,
  "refpalette": "pomkotsmechs:factory",
  "slices": [
    [
      "vvvvvvvvvvvvvvvv",
      "vvvvvvvvvvvvvvvv",
      "vvvvvvvvvvvvvvvv",
      "vvvvvvvvvvvvvvvv",
      "vvvvvvvvvvvvvvvv",
      "vvvvvvvvvvvvvvvv",
      "vvvvvvvvvvvvvvvv",
      "vvvvvvvvvvvvvvvv",
      "vvvvvvvvvvvvvvvv",
      "vvvvvvvvvvvvvvvv",
      "vvvvvvvvvvvvvvvv",
      "vvvvvvvvvvvvvvvv",
      "vvvvvvvvvvvvvvvv",
      "vvvvvvvvvvvvvvvv",
      "vvvvvvvvvvvvvvvv",
      "vvvvvvvvvvvvvvvv"
    ],
    [
      "         5      ",
      "          5     ",
      "      &   5     ",
      "     &&&  5     ",
      "      &    5    ",
      "           5    ",
      "           5    ",
      "                ",
      "                ",
      "           5    ",
      "           5    ",
      "           5    ",
      "          5     ",
      "          5     ",
      "  &       5     ",
      "  &&     5      "
    ],
    [
      "         5      ",
      "          5     ",
      "      &   5     ",
      "     &&&  5     ",
      "      &    5    ",
      "           5    ",
      "           5    ",
      "                ",
      "                ",
      "           5    ",
      "           5    ",
      "           5    ",
      "          5     ",
      "         &5&    ",
      "          5     ",
      " &&&     5      "
    ],
    [
      "         5      ",
      "          5     ",
      "      &   5     ",
      "     &&&  5     ",
      "      &    5    ",
      "           5    ",
      "           5    ",
      "                ",
      "                ",
      "           5    ",
      "           5    ",
      "           5    ",
      "          5     ",
      "         &5&    ",
      "          5     ",
      "  &      5      "
    ],
    [
      "         5      ",
      "          5     ",
      "      &   5     ",
      "     &&&        ",
      "      &         ",
      "           5    ",
      "           5    ",
      "           5    ",
      "           5    ",
      "           5    ",
      "           5    ",
      "          &5    ",
      "         &5&    ",
      "         &5&    ",
      "          5     ",
      "  &      5      "
    ],
    [
      "         5      ",
      "                ",
      "      &&        ",
      "     &&&&       ",
      "      &&        ",
      "                ",
      "                ",
      "           5    ",
      "           5    ",
      "           5    ",
      "           5    ",
      "          &5    ",
      "         &5&    ",
      "          5     ",
      "          5     ",
      "  &      5      "
    ]
  ]
}