{
  "xsize": 16,
  "zsize": 16,
  "refpalette": "lostcities:factory",
  "slices": [
    [
      "        QQQQQQQQ",
      "        QQQQQQQQ",
      "        QQQQQQQQ",
      "        QQQQQQQQ",
      "         QQQQQQQ",
      "   !!     QQQQQQ",
      "  &!!      QQQQQ",
      "   &        QQQQ",
      "                ",
      "                ",
      "                ",
      "         !!     ",
      "         !!     ",
      "                ",
      "                ",
      "                "
    ],
    [
      "      QQQQQQQQQQ",
      "      QQQQQQQQQQ",
      "       QQQQQQQQQ",
      "       QQQQQQQQQ",
      "       QQQQQQQQQ",
      "   !!   QQQQQQQQ",
      "   !!    QQQQQQQ",
      "   &&     QQQQQQ",
      "           QQQQQ",
      "              QQ",
      "                ",
      "         !!     ",
      "         !!     ",
      "                ",
      "                ",
      "                "
    ],
    [
      "   ! QQQQQQQQQQQ",
      "   ! QQQQQQQQQQQ",
      "   !  QQQQQQQQQQ",
      "   !! QQQQQQQQQQ",
      "    ! QQQQQQQQQQ",
      "   !!  QQQQQQQQQ",
      "   !!! QQQQQQQQQ",
      "   &&!! QQQQQQQQ",
      "    & !! QQQQQQQ",
      "       !!  QQQQQ",
      "        !!    QQ",
      "         !!!!   ",
      "         !! !!!!",
      "                ",
      "                ",
      "                "
    ],
    [
      "   !QQQQQQQQQQQQ",
      "   !QQQQQQQQQQQQ",
      "   ! QQQQQQQQQQQ",
      "   !!QQQQQQQQQQQ",
      "    !QQQQQQQQQQQ",
      "   !! QQQQQQQQQQ",
      "   !!!QQQQQQQQQQ",
      "   &&!!QQQQQQQQQ",
      "    & !!QQQQQQQQ",
      "       !!QQQQQQQ",
      "        !! QQQQQ",
      "         !!!! QQ",
      "         !! !!!!",
      "                ",
      "                ",
      "                "
    ],
    [
      "   VQQQQQQQQQQQQ",
      "   VQQQQQQQQQQQQ",
      "   VQQQQQQQQQQQQ",
      "   VVQQQQQQQQQQQ",
      "    VQQQQQQQQQQQ",
      "   !VQQQQQQQQQQQ",
      "   !!VQQQQQQQQQQ",
      "   &&VVQQQQQQQQQ",
      "      VVQQQQQQQQ",
      "       VVQQQQQQQ",
      "        VVQQQQQQ",
      "         !VVVQQQ",
      "         !! VVVV",
      "                ",
      "                ",
      "                "
    ],
    [
      "   VQQQQQQQQQQQQ",
      "   VQQQQQQQQQQQQ",
      "   VQQQQQQQQQQQQ",
      "   VVQQQQQQQQQQQ",
      "    VQQQQQQQQQQQ",
      "   !VQQQQQQQQQQQ",
      "   !!VQQQQQQQQQQ",
      "    &VVQQQQQQQQQ",
      "      VVQQQQQQQQ",
      "       VVQQQQQQQ",
      "        VVQQQQQQ",
      "         !VVVQQQ",
      "         !! VVVV",
      "                ",
      "                ",
      "                "
    ]
  ]
}