{
  "xsize": 16,
  "zsize": 16,
  "refpalette": "lostcities:factory",
  "slices": [
    [
      "                ",
      "                ",
      "                ",
      "                ",
      "                ",
      "                ",
      "      &         ",
      "    !!&&    !!  ",
      "      &     &&& ",
      "  !    !  ! &&& ",
      "  !   &!& !  & &",
      "       &        ",
      "    !!      !   ",
      "                ",
      "                ",
      "                "
    ],
    [
      "                ",
      "                ",
      "                ",
      "                ",
      "                ",
      "                ",
      "      &         ",
      "    55&&    55  ",
      "   5555&   555  ",
      "  555555  555&& ",
      "  555555& 55 &  ",
      "   5555&   55   ",
      "    55      5   ",
      "                ",
      "                ",
      "                "
    ],
    [
      "                ",
      "                ",
      "                ",
      "                ",
      "                ",
      "                ",
      "                ",
      "    55&&    55  ",
      "   5555&&  555  ",
      "  55  55  55&&& ",
      "  55  55& 55 &  ",
      "   5555&   55   ",
      "    55      5   ",
      "                ",
      "                ",
      "                "
    ],
    [
      "                ",
      "                ",
      "                ",
      "                ",
      "                ",
      "                ",
      "                ",
      "    55 &    55  ",
      "   5555&&  555  ",
      "  55  55& 55&&& ",
      "  55  55& 55&&& ",
      "   5555&   55&  ",
      "    55      5   ",
      "                ",
      "                ",
      "                "
    ],
    [
      "                ",
      "                ",
      "                ",
      "                ",
      "                ",
      "                ",
      "                ",
      "    55      55  ",
      "   5555&   555  ",
      "  555555& 555&  ",
      "  555555  555&& ",
      "   5555    55&  ",
      "    55          ",
      "                ",
      "                ",
      "                "
    ],
    [
      "                ",
      "                ",
      "                ",
      "                ",
      "                ",
      "                ",
      "                ",
      "                ",
      "    55      55  ",
      "   5555&   555  ",
      "   5555    555& ",
      "    55      &&  ",
      "                ",
      "                ",
      "                ",
      "                "
    ]
  ]
}