{
  "xsize": 16,
  "zsize": 16,
  "refpalette": "pomkotsmechs:factory",
  "slices": [
    [
      " 0    VVVVVVVVVV",
      " 0   &VVVVVVVVVV",
      " 0& &&VVVVVVVVVV",
      "&0&&&!VVVVVVVVVV",
      "&0&&  !         ",
      "&0&             ",
      " 0              ",
      " 0    VVV       ",
      " 0   V   V      ",
      " 0  V     V     ",
      " 0  V     V     ",
      " !  V     V     ",
      " 0   V   V      ",
      " 0    VVV       ",
      " 0              ",
      " 0              "
    ],
    [
      " 0    V       &&",
      " 0    V&&&   &&&",
      " 0   &V&&&&  &&&",
      " 0&  !VVVVVVVVVV",
      "&0&             ",
      " 0              ",
      " 0              ",
      " 0    VVV       ",
      " 0   V   V      ",
      " 0  V     V     ",
      " 0  V     V     ",
      " !  V     V     ",
      " 0   V   V      ",
      " 0    VVV       ",
      " 0              ",
      " 0              "
    ],
    [
      "      V         ",
      "      V &    &&&",
      "     &V&&&  &&&&",
      "      &&VVVVVVVV",
      " &              ",
      "                ",
      "                ",
      "      VVV       ",
      "     V   V      ",
      "    V     V     ",
      "    V     V     ",
      " $  V     V     ",
      "     V   V      ",
      "      VVV       ",
      "                ",
      "                "
    ],
    [
      "      V         ",
      "       &&    &  ",
      "      &&&&  &&& ",
      "      &&VVVVVVVV",
      "       &    &&  ",
      "                ",
      "                ",
      "      VVV       ",
      "     V   V      ",
      "    V     V     ",
      "    V     V     ",
      " !  V     V     ",
      "     V   V      ",
      "      VVV       ",
      "                ",
      "                "
    ],
    [
      "      V         ",
      "                ",
      "       &&&&&&&  ",
      "      &&VVVVVVVV",
      "       &&&&&&   ",
      "                ",
      "                ",
      "      VVV       ",
      "     V   V      ",
      "    V     V     ",
      "    V     V     ",
      "    V     V     ",
      "     V   V      ",
      "      VVV       ",
      "                ",
      "                "
    ],
    [
      "      V         ",
      "                ",
      "       &&       ",
      "      &&&&&&&  V",
      "       &&       ",
      "                ",
      "                ",
      "      VVV       ",
      "     V   V      ",
      "    V     V     ",
      "    V     V     ",
      "    V     V     ",
      "     V   V      ",
      "      VVV       ",
      "                ",
      "                "
    ]
  ]
}