{
  "xsize": 16,
  "zsize": 16,
  "refpalette": "lostcities:factory",
  "slices": [
    [
      "                ",
      "                ",
      "                ",
      "                ",
      "               &",
      "               &",
      " !            !&",
      "                ",
      "                ",
      "mmjjjjmmmmjjjmmm",
      "VVVVVVVVVVVVVVVV",
      "VVVVVVVVVVVVVVVV",
      "VVVVVVVVVVVVVVVV",
      "VnmmmmVVVVmmmmnV",
      "Vo    VVVV  &&kV",
      "Vo    VVVV    kV"
    ],
    [
      "                ",
      "                ",
      "!!!         !!!!",
      "!!!!        !!!!",
      "!!!!        !!!!",
      "!!!!        !!!!",
      "!!!!        !!!!",
      "                ",
      "                ",
      ",,,,,,,,,,,,,,,,",
      "                ",
      "              &&",
      "            &&& ",
      " +,,,,/  +,,,,/ ",
      " 0    0  0  & 0 ",
      " 0    0  0    0 "
    ],
    [
      "JJJJJJJJJJJJJJJJ",
      "JJJJJJJJJJJJJJJJ",
      "JJJJJJJJJJJJJJJJ",
      " JJJJJJJJJJJJJJ&",
      " JJJJJJJJJJJJJJ&",
      "  JJJJJJJJJJJJ &",
      "   JJJJJJJJJJ   ",
      "     JJJJJJ     ",
      "                ",
      "                ",
      "                ",
      "                ",
      "                ",
      "            &   ",
      "                ",
      "                "
    ],
    [
      "J              J",
      "J              J",
      "J              J",
      " J            J&",
      " J            J&",
      "  J          J &",
      "   JJ      JJ   ",
      "     JJJJJJ     ",
      "                ",
      "                ",
      "                ",
      "                ",
      "                ",
      "                ",
      "                ",
      "                "
    ],
    [
      "J              J",
      "J              J",
      "J              J",
      " J            J&",
      " J            J&",
      "  J          J &",
      "   JJ      JJ   ",
      "     JJJJJJ     ",
      "                ",
      "                ",
      "                ",
      "                ",
      "                ",
      "                ",
      "                ",
      "                "
    ],
    [
      "J              J",
      "J              J",
      "J              J",
      " J            J ",
      " J            J&",
      "  J          J  ",
      "   JJ      JJ   ",
      "     JJJJJJ     ",
      "                ",
      "                ",
      "                ",
      "                ",
      "                ",
      "                ",
      "                ",
      "                "
    ]
  ]
}