{
  "xsize": 16,
  "zsize": 16,
  "refpalette": "lostcities:factory",
  "slices": [
    [
      "                ",
      "   OVVVVVVVVO   ",
      "  &V&       V   ",
      "   V        V   ",
      "   V        V   ",
      "   V       &V&  ",
      "   V        V   ",
      "   V        V   ",
      "   V        V   ",
      "   V        V   ",
      "   V        V   ",
      "   O        O   ",
      "   V        V   ",
      "   V        V   ",
      "   V        V   ",
      "   V            "
    ],
    [
      "                ",
      "   OVVVVVVVVO   ",
      "  &V&       V   ",
      "  &V&       V   ",
      "   V        V   ",
      "   V       &V&  ",
      "   V        V   ",
      "   V        V   ",
      "   V        V   ",
      "   V        V   ",
      "   V        V   ",
      "   O        O   ",
      "   V        V   ",
      "   V        V   ",
      "   V            ",
      "   V            "
    ],
    [
      "                ",
      "   OVVVVVVVVO   ",
      "   V        V   ",
      "  &V&       V   ",
      "   V        V   ",
      "   V       &V&  ",
      "   V       &V&  ",
      "   V        V   ",
      "   V        V   ",
      "   V        V   ",
      "   V        V   ",
      "   O        O   ",
      "   V        V   ",
      "   V            ",
      "   V            ",
      "   V            "
    ],
    [
      "                ",
      "   OVVVVVVVVO   ",
      "   V        V   ",
      "  &V&       V   ",
      "   V        V   ",
      "   V        V   ",
      "   V       &V&  ",
      "   V        V   ",
      "   V       &V   ",
      "   V        V   ",
      "   V        V   ",
      "   O        O   ",
      "   V            ",
      "   V            ",
      "   V            ",
      "   V            "
    ],
    [
      "                ",
      "   OOOOOOOOOO   ",
      "   OVVVVVVVVO   ",
      "  &OVVVVVVVVO   ",
      "  &OVVVVVVVVO   ",
      "   OVVVVVVVVO   ",
      "   OVVVVVVVVO&  ",
      "   OVVVVVVVVO   ",
      "   OVVVVVVVVO&  ",
      "   OVVVVVVVVO   ",
      "   OVVVVVVVVO   ",
      "   OOOOOOOOO    ",
      "   OVVVVVVV     ",
      "   OVVVVVVVV    ",
      "   OVVVVVVV     ",
      "   OVVVVVVVV    "
    ],
    [
      "                ",
      "   !        !   ",
      "                ",
      "   &            ",
      "  &&&           ",
      "   !        !   ",
      "           &&&  ",
      "           &&&  ",
      "          &&&&  ",
      "   !       &!   ",
      "                ",
      "                ",
      "                ",
      "   !            ",
      "                ",
      "                "
    ]
  ]
}