{
  "xsize": 16,
  "zsize": 16,
  "refpalette": "pomkotsmechs:factory",
  "slices": [
    [
      "                ",
      "                ",
      "                ",
      "                ",
      "                ",
      "                ",
      "      !  !      ",
      "       !!       ",
      "       !!       ",
      "      !  !      ",
      "                ",
      "                ",
      "                ",
      "                ",
      "                ",
      "                "
    ],
    [
      "|zVVVVVvvvvvvvvv",
      "VVVzz|zVvvvvvvvv",
      "vvVz|}|zVVVvvvv|",
      "vvVz|}}|zVVvvvv}",
      "vvVz|}}||zzvvv}}",
      "vvVVz||||||}}}}}",
      "vvVVVVVzz|}}}}}}",
      "vVVVVvvVz|}}}}}}",
      "VVVVVvvvVz}}}}||",
      "VVVVVVVvVVz|||zV",
      "zzzzzVVVvvVVzVVV",
      "||||zzVVvvvVVVvv",
      "}}|||zVVVVVVVVvv",
      "}}}||zVVVzz|zzVv",
      "}}}||zVzz|}}|zVV",
      "|}}||zVz|}}}|zVV"
    ],
    [
      "                ",
      "        !!    !!",
      "        !!    !!",
      "5               ",
      "5               ",
      " 5              ",
      " 5              ",
      " 5              ",
      " 5              ",
      " 5              ",
      " 5              ",
      " 5              ",
      "5       !!      ",
      "5       !!      ",
      "&               ",
      "&               "
    ],
    [
      "                ",
      "              !!",
      "              !!",
      "5               ",
      "5               ",
      " 5              ",
      " 5              ",
      " 5              ",
      " 5              ",
      " 5              ",
      " 5              ",
      " 5              ",
      "5               ",
      "5               ",
      "                ",
      "&               "
    ],
    [
      "                ",
      "              !!",
      "              !!",
      "5               ",
      "5               ",
      " 5              ",
      " 5              ",
      " 5              ",
      " 5              ",
      " 5              ",
      " 5              ",
      " 5              ",
      "5               ",
      "5               ",
      "                ",
      "&               "
    ],
    [
      "&               ",
      "&             !!",
      "&             !!",
      "5               ",
      "5               ",
      " 5              ",
      " 5              ",
      " 5              ",
      " 5              ",
      " 5              ",
      " 5              ",
      " 5              ",
      "5               ",
      "5               ",
      "                ",
      "&               "
    ]
  ]
}