{
  "meta": [
    {
      "key": "dontconnect",
      "boolean": true
    }
  ],
  "xsize": 16,
  "zsize": 16,
  "refpalette": "lcmt:factory_common",
  "slices": [
    [
      "#ff             ",
      "#ff             ",
      "#ff             ",
      "#ff             ",
      "#ff             ",
      "#ff             ",
      "#ff             ",
      "#ff             ",
      "#ff             ",
      "#ff             ",
      "#ff             ",
      "#ff             ",
      "#ff             ",
      "#ff             ",
      "#lf#a#    #a####",
      "$##$ $aaaa$ $ $ "
    ],
    [
      "# :             ",
      "# :             ",
      "# :             ",
      "# :             ",
      "# :             ",
      "# :             ",
      "# :             ",
      "# :             ",
      "# :             ",
      "# :             ",
      "# :             ",
      "# :             ",
      "# :             ",
      "# :             ",
      "#l:#a#    #a####",
      "$##$ $aaaa$ $ $ "
    ],
    [
      "#               ",
      "#               ",
      "#               ",
      "#               ",
      "#               ",
      "#               ",
      "#               ",
      "#               ",
      "#               ",
      "#               ",
      "#               ",
      "#               ",
      "#               ",
      "#               ",
      "#l #a#    #a####",
      "$##$ $aaaa$ $ $ "
    ],
    [
      "#               ",
      "a               ",
      "a               ",
      "#               ",
      "#               ",
      "a               ",
      "a               ",
      "#               ",
      "#               ",
      "a               ",
      "a               ",
      "#               ",
      "#               ",
      "#               ",
      "#l #a#    #a####",
      "$##$ $aaaa$ $ $ "
    ],
    [
      "#               ",
      "#               ",
      "#               ",
      "#               ",
      "#               ",
      "#               ",
      "#               ",
      "#               ",
      "#               ",
      "#               ",
      "#               ",
      "#               ",
      "#               ",
      "#               ",
      "#l #a#    #a####",
      "$##$ $aaaa$ $ $ "
    ],
    [
      "#               ",
      "#               ",
      "#               ",
      "#               ",
      "#               ",
      "#               ",
      "#               ",
      "#               ",
      "#               ",
      "#               ",
      "#               ",
      "#               ",
      "#               ",
      "#               ",
      "#l #a#    #a####",
      "$##$ $aaaa$ $ $ "
    ]
  ]
}
