{
  "xsize": 16,
  "zsize": 16,
  "refpalette": "pomkotsmechs:factory",
  "slices": [
    [
      " ] J          J ",
      " ] J          J ",
      " ] J          J5",
      " ] J          J ",
      " ] JJJJJJJJJJJJ ",
      " ]!     555    +",
      "!!!            2",
      "!!!             ",
      "&!              ",
      " !              ",
      "!!!             ",
      "!!!            +",
      " ]!            2",
      " ]              ",
      " ]              ",
      " ]              "
    ],
    [
      " ] J          J ",
      " ] J          J ",
      " ] J          J5",
      " ] J          J ",
      " ] JJJJJJJJJJJJ ",
      " ]!     555    +",
      "!!!      5     2",
      "!!!      5      ",
      "&!       5      ",
      "&!              ",
      "!!!             ",
      "!!!            +",
      " ]!            2",
      " ]              ",
      " ]              ",
      " ]              "
    ],
    [
      " ] J          J5",
      " ] J          J5",
      " ] J          J5",
      " ] J          J ",
      " ] JJJJJJJJJJJJ ",
      " ]!     555    +",
      "!!!            2",
      "!!!             ",
      "&!       5      ",
      "&!              ",
      "!!!             ",
      "!!!            +",
      " ]!            2",
      " ]              ",
      " ]              ",
      " ]              "
    ],
    [
      " ] J          J ",
      " ] J          J ",
      " ] J          J5",
      " ] J          J ",
      " ] JJJJJJJJJJJJ ",
      " ]!            +",
      "!!!            2",
      "!!!             ",
      "&!       5      ",
      "&!              ",
      "!!!             ",
      "!!!            +",
      " ]!            2",
      " ]              ",
      " ]              ",
      " ]              "
    ],
    [
      " ] J          J ",
      " ] J          J ",
      " ] J          J5",
      " ] J          J ",
      " ] JJJJJJJJJJJJ ",
      " ]!            +",
      "!!!            2",
      "!!!             ",
      "&!       5      ",
      "&!              ",
      "!!!             ",
      "!!!            +",
      " ]!            2",
      " ]              ",
      " ]              ",
      " ]              "
    ],
    [
      " ] J          J ",
      " ] J          J5",
      " ] J          J5",
      " ] J          J5",
      " ] JJJJJJJJ   J ",
      " ]!            V",
      "!!!            V",
      "!!!             ",
      "&!       5      ",
      "&!              ",
      "!!!             ",
      "!!!            V",
      " ]!            V",
      " ]              ",
      " ]              ",
      " ]              "
    ]
  ]
}