{
  "xsize": 16,
  "zsize": 16,
  "refpalette": "pomkotsmechs:factory",
  "slices": [
    [
      "              i ",
      "              i ",
      "              i ",
      "              i ",
      "      &&      i ",
      "     &&&&     i ",
      "      &&      i ",
      "              i ",
      "             &i&",
      "              i ",
      "              i ",
      "              i ",
      "             !i ",
      "             !!!",
      "             !!!",
      "              ! "
    ],
    [
      "              i ",
      "              i ",
      "              i ",
      "              i ",
      "      &       i ",
      "     &&&      i ",
      "     &&&      i ",
      "      &       i ",
      "             &i&",
      "              i ",
      "              i ",
      "              i ",
      "             !i ",
      "             !!!",
      "             !!!",
      "              ! "
    ],
    [
      "              i ",
      "              i ",
      "              i ",
      "              i ",
      "              i ",
      "     &&       i ",
      "    &&&&      i ",
      "     &&       i ",
      "             &i&",
      "              i ",
      "              i ",
      "              i ",
      "             !i ",
      "             !!!",
      "             !!!",
      "              ! "
    ],
    [
      "              i ",
      "              i ",
      "              i ",
      "              i ",
      "              i ",
      "    &&        i ",
      "   &&&&       i ",
      "    &&        i ",
      "             &i&",
      "              i ",
      "              i ",
      "              i ",
      "             !i ",
      "             !!!",
      "             !!!",
      "              ! "
    ],
    [
      "              i ",
      "              i ",
      "              i ",
      "              i ",
      "              i ",
      "    &         i ",
      "   &&&        i ",
      "   &&&        i ",
      "    &        &i&",
      "             &i&",
      "              i ",
      "              i ",
      "             !i ",
      "             !!!",
      "             !!!",
      "              ! "
    ],
    [
      "              i ",
      "              i ",
      "              i ",
      "              i ",
      "              i ",
      "              i ",
      "   &&         i ",
      "  &&&&        i ",
      "   &&         i ",
      "             &i&",
      "              i ",
      "              i ",
      "    VV       !i ",
      "    VV       !!!",
      "             !!!",
      "              ! "
    ]
  ]
}