{
  "xsize": 16,
  "zsize": 16,
  "refpalette": "pomkotsmechs:factory",
  "slices": [
    [
      "                ",
      "                ",
      "                ",
      "                ",
      "                ",
      "                ",
      "      !  !      ",
      "       !!       ",
      "       !!       ",
      "      !  !      ",
      "                ",
      "                ",
      "                ",
      "                ",
      "                ",
      "                "
    ],
    [
      "VVz|}}}}}}|zvvvv",
      "VVz|}}}}}}||Vvvv",
      "VVz|}}}}||||zvvv",
      "zz||||||||||zVvv",
      "||||zzzzzzzzVVvv",
      "||||zVVVVVVzVVVV",
      "}}||zVVVVVVVzzzz",
      "}||zzzVvVVVzz||v",
      "||zzzzzvVVVz||}v",
      "zzVzz|v|zVVz|}}v",
      "zVVVz|||zVVz|}}v",
      "zzVzz|||zVVz||}v",
      "|zzz|||zzVVzzz|v",
      "||||||||zzzzzVVv",
      "v}}}}}|||||zzVVv",
      "vv}}}}}|||||zVVv"
    ],
    [
      "    5        &55",
      "   5        &55 ",
      "555          5  ",
      "            5   ",
      "            5   ",
      "           5    ",
      "           5    ",
      "55555555   5    ",
      "       5   5    ",
      "55555555   5    ",
      "           5    ",
      "           5    ",
      "            5   ",
      "            5   ",
      "             5  ",
      "             55 "
    ],
    [
      "    5        &55",
      "   5        &55 ",
      "555          5  ",
      "            5   ",
      "            5   ",
      "           5    ",
      "           5    ",
      "           5    ",
      "           5    ",
      "           5    ",
      "           5    ",
      "           5    ",
      "            5   ",
      "            5   ",
      "             5  ",
      "             55 "
    ],
    [
      "    5        &55",
      "   5        &55 ",
      "555          5  ",
      "            5   ",
      "            5   ",
      "           5    ",
      "           5    ",
      "           5    ",
      "           5    ",
      "           5    ",
      "           5    ",
      "           5    ",
      "            5   ",
      "            5   ",
      "             5  ",
      "             55 "
    ],
    [
      "    5        &55",
      "   55       &55 ",
      "5555         5  ",
      "555         5   ",
      "            5   ",
      "           5    ",
      "           5    ",
      "           5    ",
      "           5    ",
      "           5    ",
      "           5    ",
      "           5    ",
      "            5   ",
      "            5   ",
      "             5  ",
      "             55 "
    ]
  ]
}