{
  "xsize": 16,
  "zsize": 16,
  "refpalette": "pomkotsmechs:factory",
  "slices": [
    [
      "$!!!!!!!!!!!!  !",
      "!!!!!!!!!!!!!!!!",
      "!!!!!!!!!!!!!!!!",
      "!!!             ",
      "!!!            +",
      "!!!            2",
      "!!!             ",
      "!!!             ",
      "!!!    55555    ",
      "!!!   5&&&& 5   ",
      "!!!  5  &&   5  ",
      "!!! 5         5 ",
      "!!! 5         55",
      "!!! 5         55",
      " !! 5         55",
      "    5         5 "
    ],
    [
      "!!!!!!!!!!!!!  !",
      "!!!!!!!!!!!!!!!!",
      "!!!!!!!!!!!!!!!!",
      "!!!             ",
      "!!!            +",
      "!!!            2",
      "!!!             ",
      "!!!             ",
      "!!!    555555555",
      "!!!   5&&&  5   ",
      "!!!  5  &    5  ",
      "!!! 5         5 ",
      "!!! 5         55",
      "!!! 5         55",
      " !! 5         55",
      "    5         5 "
    ],
    [
      "!!        !!!  !",
      " ![[[[[[[[!!!!!!",
      " ! ! !   !!!!  !",
      "!!!             ",
      "!!!            +",
      "!!!            2",
      " ]!             ",
      " ]              ",
      "&]     55555    ",
      "&]!   5&&&  5   ",
      "&]   5  &    5  ",
      " ]  5         5 ",
      " ]  5         55",
      " ]! 5         55",
      " ]  5         55",
      "    5         5 "
    ],
    [
      " !        !!!  !",
      " !        !!!  !",
      " ! ! !   !!!!  !",
      "!!!             ",
      "!!!            V",
      "!!!            V",
      "  !             ",
      "                ",
      "&      55555    ",
      "&&!   5&&&  5   ",
      "&    5  &    5  ",
      "    5         5 ",
      "    5         5 ",
      "  ! 5         5 ",
      "    5         5 ",
      "    5         5 "
    ],
    [
      " !        !!!  !",
      " !        !!!  !",
      " !V!V!VVV!V!!VV!",
      "!!!           VV",
      "!!!VVVVVVVVVVVVn",
      "!!VVVVVVVVVVVVVn",
      "  !           VV",
      "  V          &&V",
      "& V    55555 & V",
      "&&!&&&5&&&  5  V",
      "& V  5  &    5 V",
      "  V 5         5V",
      "  V 5         5V",
      "  ! 5         5V",
      "  V 5         5V",
      "              5V"
    ],
    [
      "!!!!!!!!!!!!!!!!",
      "!!!!!!!!!!!!!!!!",
      "!!!!!!!!!!!!!!!!",
      "!!!!!!!!!!!!!!!!",
      "!!!!!!!!!!!!!!!!",
      "!!!!!!!!!!!!!!!!",
      "!!!!!!!!!!!!!!!!",
      "!!!!rrrrrrrrrrr!",
      "!!!!rrr55555rrr!",
      "!!!!rr5&&&  5rr!",
      "!!!!r5  &    5r!",
      "!!!!5         5!",
      "!!!!5         5!",
      "!!!!5         5!",
      "!!            5!",
      "              5!"
    ]
  ]
}