{
  "xsize": 16,
  "zsize": 16,
  "refpalette": "pomkotsmechs:factory",
  "slices": [
    [
      "                ",
      "        VVVVVVO ",
      "         &    V ",
      "        &&&   V ",
      "         &    V ",
      "              V ",
      "              V ",
      "     V        V ",
      "     V        V ",
      "     V        V ",
      "    &V&       V ",
      "     O        O ",
      "     V        V ",
      "     V        V ",
      "     V       &V&",
      "     V        V "
    ],
    [
      "                ",
      "         VVVVVO ",
      "         &    V ",
      "        &&&   V ",
      "         &    V ",
      "         &    V ",
      "         &    V ",
      "         &    V ",
      "     V   &&   V ",
      "     V    &   V ",
      "    &V&   &   V ",
      "    &O&   &   O ",
      "     V&&& &   V ",
      "     V  &&&   V ",
      "     V     &&&V&",
      "     V     &  V "
    ],
    [
      "                ",
      "         OOOOOO ",
      "         &VVVVO ",
      "        &VVVVVO ",
      "        &VVVVVO ",
      "        &VVVVVO ",
      "        VVVVVVO ",
      "        VVVVVVO ",
      "     O  VVVVVVO ",
      "     OVVVVVVVVO ",
      "     OVVVVVVVVO ",
      "    &OOOOOOOOOO ",
      "     OVVVVVVVVO ",
      "     OVVVVVVVVO ",
      "     OVVVVVVVVO&",
      "     OVVVVVVVVO "
    ],
    [
      "                ",
      "                ",
      "                ",
      "         &      ",
      "         &      ",
      "         &      ",
      "         &      ",
      "         &      ",
      "         &&     ",
      "          &     ",
      "          &     ",
      "     &&   &     ",
      "      &&&&&&    ",
      "        &&&&&   ",
      "         &&&&&& ",
      "          &&&   "
    ],
    [
      "                ",
      "                ",
      "                ",
      "                ",
      "                ",
      "                ",
      "                ",
      "                ",
      "                ",
      "                ",
      "                ",
      "                ",
      "          &     ",
      "          &     ",
      "          &&&   ",
      "                "
    ],
    [
      "                ",
      "                ",
      "                ",
      "                ",
      "                ",
      "                ",
      "                ",
      "                ",
      "                ",
      "                ",
      "                ",
      "                ",
      "                ",
      "                ",
      "                ",
      "                "
    ]
  ]
}