{
  "refpalette": "lcmt:factory_common",
  "xsize": 16,
  "zsize": 16,
  "slices": [
    [
      "                ",
      "                ",
      "  qrqrqrqrqrqr  ",
      "  r          q  ",
      "  q          r  ",
      "  r          q  ",
      "  q          r  ",
      "  r          q  ",
      "  q          r  ",
      "  r          q  ",
      "  q          r  ",
      "  r          q  ",
      "  q          r  ",
      "  rqrqrqrqrqrq  ",
      "                ",
      "                "
    ],
    [
      "                ",
      "                ",
      "                ",
      "                ",
      "    MMMMMMMk    ",
      "    MQQQQQMk    ",
      "    MQQQQQMk    ",
      "    MQQQQQMk    ",
      "    MQQQQQMk    ",
      "    MQQQQQMk    ",
      "    MMMMMMMk    ",
      "    kkukukku    ",
      "                ",
      "                ",
      "                ",
      "                "
    ],
    [
      "                ",
      "                ",
      "                ",
      "                ",
      "    M+++++M     ",
      "    +WWWWW+     ",
      "    +WOWOW+     ",
      "    +WWOWWP     ",
      "    +WOWOW+     ",
      "    +WWWWW+     ",
      "    M+U+U+M     ",
      "      V V  +    ",
      "                ",
      "                ",
      "                ",
      "                "
    ],
    [
      "                ",
      "                ",
      "                ",
      "                ",
      "    M+++++M     ",
      "    +WWWWW+%    ",
      "    +WOWOW+     ",
      "    +WWOWW+     ",
      "    +WOWOW+     ",
      "    +WWWWW+     ",
      "    M+++++M     ",
      "       %   _    ",
      "                ",
      "                ",
      "                ",
      "                "
    ],
    [
      "                ",
      "                ",
      "                ",
      "                ",
      "    M+++++M     ",
      "    +WWWWW+     ",
      "    +WOWOW+     ",
      "    +WWOWW+     ",
      "    +WOWOW+%    ",
      "    +WWWWW+     ",
      "    M+++++M     ",
      "                ",
      "                ",
      "                ",
      "                ",
      "                "
    ],
    [
      "                ",
      "                ",
      "                ",
      "                ",
      "    MMMMMMM     ",
      "    MuuuuuM     ",
      "    MufufuM     ",
      "    MuufuuM     ",
      "    MufufuM     ",
      "    MuuuuuM     ",
      "    MMMMMMM     ",
      "         %      ",
      "                ",
      "                ",
      "                ",
      "                "
    ]
  ]
}
