{
  "xsize": 16,
  "zsize": 16,
  "refpalette": "pomkotsmechs:factory",
  "slices": [
    [
      "  555  5     &55",
      "  55   5     555",
      "555    5     555",
      "       5    5555",
      "       5    5555",
      "       5   55555",
      "       5   55555",
      "       5   55555",
      "       5   55555",
      "       5   55555",
      "       5   55555",
      "       5   55555",
      "       5    5555",
      "       5    5555",
      "       5     555",
      "       5     555"
    ],
    [
      "    5        &55",
      "   55        55&",
      "5555         5 &",
      "555         5   ",
      "            5   ",
      "           5    ",
      "           5    ",
      "           5    ",
      "           5    ",
      "           5    ",
      "           5    ",
      "           5    ",
      "            5   ",
      "            5   ",
      "             5  ",
      "             55 "
    ],
    [
      "    5        &55",
      "   5         55&",
      "555          5 &",
      "            5   ",
      "            5   ",
      "           5    ",
      "           5    ",
      "           5    ",
      "           5    ",
      "           5    ",
      "           5    ",
      "           5    ",
      "            5   ",
      "            5   ",
      "             5  ",
      "             55 "
    ],
    [
      "    5        &55",
      "   5         55&",
      "555          5 &",
      "            5   ",
      "            5   ",
      "           5    ",
      "           5    ",
      "           5    ",
      "           5    ",
      "           5    ",
      "           5    ",
      "           5    ",
      "            5   ",
      "            5   ",
      "             5  ",
      "             55 "
    ],
    [
      "    5         55",
      "   5         55&",
      "555          5 &",
      "            5   ",
      "            5   ",
      "           5    ",
      "           5    ",
      "           5    ",
      "           5    ",
      "           5    ",
      "           5    ",
      "           5    ",
      "            5   ",
      "            5   ",
      "             5  ",
      "             55 "
    ],
    [
      "    5         &5",
      "   5         55&",
      "555          5  ",
      "            5   ",
      "            5   ",
      "           5    ",
      "           5    ",
      "           5    ",
      "           5    ",
      "           5    ",
      "           5    ",
      "           5    ",
      "            5   ",
      "            5   ",
      "             5  ",
      "             55 "
    ]
  ]
}