{
  "xsize": 16,
  "zsize": 16,
  "refpalette": "pomkotsmechs:factory",
  "slices": [
    [
      "vvvvvvvvvvvvvvvv",
      "vvvvvvvvvvvvvvvv",
      "vvvvvvvvvvvvvvvv",
      "vvvvvvvvvvvvvvvv",
      "vvvvvvvvvvvvvvvv",
      " vvvvvvvvvvvvvvv",
      " vvvvvvvvvvvvvvv",
      " vvvvvvvvvvvvvvv",
      " vvvvvvvvvvvvvvv",
      "vvvvvvvvvvvvvvvv",
      "vvvvvvvvvvvvvvvv",
      "vvvvvvvvvvvvvvvv",
      "vvvvvvvvvvvvvvvv",
      "vvvvvvvvvvvvvvvv",
      "vvvvvvvvvvvvvvvv",
      "vvvvvvvvvvvvvvvv"
    ],
    [
      "                ",
      "     !        ! ",
      "                ",
      "                ",
      "                ",
      "     !        ! ",
      "         &      ",
      "        &&&     ",
      "         &   && ",
      "            &&& ",
      "     !       &! ",
      "                ",
      "                ",
      "                ",
      "     !        ! ",
      "                "
    ],
    [
      "                ",
      "     !!!!!!!!!! ",
      "                ",
      "                ",
      "                ",
      "     !!!!!!!!!! ",
      "         &      ",
      "        &&&     ",
      "         &   &  ",
      "            &&& ",
      "     !!!!!!!!!! ",
      "                ",
      "                ",
      "                ",
      "     !!!!!!!!!! ",
      "                "
    ],
    [
      "     OVVVVVVVVO ",
      "     OVVVVVVVVO ",
      "     OVVVVVVVVO ",
      "     OVVVVVVVVO ",
      "     OVVVVVVVVO ",
      "     OOOOOOOOOO ",
      "         &&     ",
      "        &&&&    ",
      "         &&  &  ",
      "            &&& ",
      "     OOOOOOOOOO&",
      "     OVVVVVVVVO ",
      "     OVVVVVVVVO ",
      "     OVVVVVVVVO ",
      "     OVVVVVVVVO ",
      "     OVVVVVVVVO "
    ],
    [
      "     V        V ",
      "     V        V ",
      "     V        V ",
      "     V        V ",
      "     V        V ",
      "     OVVVVVVVVO ",
      "          &     ",
      "         &&&    ",
      "          &     ",
      "             && ",
      "     OVVVVVVVVO&",
      "     V        V ",
      "     V        V ",
      "     V        V ",
      "     V        V ",
      "     V        V "
    ],
    [
      "     V        V ",
      "     V        V ",
      "     V        V ",
      "     V        V ",
      "     V        V ",
      "     OVVVVVVVVO ",
      "         &&&    ",
      "         &&&    ",
      "          &     ",
      "              & ",
      "     OVVVVVVVVO&",
      "     V        V ",
      "     V        V ",
      "     V        V ",
      "     V        V ",
      "     V        V "
    ]
  ]
}