{
  "xsize": 16,
  "zsize": 16,
  "refpalette": "pomkotsmechs:factory",
  "slices": [
    [
      " !              ",
      "                ",
      "       OOOO     ",
      "     OO    OO   ",
      "    O        O  ",
      "    O        O  ",
      "   O          O ",
      "   O          O ",
      "   O          O ",
      "   O         &O ",
      "    O       &O& ",
      "    O       &O& ",
      "     OO&   OO&  ",
      "      &OOOO     ",
      "       &        ",
      " !              "
    ],
    [
      " !              ",
      "                ",
      "       OOOO     ",
      "     OO    OO   ",
      "    O        O  ",
      "    O        O  ",
      "   O          O ",
      "   O          O ",
      "   O          O ",
      "   O          O ",
      "    O        O  ",
      "    O       &O& ",
      "     OO&   OO&  ",
      "      &OOOO     ",
      "       &        ",
      " !              "
    ],
    [
      " !!!          !!",
      " !!            !",
      " !     OOOO     ",
      "!    OO    OO   ",
      "!   O        O  ",
      "    O        O  ",
      "   O          O ",
      "   O          O ",
      "   O          O ",
      "   O          O ",
      "    O        O  ",
      "!   O        O  ",
      "!    OO&   OO   ",
      " !    &OOOO     ",
      " !!    &       !",
      " !!!          !!"
    ],
    [
      " !              ",
      "                ",
      "       OOOO     ",
      "     OO    OO   ",
      "    O        O  ",
      "    O        O  ",
      "   O          O ",
      "   O          O ",
      "   O          O ",
      "   O          O ",
      "    O        O  ",
      "    O       &O& ",
      "     OO&   OO&  ",
      "      &OOOO     ",
      "      &&&       ",
      " !     &        "
    ],
    [
      " !              ",
      "                ",
      "       OOOO     ",
      "     OO    OO   ",
      "    O        O  ",
      "    O        O  ",
      "   O          O ",
      "   O          O ",
      "   O          O ",
      "   O          O ",
      "    O        O  ",
      "    O        O  ",
      "     OO&   OO&  ",
      "      &OOOO     ",
      "      &&&       ",
      " !     &        "
    ],
    [
      " !              ",
      "                ",
      "       OOOO     ",
      "     OO    OO   ",
      "    O        O  ",
      "    O        O  ",
      "   O          O ",
      "   O          O ",
      "   O          O ",
      "   O          O ",
      "    O        O  ",
      "    O       &O& ",
      "     OO&   OO&& ",
      "      &OOOO &&  ",
      "       &        ",
      " !              "
    ]
  ]
}