{
  "xsize": 16,
  "zsize": 16,
  "refpalette": "pomkotsmechs:factory",
  "slices": [
    [
      "                ",
      "    &           ",
      "QQQQ&&          ",
      "   &QQ          ",
      "    & QQ        ",
      "        Q       ",
      "         Q      ",
      "          Q     ",
      "           Q  ! ",
      "  &        Q  ! ",
      " &&&        Q ! ",
      "  &         Q&& ",
      "            &Q& ",
      "            &Q& ",
      "            &Q  ",
      "             Q  "
    ],
    [
      "                ",
      "                ",
      "Q   &           ",
      " QQQQ&          ",
      "    &QQ         ",
      "       QQ       ",
      "         Q      ",
      "          Q     ",
      "          Q   ! ",
      "  &        Q    ",
      " &&&       Q  ! ",
      "  &         Q   ",
      "            Q&  ",
      "           &Q&& ",
      "           &Q&  ",
      "            &Q  "
    ],
    [
      "                ",
      "    &           ",
      "   &&&          ",
      "QQQQ&&          ",
      "   &QQ          ",
      "      QQ        ",
      "        Q       ",
      "         Q      ",
      "          Q   ! ",
      "  &       Q   ! ",
      " &&&       Q  ! ",
      "  &        Q    ",
      "            Q   ",
      "            Q&  ",
      "           &Q&  ",
      "           &Q&  "
    ],
    [
      "                ",
      "    &           ",
      "   &&&          ",
      "   &&&          ",
      "QQQQQ&          ",
      "  &&&QQ         ",
      "       Q        ",
      "        Q       ",
      "         Q    ! ",
      "  &       Q     ",
      " &&&      Q   ! ",
      "  &        Q    ",
      "           Q    ",
      "           Q    ",
      "           Q&   ",
      "          &Q&&  "
    ],
    [
      "                ",
      "                ",
      "    &           ",
      "   &&           ",
      "QQ&&&           ",
      "&&QQQ           ",
      "& && QQ         ",
      "       Q        ",
      "  &     Q     ! ",
      " &&&     Q    ! ",
      " &&&     Q    ! ",
      "  &       Q     ",
      "          Q     ",
      "          Q     ",
      "           Q    ",
      "           Q&   "
    ],
    [
      "                ",
      "                ",
      "                ",
      "                ",
      "& &&            ",
      "QQ&&            ",
      "&&QQQ           ",
      "&&&& QQ         ",
      "  &   QQ      ! ",
      " &&&            ",
      "  &           ! ",
      "                ",
      "                ",
      "                ",
      "          Q     ",
      "          Q     "
    ]
  ]
}