{
  "xsize": 16,
  "zsize": 16,
  "refpalette": "pomkotsmechs:factory",
  "slices": [
    [
      "                ",
      "                ",
      "                ",
      "                ",
      "                ",
      "                ",
      "      !  !      ",
      "       !!       ",
      "       !!       ",
      "      !  !&     ",
      "          &     ",
      "          &     ",
      "           &    ",
      "           &    ",
      "            &   ",
      "            &   "
    ],
    [
      "zzVVvvvvvVvvVz|}",
      "VVVvvvvVVVVVVz|}",
      "VVvvVVzzzzzVVz|v",
      "VVVVVz|}}||zVzvv",
      "zVVVzvvv}}|zVvvv",
      "|zzzz|vvvvvvvvvv",
      "|zzzzzvvvvvvvvvv",
      "zzzzzVvvvvvvvvvv",
      "VVVVVVvvvvvvvvvv",
      "VVVVVvvvvvvvvvvv",
      "VVVVvvvV|}v}}vvv",
      "VVVVVvVz|}v}}|vv",
      "zVVVVVVz|}|v|||v",
      "zVVVVVVzzzzvzz|}",
      "zzzVVVVVVVVVvz||",
      "VVzVVVVVVvvvvVz|"
    ],
    [
      "              55",
      "&            55 ",
      "&      !!!   5  ",
      "       !!!  5   ",
      "       !!!  5   ",
      "           55   ",
      "           5    ",
      "     !!    5    ",
      "     !!  & 5    ",
      "        &&&5    ",
      "        &&&5    ",
      "         &&5&   ",
      "          &55   ",
      "          &&5&  ",
      "           &5&  ",
      "           &&5  "
    ],
    [
      "              55",
      "             55 ",
      "             5  ",
      "        !   5   ",
      "            5   ",
      "           55   ",
      "           5    ",
      "           5    ",
      "           5    ",
      "         & 5    ",
      "        &&&5    ",
      "         &&5    ",
      "          &55   ",
      "           &5   ",
      "           &5&  ",
      "           &&5& "
    ],
    [
      " 55555        55",
      " 55555       55 ",
      " !!!!!       5  ",
      " 55555  !   5   ",
      " 55555      5   ",
      " 55555     55   ",
      " 55555     5    ",
      " 55555     5    ",
      " 55555     5    ",
      " 55555   & 5    ",
      " 55555  &&&5    ",
      " 55555  &&&5    ",
      " 55555   & 55   ",
      " 55555      5   ",
      " 55555      5   ",
      " 55555      &5  "
    ],
    [
      "5     55      55",
      "5 !!! 55     55 ",
      "!!!!!!!!     5  ",
      "5     55!   5   ",
      "5     55    5   ",
      "5     55   55   ",
      "5     55   5    ",
      "5     55   5    ",
      "5     55   5    ",
      "5     55   5    ",
      "5     55 & 5    ",
      "5     55&&&5    ",
      "5     55 & 55   ",
      "5     55    5   ",
      "5     55    5   ",
      "5     55     5  "
    ]
  ]
}