{
  "xsize": 16,
  "zsize": 16,
  "refpalette": "lostcities:factory",
  "slices": [
    [
      "VVVVVVVVVVVVVVVV",
      "VVVVVVVVVVVVVVVV",
      "VVVVVVVVVVVVVVVV",
      "VVVVVVVVVVVVVVVV",
      "VVVVVVVVVVVVVVVV",
      "VVVVVVVVVVVVVVVV",
      "VVVVVVVVVVVVVVVV",
      "VVVVVVVVVVVVVVVV",
      "VVVVVVVVVVVVVVVV",
      "VVVVVVVVVVVVVVVV",
      "VVVVVVVVVVVVVVVV",
      "VVVVVVVVVVVVVVVV",
      "VVVVVVVVVVVVVVVV",
      "VVVVVVVVVVVVVVVV",
      "                ",
      "ZVVVVVVVVVVVVVVV"
    ],
    [
      " !!!!!!!!!!!!!!!",
      " !!!!!!!!!!!!!!!",
      " !!!!!!!!!!!!!!!",
      " !!!!!!!!!!!!!!!",
      " !!!!!!!!!!!!!!!",
      " !!!!!!!!!!!!!!!",
      " !!!!!!!!!!!!!!!",
      " !!!!!!!!!!!!!!!",
      " !!!!!!!!!!!!!!!",
      " !!!!!!!!!!!!!!!",
      " !!!!!!!!!!!!!!V",
      "!!!VVVVVVVVVVVVV",
      "!!!           VV",
      " !              ",
      "!!!!!!!!!!!!!!!!",
      "!!         !!  !"
    ],
    [
      " ]              ",
      " ]              ",
      " ]              ",
      " ]              ",
      " ]              ",
      " ]              ",
      " ]  &           ",
      " ] &&&          ",
      " ] &&&          ",
      " ]  &           ",
      " ]!            V",
      "!!!,,,,,,,,,,,,V",
      "!!!             ",
      " !              ",
      " !ddddddddd!!!!!",
      "$!         !!  !"
    ],
    [
      " ]              ",
      " ]              ",
      " ]              ",
      " ]              ",
      " ]              ",
      " ]              ",
      " ]  &           ",
      " ] &&&          ",
      " ] &&&          ",
      " ]  &&          ",
      " ]!            +",
      "!!!            2",
      "!!!             ",
      " !              ",
      " !ddddddddd!  !!",
      " !         !!  !"
    ],
    [
      " ]              ",
      " ]              ",
      " ]              ",
      " ]              ",
      " ]              ",
      " ]              ",
      " ]  &           ",
      " ] &&&          ",
      " ] &&&          ",
      " ] &&&&         ",
      " ]! &&         +",
      "!!!            2",
      "!!!             ",
      " !              ",
      " !ddddddddd    !",
      " !         !!  !"
    ],
    [
      " ]              ",
      " ]              ",
      " ]              ",
      " ]              ",
      " ]              ",
      " ]              ",
      " ]  &&          ",
      " ] &&&&         ",
      " ]  &&&         ",
      " ]  &&&         ",
      " ]!  &         +",
      "!!!            2",
      "!!!             ",
      " !              ",
      " !dddddddd      ",
      "$!         !   !"
    ]
  ]
}