{
  "xsize": 16,
  "zsize": 16,
  "refpalette": "pomkotsmechs:factory",
  "slices": [
    [
      "     V        V ",
      "     V        V ",
      "     V        V ",
      "     V        V ",
      "     O        O ",
      "    &V        V ",
      "   &&V        V ",
      "   &&V        V ",
      "    &V       &V&",
      "     V        V ",
      "     V        V ",
      "     V        V ",
      "     V        V ",
      "     V        V ",
      "     OVVVVVVVVO ",
      "                "
    ],
    [
      "     V        V ",
      "     V        V ",
      "     V        V ",
      "     V        V ",
      "     O        O ",
      "     V        V ",
      "    &V        V ",
      "   &&V        V ",
      "    &V       &V&",
      "     V       &V&",
      "     V        V ",
      "     V        V ",
      "     V        V ",
      "     V        V ",
      "     OVVVVVVVVO ",
      "                "
    ],
    [
      "     V        V ",
      "     V        V ",
      "     V        V ",
      "     V        V ",
      "     O        O ",
      "     V        V ",
      "    &V        V ",
      "   &&V        V ",
      "   &&V        V ",
      "    &V       &V&",
      "     V        V ",
      "     V        V ",
      "     V        V ",
      "     V        V ",
      "     OVVVVVVVVO ",
      "                "
    ],
    [
      "     V        V ",
      "     V        V ",
      "     V        V ",
      "     V        V ",
      "     O        O ",
      "     V        V ",
      "     V        V ",
      "    &V        V ",
      "   &&V        V ",
      "    &V       &V&",
      "     V        V ",
      "     V        V ",
      "     V        V ",
      "     V        V ",
      "     OVVVVVVVVO ",
      "                "
    ],
    [
      "     OVVVVVVVVO ",
      "     OVVVVVVVVO ",
      "     OVVVVVVVVO ",
      "     OVVVVVVVVO ",
      "     OOOOOOOOOO ",
      "     OVVVVVVVVO ",
      "     OVVVVVVVVO ",
      "    &OVVVVVVVVO ",
      "   &&OVVVVVVVVO ",
      "   &&OVVVVVVVVO&",
      "    &OVVVVVVVVO ",
      "     OVVVVVVVVO ",
      "     OVVVVVVVVO ",
      "     OVVVVVVVVO ",
      "     OOOOOOOOOO ",
      "                "
    ],
    [
      "                ",
      "                ",
      "     !        ! ",
      "                ",
      "                ",
      "                ",
      "     !        ! ",
      "                ",
      "    &&        & ",
      "    &&&      &&&",
      "     !       &!&",
      "              & ",
      "                ",
      "                ",
      "     !        ! ",
      "                "
    ]
  ]
}