{
  "xsize": 16,
  "zsize": 16,
  "refpalette": "lostcities:factory",
  "slices": [
    [
      "                ",
      "                ",
      "                ",
      "            VVVV",
      "          VVVʹʹʹ",
      "        VVʹʹʹʹʹʹ",
      "       VVʹʹʹʹʹʹʹ",
      "      VVʹʹʹʹʹʹʹʹ",
      "     VVʹʹʹʹʹʹʹʹʹ",
      "     Vʹʹʹʹʹʹʹʹʹʹ",
      "    Vʹʹʹʹʹʹʹʹʹʹʹ",
      "    Vʹʹʹʹʹʹʹʹʹʹʹ",
      "   VVʹʹʹʹʹʹʹʹʹʹʹ",
      "   Vʹʹʹʹʹʹʹʹʹʹʹʹ",
      "   Vʹʹʹʹʹʹʹʹʹʹʹʹ",
      "   Vʹʹʹʹʹʹʹʹʹʹʹʹ"
    ],
    [
      "                ",
      "                ",
      "                ",
      "            VVVV",
      "          VVV  V",
      "        VV     V",
      "       VV      V",
      "      VV       V",
      "     VV        V",
      "     V         V",
      "    V          V",
      "    V          V",
      "   VV          V",
      "   V           V",
      "   V           V",
      "   V          VV"
    ],
    [
      "                ",
      "                ",
      "                ",
      "            VVVV",
      "          VVV   ",
      "        VV      ",
      "       VV       ",
      "      VV        ",
      "     VV         ",
      "     V          ",
      "    V           ",
      "    V           ",
      "   VV           ",
      "   V            ",
      "   V            ",
      "   V            "
    ],
    [
      "                ",
      "                ",
      "                ",
      "               &",
      "                ",
      "                ",
      "                ",
      "                ",
      "                ",
      "                ",
      "                ",
      "                ",
      "                ",
      "                ",
      "                ",
      "                "
    ],
    [
      "                ",
      "                ",
      "                ",
      "                ",
      "                ",
      "                ",
      "                ",
      "                ",
      "                ",
      "                ",
      "                ",
      "                ",
      "                ",
      "                ",
      "                ",
      "                "
    ],
    [
      "                ",
      "                ",
      "                ",
      "                ",
      "                ",
      "                ",
      "                ",
      "                ",
      "                ",
      "                ",
      "                ",
      "                ",
      "                ",
      "                ",
      "                ",
      "                "
    ]
  ]
}