{
  "xsize": 16,
  "zsize": 16,
  "refpalette": "pomkotsmechs:factory",
  "slices": [
    [
      "!           !!! ",
      "           !!!!!",
      "            !!! ",
      "   !  !      !  ",
      "    rr      &J& ",
      "    rr       J  ",
      "   !  !      J  ",
      "             J! ",
      "             J  ",
      "             J  ",
      "             J  ",
      " !   &       !  ",
      "!!  &&&     !!  ",
      "!!! &&&  JJ!!!! ",
      "!!   &      !!  ",
      " !           !  "
    ],
    [
      "!          !!!!!",
      "           !!!!!",
      "            !!! ",
      "   !  !      !  ",
      "    rr      &!& ",
      "    rr       !  ",
      "   !  !      !  ",
      "             !! ",
      "             !  ",
      "             !  ",
      "             !  ",
      "!!           !  ",
      "!!   &      !!  ",
      "!!  &&&  !!!!!  ",
      "!!   &      !!  ",
      "!!              "
    ],
    [
      "!        &&!!!!!",
      "           !!!!!",
      "            !!! ",
      "   !  !     &!& ",
      "    rr      &J& ",
      "    rr       J  ",
      "   !  !         ",
      "             J  ",
      "                ",
      "  &&         J  ",
      "   &            ",
      "!! &&           ",
      "!!  &&      !   ",
      "!!  JJ&  JJ  !  ",
      "!!   &          ",
      "!!              "
    ],
    [
      "!     !!!!!!!!!!",
      "      !!!!!!!!!!",
      "      !!!!!!!!! ",
      "   !  !!!!!!!!& ",
      "    rr    !!!J  ",
      "    rr          ",
      "!!!!  !!        ",
      "!!!!!!!!        ",
      "!!!!!!!!        ",
      "!!!!!!!!        ",
      "!!!!!!!!!       ",
      "!!!!!!!!!!      ",
      "!!!!!!!!!!!     ",
      "!!!!JJJJJJJ     ",
      "!!  && !        ",
      "!!              "
    ],
    [
      "!!!!!!!!!&&!!!!!",
      "!!!!!!!!!&&!!!!!",
      "!!!!!!  ! &&!!! ",
      "!!!!!      &&&  ",
      "!!!!!       &   ",
      "!!!!!           ",
      "!!!!!!          ",
      "!!!!!!!         ",
      "!!!!!!!         ",
      " &&&            ",
      "  &&            ",
      "!! &&           ",
      "!!! &&          ",
      "!!!!!!!!!!      ",
      "!!! && !        ",
      "!!              "
    ],
    [
      "!!    &&&&&!!!!!",
      "!       &&&! !!!",
      "          &&!!! ",
      "   !       &&   ",
      "    r           ",
      "&   r           ",
      "&& !            ",
      "&&              ",
      "&&&             ",
      " &&             ",
      "                ",
      "!!              ",
      "!!!             ",
      "!!!!&&          ",
      "!!!    !        ",
      "!!              "
    ]
  ]
}