{
  "xsize": 16,
  "zsize": 16,
  "refpalette": "lostcities:factory",
  "slices": [
    [
      "                ",
      "                ",
      "                ",
      "                ",
      "                ",
      "                ",
      "      !  !      ",
      "       !!       ",
      "       !!       ",
      "      !  !      ",
      "                ",
      "                ",
      "                ",
      "                ",
      "                ",
      "                "
    ],
    [
      "                ",
      "                ",
      "vvvvvzzzz||vv   ",
      "|v|zVVVVVz|}v   ",
      "||zzVVVVVz|}}   ",
      "zzVVVVVVzz|||   ",
      "VVVvvVvzz||||   ",
      "VvvvvVz|||zzz   ",
      "VvvvvVz|||zVV   ",
      "VvvvVz||||zVV   ",
      "VvvVVz||||zzz   ",
      "VVVVz|||zz|||   ",
      "VVVz|||zzz||}   ",
      "VVVz|||zVz||}   ",
      "VVVVz|zzVVz||   ",
      "vvvVVzzzVVzzz   "
    ],
    [
      "                ",
      "                ",
      "                ",
      "                ",
      "                ",
      "      !!        ",
      "      !!        ",
      "                ",
      "                ",
      "                ",
      " 555            ",
      "5   5           ",
      "     5          ",
      "     5          ",
      "     5          ",
      "5   5           "
    ],
    [
      "                ",
      "                ",
      "                ",
      "                ",
      "                ",
      "                ",
      "                ",
      "                ",
      "                ",
      "                ",
      " 555            ",
      "5   5           ",
      "     55         ",
      "     55         ",
      "     55         ",
      "5   5           "
    ],
    [
      "                ",
      "                ",
      "                ",
      "                ",
      "                ",
      "                ",
      "                ",
      "                ",
      "                ",
      "                ",
      " 555            ",
      "5   5           ",
      "     5          ",
      "     5          ",
      "     5          ",
      "5   5           "
    ],
    [
      "                ",
      "                ",
      "                ",
      "                ",
      "                ",
      "                ",
      "                ",
      "                ",
      "                ",
      "                ",
      " 555            ",
      "5   5           ",
      "     5          ",
      "     5          ",
      "     5          ",
      "5   5           "
    ]
  ]
}