{
  "xsize": 16,
  "zsize": 16,
  "refpalette": "pomkotsmechs:factory",
  "slices": [
    [
      "5555555555555&  ",
      "5555555555555   ",
      "5555555555555   ",
      "5555555555555   ",
      "55555     &55   ",
      "  555555555555  ",
      "    55555555&   ",
      "                ",
      "                ",
      "                ",
      "                ",
      "                ",
      "                ",
      "                ",
      "                ",
      "                "
    ],
    [
      "  JJ      &JJ&  ",
      "          &&&   ",
      "5         &&    ",
      "55        &&&   ",
      "  555     &55&  ",
      "    55555555&&  ",
      "           &&&  ",
      "            &   ",
      "                ",
      "                ",
      "                ",
      "                ",
      "                ",
      "                ",
      "                ",
      "                "
    ],
    [
      "  ͱͱ      &ͱͱ&& ",
      "           &&&  ",
      "5               ",
      "55         &&   ",
      "  555      555  ",
      "    55555555&&  ",
      "           &&&  ",
      "            &   ",
      "                ",
      "                ",
      "                ",
      "                ",
      "                ",
      "                ",
      "                ",
      "                "
    ],
    [
      "  ͱͱ       ͱͱ&  ",
      "            &   ",
      "5               ",
      "55          &&5 ",
      "  555      555& ",
      "    55555555&&& ",
      "            &&  ",
      "                ",
      "                ",
      "                ",
      "                ",
      "                ",
      "                ",
      "                ",
      "                ",
      "                "
    ],
    [
      "  ͱͱ       ͱͱ   ",
      "                ",
      "                ",
      "                ",
      "            &&  ",
      "            &&  ",
      "                ",
      "                ",
      "                ",
      "                ",
      "                ",
      "                ",
      "                ",
      "                ",
      "                ",
      "                "
    ],
    [
      "  ͱͱ       ͱͱ   ",
      "                ",
      "                ",
      "                ",
      "                ",
      "                ",
      "                ",
      "                ",
      "                ",
      "                ",
      "                ",
      "                ",
      "                ",
      "                ",
      "                ",
      "                "
    ]
  ]
}