{
  "xsize": 16,
  "zsize": 16,
  "refpalette": "pomkotsmechs:factory",
  "slices": [
    [
      "  !XXXXXXXXXXXXX",
      "  !XXXXXXXXXXXXX",
      "  !XXXXXXXXXXXXX",
      "  !XXXXXXXXXXXXX",
      "   !XXXXXXXXXXXX",
      "  !!XXXXXXXXXXXX",
      "    !XXXXXXXXXXX",
      "    !XXXXXXXXXXX",
      "    &!XXXXXXXXXX",
      "    &!!XXXXXXXXX",
      "     & !XXXXXXXX",
      "        !!XXXXXX",
      "          !!XXXX",
      "          ! !!!!",
      "                ",
      "                "
    ],
    [
      "   X            ",
      "   X            ",
      "   X            ",
      "   X            ",
      "    X           ",
      "  ! X           ",
      "     X          ",
      "     X          ",
      "    &&X         ",
      "    &!&X        ",
      "     &  XX      ",
      "          XX    ",
      "            XXXX",
      "          !     ",
      "                ",
      "                "
    ],
    [
      "   X            ",
      "   X            ",
      "   X            ",
      "   X            ",
      "    X           ",
      "  ! X           ",
      "     X          ",
      "     X          ",
      "    &&X         ",
      "    &!&X        ",
      "     &  XX      ",
      "          XX    ",
      "            XXXX",
      "          !     ",
      "                ",
      "                "
    ],
    [
      "   X            ",
      "   X            ",
      "   X            ",
      "   X            ",
      "    X           ",
      "  ! X           ",
      "     X          ",
      "    &X&         ",
      "    &&X         ",
      "     ! X        ",
      "        XX      ",
      "          XX    ",
      "            XXXX",
      "          !     ",
      "                ",
      "                "
    ],
    [
      "   X            ",
      "   X            ",
      "   X            ",
      "   X            ",
      "    X           ",
      "  ! X           ",
      "     X          ",
      "    &X&         ",
      "     &X         ",
      "     ! X        ",
      "        XX      ",
      "          XX    ",
      "            XXXX",
      "          !     ",
      "                ",
      "                "
    ],
    [
      "   X            ",
      "   X            ",
      "   X            ",
      "   X            ",
      "    X           ",
      "  ! X           ",
      "     X          ",
      "    &X&         ",
      "     &X         ",
      "     ! X        ",
      "        XX      ",
      "          XX    ",
      "            XXXX",
      "          !     ",
      "                ",
      "                "
    ]
  ]
}