{
  "xsize": 16,
  "zsize": 16,
  "refpalette": "lostcities:factory",
  "slices": [
    [
      "VVVVVVVVVVVVVVVV",
      "VVVVVVVVVVVVVVVV",
      "VVVVVVVVVVVVVVVV",
      "VVVVVVVVVVVVVVVV",
      "VVVVVVVVVVVVVVVV",
      "VVVVVVVVVVVVVVVV",
      "VVVVVVVVVVVVVVVV",
      "VVVVVVVVVVVVVVVV",
      "VVVVVVVVVVVVVVVV",
      "VVVVVVVVVVVVVVVV",
      "VVVVVVVVVVVVVVVV",
      "VVVVVVVVVVVVVVVV",
      "VVVVVVVVVVVVVVVV",
      "VVVVVVVVVVVVVVVV",
      "VVVVVVVVVVVVVVVV",
      "VVVVVVVVVVVVVVVV"
    ],
    [
      "!!  !!        !!",
      "!!!!!!!!!!!!!!!!",
      "!!  !!!!!!!!!!!!",
      "VV           !!!",
      "VVVVVVVVVVVVV!!!",
      "V!!!!!!!!!!!!!! ",
      "!!!!!!!!!!!!!!! ",
      "!!!!!!!!!!!!!!! ",
      "!!!!!!!!!!!!!!! ",
      "!!!!!!!!!!!!!!! ",
      "!!!!!!!!!!!!!!! ",
      "!!!!!!!!!!!!!!! ",
      "!!!!!!!!!!!!!!! ",
      "!!!!!!!!!!!!!!! ",
      "!!!!!!!!!!!!!!! ",
      "!!!!!!!!!!!!!!! "
    ],
    [
      "!!  !!        !$",
      "!!!!!![[[[[[[[! ",
      "!!  !!!       ! ",
      "             !!!",
      "V,,,,,,,,,,,,!!!",
      "V            !i ",
      " JJJJJJJJJJJJ i ",
      " JJJJJJJJJJJJ i ",
      " JJJJJJJJJJJJ i ",
      " JJJJJJJJJJJJ i ",
      " JJJJJJJJJJJJ i ",
      " JJJJJJJJJJJJ i ",
      "&JJJJJJJJJJJJ i ",
      "&JJJJJJJJJJJJ i ",
      "&JJJJJJJJJJJJ i ",
      " JJJJJJJJJJJJ i "
    ],
    [
      "!!  !!        ! ",
      "!!!!!![[[[[[[[! ",
      "!!  !!!       ! ",
      "             !!!",
      "/            !!!",
      "3            !i ",
      " JJJJJJJJJJJJ i ",
      " J          J i ",
      " J          J i ",
      " J          J i ",
      " J          J i ",
      " J          J i ",
      "&J          J i ",
      "&J          J i ",
      "&J          J i ",
      " J          J i "
    ],
    [
      "!!  !!        ! ",
      "!!!!!![[[[[[[[! ",
      "!!  !!!       ! ",
      "             !!!",
      "/            !!!",
      "3            !i ",
      " JJJJJJJJJJJJ i ",
      " J          J i ",
      " J          J i ",
      " J          J i ",
      " J          J i ",
      " J          J i ",
      "&J          J i ",
      "&J          J i ",
      "&J          J i ",
      " J          J i "
    ],
    [
      "!!  !!        !$",
      "!!!!!![[[[[[[[! ",
      "!!  !!!       ! ",
      "             !!!",
      "/            !!!",
      "3            !i ",
      " JJJJJJJJJJJJ i ",
      " J          J i ",
      " J          J i ",
      " J          J i ",
      " J          J i ",
      " J          J i ",
      " J          J i ",
      "&J          J i ",
      "&J          J i ",
      " J          J i "
    ]
  ]
}