{
  "xsize": 16,
  "zsize": 16,
  "refpalette": "pomkotsmechs:factory",
  "slices": [
    [
      "   V        V   ",
      "   V       &V&  ",
      "   V        V   ",
      "   V            ",
      "   V            ",
      "   OVVVVVV  O   ",
      "                ",
      "                ",
      "                ",
      "          &     ",
      "   OVVVVVVVVO   ",
      "   V      & V   ",
      "   V        V   ",
      "   V        V   ",
      "   V        V   ",
      "  &V&       V   "
    ],
    [
      "   V   &&&&&V&  ",
      "   V       &V&  ",
      "   V        &   ",
      "   V            ",
      "   V            ",
      "   OVVVVV       ",
      "                ",
      "                ",
      "                ",
      "          &     ",
      "   OVVVVVVVVO   ",
      "   V     && V   ",
      "   V    &&  V   ",
      "   V    &   V   ",
      "   V    &   V   ",
      "  &V&&&&&   V   "
    ],
    [
      "   OVVVVVVVVO&  ",
      "   OVVVVVVV&O   ",
      "   OVVVVV       ",
      "   OVVVV        ",
      "   OVVVV        ",
      "   OOOOOO       ",
      "                ",
      "                ",
      "                ",
      "         &&     ",
      "   OOOOOOOOOO   ",
      "   OVVVVVVVVO   ",
      "   OVVVVVVVVO   ",
      "   OVVVVVVVVO   ",
      "   OVVVVVVVVO   ",
      "  &OVVVVVVVVO   "
    ],
    [
      "       &&&&&&   ",
      "                ",
      "                ",
      "                ",
      "                ",
      "                ",
      "                ",
      "                ",
      "                ",
      "                ",
      "         &&     ",
      "         &      ",
      "        &&      ",
      "        &       ",
      "      &&&&      ",
      "   &&&&&&&      "
    ],
    [
      "                ",
      "                ",
      "                ",
      "                ",
      "                ",
      "                ",
      "                ",
      "                ",
      "                ",
      "                ",
      "                ",
      "                ",
      "                ",
      "                ",
      "        &       ",
      "      &&&       "
    ],
    [
      "                ",
      "                ",
      "                ",
      "                ",
      "                ",
      "                ",
      "                ",
      "                ",
      "                ",
      "                ",
      "                ",
      "                ",
      "                ",
      "                ",
      "                ",
      "                "
    ]
  ]
}