{
  "xsize": 16,
  "zsize": 16,
  "refpalette": "pomkotsmechs:factory",
  "slices": [
    [
      "vvvvvvvvvvvvvvvv",
      "vvvvvvvvvvvvvvvv",
      "vvvvvvvvvvvvvvvv",
      "vvvvvvvvvvvvvvvv",
      "vvvvvvvvvvvvvvvv",
      "vvvvvvvvvvv!!vvv",
      "vvvvvvvvvvv!!vvv",
      "vvvvvvvvvvvvvvvv",
      "vvvvvvvvvvvvvvvv",
      "vvvvvvvvvvvvvvvv",
      "vvvvvvvvvvvvvvvv",
      "vvvvv!!vvvvvvvvv",
      "vvvvv!!vvvvvvvvv",
      "vvvvvvvvvvvvvvvv",
      "vvvvvvvvvvvvvvvv",
      "vvvvvvvvvvvvvvvv"
    ],
    [
      "                ",
      "                ",
      "                ",
      "                ",
      "                ",
      "           !!   ",
      "           !!   ",
      "                ",
      "                ",
      "                ",
      "                ",
      "     !!         ",
      "     !!         ",
      "                ",
      "                ",
      "                "
    ],
    [
      "                ",
      "                ",
      "                ",
      "                ",
      "                ",
      "           !!   ",
      "           !!   ",
      "                ",
      "                ",
      "                ",
      "                ",
      "     !!         ",
      "     !!         ",
      "                ",
      "                ",
      "                "
    ],
    [
      "                ",
      "   &&           ",
      "                ",
      "                ",
      "                ",
      "           !!   ",
      "           !!   ",
      "                ",
      "                ",
      "                ",
      "                ",
      "     !!         ",
      "     !!         ",
      "                ",
      "                ",
      "                "
    ],
    [
      "QQQQ&       !   ",
      "QQQQ&&      !   ",
      "QQQ&&       !   ",
      "QQ &       !!   ",
      "           !    ",
      "           !!   ",
      "          !!!   ",
      "         !!     ",
      "        !!      ",
      "       !!       ",
      "      !!        ",
      "   !!!!         ",
      "!!!! !!         ",
      "                ",
      "                ",
      "                "
    ],
    [
      "   &QQQ     !   ",
      "  &&QQ      !   ",
      "  &QQQ      !   ",
      "  QQQQ     !!   ",
      "QQQQQ      !    ",
      "QQQQ       !!   ",
      "Q         !!!   ",
      "         !!     ",
      "        !!      ",
      "       !!       ",
      "      !!        ",
      "   !!!!         ",
      "!!!! !!         ",
      "                ",
      "                ",
      "                "
    ]
  ]
}