{
  "xsize": 16,
  "zsize": 16,
  "refpalette": "lostcities:factory",
  "slices": [
    [
      "!!! OOOOO JJJ   ",
      " !  OOOOO JJJJJJ",
      " !  OOOOO JJJJJJ",
      "          JJJJJJ",
      "          JJJJJJ",
      " !! OOOOO JJJJJJ",
      " !! OOOOO       ",
      " !! OOOOO       ",
      " !!&OOOOO       ",
      " !! OOOOO       ",
      "!!!             ",
      "!!!             ",
      "!!!        +/   ",
      "!!!        23   ",
      "!!!             ",
      " !!             "
    ],
    [
      "!!!             ",
      "!!!             ",
      "!!! $   $       ",
      " !!             ",
      " !!             ",
      " !! $   $       ",
      " !!             ",
      " !!&&           ",
      "  !&&&          ",
      "    $   $       ",
      " !!             ",
      "!!!             ",
      "!!!        +/   ",
      "!!!        23   ",
      "!!!             ",
      " !!             "
    ],
    [
      " ]! OOOOO       ",
      " ]  OOOOO       ",
      " ]  OOOOO       ",
      " ]              ",
      " ]!             ",
      " ]  OOOOO       ",
      "   &OOOOO       ",
      "  &&OOOOO       ",
      "   &OOOOO       ",
      "    OOOOO       ",
      "                ",
      " ]!             ",
      "!!!        +/   ",
      "!!!        23   ",
      "!!!             ",
      " !              "
    ],
    [
      "  ! V <<V       ",
      "    VV<<V       ",
      "    OVVVO       ",
      "                ",
      "  !             ",
      "    OVVVO       ",
      "   &V   V       ",
      "  &&V <<V       ",
      "   &VV<<V       ",
      "    OVVVO       ",
      "                ",
      "  !             ",
      "!!!        VV   ",
      "!!!        VV   ",
      "!!!             ",
      "                "
    ],
    [
      "  ! V   V      V",
      "  V VVVVV      V",
      "  V OVVVO   &  V",
      "  V      &&&&  V",
      "  !     &&     V",
      "  V OVVVO      V",
      "  V&V   V       ",
      "  &&V   V       ",
      "   &VVVVV       ",
      "    OVVVO       ",
      "                ",
      "  !       VVVV  ",
      "!!VVVVVVVVVnnV  ",
      "!!!VVVVVVVVnnV  ",
      "!!!       VVVV  ",
      "  V             "
    ],
    [
      "!!!!VOOOV!rrrrr!",
      "!!!!VOOOV!rrrrr!",
      "!!!!OVVVO!rrrrr!",
      "!!!!rrrrr!rrrrr!",
      "!!!!rrrrr!rrrrr!",
      "!!!!OVVVO!rrrrr!",
      "!!!!VOOOV!rrrrr!",
      "  &!VOOOV!rrrrr!",
      "   !VOOOV!rrrrr!",
      "   !OVVVO!rrrrr!",
      "!!!!rrrrr!rrrrr!",
      "!!!!!!!!!!!!!!!!",
      "!!!!!!!!!!!!!!!!",
      "!!!!!!!!!!!!!!!!",
      "!!!!!!!!!!!!!!!!",
      "!!!rrrrrrrrrrrrr"
    ]
  ]
}