{
  "xsize": 16,
  "zsize": 16,
  "refpalette": "lostcities:factory",
  "slices": [
    [
      "             !!!",
      "             !!!",
      "             !!!",
      "             !!!",
      "             !!!",
      "             !!!",
      "             !!!",
      "             !!!",
      "             !!!",
      "             !!!",
      "             !!!",
      "             !!!",
      "    +/       !!!",
      "    23       !!!",
      "             !!!",
      "             !! "
    ],
    [
      "             !!!",
      "             !!!",
      "             !!!",
      "             !!!",
      "             !!!",
      "             !!!",
      "             !!!",
      "             !!!",
      "             !!!",
      "             !!!",
      "             !!!",
      "             !!!",
      "    +/       !!!",
      "    23       !!!",
      "             !!!",
      "             !! "
    ],
    [
      "             !i ",
      "              i ",
      "              i ",
      "              i ",
      "             !i ",
      "              i ",
      "              i ",
      "              i ",
      "             !i&",
      "             &i&",
      "              i&",
      "             !i ",
      "    +/       !!!",
      "    23       !!!",
      "             !!!",
      "              ! "
    ],
    [
      "             !  ",
      "                ",
      "                ",
      "                ",
      "             !  ",
      "                ",
      "                ",
      "                ",
      "             !&&",
      "             &&&",
      "              & ",
      "             !  ",
      "    VV       !!!",
      "    VV       !!!",
      "             !!!",
      "                "
    ],
    [
      "V            !  ",
      "V            V  ",
      "V            V  ",
      "V        &   V  ",
      "V            !  ",
      "V            V  ",
      "          && V  ",
      "           & V &",
      "             V&&",
      "             V&&",
      "             V&&",
      "   VVVV     &!  ",
      "   VnnVVVVVVVV!!",
      "   VnnVVVVVVV!!!",
      "   VVVV      !!!",
      "             V  "
    ],
    [
      "!!rrrrrrrrrr!!!!",
      "!!rrrrrrrrrr!!!!",
      "!!rrrrrrrrrr!!!!",
      "!!rrrrrrrrrr!!!!",
      "!!rrrrrrrrrr!!!!",
      "!!rrrrrrrrrr!!!!",
      "!!rrrrrrrrrr!!!!",
      "!!rrrrrrrrrr!!!!",
      "!!rrrrrrrrrr!!!!",
      "!!rrrrrrrrrr!!!!",
      "!!rrrrrrrrrr!!!!",
      "!!!!!!!!!!!!!!!!",
      "!!!!!!!!!!!!!!!!",
      "!!!!!!!!!!!!!!!!",
      "!!!!!!!!!!!!!!!!",
      "rrrrrrrrrrrrr!!!"
    ]
  ]
}