{
  "xsize": 16,
  "zsize": 16,
  "refpalette": "pomkotsmechs:factory",
  "slices": [
    [
      "              i ",
      "              i ",
      "              i ",
      "/            !i ",
      "3            !!!",
      "             !!!",
      "              ! ",
      "              ! ",
      "             !!!",
      "/            !!!",
      "3            !i ",
      "              i ",
      " OVVVO OVVVO  i ",
      " VOOOV VOOOV  i ",
      " VOOOV VOOOV  i ",
      "&VOOOV VOOOV  i "
    ],
    [
      "              i ",
      "              i ",
      "              i ",
      "/            !i ",
      "3            !!!",
      "             !!!",
      "              ! ",
      "              ! ",
      "             !!!",
      "/            !!!",
      "3            !i ",
      "              i ",
      " OOOOO OOOOO  i ",
      " OOOOO OOOOO  i ",
      " OOOOO OOOOO  i ",
      " OOOOO OOOOO  i "
    ],
    [
      "              i ",
      "              i ",
      "              i ",
      "/            !i ",
      "3            !!!",
      "             !!!",
      "              ! ",
      "              ! ",
      "             !!!",
      "/            !!!",
      "3            !i ",
      "              i ",
      " $   $ $   $  i ",
      "              i ",
      "              i ",
      "              i "
    ],
    [
      "              i ",
      "              i ",
      "              i ",
      "/            !i ",
      "3            !!!",
      "             !!!",
      "              ! ",
      "              ! ",
      "             !!!",
      "/            !!!",
      "3            !i ",
      "              i ",
      " OOOOO OOOOO  i ",
      " OOOOO OOOOO  i ",
      " OOOOO OOOOO  i ",
      " OOOOO OOOOO  i "
    ],
    [
      "              i ",
      "              i ",
      "              i ",
      "/            !i ",
      "3            !!!",
      "             !!!",
      "              ! ",
      "              ! ",
      "             !!!",
      "/            !!!",
      "3            !i ",
      "              i ",
      " OVVVO OVVVO  i ",
      " V   V V   V  i ",
      " V <<V V <<V  i ",
      " VV<<V VV<<V  i "
    ],
    [
      "              i ",
      "              i ",
      "              i ",
      "V            !i ",
      "V            !!!",
      "             !!!",
      "              ! ",
      "              ! ",
      "             !!!",
      "V            !!!",
      "V            !i ",
      "              i ",
      " OVVVO OVVVO  i ",
      " V   V V   V  i ",
      " V   V V   V  i ",
      " VVVVV VVVVV  i "
    ]
  ]
}