{
  "xsize": 16,
  "zsize": 16,
  "refpalette": "pomkotsmechs:factory",
  "slices": [
    [
      "VVV!!!!!!!!!!VVV",
      "VVV!!!!!!!!!!VVV",
      "VVV!!!!!!!!!!VVV",
      "VVV!!!!!!!!!!VVV",
      "VVV!!!!!!!!!!VVV",
      "VVV!!!!!!!!!!VVV",
      "VVV!!!!!!!!!!VVV",
      "VVV!!!!!!!!!!VVV",
      "VVV!!!!!!!!!!VVV",
      "VVV!!!!!!!!!!VVV",
      "VVV!!!!!!!!!!VVV",
      "V!!!!!!!!!!!!!!!",
      "V!!!!!!!!!!!!!!!",
      "V!!!!!!!!!!!!!!!",
      "V!!!!!!!!!!!!!!!",
      "V!!!!!!!!!!!!!!!"
    ],
    [
      "!               ",
      "!!!!!!!!!!!!!!!!",
      "!!!!!!!!!!!!!!!!",
      "VV            VV",
      "VV            VV",
      "VV            VV",
      "VV            VV",
      "V              V",
      "V              V",
      "V              V",
      "V&&            V",
      "e&&            f",
      "e&             f",
      "e              f",
      "e             &f",
      "e            &&f"
    ],
    [
      "!               ",
      "!               ",
      "!!             !",
      "                ",
      "V              V",
      "V              V",
      "                ",
      "5               ",
      "5               ",
      "5               ",
      "                ",
      "&&              ",
      "&               ",
      "               &",
      "              &&",
      "              &&"
    ],
    [
      "!               ",
      "!               ",
      "!!             !",
      "                ",
      "/              +",
      "3              2",
      "                ",
      "                ",
      "                ",
      "                ",
      "                ",
      "                ",
      "               &",
      "              &&",
      "              &&",
      "               &"
    ],
    [
      "!               ",
      "!               ",
      "!!             !",
      "                ",
      "/              +",
      "3              2",
      "                ",
      "                ",
      "                ",
      "                ",
      "                ",
      "                ",
      "               &",
      "              &&",
      "             &&&",
      "              &&"
    ],
    [
      "!               ",
      "!               ",
      "!!             !",
      "                ",
      "/              +",
      "3              2",
      "                ",
      "                ",
      "                ",
      "                ",
      "                ",
      "                ",
      "               &",
      "              &&",
      "             &&&",
      "              &&"
    ]
  ]
}