{
  "xsize": 16,
  "zsize": 16,
  "refpalette": "pomkotsmechs:factory",
  "slices": [
    [
      " !!!         !!!",
      "!!!!!           ",
      " !!!            ",
      "  !    !  !     ",
      "  J     rr      ",
      "        rr      ",
      "  &    !  !     ",
      " &&&            ",
      "  &             ",
      "                ",
      "  J             ",
      "  !           ! ",
      " !!!     &   !! ",
      "!!!!!JJJJJJJ!!!!",
      " !!!    !&   !!!",
      "  !           ! "
    ],
    [
      " !!!         !!!",
      "!!!!!           ",
      " !!!            ",
      "  !    !  !     ",
      "  !     rr      ",
      "        rr      ",
      "  &    !  !     ",
      " &&&            ",
      "  &             ",
      "                ",
      "  !             ",
      "  !             ",
      " !!!     &   !! ",
      "!!!!!!!!!!!!!!! ",
      " !!!    !&   !! ",
      "  !           ! "
    ],
    [
      " !!!         !!!",
      "!!!!!           ",
      "  !             ",
      "  !    !  !     ",
      "        rr      ",
      "  &     rr      ",
      " &&&   !  !     ",
      " &&&            ",
      "  &             ",
      "                ",
      "                ",
      "  !             ",
      " !!!     &   !! ",
      "!!!!!JJJJJJJ!!! ",
      " !!!    !&   !! ",
      "  !             "
    ],
    [
      " !!!         !!!",
      "!!!!!           ",
      "  !             ",
      "  !    !  !     ",
      "        rr      ",
      "  &     rr      ",
      " &&&   !  !     ",
      "  &             ",
      "                ",
      "                ",
      "                ",
      "  !           ! ",
      " !!!     &&  !! ",
      "!!!!!JJJJJJJ!!! ",
      " !!!    !&&     ",
      "  !             "
    ],
    [
      "!!!!!        !!!",
      "!!!!!           ",
      "!!!!!           ",
      "  !    !  !     ",
      "        rr      ",
      "  &     rr      ",
      " &&&   !  !     ",
      "  &             ",
      "                ",
      "                ",
      "                ",
      "  !          !!!",
      "!!!!!     & !!!!",
      "!!!!!!!!!!!!!!!!",
      "!!!!!   ! &   ! ",
      " !!!            "
    ],
    [
      " !!!         !!!",
      "!!!!!           ",
      " !!!            ",
      "  !    !JJ!     ",
      "  J    JrrJ     ",
      "  &    JrrJ     ",
      " &&&   !JJ!     ",
      "  &             ",
      "                ",
      "                ",
      "                ",
      "  !           ! ",
      " !!!      &  !!!",
      "!!!!!JJJJJJJ!!!!",
      " !!!    ! &     ",
      "  !             "
    ]
  ]
}