{
  "xsize": 16,
  "zsize": 16,
  "refpalette": "pomkotsmechs:factory",
  "slices": [
    [
      "vvvvvvvvvvvvvvvv",
      "vvvvvvvvvvvvvvvv",
      "vvvvOOvvvvvvOOvv",
      "vvvOvvOvvvvOvvOv",
      "vvvOvvOvvvvOvvOv",
      "vvvvOOvvvvvvOOvv",
      "vvvvvvvvvvvvvvvv",
      "vvvvvvvvvvvvvvvv",
      "vvvvvvvvvvvvvvvv",
      "vvvvvvvvvvvvvvvv",
      "vvvvvvvvvvvvvvvv",
      "vvvvvvvvvvvvvvvv",
      "vvvvvvvvvvvvvvvv",
      "vvvvvvvvvvvvvvvv",
      "vvvvvvvvvvvvvvvv",
      "vvvvvvvvvvvvvvvv"
    ],
    [
      "                ",
      "                ",
      "    OO      OO  ",
      "  &O  O    O  O ",
      " &&O& O    O  O ",
      "  &&OO55  55OO  ",
      "  555        555",
      "55              ",
      "                ",
      "                ",
      "                ",
      "                ",
      "                ",
      "&               ",
      "&&              ",
      "&&              "
    ],
    [
      "                ",
      "                ",
      "   &OO      OO  ",
      "  &O& O    O  O ",
      "  &O& O    O  O ",
      "   &OO55  55OO  ",
      "  555        555",
      "55              ",
      "                ",
      "                ",
      "                ",
      "                ",
      "                ",
      "&               ",
      "&&              ",
      "&               "
    ],
    [
      "                ",
      "                ",
      "   &OO      OO  ",
      "  &O& O    O  O ",
      "   O  O    O  O ",
      "    OO55  55OO  ",
      "  555        555",
      "55              ",
      "                ",
      "                ",
      "                ",
      "                ",
      "                ",
      "                ",
      "&               ",
      "                "
    ],
    [
      "                ",
      "                ",
      "   &OO      OO  ",
      "  &O& O    O  O ",
      "   O  O    O  O ",
      "    OO555555OO  ",
      "  555        555",
      "55              ",
      "                ",
      "                ",
      "                ",
      "                ",
      "                ",
      "                ",
      "&               ",
      "&               "
    ],
    [
      "                ",
      "   &            ",
      "  &&OO      OO  ",
      "  &O& O    O  O ",
      "   O  O    O  O ",
      "    OO555555OO  ",
      "  555        555",
      "55              ",
      "                ",
      "                ",
      "                ",
      "                ",
      "                ",
      "                ",
      "                ",
      "&               "
    ]
  ]
}