{
  "xsize": 16,
  "zsize": 16,
  "refpalette": "pomkotsmechs:factory",
  "slices": [
    [
      "ʹʹʹʹʹʹʹʹʹʹʹʹV   ",
      "ʹʹʹʹʹʹʹʹʹʹʹʹV   ",
      "ʹʹʹʹʹʹʹʹʹʹʹʹV   ",
      "ʹʹʹʹʹʹʹʹʹʹʹVV   ",
      "ʹʹʹʹʹʹʹʹʹʹʹV    ",
      "ʹʹʹʹʹʹʹʹʹʹʹV    ",
      "ʹʹʹʹʹʹʹʹʹʹV     ",
      "ʹʹʹʹʹʹʹʹʹVV     ",
      "ʹʹʹʹʹʹʹʹVV      ",
      "ʹʹʹʹʹʹʹVV       ",
      "ʹʹʹʹʹʹVV        ",
      "ʹʹʹVVV          ",
      "VVVV            ",
      " &              ",
      "                ",
      "                "
    ],
    [
      "VVVV        V   ",
      "  VVVV      V   ",
      "    VVV     V   ",
      "     VVVV  VV   ",
      "       VVVVV    ",
      "         VVV    ",
      "          V     ",
      "         VV     ",
      "        VV      ",
      "       VV       ",
      "      VV        ",
      "   VVV          ",
      "VVVV            ",
      "&&              ",
      "                ",
      "                "
    ],
    [
      "            V   ",
      "            V   ",
      "            V   ",
      "           VV   ",
      "           V    ",
      "           V    ",
      "          V     ",
      "         VV     ",
      "        VV      ",
      "       VV       ",
      "      VV        ",
      "   VVV          ",
      "VVVV            ",
      "&               ",
      "                ",
      "                "
    ],
    [
      "                ",
      "                ",
      "                ",
      "                ",
      "                ",
      "                ",
      "                ",
      "                ",
      "                ",
      "                ",
      "                ",
      "                ",
      "&               ",
      "&               ",
      "                ",
      "                "
    ],
    [
      "                ",
      "                ",
      "                ",
      "                ",
      "                ",
      "                ",
      "                ",
      "                ",
      "                ",
      "                ",
      "                ",
      "                ",
      "                ",
      "                ",
      "                ",
      "                "
    ],
    [
      "                ",
      "                ",
      "                ",
      "                ",
      "                ",
      "                ",
      "                ",
      "                ",
      "                ",
      "                ",
      "                ",
      "                ",
      "                ",
      "                ",
      "                ",
      "                "
    ]
  ]
}