{
  "xsize": 16,
  "zsize": 16,
  "refpalette": "lostcities:factory",
  "slices": [
    [
      "  !     &     ! ",
      " !!!   &!&   !!!",
      "!!!!!JJJJJJJ!!!!",
      " !!!         !!!",
      "  !           ! ",
      "  J             ",
      "  J             ",
      "    &  !  !     ",
      " &&&&&  rr      ",
      "    &   rr      ",
      "       !  !     ",
      "  J             ",
      "  !             ",
      " !!!            ",
      "!!!!!           ",
      " !!!         !!!"
    ],
    [
      "  !     &     ! ",
      " !!!   &!&   !!!",
      "!!!!!!!!!!!!!!!!",
      " !!!         !!!",
      "  !           ! ",
      "  !             ",
      "                ",
      "   &&  !  !     ",
      "  &&&&  rr      ",
      "   &&   rr      ",
      "       !  !     ",
      "  !             ",
      "  !             ",
      " !!!            ",
      "!!!!!          &",
      " !!!         !!!"
    ],
    [
      "  !     &     ! ",
      " !!!   &!&   !!!",
      "!!!!!JJJJJJJ!!!!",
      " !!!         !!!",
      "  !           ! ",
      "  J             ",
      "                ",
      "   &   !  !     ",
      "  &&&   rr      ",
      "   &    rr      ",
      "       !  !     ",
      "                ",
      "  !             ",
      " !!!            ",
      "!!!!!          &",
      " !!!         !!!"
    ],
    [
      "  !     &     ! ",
      " !!!   &!&   !!!",
      "!!!!!JJJJJJJ!!!!",
      " !!!         !!!",
      "  !           ! ",
      "  J             ",
      "  J             ",
      "   &   !  !     ",
      "  &&&   rr      ",
      "  &&&   rr      ",
      "   &   !  !     ",
      "                ",
      "  !             ",
      " !!!            ",
      "!!!!!          &",
      " !!!         !!!"
    ],
    [
      " !!!    &    !!!",
      "!!!!!  &!&  !!!!",
      "!!!!!!!!!!!!!!!!",
      "!!!!!       !!!!",
      " !!!         !!!",
      "  !             ",
      "  !             ",
      "  !    !  !     ",
      "  &&    rr      ",
      " &&&&   rr      ",
      "  &&   !  !     ",
      "  !             ",
      "  !             ",
      "!!!!!           ",
      "!!!!!          &",
      "!!!!!        !!!"
    ],
    [
      "  !     &     ! ",
      " !!!   &!&   !!!",
      "!!!!!JJJJJJJ!!!!",
      " !!!         !!!",
      "  !           ! ",
      "  J             ",
      "  J             ",
      "  J    !JJ!     ",
      " !J    JrrJ     ",
      " &J&   JrrJ     ",
      "  J    !JJ!     ",
      "  J             ",
      "  !             ",
      " !!!            ",
      "!!!!!          &",
      " !!!         !!!"
    ]
  ]
}