{
  "xsize": 16,
  "zsize": 16,
  "refpalette": "pomkotsmechs:factory",
  "slices": [
    [
      "VVVVVVVVVVVVVVVV",
      "VVVVVVVVVVVVVVVV",
      "VVVVVVVVVVVVVVVV",
      "VVVVVVVVVVVVVVVV",
      "VVVVVVVVVVVVVVVV",
      "VVVVVVVVVVVVVVVV",
      "VVVVVVVVVVVVVVVV",
      "VVVVVVVVVVVVVVVV",
      "VVVVVVVVVVVVVVVV",
      "VVVVVVVVVVVVVVVV",
      "VVVVVVVVVVVVVVVV",
      "VVVVVVVVVVVVVVVV",
      "VVVVVVVVVVVVVVVV",
      "VVVVVVVVVVVVVVVV",
      "VVVVVVVVVVVVVVVV",
      "VVVVVVVVVVVVVVVV"
    ],
    [
      "         V    ! ",
      "         V    ! ",
      "         V    ! ",
      "V        V   !! ",
      "VVVVVVVVVVVVV!!!",
      "VV      VVV  !!!",
      "        VVV   ! ",
      "        VV    ! ",
      "VV      VV   !!!",
      "VVVVVVVVVVVVV!!!",
      "V!!!!!!!!!!!!!! ",
      "!!!!!!!!!!!!!!! ",
      "!!!!!!!!!!!!!!! ",
      "!!!!!!!!!!!!!!! ",
      "!!!!!!!!!!!!!!! ",
      "!!!!!!!!!!!!!!! "
    ],
    [
      "              i ",
      "              i ",
      "              i ",
      "V            !i ",
      "V,,,,,,,V V,,!!!",
      "        V V  !!!",
      "        V V   ! ",
      "        V V   ! ",
      "        V V  !!!",
      "V,,,,,,,V V,,!!!",
      "V            !i ",
      "              i ",
      " $   $ $   $  i ",
      "&&&           i ",
      "&&&           i ",
      " &            i "
    ],
    [
      "              i ",
      "              i ",
      "              i ",
      "/            !i ",
      "3            !!!",
      "             !!!",
      "              ! ",
      "              ! ",
      "             !!!",
      "/            !!!",
      "3            !i ",
      "              i ",
      " OOOOO OOOOO  i ",
      " OOOOO OOOOO  i ",
      "&OOOOO OOOOO  i ",
      " OOOOO OOOOO  i "
    ],
    [
      "              i ",
      "              i ",
      "              i ",
      "/            !i ",
      "3            !!!",
      "             !!!",
      "              ! ",
      "              ! ",
      "             !!!",
      "/            !!!",
      "3            !i ",
      "              i ",
      " OVVVO OVVVO  i ",
      " V   V V   V  i ",
      "&V&<<V V <<V  i ",
      " VV<<V VV<<V  i "
    ],
    [
      "              i ",
      "              i ",
      "              i ",
      "/            !i ",
      "3            !!!",
      "             !!!",
      "              ! ",
      "              ! ",
      "             !!!",
      "/            !!!",
      "3            !i ",
      "              i ",
      " OVVVO OVVVO  i ",
      " V   V V   V  i ",
      "&V&  V V   V  i ",
      "&VVVVV VVVVV  i "
    ]
  ]
}