{
  "xsize": 16,
  "zsize": 16,
  "refpalette": "pomkotsmechs:factory",
  "slices": [
    [
      "!!!          !!!",
      "!!!          !!!",
      "!!!       && !!!",
      "         &      ",
      "       OOOO     ",
      "      O  & O&&  ",
      "     O !!  &O&& ",
      "     O  !!  O&  ",
      "         !  O   ",
      "         !8 O   ",
      "         & O    ",
      "        OOO     ",
      " !       &      ",
      "!!!          !!!",
      "!!!      &&  !!!",
      "!!!          !!!"
    ],
    [
      "$$$          $$$",
      "$!$          $!$",
      "$$$          $$$",
      "         &      ",
      "       O!!O     ",
      "      O  & O&   ",
      "     O '(  &O&  ",
      "     ! !!!  !   ",
      "     !   !  !   ",
      "         !  O   ",
      "        && O    ",
      "       O!!O     ",
      " !      &&      ",
      "$$$          $$$",
      "$!$          $!$",
      "$$$          $$$"
    ],
    [
      " $            $ ",
      "$!$          $!$",
      " $            $ ",
      "         &      ",
      "       O!!O     ",
      "      O  & O&   ",
      "     O  ') &O&  ",
      "     ! +,/ &!&  ",
      "     ! 0 0  !   ",
      "     O 2,3  O   ",
      "      O &  O    ",
      "       O!!O     ",
      "        &       ",
      " $            $ ",
      "$!$          $!$",
      " $            $ "
    ],
    [
      "                ",
      " !            ! ",
      "                ",
      "         &      ",
      "       O!!O     ",
      "      OOOOO&&   ",
      "     OOOOOOO&&  ",
      "     !OOOOOO&&  ",
      "     !OOOOOO!&  ",
      "     OOOOOOOO   ",
      "      OOOOOO    ",
      "       O!!O     ",
      "        &       ",
      "                ",
      " !            ! ",
      "                "
    ],
    [
      "                ",
      " !            ! ",
      "                ",
      "        &&      ",
      "       O!!O     ",
      "      OOOOO&&   ",
      "     OOOOOO&&&  ",
      "     !OOOOOO&&  ",
      "     !OOOOOO!   ",
      "     OOOOOOOO   ",
      "      OOOOOO    ",
      "      &O!!O     ",
      "       &&       ",
      "                ",
      " !            ! ",
      "                "
    ],
    [
      " $            $ ",
      "$!$          $!$",
      " $            $ ",
      "        &       ",
      "       OOOO     ",
      "      OOOOO     ",
      "     OOOOOO&&   ",
      "     OOOOOOO&&  ",
      "     OOOOOOOO&  ",
      "     OOOOOOOO   ",
      "      OOOOOO&   ",
      "      &OOOO&    ",
      "       &        ",
      " $            $ ",
      "$!$          $! ",
      " $            $ "
    ]
  ]
}