{
  "xsize": 16,
  "zsize": 16,
  "refpalette": "pomkotsmechs:factory",
  "slices": [
    [
      " ]VVVVVVVVVVVVVV",
      " ]VVVVVVVVVVVVVV",
      " ]VVVVVVVVVV! !V",
      " ]VVVVVVVVVVVV V",
      " ]VVVVVVVVVV! !V",
      " ]VVVVVVVVVVVVVV",
      " ]VVVVVVVVVVVnmm",
      " ]VVVVVVVVVVVo  ",
      " ]VVVVVVVVVVVo  ",
      " ]VVVVVVVVVVVo  ",
      " ]VVVVVVVVVVVo  ",
      " ]VVVVVVVVVVVo  ",
      " ]!VVVVVVVVVVo  ",
      "!!!VVVVVVVVVVo  ",
      "!!!mmmmmmmmmm3  ",
      " !              "
    ],
    [
      " ]        JJJJJJ",
      " ]        JJJJJJ",
      " ]  $   $ JJJJJJ",
      " ]        JJJJJJ",
      " ]        JJJJJJ",
      " ]  $   $ JJJJJJ",
      " ]           +,,",
      " ]           0  ",
      " ]           0 !",
      " ]  $   $    0 !",
      " ]           0 !",
      " ]           0 !",
      " ]!        +jo  ",
      "!!!        nno  ",
      "!!!,,,,,,,,mm3  ",
      " !              "
    ],
    [
      " ]  OOOOO J    J",
      " ]  OOOOO J    J",
      " ]  OOOOO J    J",
      " ]        J    J",
      " ]        J    J",
      " ]  OOOOO JJJJJJ",
      " ]  OOOOO       ",
      " ]  OOOOO       ",
      " ]  OOOOO       ",
      " ]  OOOOO       ",
      " ]              ",
      " ]              ",
      " ]!        +/   ",
      "!!!        23   ",
      "!!!             ",
      " !              "
    ],
    [
      " ]  V <<V J    J",
      " ]  VV<<V J    J",
      " ]  OVVVO J    J",
      " ]        J    J",
      " ]        J    J",
      " ]  OVVVO JJJJJJ",
      " ]  V   V       ",
      " ]  V <<V       ",
      " ]  VV<<V       ",
      " ]  OVVVO       ",
      " ]              ",
      " ]              ",
      " ]!        +/   ",
      "!!!        23   ",
      "!!!             ",
      " !              "
    ],
    [
      " ]  V   V J    J",
      " ]  VVVVV J    J",
      "    OVVVO J    J",
      "          J    J",
      "          J    J",
      " ]  OVVVO JJJJJJ",
      " ]  V   V       ",
      " ]  V   V       ",
      " ]  VVVVV       ",
      " ]  OVVVO       ",
      " ]              ",
      " ]              ",
      " ]!        +/   ",
      "!!!        23   ",
      "!!!             ",
      " !              "
    ],
    [
      " ]  VOOOV J     ",
      " ]  VOOOV J    J",
      "    OVVVO J    J",
      "          J    J",
      "          J    J",
      "    OVVVO JJJJJJ",
      "    VOOOV       ",
      "    VOOOV       ",
      "    VOOOV       ",
      " ]  OVVVO       ",
      " ]              ",
      " ]              ",
      " ]!        +/   ",
      "!!!        23   ",
      "!!!             ",
      " !              "
    ]
  ]
}