{
  "xsize": 16,
  "zsize": 16,
  "refpalette": "lostcities:factory",
  "slices": [
    [
      "VOVVVO OVVVO &i&",
      "V          && i ",
      "V         &&& i ",
      "VOVVVO OVVVO& i ",
      "VVOOOV VOOOV  i ",
      "VVOOOV VOOOV  i ",
      "VVOOOV VOOOV  i ",
      "VOVVVO OVVVO  i ",
      "V             i ",
      "V             i ",
      "VVVVVVVVVVVVV!i ",
      "VVVVVVVVVVVVV!!!",
      "mmmmmmmmmmmmm!!!",
      "              ! ",
      "!!!!!!dddddddd! ",
      "!!  !!        ! "
    ],
    [
      "&OOOOO OOOOO&&i&",
      " &         &&&i ",
      "         &&&&&i ",
      " OOOOO OOOOO& i ",
      " OOOOO OOOOO  i ",
      " OOOOO OOOOO  i ",
      " OOOOO OOOOO  i ",
      " OOOOO OOOOO  i ",
      "              i ",
      "              i ",
      "/            !i ",
      "n            !!!",
      "m,,,,,,,,,,,,!!!",
      "              ! ",
      "!!!!!!dddddddd! ",
      "!!  !!        ! "
    ],
    [
      "&$&  $ $   $&&i&",
      " &         &&&i ",
      "         & &&&i ",
      " $   $ $&&&$  i ",
      "         &    i ",
      "              i ",
      "              i ",
      " $   $ $   $  i ",
      "              i ",
      "              i ",
      "/            !i ",
      "3            !!!",
      "             !!!",
      "              ! ",
      "!!!!!!dddddddd! ",
      "!!  !!        ! "
    ],
    [
      "&OOOOO OOOOO&&i&",
      " &          &&i ",
      "         &    i ",
      " OOOOO OOOOO  i ",
      " OOOOO OOOOO  i ",
      " OOOOO OOOOO  i ",
      " OOOOO OOOOO  i ",
      " OOOOO OOOOO  i ",
      "              i ",
      "              i ",
      "/            !i ",
      "3            !!!",
      "             !!!",
      "              ! ",
      "!!!!!!dddddddd! ",
      "!!  !!        ! "
    ],
    [
      " OVVVO OVVVO && ",
      "              i ",
      "         &&   i ",
      " OVV    &VVO  i ",
      " V   V V &&V  i ",
      " V <<V V <<V  i ",
      " VV<<V VV<<V  i ",
      " OVVVO OVVVO  i ",
      "              i ",
      "              i ",
      "/            !i ",
      "3            !!!",
      "             !!!",
      "              ! ",
      "!!!!!!dddddddd! ",
      "!!  !!        !!"
    ],
    [
      " OVVVO OVVVO    ",
      "                ",
      "          &   i ",
      " O       VVO  i ",
      " V        &V  i ",
      " V   V V   V  i ",
      " VVVVV VVVVV  i ",
      " OVVVO OVVVO  i ",
      "              i ",
      "              i ",
      "/            !i ",
      "3            !!!",
      "             !!!",
      "              ! ",
      "!!!!!!dddddddd! ",
      "!!  !!        !$"
    ]
  ]
}