{
  "xsize": 16,
  "zsize": 16,
  "refpalette": "lostcities:factory",
  "slices": [
    [
      "VVVVVVVVVVVVVVVV",
      "VVVVVVVVVVVVVVVV",
      "VVVVVVVVVVVVVVVV",
      "VVVVVVVVVVVVVVVV",
      "VVVVVVVVVVVVVVVV",
      "VVVVVVVVVVVVVVVV",
      "VVVVVVVVVVVVVVVV",
      "VVVVVVVVVVVVVVVV",
      "VVVVVVVVVVVVVVVV",
      "VVVVVVVVVVVVVVVV",
      "VVVVVVVVVVVVVVVV",
      "VVVVVVVVVVVVVVVV",
      "VVVVVVVVVVVVVVVV",
      "VVVVVVVVVVVVVVVV",
      "VVVVVVVVVVVVVVVV",
      "VVVVVVVVVVVVVVVV"
    ],
    [
      " !!JJJJJJJJJJJJ!",
      " !!JJJJJJJJJJJJ!",
      " !!JJJJJJJJJJJJ!",
      " !!JJJJJJJJJJJJ!",
      "&!!JJJJJJJJJJJJ!",
      "&!!!!!!!!!!!!!!V",
      "!!!VVVVVVVVVVVVV",
      "!!!           VV",
      " !              ",
      " !              ",
      "!!!           VV",
      "!!!VVVVVVVVVVVVV",
      " !!            V",
      " !              ",
      " !              ",
      " !              "
    ],
    [
      " ] J          J ",
      " ] J          J5",
      " ] J          J5",
      " ] J          J5",
      "&] JJJJJJJJJJJJ ",
      "&]!            V",
      "!!!,,,,,,,,,,,,V",
      "!!!             ",
      " !              ",
      " !              ",
      "!!!             ",
      "!!!,,,,,,,,,,,,V",
      " ]!            V",
      " ]              ",
      " ]              ",
      " ]              "
    ],
    [
      " ] J          J ",
      " ] J          J ",
      " ] J          J5",
      " ] J          J ",
      " ] JJJJJJJJJJJJ ",
      "&]!            +",
      "!!!            2",
      "!!!             ",
      " !              ",
      " !              ",
      "!!!             ",
      "!!!            +",
      " ]!            2",
      " ]              ",
      " ]              ",
      " ]              "
    ],
    [
      " ] J          J ",
      " ] J          J ",
      " ] J          J5",
      " ] J          J ",
      " ] JJJJJJJJJJJJ ",
      "&]!            +",
      "!!!            2",
      "!!!             ",
      " !              ",
      " !              ",
      "!!!             ",
      "!!!            +",
      " ]!            2",
      " ]              ",
      " ]              ",
      " ]              "
    ],
    [
      " ] J          J ",
      " ] J          J ",
      " ] J          J5",
      " ] J          J ",
      " ] JJJJJJJJJJJJ ",
      "&]!            +",
      "!!!            2",
      "!!!             ",
      "&!              ",
      " !              ",
      "!!!             ",
      "!!!            +",
      " ]!            2",
      " ]              ",
      " ]              ",
      " ]              "
    ]
  ]
}