{
  "xsize": 16,
  "zsize": 16,
  "refpalette": "pomkotsmechs:factory",
  "slices": [
    [
      " !  5555555555  ",
      "!!! 55       5  ",
      "!!! 55       5  ",
      " ]! 55       5  ",
      "&]& 55       5  ",
      "&]& 55       5  ",
      " ]  55       5  ",
      " ]  55       5  ",
      " ]  55       5  ",
      " ]  55       5  ",
      " ]  55       5  ",
      " ]  55       5  ",
      " ]  55       5  ",
      " ]  55       5  ",
      " ]  55       5  ",
      " ]  5555555555  "
    ],
    [
      " !  5555555555  ",
      "!!! 55       5  ",
      "!!! 55       5  ",
      " ]! 55       5  ",
      "&]& 55       5  ",
      " ]  55       5  ",
      " ]  55       5  ",
      " ]  55       5  ",
      " ]  55       5  ",
      " ]  55       5  ",
      " ]  55       5  ",
      " ]  55       5  ",
      " ]  55       5  ",
      " ]  55       5  ",
      " ]  55       5  ",
      " ]  5555555555  "
    ],
    [
      " !  5555555555  ",
      "!!! 5555555555  ",
      "!!! 5555555555  ",
      " ]! 5555555555  ",
      "&]& 5555555555  ",
      " ]  5555555555  ",
      " ]  5555555555  ",
      " ]  5555555555  ",
      " ]  5555555555  ",
      " ]  5555555555  ",
      " ]  5555555555  ",
      " ]  5555555555  ",
      " ]  5555555555  ",
      " ]  5555555555  ",
      " ]  5555555555  ",
      " ]  5555555555  "
    ],
    [
      " !              ",
      "!!!             ",
      "!!!        VV   ",
      " ]!        VV   ",
      "&]&             ",
      " ]              ",
      " ]              ",
      " ]    VVV       ",
      " ]   V   V      ",
      " ]  V     V     ",
      " ]  V     V     ",
      " ]  V     V     ",
      " ]   V   V      ",
      " ]    VVV       ",
      " ]              ",
      " ]              "
    ],
    [
      " !              ",
      "!!!             ",
      "!!!        VV   ",
      " ]!        VV   ",
      "&]&             ",
      " ]              ",
      " ]              ",
      " ]    VVV       ",
      " ]   V   V      ",
      " ]  V     V     ",
      " ]  V     V     ",
      " ]  V     V     ",
      " ]       V      ",
      " ]     VV       ",
      " ]              ",
      " ]              "
    ],
    [
      " !              ",
      "!!!             ",
      "!!!        VV   ",
      " ]!        VV   ",
      "&]&             ",
      " ]              ",
      " ]              ",
      " ]    VVV       ",
      " ]   V   V      ",
      " ]  V     V     ",
      " ]        V     ",
      " ]        V     ",
      " ]       V      ",
      " ]      V       ",
      " ]              ",
      " ]              "
    ]
  ]
}