{
  "xsize": 16,
  "zsize": 16,
  "refpalette": "pomkotsmechs:factory",
  "slices": [
    [
      "vvvvvvvvvvvvvvvv",
      "vvvvvvvvvvvvvvvv",
      "vvvvvvvvvvvvvvvv",
      "vvvvvvvvvvvvvvvv",
      "vvvvvvvvvvvvvvvv",
      "vvvvvvvvvvvvvvvv",
      "vvvvvvvvvvvvvvvv",
      "vvvvvvvvvvvvvvvv",
      "vvvvvvvvvvvvvvvv",
      "vvvvvvvvvvvvvvvv",
      "vvvvvvvvvvvvvvvv",
      "vvvvvvvvvvvvvvvv",
      "vvvvvvvvvvvvvvvv",
      "vvvvvvvvvvvvvvvv",
      "vvvvvvvvvvvvvvvv",
      "vvvvvvvvvvvvvvvv"
    ],
    [
      "                ",
      "     !        ! ",
      "                ",
      "    &           ",
      "   &&&          ",
      "    &!        ! ",
      "                ",
      "                ",
      "                ",
      "     !        ! ",
      "                ",
      "                ",
      "                ",
      "     !        ! ",
      "                ",
      "                "
    ],
    [
      "                ",
      "     !!!!!!!!!! ",
      "                ",
      "    &&          ",
      "   &&&&         ",
      "    &!!!!!!!!!! ",
      "     &          ",
      "                ",
      "              & ",
      "     !!!!!!!!!!&",
      "              & ",
      "                ",
      "                ",
      "     !!!!!!!!!! ",
      "                ",
      "                "
    ],
    [
      "                ",
      "     OOOOOOOOOO ",
      "     OVVVVVVVVO ",
      "     OVVVVVVVVO ",
      "    &OVVVVVVVVO ",
      "    &OVVVVVVVVO ",
      "     OVVVVVVVVO ",
      "     OVVVVVVVVO ",
      "     OVVVVVVVVO ",
      "     OVVVVVVVVO&",
      "     OVVVVVVVVO ",
      "     OVVVVVVVVO ",
      "     OVVVVVVVVO ",
      "     OVVVVVVVVO ",
      "     OVVVVVVVVO ",
      "     OVVVVVVVVO "
    ],
    [
      "                ",
      "     OVVVVVVVVO ",
      "     V        V ",
      "     V        V ",
      "     V        V ",
      "    &V&       V ",
      "    &V&       V ",
      "     V        V ",
      "     V        V ",
      "     V       &V&",
      "     V       &V&",
      "     O        O ",
      "     V        V ",
      "     V        V ",
      "     V        V ",
      "     V        V "
    ],
    [
      "                ",
      "     OVVVVVVVVO ",
      "     V        V ",
      "     V        V ",
      "     V        V ",
      "     V        V ",
      "    &V&       V ",
      "     V        V ",
      "     V        V ",
      "     V        V ",
      "     V       &V&",
      "     O        O ",
      "     V        V ",
      "     V        V ",
      "     V        V ",
      "     V        V "
    ]
  ]
}