{
  "xsize": 16,
  "zsize": 16,
  "refpalette": "lostcities:factory",
  "slices": [
    [
      "ʹʹʹʹʹʹʹʹʹʹʹʹV   ",
      "ʹʹʹʹʹʹʹʹʹʹʹʹV   ",
      "͵ʹʹʹʹʹʹʹʹʹʹʹV   ",
      "͵ʹʹʹʹʹʹʹʹʹʹVV   ",
      "ʹʹʹʹʹʹʹʹʹʹʹV    ",
      "ʹʹʹʹʹʹʹʹʹʹʹV    ",
      "ʹʹʹʹʹʹʹʹʹʹV     ",
      "ʹʹʹʹʹʹʹʹʹVV     ",
      "ʹʹʹʹʹʹʹʹVV      ",
      "ʹʹʹʹʹʹʹVV       ",
      "ʹʹʹʹʹʹVV        ",
      "ʹʹʹVVV          ",
      "VVVV&&          ",
      "                ",
      "                ",
      "                "
    ],
    [
      "ʹʹʹʹʹʹʹʹʹʹʹʹV   ",
      "ʹʹʹʹʹʹʹʹʹʹʹʹV   ",
      "ʹʹʹʹʹʹʹʹʹʹʹʹV   ",
      "ʹʹʹʹʹʹʹʹʹʹʹVV   ",
      "ʹʹʹʹʹʹʹʹʹʹʹV    ",
      "ʹʹʹʹʹʹʹʹʹʹʹV    ",
      "ʹʹʹʹʹʹʹʹʹʹV     ",
      "ʹʹʹʹʹʹʹʹʹVV     ",
      "ʹʹʹʹʹʹʹʹVV      ",
      "ʹʹʹʹʹʹʹVV       ",
      "ʹʹʹʹʹʹVV        ",
      "ʹʹʹVVV          ",
      "VVVV&           ",
      "  &&            ",
      "                ",
      "                "
    ],
    [
      "ʹʹʹʹʹʹʹʹʹʹʹʹV   ",
      "ʹʹʹʹʹʹʹʹʹʹʹʹV   ",
      "ʹʹʹʹʹʹʹʹʹʹʹʹV   ",
      "ʹʹʹʹʹʹʹʹʹʹʹVV   ",
      "ʹʹʹʹʹʹʹʹʹʹʹV    ",
      "ʹʹʹʹʹʹʹʹʹʹʹV    ",
      "ʹʹʹʹʹʹʹʹʹʹV     ",
      "ʹʹʹʹʹʹʹʹʹVV     ",
      "ʹʹʹʹʹʹʹʹVV      ",
      "ʹʹʹʹʹʹʹVV       ",
      "ʹʹʹʹʹʹVV        ",
      "ʹʹʹVVV          ",
      "VVVV            ",
      "  &&            ",
      "                ",
      "                "
    ],
    [
      "ʹʹʹʹʹʹʹʹʹʹʹʹV   ",
      "ʹʹʹʹʹʹʹʹʹʹʹʹV   ",
      "ʹʹʹʹʹʹʹʹʹʹʹʹV   ",
      "ʹʹʹʹʹʹʹʹʹʹʹVV   ",
      "ʹʹʹʹʹʹʹʹʹʹʹV    ",
      "ʹʹʹʹʹʹʹʹʹʹʹV    ",
      "ʹʹʹʹʹʹʹʹʹʹV     ",
      "ʹʹʹʹʹʹʹʹʹVV     ",
      "ʹʹʹʹʹʹʹʹVV      ",
      "ʹʹʹʹʹʹʹVV       ",
      "ʹʹʹʹʹʹVV        ",
      "ʹʹʹVVV          ",
      "VVVV            ",
      "  &&            ",
      "                ",
      "                "
    ],
    [
      "ʹʹʹʹʹʹʹʹʹʹʹʹV   ",
      "͵ʹʹʹʹʹʹʹʹʹʹʹV   ",
      "ʹʹʹʹʹʹʹʹʹʹʹʹV   ",
      "ʹʹʹʹʹʹʹʹʹʹʹVV   ",
      "ʹʹʹʹʹʹʹʹʹʹʹV    ",
      "ʹʹʹʹʹʹʹʹʹʹʹV    ",
      "ʹʹʹʹʹʹʹʹʹʹV     ",
      "ʹʹʹʹʹʹʹʹʹVV     ",
      "ʹʹʹʹʹʹʹʹVV      ",
      "ʹʹʹʹʹʹʹVV       ",
      "ʹʹʹʹʹʹVV        ",
      "ʹʹʹVVV          ",
      "VVVV            ",
      "  &             ",
      "                ",
      "                "
    ],
    [
      "ʹʹʹʹʹʹʹʹʹʹʹʹV   ",
      "ʹʹʹʹʹʹʹʹʹʹʹʹV   ",
      "ʹʹʹʹʹʹʹʹʹʹʹʹV   ",
      "ʹʹʹʹʹʹʹʹʹʹʹVV   ",
      "ʹʹʹʹʹʹʹʹʹʹʹV    ",
      "ʹʹʹʹʹʹʹʹʹʹʹV    ",
      "ʹʹʹʹʹʹʹʹʹʹV     ",
      "ʹʹʹʹʹʹʹʹʹVV     ",
      "ʹʹʹʹʹʹʹʹVV      ",
      "ʹʹʹʹʹʹʹVV       ",
      "ʹʹʹʹʹʹVV        ",
      "ʹʹʹVVV          ",
      "VVVV            ",
      " &&             ",
      "                ",
      "                "
    ]
  ]
}