{
  "xsize": 16,
  "zsize": 16,
  "refpalette": "pomkotsmechs:factory",
  "slices": [
    [
      "                ",
      "                ",
      "                ",
      "                ",
      "                ",
      "                ",
      "      !  !      ",
      "       !!       ",
      "       !!       ",
      "      !  !      ",
      "                ",
      "                ",
      "                ",
      "                ",
      "                ",
      "                "
    ],
    [
      "v||zVVVVz|vvvvvv",
      "|||zVVVVzz||zzzz",
      "}}|zVVVzz||zzVVV",
      "}}}|zzzz|||zVVVV",
      "}}}|zzz||||zVVVV",
      "}}||zz||||zzVVVV",
      "|||zz||||zVVVVVV",
      "zzzz|||||VvvvVVV",
      "zVVz|}}}|VvvvVVV",
      "VVVz|}}}|VvvvVVV",
      "VvVz|}}|zVVVVzvv",
      "VvVz|}|zzVVVzvvv",
      "VVz|}}|zVVVz|vvv",
      "zz|}}}|zVVz|vvvv",
      "||}}}|zzzz|vvvvv",
      "}}}}}|zzz|vvvvvv"
    ],
    [
      "             55&",
      "5           55&&",
      " 55       55   &",
      "   5555555      ",
      "                ",
      "                ",
      "                ",
      "                ",
      "                ",
      "             !! ",
      "  !!         !! ",
      "  !!            ",
      "    55555555    ",
      "  555      555  ",
      "55            55",
      "5              5"
    ],
    [
      "             55&",
      "5           55 &",
      " 55       55    ",
      "   5555555      ",
      "                ",
      "                ",
      "                ",
      "                ",
      "                ",
      "                ",
      "                ",
      "                ",
      "    55555555    ",
      "  555      555  ",
      "55            55",
      "5              5"
    ],
    [
      "             55&",
      "5           55&&",
      " 55       55    ",
      "   5555555      ",
      "                ",
      "                ",
      "                ",
      "                ",
      "                ",
      "                ",
      "                ",
      "                ",
      "    55555555    ",
      "  555      555  ",
      "55            55",
      "5              5"
    ],
    [
      "             55&",
      "5           55&&",
      " 55       55 && ",
      "   5555555      ",
      "                ",
      "                ",
      "                ",
      "                ",
      "                ",
      "                ",
      "                ",
      "                ",
      "    55555555    ",
      "  555      555  ",
      "55            55",
      "5              5"
    ]
  ]
}