{
  "xsize": 16,
  "zsize": 16,
  "refpalette": "pomkotsmechs:factory",
  "slices": [
    [
      "                ",
      "                ",
      "                ",
      "                ",
      "                ",
      "                ",
      "                ",
      "                ",
      "                ",
      "                ",
      "                ",
      "                ",
      "                ",
      "                ",
      "                ",
      "                "
    ],
    [
      "                ",
      "                ",
      "                ",
      "                ",
      "                ",
      "                ",
      "                ",
      "                ",
      "                ",
      "                ",
      "                ",
      "                ",
      "                ",
      "                ",
      "                ",
      "                "
    ],
    [
      "!!!!JJ!!!!!!!!!!",
      "!!JJ!!!!!!!!!!!!",
      "!J!!!!!!!!!!!!!!",
      "!!!!!!!!!!!!!!!!",
      "!!!!!!!!!!!!!!!!",
      "!!!!!!!!!!!!!!!!",
      "!!!!!!!!!!!!!!!!",
      "!!!!!!!!!!!!!!!!",
      "!!!!!!!!!!!!!!!!",
      "!!!!!!!!!!!!!!!!",
      "!!!!!!!!!!!!!!!!",
      "!!J!!!!!!!!!!!!!",
      "!!!JJ!!!!!!!!!!!",
      "!!!!!JJ!!!!!!!!!",
      "!!!!!!!JJ!!!!!!!",
      "!!!!!!!!!JJ!!!!!"
    ],
    [
      "    JJ          ",
      "  JJ            ",
      " J              ",
      "                ",
      "                ",
      "                ",
      "                ",
      "                ",
      "                ",
      "                ",
      "                ",
      "  J             ",
      "   JJ           ",
      "     JJ         ",
      "       JJ       ",
      "         JJ     "
    ],
    [
      "   &            ",
      "   &            ",
      "                ",
      "                ",
      "                ",
      "               &",
      "               &",
      "                ",
      "                ",
      "                ",
      "                ",
      "                ",
      "                ",
      "                ",
      "                ",
      "                "
    ],
    [
      "!!!!!!!!!!!!!!!!",
      "!!!!!!!!!!!!!!!!",
      "!! &  !!!!!!!!!!",
      "!     !!!!!!!!!!",
      "!      !!!!!!!!!",
      "!       !!!!!!!!",
      "!       !!!!!!!!",
      "!!      !!!!!!!!",
      "!!     !!!!!!!!!",
      "!!!   !!!!!!!!!!",
      "!!!!!!!!!!!!!!!!",
      "!!!!!!!!!!!!!!!!",
      "!!!!!!!!!!!!!!!!",
      "!!!!!!!!!!!!!!!!",
      "!!!!!!!!!!!!!!!!",
      "!!!!!!!!!!!!!!!!"
    ]
  ]
}