{
  "xsize": 16,
  "zsize": 16,
  "refpalette": "pomkotsmechs:factory",
  "slices": [
    [
      " 0  OOOOO       ",
      " !  OOOOO  &&   ",
      " 0  OOOOO &&&&  ",
      " 0     &&&&&&   ",
      " 0    &&&&      ",
      " 0  OOOOO       ",
      " 0 &OOOOO       ",
      "   &OOOOO       ",
      "    OOOOO       ",
      "    OOOOO       ",
      " 0              ",
      " 0    !         ",
      " 0   !VVVVVVVVVV",
      " 0    VVVVVVVVVV",
      " !    VVVVVVVVVV",
      " 0    VVVVVVVVVV"
    ],
    [
      " 0              ",
      " !         &    ",
      " 0  $   $ &&&   ",
      " 0     &   &    ",
      " 0    &&&       ",
      " 0  $  &$       ",
      " 0 &&&          ",
      " 0  &           ",
      "                ",
      " 0  $   $       ",
      " 0              ",
      " 0    !         ",
      " 0   !VVVVVVVVVV",
      " 0    V         ",
      " !    V         ",
      " 0    V         "
    ],
    [
      "    OOOOO       ",
      " $  OOOOO &&    ",
      "    OOOOO&&&&   ",
      "      &&  &&    ",
      "     &&&&       ",
      "    OOOOO       ",
      "   &OOOOO       ",
      "    OOOOO       ",
      "    OOOOO       ",
      "    OOOOO       ",
      "                ",
      "      !         ",
      "     !VVVVVVVVVV",
      "      V         ",
      " $    V         ",
      "      V         "
    ],
    [
      "    V <<V       ",
      " !  VV<<V&&     ",
      "    OVVVO&&&    ",
      "      &  &&     ",
      "     &&&        ",
      "    OVVVO       ",
      "   &&&& V       ",
      "    &  <V       ",
      "     V<<V       ",
      "    OVVVO       ",
      "                ",
      "      !         ",
      "     !VVVVVVVVVV",
      "      V         ",
      " !    V         ",
      "      V         "
    ],
    [
      "    V   V       ",
      "    VVVVV&      ",
      "    OVVVO&&     ",
      "         &      ",
      "    &&&         ",
      "   &OVVVO       ",
      "   &&&  V       ",
      "    &   V       ",
      "       VV       ",
      "      VVO       ",
      "                ",
      "      !         ",
      "     !VVVVVVVVVV",
      "      V         ",
      "      V         ",
      "      V         "
    ],
    [
      "    VOOOV       ",
      "    VOOOV&      ",
      "    OVVVO&&     ",
      "        &&      ",
      "    &&          ",
      "   &OVVVO       ",
      "    &OOOV       ",
      "       OV       ",
      "      OOV       ",
      "       VO       ",
      "                ",
      "      !         ",
      "     !VVVVVVVVVV",
      "      V         ",
      "      V         ",
      "      V         "
    ]
  ]
}