{
  "xsize": 16,
  "zsize": 16,
  "refpalette": "lostcities:factory",
  "slices": [
    [
      "ͱͱͱͱͱͱͱͱͱͱ      ",
      " &              ",
      "                ",
      "                ",
      "ͱͱͱͱͱͱͱͱͱͱ      ",
      "         ͱ      ",
      "         ͱ      ",
      "         ͱ      ",
      "         ͱ      ",
      "         ͱ      ",
      "         ͱ      ",
      "      &  ͱ      ",
      "ͱͱͱͱͱͱͱͱͱͱ      ",
      "      &         ",
      "                ",
      "                "
    ],
    [
      "ͱͱͱͱͱͱͱͱͱͱ      ",
      " &&             ",
      "                ",
      "                ",
      "ͱͱͱͱͱͱͱͱͱͱ      ",
      "         ͱ      ",
      "         ͱ      ",
      "         ͱ      ",
      "         ͱ      ",
      "         ͱ      ",
      "         ͱ      ",
      "      &  ͱ      ",
      "ͱͱͱͱͱͱͱͱͱͱ      ",
      "      &         ",
      "                ",
      "                "
    ],
    [
      "ͱͱͱͱͱͱͱͱͱͱ      ",
      "  &             ",
      "                ",
      "                ",
      "ͱͱͱͱͱͱͱͱͱͱ      ",
      "         ͱ      ",
      "         ͱ      ",
      "         ͱ      ",
      "         ͱ      ",
      "         ͱ      ",
      "         ͱ      ",
      "      && ͱ      ",
      "ͱͱͱͱͱͱͱͱͱͱ      ",
      "      &&        ",
      "                ",
      "                "
    ],
    [
      "ͱͱͱͱͱͱͱͱͱͱ      ",
      " &&             ",
      "                ",
      "                ",
      "ͱͱͱͱͱͱͱͱͱͱ      ",
      "         ͱ      ",
      "         ͱ      ",
      "         ͱ      ",
      "         ͱ      ",
      "         ͱ      ",
      "     &&  ͱ      ",
      "     &&& ͱ      ",
      "ͱͱͱͱͱͱͱͱͱͱ      ",
      "      &&        ",
      "                ",
      "                "
    ],
    [
      "&&&             ",
      " &              ",
      "                ",
      "                ",
      "                ",
      "ͱͱͱͱͱͱͱͱͱͱ      ",
      "         ͱ      ",
      "         ͱ      ",
      " & &     ͱ      ",
      "&&&&&&&  ͱ      ",
      "    &&&& ͱ      ",
      "ͱͱͱͱͱͱͱͱͱͱ      ",
      "     &&&        ",
      "                ",
      "                ",
      "                "
    ],
    [
      " &              ",
      "                ",
      "                ",
      "                ",
      "                ",
      "                ",
      "ͱͱͱͱͱͱͱͱͱͱ      ",
      "ͱͱͱͱͱͱͱͱͱͱ      ",
      "ͱͱͱͱͱͱͱͱͱͱ      ",
      "ͱͱͱͱͱͱͱͱͱͱ      ",
      "ͱͱͱͱͱͱͱͱͱͱ      ",
      "     &&         ",
      "                ",
      "                ",
      "                ",
      "                "
    ]
  ]
}