{
  "xsize": 16,
  "zsize": 16,
  "refpalette": "lostcities:factory",
  "slices": [
    [
      "                ",
      "                ",
      "                ",
      "                ",
      "                ",
      "                ",
      "      !  !      ",
      "       !!       ",
      "       !!       ",
      "      !  !      ",
      "                ",
      "                ",
      "                ",
      "                ",
      "                ",
      "                "
    ],
    [
      "vvvvvvVVzz||zzzV",
      "vvVvvvvVzzzzzVVV",
      "VVVVvvvVzzzVVVVV",
      "|||zVVVVzzzVVVVz",
      "}}|zVVVz||zVVVzz",
      "}}|zzzz|||zVVVz|",
      "}|zzzz|}}||zVVz|",
      "zzVVz|}}}||zVVVz",
      "VVVVz|}}|||zzVVV",
      "vvvVz|||zz||zVVv",
      "                ",
      "                ",
      "                ",
      "                ",
      "                ",
      "                "
    ],
    [
      " 55             ",
      "55            !!",
      "5             !!",
      "                ",
      "                ",
      "                ",
      "          !!    ",
      "                ",
      "                ",
      "                ",
      "                ",
      "                ",
      "                ",
      "                ",
      "                ",
      "                "
    ],
    [
      " 55             ",
      "55            !!",
      "5             !!",
      "                ",
      "                ",
      "                ",
      "                ",
      "                ",
      "                ",
      "                ",
      "                ",
      "                ",
      "                ",
      "                ",
      "                ",
      "                "
    ],
    [
      " 55             ",
      "55            !!",
      "5             !!",
      "                ",
      "                ",
      "                ",
      "                ",
      "                ",
      "                ",
      "                ",
      "                ",
      "                ",
      "                ",
      "                ",
      "                ",
      "                "
    ],
    [
      " 55             ",
      "55            !!",
      "5             !!",
      "                ",
      "                ",
      "                ",
      "                ",
      "                ",
      "                ",
      "                ",
      "                ",
      "                ",
      "                ",
      "                ",
      "                ",
      "                "
    ]
  ]
}