{
  "meta": [
    {
      "key": "dontconnect",
      "boolean": true
    }
  ],
  "xsize": 16,
  "zsize": 16,
  "refpalette": "lostcities:factory_common",
  "slices": [
    [
      "$$$$$$$$$$$$$$$$",
      "######SSSS###Sm$",
      "SSSSSSSSSSSSSSS$",
      "SSSSSSSSSSSSSSS$",
      "SSSSSSSSSSSSSSS$",
      "SSSSSSSSSSSSSSS$",
      "SSSSSSSSSSSSSSS$",
      "SSSSSSSSSSSSSSS$",
      "SSSSSSSSSSSSSSS$",
      "SSSSSSSSSSSSSSS$",
      "SSSSSSSSSSSSSSS$",
      "SSSSSSSSSSSSSSS$",
      "SSSSSSSSSSSSSSS$",
      "SSSSSSSSSSSSSSS$",
      "SSSSSSSSSSSSSSS$",
      "SSSSSSSSSSSSSSS$"
    ],
    [
      " $ $ $#  #$ $##$",
      "####a#    #a# m#",
      "               #",
      "               #",
      "               #",
      "               #",
      "               #",
      "               #",
      "               #",
      "               #",
      "               #",
      "               #",
      "               #",
      "               #",
      "               #",
      "               #"
    ],
    [
      " $ $ $#  #$ $##$",
      "####a#    #a# m#",
      "               #",
      "               #",
      "               #",
      "               #",
      "               #",
      "               #",
      "               #",
      "               #",
      "               #",
      "               #",
      "               #",
      "               #",
      "               #",
      "               #"
    ],
    [
      " $ $ $####$ $##$",
      "####a#    #a# m#",
      "               #",
      "               #",
      "               #",
      "               a",
      "               a",
      "               #",
      "               #",
      "               a",
      "               a",
      "               #",
      "               #",
      "               a",
      "               a",
      "               #"
    ],
    [
      " $ $ $aaaa$ $##$",
      "####a#    #a# m#",
      "               #",
      "               #",
      "               #",
      "               #",
      "               #",
      "               #",
      "               #",
      "               #",
      "               #",
      "               #",
      "               #",
      "               #",
      "               #",
      "               #"
    ],
    [
      " $ $ $aaaa$ $##$",
      "####a#    #a# m#",
      "               #",
      "               #",
      "               #",
      "               #",
      "               #",
      "               #",
      "               #",
      "               #",
      "               #",
      "               #",
      "               #",
      "               #",
      "               #",
      "               #"
    ]
  ]
}
