{
  "xsize": 16,
  "zsize": 16,
  "refpalette": "pomkotsmechs:factory",
  "slices": [
    [
      "                ",
      "               J",
      "J            JJJ",
      "JJJ        JJJJ&",
      " JJJrJJJJrJJJ&& ",
      "   J JJJJ J     ",
      "                ",
      "               &",
      "               &",
      "                ",
      "                ",
      "                ",
      "                ",
      "                ",
      "                ",
      "                "
    ],
    [
      "                ",
      "               J",
      "J            JJJ",
      "JJJ        JJJJ ",
      " JJJrJJJJrJJJ&  ",
      "   J JJJJ J     ",
      "                ",
      "                ",
      "                ",
      "                ",
      "                ",
      "                ",
      "                ",
      "                ",
      "                ",
      "                "
    ],
    [
      "JJJJJJJJJJJJJJJJ",
      "JJJJJJJJJJJJJJJJ",
      "JJJJJJJJJJJJJJJJ",
      "JJJJJJJJJJJJJJJ ",
      " JJJrJJJJrJJJ&  ",
      "   J JJJJ J     ",
      "                ",
      "                ",
      "                ",
      "               J",
      "JJJ        JJJJJ",
      "JJJJJJJJJJJJJJJ ",
      "  JJJJJJJJJJ    ",
      "                ",
      "                ",
      "                "
    ],
    [
      "                ",
      "               J",
      "J            JJJ",
      "JJJ        JJJJ ",
      " JJJrJJJJrJJJ&  ",
      "   J JJJJ J     ",
      "                ",
      "                ",
      "                ",
      "               J",
      "JJJ        JJJJJ",
      "JJJJJJJJJJJJJJJ ",
      "  JJJJJJJJJJ    ",
      "                ",
      "                ",
      "                "
    ],
    [
      "                ",
      "               r",
      "r           &rr ",
      "Jrr        rr&& ",
      "&JJrrrrrrrr&&&  ",
      "   J JJJJ   &   ",
      "                ",
      "                ",
      "                ",
      "                ",
      "                ",
      "                ",
      "                ",
      "                ",
      "                ",
      "                "
    ],
    [
      "                ",
      "               J",
      "J            JJJ",
      "JJJ        JJJJ ",
      "&JJJrJJJJrJJJ&  ",
      "   J JJJJ J &   ",
      "                ",
      "                ",
      "                ",
      "                ",
      "                ",
      "                ",
      "                ",
      "                ",
      "                ",
      "                "
    ]
  ]
}