{
  "xsize": 16,
  "zsize": 16,
  "refpalette": "lostcities:factory",
  "slices": [
    [
      "vvvvvvvvvvvvvvvv",
      "vvvvvvvvvvvvvvvv",
      "vvvvvvvvvvvvvvvv",
      "vvvvvvvvvvvvvvvv",
      "vvvvvvvvvvvvvvvv",
      "vvvvvvvvvvvvvvvv",
      "vvvvvvvvvvvvvvvv",
      "vvvvvvvvvvvvvvvv",
      "vvvvvvvvvvvvvvvv",
      "vvvvvvvvvvvvvvvv",
      "vvvvvvvvvvvvvvvv",
      "vvvvvvvvvvvvvvvv",
      "vvvvvvvvvvvvvvvv",
      "vvvvvvvvvvvvvvvv",
      "vvvvvvvvvvvvvvvv",
      "vvvvvvvvvvvvvvvv"
    ],
    [
      "                ",
      "   $   $  $   $ ",
      "        &     &&",
      "        &    &&&",
      "        & &   & ",
      "   $   $&&$&  $ ",
      "         &&&    ",
      "         &&&    ",
      "   $   $ &$&  $ ",
      "   &      &     ",
      "  &&&           ",
      "  &&            ",
      "   $   $  $   $ ",
      "                ",
      "  $     $     >x",
      "   << <<  << << "
    ],
    [
      "                ",
      "   OOOOO  OOOOO ",
      "   OOOOO  OOOOO ",
      "   OOOOO  OOOOO&",
      "   OOOOO  OOOOO ",
      "   OOOOO &OOOOO ",
      "         &&&    ",
      "          &     ",
      "   OOOOO &OOOOO ",
      "   OOOOO  OOOOO ",
      "  &OOOOO  OOOOO ",
      "   OOOOO  OOOOO ",
      "   OOOOO  OOOOO ",
      "                ",
      "  $     $      $",
      "   << <<  << <<&"
    ],
    [
      "                ",
      "   OVVVO  OVVVO ",
      "   V   V  V   V ",
      "   V   V  V  &V&",
      "   V <<V  V <<V ",
      "   OVVVO &OVVVO ",
      "         &&&    ",
      "          &     ",
      "   OVVVO &OVVVO ",
      "   V   V  V   V ",
      "  &V&<<V  V <<V ",
      "   VV<<V  VV<<V ",
      "   OVVVO  OVVVO ",
      "                ",
      "  $     $     &$",
      "               &"
    ],
    [
      "                ",
      "   OVVVO  OVVVO ",
      "   V   V  V   V ",
      "   V   V  V  &V&",
      "   V   V  V   V ",
      "   OVVVO &OVVVO ",
      "         &&&    ",
      "          &     ",
      "   OVVVO &OVVVO ",
      "   V   V  V   V ",
      "  &V&  V  V   V ",
      "   VVVVV  VVVVV ",
      "   OVVVO  OVVVO ",
      "              &&",
      "  !!!!!!!!!!!!!!",
      "  !!!!!!!!!!!!!!"
    ],
    [
      "                ",
      "   OVVVO  OVVVO ",
      "   VOOOV  VOOOV ",
      "   VOOOV  VOOOV&",
      "   VOOOV  VOOOV ",
      "   OVVVO &OVVVO ",
      "          &     ",
      "          &     ",
      "   OVVVO &OVVVO ",
      "   VOOOV  VOOOV ",
      "  &VOOOV  VOOOV ",
      "   VOOOV  VOOOV ",
      "   OVVVO  OVVVO ",
      "             &&&",
      "             &&&",
      "   << <<  << <<&"
    ]
  ]
}