{
  "xsize": 16,
  "zsize": 16,
  "refpalette": "lostcities:factory",
  "slices": [
    [
      "  ͰͰ     ͰͰͰ   !",
      "           ͰͰ   ",
      "            ͰͰ  ",
      "             ͰͰ ",
      "              Ͱ ",
      "              Ͱ ",
      "               Ͱ",
      "               Ͱ",
      "               Ͱ",
      "               Ͱ",
      "               Ͱ",
      "            &&Ͱ ",
      "            &&Ͱ&",
      "             ͰͰ&",
      "Ͱ           ͰͰ&&",
      "ͰͰ         ͰͰ  &"
    ],
    [
      "    ͰͰͰͰͰ       ",
      "  ͰͰ     ͰͰ     ",
      "           Ͱ    ",
      "Ͱ           Ͱ   ",
      "             Ͱ  ",
      "             Ͱ  ",
      "              Ͱ ",
      "              Ͱ ",
      "              Ͱ ",
      "            & Ͱ ",
      "            &&Ͱ ",
      "           &&Ͱ& ",
      "            &Ͱ& ",
      "Ͱ           Ͱ&& ",
      " Ͱ         Ͱ    ",
      "  ͰͰ     ͰͰ     "
    ],
    [
      "   5            ",
      "   5ͰͰͰͰͰ       ",
      "  ͰͰͰ   ͰͰͰ     ",
      " ͰͰ       ͰͰ    ",
      "ͰͰ         ͰͰ   ",
      "Ͱ           Ͱ   ",
      "Ͱ           ͰͰ  ",
      "             Ͱ  ",
      "            &Ͱ  ",
      "           &&Ͱ  ",
      "Ͱ          &ͰͰ& ",
      "Ͱ          &Ͱ&  ",
      "ͰͰ         ͰͰ&  ",
      " ͰͰ       ͰͰ    ",
      "  ͰͰͰ   ͰͰͰ     ",
      "    ͰͰͰͰͰ       "
    ],
    [
      "                ",
      "                ",
      "     ͰͰͰ        ",
      "   ͰͰ   ͰͰ      ",
      "  Ͱ       Ͱ     ",
      " Ͱ         Ͱ    ",
      " Ͱ         Ͱ    ",
      "Ͱ           Ͱ   ",
      "Ͱ          &Ͱ   ",
      "Ͱ         &&Ͱ&  ",
      " Ͱ         Ͱ&&  ",
      " Ͱ         Ͱ&   ",
      "  Ͱ       Ͱ     ",
      "   ͰͰ   ͰͰ      ",
      "     ͰͰͰ        ",
      "                "
    ],
    [
      "                ",
      "                ",
      "                ",
      "     ͰͰͰ        ",
      "   ͰͰ   ͰͰ      ",
      "  ͰͰ     ͰͰ     ",
      "  Ͱ       Ͱ     ",
      " Ͱ         Ͱ    ",
      " Ͱ         Ͱ    ",
      " Ͱ        &Ͱ&   ",
      "  Ͱ       Ͱ&    ",
      "  ͰͰ     ͰͰ     ",
      "   ͰͰ   ͰͰ      ",
      "     ͰͰͰ        ",
      "                ",
      "                "
    ],
    [
      "                ",
      "                ",
      "                ",
      "                ",
      "     ͰͰͰ        ",
      "    ͰͰ ͰͰ       ",
      "   Ͱ     Ͱ      ",
      "  ͰͰ     ͰͰ     ",
      "  Ͱ       Ͱ     ",
      "  ͰͰ     ͰͰ&    ",
      "   Ͱ     Ͱ      ",
      "    ͰͰ ͰͰ       ",
      "     ͰͰͰ        ",
      "                ",
      "                ",
      "                "
    ]
  ]
}