{
  "xsize": 16,
  "zsize": 16,
  "refpalette": "pomkotsmechs:factory",
  "slices": [
    [
      "                ",
      "               J",
      "J            JJJ",
      "JJJ        JJJJ ",
      " JJJrJJJJrJJJ&  ",
      "  &J JJJJ J &   ",
      "                ",
      "                ",
      "                ",
      "                ",
      "                ",
      "                ",
      "                ",
      "                ",
      "                ",
      "                "
    ],
    [
      "                ",
      "               J",
      "J            JJJ",
      "JJJ        JJJJ ",
      " JJJrJJJJrJJJ&  ",
      "  &J&JJJJ J &   ",
      "   &            ",
      "                ",
      "                ",
      "                ",
      "                ",
      "                ",
      "                ",
      "                ",
      "                ",
      "                "
    ],
    [
      "                ",
      "               J",
      "J            JJJ",
      "JJJ &      JJJJ ",
      " JJJrJJJJrJJJ&  ",
      "  &J&JJJJ J &   ",
      "   &&           ",
      "                ",
      "                ",
      "                ",
      "                ",
      "                ",
      "                ",
      "                ",
      "                ",
      "                "
    ],
    [
      "                ",
      "               J",
      "J            JJJ",
      "JJJ &&     JJJJ ",
      " JJJrJJJJrJJJ&  ",
      "   J&JJJJ J &   ",
      "     &          ",
      "                ",
      "                ",
      "                ",
      "                ",
      "                ",
      "                ",
      "                ",
      "                ",
      "                "
    ],
    [
      "                ",
      "               r",
      "r            rr ",
      " rr  &     rr   ",
      "   rrrrrrrr&&&  ",
      "    &&&     &   ",
      "     &          ",
      "                ",
      "                ",
      "                ",
      "                ",
      "                ",
      "                ",
      "                ",
      "                ",
      "                "
    ],
    [
      "                ",
      "               J",
      "J            JJJ",
      "JJJ  &     JJJJ ",
      " JJJrJJJJrJJJ&  ",
      "   J&JJJJ J&&   ",
      "     &          ",
      "                ",
      "                ",
      "                ",
      "                ",
      "                ",
      "                ",
      "                ",
      "                ",
      "                "
    ]
  ]
}