{
  "meta": [
    {
      "key": "dontconnect",
      "boolean": true
    }
  ],
  "xsize": 16,
  "zsize": 16,
  "refpalette": "lcmt:factory_common",
  "slices": [
    [
      "$$$$$$$$$$$$$$$$",
      "$mS###SSSS######",
      "$SSSSSSSSSSSSSSS",
      "$SSSSSSSSSSSSSSS",
      "$SSSSSSSSSSSSSSS",
      "$SSSSSSSSSSSSSSS",
      "$SSSSSSSSSSSSSSS",
      "$SSSSSSSSSSSSSSS",
      "$SSSSSSSSSSSSSSS",
      "$SSSSSSSSSSSSSSS",
      "$SSSSSSSSSSSSSSS",
      "$SSSSSSSSSSSSSSS",
      "$SSSSSSSSSSSSSSS",
      "$SSSSSSSSSSSSSSS",
      "$SSSSSSSSSSSSSSS",
      "$SSSSSSSSSSSSSSS"
    ],
    [
      "$##$ $#  #$ $ $ ",
      "#m #a#    #a####",
      "#               ",
      "#               ",
      "#               ",
      "#               ",
      "#               ",
      "#               ",
      "#               ",
      "#               ",
      "#               ",
      "#               ",
      "#               ",
      "#               ",
      "#               ",
      "#               "
    ],
    [
      "$##$ $#  #$ $ $ ",
      "#m #a#    #a####",
      "#               ",
      "#               ",
      "#               ",
      "#               ",
      "#               ",
      "#               ",
      "#               ",
      "#               ",
      "#               ",
      "#               ",
      "#               ",
      "#               ",
      "#               ",
      "#               "
    ],
    [
      "$##$ $####$ $ $ ",
      "#m #a#    #a####",
      "#               ",
      "#               ",
      "#               ",
      "a               ",
      "a               ",
      "#               ",
      "#               ",
      "a               ",
      "a               ",
      "#               ",
      "#               ",
      "a               ",
      "a               ",
      "#               "
    ],
    [
      "$##$ $aaaa$ $ $ ",
      "#m #a#    #a####",
      "#               ",
      "#               ",
      "#               ",
      "#               ",
      "#               ",
      "#               ",
      "#               ",
      "#               ",
      "#               ",
      "#               ",
      "#               ",
      "#               ",
      "#               ",
      "#               "
    ],
    [
      "$##$ $aaaa$ $ $ ",
      "#m #a#    #a####",
      "#               ",
      "#               ",
      "#               ",
      "#               ",
      "#               ",
      "#               ",
      "#               ",
      "#               ",
      "#               ",
      "#               ",
      "#               ",
      "#               ",
      "#               ",
      "#               "
    ]
  ]
}
