{
  "xsize": 16,
  "zsize": 16,
  "refpalette": "lostcities:factory",
  "slices": [
    [
      "           &    ",
      "  ͳ,,,q  ͳ,,,q  ",
      "          &&&   ",
      "   VVVV   !!&   ",
      "   !!!V   &&&&  ",
      "   !!!V&!  &&!  ",
      " &V!!!V !    !  ",
      "&&VVVVV         ",
      " &&&&     !!    ",
      "                ",
      "                ",
      "                ",
      "                ",
      "                ",
      "  ͳ,,,q  ͳ,,,q  ",
      "                "
    ],
    [
      "                ",
      "           &    ",
      "           &    ",
      "   VVVV   55&   ",
      "      V&&5555&  ",
      "     &V&555555  ",
      "  V&&&V&555555  ",
      " &VVVVV  5555   ",
      "  &&      55    ",
      "                ",
      "                ",
      "                ",
      "                ",
      "                ",
      "                ",
      "                "
    ],
    [
      "                ",
      "                ",
      "                ",
      "          55&   ",
      "        &5555&  ",
      "      &&55  55  ",
      "     && 55  55  ",
      "  &&     5555   ",
      "          55    ",
      "                ",
      "                ",
      "                ",
      "                ",
      "                ",
      "                ",
      "                "
    ],
    [
      "                ",
      "                ",
      "                ",
      "          55    ",
      "         5555   ",
      "        55  55  ",
      "        55  55  ",
      "         5555   ",
      "                ",
      "                ",
      "                ",
      "                ",
      "                ",
      "                ",
      "                ",
      "                "
    ],
    [
      "                ",
      "                ",
      "                ",
      "          55    ",
      "         5555   ",
      "        555555  ",
      "        555555  ",
      "         5555   ",
      "           &    ",
      "                ",
      "                ",
      "                ",
      "                ",
      "                ",
      "                ",
      "                "
    ],
    [
      "                ",
      "                ",
      "                ",
      "                ",
      "          55    ",
      "         5555   ",
      "         5555   ",
      "         &55&   ",
      "          &&    ",
      "                ",
      "                ",
      "                ",
      "                ",
      "                ",
      "                ",
      "                "
    ]
  ]
}