{
  "xsize": 16,
  "zsize": 16,
  "refpalette": "lostcities:factory",
  "slices": [
    [
      "                ",
      "                ",
      "          ! !!!!",
      "          !!XXXX",
      "       &!!XXXXXX",
      "      &!XXXXXXXX",
      "     !!XXXXXXXXX",
      "    &!XXXXXXXXXX",
      "   &!XXXXXXXXXXX",
      "    !XXXXXXXXXXX",
      "  !!XXXXXXXXXXXX",
      "   !XXXXXXXXXXXX",
      "  !XXXXXXXXXXXXX",
      "  !XXXXXXXXXXXXX",
      "  !XXXXXXXXXXXXX",
      "  !XXXXXXXXXXXXX"
    ],
    [
      "                ",
      "                ",
      "          !     ",
      "            XXXX",
      "       && XX    ",
      "      &&XX      ",
      "     ! X&      &",
      "    &&X       &&",
      "   &&X&       &&",
      "    &X         &",
      "  ! X   &       ",
      "    X  &&&&     ",
      "   X    &&&&    ",
      "   X      &     ",
      "   X            ",
      "   X            "
    ],
    [
      "                ",
      "                ",
      "          !     ",
      "            XXXX",
      "        &&XX    ",
      "       &XX&     ",
      "     ! X&&    &&",
      "     &X      &&&",
      "    &X&       &&",
      "    &X&        &",
      "  ! X& &&       ",
      "    X &&&&&     ",
      "   X   &&&&&    ",
      "   X     &&     ",
      "   X            ",
      "   X            "
    ],
    [
      "                ",
      "                ",
      "          !     ",
      "            XXXX",
      "         &XX    ",
      "        XX&     ",
      "     ! X &    &&",
      "      X      &&&",
      "     X        &&",
      "    &X&&        ",
      "  ! X&&&&       ",
      "    X &&&&      ",
      "   X   &&&&     ",
      "   X     &      ",
      "   X            ",
      "   X            "
    ],
    [
      "                ",
      "                ",
      "          !     ",
      "          & XXXX",
      "         &XX    ",
      "        XX&&  & ",
      "     ! X &&  &&&",
      "      X      &&&",
      "     X        &&",
      "    &X&&        ",
      "  ! X&&&&       ",
      "    X  & &      ",
      "   X    &&&     ",
      "   X     &      ",
      "   X            ",
      "   X            "
    ],
    [
      "                ",
      "                ",
      "          !     ",
      "          & XXXX",
      "         &XX    ",
      "        XX&   & ",
      "     ! X     &&&",
      "      X       &&",
      "     X         &",
      "    &X&&        ",
      "  ! X&&&&       ",
      "    X  & &      ",
      "   X    &&&     ",
      "   X     &      ",
      "   X            ",
      "   X            "
    ]
  ]
}