{
  "xsize": 16,
  "zsize": 16,
  "refpalette": "pomkotsmechs:factory",
  "slices": [
    [
      "                ",
      "                ",
      "                ",
      "           &    ",
      "          &&&   ",
      "          &&&&&&",
      "           &&&&&",
      "       !  !   &&",
      "        rr     &",
      "        rr      ",
      "       !!!!     ",
      "                ",
      "               J",
      "   &          JJ",
      "  &&&&&      JJ ",
      "   &&&&&   &Jr  "
    ],
    [
      "                ",
      "                ",
      "                ",
      "           &    ",
      "          &&&&& ",
      "           &&&&&",
      "             &&&",
      "       !  !   &&",
      "        rr      ",
      "        rr      ",
      "       !!!!     ",
      "                ",
      "               J",
      "   &          JJ",
      "  &&&&       JJ ",
      "   &&&&    &Jr  "
    ],
    [
      "                ",
      "                ",
      "               J",
      "           & JJJ",
      "          &JJJJ ",
      "          JJJ&&&",
      "        JJJJ && ",
      "       JJJJ     ",
      "      JJJJJ     ",
      "      JJJJJ     ",
      "     JJJJJ!     ",
      "    JJJ         ",
      "    JJ         J",
      "   JJ         JJ",
      "  &JJ        JJJ",
      "  JJ&&      JrJJ"
    ],
    [
      "                ",
      "                ",
      "               J",
      "           &&JJJ",
      "          &JJJJ ",
      "          JJJ&& ",
      "        JJJJ    ",
      "       JJJ!     ",
      "      JJJr      ",
      "      JJrr      ",
      "     JJ!  !     ",
      "    JJJ         ",
      "    JJ         J",
      "   JJ         JJ",
      "  &JJ        JJ ",
      "  JJ&       Jr  "
    ],
    [
      "                ",
      "                ",
      "                ",
      "                ",
      "           &&&  ",
      "                ",
      "                ",
      "       !  !     ",
      "        rr      ",
      "        rr      ",
      "       !  !     ",
      "                ",
      "               J",
      "              Jr",
      "             Jr ",
      "  &&        Jr  "
    ],
    [
      "                ",
      "                ",
      "                ",
      "                ",
      "                ",
      "                ",
      "                ",
      "       !  !     ",
      "        rr      ",
      "        rr      ",
      "       !  !     ",
      "                ",
      "               J",
      "              JJ",
      "             JJ ",
      "            Jr  "
    ]
  ]
}