{
  "xsize": 16,
  "zsize": 16,
  "refpalette": "pomkotsmechs:factory",
  "slices": [
    [
      "tttttttttttttttt",
      "t      P5P &   t",
      "t     VVVV&&&& t",
      "t   VV    VV&   ",
      "t  V       &V   ",
      "t  V        V   ",
      "tPV    &&&&     ",
      "t5V   &&&&   V  ",
      "tPV  &&&&    V  ",
      "t V  &&&    &V  ",
      "t  V       &V&  ",
      "t &V&      &V& t",
      "t  &VV    VV&  t",
      "t     VVVV     t",
      "t     P5P      t",
      "tttttttttttttttt"
    ],
    [
      "t              t",
      "       P5P      ",
      "      VVVV &&   ",
      "    VV    VV&   ",
      "   V       &V&  ",
      "   V     &&&V   ",
      " PV    &&&&&    ",
      " 5V   &&&&&     ",
      "&PV   &&&&   V  ",
      "  V    &    &V  ",
      "   V       &V&  ",
      "  &V&&     &V&  ",
      "   &VV&   VV&   ",
      "     &VVVV      ",
      "      P5P       ",
      "t              t"
    ],
    [
      "t              t",
      "       P5P      ",
      "      VVVV      ",
      "   &VV    VV&   ",
      "  &V&      &V&  ",
      "   V      &&V&  ",
      " PV     &&&&&   ",
      " 5V    &&&&& V  ",
      " PV    &&&   V5 ",
      "  V         &VP ",
      "   V&      &V&  ",
      "  &V&&&     V   ",
      "   &VV&&  VV    ",
      "    &&VVVV      ",
      "     &P5P       ",
      "t     &        t"
    ],
    [
      "t              t",
      "       P5P      ",
      "   && VVVV      ",
      "  &&VV    V     ",
      "  &V&      &&   ",
      "   V     &&&V&  ",
      " PV     &&&&&V  ",
      " 5V     &&&  VP ",
      " PV      &   V5&",
      "  V         &VP&",
      "   V       &V&& ",
      "   V&       V&  ",
      "    VV&   VV    ",
      "      VVVV      ",
      "     &P5P       ",
      "t     &        t"
    ],
    [
      "t              t",
      "    &!!!!!!     ",
      "   &!!VVVV!     ",
      "   !VV    V     ",
      "  !V&      &    ",
      " !!V      &&&   ",
      " !V      &&&&V! ",
      " !V      &&& V! ",
      " !V          V! ",
      " !V          V! ",
      " !!V        V!! ",
      "  !V        V!  ",
      "   !VV    VV!   ",
      "    !!VVVV!!    ",
      "     !!!!!!     ",
      "t              t"
    ],
    [
      "t    &         t",
      "    &!!!!!!     ",
      "   &!!VVVV!     ",
      "   !VV    V     ",
      "  !V       &&   ",
      " !!V      &&V&  ",
      " !V       &&&V! ",
      " !V          V! ",
      " !V          V! ",
      " !V          V! ",
      " !!V        V!! ",
      "  !V        V!  ",
      "   !VV    VV!   ",
      "    !!VVVV!!    ",
      "     !!!!!!     ",
      "t              t"
    ]
  ]
}