{
  "xsize": 16,
  "zsize": 16,
  "refpalette": "lostcities:factory",
  "slices": [
    [
      "ZVVVVVVVVVVVVVVV",
      "VVVVVVVVVVVVVVVV",
      "VVVVVVVVVVVVVVVV",
      "VVVVVVVVVVVVVVVV",
      "VVVVVVVVVVVVVVVV",
      "VVVVVVVVVVVVVVVV",
      "VVVVVVVVVVVVVVVV",
      "VVVVVVVVVVVVVVVV",
      "VVVVVVVVVVVVVVVV",
      "VVVVVVVVVVVVVVVV",
      "VVVVVVVVVVVVVVVV",
      "VVVVVVVVVVVVVVVV",
      "VVVVVVVVVVVVVVVV",
      "VVVVVVVVVVVVVVVV",
      "VVVVVVVVVVVVVVVV",
      "VVVVVVVVVVVVVVVV"
    ],
    [
      "!!         !!  !",
      "!!!!!!!!!!!!!!!!",
      "!!!!!!!!!!!!!  !",
      "!!!           VV",
      "!!!VVVVVVVVVVVVV",
      " !!!!!!!!!!!!!!V",
      " !!JJJJJJJJJJJJ!",
      " !!JJJJJJJJJJJJ!",
      "&!!JJJJJJJJJJJJ!",
      "&!!JJJJJJJJJJJJ!",
      "&!!JJJJJJJJJJJJ!",
      " !!JJJJJJJJJJJJ!",
      " !!JJJJJJJJJJJJ!",
      " !!JJJJJJJJJJJJ!",
      " !!JJJJJJJJJJJJ!",
      " !!JJJJJJJJJJJJ!"
    ],
    [
      "$!         !!  !",
      " ![[[[[[[[[!!!!!",
      " !        !!!  !",
      "!!!             ",
      "!!!,,,,,,,,,,,,V",
      " ]!            V",
      " ] JJJJJJJJJJJJ ",
      " ] J          J5",
      " ] J          J5",
      "&]&J          J5",
      " ] J          J ",
      " ] J          J&",
      " ] J         &J&",
      " ] J          J&",
      " ] J          J ",
      " ] J          J "
    ],
    [
      " !         !!  !",
      " ![[[[[[[[[!!!!!",
      " !        !!!  !",
      "!!!             ",
      "!!!            +",
      " ]!            2",
      " ] JJJJJJJJJJJJ ",
      " ] J          J ",
      " ] J          J5",
      "&]&J          J ",
      " ] J          J ",
      " ] J          J ",
      " ] J         &J&",
      " ] J          J ",
      " ] J          J ",
      " ] J          J "
    ],
    [
      " !         !!  !",
      " ![[[[[[[[[!!!!!",
      " !        !!!  !",
      "!!!             ",
      "!!!            +",
      " ]!            2",
      " ] JJJJJJJJJJJJ ",
      " ] J          J ",
      " ] J          J5",
      "&]&J          J ",
      " ] J          J ",
      " ] J          J ",
      " ] J         &J&",
      " ] J          J ",
      " ] J          J ",
      " ] J          J "
    ],
    [
      "$!         !!  !",
      " ![[[[[[[[[!!!!!",
      " !        !!!  !",
      "!!!             ",
      "!!!            +",
      " ]!            2",
      " ] JJJJJJJJJJJJ ",
      " ] J          J ",
      " ] J          J5",
      "&]&J          J ",
      " ] J          J ",
      " ] J          J ",
      " ] J         &J&",
      " ] J          J ",
      " ] J          J ",
      " ] J          J "
    ]
  ]
}