{
  "xsize": 16,
  "zsize": 16,
  "refpalette": "lostcities:factory",
  "slices": [
    [
      "!!!!!!!!!!!!!!!!",
      "!!!!!!!!!!!!!!!!",
      "!!!!!!!!!!!!!!!!",
      "!!!!!!!!!!!!!!!!",
      "!!!!!!!!!!!!!!!!",
      "!!!!!!!!!!!!!!!!",
      "!!!!!!!!!!!!!!!!",
      "!!!!!!!!!!!!!!!!",
      "!!!!!!!!!!!!!!!!",
      "!!!!!!!!!!!!!!!!",
      "!!!!!!!!#!!!!!!!",
      "!!!!!!!!!!!!!!!!",
      "!!!!!!!!!!!!!!!!",
      "!!!!!!!!!!!!!!!!",
      "!!!!!!!!!!!!!!!!",
      "!!!!!!!!!!!!!!!!"
    ],
    [
      "$$$          $$$",
      "$!$          $!$",
      "$$$          $$$",
      "     &&&&&      ",
      "                ",
      "                ",
      " &&    '( $     ",
      "&&&&   !!!      ",
      " &&      !      ",
      "       ! !      ",
      "                ",
      "                ",
      "                ",
      "$$$          $$$",
      "$!$          $!$",
      "$$$          $$$"
    ],
    [
      " $            $ ",
      "$!$          $!$",
      " $            $ ",
      "                ",
      "                ",
      "                ",
      " &      ')$     ",
      "&&&    +,/      ",
      " &     0 0      ",
      "       2,3      ",
      "                ",
      "                ",
      "                ",
      " $            $ ",
      "$!$          $!$",
      " $            $ "
    ],
    [
      "                ",
      " !            ! ",
      "                ",
      "                ",
      "                ",
      "                ",
      " &       '5     ",
      "&&&    +,/6     ",
      " &     0 0      ",
      "       7 7      ",
      "                ",
      "                ",
      "                ",
      "                ",
      " !            ! ",
      "                "
    ],
    [
      "                ",
      " !            ! ",
      "                ",
      "                ",
      "                ",
      "                ",
      " &              ",
      "&&&    +,/8     ",
      " &     0 06     ",
      "       2,3      ",
      "          $     ",
      "                ",
      "                ",
      "                ",
      " !            ! ",
      "                "
    ],
    [
      "                ",
      " !            ! ",
      "                ",
      "                ",
      "                ",
      " &            & ",
      "&&            & ",
      "&&&    +,/      ",
      "&&     0 08     ",
      "       2,36     ",
      "          $     ",
      "                ",
      "                ",
      "        &       ",
      " !      &     ! ",
      "                "
    ]
  ]
}