{
  "xsize": 16,
  "zsize": 16,
  "refpalette": "lostcities:factory",
  "slices": [
    [
      "vvvvvvvvvvvvvvvv",
      "vvvvvvvvvvvvvvvv",
      "vvvvvvvvvvvvvvvv",
      "vvvvvvvvv!!vvvvv",
      "vvvvvvvvv!!vvvvv",
      "vvvvvvvvvvvvvvvv",
      "vvvvvvvvvvvvvvvv",
      "vvvvvvvvvvvvvvvv",
      "vvvvvvvvvvvvvvvv",
      "vvv!!vvvvvvvvvvv",
      "vvv!!vvvvvvvvvvv",
      "vvvvvvvvvvvvvvvv",
      "vvvvvvvvvvvvvvvv",
      "vvvvvvvvvvvvvvvv",
      "vvvvvvvvvvvvvvvv",
      "vvvvvvvvvvvvvvvv"
    ],
    [
      "                ",
      "                ",
      "                ",
      "         !!     ",
      "         !!     ",
      "                ",
      "                ",
      "                ",
      "   &            ",
      "   !!           ",
      "   !!           ",
      "                ",
      "                ",
      "                ",
      "                ",
      "                "
    ],
    [
      "                ",
      "                ",
      "                ",
      "         !!     ",
      "         !!     ",
      "                ",
      "                ",
      "                ",
      "   &            ",
      "  &!!           ",
      "   !!           ",
      "                ",
      "                ",
      "                ",
      "                ",
      "                "
    ],
    [
      "                ",
      "                ",
      "                ",
      "         !!     ",
      "         !!     ",
      "                ",
      "                ",
      "                ",
      "                ",
      "  &!!           ",
      "   !!           ",
      "                ",
      "                ",
      "                ",
      "                ",
      "                "
    ],
    [
      "                ",
      "                ",
      "                ",
      "         !! !!!!",
      "         !!!!   ",
      "        !!      ",
      "       !!       ",
      "      !!        ",
      "     !!         ",
      "  &!!!          ",
      "   !!           ",
      "    !           ",
      "   !!         QQ",
      "   !         QQQ",
      "   !        QQQQ",
      "   !        QQQQ"
    ],
    [
      "                ",
      "                ",
      "                ",
      "         !! !!!!",
      "         !!!!   ",
      "        !!      ",
      "       !!       ",
      "      !!        ",
      "     !!         ",
      "  &!!!         Q",
      "   !!       QQQQ",
      "    !      QQQQQ",
      "   !!     QQQQQQ",
      "   !      QQQQQQ",
      "   !      QQQQQQ",
      "   !     QQQQQQQ"
    ]
  ]
}