{
  "xsize": 16,
  "zsize": 16,
  "refpalette": "pomkotsmechs:factory",
  "slices": [
    [
      "VVVVVVVVVVVVVVVV",
      "VVVVVVVVVVVVVVVV",
      "VVVVVVVVVVVVVVVV",
      "VVVVVVVVVVVVVVVV",
      "VVVVVVVVVVVVVVVV",
      "VVVVVVVVVVVVVVVV",
      "VVVVVVVVVVVVVVVV",
      "VVVVVVVVVVVVVVVV",
      "VVVVVVVVVVVVVVVV",
      "VVVVVVVVVVVVVVVV",
      "VVVVVVVVVVVVVVVV",
      "VVVVVVVVVVVVVVVV",
      "VVVVVVVVVVVVVVVV",
      "VVVVVVVVVVVVVVVV",
      "VVVVVVVVVVVVVVVV",
      "VVVVVVVVVVVVVVVV"
    ],
    [
      "!!!!!!!!!!!!!!! ",
      "!!!!!!!!!!!!!!! ",
      "!!!!!!!!!!!!!!! ",
      "!!!!!!!!!!!!!!! ",
      "!!!!!!!!!!!!!!! ",
      "V!!!!!!!!!!!!!! ",
      "VVVVVVVVVVVVV!!!",
      "VV   &       !!!",
      "    &&&       ! ",
      "     &&       ! ",
      "VV   &&&     !!!",
      "VVVVVVVVVVVVV!!!",
      "V     &      !! ",
      "              ! ",
      "              ! ",
      "              ! "
    ],
    [
      " JJJJJJJJJJJJ i ",
      " JJJJJJJJJJJJ i ",
      " JJJJJJJJJJJJ i ",
      " JJJJJJJJJJJJ i ",
      " JJJJJJJJJJJJ i ",
      "V            !i ",
      "V,,,,,,,,,,,,!!!",
      "     &       !!!",
      "    &&&       ! ",
      "     &&&      ! ",
      "     &&&     !!!",
      "V,,,,,,,,,,,,!!!",
      "V            !i ",
      "              i ",
      "              i ",
      "              i "
    ],
    [
      " J          J i ",
      " J          J i ",
      " J          J i ",
      " J          J i ",
      " JJJJJJJJJJJJ i ",
      "/            !i ",
      "3    &       !!!",
      "    &&&      !!!",
      "    &&&       ! ",
      "     &&&      ! ",
      "      &      !!!",
      "/            !!!",
      "3            !i ",
      "              i ",
      "              i ",
      "              i "
    ],
    [
      " J          J i ",
      " J          J i ",
      " J          J i ",
      " J          J i ",
      " JJJJJJJJJJJJ i ",
      "/            !i ",
      "3    &       !!!",
      "    &&&      !!!",
      "    &&&       ! ",
      "     &&&      ! ",
      "      &      !!!",
      "/            !!!",
      "3            !i ",
      "              i ",
      "              i ",
      "              i "
    ],
    [
      " J          J i ",
      " J          J i ",
      " J          J i ",
      " J          J i ",
      " JJJJJJJJJJJJ i ",
      "/            !i ",
      "3    &       !!!",
      "    &&&      !!!",
      "    &&&       ! ",
      "     &&&      ! ",
      "      &      !!!",
      "/            !!!",
      "3            !i ",
      "              i ",
      "              i ",
      "              i "
    ]
  ]
}