{
  "xsize": 16,
  "zsize": 16,
  "refpalette": "pomkotsmechs:factory",
  "slices": [
    [
      "                ",
      "                ",
      "                ",
      "      OOOO      ",
      "     OOOOOO     ",
      "     OOOOOOO    ",
      "    OOOOOOOO    ",
      "   &OOOOOOOO    ",
      "    OOOOOOOO    ",
      "     OOOOOO     ",
      "      OOOO      ",
      "                ",
      "                ",
      "                ",
      "                ",
      "                "
    ],
    [
      "                ",
      "                ",
      "                ",
      "      OOOO      ",
      "     O && O     ",
      "    O &&&  O    ",
      "    O&&&&  O    ",
      "    O&&&   O    ",
      "    O&     O    ",
      "    &O&   O     ",
      "     &OOOO      ",
      "                ",
      "                ",
      "                ",
      "                ",
      "                "
    ],
    [
      "                ",
      "                ",
      "                ",
      "      OOOO      ",
      "     O    O     ",
      "    O &&   O    ",
      "    O&&&   O    ",
      "    O&&&   O    ",
      "   &O&&    O    ",
      "   &&O&   O     ",
      "    &&OOOO      ",
      "                ",
      "                ",
      "                ",
      "                ",
      "                "
    ],
    [
      "                ",
      "                ",
      "                ",
      "      OOOO      ",
      "     OO  OO     ",
      "    OO    OO    ",
      "    O&&    O    ",
      "    &&&    O    ",
      "   &&O&   OO    ",
      "    &OO  OO     ",
      "      OOOO      ",
      "                ",
      "                ",
      "                ",
      "                ",
      "                "
    ],
    [
      "                ",
      "                ",
      "                ",
      "      OOOO      ",
      "     OO  OO     ",
      "    OO    OO    ",
      "    O      O    ",
      "     &     O    ",
      "    &O    OO    ",
      "     OO  OO     ",
      "      OOOO      ",
      "                ",
      "                ",
      "                ",
      "                ",
      "                "
    ],
    [
      "                ",
      "                ",
      "                ",
      "      OOOO      ",
      "     OO  OO     ",
      "    OO    OO    ",
      "    O      O    ",
      "           O    ",
      "     O    OO    ",
      "     OO  OO     ",
      "      OOOO      ",
      "                ",
      "                ",
      "                ",
      "                ",
      "                "
    ]
  ]
}