{
  "xsize": 16,
  "zsize": 16,
  "refpalette": "pomkotsmechs:factory",
  "slices": [
    [
      "                ",
      "   OVVVVV       ",
      "   V            ",
      "   V            ",
      "   V        &   ",
      "  &V&           ",
      "   V            ",
      "   V     && &   ",
      "   V    &&&&&&  ",
      "   V     && V   ",
      "   V        V   ",
      "   O        O   ",
      "   V        V   ",
      "   V        V   ",
      "   V        V   ",
      "   V        V   "
    ],
    [
      "                ",
      "   OVVVVV       ",
      "   V            ",
      "   V            ",
      "   V            ",
      "  &V&           ",
      "   V            ",
      "   V&     & &   ",
      "   V&    &&&V&  ",
      "   V&&   &&&V   ",
      "   V &  && &V   ",
      "   O &  &&&&O   ",
      "   V && &&  V   ",
      "   V  &&&   V   ",
      "   V  &&    V   ",
      "   V   &    V   "
    ],
    [
      "                ",
      "   OOOOOO       ",
      "   OVVVVV       ",
      "   OVVVVV       ",
      "   OVVVVVV      ",
      "  &OVVVVVV      ",
      "  &OVVVVVV      ",
      "  &OVVVVVV& O   ",
      "   OVVVVVVVVO&  ",
      "   OVVVVVVVVO&  ",
      "   OVVVVVVVVO   ",
      "   OOOOOOOOOO   ",
      "   OVVVVVVVVO   ",
      "   OVVVVVVVVO   ",
      "   OVVVVVVVVO   ",
      "   OVVVVVVVVO   "
    ],
    [
      "                ",
      "                ",
      "                ",
      "                ",
      "                ",
      "   &            ",
      "   &            ",
      "   &&           ",
      "    &     & &   ",
      "    &&   &&&&   ",
      "     &  && &    ",
      "     & &&&&&    ",
      "     &&&&&      ",
      "      &&&       ",
      "      &&        ",
      "       &        "
    ],
    [
      "                ",
      "                ",
      "                ",
      "                ",
      "                ",
      "                ",
      "                ",
      "                ",
      "                ",
      "                ",
      "                ",
      "        &&      ",
      "        &       ",
      "                ",
      "                ",
      "                "
    ],
    [
      "                ",
      "                ",
      "                ",
      "                ",
      "                ",
      "                ",
      "                ",
      "                ",
      "                ",
      "                ",
      "                ",
      "                ",
      "                ",
      "                ",
      "                ",
      "                "
    ]
  ]
}