{
  "xsize": 16,
  "zsize": 16,
  "refpalette": "lostcities:factory",
  "slices": [
    [
      " ]             V",
      " ]             V",
      " ]             V",
      " ]!V     VVVVVVV",
      "!!!VV   VVVVVVVV",
      "!!!mm    mmmmmmm",
      " !              ",
      " !              ",
      "!!!jjj   jjjjjjj",
      "!!!VVV   VVVVVVV",
      " ]!VVVV VVVVVVVV",
      " ]             V",
      " ]             V",
      " ]             V",
      " ]             V",
      " ]             V"
    ],
    [
      " ]              ",
      " ]              ",
      " ]              ",
      " ]!            +",
      "!!!            n",
      "!!!,,    ,,,,,,m",
      " !              ",
      " !              ",
      "!!!,,     ,,,,,j",
      "!!!            k",
      " ]!            2",
      " ]              ",
      " ]              ",
      " ]              ",
      " ]              ",
      "                "
    ],
    [
      " ]              ",
      " ]              ",
      " ]              ",
      " ]!            +",
      "!!!            2",
      "!!!             ",
      " !              ",
      " !              ",
      "!!!             ",
      "!!!            +",
      " ]!            2",
      " ]              ",
      " ]              ",
      " ]              ",
      "                ",
      "                "
    ],
    [
      " ]              ",
      " ]              ",
      " ]              ",
      " ]!            +",
      "!!!            2",
      "!!!             ",
      " !              ",
      " !              ",
      "!!!             ",
      "!!!            +",
      " ]!            2",
      " ]              ",
      " ]              ",
      " ]              ",
      "                ",
      "                "
    ],
    [
      " ]              ",
      " ]              ",
      " ]              ",
      " ]!            +",
      "!!!            2",
      "!!!             ",
      " !              ",
      " !              ",
      "!!!             ",
      "!!!            +",
      " ]!            2",
      " ]              ",
      " ]              ",
      "                ",
      "                ",
      "                "
    ],
    [
      " ]              ",
      " ]              ",
      " ]              ",
      " ]!            +",
      "!!!            2",
      "!!!             ",
      " !              ",
      " !              ",
      "!!!             ",
      "!!!            +",
      " ]!            2",
      " ]              ",
      "                ",
      "                ",
      "                ",
      "                "
    ]
  ]
}