{
  "xsize": 16,
  "zsize": 16,
  "refpalette": "pomkotsmechs:factory",
  "slices": [
    [
      "                ",
      "                ",
      "                ",
      "                ",
      "                ",
      "                ",
      "      !  !      ",
      "       !!       ",
      "       !!       ",
      "      !  !      ",
      "                ",
      "  &             ",
      "                ",
      "                ",
      "                ",
      "                "
    ],
    [
      "                ",
      "                ",
      "vvvvvvvvvvvvvvvv",
      "vvvvvvvvvvvvvvv}",
      "VvvvVz}}|vvvvv}}",
      "VVVVz|}}||vvv}}}",
      "zVVz|||||zzvv}}}",
      "zzz|}}|zzVz|v}}}",
      "Vz|}}}|zVVz|}}}}",
      "VVz}}}|VvvV|}}}}",
      "vVz|}|zVvvV|}v||",
      "vVv|||zVVVzz|vzz",
      "VVzz||zzVzzzzvvV",
      "VVzz|||||||zVvvv",
      "VVz||||||||zVvvv",
      "VVz||}}}}||zVvvv"
    ],
    [
      "                ",
      "                ",
      "                ",
      "                ",
      "                ",
      "                ",
      "                ",
      "                ",
      "                ",
      "                ",
      "  &             ",
      " &&&            ",
      "555             ",
      "   5            ",
      "    5           ",
      "    5          5"
    ],
    [
      "                ",
      "                ",
      "                ",
      "                ",
      "                ",
      "                ",
      "                ",
      "                ",
      "                ",
      "                ",
      "  &             ",
      " &&&            ",
      "555             ",
      "   5            ",
      "    5           ",
      "    5          5"
    ],
    [
      "                ",
      "                ",
      "                ",
      "                ",
      "                ",
      "                ",
      "                ",
      "                ",
      "                ",
      "                ",
      "  &             ",
      " &&&            ",
      "555             ",
      "   5            ",
      "    5           ",
      "    5          5"
    ],
    [
      "                ",
      "                ",
      "                ",
      "                ",
      "                ",
      "                ",
      "                ",
      "                ",
      "                ",
      "                ",
      " &&             ",
      "555&            ",
      "5555            ",
      "   55           ",
      "    5           ",
      "    5          5"
    ]
  ]
}