{
  "xsize": 16,
  "zsize": 16,
  "refpalette": "pomkotsmechs:factory",
  "slices": [
    [
      "                ",
      "   &!!      !!  ",
      "  &!OO!    !OO! ",
      "  !O  O!  !O  O!",
      "  !O  O!  !O  O!",
      "   !OO!5555!OO! ",
      "  55!!      !!55",
      "55              ",
      "                ",
      "                ",
      "                ",
      "                ",
      "                ",
      "                ",
      "                ",
      "&               "
    ],
    [
      "                ",
      "   &&           ",
      "  &&OO      OO  ",
      "   O& O    O  O ",
      "   O  O    O  O ",
      "    OO555555OO  ",
      "  555        555",
      "55              ",
      "                ",
      "                ",
      "                ",
      "                ",
      "                ",
      "                ",
      "                ",
      "&               "
    ],
    [
      "                ",
      "    &           ",
      "   &OO      OO  ",
      "   O& O    O  O ",
      "   O  O    O  O ",
      "    OO555555OO  ",
      "  555        555",
      "55              ",
      "                ",
      "                ",
      "                ",
      "                ",
      "                ",
      "                ",
      "                ",
      "                "
    ],
    [
      "                ",
      "    &           ",
      "   &OO      OO  ",
      "   O& O    O  O ",
      "   O  O    O  O ",
      "    OO!!!!!!OO  ",
      "  !!!!!!!!!!!!!!",
      "!!!!!!!!!!!!!!!!",
      "!!!!!!!!!!!!!!!!",
      "!!!!!!!!!!!!!!!!",
      "!!!!!!!!!!!!!!!!",
      "!!!!!!!!!!!!!!!!",
      "!!!!!!!!!!!!!!!!",
      "!!!!!!!!!!!!!!!!",
      " !!!!!!!!!!!!!!!",
      " !!!!!!!!!!!!!!!"
    ],
    [
      "                ",
      "    &&          ",
      "   &OO&     OO  ",
      "   O&&O    O  O ",
      "   O  O    O  O ",
      "    OO      OO  ",
      "                ",
      "     55!!!!55   ",
      "   !!!!!!!!!!!! ",
      " !!!!!!!!!!!!!!!",
      "!!!!!!!!!!!!!!!!",
      "!!!!!!!!!!!!!!!!",
      "  !!!!!!!!!!!!!!",
      "  !!!!!!!!!!!!!!",
      "  !!!!!!!!!!!!!!",
      "& !!!!!!!!!!!!!!"
    ],
    [
      "                ",
      "     &&         ",
      "    OO&&    OO  ",
      "   OOOO    OOOO ",
      "   OOOO    OOOO ",
      "    OO      OO  ",
      "                ",
      "                ",
      "     55    55   ",
      "    OO5    5OO  ",
      "   OOOO!!!!OOOO ",
      "  !OOOO!!!!OOOO!",
      "   !OO!!!!!!OO!!",
      "   !!!!!!!!!!!!!",
      "   !!!!!!!!!!!!!",
      "   !!!!!!!!!!!!!"
    ]
  ]
}