{
  "xsize": 16,
  "zsize": 16,
  "refpalette": "pomkotsmechs:factory",
  "slices": [
    [
      "!           !!! ",
      "           !!!!!",
      "            !!! ",
      "   !  !      !  ",
      "    rr      &J& ",
      "    rr       J  ",
      "   !  !      J  ",
      "             J! ",
      "             J  ",
      "             J  ",
      "     &       J  ",
      " !  &&&      !  ",
      "!!!  &      !!! ",
      "!!!!JJ&  JJ!!!!!",
      "!!!  &      !!! ",
      " !           !  "
    ],
    [
      "!           !!! ",
      "           !!!!!",
      "            !!! ",
      "   !  !      !  ",
      "    rr      &!& ",
      "    rr       !  ",
      "   !  !      !  ",
      "             !! ",
      "             !  ",
      "             !  ",
      "     &       !  ",
      " !  &&&      !  ",
      "!!! &&&     !!! ",
      "!!!!!&    !!!!!!",
      "!!!         !!! ",
      " !           !  "
    ],
    [
      "!           !!! ",
      "           !!!!!",
      "            !!! ",
      "   !  !      !  ",
      "    rr      &J& ",
      "    rr       J  ",
      "   !  !      J  ",
      "             J! ",
      "             J  ",
      "             J  ",
      "             J  ",
      " !   &       !  ",
      "!!! &&&     !!! ",
      "!!!!J&    J!!!!!",
      "!!!         !!! ",
      " !           !  "
    ],
    [
      "!           !!! ",
      "           !!!!!",
      "            !!! ",
      "   !  !      !  ",
      "    rr      &J& ",
      "    rr       J  ",
      "   !  !      J  ",
      "             J! ",
      "             J  ",
      "             J  ",
      "             J  ",
      " !   &       !  ",
      "!!! &&&     !!! ",
      "!!!!J&    J!!!!!",
      "!!!         !!! ",
      " !           !  "
    ],
    [
      "!          !!!!!",
      "           !!!!!",
      "           !!!!!",
      "   !  !     !!! ",
      "    rr      &!& ",
      "    rr       !  ",
      "   !  !      !  ",
      "             !! ",
      "             !  ",
      "             !  ",
      "             !  ",
      "!!!  &      !!! ",
      "!!! &&&    !!!!!",
      "!!!! &   !!!!!!!",
      "!!!        !!!!!",
      "!!!         !!! "
    ],
    [
      "!           !!! ",
      "           !!!!!",
      "            !!! ",
      "   !JJ!      !  ",
      "   JrrJ     &J& ",
      "   JrrJ      J  ",
      "   !JJ!      J  ",
      "             J! ",
      "             J  ",
      "             J  ",
      "             J  ",
      " !   &       !  ",
      "!!  &&&     !!! ",
      "!!!  &   JJ!!!!!",
      "!!          !!! ",
      " !           !  "
    ]
  ]
}