{
  "xsize": 16,
  "zsize": 16,
  "refpalette": "lostcities:factory",
  "slices": [
    [
      "Vo    VVVV    kV",
      "Vo    VVVV    kV",
      "VnjjjjVVVVjjjjnV",
      "VVVVVVVVVVVVVVVV",
      "VVVVVVVVVVVVVVVV",
      "VVVVVVVVVVVVVVVV",
      "mmmmmmmmmmmmmmmm",
      "                ",
      " !            ! ",
      "                ",
      "                ",
      "                ",
      "                ",
      "                ",
      "                ",
      "                "
    ],
    [
      " 0    0  0    0 ",
      " 0    0  0    0 ",
      " 2,,,,3  2,,,,3 ",
      "                ",
      "                ",
      "                ",
      ",,,,,,,,,,,,,,,,",
      "                ",
      "!!!!        !!!!",
      "!!!!        !!!!",
      "!!!!        !!!!",
      "!!!!       &!!!!",
      "!!!!        !!!!",
      "             && ",
      "                ",
      "                "
    ],
    [
      "                ",
      "                ",
      "                ",
      "                ",
      "                ",
      "                ",
      "                ",
      "                ",
      "     JJJJJJ     ",
      "   JJJJJJJJJJ   ",
      "  JJJJJJJJJJJJ  ",
      " JJJJJJJJJJJJJJ ",
      " JJJJJJJJJJJJJJ ",
      "JJJJJJJJJJJJJJJJ",
      "JJJJJJJJJJJJJJJJ",
      "JJJJJJJJJJJJJJJJ"
    ],
    [
      "                ",
      "                ",
      "                ",
      "                ",
      "                ",
      "                ",
      "                ",
      "                ",
      "     JJJJJJ     ",
      "   JJ      JJ   ",
      "  J        & J  ",
      " J        &&& J ",
      " J         &&&J ",
      "J            &&J",
      "J             &J",
      "J              J"
    ],
    [
      "                ",
      "                ",
      "                ",
      "                ",
      "                ",
      "                ",
      "                ",
      "                ",
      "     JJJJJJ     ",
      "   JJ      JJ   ",
      "  J        & J  ",
      " J        &&& J ",
      " J         &  J ",
      "J            &&J",
      "J             &J",
      "J              J"
    ],
    [
      "                ",
      "                ",
      "                ",
      "                ",
      "                ",
      "                ",
      "                ",
      "                ",
      "     JJJJJJ     ",
      "   JJ      JJ   ",
      "  J        & J  ",
      " J        &&& J ",
      " J         & &J&",
      "J            &&J",
      "J             &J",
      "J              J"
    ]
  ]
}