{
  "xsize": 16,
  "zsize": 16,
  "refpalette": "pomkotsmechs:factory",
  "slices": [
    [
      "!!!!!!!!!!!     ",
      "!!!!!!!!!!!!   !",
      "!!!!!!!!!!!!  &!",
      "!!!!!!!!!!!!! !!",
      "!!!!!!!!!!!!!!!!",
      "!!!!!!!!!!!!!!!!",
      "!!!!!!!!!!<!!!!!",
      "!!!!!!!!!!<!!!!!",
      "!!!!!!!!<!<!!!!!",
      "!!!!!!!!!!8!!!!!",
      "!!!!!!!!#95!!!!!",
      "!!!!!!!!!!!!!!!!",
      "!!!!!!!!!!!!!!!!",
      "!!!!!!!!!!!!!!!!",
      "!!!!!!!!!!!!!!!!",
      "   !!!!!!!!!!!!!"
    ],
    [
      "$$$   &&&       ",
      "$!$    &&&    !$",
      "$$!! !!&!! !!$$$",
      "  !!!!!!!!!!! & ",
      "   !<<<<<<<<!   ",
      "  !!<!!!!!!!!   ",
      "  !!<!!'!!!!!   ",
      " &&!<!!!!!!<!   ",
      "&&!!<!!0!!!!!   ",
      "&&!!<!!!!!!!!&  ",
      "&& !<!!!!!!<!&& ",
      "  !!<!!<!!<!!&&&",
      " !!!!!!!!!!!!  &",
      " $$  &&&     $$$",
      " !    &&     $!$",
      "     &&&&    $$$"
    ],
    [
      " $              ",
      "$!$     &    $!$",
      " $<< <<&<< <<&$&",
      "  << << << << & ",
      "    <<<<<<<<    ",
      "   <<<< << <<   ",
      "  &<<<< << <<   ",
      "  &&<  +,/ <    ",
      " &<<<<<0<< <<   ",
      "  <<<<<2<< <<&  ",
      "    <  &   <&&  ",
      "  <<<<<<<<<<<   ",
      "  << <<&<< <<   ",
      "      &&      $ ",
      "             $!$",
      "      &&      $ "
    ],
    [
      "                ",
      " !      &     !&",
      "  << <<&<< <<&&&",
      "  <<!<<!<<!<< &&",
      "    <<<<<<<<!   ",
      "   <<<<!<<!<<   ",
      "  &<<<<!<<5<<   ",
      "   &<!!+,/6<!   ",
      "  <<<<<0<<!<<&  ",
      "  <<<<<7<<!<<&& ",
      "   !<!!!!!!<!&& ",
      "  <<<<<<<<<<<   ",
      "  <<!<<!<<!<<   ",
      "       &&       ",
      "              ! ",
      "                "
    ],
    [
      "       &&       ",
      " !     &&&    !&",
      "  << <<&<< << &&",
      "  << << << <<  &",
      "    !<<<<<<!    ",
      "  &<<<< <<!<<   ",
      " &&<<<< << <<   ",
      " &&&<  +,/8<    ",
      "  <<<<<0<<6<<&& ",
      "  <<<<<2<< <<&&&",
      "    <!    !< &&&",
      "  <<!<<<<<<<< & ",
      "  << <<&<< <<   ",
      "      &&&&      ",
      "       &&     ! ",
      "                "
    ],
    [
      " $    &&&     $ ",
      "$!$   &&&&   $!$",
      " $<< <<&<< << $&",
      "  << << << << &&",
      "    !!!!!!!! && ",
      " &<<!<<<<<<<<&  ",
      "&&<<!<<<<<<<<   ",
      "&&& !<<+,/<!    ",
      " &<<!<<0<<8<<   ",
      "  <<!<<2<<6<<&&&",
      "    !<<<<<$! &&&",
      "  <<!<<!<<!<< &&",
      "   < <<&<< <<   ",
      "       &&&    $ ",
      "       &&&   $!$",
      "        &     $ "
    ]
  ]
}