{
  "xsize": 16,
  "zsize": 16,
  "refpalette": "lostcities:factory",
  "slices": [
    [
      "VVVVVVVVVVVVVVVV",
      "VVVVVVVVVVVVVVVV",
      "VVVVVVVVVVVVVVVV",
      "VVVVVVVVVVVVVVVV",
      "VVVVVVVVVVVVVVVV",
      "VVVVVVVVVVVVVVVV",
      "VVVVVVVVVVVVVVVV",
      "VVVVVVVVVVVVVVVV",
      "VVVVVVVVVVVVVVVV",
      "VVVVVVVVVVVVVVVV",
      "VVVVVVVVVVVVVVVV",
      "VVVVVVVVVVVVVVVV",
      "VVVVVVVVVVVVVVVV",
      "VVVVVVVVVVVVVVVV",
      "                ",
      "VVVVVVVVVVVVVVVV"
    ],
    [
      "!!!!!!!!!!!!!!! ",
      "!!!!!!!!!!!!!!! ",
      "!!!!!!!!!!!!!!! ",
      "!!!!!!!!!!!!!!! ",
      "!!!!!!!!!!!!!!! ",
      "!!!!!!!!!!!!!!! ",
      "!!!!!!!!!!!!!!! ",
      "!!!!!!!!!!!!!!! ",
      "!!!!!!!!!!!!!!! ",
      "!!!!!!!!!!!!!!! ",
      "V!!!!!!!!!!!!!! ",
      "VVVVVVVVVVVVV!!!",
      "VV           !!!",
      "              ! ",
      "!!!!!!!!!!!!!!!!",
      "!!  !!        !!"
    ],
    [
      " $   $ $   $  i ",
      "              i ",
      "              i ",
      " $   $ $   $  i ",
      "              i ",
      "              i ",
      "              i ",
      " $   $ $   $  i ",
      "              i ",
      "              i ",
      "V            !i ",
      "V,,,,,,,,,,,,!!!",
      "             !!!",
      "              ! ",
      "!!!!!!dddddddd! ",
      "!!  !!        !$"
    ],
    [
      " OOOOO OOOOO  i ",
      "              i ",
      "              i ",
      " OOOOO OOOOO  i ",
      " OOOOO OOOOO  i ",
      " OOOOO OOOOO  i ",
      " OOOOO OOOOO  i ",
      " OOOOO OOOOO  i ",
      "              i ",
      "              i ",
      "/            !i ",
      "3            !!!",
      "             !!!",
      "              ! ",
      "!!!!!!dddddddd! ",
      "!!  !!        ! "
    ],
    [
      " OVVVO OVVVO  i ",
      "             &i&",
      "              i ",
      " OVVVO OVVVO  i ",
      " V   V V   V  i ",
      " V <<V V <<V  i ",
      " VV<<V VV<<V  i ",
      " OVVVO OVVVO  i ",
      "              i ",
      "              i ",
      "/            !i ",
      "3            !!!",
      "             !!!",
      "              ! ",
      "!!!!!!dddddddd! ",
      "!!  !!        ! "
    ],
    [
      " OVVVO OVVVO  i ",
      "             &i&",
      "              i ",
      " OVVVO OVVVO  i ",
      " V   V V   V  i ",
      " V   V V   V  i ",
      " VVVVV VVVVV  i ",
      " OVVVO OVVVO  i ",
      "              i ",
      "              i ",
      "/            !i ",
      "3            !!!",
      "             !!!",
      "              ! ",
      "!!!!!!dddddddd! ",
      "!!  !!        !$"
    ]
  ]
}