{
  "meta": [
    {
      "key": "dontconnect",
      "boolean": true
    }
  ],
  "xsize": 16,
  "zsize": 16,
  "refpalette": "lostcities:factory_common",
  "slices": [
    [
      "SSSSSSSSSSSSSSS#",
      "SSSSSSSSSSSSSSS#",
      "SSSSSSSSSSSSSSS#",
      "SSSSSSSSSSSSSSS#",
      "SSSSSSSSSSSSSSS#",
      "SSSSSSSSSSSSSSS#",
      "SSSSSSSSSSSSSSS#",
      "SSSSSSSSSSSSSSS#",
      "SSSSSSSSSSSSSSS#",
      "SSSSSSSSSSSSSSS#",
      "SSSSSSSSSSSSSSS#",
      "SSSSSSSSSSSSSSS#",
      "SSSSSSSSSSSSSSS#",
      "SSSSSSSSSSSSSSS#",
      "SSSSSSSSSSSSSSS#",
      "SSSSSSSSSSSSSSS#"
    ],
    [
      "#######  #######",
      "#              #",
      "#              #",
      "#              #",
      "#              #",
      "#              #",
      "#              #",
      "#              #",
      "#              #",
      "#              #",
      "#              #",
      "#              #",
      "#              #",
      "#              #",
      "#              #",
      "#######  #######"
    ],
    [
      "#######  #######",
      "#              #",
      "#              #",
      "#              #",
      "#              #",
      "#              #",
      "#              #",
      "#              #",
      "#              #",
      "#              #",
      "#              #",
      "#              #",
      "#              #",
      "#              #",
      "#              #",
      "#######  #######"
    ],
    [
      "################",
      "#              #",
      "#              #",
      "#              #",
      "#              #",
      "#              #",
      "#              #",
      "#              #",
      "#              #",
      "#              #",
      "#              #",
      "#              #",
      "#              #",
      "#              #",
      "#              #",
      "################"
    ],
    [
      "################",
      "#              #",
      "#              #",
      "#              #",
      "#              #",
      "#              #",
      "#              #",
      "#              #",
      "#              #",
      "#              #",
      "#              #",
      "#              #",
      "#              #",
      "#              #",
      "#              #",
      "################"
    ],
    [
      "################",
      "################",
      "################",
      "################",
      "################",
      "################",
      "################",
      "################",
      "################",
      "################",
      "################",
      "################",
      "################",
      "################",
      "################",
      "################"
    ]
  ]
}
