{
  "xsize": 16,
  "zsize": 16,
  "refpalette": "lostcities:factory",
  "slices": [
    [
      "                ",
      "                ",
      "          ! !!!!",
      "         &!!XXXX",
      "        ! &X&&& ",
      "      !!X   &&& ",
      "     !!X    &&&&",
      "     !X      && ",
      "    !X          ",
      "   &!X&         ",
      "  !!X& &&       ",
      "   !X &&&&      ",
      "  !X   &&       ",
      "  !X            ",
      "  !X            ",
      "  !X            "
    ],
    [
      "                ",
      "                ",
      "          !&!!!!",
      "         &&!XXXX",
      "          &&&&  ",
      "      !!    &&& ",
      "     !!      && ",
      "     !          ",
      "    !&          ",
      "   &!&&         ",
      "  !!X& &        ",
      "   !X &&&       ",
      "  !X   &        ",
      "  !X            ",
      "  !X            ",
      "  !X            "
    ],
    [
      "                ",
      "                ",
      "           &&   ",
      "          &&XXXX",
      "           &&XXX",
      "            &XXX",
      "            XXXX",
      "           XXXXX",
      "          XXXXXX",
      "    &&   XXXXXXX",
      "       &XXXXXXXX",
      "    XXXXXXXXXXXX",
      "   XXXXXXXXXXXXX",
      "   XXXXXXXXXXXXX",
      "   XXXXXXXXXXXXX",
      "   XXXXXXXXXXXXX"
    ],
    [
      "                ",
      "                ",
      "                ",
      "           &&   ",
      "             & X",
      "            &&XX",
      "           XXXXX",
      "          XXXXXX",
      "          XXXXXX",
      "         XXXXXXX",
      "       &XXXXXXXX",
      "      &XXXXXXXXX",
      "       XXXXXXXXX",
      "    XXXXXXXXXXXX",
      "    XXXXXXXXXXXX",
      "    XXXXXXXXXXXX"
    ],
    [
      "                ",
      "                ",
      "                ",
      "                ",
      "                ",
      "            &&XX",
      "           &XXXX",
      "           XXXXX",
      "          XXXXXX",
      "          XXXXXX",
      "         XXXXXXX",
      "       &&XXXXXXX",
      "        &XXXXXXX",
      "        XXXXXXXX",
      "     XXXXXXXXXXX",
      "     XXXXXXXXXXX"
    ],
    [
      "                ",
      "                ",
      "                ",
      "                ",
      "                ",
      "                ",
      "            &&  ",
      "             &  ",
      "             &&&",
      "               &",
      "               &",
      "               &",
      "         &&     ",
      "          &&&&&&",
      "          &&&   ",
      "         &&&&   "
    ]
  ]
}