{
  "xsize": 16,
  "zsize": 16,
  "refpalette": "lostcities:factory",
  "slices": [
    [
      "  5       5     ",
      "   5     5      ",
      "    55555       ",
      "              0 ",
      "              0 ",
      "              0 ",
      "              0 ",
      " JJ      JJ   0 ",
      "              0 ",
      "    J  J    J 0 ",
      "    J  J    J 0 ",
      "              0 ",
      " JJ      JJ   0 ",
      "              0 ",
      "              0 ",
      "              0 "
    ],
    [
      "  5       5     ",
      "   5     5      ",
      "    55555       ",
      "              0 ",
      "              0 ",
      "              0 ",
      "              0 ",
      " XX      XX   0 ",
      "XXXX    XXXX  0 ",
      "X  XX  XX  XX 0 ",
      "X  XX  XX  XX 0 ",
      "XXXX    XXXX  0 ",
      " XX      XX   0 ",
      "              0 ",
      "              0 ",
      "              0 "
    ],
    [
      "  5       5     ",
      "   5     5      ",
      "    55555       ",
      "                ",
      "                ",
      "                ",
      "                ",
      " XX      XX     ",
      "XXXX    XXXX    ",
      "X  XX  XX  XX   ",
      "X  XX  XX  XX   ",
      "XXXX    XXXX    ",
      " XX      XX     ",
      "                ",
      "                ",
      "                "
    ],
    [
      "  5       5     ",
      "   5     5      ",
      "    55555       ",
      "                ",
      "                ",
      "                ",
      "                ",
      " XX      XX     ",
      "XXXX    XX      ",
      "X  XX  XX       ",
      "X  XX  XX  XX   ",
      "XXXX    XXXX    ",
      " XX      XX     ",
      "                ",
      "                ",
      "                "
    ],
    [
      "  5       5     ",
      "   5     5      ",
      "    55555       ",
      "                ",
      "                ",
      "                ",
      "                ",
      " XX      X      ",
      "XXXX    X       ",
      "X  XX  XX       ",
      "X  XX  XX       ",
      "XXXX    XXXX    ",
      " XX      XX     ",
      "                ",
      "                ",
      "                "
    ],
    [
      "  5       5     ",
      "   5     5      ",
      "    55555       ",
      "                ",
      "                ",
      "                ",
      "                ",
      "                ",
      " XX             ",
      "XXXX    X       ",
      "XXXX    X       ",
      " XX      XX     ",
      "                ",
      "                ",
      "                ",
      "                "
    ]
  ]
}