{
  "xsize": 16,
  "zsize": 16,
  "refpalette": "pomkotsmechs:factory",
  "slices": [
    [
      "   Vʹʹʹʹʹʹʹʹʹʹʹʹ",
      "   Vʹʹʹʹʹʹʹʹʹʹʹ͵",
      "   Vʹʹʹʹʹʹʹʹʹʹʹʹ",
      "   VVʹʹʹʹʹʹʹʹʹʹʹ",
      "    Vʹʹʹʹʹʹʹʹʹʹʹ",
      "    Vʹʹʹʹʹʹʹʹʹʹʹ",
      "     Vʹʹʹʹʹʹʹʹʹʹ",
      "     VVʹʹʹʹʹʹʹʹʹ",
      "     &VVʹʹʹʹʹʹʹʹ",
      "      &VVʹʹʹʹʹʹʹ",
      "        VVʹʹʹʹʹʹ",
      "          VVVʹʹʹ",
      "            VVVV",
      "                ",
      "                ",
      "                "
    ],
    [
      "   V        VVVV",
      "   V      VVVV &",
      "   V    VVVVV   ",
      "   VV  VVVV     ",
      "    VVVVV       ",
      "    VVV         ",
      "     V          ",
      "     VV         ",
      "     &VV        ",
      "      &VV       ",
      "        VV      ",
      "          VVV  &",
      "            VVVV",
      "                ",
      "                ",
      "                "
    ],
    [
      "   V           &",
      "   V            ",
      "   V            ",
      "   VV           ",
      "    V &         ",
      "    V &         ",
      "     V&         ",
      "     VV         ",
      "     &VV        ",
      "      &VV       ",
      "        VV      ",
      "          VVV  &",
      "            VVVV",
      "                ",
      "                ",
      "                "
    ],
    [
      "                ",
      "                ",
      "                ",
      "                ",
      "                ",
      "      &         ",
      "     &&         ",
      "      &         ",
      "      &         ",
      "                ",
      "                ",
      "                ",
      "               &",
      "                ",
      "                ",
      "                "
    ],
    [
      "                ",
      "                ",
      "                ",
      "                ",
      "                ",
      "                ",
      "                ",
      "                ",
      "                ",
      "                ",
      "                ",
      "                ",
      "                ",
      "                ",
      "                ",
      "                "
    ],
    [
      "                ",
      "                ",
      "                ",
      "                ",
      "                ",
      "                ",
      "                ",
      "                ",
      "                ",
      "                ",
      "                ",
      "                ",
      "                ",
      "                ",
      "                ",
      "                "
    ]
  ]
}