{
  "xsize": 16,
  "zsize": 16,
  "refpalette": "lostcities:factory",
  "slices": [
    [
      "VVVVVVVVVVVVVVVV",
      "VVVVVVVVVVVVVVVV",
      "VVVVVVVVVVVVVVVV",
      "VVVVVVVVVVVVVVVV",
      "VVVVVVVVVVVVVVVV",
      "VVVVVVVVVVVVVVVV",
      "VVVVVVVVVVVVVVVV",
      "VVVVVVVVVVVVVVVV",
      "VVVVVVVVVVVVVVVV",
      "VVVVVVVVVVVVVVVV",
      "VVVVVVVVVVVVVVVV",
      "VVVVVVVVVVVVVVVV",
      "VVVVVVVVVVVVVVVV",
      "VVVVVVVVVVVVVVVV",
      "VVVVVVVVVVVVVVVV",
      "VVVVVVVVVVVVVVVV"
    ],
    [
      "              ! ",
      "              ! ",
      " VVVVVVVVV    ! ",
      " V J   J V J  ! ",
      " V J   J V J  ! ",
      " V J   J V J  ! ",
      " V J   J V J  ! ",
      " V J   J V J  ! ",
      " V       V    ! ",
      " V       V    ! ",
      "VV       V    ! ",
      " V       V    ! ",
      " V       V   !! ",
      " V J   J V J !!!",
      " V J   J V J !!!",
      " V J   J V J  ! "
    ],
    [
      "              i ",
      "              i ",
      "              i ",
      "   J   J   J  i ",
      "   X   X   X  i ",
      "   X  &X&  X  i ",
      "   X   X   X  i ",
      "   J   J   J  i ",
      "              i ",
      "              i ",
      "              i ",
      "              i ",
      "             !i ",
      "   J   J   J !!!",
      "   X   X   X !!!",
      "   X   X   X  ! "
    ],
    [
      "              i ",
      "              i ",
      "              i ",
      "   J   J   J  i ",
      "       &      i ",
      "      &&&     i ",
      "       &      i ",
      "   J   J   J  i ",
      "              i ",
      "              i ",
      "              i ",
      "              i ",
      "             !i ",
      "   J   J   J !!!",
      "             !!!",
      "              ! "
    ],
    [
      "              i ",
      "              i ",
      "              i ",
      "   J   J   J  i ",
      "   J   J   J  i ",
      "   J  &J&  J  i ",
      "   J   J   J  i ",
      "   J   J   J  i ",
      "             &i&",
      "              i ",
      "              i ",
      "              i ",
      "             !i ",
      "   J   J   J !!!",
      "   J   J   J !!!",
      "   J   J   J  ! "
    ],
    [
      "              i ",
      "              i ",
      "              i ",
      "JJJJ   JJJJJ  i ",
      " X X   X X X  i ",
      " X X  &X&X X  i ",
      " X X   X X X  i ",
      "JJJJ   JJJJJ  i ",
      "             &i&",
      "              i ",
      "              i ",
      "              i ",
      "             !i ",
      "JJJJ   JJJJJ !!!",
      " X X   X X X !!!",
      " X X   X X X  ! "
    ]
  ]
}