{
  "xsize": 16,
  "zsize": 16,
  "refpalette": "lostcities:factory",
  "slices": [
    [
      "                ",
      "                ",
      "  &&OO      OO  ",
      " &&O& O    O  O ",
      "  &O  O    O  O ",
      "    OO      OO  ",
      "                ",
      "                ",
      "            &   ",
      "    OO     &OO  ",
      "   O  O    O& O ",
      "   O  O    O  O ",
      "    OO      OO  ",
      "                ",
      "                ",
      "                "
    ],
    [
      "                ",
      "                ",
      "  &&OO      OO  ",
      " &&O& O    O  O ",
      "  &O  O    O  O ",
      "    OO      OO  ",
      "                ",
      "                ",
      "            &&  ",
      "    OO     &OO  ",
      "   O  O    O& O ",
      "   O  O    O  O ",
      "    OO      OO  ",
      "                ",
      "                ",
      "                "
    ],
    [
      "                ",
      "                ",
      "   &OO      OO  ",
      "  &O& O    O  O ",
      "   O  O    O  O ",
      "    OO      OO  ",
      "                ",
      "             &  ",
      "            &&& ",
      "    OO     &OO& ",
      "   O  O    O&&O ",
      "   O  O    O  O ",
      "    OO      OO  ",
      "                ",
      "      !!!!!!    ",
      "    !!      !!  "
    ],
    [
      "                ",
      "   &!!      !   ",
      "  &!OO!    !O   ",
      "  !OOOO!  !OOOO!",
      "  !OOOO!  !OOOO!",
      "   !OO!    !OO! ",
      "    !!      !!  ",
      "             &  ",
      "    !!      !!& ",
      "   !OO!    !OO! ",
      "  !OOOO!  !OOOO!",
      "  !OOOO!  !OOOO!",
      "   !OO!    !OO! ",
      "    !!      !!  ",
      "                ",
      "                "
    ],
    [
      "                ",
      "   &            ",
      "  &&55          ",
      "  &5555     5   ",
      "   5555    5 55 ",
      "    55      55  ",
      "                ",
      "             &  ",
      "            &&& ",
      "    55      55& ",
      "   5555    5555 ",
      "   5555    5555 ",
      "    55      55  ",
      "                ",
      "                ",
      "                "
    ],
    [
      "                ",
      "                ",
      "   &55          ",
      "  &5& 5         ",
      "   5  5    5    ",
      "    55          ",
      "                ",
      "                ",
      "             &  ",
      "    55      55& ",
      "   5  5    5 &5 ",
      "   5  5    5  5 ",
      "    55      55  ",
      "                ",
      "                ",
      "                "
    ]
  ]
}