{
  "xsize": 16,
  "zsize": 16,
  "refpalette": "lostcities:factory",
  "slices": [
    [
      "JJJJJJJJJJJJvvvv",
      "JJJJJJJJJJJJvvvv",
      "JJJJJJJJJJJJvvvv",
      "JJJJJJJJJJJJvvvv",
      "JJJJJJJJJJJJvvvv",
      "JJJJJJJJJJJJvvvv",
      "JJJJJJJJJJJJvvvv",
      "JJJJJJJJJJJJvvvv",
      "JJJJJJJJJJJJvvvv",
      "JJJJJJJJJJJJvvvv",
      "JJJJJJJJJJJJvvvv",
      "JJJJJJJJJJJJvvvv",
      "JJJJJJJJJJJJvvvv",
      "JJJJJJJJJJJJvvvv",
      "JJJJJJJJJJJJvvvv",
      "JJJJJJJJJJJJvvvv"
    ],
    [
      "!          !!!!!",
      "!               ",
      "                ",
      "                ",
      "                ",
      "                ",
      "                ",
      "                ",
      "                ",
      "                ",
      "                ",
      "                ",
      "                ",
      "                ",
      "!               ",
      "!          !!!!!"
    ],
    [
      "!            !  ",
      "!               ",
      "                ",
      "                ",
      "                ",
      "                ",
      "                ",
      "                ",
      "                ",
      "                ",
      "                ",
      "                ",
      "                ",
      "                ",
      "!               ",
      "!            !  "
    ],
    [
      "!            !  ",
      "!               ",
      "                ",
      "                ",
      "                ",
      "                ",
      "                ",
      "                ",
      "                ",
      "                ",
      "                ",
      "                ",
      "                ",
      "                ",
      "!               ",
      "!            !  "
    ],
    [
      "!            !  ",
      "!               ",
      "                ",
      "                ",
      "                ",
      "                ",
      "                ",
      "                ",
      "                ",
      "                ",
      "                ",
      "                ",
      "                ",
      "                ",
      "!               ",
      "!            !  "
    ],
    [
      "!            !  ",
      "!               ",
      "                ",
      "                ",
      "                ",
      "                ",
      "                ",
      "                ",
      "                ",
      "                ",
      "                ",
      "                ",
      "                ",
      "                ",
      "!               ",
      "!            !  "
    ]
  ]
}