{
  "xsize": 16,
  "zsize": 16,
  "refpalette": "pomkotsmechs:factory",
  "slices": [
    [
      "  !X            ",
      "  !X            ",
      "  !X            ",
      "  !X            ",
      "   !X           ",
      "  !!X           ",
      "   &!X          ",
      "    !X          ",
      "     !X         ",
      "     !!         ",
      "         X      ",
      "        !!XX    ",
      "          !!XXXX",
      "          ! !!!!",
      "                ",
      "                "
    ],
    [
      "  !X            ",
      "  !X            ",
      "  !X            ",
      "  !X &&         ",
      "   !X&          ",
      "  !!X           ",
      "   &!X          ",
      "    !X          ",
      "                ",
      "                ",
      "                ",
      "                ",
      "           !XXXX",
      "          ! !!!!",
      "                ",
      "                "
    ],
    [
      "   XXXXXXXXXXXXX",
      "   XXXXXXXXXXXXX",
      "   XXXXXXXXXXXXX",
      "   XXXXXXXXXXXXX",
      "   &XXXXXXXXXXXX",
      "   &XXXXXXXXXXXX",
      "   &&& XXXXXXXXX",
      "    &    XXXXXXX",
      "           XXXXX",
      "            XXXX",
      "             XXX",
      "             XXX",
      "             XXX",
      "                ",
      "                ",
      "                "
    ],
    [
      "    XXXXXXXXXXXX",
      "    XXXXXXXXXXXX",
      "    XXXXXXXXXXXX",
      "     &&XXXXXXXXX",
      "    &&&XXXXXXXXX",
      "    &  XXXXXXXXX",
      "    &  XXXXXXXXX",
      "        XXXXXXXX",
      "         XXXXXXX",
      "           XXXXX",
      "             XXX",
      "             XXX",
      "                ",
      "                ",
      "                ",
      "                "
    ],
    [
      "     XXXXXXXXXXX",
      "     XXXXXXXXXXX",
      "     X&&XXXXXXXX",
      "      &&XXXXXXXX",
      "        XXXXXXXX",
      "       XXXXXXXXX",
      "       XXXXXXXXX",
      "        XXXXXXXX",
      "          XXXXXX",
      "           XXXXX",
      "             XXX",
      "                ",
      "                ",
      "                ",
      "                ",
      "                "
    ],
    [
      "        &&&&&   ",
      "       && &&&   ",
      "       &   &&   ",
      "            &&  ",
      "             && ",
      "              & ",
      "              &&",
      "               &",
      "               &",
      "               &",
      "                ",
      "                ",
      "                ",
      "                ",
      "                ",
      "                "
    ]
  ]
}