{
  "xsize": 16,
  "zsize": 16,
  "refpalette": "lostcities:top_decorations",
  "slices": [
    [
      "                ",
      "                ",
      "                ",
      "                ",
      "                ",
      "                ",
      "                ",
      "                ",
      "                ",
      "                ",
      "                ",
      "                ",
      "                ",
      "                ",
      "                ",
      "                "
    ],
    [
      "                ",
      "                ",
      "                ",
      "   $$  $$  $$   ",
      "   $$  $$  $$   ",
      "                ",
      "                ",
      "                ",
      "                ",
      "                ",
      "                ",
      "   $$  $$  $$   ",
      "   $$  $$  $$   ",
      "                ",
      "                ",
      "                "
    ],
    [
      "~~~~~~~~~~~~~~~~",
      "~~~~~~~~~~~~~~~~",
      "~~~~~~~~~~~~~~~~",
      "~~~mn  mn  mn~~~",
      "~~~qr  qr  qr~~~",
      "~~~~~~~~~~~~~~~~",
      "~~~~~~~~~~~~~~~~",
      "~~~~~~~~~~~~~~~~",
      "~~~~~~~~~~~~~~~~",
      "~~~~~~~~~~~~~~~~",
      "~~~~~~~~~~~~~~~~",
      "~~~mn  mn  mn~~~",
      "~~~qr  qr  qr~~~",
      "~~~~~~~~~~~~~~~~",
      "~~~~~~~~~~~~~~~~",
      "~~~~~~~~~~~~~~~~"
    ]
  ]
}
