{
  "xsize": 16,
  "zsize": 16,
  "refpalette": "pomkotsmechs:factory",
  "slices": [
    [
      "5555555555555555",
      "5555555555555555",
      "5555555555555555",
      "5555555555555555",
      "5555555555555555",
      "5555555555555555",
      "5555555555555555",
      "5555555555555555",
      "5555555555555555",
      "5555555555555555",
      "5555555555555555",
      "5555555555555555",
      "5555555555555555",
      "555555555555555 ",
      "555555555555555 ",
      "55555555555555& "
    ],
    [
      "                ",
      "  JJ       JJ   ",
      "                ",
      "J    J   J    J&",
      "J    J   J   &J&",
      "  JJ       JJ &&",
      "  JJ       JJ   ",
      "                ",
      "                ",
      "                ",
      "                ",
      "  JJ       JJ   ",
      "                ",
      "J    J   J    J ",
      "J    J   J   &  ",
      "  JJ       JJ&& "
    ],
    [
      "                ",
      "  ͱͱ       ͱͱ   ",
      " ͱͱͱͱ     ͱͱͱͱ  ",
      "ͱͱ  ͱͱ   ͱͱ  ͱͱ ",
      "ͱͱ  ͱͱ   ͱͱ  ͱͱ&",
      " ͱͱͱͱ     ͱͱͱͱ& ",
      "  ͱͱ       ͱͱ   ",
      "                ",
      "                ",
      "                ",
      "                ",
      "  ͱͱ       ͱͱ   ",
      " ͱͱͱͱ     ͱͱͱͱ  ",
      "ͱͱ  ͱͱ   ͱͱ  ͱͱ ",
      "ͱͱ  ͱͱ   ͱͱ  ͱͱ ",
      " ͱͱͱͱ     ͱͱͱͱ& "
    ],
    [
      "                ",
      "  ͱͱ       ͱͱ   ",
      " ͱͱͱͱ     ͱͱͱͱ  ",
      "ͱͱ  ͱͱ   ͱͱ  ͱͱ ",
      "ͱͱ  ͱͱ   ͱͱ  ͱͱ&",
      " ͱͱͱͱ     ͱͱͱͱ& ",
      "  ͱͱ       ͱͱ   ",
      "                ",
      "                ",
      "                ",
      "                ",
      "  ͱͱ       ͱͱ   ",
      " ͱͱͱͱ     ͱͱͱͱ  ",
      "ͱͱ  ͱͱ   ͱͱ  ͱͱ ",
      "ͱͱ  ͱͱ   ͱͱ  ͱͱ ",
      " ͱͱͱͱ     ͱͱͱͱ  "
    ],
    [
      "                ",
      "  ͱͱ       ͱͱ   ",
      " ͱͱͱͱ     ͱͱͱͱ  ",
      "ͱͱ  ͱͱ   ͱͱ  ͱͱ ",
      "ͱͱ  ͱͱ   ͱͱ &ͱͱ&",
      " ͱͱͱͱ     ͱͱͱͱ& ",
      "  ͱͱ       ͱͱ&  ",
      "                ",
      "                ",
      "                ",
      "                ",
      "  ͱͱ       ͱͱ   ",
      " ͱͱͱͱ     ͱͱͱͱ  ",
      "ͱͱ  ͱͱ   ͱͱ  ͱͱ ",
      "ͱͱ  ͱͱ   ͱͱ  ͱͱ ",
      " ͱͱͱͱ     ͱͱͱͱ  "
    ],
    [
      "                ",
      "  ͱͱ       ͱͱ   ",
      " ͱͱͱͱ     ͱͱͱͱ  ",
      "ͱͱ  ͱͱ   ͱͱ  ͱͱ ",
      "ͱͱ  ͱͱ   ͱͱ &ͱͱ ",
      " ͱͱͱͱ     ͱͱͱͱ& ",
      "  ͱͱ       ͱͱ&  ",
      "                ",
      "                ",
      "                ",
      "                ",
      "  ͱͱ       ͱͱ   ",
      " ͱͱͱͱ     ͱͱͱͱ  ",
      "ͱͱ  ͱͱ   ͱͱ  ͱͱ ",
      "ͱͱ  ͱͱ   ͱͱ  ͱͱ ",
      " ͱͱͱͱ     ͱͱͱͱ  "
    ]
  ]
}