{
  "xsize": 16,
  "zsize": 16,
  "refpalette": "pomkotsmechs:factory",
  "slices": [
    [
      "                ",
      "      &         ",
      "    OO&&    OO  ",
      "   O &O&   O  O ",
      "   O  O    O  O ",
      "    OO      OO  ",
      "                ",
      "                ",
      "                ",
      "    OO5    5OO  ",
      "   O 5O    O5 O ",
      "   O 5O    O5 O&",
      "    OO5!!!!5OO&&",
      "    !!!!!!!!!!!&",
      "    !!!!!!!!!!!!",
      "   !!!!!!!!!!!!!"
    ],
    [
      "                ",
      "      &         ",
      "    OO&&    OO  ",
      "   O &O&   O  O ",
      "   O  O    O  O ",
      "    OO      OO  ",
      "                ",
      "                ",
      "                ",
      "    OO      OO  ",
      "   O  O    O  O ",
      "   O  O    O &O ",
      "    OO      OO&&",
      "     55    55&&&",
      "     55    55&& ",
      "     !!!!!!!!   "
    ],
    [
      "                ",
      "    !!&     !!  ",
      "   !OO!&   !OO! ",
      "  !OOOO!  !OOOO!",
      "  !OOOO!  !OOOO!",
      "   !OO!    !OO! ",
      "    !!      !!  ",
      "                ",
      "                ",
      "    OO      OO  ",
      "   O  O    O  O ",
      "   O  O    O &O ",
      "    OO      OO& ",
      "             && ",
      "                ",
      "                "
    ],
    [
      "                ",
      "      &         ",
      "    55&&    55  ",
      "   5555&   5555 ",
      "   5555    5555 ",
      "    55      55  ",
      "                ",
      "                ",
      "                ",
      "    OO      OO  ",
      "   O  O    O  O ",
      "   O  O    O &O&",
      "    OO      OO&&",
      "             && ",
      "                ",
      "                "
    ],
    [
      "                ",
      "                ",
      "    55&     55  ",
      "   5 &5&   5  5 ",
      "   5  5    5  5 ",
      "    55      55  ",
      "                ",
      "                ",
      "                ",
      "    OO      OO  ",
      "   O  O    O  O ",
      "   O  O    O &O&",
      "    OO      OO& ",
      "                ",
      "                ",
      "                "
    ],
    [
      "                ",
      "                ",
      "    55&     55  ",
      "   5 &5&   5  5 ",
      "   5  5    5  5 ",
      "    55      55  ",
      "                ",
      "                ",
      "                ",
      "    OO      OO& ",
      "   O  O    O &O&",
      "   O  O    O &O&",
      "    OO      OO& ",
      "                ",
      "                ",
      "                "
    ]
  ]
}