{
  "xsize": 16,
  "zsize": 16,
  "refpalette": "pomkotsmechs:factory",
  "slices": [
    [
      "                ",
      "                ",
      "Q               ",
      " QQQQ &&        ",
      "     QQ&        ",
      "      &QQ       ",
      "         Q      ",
      "          Q     ",
      "          Q&  ! ",
      "          &Q& ! ",
      "           Q  ! ",
      "  &         Q   ",
      " &&&        Q   ",
      "  &         Q   ",
      "            Q   ",
      "             Q  "
    ],
    [
      "                ",
      "                ",
      "QQQQ   &        ",
      "    QQ&&&       ",
      "     &QQ&       ",
      "      &&Q       ",
      "         Q      ",
      "          Q     ",
      "           Q& ! ",
      "          &Q&&  ",
      "           &Q ! ",
      "  &         Q   ",
      " &&&         Q  ",
      "  &          Q  ",
      "             Q  ",
      "             Q  "
    ],
    [
      "                ",
      "                ",
      "QQQQQ  &        ",
      "     QQ&&       ",
      "      &QQ       ",
      "         Q      ",
      "          Q     ",
      "           Q&   ",
      "           Q&&! ",
      "           &Q&! ",
      "  &         Q ! ",
      " &&&         Q  ",
      " &&&         Q  ",
      "  &          Q  ",
      "             Q  ",
      "             Q  "
    ],
    [
      "                ",
      "QQ              ",
      "  QQQQ &        ",
      "      QQ&       ",
      "       &Q       ",
      "         Q      ",
      "          Q     ",
      "           Q&&  ",
      "           &Q&! ",
      "            Q&  ",
      "  &          Q! ",
      " &&&         Q  ",
      "  &          Q  ",
      "             Q  ",
      "              Q ",
      "              Q "
    ],
    [
      "                ",
      "QQQ             ",
      "   QQQ &        ",
      "      QQ&       ",
      "       &Q       ",
      "         Q      ",
      "          Q     ",
      "           Q && ",
      "            Q&!&",
      "            Q&! ",
      "  &          Q! ",
      " &&&         Q  ",
      "  &          Q  ",
      "              Q ",
      "              Q ",
      "              Q "
    ],
    [
      "                ",
      "QQQQ            ",
      "    QQ&&        ",
      "     &QQ&       ",
      "      &&QQ      ",
      "          Q     ",
      "           Q    ",
      "           Q  & ",
      "            Q&!&",
      "            Q & ",
      "  &          Q! ",
      " &&&         Q  ",
      "  &           Q ",
      "              Q ",
      "              Q ",
      "             &Q&"
    ]
  ]
}