{
  "xsize": 16,
  "zsize": 16,
  "refpalette": "pomkotsmechs:factory",
  "slices": [
    [
      "vvvvvvvvvvvvvvvv",
      "vvvvvvvvvvvvvvvv",
      "vvvvvvvvvvvvvvvv",
      "vvvvvvvvvvvvvvvv",
      "vvvvvvvvvvvvvvvv",
      "vvvvvvvvvvvvvvvv",
      "vvvvvvvvvvvvvvvv",
      "vvvvvvvvvvvvvvvv",
      "vvvvvvvvvvvvvvvv",
      "vvvvvvvvvvvvvvvv",
      "vvvvvvvvvvvvvvvv",
      "vvvvvvvvvvvvvvvv",
      "vvvvvvvvvvvvvvvv",
      "vvvvvvvvvvvvvvvv",
      "vvvvvvvvvvvvvvvv",
      "vvvvvvvvvvvvvvvv"
    ],
    [
      "                ",
      "                ",
      "                ",
      "                ",
      "                ",
      "                ",
      "                ",
      "55              ",
      "  55            ",
      "    5           ",
      "     5&&        ",
      "     &5&&       ",
      "      &5        ",
      "        5       ",
      "        5       ",
      "         5      "
    ],
    [
      "                ",
      "                ",
      "                ",
      "                ",
      "                ",
      "                ",
      "                ",
      "55              ",
      "  55            ",
      "    5           ",
      "     5&         ",
      "     &5&        ",
      "      &5        ",
      "        5       ",
      "        5       ",
      "         5      "
    ],
    [
      "                ",
      "                ",
      "                ",
      "                ",
      "                ",
      "                ",
      "                ",
      "55              ",
      "  55            ",
      "    5           ",
      "     5&         ",
      "     &5&        ",
      "      &5        ",
      "        5       ",
      "        5       ",
      "         5      "
    ],
    [
      "                ",
      "                ",
      "                ",
      "                ",
      "                ",
      "                ",
      "                ",
      "55              ",
      "  55            ",
      "    5           ",
      "     5&         ",
      "     &5&        ",
      "      &5        ",
      "        5       ",
      "        5       ",
      "         5      "
    ],
    [
      "                ",
      "                ",
      "                ",
      "                ",
      "                ",
      "                ",
      "                ",
      "55              ",
      "  55            ",
      "    5           ",
      "     5&         ",
      "     &5&        ",
      "      &5        ",
      "        5       ",
      "        5       ",
      "         5      "
    ]
  ]
}