{
  "xsize": 16,
  "zsize": 16,
  "refpalette": "pomkotsmechs:factory",
  "slices": [
    [
      "                ",
      "                ",
      "                ",
      "     &          ",
      "    &&!!!!      ",
      "    &!&   !     ",
      "    !&     !    ",
      "    !&     !    ",
      "    &&     !    ",
      "   &&&&   &!&   ",
      "    &!    !&    ",
      "      !!!!      ",
      "                ",
      "                ",
      "                ",
      "                "
    ],
    [
      "                ",
      "                ",
      "                ",
      "     &          ",
      "    &&!OO!      ",
      "     O    O     ",
      "    !      !    ",
      "    O      O    ",
      "    O      O    ",
      "   &!&    &!&   ",
      "    &O    O&    ",
      "      !OO!      ",
      "                ",
      "                ",
      "                ",
      "                "
    ],
    [
      "                ",
      "                ",
      "                ",
      "     &          ",
      "    &&!OO!      ",
      "    &O&   O     ",
      "    !&     !    ",
      "    O      O    ",
      "    O      O    ",
      "   &!&    &!&   ",
      "    &O   &O&&   ",
      "      !OO!&&    ",
      "                ",
      "                ",
      "                ",
      "                "
    ],
    [
      "                ",
      "                ",
      "                ",
      "      &         ",
      "     &!OO!      ",
      "    &O&&  O     ",
      "    !&&    !    ",
      "    O      O    ",
      "    O      O    ",
      "   &!&    &!    ",
      "    &O   &O&    ",
      "      !OO!&&    ",
      "                ",
      "                ",
      "                ",
      "                "
    ],
    [
      "                ",
      "                ",
      "                ",
      "      &&        ",
      "     &!OO!      ",
      "     O&   O     ",
      "    !      !    ",
      "    O      O    ",
      "    O      O    ",
      "   &!&    &!    ",
      "    &O   &O&    ",
      "      !OO!&&    ",
      "                ",
      "                ",
      "                ",
      "                "
    ],
    [
      "                ",
      "                ",
      "      &&        ",
      "     &!!!!      ",
      "    !!!!!!!!    ",
      "    !!&   !!    ",
      "   !!      !!   ",
      "   !!      !!   ",
      "   !!      !!   ",
      "   !!&    &!!   ",
      "   &!!   &!!    ",
      "    !!!!!!!!    ",
      "      !!!!      ",
      "                ",
      "                ",
      "                "
    ]
  ]
}