{
  "xsize": 16,
  "zsize": 16,
  "refpalette": "pomkotsmechs:factory",
  "slices": [
    [
      "XXXXXXXXXXXX    ",
      "XXXXX!!!!!!X    ",
      "XXXXX!   &!X&   ",
      "XXXXX!    !X    ",
      "XXXXX!    !X    ",
      "XXXXX!    !X    ",
      "XXXXX!!!!!!X    ",
      "XXXXXXXXXXXX    ",
      "XXXXXXXXXXXX    ",
      "XXXXXXXXXXXX    ",
      "XXXXXXXXXXXX    ",
      "XXXXX XX   X    ",
      "XXXXX XX   X    ",
      "XXXXXXXXXXXX    ",
      "                ",
      "                "
    ],
    [
      " &&&            ",
      "X &&X!    !     ",
      "X   X&   &&&    ",
      "          &     ",
      "                ",
      "                ",
      "     !    !     ",
      "    &XXXXXXX    ",
      "   &&XXXXXXX    ",
      "  &&&XXXXXXX    ",
      "X   XXXXXXXX    ",
      "     XXXXXXX    ",
      "X   XXXXXXXX    ",
      "     XXXXXXX    ",
      "                ",
      "                "
    ],
    [
      "XXXXX           ",
      "X &&X!   !!     ",
      "   &&!&  &!&    ",
      "    &&    &     ",
      "                ",
      "                ",
      "    &!   !!     ",
      "   &&XXXXXX     ",
      "   &&XXXXXX     ",
      "    &XXXXXX     ",
      "XXXXXXXXXXX     ",
      "XXXXXXXXXXX     ",
      "XXXXXXXXXXX     ",
      "XXXXX           ",
      "                ",
      "                "
    ],
    [
      "XXXXX           ",
      " &&&&!  !!!     ",
      "   &&!&  &!&    ",
      "    &!&  &!&    ",
      "     &    &     ",
      "                ",
      "   &&!  !!!     ",
      "  &&&&          ",
      "   &&           ",
      "                ",
      "X   X           ",
      "                ",
      "X   X           ",
      "                ",
      "                ",
      "                "
    ],
    [
      "&&&&            ",
      "   & ! !! !     ",
      "     &    &     ",
      "    &!&  &!&    ",
      "     !    !     ",
      "                ",
      "   & ! !! !     ",
      "  &&&           ",
      "   &            ",
      "                ",
      "X   X           ",
      "                ",
      "X   X           ",
      "                ",
      "                ",
      "                "
    ],
    [
      "                ",
      "     !!!  !     ",
      "                ",
      "     &    &     ",
      "     !    !     ",
      "   & !    !     ",
      "  &&&!!!  !     ",
      "  &&&           ",
      "   &            ",
      "                ",
      "X   X           ",
      "                ",
      "X   X           ",
      "                ",
      "                ",
      "                "
    ]
  ]
}