{
  "xsize": 16,
  "zsize": 16,
  "refpalette": "pomkotsmechs:factory",
  "slices": [
    [
      "                ",
      "                ",
      "                ",
      "            VVVV",
      "          VVVʹʹʹ",
      "        VVʹʹʹʹʹʹ",
      "       VVʹʹʹʹʹʹʹ",
      "      VVʹʹʹʹʹʹʹʹ",
      "     VVʹʹʹʹʹʹʹʹʹ",
      "    &Vʹʹʹʹʹʹʹʹʹʹ",
      "  &&Vʹʹʹʹʹʹʹʹʹʹʹ",
      "    Vʹʹʹʹʹʹʹʹʹʹʹ",
      "   VVʹʹʹʹʹʹʹʹʹʹʹ",
      "   Vʹʹʹʹʹʹʹʹʹʹʹʹ",
      "   Vʹʹʹʹʹʹʹʹʹʹʹʹ",
      "   Vʹʹʹʹʹʹʹʹʹʹ͵͵"
    ],
    [
      "                ",
      "                ",
      "                ",
      "            VVVV",
      "          VVVʹʹʹ",
      "        VVʹʹʹʹʹʹ",
      "       VVʹʹʹʹʹʹʹ",
      "      VVʹʹʹʹʹʹʹʹ",
      "     VVʹʹʹʹʹʹʹʹʹ",
      "     Vʹʹʹʹʹʹʹʹʹʹ",
      "   &Vʹʹʹʹʹʹʹʹʹʹʹ",
      "  &&Vʹʹʹʹʹʹʹʹʹʹʹ",
      "   VVʹʹʹʹʹʹʹʹʹʹʹ",
      "   Vʹʹʹʹʹʹʹʹʹʹʹʹ",
      "   Vʹʹʹʹʹʹʹʹʹʹʹʹ",
      "   Vʹʹʹʹʹʹʹʹʹʹʹ͵"
    ],
    [
      "                ",
      "                ",
      "                ",
      "            VVVV",
      "          VVVʹʹʹ",
      "        VVʹʹʹʹʹʹ",
      "       VVʹʹʹʹʹʹʹ",
      "      VVʹʹʹʹʹʹʹʹ",
      "     VVʹʹʹʹʹʹʹʹʹ",
      "     Vʹʹʹʹʹʹʹʹʹʹ",
      "    Vʹʹʹʹʹʹʹʹʹʹʹ",
      "   &Vʹʹʹʹʹʹʹʹʹʹʹ",
      "   VVʹʹʹʹʹʹʹʹʹʹʹ",
      "   Vʹʹʹʹʹʹʹʹʹʹʹʹ",
      "   Vʹʹʹʹʹʹʹʹʹʹʹʹ",
      "   Vʹʹʹʹʹʹʹʹʹʹʹ͵"
    ],
    [
      "                ",
      "                ",
      "                ",
      "            VVVV",
      "          VVVʹʹʹ",
      "        VVʹʹʹʹʹʹ",
      "       VVʹʹʹʹʹʹʹ",
      "      VVʹʹʹʹʹʹʹʹ",
      "     VVʹʹʹʹʹʹʹʹʹ",
      "     Vʹʹʹʹʹʹʹʹʹʹ",
      "    Vʹʹʹʹʹʹʹʹʹʹʹ",
      "    Vʹʹʹʹʹʹʹʹʹʹʹ",
      "   VVʹʹʹʹʹʹʹʹʹʹʹ",
      "   Vʹʹʹʹʹʹʹʹʹʹʹʹ",
      "   Vʹʹʹʹʹʹʹʹʹʹʹʹ",
      "   Vʹʹʹʹʹʹʹʹʹʹʹʹ"
    ],
    [
      "                ",
      "                ",
      "                ",
      "            VVVV",
      "          VVVʹʹʹ",
      "        VVʹʹʹʹʹʹ",
      "       VVʹʹʹʹʹʹʹ",
      "      VVʹʹʹʹʹʹʹʹ",
      "     VVʹʹʹʹʹʹʹʹʹ",
      "     Vʹʹʹʹʹʹʹʹʹʹ",
      "    Vʹʹʹʹʹʹʹʹʹʹʹ",
      "    Vʹʹʹʹʹʹʹʹʹʹʹ",
      "   VVʹʹʹʹʹʹʹʹʹʹʹ",
      "   Vʹʹʹʹʹʹʹʹʹʹʹʹ",
      "   Vʹʹʹʹʹʹʹʹʹʹʹʹ",
      "   Vʹʹʹʹʹʹʹʹʹʹʹʹ"
    ],
    [
      "                ",
      "                ",
      "                ",
      "            VVVV",
      "          VVVʹʹʹ",
      "        VVʹʹʹʹʹʹ",
      "       VVʹʹʹʹʹʹʹ",
      "      VVʹʹʹʹʹʹʹʹ",
      "     VVʹʹʹʹʹʹʹʹʹ",
      "     Vʹʹʹʹʹʹʹʹʹʹ",
      "    Vʹʹʹʹʹʹʹʹʹʹʹ",
      "    Vʹʹʹʹʹʹʹʹʹʹʹ",
      "   VVʹʹʹʹʹʹʹʹʹʹʹ",
      "   Vʹʹʹʹʹʹʹʹʹʹʹʹ",
      "   Vʹʹʹʹʹʹʹʹʹʹʹʹ",
      "   Vʹʹʹʹʹʹʹʹʹʹʹʹ"
    ]
  ]
}