{
  "xsize": 16,
  "zsize": 16,
  "refpalette": "lostcities:factory",
  "slices": [
    [
      "                ",
      "   !!!!!!!!!!   ",
      "                ",
      "   &      &&    ",
      "  &&&     &     ",
      "   !!!!!!!!!!   ",
      "         &&&&&  ",
      "        && &&&  ",
      "        & &&&   ",
      "   !!!!!!!!!    ",
      "                ",
      "                ",
      "                ",
      "   !!!!!!!!     ",
      "                ",
      "                "
    ],
    [
      "                ",
      "   OOOOOOOOOO   ",
      "   OVVVVVVVVO   ",
      "   OVVVVVVVVO   ",
      "  &OVVVVVVVVO   ",
      "   OVVVVVVVVO   ",
      "   OVVVVVVVVO   ",
      "   OVVVVVVVVO&  ",
      "   OVVVVVVVV&   ",
      "   OVVVVVVVV    ",
      "   OVVVVVVV     ",
      "   OVVVVVVV     ",
      "   OVVVVVVV     ",
      "   OVVVVVVVV    ",
      "   OVVVVVVVVO   ",
      "   OVVVVVVVVO   "
    ],
    [
      "                ",
      "   OVVVVVVVVO   ",
      "   V       &V   ",
      "   V      &&V   ",
      "  &V&     &&V   ",
      "  &V&     & V   ",
      "   V     && V   ",
      "   V    && &&   ",
      "   V   &&&&&&&  ",
      "   V    &  &&   ",
      "   V            ",
      "   O            ",
      "   V            ",
      "   V        V   ",
      "   V        V   ",
      "   V        V   "
    ],
    [
      "                ",
      "   OVVVVVV  O   ",
      "   V       &V   ",
      "   V      &&V&  ",
      "   V      &&V&  ",
      "  &V&      &V   ",
      "   V            ",
      "   V    &&  &   ",
      "   V   &&&&&&&  ",
      "   V    &&  &   ",
      "   V            ",
      "   O            ",
      "   V        V   ",
      "   V        V   ",
      "   V        V   ",
      "   V        V   "
    ],
    [
      "                ",
      "   OVVVVVV      ",
      "   V            ",
      "   V       &&   ",
      "   V       &V&  ",
      "  &V&       V   ",
      "   V            ",
      "   V     &  &   ",
      "   V    &&&&&&  ",
      "   V     &  &   ",
      "   V            ",
      "   O        O   ",
      "   V        V   ",
      "   V        V   ",
      "   V        V   ",
      "   V        V   "
    ],
    [
      "                ",
      "   OVVVVV       ",
      "   V            ",
      "   V        &   ",
      "   V       &V&  ",
      "  &V&       &   ",
      "   V            ",
      "   V     &  &   ",
      "   V    &&&&&&  ",
      "   V     &  &   ",
      "   V        V   ",
      "   O        O   ",
      "   V        V   ",
      "   V        V   ",
      "   V        V   ",
      "   V        V   "
    ]
  ]
}