{
  "xsize": 16,
  "zsize": 16,
  "refpalette": "pomkotsmechs:factory",
  "slices": [
    [
      "                ",
      "                ",
      "  5             ",
      "                ",
      "                ",
      "/              +",
      "3              2",
      "                ",
      "                ",
      "                ",
      "                ",
      "/              +",
      "3              2",
      "                ",
      "                ",
      "                "
    ],
    [
      "                ",
      "                ",
      "555             ",
      "                ",
      "                ",
      "/              +",
      "3              2",
      "                ",
      "                ",
      "                ",
      "                ",
      "/              +",
      "3              2",
      "                ",
      "                ",
      "                "
    ],
    [
      "                ",
      "                ",
      "                ",
      "                ",
      "                ",
      "/              +",
      "3              2",
      "                ",
      "                ",
      "                ",
      "                ",
      "/              +",
      "3              2",
      "                ",
      "                ",
      "                "
    ],
    [
      "                ",
      "                ",
      "                ",
      "                ",
      "                ",
      "V              V",
      "V              V",
      "                ",
      "                ",
      "                ",
      "                ",
      "V              V",
      "V              V",
      "                ",
      "                ",
      "                "
    ],
    [
      "V              V",
      "V              V",
      "V              V",
      "V              V",
      "VV            VV",
      "nV            Vn",
      "nV            Vn",
      "VV            VV",
      "                ",
      "                ",
      "VV            VV",
      "nV            Vn",
      "nV            Vn",
      "VV      &     VV",
      "V              V",
      "V              V"
    ],
    [
      "!!rrrrrrrrrrrr!!",
      "!!rrrrrrrrrrrr!!",
      "!!rrrrrrrrrrrr!!",
      "!!rrrrrrrrrrrr!!",
      "!!!!!!!!!!!!!!!!",
      "!!!!!!!!!!!!!!!!",
      "!!!!!!!!!!!!!!!!",
      "!!!!!!!!!!!!!!!!",
      "rrrrrrrrrrrrrrrr",
      "rrrrrrrrrrrrrrrr",
      "!!!!!!!!!!!!!!!!",
      "!!!!!!!!!!!!!!!!",
      "!!!!!!!!!!!!!!!!",
      "!!!!!!!!!!!!!!!!",
      "rrrrrrrrrrrrrrrr",
      "rrrrrrrrrrrrrrrr"
    ]
  ]
}