{
  "xsize": 16,
  "zsize": 16,
  "refpalette": "lostcities:top_decorations",
  "slices": [
    [
      "                ",
      "                ",
      "                ",
      "                ",
      "                ",
      "                ",
      "                ",
      "                ",
      "                ",
      "                ",
      "                ",
      "                ",
      "                ",
      "                ",
      "                ",
      "                "
    ],
    [
      "                ",
      "                ",
      "                ",
      "   uuu  uuu     ",
      "   uuukkuuu     ",
      "   uuu  uuu     ",
      "    k           ",
      "    k           ",
      "   uuu          ",
      "   uuu          ",
      "   uuu          ",
      "                ",
      "            :   ",
      "                ",
      "                ",
      "                "
    ],
    [
      "~~~~~~~~~~~~~~~~",
      "~~~~~~~~~~~~~~~~",
      "~~~~~~~~~~~~~~~~",
      "~~~~~~~~~~~~~~~~",
      "~~~~~~~~~~~~~~~~",
      "~~~~~~~~~~~~~~~~",
      "~~~~~~~~~~~~~~~~",
      "~~~~~~~~~~~~~~~~",
      "~~~~~~~~~~~~~~~~",
      "~~~~~~~~~~~~~~~~",
      "~~~~~~~~~~~~~~~~",
      "~~~~~~~~~~~   ~~",
      "~~~~~~~~~~~ : ~~",
      "~~~~~~~~~~~   ~~",
      "~~~~~~~~~~~~~~~~",
      "~~~~~~~~~~~~~~~~"
    ],
    [
      "~~~~~~~~~~~~~~~~",
      "~~~~~~~~~~~~~~~~",
      "~~~~~~~~~~~~~~~~",
      "~~~~~~~~~~~~~~~~",
      "~~~~~~~~~~~~~~~~",
      "~~~~~~~~~~~~~~~~",
      "~~~~~~~~~~~~~~~~",
      "~~~~~~~~~~~~~~~~",
      "~~~~~~~~~~~~~~~~",
      "~~~~~~~~~~~~~~~~",
      "~~~~~~~~~~~~~~~~",
      "~~~~~~~~~~~   ~~",
      "~~~~~~~~~~~ : ~~",
      "~~~~~~~~~~~   ~~",
      "~~~~~~~~~~~~~~~~",
      "~~~~~~~~~~~~~~~~"
    ],
    [
      "~~~~~~~~~~~~~~~~",
      "~~~~~~~~~~~~~~~~",
      "~~~~~~~~~~~~~~~~",
      "~~~~~~~~~~~~~~~~",
      "~~~~~~~~~~~~~~~~",
      "~~~~~~~~~~~~~~~~",
      "~~~~~~~~~~~~~~~~",
      "~~~~~~~~~~~~~~~~",
      "~~~~~~~~~~~~~~~~",
      "~~~~~~~~~~~~~~~~",
      "~~~~~~~~~~~~~~~~",
      "~~~~~~~~~~~ : ~~",
      "~~~~~~~~~~~:::~~",
      "~~~~~~~~~~~ : ~~",
      "~~~~~~~~~~~~~~~~",
      "~~~~~~~~~~~~~~~~"
    ]
  ]
}
