{
  "xsize": 16,
  "zsize": 16,
  "refpalette": "lostcities:factory",
  "slices": [
    [
      "tttttttttttttttt",
      "t       5      t",
      "t     VVVV     t",
      "t   VV    VV   t",
      "t  V        V  t",
      "t  V        V  t",
      "t V          V t",
      "t5V          V t",
      "t V          V5t",
      "t V          V t",
      "t  V        V  t",
      "t  V &     &V& t",
      "t   VV&   VV&  t",
      "t    &VVVV     t",
      "t      5       t",
      "tttttttttttttttt"
    ],
    [
      "                ",
      "        5       ",
      "      VVVV      ",
      "    VV    VV    ",
      "   V        V   ",
      "   V        V   ",
      "  V          V  ",
      " 5V          V  ",
      "  V          V5 ",
      "  V          V  ",
      "   V &      V   ",
      "   V &     &V&  ",
      "    VV&   VV&   ",
      "     &VVVV      ",
      "       5        ",
      "                "
    ],
    [
      "                ",
      "       &5       ",
      "      VVVV      ",
      "    VVVVVVVV    ",
      "   VVVVVVVVVV   ",
      "   VVVVVVVVVV   ",
      "  VVVVVVVVVVVV  ",
      " 5VVVVVVVVVVVV  ",
      "  VVVVVVVVVVVV5 ",
      "  VVVVVVVVVVVV  ",
      "   VVVVVVVVVV   ",
      "   VVVVVVVVVV&  ",
      "    VVVVVVVV&   ",
      "     &VVVV      ",
      "       5        ",
      "                "
    ],
    [
      "                ",
      "       &5       ",
      "     &&&&       ",
      "    &&VVVV      ",
      "   &VVVVVVVV    ",
      "   &VVVVVVVV    ",
      "   VVVVVVVVVV   ",
      " 5 VVVVVVVVVV   ",
      "   VVVVVVVVVV 5 ",
      "   V &VVVVVVV   ",
      "    &&&VVVVV&   ",
      "     &&VVVVV&&  ",
      "     &VVVV&&&   ",
      "                ",
      "       5        ",
      "                "
    ],
    [
      "                ",
      "        5       ",
      "       &5       ",
      "     &&&5       ",
      "    &&  5       ",
      "    &ttt5tt     ",
      "   &&t& 5 t     ",
      " 55555    t     ",
      "       &  55555 ",
      "      &&& t     ",
      "     &&5ttt     ",
      "       5  &&&   ",
      "       5        ",
      "       5        ",
      "       5        ",
      "                "
    ],
    [
      "                ",
      "                ",
      "                ",
      "                ",
      "     &          ",
      "    &tttttt     ",
      "    &tttttt     ",
      "     tttttt     ",
      "     tttttt     ",
      "       tttt     ",
      "      &tttt     ",
      "       &        ",
      "                ",
      "                ",
      "                ",
      "                "
    ]
  ]
}