{
  "xsize": 16,
  "zsize": 16,
  "refpalette": "pomkotsmechs:factory",
  "slices": [
    [
      "                ",
      "                ",
      "       &        ",
      "      &&&       ",
      "       &        ",
      "                ",
      "                ",
      "           5    ",
      "           5    ",
      "           5    ",
      "           5    ",
      "          &5    ",
      "         &5&    ",
      "          5     ",
      "          5     ",
      " &&      5      "
    ],
    [
      "                ",
      "                ",
      "       &        ",
      "      &&&       ",
      "       &        ",
      "                ",
      "                ",
      "           5    ",
      "           5    ",
      "           5    ",
      "           5    ",
      "          &5    ",
      "         &5&    ",
      "          5     ",
      "  &       5     ",
      " &&      5      "
    ],
    [
      "                ",
      "                ",
      "       &        ",
      "      &&&       ",
      "       &        ",
      "                ",
      "                ",
      "           5    ",
      "           5    ",
      "           5    ",
      "          &5    ",
      "          &5&   ",
      "         &5&&   ",
      "          5&    ",
      "  &       5     ",
      " &&&     5      "
    ],
    [
      "!!!!!!!!!       ",
      "!!!!!!!!        ",
      "!!!!!!!&        ",
      "!!!!!!!&&       ",
      "!!!!!!!&&       ",
      "!!!!!!!!        ",
      "!!!!!!!!!       ",
      "!!!!!!!!!!!!    ",
      "!!!!!!!!!!!!    ",
      "!!!!!!!!!!!!    ",
      "!!!!!!!!!!!!    ",
      "!!!!!!!!!!!!&   ",
      "!!!!!!!!!!!&    ",
      "!!!!!!!!!!!     ",
      "!!!!!   !!!     ",
      "!!!&     !      "
    ],
    [
      "!!!!!!!!        ",
      "!!!!!!!!        ",
      "!!!!!!!!        ",
      "!!!!!!!!&       ",
      "!!!!!!!!!&      ",
      "!!!!!!!!!5      ",
      "!!!!!!!!!!      ",
      "!!!!!!!!!!      ",
      "!!!!!!!!!!      ",
      "!!!!!!!!!!&     ",
      "!!!!!!!!!5&&    ",
      "!!!!!!!!!5&&    ",
      "!!!!!!!!!       ",
      "!!!!!  !!       ",
      "!!!!            ",
      "!!!&            "
    ],
    [
      "!!!!!           ",
      "!!!!!!          ",
      "!!!!!!          ",
      "!!!!!!!&&       ",
      "!!!!!!!55&      ",
      "!!!!!!!55       ",
      "!!!!!!!&        ",
      "!!!!!!!         ",
      "!!!!!!!&        ",
      "!!!!!!!&&&      ",
      "!!!!!!!55&&     ",
      "!!!!!!!55&      ",
      "!!!!!!!         ",
      "!!!             ",
      "!!&             ",
      "!&&             "
    ]
  ]
}