{
  "xsize": 16,
  "zsize": 16,
  "refpalette": "lostcities:factory",
  "slices": [
    [
      "!!  !!        ! ",
      "!!!!!![[[[[[[[! ",
      "!!  !!!       ! ",
      "jjjjjjjjjjjjj!!!",
      "VVVVVVVVVVVVV!!!",
      "VVVVVVVVVVVVV!i ",
      "VJJJJJJJJJJJJ!i ",
      "VJ          J!i ",
      "VJ          J!i ",
      "VJ          J!i ",
      "VJ          J!i ",
      "VJ          J!i ",
      "VJ          J!i ",
      "VJ          J!i ",
      "VJ          J!i ",
      "VJ          J!i "
    ],
    [
      "!!  !!        ! ",
      "!!!!!![[[[[[[[! ",
      "!!  !!!       ! ",
      "j,,,,,,,,,,,,!!!",
      "o            !!!",
      "3            !i ",
      " JJJJJJJJJJJJ i ",
      " J          J i ",
      " J          J i ",
      " J          J i ",
      " J          J i ",
      " J          J i ",
      "&J          J i ",
      "&J&         J i ",
      "&J          J i ",
      " J          J i "
    ],
    [
      "!!  !!        ! ",
      "!!!!!![[[[[[[[! ",
      "!!  !!!       ! ",
      "             !!!",
      "/            !!!",
      "3            !i ",
      " JJJJJJJJJJJJ i ",
      " J          J i ",
      " J          J i ",
      " J          J i ",
      " J          J i ",
      " J          J i ",
      " J          J i ",
      "&J&         J i ",
      " J          J i ",
      " J          J i "
    ],
    [
      "!!  !!        ! ",
      "!!!!!![[[[[[[[! ",
      "!!  !!!       ! ",
      "             !!!",
      "             !!!",
      "             !i ",
      "    JJJJJJJJJ i ",
      " J          J i ",
      " J          J i ",
      " J          J i ",
      " J          J i ",
      " J          J i ",
      " J          J i ",
      "&J&         J i ",
      " J          J i ",
      " J          J i "
    ],
    [
      "!!  !!        !!",
      "!!!!!![[[[[[[[! ",
      "!!  !!!       ! ",
      "             !!!",
      "             !!!",
      "             !i ",
      "     JJJJJJJJ i ",
      "     JJJJJJJJ i ",
      " J   JJJJJJJJ i ",
      " JJJJJJJJJJJJ i ",
      " JJJJJJJJJJJJ i ",
      " JJJJJJJJJJJJ i ",
      " JJJJJJJJJJJJ i ",
      "&JJJJJJJJJJJJ i ",
      " JJJJJJJJJJJJ i ",
      " JJJJJJJJJJJJ i "
    ],
    [
      "!!  !!        !$",
      "!!!!!![[[[[[[[! ",
      "    !!!       ! ",
      "             !!!",
      "             !!!",
      "             !i ",
      "              i ",
      "              i ",
      "     5555     i ",
      "   5     5    i ",
      "  5       5   i ",
      " 5         5  i ",
      " 5         5  i ",
      " 5         5  i ",
      " 5         5  i ",
      " 5         5  i "
    ]
  ]
}