{
  "xsize": 16,
  "zsize": 16,
  "refpalette": "pomkotsmechs:factory",
  "slices": [
    [
      "   Vʹʹʹʹʹʹʹʹʹʹʹ͵",
      "   Vʹʹʹʹʹʹʹʹʹʹʹ͵",
      "   Vʹʹʹʹʹʹʹʹʹʹʹ͵",
      "   VVʹʹʹʹʹʹʹʹʹʹʹ",
      "    Vʹʹʹʹʹʹʹʹʹʹʹ",
      "    Vʹʹʹʹʹʹʹʹʹʹʹ",
      "     Vʹʹʹʹʹʹʹʹʹʹ",
      "    &VVʹʹʹʹʹʹʹʹʹ",
      "      VVʹʹʹʹʹʹʹʹ",
      "       VVʹʹʹʹʹʹʹ",
      "        VVʹʹʹʹʹʹ",
      "          VVVʹʹʹ",
      "            VVVV",
      "                ",
      "                ",
      "                "
    ],
    [
      "   Vʹʹʹʹʹʹʹʹʹʹʹ͵",
      "   Vʹʹʹʹʹʹʹʹʹʹʹ͵",
      "   Vʹʹʹʹʹʹʹʹʹʹʹʹ",
      "   VVʹʹʹʹʹʹʹʹʹʹʹ",
      "    Vʹʹʹʹʹʹʹʹʹʹʹ",
      "    Vʹʹʹʹʹʹʹʹʹʹʹ",
      "     Vʹʹʹʹʹʹʹʹʹʹ",
      "    &VVʹʹʹʹʹʹʹʹʹ",
      "     &VVʹʹʹʹʹʹʹʹ",
      "       VVʹʹʹʹʹʹʹ",
      "        VVʹʹʹʹʹʹ",
      "          VVVʹʹʹ",
      "            VVVV",
      "                ",
      "                ",
      "                "
    ],
    [
      "   Vʹʹʹʹʹʹʹʹʹʹʹ͵",
      "   Vʹʹʹʹʹʹʹʹʹʹʹ͵",
      "   Vʹʹʹʹʹʹʹʹʹʹʹʹ",
      "   VVʹʹʹʹʹʹʹʹʹʹʹ",
      "    Vʹʹʹʹʹʹʹʹʹʹʹ",
      "    Vʹʹʹʹʹʹʹʹʹʹʹ",
      "     Vʹʹʹʹʹʹʹʹʹʹ",
      "    &VVʹʹʹʹʹʹʹʹʹ",
      "     &VVʹʹʹʹʹʹʹʹ",
      "       VVʹʹʹʹʹʹʹ",
      "        VVʹʹʹʹʹʹ",
      "          VVVʹʹʹ",
      "            VVVV",
      "                ",
      "                ",
      "                "
    ],
    [
      "   Vʹʹʹʹʹʹʹʹʹʹʹ͵",
      "   Vʹʹʹʹʹʹʹʹʹʹʹ͵",
      "   Vʹʹʹʹʹʹʹʹʹʹʹʹ",
      "   VVʹʹʹʹʹʹʹʹʹʹʹ",
      "    Vʹʹʹʹʹʹʹʹʹʹʹ",
      "    Vʹʹʹʹʹʹʹʹʹʹʹ",
      "     Vʹʹʹʹʹʹʹʹʹʹ",
      "     VVʹʹʹʹʹʹʹʹʹ",
      "    &&VVʹʹʹʹʹʹʹʹ",
      "       VVʹʹʹʹʹʹʹ",
      "        VVʹʹʹʹʹʹ",
      "          VVVʹʹʹ",
      "            VVVV",
      "                ",
      "                ",
      "                "
    ],
    [
      "   Vʹʹʹʹʹʹʹʹʹʹʹ͵",
      "   Vʹʹʹʹʹʹʹʹʹʹʹ͵",
      "   Vʹʹʹʹʹʹʹʹʹʹʹʹ",
      "   VVʹʹʹʹʹʹʹʹʹʹʹ",
      "    Vʹʹʹʹʹʹʹʹʹʹʹ",
      "    Vʹʹʹʹʹʹʹʹʹʹʹ",
      "     Vʹʹʹʹʹʹʹʹʹʹ",
      "     VVʹʹʹʹʹʹʹʹʹ",
      "     &VVʹʹʹʹʹʹʹʹ",
      "      &VVʹʹʹʹʹʹʹ",
      "        VVʹʹʹʹʹʹ",
      "          VVVʹʹʹ",
      "            VVVV",
      "                ",
      "                ",
      "                "
    ],
    [
      "   Vʹʹʹʹʹʹʹʹʹʹʹ͵",
      "   Vʹʹʹʹʹʹʹʹʹʹʹ͵",
      "   Vʹʹʹʹʹʹʹʹʹʹʹʹ",
      "   VVʹʹʹʹʹʹʹʹʹʹʹ",
      "    Vʹʹʹʹʹʹʹʹʹʹʹ",
      "    Vʹʹʹʹʹʹʹʹʹʹʹ",
      "     Vʹʹʹʹʹʹʹʹʹʹ",
      "     VVʹʹʹʹʹʹʹʹʹ",
      "     &VVʹʹʹʹʹʹʹʹ",
      "     &&VVʹʹʹʹʹʹʹ",
      "        VVʹʹʹʹʹʹ",
      "          VVVʹʹʹ",
      "            VVVV",
      "                ",
      "                ",
      "                "
    ]
  ]
}