{
  "xsize": 16,
  "zsize": 16,
  "refpalette": "pomkotsmechs:factory",
  "slices": [
    [
      "!!!!!!!!!!!!!!!!",
      "!!!!!!!!!!!!!!!!",
      "!!!!!!!!!!!!!!!!",
      "!!!!!!!!!!!!!!!!",
      "!!!!!!!!!!!!!!!!",
      "!!!!!!!!!!!!!!!!",
      "!!!!!!!!!!<!!!!!",
      "!!!!!!!!!!<!!!!!",
      "!!!!!!!!<!<!!!!!",
      "!!!!!!!!!!8!!!!!",
      "!!!!!!!!#95!!!!!",
      "!!!!!!!!!!!!!!!!",
      "!!!!!!!!!!!!!!!!",
      "!!  !!!!!!!!!!!!",
      "!   !!!!!!!!!!!!",
      "     !!!!!!!!!!!"
    ],
    [
      "$$$    &&    $$$",
      "$!$    &&&   $!$",
      "$$!! !!&!! !!$$$",
      "  !!!!!!!!!!! &&",
      "   !<<<<<<<<!&& ",
      " &!!<!!!!!!!!&  ",
      "&&!!<!!'!!!!!   ",
      "&&&!<!!!!!!<!   ",
      "  !!<!!0!!!!!&  ",
      "  !!<!!!!!!!!&& ",
      "   !<!!!!!!<!&&&",
      "  !!<!!<!!<!!   ",
      " !!!!!!!!!!!!   ",
      "$$      &&&  $$$",
      "        &&   $!$",
      "        &    $$$"
    ],
    [
      " $            $ ",
      "$!$    &&    $!$",
      " $<< <<&<< << $ ",
      "  << << << <<   ",
      "  & <<<<<<<<&   ",
      " &<<<<< <<O<<&  ",
      " &<<<<< << <<   ",
      "  & <  +,/ <    ",
      "  <<<<<0<< <<   ",
      "  <<<<<2<< <<&  ",
      "   &<O    O<&   ",
      "  <<<<<<<<<<<   ",
      "   < << <<&<<   ",
      "         &    $ ",
      "             $!$",
      "              $ "
    ],
    [
      "      &&        ",
      " !    &&&       ",
      "  << <<&<< <<   ",
      "  <<!<<!<<!<<   ",
      "  &!<<<<<<<<!&  ",
      " &<<<<<!<<!<<&& ",
      "  <<<<<!<<5<<&  ",
      "   !<!!+,/6<!   ",
      "  <<<<<0<<!<<   ",
      "  <<<<<7<<!<<   ",
      "  &!<!!!!!!<!   ",
      "  <<<<<<<<<<<   ",
      "    !<<!<<!<<   ",
      "                ",
      "              ! ",
      "                "
    ],
    [
      "     &&&        ",
      " !   &&&&       ",
      "  << <<&<< <    ",
      "  << << << <    ",
      "  & !<<<<<<! && ",
      " &<<<<< <<!<<&&&",
      "&&<<<<< << <<&& ",
      "    <  +,/8<&&& ",
      "  <<<<<0<<6<<   ",
      "  <<<<<2<< <<   ",
      "  &&<!    !<    ",
      " &<<!<<<<<<<<   ",
      "  && << << <<   ",
      "                ",
      "              ! ",
      "                "
    ],
    [
      "!!!!!!!!!!!!!!!!",
      "!!!!!!!!!!!!!   ",
      "!!!!!!!!!!!!    ",
      "!!!!!!!!!!!!!   ",
      "!!!!!!!!!!!!!!& ",
      "!!!!!!!!!!O!!!!!",
      "!!!!!!!!!!<!!!!!",
      "!!! !!!!!!<!!!!!",
      "!!   &!!!!8!!!!!",
      "!!  &&!!!!6!!!!!",
      "!!!&&!!!!!8!!!!!",
      "!!!!!!!!!!!!!!!!",
      "!!&!!!!!!!!!!!!!",
      "!   !!!!!!!!!!!!",
      "     !!!!!!!!!!!",
      "     !!!!!!!!!!!"
    ]
  ]
}