{
  "xsize": 16,
  "zsize": 16,
  "refpalette": "pomkotsmechs:factory",
  "slices": [
    [
      "VVVVVVVVVVVVVVVV",
      "VVVVVVVVVVVVVVVV",
      "VVVVVVVVVVVVVVVV",
      "VVVVVVVVVVVVVVVV",
      "VVVVVVVVVVVVVVVV",
      "VVVVVVVVVVVVVVVV",
      "VVVVVVVVVVVVVVVV",
      "VVVVVVVVVVVVVVVV",
      "VVVVVVVVVVVVVVVV",
      "VVVVVVVVVVVVVVVV",
      "VVVVVVVVVVVVVVVV",
      "VVVVVVVVVVVVVVVV",
      "VVVVVVVVVVVVVVVV",
      "VVVVVVVVVVVVVVVV",
      "VVVVVVVVVVVVVVVV",
      "VVVVVVVVVVVVVVVV"
    ],
    [
      " !              ",
      " !        <<<<<<",
      " !        <     ",
      " !    VVVVVVVVVV",
      " !    V   <     ",
      " !    V   <<<<<<",
      " !    V         ",
      " !    V         ",
      " !    V         ",
      " !    V        V",
      " !    VVVVVVVVVV",
      " !    V        V",
      " !!   V    VV   ",
      "!!!   V    VV   ",
      "!!!   V         ",
      " !    V         "
    ],
    [
      " ]              ",
      " ]        <<<<<<",
      " ]        <     ",
      " ]    ^`````````",
      " ]    a   <     ",
      " ]    a   <<<<<<",
      " ]    a         ",
      " ]    a         ",
      " ]    a         ",
      " ]    a        V",
      " ]    c`````````",
      " ]             V",
      " ]!        +/   ",
      "!!!        23   ",
      "!!!             ",
      " !              "
    ],
    [
      " ]              ",
      " ]         <<<<<",
      " ]        <     ",
      " ]              ",
      " ]        <     ",
      " ]         <<<<<",
      " ]              ",
      " ]              ",
      " ]              ",
      " ]             V",
      " ]             V",
      " ]             V",
      " ]!        +/   ",
      "!!!        23   ",
      "!!!             ",
      " !              "
    ],
    [
      " ]              ",
      " ]         <<<<<",
      " ]        <<<<<<",
      " ]        <<<<<<",
      " ]        <<<<<<",
      " ]         <<<<<",
      " ]              ",
      " ]              ",
      " ]              ",
      " ]              ",
      " ]              ",
      " ]              ",
      " ]!        +/   ",
      "!!!        23   ",
      "!!!             ",
      " !              "
    ],
    [
      " ]              ",
      " ]              ",
      " ]          ! ! ",
      " ]           V  ",
      " ]          ! ! ",
      " ]              ",
      " ]              ",
      " ]              ",
      " ]              ",
      " ]              ",
      " ]              ",
      " ]              ",
      " ]!        +/   ",
      "!!!        23   ",
      "!!!             ",
      " !              "
    ]
  ]
}