{
  "xsize": 16,
  "zsize": 16,
  "refpalette": "lostcities:factory",
  "slices": [
    [
      "                ",
      " !,,,,,,,,,,,,!,",
      " 0              ",
      " 0              ",
      " 0            & ",
      " 0            & ",
      " 0            & ",
      " 0          &&& ",
      " 0&& &&55555&&& ",
      "&0&&&&5&&& &5&  ",
      " 0&& 5& &   &5  ",
      " 0  5         5 ",
      " 0  5         5 ",
      " 0  5         5 ",
      " !            5 ",
      "              5 "
    ],
    [
      "                ",
      " !,,,,,,,,,,,,!,",
      " 0              ",
      " 0              ",
      " 0              ",
      " 0              ",
      " 0              ",
      " 0         &    ",
      " 0 && &55555&&  ",
      "&0&&&&5&&&&&5&  ",
      " 0 &&5& &  &&5  ",
      " 0  5         5 ",
      " 0  5         5 ",
      " 0  5         5 ",
      " !            5 ",
      "              5 "
    ],
    [
      "                ",
      " $            $ ",
      "                ",
      "                ",
      "                ",
      "                ",
      "                ",
      "           &    ",
      "    &&&55555&   ",
      " & &&&5&&& &5   ",
      "    &5&&&    5  ",
      "    5&        5 ",
      "    5         5 ",
      "    5         5 ",
      " $            5 ",
      "              5 "
    ],
    [
      "                ",
      " !            ! ",
      "                ",
      "                ",
      "                ",
      "                ",
      "                ",
      "           &    ",
      "    && 55555&   ",
      "   &&&5&&  &5   ",
      "    &5&&     5  ",
      "    5&        5 ",
      "    5         5 ",
      "    5         5 ",
      " !            5 ",
      "              5 "
    ],
    [
      "                ",
      "                ",
      "                ",
      "                ",
      "                ",
      "                ",
      "                ",
      "          &&    ",
      "     & 55555&   ",
      "    &&5&& &&5   ",
      "    &5&&     5  ",
      "    5&        5 ",
      "    5         5 ",
      "    5         5 ",
      "              5 ",
      "              5 "
    ],
    [
      "                ",
      "                ",
      "                ",
      "                ",
      "                ",
      "                ",
      "                ",
      "          &     ",
      "     & 55555    ",
      "    &&5&& & 5   ",
      "    &5&&     5  ",
      "    5&        5 ",
      "    5         5 ",
      "    5         5 ",
      "              5 ",
      "              5 "
    ]
  ]
}