{
  "xsize": 16,
  "zsize": 16,
  "refpalette": "pomkotsmechs:factory",
  "slices": [
    [
      "                ",
      "                ",
      "                ",
      "                ",
      "                ",
      "                ",
      "      !  !      ",
      "       !!       ",
      "       !!       ",
      "      !  !      ",
      "                ",
      "                ",
      "                ",
      "                ",
      "                ",
      "                "
    ],
    [
      "                ",
      "                ",
      "VzzzzVvVVz||||}}",
      "VzzzVVVVVzzzz|||",
      "VzzVVvvVVVVVVVz|",
      "VzzVVvvvVVvvvVVz",
      "z||zVvvvvvvvvvVV",
      "z|}|zVVvVvvvvVVV",
      "z|}}|zVVVVVVVzzV",
      "z|}}}|zzVVVzz|zz",
      "z|}}||zzzzzz|||z",
      "z|||zzVVVVzz|||z",
      "|||zVVVVVVVzz|zz",
      "}|zVVvvvvVVVVVVV",
      "}|zVvvvvvvvvvVVV",
      "}|zVVvvvvvvvvvvv"
    ],
    [
      "                ",
      "                ",
      "                ",
      "                ",
      "                ",
      "        !!      ",
      "        !!      ",
      "                ",
      "                ",
      "                ",
      "                ",
      "                ",
      "               5",
      "               5",
      "               5",
      "                "
    ],
    [
      "                ",
      "                ",
      "                ",
      "                ",
      "                ",
      "                ",
      "                ",
      "                ",
      "                ",
      "                ",
      "                ",
      "                ",
      "               5",
      "&              5",
      "&              5",
      "                "
    ],
    [
      "                ",
      "                ",
      "                ",
      "                ",
      "                ",
      "                ",
      "                ",
      "                ",
      "                ",
      "                ",
      "                ",
      "                ",
      "               5",
      "&              5",
      "               5",
      "                "
    ],
    [
      "                ",
      "                ",
      "                ",
      "                ",
      "                ",
      "                ",
      "                ",
      "                ",
      "                ",
      "                ",
      "                ",
      "                ",
      "               5",
      "&              5",
      "               5",
      "                "
    ]
  ]
}