{
  "meta": [
    {
      "key": "dontconnect",
      "boolean": true
    }
  ],
  "xsize": 16,
  "zsize": 16,
  "refpalette": "lostcities:factory_common",
  "slices": [
    [
      " $ $ $aaaa$ $##$",
      "####a#    #a#fm#",
      "             ff#",
      "             ff#",
      "             ff#",
      "             ff#",
      "             ff#",
      "             ff#",
      "             ff#",
      "             ff#",
      "             ff#",
      "             ff#",
      "             ff#",
      "             ff#",
      "             ff#",
      "             ff#"
    ],
    [
      " $ $ $aaaa$ $##$",
      "####a#    #a#:m#",
      "             : #",
      "             : #",
      "             : #",
      "             : #",
      "             : #",
      "             : #",
      "             : #",
      "             : #",
      "             : #",
      "             : #",
      "             : #",
      "             : #",
      "             : #",
      "             : #"
    ],
    [
      " $ $ $aaaa$ $##$",
      "####a#    #a# m#",
      "               #",
      "               #",
      "               #",
      "               #",
      "               #",
      "               #",
      "               #",
      "               #",
      "               #",
      "               #",
      "               #",
      "               #",
      "               #",
      "               #"
    ],
    [
      " $ $ $aaaa$ $##$",
      "####a#    #a# m#",
      "               #",
      "               #",
      "               #",
      "               a",
      "               a",
      "               #",
      "               #",
      "               a",
      "               a",
      "               #",
      "               #",
      "               a",
      "               a",
      "               #"
    ],
    [
      " $ $ $aaaa$ $##$",
      "####a#    #a# m#",
      "               #",
      "               #",
      "               #",
      "               #",
      "               #",
      "               #",
      "               #",
      "               #",
      "               #",
      "               #",
      "               #",
      "               #",
      "               #",
      "               #"
    ],
    [
      " $ $ $aaaa$ $##$",
      "####a#    #a# m#",
      "               #",
      "               #",
      "               #",
      "               #",
      "               #",
      "               #",
      "               #",
      "               #",
      "               #",
      "               #",
      "               #",
      "               #",
      "               #",
      "               #"
    ]
  ]
}
