{
  "xsize": 16,
  "zsize": 16,
  "refpalette": "pomkotsmechs:factory",
  "slices": [
    [
      " !         !!  !",
      " ![[[[[[[[[!!!!!",
      " !        !!!  !",
      "!!!             ",
      "!!!            +",
      " ]!            2",
      " ] JJJJJJJJJJJJ ",
      " ] J          J ",
      " ] J          J5",
      "&]&J          J ",
      " ] J          J ",
      " ] J          J ",
      " ] J         &J&",
      " ] J          J ",
      " ] J          J ",
      " ] J          J "
    ],
    [
      "!!         !!  !",
      " ![[[[[[[[[!!!!!",
      " !        !!!  !",
      "!!!             ",
      "!!!            +",
      " ]!            2",
      " ] JJJJJJJJJJJJ ",
      " ] J          J ",
      " ] J          J5",
      "&]&J          J ",
      " ] J          J ",
      " ] J          J&",
      " ] J         &J&",
      " ] J          J&",
      " ] J          J ",
      " ] J          J "
    ],
    [
      " !         !!  !",
      " ![[[[[[[[[!!!!!",
      " !        !!!  !",
      "!!!             ",
      "!!!            +",
      " ]!            2",
      " ] JJJJJJJJJJJJ ",
      " ] J          J ",
      " ] J          J5",
      "&]&J          J5",
      " ] J          J5",
      " ] J          J5",
      " ] J          J5",
      " ] J          J5",
      " ] J          J5",
      " ] J          J5"
    ],
    [
      " !         !!  !",
      " ![[[[[[[[[!!!!!",
      " !        !!!  !",
      "!!!             ",
      "!!!            +",
      " ]!            2",
      " ] JJJJJJJJJJJJ ",
      " ] J          J ",
      " ] J          J5",
      "&]&J          J ",
      " ] J          J ",
      " ] J          J&",
      " ] J          J&",
      " ] J          J&",
      " ] J          J ",
      " ] J          J "
    ],
    [
      "!!         !!  !",
      " ![[[[[[[[[!!!!!",
      " !        !!!  !",
      "!!!             ",
      "!!!            +",
      " ]!            2",
      " ] JJJJJJJJJJJJ ",
      " ] J          J ",
      " ] J          J5",
      "&]&J          J ",
      " ] J          J ",
      " ] J          J&",
      " ] J          J&",
      " ] J          J ",
      " ] J          J ",
      " ] J          J "
    ],
    [
      ">!         !!  !",
      " ![[[[[[[[[!!!!!",
      " !        !!!  !",
      "!!!             ",
      "!!!            V",
      " ]!            V",
      " ] JJJJJJJJJJJJ ",
      " ] J          J5",
      " ] J          J5",
      "&]&J          J5",
      " ] J          J ",
      " ] J          J&",
      " ] J          J&",
      " ] J          J&",
      " ] J          J ",
      " ] J          J "
    ]
  ]
}