{
  "xsize": 16,
  "zsize": 16,
  "refpalette": "pomkotsmechs:factory",
  "slices": [
    [
      "                ",
      "                ",
      "!!!! !          ",
      "XXXX!!          ",
      "    XX!!        ",
      "      XX!!      ",
      "        X!!     ",
      "         X!     ",
      "          X!    ",
      "          X!    ",
      "           X!!  ",
      "           X!&  ",
      "            X!  ",
      "            X!  ",
      "            X!  ",
      "            X!  "
    ],
    [
      "                ",
      "                ",
      "!!!! !          ",
      "XXXX!!          ",
      "    XX!!        ",
      "      XX!!      ",
      "        X!!     ",
      "         X!     ",
      "          X!    ",
      "          X!    ",
      "           X!!  ",
      "           X!&  ",
      "           &X!  ",
      "           &X!  ",
      "            X!  ",
      "            X!  "
    ],
    [
      "                ",
      "                ",
      "                ",
      "XXXX            ",
      "XXXXXX          ",
      "XXXXXXXX        ",
      "XXXXXXXXX       ",
      "XXXXXXXXXX      ",
      "XXXXXXXXXXX     ",
      "XXXXXXXXXXX     ",
      "XXXXXXXXXXXX    ",
      "XXXXXXXXXXXX&   ",
      "XXXXXXXXXXXXX&  ",
      "XXXXXXXXXXXXX   ",
      "XXXXXXXXXXXXX   ",
      "XXXXXXXXXXXXX   "
    ],
    [
      "                ",
      "                ",
      "                ",
      "                ",
      "XXX             ",
      "XXXXXX          ",
      "XXXXXXX         ",
      "XXXXXXXX        ",
      "XXXXXXXXX       ",
      "XXXXXXXXXX      ",
      "XXXXXXXXXXX     ",
      "XXXXXXXXXXX     ",
      "XXXXXXXXXXX&&   ",
      "XXXXXXXXXXXX&   ",
      "XXXXXXXXXXXX    ",
      "XXXXXXXXXXXX    "
    ],
    [
      "                ",
      "                ",
      "                ",
      "                ",
      "                ",
      "XXX             ",
      "XXXXXX          ",
      "XXXXXXX         ",
      "XXXXXXXX        ",
      "XXXXXXXXX       ",
      "XXXXXXXXXX      ",
      "XXXXXXXXXX      ",
      "XXXXXXXXXX&     ",
      "XXXXXXXXXXX&    ",
      "XXXXXXXXXXX&    ",
      "XXXXXXXXXXX     "
    ],
    [
      "                ",
      "                ",
      "                ",
      "                ",
      "                ",
      "                ",
      "                ",
      "                ",
      "                ",
      "                ",
      "&&              ",
      "&&&             ",
      "&&&&            ",
      "&&&  &&&&&&     ",
      "&&&&&&&&&&&     ",
      "  &&&&&&&&      "
    ]
  ]
}