{
  "xsize": 16,
  "zsize": 16,
  "refpalette": "lostcities:factory",
  "slices": [
    [
      "!!  !!        ! ",
      "!!!!!![[[[[[[[! ",
      "!!  !!!       ! ",
      "             !!!",
      "/            !!!",
      "3            !i ",
      " JJJJJJJJJJJJ i ",
      " J          J i ",
      " J          J i ",
      " J          J i ",
      " J          J i ",
      " J          J i ",
      " J          J i ",
      "&J          J i ",
      "&J          J i ",
      " J          J i "
    ],
    [
      "!!  !!        !!",
      "!!!!!![[[[[[[[! ",
      "!!  !!!       ! ",
      "             !!!",
      "/            !!!",
      "3            !i ",
      " JJJJJJJJJJJJ i ",
      " J          J i ",
      " J          J i ",
      " J          J i ",
      " J          J i ",
      " J          J i ",
      " J          J i ",
      " J          J i ",
      "&J          J i ",
      " J          J i "
    ],
    [
      "!!  !!        ! ",
      "!!!!!![[[[[[[[! ",
      "!!  !!!       ! ",
      "             !!!",
      "/            !!!",
      "3            !i ",
      " JJJJJJJJJJJJ i ",
      " J          J i ",
      " J          J i ",
      " J          J i ",
      " J          J i ",
      " J          J i ",
      " J          J i ",
      " J          J i ",
      "&J          J i ",
      " J          J i "
    ],
    [
      "!!  !!        ! ",
      "!!!!!![[[[[[[[! ",
      "!!  !!!       ! ",
      "             !!!",
      "/            !!!",
      "3            !i ",
      " JJJJJJJJJJJJ i ",
      " J          J i ",
      " J          J i ",
      " J          J i ",
      " J          J i ",
      " J          J i ",
      " J          J i ",
      " J          J i ",
      "&J          J i ",
      " J          J i "
    ],
    [
      "!!  !!        !!",
      "!!!!!![[[[[[[[! ",
      "!!  !!!       ! ",
      "             !!!",
      "/            !!!",
      "3            !i ",
      " JJJJJJJJJJJJ i ",
      " J          J i ",
      " J          J i ",
      " J          J i ",
      " J          J i ",
      " J          J i ",
      " J          J i ",
      " J          J i ",
      " J          J i ",
      " J          J i "
    ],
    [
      "!!  !!        !@",
      "!!!!!![[[[[[[[! ",
      "!!  !!!       ! ",
      "             !!!",
      "V            !!!",
      "V            !i ",
      " JJJJJJJJJJJJ i ",
      " J          J i ",
      " J          J i ",
      " J          J i ",
      " J          J i ",
      " J          J i ",
      " J          J i ",
      "&J          J i ",
      " J          J i ",
      " J          J i "
    ]
  ]
}