{
  "xsize": 16,
  "zsize": 16,
  "refpalette": "pomkotsmechs:factory",
  "slices": [
    [
      "             55&",
      "5           55&&",
      " 55       55 && ",
      "   5555555      ",
      "                ",
      "                ",
      "                ",
      "                ",
      "                ",
      "                ",
      "                ",
      "                ",
      "    55555555    ",
      "  555      555  ",
      "55            55",
      "5              5"
    ],
    [
      "             55 ",
      "5           55&&",
      " 55       55 && ",
      "   5555555      ",
      "                ",
      "                ",
      "                ",
      "                ",
      "                ",
      "                ",
      "                ",
      "                ",
      "    55555555    ",
      "  555      555  ",
      "55            55",
      "5              5"
    ],
    [
      "             55 ",
      "5           55&&",
      " 55       55 && ",
      "   5555555      ",
      "                ",
      "                ",
      "                ",
      "                ",
      "                ",
      "                ",
      "                ",
      "                ",
      "    55555555    ",
      "  555      555  ",
      "55            55",
      "5              5"
    ],
    [
      "             55&",
      "5           55&&",
      " 55       55 &&&",
      "   5555555    & ",
      "                ",
      "                ",
      "                ",
      "                ",
      "                ",
      "                ",
      "                ",
      "                ",
      "    55555555    ",
      "  555      555  ",
      "55            55",
      "5              5"
    ],
    [
      "55           55&",
      "55          55& ",
      " 55       55  & ",
      "   5555555      ",
      "                ",
      "                ",
      "                ",
      "                ",
      "                ",
      "                ",
      "                ",
      "                ",
      "    55555555    ",
      "  555      555  ",
      "55            55",
      "5              5"
    ],
    [
      " 5           55&",
      "5           55& ",
      " 55       55    ",
      "   5555555      ",
      "                ",
      "                ",
      "                ",
      "                ",
      "                ",
      "                ",
      "                ",
      "                ",
      "    55555555    ",
      "  555      555  ",
      "55            55",
      "5              5"
    ]
  ]
}