{
  "xsize": 16,
  "zsize": 16,
  "refpalette": "pomkotsmechs:factory",
  "slices": [
    [
      "J              J",
      "J              J",
      "J              J",
      " J            J ",
      " J            J&",
      "  J          J &",
      "   JJ      JJ   ",
      "     JJJJJJ     ",
      "                ",
      "                ",
      "                ",
      "                ",
      "                ",
      "                ",
      "                ",
      "                "
    ],
    [
      "J              J",
      "J              J",
      "J              J",
      " J            J ",
      " J            J ",
      "  J          J &",
      "   JJ      JJ   ",
      "     JJJJJJ     ",
      "                ",
      "                ",
      "                ",
      "                ",
      "                ",
      "                ",
      "                ",
      "                "
    ],
    [
      "J              J",
      "J              J",
      "J              J",
      " J            J ",
      " J            J ",
      "  J          J &",
      "   JJ      JJ   ",
      "     JJJJJJ     ",
      "                ",
      "                ",
      "                ",
      "                ",
      "                ",
      "                ",
      "                ",
      "                "
    ],
    [
      "J              J",
      "J              J",
      "J              J",
      " J            J ",
      " J            J ",
      "  J          J &",
      "   JJ      JJ   ",
      "     JJJJJJ     ",
      "                ",
      "                ",
      "                ",
      "                ",
      "                ",
      "                ",
      "                ",
      "                "
    ],
    [
      "J              J",
      "J              J",
      "J              J",
      " J            J ",
      " J            J&",
      "  J             ",
      "   JJ      J    ",
      "     JJJJJJ     ",
      "                ",
      "                ",
      "V               ",
      "V              V",
      "V              V",
      "V              V",
      "V              V",
      "V              V"
    ],
    [
      "Jr            rJ",
      "J!            !J",
      "J!            !J",
      "rJ            Jr",
      "rJ            Jr",
      "rrJ          Jrr",
      "rrrJJ      JJrrr",
      "rrrrrJJJJJJrr   ",
      "rrrrrrrrrrrrrr  ",
      "rrrrrrrrrrrrrr  ",
      "rrrrrrrrrrrrrrr ",
      "rrrrrrrrrrrrrrrr",
      "rrrrrrrrrrrrrrrr",
      "rrrrrrrrrrrrrrrr",
      "rrrrrrrrrrrrrrrr",
      "rrrrrrrrrrrrrrrr"
    ]
  ]
}