{
  "xsize": 16,
  "zsize": 16,
  "refpalette": "lostcities:factory",
  "slices": [
    [
      "  5       5  !!!",
      "   5     5   !!!",
      "    55555    !!!",
      "             !!!",
      "             !!!",
      "/            !!!",
      "3            !!!",
      "             !!!",
      "             !! ",
      "             !! ",
      "             !!!",
      "/            !!!",
      "3            !!!",
      "             !!!",
      "             !!!",
      "             !!!"
    ],
    [
      "  5       5  !!!",
      "   5     5   !!!",
      "    55555    !!!",
      "             !!!",
      "             !!!",
      "/            !!!",
      "3            !!!",
      "             !!!",
      "             !! ",
      "             !! ",
      "             !!!",
      "/            !!!",
      "3            !!!",
      "             !!!",
      "             !!!",
      "             !!!"
    ],
    [
      "  5       5   i ",
      "   5     5   !i ",
      "    55555     i ",
      "              i ",
      "             !i ",
      "/            !!!",
      "3            !!!",
      "             !!!",
      "              ! ",
      "              ! ",
      "             !!!",
      "/            !!!",
      "3            !!!",
      "             !i ",
      "              i ",
      "              i "
    ],
    [
      "  5       5     ",
      "   5     5   !  ",
      "    55555       ",
      "                ",
      "             !  ",
      "V            !!!",
      "V            !!!",
      "             !!!",
      "                ",
      "                ",
      "             !!!",
      "V            !!!",
      "V            !!!",
      "             !  ",
      "                ",
      "                "
    ],
    [
      "V 5       5     ",
      "V  5     5      ",
      "V   55555    V  ",
      "V            V  ",
      "V            !  ",
      "nVVVVVVVVVVVVV!!",
      "nVVVVVVVVVVVV!!!",
      "VV           !!!",
      "             V  ",
      "             V  ",
      "VV           !!!",
      "nVVVVVVVVVVVV!!!",
      "nVVVVVVVVVVVVV!!",
      "VV           !  ",
      "V            V  ",
      "V            V  "
    ],
    [
      "!r5       5r    ",
      "!rr5     5rr    ",
      "!rrr55555rrr    ",
      "!rrrrrrrrrrrr!!!",
      "!rrrrrrrrrrrr!!!",
      "!!!!!!!!!!!!!!!!",
      "!!!!!!!!!!!!!!!!",
      "!!!!!!!!!!!!!!!!",
      "rrrrrrrrrrrrr!!!",
      "rrrrrrrrrrrrr!!!",
      "!!!!!!!!!!!!!!!!",
      "!!!!!!!!!!!!!!!!",
      "!!!!!!!!!!!!!!!!",
      "!!!!!!!!!!!!!!!!",
      "!!rrrrrrrrrr!!!!",
      "!!rrrrrrrrrr!!!!"
    ]
  ]
}