{
  "xsize": 16,
  "zsize": 16,
  "refpalette": "pomkotsmechs:factory",
  "slices": [
    [
      " !!!         !!!",
      "!!!!!           ",
      " !!!            ",
      "  !    !!!!     ",
      "  J     rr      ",
      " &&&    rr      ",
      " &&&   !  !     ",
      "  &             ",
      "                ",
      "                ",
      "  J             ",
      "  !           ! ",
      " !!!      && !!!",
      "!!!!!JJJJJJJ!!!!",
      " !!!    ! &&   !",
      "  !             "
    ],
    [
      "!!!!!        !!!",
      "!!!!!           ",
      " !!!            ",
      "  !    !!!!     ",
      "  !     rr      ",
      " &&&    rr      ",
      "  &    !  !     ",
      "                ",
      "                ",
      "                ",
      "  !             ",
      "  !           !!",
      " !!!       & !!!",
      "!!!!!!!!!!!!! !!",
      " !!!    !  &   !",
      "  !           !!"
    ],
    [
      "!!!!!        !!!",
      "!!!!!           ",
      " !!!            ",
      "  !&&  !!!!     ",
      "  J&    rr      ",
      " &J&    rr      ",
      "  &    !  !     ",
      "                ",
      "                ",
      "  J          &  ",
      "  J          &  ",
      "  !         &&!!",
      " !!!       &&!!!",
      "!!!!!JJJJJJJ! !!",
      " !!!    !  &   !",
      "  !           !!"
    ],
    [
      "!!!!!!!!!!!  !!!",
      "!!!!!!!!!!!     ",
      " !!!!!!!!!!  &  ",
      "  !!!!!!!!!  &  ",
      "  J!!!! rr   &  ",
      " &J!!!! rr      ",
      "  J!!!!!  !!!!!!",
      " !J !!!!!!!!!!!!",
      "  J!!!!!!!!!!!!!",
      "  J!!!!!!!!!!!!!",
      "  J!!!!!!!!!!!!!",
      "  !!!!!!!!!!!!!!",
      " !!!!!!!!!!!!!!!",
      "!!!!!JJJJJJJ! !!",
      " !!!    !  &   !",
      "  !           !!"
    ],
    [
      "!!!!!!!!!!!!!!!!",
      "!!!!!!!!!!!!!!!!",
      " !!!&!!!!!!!!!!!",
      "  !&&!!!!!!!!!!!",
      " &!&&!!!!!!!!!!!",
      " &!& !!!!!!!!!!!",
      "  !  !!!!!!!!!!!",
      " !!  !!!!!!!!!!!",
      "  !  !!!!!!!!!!!",
      "  !         &&& ",
      "  !         &&  ",
      "  !        &&&!!",
      " !!!       &&!!!",
      "!!!!!!!!!!!!!&!!",
      " !!!    !  &&  !",
      "  !           !!"
    ],
    [
      "!!!!!&&     !!!!",
      "!!!!!&       !!!",
      " !!!&       &&!!",
      "  !&&& !!!!  &&!",
      "  &&&   rr  &&& ",
      "  &     rr  &&& ",
      "       !  !  &  ",
      " !           &  ",
      "            &&& ",
      "            &&& ",
      "             &  ",
      "  !         &&!!",
      " !!!        &!!!",
      "!!!!!      &!!!!",
      " !!!    !   & !!",
      "  !           !!"
    ]
  ]
}