{
  "xsize": 16,
  "zsize": 16,
  "refpalette": "lostcities:factory",
  "slices": [
    [
      "                ",
      "                ",
      " &              ",
      "VVVV            ",
      "ʹʹʹVVV          ",
      "ʹʹʹʹʹʹVV        ",
      "ʹʹʹʹʹʹʹVV       ",
      "ʹʹʹʹʹʹʹʹVV      ",
      "ʹʹʹʹʹʹʹʹʹVV     ",
      "ʹʹʹʹʹʹʹʹʹʹV     ",
      "ʹʹʹʹʹʹʹʹʹʹʹV    ",
      "ʹʹʹʹʹʹʹʹʹʹʹV    ",
      "ʹʹʹʹʹʹʹʹʹʹʹVV&  ",
      "ʹʹʹʹʹʹʹʹʹʹʹʹV!  ",
      "ʹʹʹʹʹʹʹʹʹʹʹʹV!  ",
      "ʹʹʹʹʹʹʹʹʹʹʹʹV!  "
    ],
    [
      "                ",
      "                ",
      " &              ",
      "VVVV            ",
      "V& VVV          ",
      "V&    VV        ",
      "V      VV       ",
      "V       VV      ",
      "V        VV     ",
      "V         V     ",
      "V          V&   ",
      "V          V&   ",
      "V          VV&  ",
      "V           V!  ",
      "V           V   ",
      "VV          V!  "
    ],
    [
      "                ",
      "                ",
      " &              ",
      "VVVV            ",
      "&  VVV          ",
      "&     VV        ",
      "&      VV       ",
      "&       VV      ",
      "&        VV     ",
      "&         V     ",
      "&          V&   ",
      "&          V&   ",
      "           VV&  ",
      "            V!  ",
      "            V!  ",
      "            V!  "
    ],
    [
      "                ",
      "                ",
      " &              ",
      "&&              ",
      "&               ",
      "                ",
      "                ",
      "                ",
      "                ",
      "                ",
      "           &    ",
      "           &    ",
      "           &&   ",
      "             !  ",
      "                ",
      "             !  "
    ],
    [
      "                ",
      "                ",
      "                ",
      "                ",
      "                ",
      "                ",
      "                ",
      "                ",
      "                ",
      "                ",
      "                ",
      "                ",
      "                ",
      "                ",
      "                ",
      "                "
    ],
    [
      "                ",
      "                ",
      "                ",
      "                ",
      "                ",
      "                ",
      "                ",
      "                ",
      "                ",
      "                ",
      "                ",
      "                ",
      "                ",
      "                ",
      "                ",
      "                "
    ]
  ]
}