{
  "xsize": 16,
  "zsize": 16,
  "refpalette": "pomkotsmechs:factory",
  "slices": [
    [
      "    5        &55",
      "   5        &55&",
      "555          5& ",
      "            5   ",
      "            5   ",
      "           5    ",
      "           5    ",
      "           5    ",
      "           5    ",
      "           5    ",
      "           5    ",
      "           5    ",
      "            5   ",
      "            5   ",
      "             5  ",
      "             55 "
    ],
    [
      "    5        &55",
      "   5         55 ",
      "555          5  ",
      "            5   ",
      "            5   ",
      "           5    ",
      "           5    ",
      "           5    ",
      "           5    ",
      "           5    ",
      "           5    ",
      "           5    ",
      "            5   ",
      "            5   ",
      "             5  ",
      "             55 "
    ],
    [
      "    5        &55",
      "   5         55 ",
      "555          5  ",
      "            5   ",
      "            5   ",
      "           5    ",
      "           5    ",
      "           5    ",
      "           5    ",
      "           5    ",
      "           5    ",
      "           5    ",
      "            5   ",
      "            5   ",
      "             5  ",
      "             55 "
    ],
    [
      "    5        &55",
      "   5         55 ",
      "555          5  ",
      "            5   ",
      "            5   ",
      "           5    ",
      "           5    ",
      "           5    ",
      "           5    ",
      "           5    ",
      "           5    ",
      "           5    ",
      "            5   ",
      "            5   ",
      "             5  ",
      "             55 "
    ],
    [
      "    5        &55",
      "   5         555",
      "555          555",
      "            5555",
      "            5555",
      "           55555",
      "           55555",
      "           55555",
      "           55555",
      "           55555",
      "           55555",
      "           55555",
      "            5555",
      "            5555",
      "             555",
      "             555"
    ],
    [
      "    5        &55",
      "   5         55 ",
      "555          5  ",
      "            5   ",
      "            5   ",
      "           5    ",
      "           5    ",
      "           5    ",
      "           5    ",
      "           5    ",
      "           5    ",
      "           5    ",
      "            5   ",
      "            5   ",
      "             5  ",
      "             55 "
    ]
  ]
}