{
  "xsize": 16,
  "zsize": 16,
  "refpalette": "lostcities:factory",
  "slices": [
    [
      "           <   <",
      "           <   <",
      "           <   <",
      "           <   <",
      "           <   <",
      "           <   <",
      "           <   <",
      "          X<XXX<",
      "          X<XXX<",
      "         &X<XXX<",
      "          X<<<<<",
      "          XXXXXX",
      "          XXXXXX",
      "                ",
      "                ",
      "                "
    ],
    [
      "           <   <",
      "           y   <",
      "           y   <",
      "           <   <",
      "           <    ",
      "           <    ",
      "           <   <",
      "           <   <",
      "          &<   <",
      "         &&<&  <",
      "          &<<<<<",
      "                ",
      "                ",
      "                ",
      "                ",
      "                "
    ],
    [
      "           <   <",
      "           y   y",
      "           y   y",
      "           <   <",
      "           <    ",
      "           <    ",
      "           <   <",
      "           <   <",
      "           <   <",
      "          &<&  <",
      "           <yyy<",
      "                ",
      "                ",
      "                ",
      "                ",
      "                "
    ],
    [
      "           <   <",
      "           y   y",
      "           y   y",
      "           <   <",
      "           <    ",
      "           <    ",
      "           <   <",
      "           <   <",
      "           <   <",
      "          &<&  <",
      "           <yyy<",
      "                ",
      "                ",
      "                ",
      "                ",
      "                "
    ],
    [
      "           <yyy<",
      "           <<<<<",
      "           <<<<<",
      "           <<<<<",
      "           <<<<<",
      "           <<<<<",
      "           <<<<<",
      "           <<<<<",
      "           <<<<<",
      "          &<<<<<",
      "           <<<<<",
      "                ",
      "                ",
      "                ",
      "                ",
      "                "
    ],
    [
      "                ",
      "                ",
      "                ",
      "                ",
      "                ",
      "                ",
      "                ",
      "                ",
      "                ",
      "           &    ",
      "                ",
      "                ",
      "                ",
      "                ",
      "                ",
      "                "
    ]
  ]
}