{
  "xsize": 16,
  "zsize": 16,
  "refpalette": "pomkotsmechs:factory",
  "slices": [
    [
      "VVV!!!!!!!!!!VVV",
      "VVV!!!!!!!!!!VVV",
      "VVV!!!!!!!!!!VVV",
      "VVV!!!!!!!!!!VVV",
      "VVV!!!!!!!!!!VVV",
      "VVV!!!!!!!!!!VVV",
      "VVV!!!!!!!!!!VVV",
      "VVV!!!!!!!!!!VVV",
      "VVV!!!!!!!!!!VVV",
      "VVV!!!!!!!!!!VVV",
      "VVV!!!!!!!!!!VVV",
      "VVV!!!!!!!!!!VVV",
      "VVV!!!!!!!!!!VVV",
      "VVV!!!!!!!!!!VVV",
      "VVV!!!!!!!!!!VVV",
      "VVV!!!!!!!!!!VVV"
    ],
    [
      "V            &&V",
      "V            & V",
      "V           && V",
      "V              V",
      "VV            VV",
      "VV            VV",
      "VV            VV",
      "VV            VV",
      "                ",
      "                ",
      "VV            VV",
      "VV            VV",
      "VV            VV",
      "VV            VV",
      "                ",
      "                "
    ],
    [
      "                ",
      "5               ",
      "5               ",
      "5               ",
      "                ",
      "V              V",
      "V              V",
      "                ",
      "                ",
      "                ",
      "                ",
      "V              V",
      "V              V",
      "                ",
      "                ",
      "                "
    ],
    [
      "                ",
      "                ",
      "                ",
      "                ",
      "                ",
      "/              +",
      "3              2",
      "                ",
      "                ",
      "                ",
      "                ",
      "/              +",
      "3              2",
      "                ",
      "                ",
      "                "
    ],
    [
      "                ",
      "                ",
      "                ",
      "                ",
      "                ",
      "/              +",
      "3              2",
      "                ",
      "                ",
      "                ",
      "                ",
      "/              +",
      "3              2",
      "                ",
      "                ",
      "                "
    ],
    [
      "                ",
      "                ",
      "                ",
      "                ",
      "                ",
      "/              +",
      "3              2",
      "                ",
      "                ",
      "                ",
      "                ",
      "/              +",
      "3              2",
      "                ",
      "                ",
      "                "
    ]
  ]
}