{
  "xsize": 16,
  "zsize": 16,
  "refpalette": "lostcities:factory",
  "slices": [
    [
      "                ",
      "                ",
      "                ",
      "                ",
      "                ",
      "                ",
      "      !  !      ",
      "       !!       ",
      "       !!       ",
      "      !  !      ",
      "                ",
      "                ",
      "                ",
      "                ",
      "                ",
      "                "
    ],
    [
      "     }}||zz|||zv",
      "     }}}||||||zv",
      "     }}}}|||||zV",
      "     v}|||||||zz",
      "     v||||z|||||",
      "     vz||zzz|||v",
      "     vzz||z|||}v",
      "     vVz||||}}}}",
      "     vV|}}}}}}}}",
      "     vz|}}}}}}}|",
      "     vz}}}}}}}||",
      "     vz}}}}|||||",
      "     vz|}}|zzzz|",
      "     vz|}}|zVVz|",
      "     vz|||zVVVz|",
      "     vz||zzVVV|}"
    ],
    [
      "              5 ",
      "               5",
      "                ",
      "                ",
      "                ",
      "                ",
      "                ",
      "               5",
      "               5",
      "               5",
      "                ",
      "                ",
      "                ",
      "                ",
      "                ",
      "                "
    ],
    [
      "              5 ",
      "               5",
      "                ",
      "                ",
      "                ",
      "                ",
      "                ",
      "                ",
      "                ",
      "                ",
      "                ",
      "                ",
      "                ",
      "                ",
      "                ",
      "                "
    ],
    [
      "              5 ",
      "               5",
      "                ",
      "                ",
      "                ",
      "                ",
      "                ",
      "                ",
      "                ",
      "                ",
      "                ",
      "                ",
      "                ",
      "                ",
      "                ",
      "                "
    ],
    [
      "             55 ",
      "              55",
      "               5",
      "                ",
      "                ",
      "                ",
      "                ",
      "                ",
      "                ",
      "                ",
      "                ",
      "                ",
      "                ",
      "                ",
      "                ",
      "                "
    ]
  ]
}