{
  "xsize": 16,
  "zsize": 16,
  "refpalette": "pomkotsmechs:factory",
  "slices": [
    [
      "V!!!!!!!!!!!!!!!",
      "V!!!!!!!!!!!!!!!",
      "V!!!!!!!!!!!!!!!",
      "V!!!!!!!!!!!!!!!",
      "V!!!!!!!!!!!!!!!",
      "VVV!!!!!!!!!!VVV",
      "VVV!!!!!!!!!!VVV",
      "VVV!!!!!!!!!!VVV",
      "VVV!!!!!!!!!!VVV",
      "VVV!!!!!!!!!!VVV",
      "VVV!!!!!!!!!!VVV",
      "VVV!!!!!!!!!!VVV",
      "VVV!!!!!!!!!!VVV",
      "VVV!!!!!!!!!!VVV",
      "                ",
      "VVV!!!!!!!!!!VVV"
    ],
    [
      "e            &&f",
      "e           && f",
      "e           &  f",
      "e              f",
      "e              f",
      "V              V",
      "V              V",
      "V              V",
      "V              V",
      "VV            VV",
      "VV            VV",
      "VV            VV",
      "VV            VV",
      "                ",
      "!!!!!!!!!!!!!!!!",
      "!               "
    ],
    [
      "                ",
      "                ",
      "                ",
      "                ",
      "                ",
      "                ",
      "                ",
      "                ",
      "                ",
      "                ",
      "V              V",
      "V              V",
      "                ",
      "                ",
      "!               ",
      "!               "
    ],
    [
      "                ",
      "                ",
      "                ",
      "                ",
      "                ",
      "                ",
      "                ",
      "                ",
      "                ",
      "                ",
      "/              +",
      "3              2",
      "                ",
      "                ",
      "!               ",
      "!               "
    ],
    [
      "                ",
      "                ",
      "                ",
      "                ",
      "                ",
      "                ",
      "                ",
      "                ",
      "                ",
      "                ",
      "/              +",
      "3              2",
      "                ",
      "                ",
      "!               ",
      "!               "
    ],
    [
      "                ",
      "                ",
      "                ",
      "                ",
      "                ",
      "                ",
      "                ",
      "                ",
      "                ",
      "                ",
      "/              +",
      "3              2",
      "                ",
      "                ",
      "!               ",
      "!               "
    ]
  ]
}