{
  "xsize": 16,
  "zsize": 16,
  "refpalette": "lostcities:factory",
  "slices": [
    [
      "VVV!!!!!!!!!!VVV",
      "VVV!!!!!!!!!!VVV",
      "VVV!!!!!!!!!!VVV",
      "VVV!!!!!!!!!!VVV",
      "VVV!!!!!!!!!!VVV",
      "VVV!!!!!!!!!!VVV",
      "VVV!!!!!!!!!!VVV",
      "VVV!!!!!!!!!!VVV",
      "V!V!!!!!!!!!!VVV",
      "VVV!!!!!!!!!!VVV",
      "VVV!!!!!!!!!!VVV",
      "VVV!!!!!!!!!!VVV",
      "VVV!!!!!!!!!!VVV",
      "VVV!!!!!!!!!!VVV",
      "VVV!!!!!!!!!!VVV",
      "VVV!!!!!!!!!!VVV"
    ],
    [
      "                ",
      "                ",
      "<               ",
      "<              J",
      "<              J",
      "               J",
      "               J",
      "               J",
      " !            ! ",
      "VV           VVV",
      "VV           VVV",
      "VV           VVV",
      "                ",
      "               J",
      "               J",
      "               J"
    ],
    [
      "                ",
      "                ",
      "<               ",
      "<              J",
      "<              X",
      "               X",
      "               X",
      "               J",
      " !            ! ",
      "VV           VVV",
      "`V            V ",
      "VV           VVV",
      "                ",
      "               J",
      "               X",
      "               X"
    ],
    [
      "                ",
      "                ",
      "<               ",
      "               J",
      "<               ",
      "                ",
      "                ",
      "               J",
      " !            ! ",
      "VV           VVV",
      "VV           VVV",
      "VV           VVV",
      "                ",
      "               J",
      "                ",
      "                "
    ],
    [
      "                ",
      "                ",
      "<               ",
      "<              J",
      "<              J",
      "               J",
      "               J",
      "               J",
      " !            ! ",
      "                ",
      "V             V ",
      "                ",
      "                ",
      "               J",
      "               J",
      "               J"
    ],
    [
      "                ",
      "                ",
      "                ",
      "               J",
      "               X",
      "               X",
      "               X",
      "               J",
      " !            ! ",
      "                ",
      "V             V ",
      "                ",
      "                ",
      "               J",
      "               X",
      "               X"
    ]
  ]
}