{
  "xsize": 16,
  "zsize": 16,
  "refpalette": "pomkotsmechs:factory",
  "slices": [
    [
      "!!!!!     !!!!!!",
      "!!!!!    !!!!!!!",
      "!!!!!    !!!!!!!",
      "!!!!!!! !!!!!!!!",
      "!!!!!!!!!!!!!!!!",
      "!!!!!!!!!!!!!!!!",
      "!!!!!!!!!!&!!!!!",
      "!!!!!!!!!!&!!!!!",
      "!!!!!!!!!! !   !",
      "!!!!!!!!!!8!    ",
      "!!!!!!!!!!!!    ",
      "!!!!!!!!!!!!    ",
      "!!!!!!!!!!!!!  !",
      "!!!!!!!!!!!!!!!!",
      "!!!!!!!!!!!!!!!!",
      "!!!!!!!!!!!!!!!!"
    ],
    [
      "!,,,,     !,,,,!",
      "0              0",
      "0 VVV     !!   0",
      "0 V!!!         0",
      "0 V!!!V ! &  ! !",
      "! V!!!V&!&&  !  ",
      "  VVVVV&&&&&    ",
      "     &&&&&!!    ",
      "       && &     ",
      "       &        ",
      "!     &&        ",
      "0    &&&&       ",
      "0    &&&        ",
      "0    &&&        ",
      "0  &&&&&       0",
      "!,,,,!&   !,,,,!"
    ],
    [
      "$              $",
      "                ",
      "  VVVV    55    ",
      "  V   V  5555   ",
      "  V   V 555555  ",
      "  V&&&V 555555  ",
      " &VVVVV& 5555   ",
      "  &&&&  &&55    ",
      "          &     ",
      "                ",
      "                ",
      "      &&        ",
      "      &         ",
      "      &         ",
      "     &&         ",
      "$  &&&         $"
    ],
    [
      "                ",
      "                ",
      "          55    ",
      "         5555   ",
      "        55  55  ",
      "        55  55  ",
      "  &&&&   5555   ",
      "          55    ",
      "                ",
      "                ",
      "                ",
      "                ",
      "                ",
      "                ",
      "                ",
      "                "
    ],
    [
      "                ",
      "                ",
      "          55    ",
      "         5555   ",
      "        55  55  ",
      "        55  55  ",
      "         5555   ",
      "          55    ",
      "                ",
      "                ",
      "                ",
      "                ",
      "                ",
      "                ",
      "                ",
      "                "
    ],
    [
      "                ",
      "                ",
      "          55    ",
      "         5555   ",
      "        555555  ",
      "        555555  ",
      "         5555   ",
      "         &55&   ",
      "    &   &&&&    ",
      "    &   &       ",
      "                ",
      "                ",
      "                ",
      "                ",
      "                ",
      "                "
    ]
  ]
}