{
  "xsize": 16,
  "zsize": 16,
  "refpalette": "pomkotsmechs:factory",
  "slices": [
    [
      "               V",
      "               V",
      "               V",
      "               V",
      " ]             V",
      " ]             V",
      " ]             V",
      " ]   &&        V",
      " ]  &&&&       V",
      " ]   &&&       V",
      " ]!VVVVV    VVVV",
      "!!!VVVVVV   VVVV",
      "!!!mmmmmmmmmmmmm",
      " !              ",
      " !ddddddddd!!!!!",
      " !         !!  !"
    ],
    [
      "                ",
      "                ",
      "                ",
      "                ",
      "                ",
      " ]              ",
      " ]              ",
      " ]              ",
      " ]   &&         ",
      " ]   &&&        ",
      " ]!   &        +",
      "!!!   &&       n",
      "!!!,,,,,,,,,,,,m",
      " !              ",
      " !ddddddddd!!!!!",
      " !         !!  !"
    ],
    [
      "                ",
      "                ",
      "                ",
      "                ",
      "                ",
      " ]              ",
      " ]              ",
      " ]              ",
      " ]    &         ",
      " ]   &&&        ",
      " ]!   &        +",
      "!!!            2",
      "!!!             ",
      " !              ",
      " !ddddddddd!!!!!",
      " !         !!  !"
    ],
    [
      "                ",
      "                ",
      "                ",
      "                ",
      "                ",
      " ]              ",
      " ]              ",
      " ]              ",
      " ]    &         ",
      " ]   &&&        ",
      " ]!   &        +",
      "!!!            2",
      "!!!             ",
      " !              ",
      " !ddddddddd!!!!!",
      " !         !!  !"
    ],
    [
      "                ",
      "                ",
      "                ",
      "                ",
      "                ",
      " ]              ",
      " ]              ",
      " ]              ",
      " ]    &         ",
      " ]   &&&        ",
      " ]!   &        +",
      "!!!            2",
      "!!!             ",
      " !              ",
      " !ddddddddd!!!!!",
      "!!         !!  !"
    ],
    [
      "                ",
      "                ",
      "                ",
      "                ",
      " ]              ",
      " ]              ",
      " ]              ",
      " ]              ",
      " ]    &         ",
      " ]   &&&        ",
      " ]!   &        +",
      "!!!            2",
      "!!!             ",
      " !              ",
      " !ddddddddd!!!!!",
      "$!         !!  !"
    ]
  ]
}