{
  "xsize": 16,
  "zsize": 16,
  "refpalette": "lostcities:factory",
  "slices": [
    [
      " OVVVO OVVVO    ",
      "              ! ",
      "          &  !! ",
      "        VVVO !!!",
      "  OOO &VOOOV !!!",
      " VOOOV&VOOOV !!!",
      " VOOOV VOOOV !!!",
      " OVVVO OVVVO !!!",
      "             !!!",
      "             !!!",
      "/            !!!",
      "3            !!!",
      "             !!!",
      "             !! ",
      "!!!!!!!!!!!!!!!!",
      "!!  !!!!!!!!!!!$"
    ],
    [
      " OOOOO OOOOO    ",
      "                ",
      "        &&&   ! ",
      "      &OOOOO  ! ",
      "    OO&OOOOO !!!",
      " O OOO&OOOOO !!!",
      " OOOOO&OOOOO !!!",
      " OOOOO OOOOO !!!",
      "             !!!",
      "             !!!",
      "/            !!!",
      "3            !!!",
      "             !!!",
      "             !! ",
      "!!!!!!!!!!!!!!!!",
      "!!  !!!!!!!!!!!!"
    ],
    [
      "                ",
      "                ",
      "                ",
      "      &&&&&     ",
      "     &&&&       ",
      "    &&&&      i ",
      "     &&      !i ",
      "              i ",
      "              i ",
      "             !i ",
      "/            !!!",
      "3            !!!",
      "             !!!",
      "              ! ",
      "!!!!!!!ddddddd! ",
      "!!  !!!       !!"
    ],
    [
      "                ",
      "                ",
      "       &&       ",
      "      &&&       ",
      "     &&&&       ",
      "     &&&        ",
      "             !  ",
      "                ",
      "                ",
      "             !  ",
      "V            !!!",
      "V            !!!",
      "             !!!",
      "                ",
      "!!  !!!       ! ",
      "!!  !!!       ! "
    ],
    [
      "V               ",
      "V  &&   &       ",
      "V   && &&&      ",
      "V     &&&&      ",
      "V     &&&       ",
      "V       &       ",
      "V               ",
      "V            V  ",
      "V            V  ",
      "VV           !  ",
      "nVVVVVVVVVVVVV!!",
      "nVVVVVVVVVVVV!!!",
      "VV           !!!",
      "             V  ",
      "!!  !!!       ! ",
      "!!  !!!       ! "
    ],
    [
      "!!!!!!!!!!      ",
      "!!!!!!!!!!&     ",
      "!!!!!!!!!!&     ",
      "!!!!!!!!!!!     ",
      "!!!!!!!!!!!!    ",
      "!!!!!!!!!!!!    ",
      "!!!!!!!!!!!!    ",
      "!!!!!!!!!!!!!!! ",
      "!!!!!!!!!!!!!!!!",
      "!!!!!!!!!!!!!!!!",
      "!!!!!!!!!!!!!!!!",
      "!!!!!!!!!!!!!!!!",
      "!!!!!!!!!!!!!!!!",
      "rrrrrrrrrrrrr!!!",
      "!!!!!!!!!!!!!!!!",
      "!!!!!!!!!!!!!!!!"
    ]
  ]
}