{
  "xsize": 16,
  "zsize": 16,
  "refpalette": "pomkotsmechs:factory",
  "slices": [
    [
      "   V            ",
      "   V            ",
      "   V            ",
      "   V            ",
      "   V        &   ",
      "   OVVVVVVVVO&  ",
      "            &   ",
      "                ",
      "        &       ",
      "   &   &&&      ",
      "  &OVVVVVVVVO   ",
      "   V        V   ",
      "   V        V   ",
      "   V        V   ",
      "   V        V   ",
      "  &V        V   "
    ],
    [
      "   V            ",
      "   V            ",
      "   V            ",
      "   V        &   ",
      "   V       &V&  ",
      "   OVVVVVVVVO&  ",
      "            &   ",
      "                ",
      "        &       ",
      "   &   &&&      ",
      "  &OVVVVVVVVO   ",
      "   V        V   ",
      "   V        V   ",
      "   V        V   ",
      "   V        V   ",
      "   V        V   "
    ],
    [
      "   V            ",
      "   V            ",
      "   V            ",
      "   V        V   ",
      "   V       &V&  ",
      "   OVVVVVVVVO   ",
      "                ",
      "                ",
      "        &       ",
      "   &   &&&      ",
      "  &OVVVVVVVVO   ",
      "  &V&       V   ",
      "   V        V   ",
      "   V        V   ",
      "   V        V   ",
      "   V        V   "
    ],
    [
      "   V            ",
      "   V            ",
      "   V        V   ",
      "   V        V   ",
      "   V       &V&  ",
      "   OVVVVVVVVO   ",
      "                ",
      "                ",
      "        &       ",
      "       &&&      ",
      "   OVVVVVVVVO   ",
      "  &V&       V   ",
      "   V        V   ",
      "   V        V   ",
      "   V        V   ",
      "   V        V   "
    ],
    [
      "   OVVVVVVVV    ",
      "   OVVVVVVVVO   ",
      "   OVVVVVVVVO   ",
      "   OVVVVVVVVO&  ",
      "   OVVVVVVVVO&  ",
      "   OOOOOOOOOO   ",
      "                ",
      "                ",
      "        &       ",
      "       &&&      ",
      "   OOOOOOOOOO   ",
      "  &OVVVVVVVVO   ",
      "  &OVVVVVVVVO   ",
      "   OVVVVVVVVO   ",
      "   OVVVVVVVVO   ",
      "   OVVVVVVVVO   "
    ],
    [
      "                ",
      "   !        !   ",
      "            &   ",
      "           &&&  ",
      "            &   ",
      "   !        !   ",
      "                ",
      "                ",
      "                ",
      "        &&      ",
      "   !    &&& !   ",
      "   &     &      ",
      "  &&&           ",
      "  &&&           ",
      "   !        !   ",
      "                "
    ]
  ]
}