{
  "xsize": 16,
  "zsize": 16,
  "refpalette": "lostcities:factory",
  "slices": [
    [
      "                ",
      "   &            ",
      "   &            ",
      "VVVV            ",
      "ʹ͵͵VVV          ",
      "ʹʹ͵ʹʹʹVV        ",
      "ʹʹʹʹʹʹʹVV       ",
      "ʹʹʹʹʹʹʹʹVV      ",
      "ʹʹʹʹʹʹʹʹʹVV     ",
      "ʹʹʹʹʹʹʹʹʹʹV     ",
      "ʹʹʹʹʹʹʹʹʹʹʹV    ",
      "ʹʹʹʹʹʹʹʹʹʹʹV    ",
      "ʹʹʹʹʹʹʹʹʹʹʹVV&  ",
      "ʹʹʹʹʹʹʹʹʹʹʹʹV!& ",
      "ʹʹʹʹʹʹʹʹʹʹʹʹV!  ",
      "ʹʹʹʹʹʹʹʹʹʹʹʹV!  "
    ],
    [
      "                ",
      "   &            ",
      "  &&            ",
      "VVVV            ",
      "ʹ͵ʹVVV          ",
      "ʹʹʹʹʹʹVV        ",
      "ʹʹʹʹʹʹʹVV       ",
      "ʹʹʹʹʹʹʹʹVV      ",
      "ʹʹʹʹʹʹʹʹʹVV     ",
      "ʹʹʹʹʹʹʹʹʹʹV     ",
      "ʹʹʹʹʹʹʹʹʹʹʹV    ",
      "ʹʹʹʹʹʹʹʹʹʹʹV    ",
      "ʹʹʹʹʹʹʹʹʹʹʹVV&  ",
      "ʹʹʹʹʹʹʹʹʹʹʹʹV!& ",
      "ʹʹʹʹʹʹʹʹʹʹʹʹV&  ",
      "ʹʹʹʹʹʹʹʹʹʹʹʹV!  "
    ],
    [
      "                ",
      "                ",
      "  &&            ",
      "VVVV            ",
      "ʹ͵ʹVVV          ",
      "ʹʹʹʹʹʹVV        ",
      "ʹʹʹʹʹʹʹVV       ",
      "ʹʹʹʹʹʹʹʹVV      ",
      "ʹʹʹʹʹʹʹʹʹVV     ",
      "ʹʹʹʹʹʹʹʹʹʹV     ",
      "ʹʹʹʹʹʹʹʹʹʹʹV    ",
      "ʹʹʹʹʹʹʹʹʹʹʹV    ",
      "ʹʹʹʹʹʹʹʹʹʹʹVV&  ",
      "ʹʹʹʹʹʹʹʹʹʹʹʹV!& ",
      "ʹʹʹʹʹʹʹʹʹʹʹʹV!  ",
      "ʹʹʹʹʹʹʹʹʹʹʹʹV!  "
    ],
    [
      "                ",
      "                ",
      "  &             ",
      "VVVV            ",
      "ʹ͵ʹVVV          ",
      "ʹʹʹʹʹʹVV        ",
      "ʹʹʹʹʹʹʹVV       ",
      "ʹʹʹʹʹʹʹʹVV      ",
      "ʹʹʹʹʹʹʹʹʹVV     ",
      "ʹʹʹʹʹʹʹʹʹʹV     ",
      "ʹʹʹʹʹʹʹʹʹʹʹV    ",
      "ʹʹʹʹʹʹʹʹʹʹʹV    ",
      "ʹʹʹʹʹʹʹʹʹʹʹVV&  ",
      "ʹʹʹʹʹʹʹʹʹʹʹʹV!& ",
      "ʹʹʹʹʹʹʹʹʹʹʹʹV   ",
      "ʹʹʹʹʹʹʹʹʹʹʹʹV!  "
    ],
    [
      "                ",
      "                ",
      " &&             ",
      "VVVV            ",
      "ʹ͵ʹVVV          ",
      "ʹʹʹʹʹʹVV        ",
      "ʹʹʹʹʹʹʹVV       ",
      "ʹʹʹʹʹʹʹʹVV      ",
      "ʹʹʹʹʹʹʹʹʹVV     ",
      "ʹʹʹʹʹʹʹʹʹʹV     ",
      "ʹʹʹʹʹʹʹʹʹʹʹV    ",
      "ʹʹʹʹʹʹʹʹʹʹʹV    ",
      "ʹʹʹʹʹʹʹʹʹʹʹVV&  ",
      "ʹʹʹʹʹʹʹʹʹʹʹʹV!& ",
      "ʹʹʹʹʹʹʹʹʹʹʹʹV!  ",
      "ʹʹʹʹʹʹʹʹʹʹʹʹV!  "
    ],
    [
      "                ",
      "                ",
      " &              ",
      "VVVV            ",
      "ʹ͵ʹVVV          ",
      "ʹʹʹʹʹʹVV        ",
      "ʹʹʹʹʹʹʹVV       ",
      "ʹʹʹʹʹʹʹʹVV      ",
      "ʹʹʹʹʹʹʹʹʹVV     ",
      "ʹʹʹʹʹʹʹʹʹʹV     ",
      "ʹʹʹʹʹʹʹʹʹʹʹV    ",
      "ʹʹʹʹʹʹʹʹʹʹʹV    ",
      "ʹʹʹʹʹʹʹʹʹʹʹVV&  ",
      "ʹʹʹʹʹʹʹʹʹʹʹʹV!  ",
      "ʹʹʹʹʹʹʹʹʹʹʹʹV   ",
      "ʹʹʹʹʹʹʹʹʹʹʹʹV!  "
    ]
  ]
}