{
  "xsize": 16,
  "zsize": 16,
  "refpalette": "lostcities:factory",
  "slices": [
    [
      "VVVVVVVVVVVVVVVV",
      "VVVVVVVVVVVVVVVV",
      "VVVVVVVVVVVVVVVV",
      "VVVVVVVVVVVVVVVV",
      "VVVVVVVVVVVVVVVV",
      "VVVVVVVVVVVVVVVV",
      "VVVVVVVVVVVVVVVV",
      "VVVVVVVVVVVVVVVV",
      "VVVVVVVVVVVVVVVV",
      "VVVVVVVVVVVVVVVV",
      "VVVVVVVVVVVVVVVV",
      "VVVVVVVVVVVVVVVV",
      "VVVVVVVVVVVVVVVV",
      "VVVVVVVVVVVVVVVV",
      "VVVVVVVVVVVVVVVV",
      "VVVVVVVVVVVVVVVV"
    ],
    [
      " !              ",
      " !              ",
      " !              ",
      " !!            V",
      "!!!VVVVVVVVVVVVV",
      "!!!           VV",
      " !              ",
      " !              ",
      "!!!           VV",
      "!!!VVVVVVVVVVVVV",
      " !!!!!!!!!!!!!!V",
      " !!!!!!!!!!!!!!!",
      " !!!!!!!!!!!!!!!",
      " !!!!!!!!!!!!!!!",
      " !!!!!!!!!!!!!!!",
      " !!!!!!!!!!!!!!!"
    ],
    [
      " ]              ",
      " ]              ",
      " ]              ",
      " ]!            V",
      "!!!,,,,,,,,,,,,V",
      "!!!             ",
      " !              ",
      " !              ",
      "!!!             ",
      "!!!,,,,,,,,,,,,V",
      " ]!            V",
      " ]              ",
      " ]              ",
      " ]              ",
      " ]              ",
      " ]              "
    ],
    [
      " ]              ",
      " ]              ",
      " ]              ",
      " ]!            +",
      "!!!            2",
      "!!!             ",
      " !              ",
      " !              ",
      "!!!             ",
      "!!!            +",
      " ]!            2",
      " ]              ",
      " ]              ",
      " ]              ",
      " ]              ",
      " ]              "
    ],
    [
      " ]              ",
      " ]              ",
      " ]              ",
      " ]!            +",
      "!!!            2",
      "!!!             ",
      " !              ",
      " !              ",
      "!!!             ",
      "!!!            +",
      " ]!            2",
      " ]              ",
      " ]              ",
      " ]              ",
      " ]              ",
      " ]              "
    ],
    [
      " ]              ",
      " ]              ",
      " ]              ",
      " ]!            +",
      "!!!            2",
      "!!!             ",
      "                ",
      "                ",
      " !!             ",
      " !!            +",
      " ]!            2",
      " ]              ",
      " ]              ",
      " ]              ",
      " ]              ",
      " ]              "
    ]
  ]
}