{
  "xsize": 16,
  "zsize": 16,
  "refpalette": "lostcities:factory",
  "slices": [
    [
      "                ",
      "                ",
      "                ",
      "                ",
      "                ",
      "                ",
      "      !  !      ",
      "       !!       ",
      "       !!       ",
      "      !  !      ",
      "&&              ",
      "&               ",
      "                ",
      "                ",
      "                ",
      "                "
    ],
    [
      "vvv}}}||||||zVVv",
      "vvv}}|||||}||zz|",
      "vv}}}||||}}}|||}",
      "vvv}}||||}}}||}}",
      "vvvv}}||||||||}}",
      "vvvvv}|||||zz||}",
      "z|vv}||zzzzVzz||",
      "zz||zzzzVVVVzz||",
      "VVVVVVVVVVVVz|||",
      "VVVVvvVzzzVz|}}|",
      "vvVVvvV||zzz|}}z",
      "vzzVVVz|||zz|}|z",
      "|||zVV||||zzz||z",
      "}||zVVz||zVVVzzz",
      "}|zVVvVVVVVVVzz|",
      "||zVvvvvVVvvVz||"
    ],
    [
      "              55",
      "               5",
      "555             ",
      "   5            ",
      "    5           ",
      "    5           ",
      "    5           ",
      "   5            ",
      "555             ",
      "&&              ",
      "&&& !!          ",
      "&&  !!          ",
      "                ",
      "                ",
      "                ",
      "               5"
    ],
    [
      "              55",
      "               5",
      "555             ",
      "   5            ",
      "    5           ",
      "    5           ",
      "    5           ",
      "   5            ",
      "555             ",
      "&&&             ",
      "&&&             ",
      " &              ",
      "                ",
      "                ",
      "                ",
      "               5"
    ],
    [
      "              55",
      "               5",
      "555             ",
      "   5            ",
      "    5           ",
      "    5           ",
      "    5           ",
      "   5            ",
      "555             ",
      "&&              ",
      "&&              ",
      "                ",
      "                ",
      "                ",
      "                ",
      "               5"
    ],
    [
      "              55",
      "555            5",
      "5555            ",
      "   55           ",
      "    55          ",
      "    55          ",
      "    55          ",
      " & 55           ",
      "5555            ",
      "555             ",
      "&&              ",
      "                ",
      "                ",
      "                ",
      "                ",
      "               5"
    ]
  ]
}