{
  "xsize": 16,
  "zsize": 16,
  "refpalette": "lostcities:factory",
  "slices": [
    [
      "    5        &55",
      "   5         55&",
      "555          5  ",
      "            5   ",
      "            5   ",
      "           5    ",
      "           5    ",
      "           5    ",
      "           5    ",
      "           5    ",
      "           5    ",
      "           5    ",
      "            5   ",
      "            5   ",
      "             5  ",
      "             55 "
    ],
    [
      "    5         55",
      "   5         55 ",
      "555          5  ",
      "            5   ",
      "            5   ",
      "           5    ",
      "           5    ",
      "           5    ",
      "           5    ",
      "           5    ",
      "           5    ",
      "           5    ",
      "            5   ",
      "            5   ",
      "             5  ",
      "             55 "
    ],
    [
      "    5         55",
      "   5         55 ",
      "555          5  ",
      "            5  &",
      "            5   ",
      "           5    ",
      "           5    ",
      "           5    ",
      "           5    ",
      "           5    ",
      "           5    ",
      "           5    ",
      "            5   ",
      "            5   ",
      "             5  ",
      "             55 "
    ],
    [
      "    5         55",
      "   55        55 ",
      "5555         5  ",
      "555         5  &",
      "            5   ",
      "           5    ",
      "           5    ",
      "           5    ",
      "           5    ",
      "           5    ",
      "           5    ",
      "           5    ",
      "            5   ",
      "            5   ",
      "             5  ",
      "             55 "
    ],
    [
      "    5       !!55",
      "   5       !!55 ",
      "555       !!!5  ",
      "          !!5  &",
      "          !!5   ",
      "         !!5    ",
      "         !!5    ",
      "         !!5    ",
      "         !!5    ",
      "         !!5    ",
      "         !!5    ",
      "         !!5    ",
      "          !!5   ",
      "          !!5   ",
      "          !!!5  ",
      "           !!55 "
    ],
    [
      "    5         55",
      "   5         55 ",
      "555          5  ",
      "            5  &",
      "            5   ",
      "           5    ",
      "           5    ",
      "           5    ",
      "           5    ",
      "           5    ",
      "           5    ",
      "           5    ",
      "            5   ",
      "            5   ",
      "             5  ",
      "             55 "
    ]
  ]
}