{
  "xsize": 16,
  "zsize": 16,
  "refpalette": "pomkotsmechs:factory",
  "slices": [
    [
      "                ",
      "               J",
      "J&           JJJ",
      "JJJ        JJJJ ",
      "&JJJrJJJJrJJJ&  ",
      " & J JJJJ J &   ",
      "                ",
      "                ",
      "                ",
      "                ",
      "                ",
      "                ",
      "                ",
      "                ",
      "                ",
      "                "
    ],
    [
      "                ",
      "               J",
      "J            JJJ",
      "JJJ        JJJJ ",
      "&JJJrJJJJrJJJ&  ",
      " & J JJJJ J &   ",
      "                ",
      "                ",
      "                ",
      "                ",
      "                ",
      "                ",
      "                ",
      "                ",
      "                ",
      "                "
    ],
    [
      "!!!!!!!!!!!JJ!!!",
      "!!!!!!!!!!!!!JJ!",
      "!!!!!!!!!!!!!!!J",
      "!!!!!!!!!!!!!!! ",
      "&!!!!!!!!!!!!&  ",
      " &&!!!!!!!! &   ",
      "                ",
      "                ",
      "                ",
      "                ",
      "                ",
      "                ",
      "                ",
      "                ",
      "                ",
      "                "
    ],
    [
      "           JJ   ",
      "             JJJ",
      "J            JJJ",
      "JJJ        JJJJ ",
      " JJJrJJJJrJJJ&  ",
      "  &J JJJJ J &   ",
      "                ",
      "                ",
      "                ",
      "                ",
      "                ",
      "                ",
      "                ",
      "                ",
      "                ",
      "                "
    ],
    [
      "                ",
      "               J",
      "J            JJJ",
      "JJJ        JJJJ ",
      " JJJrJJJJrJJJ&  ",
      "  &J JJJJ J &   ",
      "                ",
      "                ",
      "                ",
      "                ",
      "                ",
      "                ",
      "                ",
      "                ",
      "                ",
      "                "
    ],
    [
      "!!!!!!!!!!!!!!!!",
      "!!!!!!!!!!!!!!!J",
      "!!!!!!!!!!!!!JJJ",
      "!!!!!!!!!!!JJJJ ",
      " !!!!!!!!!JJJ&  ",
      "  &!!!!!!!J &   ",
      "                ",
      "                ",
      "                ",
      "                ",
      "                ",
      "                ",
      "                ",
      "                ",
      "                ",
      "                "
    ]
  ]
}