{
  "xsize": 16,
  "zsize": 16,
  "refpalette": "pomkotsmechs:factory",
  "slices": [
    [
      "vvvvvvvvvvvvvvvv",
      "vvvvvvvvvvvvvvvv",
      "vvvvvvvvvvvvvvvv",
      "vvvvvvvvv!!vvvvv",
      "vvvvvvvvv!!vvvvv",
      "vvvvvvvvvvvvvvvv",
      "vvvvvvvvvvvvvvvv",
      "vvvvvvvvvvvvvvvv",
      "vvvvvvvvvvvvvvvv",
      "vvv!!vvvvvvvvvvv",
      "vvv!!vvvvvvvvvvv",
      "vvvvvvvvvvvvvvvv",
      "vvvvvvvvvvvvvvvv",
      "vvvvvvvvvvvvvvvv",
      "vvvvvvvvvvvvvvvv",
      "vvvvvvvvvvvvvvvv"
    ],
    [
      "                ",
      "                ",
      "                ",
      "         !!     ",
      "         !!     ",
      "                ",
      "                ",
      "                ",
      "                ",
      "   !!           ",
      "   !!           ",
      "                ",
      "                ",
      "                ",
      "                ",
      "                "
    ],
    [
      "                ",
      "                ",
      "         &      ",
      "        &!!     ",
      "         !!     ",
      "                ",
      "                ",
      "                ",
      "                ",
      "   !!           ",
      "   !!           ",
      "                ",
      "                ",
      "                ",
      "                ",
      "                "
    ],
    [
      "                ",
      "                ",
      "         &      ",
      "        &!!     ",
      "         !!     ",
      "                ",
      "                ",
      "                ",
      "                ",
      "   !!           ",
      "   !!           ",
      "                ",
      "                ",
      "                ",
      "                ",
      "                "
    ],
    [
      "                ",
      "                ",
      "         &      ",
      "        &!! !!!!",
      "         !!!!   ",
      "        !!      ",
      "       !!       ",
      "      !!        ",
      "     !!         ",
      "   !!!          ",
      "   !!           ",
      "    !           ",
      "   !!         QQ",
      "   !         QQQ",
      "   !        QQQQ",
      "   !        QQQQ"
    ],
    [
      "                ",
      "                ",
      "         &      ",
      "        &!! !!!!",
      "         !!!!   ",
      "        !!      ",
      "       !!       ",
      "      !!        ",
      "     !!         ",
      "   !!!         Q",
      "   !!       QQQQ",
      "    !      QQQQQ",
      "   !!     QQQQ  ",
      "   !      QQQ   ",
      "   !      QQ    ",
      "   !     QQQ    "
    ]
  ]
}