{
  "xsize": 16,
  "zsize": 16,
  "refpalette": "lostcities:factory",
  "slices": [
    [
      "       55    55 ",
      "       55     55",
      "       55      5",
      "       55       ",
      "       55       ",
      "       55       ",
      "       55       ",
      "       !!!      ",
      "       55!      ",
      "!!!!!!!55!      ",
      "ͰͰͰͰͰͰͰ55       ",
      "       55       ",
      "                ",
      "                ",
      "                ",
      "                "
    ],
    [
      "        5    55 ",
      "        5     55",
      "        5      5",
      "        5       ",
      "        5       ",
      "        5       ",
      "        5       ",
      "        5       ",
      "        5       ",
      "!!!!!!!!!       ",
      "ͰͰͰͰͰͰͰͰ5       ",
      "        5       ",
      "                ",
      "                ",
      "                ",
      "                "
    ],
    [
      "         5   55 ",
      "         5    55",
      "         5     5",
      "         5      ",
      "         5      ",
      "         5      ",
      "         5      ",
      "         5      ",
      "         5      ",
      "!!!!!!!!!!      ",
      "ͰͰ   ͰͰͰ 5      ",
      "  ͰͰͰ    5      ",
      "                ",
      "                ",
      "                ",
      "                "
    ],
    [
      "         5   55 ",
      "         5    55",
      "         5     5",
      "         5      ",
      "         5      ",
      "         5      ",
      "         5      ",
      "         5      ",
      "         5      ",
      "!!!!!!!!!!      ",
      "Ͱ     ͰͰͰ5      ",
      " ͰͰͰͰͰ   5      ",
      "                ",
      "                ",
      "                ",
      "                "
    ],
    [
      "         5   55 ",
      "         5    55",
      "         5     5",
      "         5      ",
      "         5      ",
      "         5      ",
      "         5      ",
      "         5      ",
      "         5      ",
      "!!!!!!!!!!      ",
      "Ͱ     ͰͰͰ5      ",
      " ͰͰͰͰͰ   5      ",
      "                ",
      "                ",
      "                ",
      "                "
    ],
    [
      "         5   55 ",
      "         5    55",
      "        &5     5",
      "         5      ",
      "         5      ",
      "         5      ",
      "         5      ",
      "         5      ",
      "         5      ",
      "!!!!!!!!!!      ",
      "Ͱ     ͰͰͰ5      ",
      " ͰͰͰͰͰ   5      ",
      "                ",
      "                ",
      "                ",
      "                "
    ]
  ]
}