{
  "xsize": 16,
  "zsize": 16,
  "refpalette": "pomkotsmechs:factory",
  "slices": [
    [
      "                ",
      "                ",
      "  !          !  ",
      "                ",
      "     &          ",
      "    &&&         ",
      "     &          ",
      "                ",
      "                ",
      "                ",
      "                ",
      "                ",
      "                ",
      "  !          !  ",
      "                ",
      "                "
    ],
    [
      "                ",
      "                ",
      "  !          !  ",
      "                ",
      "     &          ",
      "    &&&         ",
      "    &&&         ",
      "     &          ",
      "                ",
      "                ",
      "                ",
      "                ",
      "                ",
      "  !          !  ",
      "                ",
      "                "
    ],
    [
      "                ",
      "                ",
      "  !          !  ",
      "                ",
      "                ",
      "    &&          ",
      "   &&&&         ",
      "    &&          ",
      "                ",
      "                ",
      "                ",
      "                ",
      "                ",
      "  !          !  ",
      "                ",
      "                "
    ],
    [
      "                ",
      "                ",
      "  !          !  ",
      "                ",
      "                ",
      "    &           ",
      "   &&&          ",
      "    &           ",
      "                ",
      "                ",
      "                ",
      "                ",
      "                ",
      "  !          !  ",
      "                ",
      "                "
    ],
    [
      "                ",
      "                ",
      "  !     &    !  ",
      "        &       ",
      "        &       ",
      "   &&           ",
      "  &&&&          ",
      "   &&           ",
      "                ",
      "                ",
      "                ",
      "                ",
      "                ",
      "  !          !  ",
      "                ",
      "                "
    ],
    [
      "!!     !!     !!",
      "!ttttttttttttt  ",
      " t!tttttttttt!  ",
      " tttttttttttt   ",
      " tt  tttttttt   ",
      "   &  tttttttt  ",
      "  &&& tttttttt  ",
      "   &  ttttttttt!",
      "     tttttttttt!",
      "   tttttttttttt ",
      " tttttttttttttt ",
      " tttttttttttttt ",
      " tttttttttttttt ",
      " t!tttttttttt!t ",
      "!tttttttttttttt!",
      "!!            !!"
    ]
  ]
}