{
  "xsize": 16,
  "zsize": 16,
  "refpalette": "pomkotsmechs:factory",
  "slices": [
    [
      "vvvvvvvvvvvvvvvv",
      "vvvvvvvvvvvvvvvv",
      "vvvvvvvvvvvvvvvv",
      "vvvvv!!vvvvvvvvv",
      "vvvvv!!vvvvvvvvv",
      "vvvvvvvvvvvvvvvv",
      "vvvvvvvvvvvvvvvv",
      "vvvvvvvvvvvvvvvv",
      "vvvvvvvvvvvvvvvv",
      "vvvvvvvvvvv!!vvv",
      "vvvvvvvvvvv!!vvv",
      "vvvvvvvvvvvvvvvv",
      "vvvvvvvvvvvvvvvv",
      "vvvvvvvvvvvvvvvv",
      "vvvvvvvvvvvvvvvv",
      "vvvvvvvvvvvvvvvv"
    ],
    [
      "                ",
      "                ",
      "                ",
      "     !!         ",
      "     !!&        ",
      "                ",
      "                ",
      "                ",
      "                ",
      "           !!   ",
      "           !!   ",
      "                ",
      "                ",
      "             !  ",
      "                ",
      "             !  "
    ],
    [
      "                ",
      "                ",
      "                ",
      "     !!         ",
      "     !!         ",
      "                ",
      "                ",
      "                ",
      "                ",
      "           !!   ",
      "           !!   ",
      "                ",
      "                ",
      "             !  ",
      "             !  ",
      "             !  "
    ],
    [
      "                ",
      "                ",
      "                ",
      "     !!         ",
      "     !!         ",
      "                ",
      "                ",
      "                ",
      "                ",
      "           !!   ",
      "           !!   ",
      "                ",
      "                ",
      "             !  ",
      "                ",
      "             !& "
    ],
    [
      "                ",
      "                ",
      "                ",
      "!!!! !!         ",
      "   !!!!         ",
      "      !!        ",
      "       !!       ",
      "        !!      ",
      "         !!     ",
      "          !!!   ",
      "           !!   ",
      "           !    ",
      "QQ         !!   ",
      "QQQ         !!  ",
      "QQQQ        !!  ",
      "QQQQ        !!& "
    ],
    [
      "                ",
      "                ",
      "      &         ",
      "!!!! !!         ",
      "   !!!!         ",
      "      !!        ",
      "       !!       ",
      "        !!      ",
      "         !!     ",
      "Q         !!!   ",
      "QQQQ       !!   ",
      "QQQQQ      !    ",
      "QQQQQQ     !!   ",
      "QQQQQQ      !!  ",
      "QQQQQQ      !   ",
      "QQQQQQQ     !!& "
    ]
  ]
}