{
  "xsize": 16,
  "zsize": 16,
  "refpalette": "lostcities:factory",
  "slices": [
    [
      "                ",
      "                ",
      "      &         ",
      "     !!         ",
      "     !!         ",
      "                ",
      "                ",
      "                ",
      "QQQQ            ",
      "QQQQQ      !!   ",
      "QQQQQQ     !!   ",
      "QQQQQQQ         ",
      "QQQQQQQQ        ",
      "QQQQQQQQ     !  ",
      "QQQQQQQQ     !  ",
      "QQQQQQQQ     !& "
    ],
    [
      "                ",
      "                ",
      "     &&         ",
      "     !!         ",
      "     !!         ",
      "                ",
      "QQ              ",
      "QQQQQ           ",
      "QQQQQQ          ",
      "QQQQQQQ    !!   ",
      "QQQQQQQQ   !!   ",
      "QQQQQQQQQ       ",
      "QQQQQQQQQ       ",
      "QQQQQQQQQ    !  ",
      "QQQQQQQQQQ      ",
      "QQQQQQQQQQ   !& "
    ],
    [
      "                ",
      "                ",
      "     &          ",
      "!!!! !!         ",
      "   !!!!         ",
      "QQ    !!        ",
      "QQQQQ  !!       ",
      "QQQQQQQ !!      ",
      "QQQQQQQQ !!     ",
      "QQQQQQQQQ !!!   ",
      "QQQQQQQQQ  !!   ",
      "QQQQQQQQQQ !    ",
      "QQQQQQQQQQ !!   ",
      "QQQQQQQQQQ  !!  ",
      "QQQQQQQQQQQ !!& ",
      "QQQQQQQQQQQ !!& "
    ],
    [
      "                ",
      "                ",
      "     &          ",
      "!!!!&!!         ",
      "QQ !!!!         ",
      "QQQQQ !!        ",
      "QQQQQQQ!!       ",
      "QQQQQQQQ!!      ",
      "QQQQQQQQQ!!     ",
      "QQQQQQQQQQ!!!   ",
      "QQQQQQQQQQ !!   ",
      "QQQQQQQQQQQ!    ",
      "QQQQQQQQQQQ!!   ",
      "QQQQQQQQQQQ !!& ",
      "QQQQQQQQQQQQ!&& ",
      "QQQQQQQQQQQQ!!  "
    ],
    [
      "                ",
      "                ",
      "                ",
      "VVVV&!!         ",
      "QQQVVV!         ",
      "QQQQQQVV        ",
      "QQQQQQQVV       ",
      "QQQQQQQQVV      ",
      "QQQQQQQQQVV     ",
      "QQQQQQQQQQV!!   ",
      "QQQQQQQQQQQV!   ",
      "QQQQQQQQQQQV    ",
      "QQQQQQQQQQQVV   ",
      "QQQQQQQQQQQQV!& ",
      "QQQQQQQQQQQQV!& ",
      "QQQQQQQQQQQQV!  "
    ],
    [
      "                ",
      "                ",
      "   &            ",
      "VVVV&!!         ",
      "QQQVVV!         ",
      "QQQQQQVV        ",
      "QQQQQQQVV       ",
      "QQQQQQQQVV      ",
      "QQQQQQQQQVV     ",
      "QQQQQQQQQQV!!   ",
      "QQQQQQQQQQQV!   ",
      "QQQQQQQQQQQV    ",
      "QQQQQQQQQQQVV   ",
      "QQQQQQQQQQQQV!& ",
      "QQQQQQQQQQQQV&& ",
      "QQQQQQQQQQQQV!  "
    ]
  ]
}