{
  "xsize": 16,
  "zsize": 16,
  "refpalette": "pomkotsmechs:factory",
  "slices": [
    [
      "   V     && V   ",
      "   V    &&&&V   ",
      "   V    &&& V   ",
      "   V     &      ",
      "   O        &   ",
      "   V        &   ",
      "  &V&           ",
      "   V            ",
      "   V            ",
      "   V            ",
      "   V            ",
      "   V            ",
      "   V            ",
      "   V        V   ",
      "   OVVVVVVVVO   ",
      "                "
    ],
    [
      "   V    & & V   ",
      "   V    &&&&V   ",
      "   V   &&&& V   ",
      "   V  &&        ",
      "   O &&         ",
      "   V&&          ",
      "  &V&           ",
      "  &V&           ",
      "   V            ",
      "   V            ",
      "   V            ",
      "   V            ",
      "   V            ",
      "   V            ",
      "   OVVVVVVVVO   ",
      "                "
    ],
    [
      "  &OVVVVVVVVO   ",
      "   OVVVVVVVVO   ",
      "   OVVVVVV&     ",
      "   OVVVVVV      ",
      "   OOOOOOO      ",
      "  &OVVVVVV      ",
      "  &OVVVVVV      ",
      "  &OVVVVVV      ",
      "   OVVVVV       ",
      "   OVVVVV       ",
      "   OVVVVV       ",
      "   OVVVVVV      ",
      "   OVVVVVV      ",
      "   OVVVVVVVV    ",
      "   OOOOOOOOOO   ",
      "                "
    ],
    [
      "   &  &&&       ",
      "        &&&     ",
      "       &&       ",
      "      &&        ",
      "     &&         ",
      "   &&&          ",
      "   &            ",
      "   &            ",
      "                ",
      "                ",
      "                ",
      "                ",
      "                ",
      "                ",
      "                ",
      "                "
    ],
    [
      "                ",
      "                ",
      "                ",
      "                ",
      "                ",
      "                ",
      "                ",
      "                ",
      "                ",
      "                ",
      "                ",
      "                ",
      "                ",
      "                ",
      "                ",
      "                "
    ],
    [
      "                ",
      "                ",
      "                ",
      "                ",
      "                ",
      "                ",
      "                ",
      "                ",
      "                ",
      "                ",
      "                ",
      "                ",
      "                ",
      "                ",
      "                ",
      "                "
    ]
  ]
}