{
  "xsize": 16,
  "zsize": 16,
  "refpalette": "pomkotsmechs:factory",
  "slices": [
    [
      "                ",
      "  ͳ,,,,,,,,,,q  ",
      "                ",
      "   !! !! !! !!  ",
      "   !! !! !! !!  ",
      "   &            ",
      "  &!! !! !! !!  ",
      "   !! !!&!!&!!  ",
      "         &&     ",
      "                ",
      "                ",
      "                ",
      "                ",
      "                ",
      "  ͳ,,,,,,,,,,q  ",
      "                "
    ],
    [
      "                ",
      "                ",
      "                ",
      "   << << << <<  ",
      "   << << << <<  ",
      "   &            ",
      "  &<< << << <<  ",
      "   << <<&<< <<  ",
      "         &      ",
      "                ",
      "                ",
      "                ",
      "                ",
      "                ",
      "                ",
      "                "
    ],
    [
      "                ",
      "                ",
      "                ",
      "   << << << <<  ",
      "   << << << <<  ",
      "   &            ",
      "  &<< << << <<  ",
      "   << <<&<< <<  ",
      "         &      ",
      "                ",
      "                ",
      "                ",
      "                ",
      "                ",
      "                ",
      "                "
    ],
    [
      "                ",
      "                ",
      "                ",
      "   << << << <<  ",
      "    < << << <<  ",
      "   &            ",
      "  &<< << << <<  ",
      "   << << << <<  ",
      "                ",
      "                ",
      "                ",
      "                ",
      "                ",
      "                ",
      "                ",
      "                "
    ],
    [
      "                ",
      "                ",
      "                ",
      "    < << << <<  ",
      "    < << << <<  ",
      "   &            ",
      "  &<< << << <<  ",
      "  &<< << << <<  ",
      "   &            ",
      "                ",
      "                ",
      "                ",
      "                ",
      "                ",
      "                ",
      "                "
    ],
    [
      "                ",
      "                ",
      "                ",
      "      << << <<  ",
      "      <<&<< <<  ",
      "       &&       ",
      "   << <<    <<  ",
      "  &<< <<    <<  ",
      "   &            ",
      "                ",
      "                ",
      "                ",
      "                ",
      "                ",
      "                ",
      "                "
    ]
  ]
}