{
  "xsize": 16,
  "zsize": 16,
  "refpalette": "pomkotsmechs:quarry",
  "slices": [
    [
      "~~!!!!!~~~~~~~~~",
      "~~!!!!!~~~~~~~~~",
      "~~!!!!!~~~~~~~~~",
      "~~!!!!!~~~~~~~~~",
      "~~!!!!!~~~~~~~~~",
      "~~!!!!!~~~~~~~~~",
      "~~!!!!!~$~~~~~~~",
      "~~!!!!!$$$~~~~~~",
      "~~!!!!!~$~~~~~~~",
      "~~!!!!!~$~~~~~~~",
      "~~~~~~~~~~~~~~~~",
      "~~~~~~~~~~~~~~~~",
      "~~~~~~~~~~~~~~~~",
      "~~~~~~~~~~~~~~~~",
      "~~~~~~~~~~~~~~~~",
      "~~~~~~~~~~~~~~~~"
    ],
    [
      "~~~000~~~~~~~!!!",
      "~~~000~~~~~~~!!!",
      "~~~000~~~~~~~!!!",
      "~~~~~~~~~~~~~!!!",
      "~~~~~~~~~~~~~!!!",
      "~~~~~~~~~~~~~!!!",
      "~~~000~~$~~~~!!!",
      "~~~000~$$$~~~!!!",
      "~~~000~$$$~~~!!!",
      "~~!!!!!~$~~~~!!!",
      "~~!!!!!~~~~~~!!!",
      "~~~~~~~~~~~~~~~~",
      "~~~~~~~~~~~~~~~~",
      "~~~~~~~~~~~~~~~~",
      "~~~~~~~~~~~~~~~~",
      "~~~~~~~~~~~~~~~~"
    ],
    [
      "~~~'~'~~~~3~~!~~",
      "~~'~~~'333333333",
      "~~~'~'~~~~3~~!~~",
      "~~~000~~~~~~~!~~",
      "~~~~~~~~~~~~~!~~",
      "~~~000~~~~~~~!~~",
      "~~~'~'~~~~3~~!~~",
      "~~'~~~'333333333",
      "~~~'~'~$$$3~~!~~",
      "~~~000~~$~~~~!!!",
      "~~!!!!!~~~~~~~~~",
      "~~!!!!!~~~~~~~~~",
      "~~~~~~~~~~~~~~~~",
      "~~~~~~~~~~~~~~~~",
      "~~~~~~~~~~~~~~~~",
      "~~~~~~~~~~~~~~~~"
    ],
    [
      "~~'~~~'333333333",
      "~~~'~'~3~~~~~!~~",
      "~~'~~~'333333333",
      "~~~000~~~~~~~!~~",
      "~~~~~~~~~~~~~!~~",
      "~~~000~~~~~~~!~~",
      "~~'~~~'333333333",
      "~~~'~'~3$~~~~!~~",
      "~~'~~~'333333333",
      "~~~000~~$~~~~!!!",
      "~~~~~~~~~~~~~~~~",
      "~~!!!!!~~~~~~~~~",
      "~~~~~~~~~~~~~~~~",
      "~~~~~~~~~~~~~~~~",
      "~~~~~~~~~~~~~~~~",
      "~~~~~~~~~~~~~~~~"
    ],
    [
      "~~~'~'~~~~3~~!~~",
      "~~'~~~'333333333",
      "~~~'~'~~~~3~~!~~",
      "~~~000~~~~~~~!~~",
      "~~~~~~~~~~~~~!~~",
      "~~~000~~~~~~~!~~",
      "~~~'~'~~~~3~~!~~",
      "~~'~~~'333333333",
      "~~~'~'~$$$3~~!''",
      "~~~000~~$~~~~!!!",
      "~~!!!!!~~~~~~!!!",
      "~~!!!!!~~~~~~~~~",
      "~~~~~~~~~~~~~~~~",
      "~~~~~~~~~~~~~~~~",
      "~~~~~~~~~~~~~~~~",
      "~~~~~~~~~~~~~~~~"
    ],
    [
      "~~~000~~~~~~~!~~",
      "~~~000~~~~~~~!~~",
      "~~~000~~~~~~~!~~",
      "~~~~~~~~~~~~~!~~",
      "~~~~~~~~~~~~~!~~",
      "~~~~~~~~~~~~~!~~",
      "~~~000~~~~~~~!~~",
      "~~~000~~$~~~~!~~",
      "~~~000~$$$~~~!''",
      "~~!!!!!~$~~~~!~!",
      "~~!!!!!~~~~~~~~~",
      "~~~~~~~~~~~~~~~~",
      "~~~~~~~~~~~~~~~~",
      "~~~~~~~~~~~~~~~~",
      "~~~~~~~~~~~~~~~~",
      "~~~~~~~~~~~~~~~~"
    ]
  ]
}