{
  "xsize": 16,
  "zsize": 16,
  "refpalette": "pomkotsmechs:quarry",
  "slices": [
    [
      "!!!!!!!!!!!!!!~~",
      "!!!!!!!!!!!!!!~~",
      "!!!!!!!!!!!!!~~~",
      "!!!!!!!!!!!!!~~~",
      "!!!!!!!!!!!!~~~~",
      "!!!!!!!!!!!!~~~~",
      "!!!!!!!!!!!$~~~~",
      "!!!!!!!!!!$~~~~~",
      "~!!!!!!!!~~~~~~~",
      "!!!!!!!!~~~~~~~~",
      "!!!!!!~~~~~~~~~~",
      "!!!!~~~~~~~~~~~~",
      "~~~!~~~~~~~~~~~~",
      "~~~!~~~~~~~~~~~~",
      "~~~!~~~~~~~~~~~~",
      "~~~~~~~~~~~~~~~~"
    ],
    [
      "~~~~~~~~~~~~~~~~",
      "~~!~~~~~~~~~~~~~",
      "~~!!!~~~~~~~~~~~",
      "~~~!~~~~$~~~~~~~",
      "~~~!~~~$$$~~~~~~",
      "~~!!!~~~$$$~~~~~",
      "~~!!!~~~~~$~~~~~",
      "~~!!!~~~~~~~~~~~",
      "~~!!!~~~~~~~~~~~",
      "00!!!~~~~~~~~~~~",
      "~~~!~~~~~~~~~~~~",
      "~~~!~~~~~~~~~~~~",
      "~~!!!~~~~~~~~~~~",
      "!!!!!!~~~~~~~~~~",
      "~~!!!~~~~~~~~~~~",
      "~~~~~~~~~~~~~~~~"
    ],
    [
      "~~~~~~~~~~~~~~~~",
      "~~~!~~~~~~~~~~~~",
      "~~!!!~~~~~~~~~~~",
      "~~~!~~~~$~~~~~~~",
      "~~~~~~~$$$~~~~~~",
      "~~!~!~~~$~~~~~~~",
      "~~~~~~~~~~~~~~~~",
      "~~~~~~~~~~~~~~~~",
      "~~~!~~~~~~~~~~~~",
      "000~~~~~~~~~~~~~",
      "~~~~~~~~~~~~~~~~",
      "~~~~~~~~~~~~~~~~",
      "~~~~~!~~~~~~~~~~",
      "~~~!~!~~~~~~~~~~",
      "~~~~~~~~~~~~~~~~",
      "~~~~~~~~~~~~~~~~"
    ],
    [
      "~~~~~~~~~~~~~~~~",
      "~~~~!~~~~~~~~~~~",
      "~~!!!~~~~~~~~~~~",
      "~~~!~~~~$~~~~~~~",
      "~~~!~~~$$$~~~~~~",
      "~~!!!~~~$~~~~~~~",
      "~~~~~~~~~~~~~~~~",
      "~~~~~~~~~~~~~~~~",
      "~~~!~~~~~~~~~~~~",
      "000~~~~~~~~~~~~~",
      "~~~~~~~~~~~~~~~~",
      "~~~~~~~~~~~~~~~~",
      "~~~~~!~~~~~~~~~~",
      "~~~!~~~~~~~~~~~~",
      "~~~~~~~~~~~~~~~~",
      "~~~~~~~~~~~~~~~~"
    ],
    [
      "~~~~~~~~~~~~~~~~",
      "~~~~~!~~~~~~~~~~",
      "~~!!!!~~~~~~~~~~",
      "~~~!~~~~$~~~~~~~",
      "~~~~~$$$$$~~~~~~",
      "~~!!!$~~$~~~~~~~",
      "~~~!~~~~~~~~~~~~",
      "~~~!~~~~~~~~~~~~",
      "~~~!~~~~~~~~~~~~",
      "000~~~~~~~~~~~~~",
      "~~~~~~~~~~~~~~~~",
      "~~~~~~~~~~~~~~~~",
      "~~~~~!~~~~~~~~~~",
      "~~~!~~~~~~~~~~~~",
      "~~~~~~~~~~~~~~~~",
      "~~~~~~~~~~~~~~~~"
    ],
    [
      "!!!!!!!!!~~~~~~~",
      "!!~~~~!!!~~~~~~~",
      "!!!!!!!!!~~~~~~~",
      "!!!!!!!!!~~~~~~~",
      "!!!!!!!!!$~~~~~~",
      "!!!!!!!!!~~~~~~~",
      "!!!!!!!!!~~~~~~~",
      "000~~~~~~~~~~~~~",
      "000!~~~~~~~~~~~~",
      "000!~~~~~~~~~~~~",
      "~~~!~~~~~~~~~~~~",
      "~~~!~!~~~~~~~~~~",
      "~~~~~!~~~~~~~~~~",
      "~~~!~~~~~~~~~~~~",
      "~~~~~~~~~~~~~~~~",
      "~~~~~~~~~~~~~~~~"
    ]
  ]
}