{
  "xsize": 16,
  "zsize": 16,
  "refpalette": "lostcities:quarry",
  "slices": [
    [
      "~~~~~~~~~~~~~~~~",
      "~~~~~~~~~~~~~~~~",
      "~~~~~~~~~~~~~~~~",
      "~~~~~~~~~~~~~~~~",
      "!~~~~~~~~~~~~~~~",
      "66~~~~~~~~~~~~~~",
      "!~~~~~~~~~~~~~~~",
      "~~~~~~~~~~~~~~~~",
      "!~~~~~~~~~~~~~~~",
      "!~~~~~~~~~~~~~~~",
      "~~~~~~~~~~~~~~~~",
      "!~~~~~~~~~~~~~~~",
      "!~~~~~~~~~~~~~~~",
      "~~~~~~~~~~~~~~~~",
      "~~~~~~~~~~~~~~~~",
      "!~~~~~~~~~~~~~~~"
    ],
    [
      "~~~~~~~~~~~~~~~~",
      "~~~~~~~~~~~~~~~~",
      "~~~~~~~~~~~~~~~~",
      "'~~~~~~~~~~~~~~~",
      "66~~~~~~~~~~~~~~",
      "!~~~~~~~~~~~~~~~",
      "!~~~~~~~~~~~~~~~",
      "~~~~~~~~~~~~~~~~",
      "~~~~~~~~~~~~~~~~",
      "!~~~~~~~~~~~~~~~",
      "!~~~~~~~~~~~~~~~",
      "!~~~~~~~~~~~~~~~",
      "!~~!~~~~~~~~~~~~",
      "~~~!~~~~~~~~~~~~",
      "!~~!~~~~~~~~~~~~",
      "!~~!~~~~~~~~~~~~"
    ],
    [
      "~~~~~~~~~~~~~~~~",
      "~~~~~~~~~~~~~~~~",
      "'~~~~~~~~~~~~~~~",
      "''~~~~~~~~~~~~~~",
      "66~~~~~~~~~~~~~~",
      "!~~~~~~~~~~~~~~~",
      "~~~~~~~~~~~~~~~~",
      "~~~~~~~~~~~~~~~~",
      "~~~~~~~~~~~~~~~~",
      "~~~~~~~~~~~~~~~~",
      "!~~~~~~~~~~~~~~~",
      "!88!8~~~~~~~~~~~",
      "!88!8~~~~~~~~~~~",
      "!~~~~~~~~~~~~~~~",
      "!~~~~~~~~~~~~~~~",
      "~~~~~~~~~~~~~~~~"
    ],
    [
      "~~~~~~~~~~~~~~~~",
      "'~~~~~~~~~~~~~~~",
      "''~~~~~~~~~~~~~~",
      "!!~~~~~~~~~~~~~~",
      "66~~~~~~~~~~~~~~",
      "!~~~~~~~~~~~~~~~",
      "!~~~~~~~~~~~~~~~",
      "!~~~~~~~~~~~~~~~",
      "!~~~~~~~~~~~~~~~",
      "!~~~~~~~~~~~~~~~",
      "!8888~~~~~~~~~~~",
      "~8888'~~~~~~~~~~",
      "~8888'~~~~~~~~~~",
      "!8888~~~~~~~~~~~",
      "!~~~~~~~~~~~~~~~",
      "!~~~~~~~~~~~~~~~"
    ],
    [
      "'~~~~~~~~~~~~~~~",
      "''~~~~~~~~~~~~~~",
      "!!~~~~~~~~~~~~~~",
      "!!~~~~~~~~~~~~~~",
      "66~~~~~~~~~~~~~~",
      "!~~~~~~~~~~~~~~~",
      "!~~~~~~~~~~~~~~~",
      "!~~~~~~~~~~~~~~~",
      "!~~~~~~~~~~~~~~~",
      "!~~~~~~~~~~~~~~~",
      "!8888~~~~~~~~~~~",
      "!8888!~~~~~~~~~~",
      "'8888!~~~~~~~~~~",
      "!8888~~~~~~~~~~~",
      "!~~~~~~~~~~~~~~~",
      "!~~~~~~~~~~~~~~~"
    ],
    [
      "''~~~~~~~~~~~~~~",
      "''~~~~~~~~~~~~~~",
      "~~~~~~~~~~~~~~~~",
      "!!~~~~~~~~~~~~~~",
      "66~~~~~~~~~~~~~~",
      "!~~~~~~~~~~~~~~~",
      "~~~~~~~~~~~~~~~~",
      "~~~~~~~~~~~~~~~~",
      "~~~~~~~~~~~~~~~~",
      "!~~~~~~~~~~~~~~~",
      "!~~~~~~~~~~~~~~~",
      "!88!8~~~~~~~~~~~",
      "!88!8!~~~~~~~~~~",
      "!~~~~!~~~~~~~~~~",
      "~~~~~!~~~~~~~~~~",
      "~~~~~!~~~~~~~~~~"
    ]
  ]
}