{
  "xsize": 16,
  "zsize": 16,
  "refpalette": "pomkotsmechs:quarry",
  "slices": [
    [
      "~~~~~~~~~~~~~~~~",
      "~~~~~~~~~~~~~~~~",
      "~~~~~~~~~~~~~~~~",
      "~~~~~~~~~~~~$~~~",
      "~~~~~~<<~~~~$~~~",
      "~~~~~~<<00000000",
      "~~~~~~~&00000000",
      "~~~~~~~&00000000",
      "~~~~~~~&00000000",
      "~~~~~~~&00000000",
      "~~~~~~~&00000000",
      "~~~~~~~&00000000",
      "~~~~~~~&00000000",
      "~~~~~~~&00000000",
      "~~~~~~~&00000000",
      "~~~$$$~&00000000"
    ],
    [
      "~~~~~~~~~~~~~~~~",
      "~~~~~~~~~~~~~~~~",
      "~~~~~~~~~~~~~~~~",
      "~~~~~~~~~~~~~~~~",
      "~~~~~~<<~~~$$~~~",
      "~~~~~~<<00000000",
      "~~~~~~~&~~~~$~~~",
      "~~~~~~~&~~~~~~~~",
      "~~~~~~~&~~~~~~~~",
      "~~~~~~~&~~~~~~~~",
      "~~~~~~~&~~~~~~~~",
      "~~~~~~~&~~~~~~~~",
      "~~~~~~~&~~~~~~~~",
      "~~~~~~~&~~~~~~~~",
      "~~~~~~~&~~~~~~~~",
      "~~~~~$~&~~~~~~~~"
    ],
    [
      "~~~~~~~~~~~~~~~~",
      "~~~~~~~~~~~~~~~~",
      "~~~~~~~~~~~~~~~~",
      "~~~~~~~~~~~$$~~~",
      "~~~~~~<<~~$$$$~~",
      "~~~~~~<<0~~$00~~",
      "~~~~~~~&~~~~$~~~",
      "~~~~~~~&~~~~~~~~",
      "~~~~~~~&~~~~~~~~",
      "~~~~~~~~~~~~~~~~",
      "~~~~~~~~~~~~~~~~",
      "~~~~~~~~~~~~~~~~",
      "~~~~~~~~~~~~~~~~",
      "~~~~~~~&~~~~~~~~",
      "~~~~~~~&~~~~~~~~",
      "~~~~~$~~~~~~~~~~"
    ],
    [
      "~~~~~~~~~~~~~~~~",
      "~~~~~~~~~~~~~~~~",
      "~~~~~~~~~~~~~~~~",
      "~~~~~~~~~~~$~~~~",
      "~~~~~~<<~~$$$~~~",
      "~~~~~~<<0~~$00~~",
      "~~~~~~~&~~~~~~~~",
      "~~~~~~~&~~~~~~~~",
      "~~~~~~~&~~~~~~~~",
      "~~~~~~~~~~~~~~~~",
      "~~~~~~~~~~~~~~~~",
      "~~~~~~~~~~~~~~~~",
      "~~~~~~~~~~~~~~~~",
      "~~~~~~~&~~~~~~~~",
      "~~~~~~~&~~~~~~~~",
      "~~~~~~~~~~~~~~~~"
    ],
    [
      "~~~~~~~~~~~~~~~~",
      "~~~~~~~~~~~~~~~~",
      "~~~~~~~~~~~~~~~~",
      "~~~~~~~~~~~$~~~~",
      "~~~~~~<<~~$$$~~~",
      "~~~~~~<<0~~$00~~",
      "~~~~~~~&~~~~~~~~",
      "~~~~~~~&~~~~~~~~",
      "~~~~~~~&~~~~~~~~",
      "~~~~~~~~~~~~~~~~",
      "~~~~~~~~~~~~~~~~",
      "~~~~~~~~~~~~~~~~",
      "~~~~~~~~~~~~~~~~",
      "~~~~~~~&~~~~~~~~",
      "~~~~~~~&~~~~~~~~",
      "~~~~~~~~~~~~~~~~"
    ],
    [
      "~~~~~~~~~~~~~~~~",
      "~~~~~~~~~~~~~~~~",
      "~~~~~~~~~~~~~~~~",
      "~~~~~~~~~~~$~~~~",
      "~~~~~~<<~~$$$~~~",
      "~~~~~~<<0~~$00~~",
      "~~~~~~~&~~~~~~~~",
      "~~~~~~~&~~~~~~~~",
      "~~~~~~~&~~~~~~~~",
      "~~~~~~~~~~~~~~~~",
      "~~~~~~~~~~~~~~~~",
      "~~~~~~~~~~~~~~~~",
      "~~~~~~~~~~~~~~~~",
      "~~~~~~~&~~~~~~~~",
      "~~~~~~~&~~~~~~~~",
      "~~~~~~~~~~~~~~~~"
    ]
  ]
}