{
  "xsize": 16,
  "zsize": 16,
  "refpalette": "lostcities:quarry",
  "slices": [
    [
      "~~~~~~~~~~~~~~~~",
      "~~~~~~~~~$~~~~~~",
      "~~+~~~+~$+$~~+~~",
      "~~~~~~~~$$$~~~~~",
      "~~~~~~~~~$~~~~~~",
      "~~~~~~~~~~~~~~~~",
      "~~+~~~+~~+~~~+~~",
      "~~~~~~~~~~~~~~~~",
      "~~~~~~~~~~~~~~~~",
      "~~+~~~+~~+~~~+~~",
      "~$$$~~~~~~~~~~~~",
      "~~$~~~~~~~~~~~~~",
      "~~~~~~~~~~~~~~~~",
      "~~+~~~+~~+~~~+~~",
      "~~~~~~~~~~~~~~~~",
      "~~~~~~~~~~~~~~~~"
    ],
    [
      "~~~~~~~~~~~~~~~~",
      "~~~~~~~~~~~~~~~~",
      "~~&&&&&~~&&&&&~~",
      "~~&&&&&~$&&&&&~~",
      "~~&&&&&~~&&&&&~~",
      "~~&&&&&~~&&&&&~~",
      "~~&&&&&~~&&&&&~~",
      "~~~~~~~~~~~~~~~~",
      "~~~~~~~~~~~~~~~~",
      "~~&&&&&~~&&&&&~~",
      "~$&&&&&~~&&&&&~~",
      "~~&&&&&~~&&&&&~~",
      "~~&&&&&~~&&&&&~~",
      "~~&&&&&~~&&&&&~~",
      "~~~~~~~~~~~~~~~~",
      "~~~~~~~~~~~~~~~~"
    ],
    [
      "~~~~~~~~~~~~~~~~",
      "~~~~~~~~~~~~~~~~",
      "~~&000&~~&000&~~",
      "~~0~~~0~$0$~~0~~",
      "~~0~~~0~~0~~~0~~",
      "~~0~,,0~~0~,,0~~",
      "~~&000&~~&000&~~",
      "~~~~~~~~~~~~~~~~",
      "~~~~~~~~~~~~~~~~",
      "~~&000&~~&000&~~",
      "~$0$~~0~~0~~~0~~",
      "~~0~,,0~~0~,,0~~",
      "~~00,,0~~00,,0~~",
      "~~&000&~~&000&~~",
      "~~~~~~~~~~~~~~~~",
      "~~~~~~~~~~~~~~~~"
    ],
    [
      "~~~~~~~~~~~~~~~~",
      "~~~~~~~~~~~~~~~~",
      "~~&000&~~&000&~~",
      "~~0~~~0~$0$~~0~~",
      "~~0~~~0~$0$~~0~~",
      "~~0~~~0~~0~~~0~~",
      "~~&000&~~&000&~~",
      "~~~~~~~~~~~~~~~~",
      "~~~~~~~~~~~~~~~~",
      "~~&000&~~&000&~~",
      "~$0$$~0~~0~~~0~~",
      "~$0$~~0~~0~~~0~~",
      "~~00000~~00000~~",
      "~~&000&~~&000&~~",
      "~~~~~~~~~~~~~~~~",
      "~~~~~~~~~~~~~~~~"
    ],
    [
      "~~~~~~~~~~~~~~~~",
      "~~~~~~~~~~~~~~~~",
      "~~&&&&&~~&&&&&~~",
      "~~&&&&&~~&&&&&~~",
      "~~&&&&&~$&&&&&~~",
      "~~&&&&&~~&&&&&~~",
      "~~&&&&&~~&&&&&~~",
      "~~~~~~~~~~~~~~~~",
      "~~~~~~~~~~~~~~~~",
      "~~&&&&&~~&&&&&~~",
      "~$&&&&&~~&&&&&~~",
      "~$&&&&&~~&&&&&~~",
      "~~&&&&&~~&&&&&~~",
      "~~&&&&&~~&&&&&~~",
      "~~~~~~~~~~~~~~~~",
      "~~~~~~~~~~~~~~~~"
    ],
    [
      "~~~~~~~~~~~~~~~~",
      "~~~~~~~~~~~~~~~~",
      "~~~~~~~~~~~~~~~~",
      "~~~~~~~~~~~~~~~~",
      "~~~~~~~~~$~~~~~~",
      "~~~~~~~~~~~~~~~~",
      "~~~~~~~~~~~~~~~~",
      "~~~~~~~~~~~~~~~~",
      "~~~~~~~~~~~~~~~~",
      "~~~~~~~~~~~~~~~~",
      "~~$$$~~~~~~~~~~~",
      "~~$~~~~~~~~~~~~~",
      "~~~~~~~~~~~~~~~~",
      "~~~~~~~~~~~~~~~~",
      "~~~~~~~~~~~~~~~~",
      "~~~~~~~~~~~~~~~~"
    ]
  ]
}