{
  "xsize": 16,
  "zsize": 16,
  "refpalette": "lostcities:quarry",
  "slices": [
    [
      "~~~~~~~~~~~~~~!!",
      "~~~~~~~~~~~~~~~!",
      "~~~~~~~~~~~~~~66",
      "~~~~~~~~~~~~~~!!",
      "~~~~~~~~~~~~~~~5",
      "~~~~~~~~~~~~~~~~",
      "~~~~~~~~~~~~!~~~",
      "~~~~~~~~~~~~!~~~",
      "~~~~~~~~~~~~!~~~",
      "~~~~~~~~~~~~~~~~",
      "~~~~~~~~~~~~~~~~",
      "~~~~~~~~~~~~~~~~",
      "~~~~~~~~~~~~~~~~",
      "~~~~~~~~~~~~~~~~",
      "~~~~~~~~~~~~~~~~",
      "~~~~~~~~~~~~~~~~"
    ],
    [
      "~~~~~~~~~~~~!~~'",
      "~~~~~~~~~~~~!~~!",
      "~~~~~~~~~~~~!~~!",
      "~~~~~~~~~~~~!~66",
      "~~~~~~~~~~~~!~~5",
      "~~~~~~~~~~~~!~~~",
      "~~~~~~~~~~~!!!~~",
      "~~~~~~~~~~~!!!''",
      "~~~~~~~~~~~!!!~~",
      "~~~~~~~~~~~~!!!~",
      "~~~~~~~~~~~~!~!~",
      "~~~~~~~~~~~~!~!~",
      "~~~~~~~~~~~~!~!!",
      "~~~~~~~~~~~~!~~!",
      "~~~~~~~~~~~~!~~!",
      "~~~~~~~~~~~~!~~!"
    ],
    [
      "~~~~~~~~~~~~~~~'",
      "~~~~~~~~~~~~~~~'",
      "~~~~~~~~~~~~~~~!",
      "~~~~~~~~~~~~~~66",
      "~~~~~~~~~~~~~~!!",
      "~~~~~~~~~~~~~~~~",
      "~~~~~~~~~~~~~~''",
      "~~~~~~~~~~~~!~''",
      "~~~~~~~~~~~~~~~~",
      "~~~~~~~~~~~~!~~~",
      "~~~~~~~~~~~~!~~~",
      "~~~~~~~~~~~~!~~~",
      "~~~~~~~~~~~~!~~~",
      "~~~~~~~~~~~~~~~~",
      "~~~~~~~~~~~~~~~~",
      "~~~~~~~~~~~~~~~~"
    ],
    [
      "~~~~~~~~~~~~~~!!",
      "~~~~~~~~~~~~~~!!",
      "~~~~~~~~~~~~~~~!",
      "~~~~~~~~~~~~~~66",
      "~~~~~~~~~~~~~~!!",
      "~~~~~~~~~~~~~~!!",
      "~~~~~~~~~~~~~~''",
      "~~~~~~~~~~~~!~~'",
      "~~~~~~~~~~~~~~~~",
      "~~~~~~~~~~~~~~~~",
      "~~~~~~~~~~~~~~~~",
      "~~~~~~~~~~~~~~~~",
      "~~~~~~~~~~~~!~~~",
      "~~~~~~~~~~~~!~~~",
      "~~~~~~~~~~~~!~~~",
      "~~~~~~~~~~~~!~~~"
    ],
    [
      "~~~~~~~~~~~~~~!!",
      "~~~~~~~~~~~~~~!!",
      "~~~~~~~~~~~~~~~!",
      "~~~~~~~~~~~~~~66",
      "~~~~~~~~~~~~~~!!",
      "~~~~~~~~~~~~~~''",
      "~~~~~~~~~~~~~~~'",
      "~~~~~~~~~~~~!~~~",
      "~~~~~~~~~~~~~~~~",
      "~~~~~~~~~~~~~~~~",
      "~~~~~~~~~~~~~~~~",
      "~~~~~~~~~~~~~~~~",
      "~~~~~~~~~~~~~~~~",
      "~~~~~~~~~~~~~~~~",
      "~~~~~~~~~~~~~~~~",
      "~~~~~~~~~~~~!~~~"
    ],
    [
      "~~~~~~~~~~~~~~~'",
      "~~~~~~~~~~~~~~~'",
      "~~~~~~~~~~~~~~~!",
      "~~~~~~~~~~~~~~66",
      "~~~~~~~~~~~~~~''",
      "~~~~~~~~~~~~~~~'",
      "~~~~~~~~~~~~~~~~",
      "~~~~~~~~~~~~!~~~",
      "~~~~~~~~~~~~~~~~",
      "~~~~~~~~~~~~~~~~",
      "~~~~~~~~~~~~~~~~",
      "~~~~~~~~~~~~~~~~",
      "~~~~~~~~~~~~~~~~",
      "~~~~~~~~~~~~~~~~",
      "~~~~~~~~~~~~~~~~",
      "~~~~~~~~~~~~~~~~"
    ]
  ]
}