{
  "xsize": 16,
  "zsize": 16,
  "refpalette": "pomkotsmechs:quarry",
  "slices": [
    [
      "~~~~~~~~~~~~~~~~",
      "~~~~~~~~~~~~~~~~",
      "~~~~~~~~~~~~~~~~",
      "~~~~~~~~~~~~~~~~",
      "~~!!!!!~~~~~~~~~",
      "~~~~~~~~~~~~~~~~",
      "~~~~~~~~~~!!!!~~",
      "~~~~~~~~~~!!!~~~",
      "~~~~~~~~~~!!!~~~",
      "~~~~~~~~~~!!!!~~",
      "~~!!!!!~~~~~~~~~",
      "~~~~~~~~~~~~~~~~",
      "~~~~~~~~~~~~~~~~",
      "~~~~~~~~~~~~~~~~",
      "~~~~~~~~~~~~~~~~",
      "~~~~~~~~~~~~~~~~"
    ],
    [
      "~~~~~~~~~~~~~~~~",
      "~~~~~~~~~~~~~~~~",
      "~~~~~~~~~~~~~~~~",
      "~~~~~~~~~~~~~~~~",
      "~!&&&&&!~~~~~~~~",
      "~~~!!!~~~~~~~~~~",
      "2~~!!!~~~~~!!!!~",
      "2~~!!!~~~~~~~!~~",
      "~~~!!!~~~~~~~!~~",
      "~~~!!!~~~~~!!!!~",
      "~!&&&&&!~~~~~~~~",
      "~~~~~~~~~~~~~~~~",
      "~~~~~~~~~~~~~~~~",
      "~~~~~~~~~~~~~~~~",
      "~~~~~~~~~~~~~~~~",
      "~~~~~~~~~~~~~~~~"
    ],
    [
      "~~~~~~~~~~~~~~~~",
      "~~~~~~~~~~~~~~~~",
      "~~~~~~~~~~~~~~~~",
      "~~~~~~~~~~~~~~~~",
      "~~!!!!!~~~~~~~~~",
      "2~~####~~~~~~~~~",
      "2~~~~~#~~~~~!!!~",
      "~~~####~~~~~~!~~",
      "~~~~~~#~~~~~~!~~",
      "~~~####~~~~~!!!~",
      "~~!!!!!~~~~~~~~~",
      "~~~~~~~~~~~~~~~~",
      "~~~~~~~~~~~~~~~~",
      "~~~~~~~~~~~~~~~~",
      "~~~~~~~~~~~~~~~~",
      "~~~~~~~~~~~~~~~~"
    ],
    [
      "~~~~~~~~~~~~~~~~",
      "~~~~~~~~~~~~~~~~",
      "~~~~~~~~~~~~~~~~",
      "~~~~####~~~~~~~~",
      "~#######~~~~~~~~",
      "2#######~~~~~~~~",
      "~#######~~~~~!!~",
      "~#######~~~~~#!~",
      "~#######~~~~~#!~",
      "~#######~~~~~!!~",
      "~######~~~~~~~~~",
      "~~~~~~~~~~~~~~~~",
      "~~~~~~~~~~~~~~~~",
      "~~~~~~~~~~~~~~~~",
      "~~~~~~~~~~~~~~~~",
      "~~~~~~~~~~~~~~~~"
    ],
    [
      "~~~~~~~~~~~~~~~~",
      "~~~~~~~~~~~~~~~~",
      "~~~~~~~~~~~~~~~~",
      "~~~~#~##~~~~~~~~",
      "~#~~~~~~~~~~~~~~",
      "~#~~#~~#~~~~~~~~",
      "~#~##~~#~~~~~~~~",
      "~#~~#~~#~~~~~#~~",
      "~#~##~~#~~~~~#~~",
      "~#~~~~~#~~~~~~~~",
      "~######~~~~~~~~~",
      "~~~~~~~~~~~~~~~~",
      "~~~~~~~~~~~~~~~~",
      "~~~~~~~~~~~~~~~~",
      "~~~~~~~~~~~~~~~~",
      "~~~~~~~~~~~~~~~~"
    ],
    [
      "~~~~~~~~~~~~~~~~",
      "~~~~~~~~~~~~~~~~",
      "~~~~~~~~~~~~~~~~",
      "~~~~#~~#~~~~~~~~",
      "~#~~~~~~~~~~~~~~",
      "~~~~#~~#~~~~~~~~",
      "~~~~~~~~~~~~~~~~",
      "~~~~#~~~~~~~~#~~",
      "~~~~#~~~~~~~~#~~",
      "~~~~~~~~~~~~~~~~",
      "~#~~~~~~~~~~~~~~",
      "~~~~~~~~~~~~~~~~",
      "~~~~~~~~~~~~~~~~",
      "~~~~~~~~~~~~~~~~",
      "~~~~~~~~~~~~~~~~",
      "~~~~~~~~~~~~~~~~"
    ]
  ]
}