{
  "xsize": 16,
  "zsize": 16,
  "refpalette": "lostcities:quarry",
  "slices": [
    [
      "~~!!!!!!!!!!!!!!",
      "~~!!!!!!!!!!!!!!",
      "~~~!!!!!!!!!!!!!",
      "~~~!!!!!!!!!!!!!",
      "~~~~!!!!!!!!!!!!",
      "~~~~!!!!!!!!!!!!",
      "~~~~~!!!!!!!!!!!",
      "~~~~~~!!!!!!!!!!",
      "~~~~~~~!!!!!!!~~",
      "~~~~~~~$!!!!!!!!",
      "~~~~~~~~$~!!!!!!",
      "~~~~~~~~~~~~!!!!",
      "~~~~~~~~~~~~!~~~",
      "~~~~~~~~~~~~!~~~",
      "~~~~~~~~~~~~!~~~",
      "~~~~~~~~~~~~~~~~"
    ],
    [
      "~~~~~~0~~~~~~~~9",
      "~~~~~~0~~~~~~!~~",
      "~~~~~~0~~~~!!!~~",
      "~~~~~~0~~~~~!~~~",
      "~~~~~~0~~~~~!~~~",
      "~~~~~~0~~~~!!!~~",
      "~~~~~~!0000!!!~~",
      "~~~~~~~$$$~!!!~~",
      "~~~~~~~~$~~!!!~~",
      "~~~~~~~~$~~!!!00",
      "~~~~~~~~~~~~!~~~",
      "~~~~~~~~~~~~!~~~",
      "~~~~~~~~~~~!!!~~",
      "~~~~~~~~~~!!!!!!",
      "~~~~~~~~~~~!!!~~",
      "~~~~~~~~~~~~~~~~"
    ],
    [
      "~~~~~~0~~~~~~~~~",
      "~~~~~~~~~~~~!~~~",
      "~~~~~~~~~~~!!!~~",
      "~~~~~~~~~~~~!~~~",
      "~~~~~~~~~~~~~~~~",
      "~~~~~~0~~~~!~!~~",
      "~~~~~~!0$~0~~~~~",
      "~~~~~~~$$$~~~~~~",
      "~~~~~~~~$~~~!~~~",
      "~~~~~~~~~~~~~000",
      "~~~~~~~~~~~~~~~~",
      "~~~~~~~~~~~~~~~~",
      "~~~~~~~~~~!~~~~~",
      "~~~~~~~~~~!~!~~~",
      "~~~~~~~~~~~~~~~~",
      "~~~~~~~~~~~~~~~~"
    ],
    [
      "~~~~~'0~~~~~~~~~",
      "~~~~~'0~~~~!~~~~",
      "~~~~~'0~~~~!!!~~",
      "~~~~~'0~~~~~!~~~",
      "~~~~~'0~~~~~!~~~",
      "~~~~~~0~~~~!!!~~",
      "~~~~~~!0000~~~~~",
      "~~~~~~~$''~~~~~~",
      "~~~~~~~~$~~~!~~~",
      "~~~~~~~~~~~~~000",
      "~~~~~~~~~~~~~~~~",
      "~~~~~~~~~~~~~~~~",
      "~~~~~~~~~~!~~~~~",
      "~~~~~~~~~~~~!~~~",
      "~~~~~~~~~~~~~~~~",
      "~~~~~~~~~~~~~~~~"
    ],
    [
      "~~~~~~0~~~~~~~~~",
      "~~~~~~0~~~!~~~~~",
      "~~~~~~0~~~~!!!~~",
      "~~~~~~0~~$~~!~~~",
      "~~~~~~0~$$$$~~~~",
      "~~~~~~0~~~~!!!~~",
      "~~~~~~!0000~!~~~",
      "~~~~~~~$$$~~!~~~",
      "~~~~~~~~$~~~!~~~",
      "~~~~~~~~~~~~~000",
      "~~~~~~~~~~~~~~~~",
      "~~~~~~~~~~~~~~~~",
      "~~~~~~~~~~!~~~~~",
      "~~~~~~~~~~~~!~~~",
      "~~~~~~~~~~~~~~~~",
      "~~~~~~~~~~~~~~~~"
    ],
    [
      "~~~~~!!!!!!!!!!!",
      "~~~~~!!!!!~~~~!!",
      "~~~~~!!!!!!!!!!!",
      "~~~~~!!!!!!!!!!!",
      "~~~~~!!!!!!!!!!!",
      "~~~~~!!!!!!!!!!!",
      "~~~~~!!!!!!!!!!!",
      "~~~~~~!!!!!!~000",
      "~~~~~~~~$~~~!000",
      "~~~~~~~~~~~~!000",
      "~~~~~~~~~~~~!~~~",
      "~~~~~~~~~~!~!~~~",
      "~~~~~~~~~~!~~~~~",
      "~~~~~~~~~~~~!~~~",
      "~~~~~~~~~~~~~~~~",
      "~~~~~~~~~~~~~~~~"
    ]
  ]
}