{
  "xsize": 16,
  "zsize": 16,
  "refpalette": "lostcities:quarry",
  "slices": [
    [
      "~~~~~~~~~~~~~~~~",
      "~~~~~~~~~~~~~~~~",
      "~~~~~~~~~~~~~~~~",
      "~~~~~~~~~~~~~~~~",
      "~~~~~~~~~<<~~~~~",
      "~~~00~~~0<<$~~~~",
      "~~~~~~~~~&$$$~~~",
      "~~~~~~~~~&$$$~~~",
      "~~~~~~~~~&~$~~~~",
      "~~~~~~~~~~~~~~~~",
      "~~~~~~~~~~~~~~~~",
      "~~~~~~~~~~~~~~~~",
      "~~~~~~~~~~~~~~~~",
      "~~~~~~~~~&~~~~~~",
      "~~~~~~~~~&~~~~~~",
      "~~~~~~~~~~~~~~~~"
    ],
    [
      "~~~~~~~~~~~~~~~~",
      "~~~~~~~~~~~~~~~~",
      "~~~~~~~~~~~~~~~~",
      "~~~~~~~~~~~~~~~~",
      "~~~~~~~~~<<~~~~~",
      "000000000<<$~~~~",
      "~~~~~~~~~&$$$~~~",
      "~~~~~~~~~&~$~~~~",
      "~~~~~~~~~&~~~~~~",
      "~~~~~~~~~&~~~~~~",
      "~~~~~~~~~&~~~~~~",
      "~~~~~~~~~&~~~~~~",
      "~~~~~~~~~&~~~~~~",
      "~~~~~~~~~&~~~~~~",
      "~~~~~~~~~&~~~~~~",
      "~~~~~~~~~&~~~~~~"
    ],
    [
      "~~~~~~~~~~~~~~~~",
      "~~~~~~~~~~~~~~~~",
      "~~~~~~~~~~~~~~~~",
      "~~~~~~~~~~~~~~~~",
      "~~~~~~~~~<<$~~~~",
      "000000000<<$$~~~",
      "000000000$$$$~~~",
      "000000000$~$~~~~",
      "000000000~~~~~~~",
      "000000000~~~~~~~",
      "000000000~~~~~~~",
      "000000000~~~~~~~",
      "000000000~~~~~~~",
      "000000000~~~~~~~",
      "000000000~~~~~~~",
      "000000000~~~~~~~"
    ],
    [
      "~~~~~~~~~~~~~~~~",
      "~~~~~~~~~~~~~~~~",
      "~~~~~~~~~~~~~~~~",
      "<<<<<<<<<<<<~~~~",
      "<<<<<<<<<<<<~~~~",
      "<<<<<<<<<<<<$~~~",
      "<<<<<<<<<<<<$~~~",
      "~~~~$$$$&$$$~~~~",
      "~~$$$$$~&$~~~~~~",
      "$$$~~~~~&~~~~~~~",
      "$~~~~~~~&~~~~~~~",
      "~~~~~~~~&~~~~~~~",
      "~~~~~~~~~~~~~~~~",
      "~~~~~~~~~~~~~~~~",
      "~~~~~~~~~~~~~~~~",
      "~~~~~~~~~~~~~~~~"
    ],
    [
      "~~~~~~~~~~~~~~~~",
      "~~~~~~~~~~~~~~~~",
      "~~~~~~~~~~~~~~~~",
      "~~~~~~~~~~~~~~~~",
      "~~~~~~~~~~~~~~~~",
      "~~~~~~~~~~~$~~~~",
      "~~~~$$$$$$$$~~~~",
      "<<<<<<<<<<<<~~~~",
      "<<<<<<<<<<<<~~~~",
      "<<<<<<<<<<<<~~~~",
      "<<<<<<<<<<<<~~~~",
      "$~~~~~~~&~~~~~~~",
      "~~~~~~~~&~~~~~~~",
      "~~~~~~~~&~~~~~~~",
      "~~~~~~~~&~~~~~~~",
      "~~~~~~~~&~~~~~~~"
    ],
    [
      "~~~~~~~~~~~~~~~~",
      "~~~~~~~~~~~~~~~~",
      "~~~~~~~~~~~~~~~~",
      "~~~~~~~~~~~~~~~~",
      "~~~~~~~~~~~~~~~~",
      "~~~~~~~~~~~~~~~~",
      "~~~~~~~~~~~~~~~~",
      "~~~~$$~~$$~~~~~~",
      "~~$$$~~~~~~~~~~~",
      "$$$~~~~~~~~~~~~~",
      "$~~~~~~~~~~~~~~~",
      "<<<<<<<<<<<<~~~~",
      "<<<<<<<<<<<<~~~~",
      "<<<<<<<<<<<<~~~~",
      "<<<<<<<<<<<<~~~~",
      "<<<<<<<<<<<<~~~~"
    ]
  ]
}