{
  "xsize": 16,
  "zsize": 16,
  "refpalette": "pomkotsmechs:quarry",
  "slices": [
    [
      "~~~~~~~~~~~~~~~~",
      "~~~~~~~~~~~~~~~~",
      "~~~~~~~~~~~~~~~~",
      "~~~~~~~~~~~~~~~~",
      "~~~~~~~~~~~~~~~~",
      "~~~~~~~~~~~~~~~~",
      "~~~~~~~~~~~~~~~~",
      "~~~~~~~~~~~~~~~~",
      "~~~~~~~~~~~~~~~~",
      "~~~~~~~~~~~~~~~~",
      "~~~~~~~~~~~~~~~~",
      "~~~~~~~~~~~~~~!!",
      "~~~~~~~~~~~~~~''",
      "~~~~~~~~~~~~~~~'",
      "~~~~~~~~~~~~~~~~",
      "~~~~~~~~~~~~~~~~"
    ],
    [
      "~~~~~~~~~~~~~~~~",
      "~~~~~~~~~~~~~~~~",
      "~~~~~~~~~~~~~~~~",
      "~~~~~~~~~~~~~~~~",
      "~~~~~~~~~~~~~~~'",
      "~~~~~~~~~~~~~~~'",
      "~~~~~~~~~~~~~~~'",
      "~~~~~~~~~~~~~~~5",
      "~~~~~~~~~~~~~~~5",
      "~~~~~~~~~~~~~~$5",
      "~~~~~~~~~~~~~~!!",
      "~~~~~~~~~~~~~~!!",
      "~~~~~~~~~~~~~~!!",
      "~~~~~~~~~~~~~~''",
      "~~~~~~~~~~~~~~~'",
      "~~~~~~~~~~~~~~~~"
    ],
    [
      "~~~~~~~~~~~~~~~~",
      "~~~~~~~~~~~~~~~~",
      "~~~~~~~~~~~~~~~~",
      "~~~~~~~~~~~~~~~'",
      "~~~~~~~~~~~~~~!'",
      "~~~~~~~~~~~~~~~'",
      "~~~~~~~~~~~~~~!'",
      "~~~~~~~~~~~~~~~'",
      "~~~~~~~~~~~~~~!!",
      "~~~~~~~~~~~~~$66",
      "~~~~~~~~~~~~~~66",
      "~~~~~~~~~~~~~~66",
      "~~~~~~~~~~~~~~66",
      "~~~~~~~~~~~~~~66",
      "~~~~~~~~~~~~~~66",
      "~~~~~~~~~~~~~~~!"
    ],
    [
      "~~~~~~~~~~~~~~~~",
      "~~~~~~~~~~~~~~~~",
      "~~~~~~~~~~~~~~''",
      "~~~~~~~~~~~~~~''",
      "~~~~~~~~~~~~~~!!",
      "~~~~~~~~~~~~~~!!",
      "~~~~~~~~~~~~~~!'",
      "~~~~~~~~~~~~~~66",
      "~~~~~~~~~~~~~~66",
      "~~~~~~~~~~~~~$$!",
      "~~~~~~~~~~~~~~$!",
      "~~~~~~~~~~~~~~~!",
      "~~~~~~~~~~~~~~~!",
      "~~~~~~~~~~~~~~~!",
      "~~~~~~~~~~~~~~~!",
      "~~~~~~~~~~~~~~66"
    ],
    [
      "~~~~~~~~~~~~~~~~",
      "~~~~~~~~~~~~~~''",
      "~~~~~~~~~~~~~~''",
      "~~~~~~~~~~~~~~~~",
      "~~~~~~~~~~~~~~~~",
      "~~~~~~~~~~~~~~!!",
      "~~~~~~~~~~~~~~66",
      "~~~~~~~~~~~~~~66",
      "~~~~~~~~~~~~~$$!",
      "~~~~~~~~~~~~~$$!",
      "~~~~~~~~~~~~~$$'",
      "~~~~~~~~~~~~~~!!",
      "~~~~~~~~~~~~~~!!",
      "~~~~~~~~~~~~~~~'",
      "~~~~~~~~~~~~~~~!",
      "~~~~~~~~~~~~~~~!"
    ],
    [
      "~~~~~~~~~~~~~~~~",
      "~~~~~~~~~~~~~~~~",
      "~~~~~~~~~~~~~~~~",
      "~~~~~~~~~~~~~~~~",
      "~~~~~~~~~~~~~~~!",
      "~~~~~~~~~~~~~~66",
      "~~~~~~~~~~~~~~66",
      "~~~~~~~~~~~~~~!!",
      "~~~~~~~~~~~~~$!!",
      "~~~~~~~~~~~~~$$'",
      "~~~~~~~~~~~~$$$'",
      "~~~~~~~~~~~~~$!!",
      "~~~~~~~~~~~~~~!!",
      "~~~~~~~~~~~~~~~'",
      "~~~~~~~~~~~~~~~'",
      "~~~~~~~~~~~~~~~'"
    ]
  ]
}