{
  "xsize": 16,
  "zsize": 16,
  "refpalette": "pomkotsmechs:quarry",
  "slices": [
    [
      "~~~~~~~~~~~~~~~~",
      "~~~~~~~~~~~~~~~~",
      "~~~~~!~~~~~!~~~~",
      "~~~~~!~~~~~!~~~~",
      "~~~~~!~~~~~!~~~~",
      "~~~~~!~~~~~!~~~~",
      "~~~~~!~~~~~!~~~~",
      "~~~~~~~~~~~~~~~~",
      "~~~~~~~~~~~~~~~~",
      "~~~~~~~~~~~~~~~~",
      "~~~~~~!!!!~~~~~~",
      "~~~~~~!!!!~~~~~~",
      "~~~~~~!!!!~~~~~~",
      "~~~~~~!~~!~~~~~~",
      "~~~~~~~~~~~~~~~~",
      "~~~~~~~~~~~~~~~~"
    ],
    [
      "~~~~~~~~22~~~~~~",
      "~~~~~!~~~~~!~~~~",
      "~~~~~&~~~~~&~~~~",
      "~~~~~&!!!!!&~~~~",
      "~~~~~&!!!!!&~~~~",
      "~~~~~&!!!!!&~~~~",
      "~~~~~&~~~~~&~~~~",
      "~~~~~!~~~~~!~~~~",
      "~~~~~~~~~~~~~~~~",
      "~~~~~~~~~~~~~~~~",
      "~~~~~~~~~~~~~~~~",
      "~~~~~~!~~!~~~~~~",
      "~~~~~~!~~!~~~~~~",
      "~~~~~~!!!!~~~~~~",
      "~~~~~~!~~!~~~~~~",
      "~~~~~~~~~~~~~~~~"
    ],
    [
      "~~~~~~~~~22~~~~~",
      "~~~~~~~~~~~~~~~~",
      "~~~~~!~~~~~!~~~~",
      "~~~~~!#~#~#!~~~~",
      "~~~~~!#~#~#!~~~~",
      "~~~~~!#~#~#!~~~~",
      "~~~~~!#####!~~~~",
      "~~~~~~~~~~~~~~~~",
      "~~~~~~~~~~~~~~~~",
      "~~~~~~~~~~~~~~~~",
      "~~~~~~~~~~~~~~~~",
      "~~~~~~~~~~~~~~~~",
      "~~~~~~!~~!~~~~~~",
      "~~~~~~!!!!~~~~~~",
      "~~~~~~!~~!~~~~~~",
      "~~~~~~~~~~~~~~~~"
    ],
    [
      "~~~~~~~~~~2~~~~~",
      "~~~~~#######~~~~",
      "~~~~~#######~~~~",
      "~~~~~#######~~~~",
      "~~~~~########~~~",
      "~~~~~########~~~",
      "~~~~~########~~~",
      "~~~~~~#######~~~",
      "~~~~~~~~~~~~~~~~",
      "~~~~~~~~~~~~~~~~",
      "~~~~~~~~~~~~~~~~",
      "~~~~~~~~~~~~~~~~",
      "~~~~~~~~~~~~~~~~",
      "~~~~~~!##!~~~~~~",
      "~~~~~~!!!!~~~~~~",
      "~~~~~~~~~~~~~~~~"
    ],
    [
      "~~~~~~~~~~~~~~~~",
      "~~~~~#######~~~~",
      "~~~~~#~~~~~~~~~~",
      "~~~~~#~#~#~~~~~~",
      "~~~~~#~####~#~~~",
      "~~~~~#~~~~~~~~~~",
      "~~~~~#~~~~~~#~~~",
      "~~~~~~#####~#~~~",
      "~~~~~~~~~~~~~~~~",
      "~~~~~~~~~~~~~~~~",
      "~~~~~~~~~~~~~~~~",
      "~~~~~~~~~~~~~~~~",
      "~~~~~~~~~~~~~~~~",
      "~~~~~~~##~~~~~~~",
      "~~~~~~~~~~~~~~~~",
      "~~~~~~~~~~~~~~~~"
    ],
    [
      "~~~~~~~~~~~~~~~~",
      "~~~~~#~~~~~#~~~~",
      "~~~~~~~~~~~~~~~~",
      "~~~~~~~~~~~~~~~~",
      "~~~~~~~##~#~#~~~",
      "~~~~~~~~~~~~~~~~",
      "~~~~~~~~~~~~~~~~",
      "~~~~~~~~~~#~#~~~",
      "~~~~~~~~~~~~~~~~",
      "~~~~~~~~~~~~~~~~",
      "~~~~~~~~~~~~~~~~",
      "~~~~~~~~~~~~~~~~",
      "~~~~~~~~~~~~~~~~",
      "~~~~~~~##~~~~~~~",
      "~~~~~~~~~~~~~~~~",
      "~~~~~~~~~~~~~~~~"
    ]
  ]
}