{
  "xsize": 16,
  "zsize": 16,
  "refpalette": "lostcities:quarry",
  "slices": [
    [
      "~~~~~~~~~~~~~~~~",
      "~~~~~~~~~~~~~~~~",
      "~~~~~~!~~!~~~~~~",
      "~~~~~~!!!!~~~~~~",
      "~~~~~~!!!!~~~~~~",
      "~~~~~~!!!!~~~~~~",
      "~~~~~~~~~~~~~~~~",
      "~~~~~~~~~~~~~~~~",
      "~~~~~~~~~~~~~~~~",
      "~~~~!~~~~~!~~~~~",
      "~~~~!~~~~~!~~~~~",
      "~~~~!~~~~~!~~~~~",
      "~~~~!~~~~~!~~~~~",
      "~~~~!~~~~~!~~~~~",
      "~~~~~~~~~~~~~~~~",
      "~~~~~~~~~~~~~~~~"
    ],
    [
      "~~~~~~~~~~~~~~~~",
      "~~~~~~!~~!~~~~~~",
      "~~~~~~!!!!~~~~~~",
      "~~~~~~!~~!~~~~~~",
      "~~~~~~!~~!~~~~~~",
      "~~~~~~~~~~~~~~~~",
      "~~~~~~~~~~~~~~~~",
      "~~~~~~~~~~~~~~~~",
      "~~~~!~~~~~!~~~~~",
      "~~~~&~~~~~&~~~~~",
      "~~~~&!!!!!&~~~~~",
      "~~~~&!!!!!&~~~~~",
      "~~~~&!!!!!&~~~~~",
      "~~~~&~~~~~&~~~~~",
      "~~~~!~~~~~!~~~~~",
      "~~~~~~22~~~~~~~~"
    ],
    [
      "~~~~~~~~~~~~~~~~",
      "~~~~~~!~~!~~~~~~",
      "~~~~~~!!!!~~~~~~",
      "~~~~~~!~~!~~~~~~",
      "~~~~~~~~~~~~~~~~",
      "~~~~~~~~~~~~~~~~",
      "~~~~~~~~~~~~~~~~",
      "~~~~~~~~~~~~~~~~",
      "~~~~~~~~~~~~~~~~",
      "~~~~!#####!~~~~~",
      "~~~~!#~#~#!~~~~~",
      "~~~~!#~#~#!~~~~~",
      "~~~~!#~#~#!~~~~~",
      "~~~~!~~~~~!~~~~~",
      "~~~~~~~~~~~~~~~~",
      "~~~~~22~~~~~~~~~"
    ],
    [
      "~~~~~~~~~~~~~~~~",
      "~~~~~~!!!!~~~~~~",
      "~~~~~~!##!~~~~~~",
      "~~~~~~~~~~~~~~~~",
      "~~~~~~~~~~~~~~~~",
      "~~~~~~~~~~~~~~~~",
      "~~~~~~~~~~~~~~~~",
      "~~~~~~~~~~~~~~~~",
      "~~~#######~~~~~~",
      "~~~########~~~~~",
      "~~~########~~~~~",
      "~~~########~~~~~",
      "~~~~#######~~~~~",
      "~~~~#######~~~~~",
      "~~~~#######~~~~~",
      "~~~~~2~~~~~~~~~~"
    ],
    [
      "~~~~~~~~~~~~~~~~",
      "~~~~~~~~~~~~~~~~",
      "~~~~~~~##~~~~~~~",
      "~~~~~~~~~~~~~~~~",
      "~~~~~~~~~~~~~~~~",
      "~~~~~~~~~~~~~~~~",
      "~~~~~~~~~~~~~~~~",
      "~~~~~~~~~$~~~~~~",
      "~~~#~#####$~~~~~",
      "~~~#~~~~~$#~~~~~",
      "~~~~~~~~~~#~~~~~",
      "~~~#~####~#~~~~~",
      "~~~~~~#~#~#~~~~~",
      "~~~~~~~~~~#~~~~~",
      "~~~~#######~~~~~",
      "~~~~~~~~~~~~~~~~"
    ],
    [
      "~~~~~~~~~~~~~~~~",
      "~~~~~~~~~~~~~~~~",
      "~~~~~~~##~~~~~~~",
      "~~~~~~~~~~~~~~~~",
      "~~~~~~~~~~~~~~~~",
      "~~~~~~~~~~~~~~~~",
      "~~~~~~~~~~~~~~~~",
      "~~~~~~~~~~~~~~~~",
      "~~~#~#~~~$~~~~~~",
      "~~~~~~~~~~~~~~~~",
      "~~~~~~~~~~~~~~~~",
      "~~~#~#~##~~~~~~~",
      "~~~~~~~~~~~~~~~~",
      "~~~~~~~~~~~~~~~~",
      "~~~~#~~~~~#~~~~~",
      "~~~~~~~~~~~~~~~~"
    ]
  ]
}