{
  "xsize": 16,
  "zsize": 16,
  "refpalette": "pomkotsmechs:quarry",
  "slices": [
    [
      "~~~~~~~~~~~~~~~~",
      "~~~~~~~~~~~~~~~~",
      "~~~~~~~~~~~~~~~~",
      "~~~~~~~~~~~~~~~~",
      "~~~~~~~~~~~~~~~!",
      "~~~~~~~~~~~~~~66",
      "~~~~~~~~~~~~~~~!",
      "~~~~~~~~~~~~~~$'",
      "~~~~~~~~~~~~~$!!",
      "~~~~~~~~~~~~~$!!",
      "~~~~~~~~~~~~$$$'",
      "~~~~~~~~~~~~~$!!",
      "~~~~~~~~~~~~~~!!",
      "~~~~~~~~~~~~~~~'",
      "~~~~~~~~~~~~~~~'",
      "~~~~~~~~~~~~~~!!"
    ],
    [
      "~~~~~~~~~~~~~~~~",
      "~~~~~~~~~~~~~~~~",
      "~~~~~~~~~~~~~~~~",
      "~~~~~~~~~~~~~~~'",
      "~~~~~~~~~~~~~~66",
      "~~~~~~~~~~~~~~~!",
      "~~~~~~~~~~~~~~~!",
      "~~~~~~~~~~~~~~$'",
      "~~~~~~~~~~~~~$$'",
      "~~~~~~~~~~~~~$!!",
      "~~~~~~~~~~~~$$!!",
      "~~~~~~~~~~~~~$!!",
      "~~~~~~~~~~~~!~!!",
      "~~~~~~~~~~~~!~~'",
      "~~~~~~~~~~~~!~!!",
      "~~~~~~~~~~~~!~!!"
    ],
    [
      "~~~~~~~~~~~~~~~~",
      "~~~~~~~~~~~~~~~~",
      "~~~~~~~~~~~~~~~'",
      "~~~~~~~~~~~~~~''",
      "~~~~~~~~~~~~~~66",
      "~~~~~~~~~~~~~~~!",
      "~~~~~~~~~~~~~~~'",
      "~~~~~~~~~~~~~~$'",
      "~~~~~~~~~~~~~$$'",
      "~~~~~~~~~~~~~$$'",
      "~~~~~~~~~~~~$$!!",
      "~~~~~~~~~~~8!8!!",
      "~~~~~~~~~~~8!8!!",
      "~~~~~~~~~~~~~~!!",
      "~~~~~~~~~~~~~~!!",
      "~~~~~~~~~~~~~~~'"
    ],
    [
      "~~~~~~~~~~~~~~~~",
      "~~~~~~~~~~~~~~~'",
      "~~~~~~~~~~~~~~''",
      "~~~~~~~~~~~~~~!!",
      "~~~~~~~~~~~~~~66",
      "~~~~~~~~~~~~~~~!",
      "~~~~~~~~~~~~~~!!",
      "~~~~~~~~~~~~~~!!",
      "~~~~~~~~~~~~~$!!",
      "~~~~~~~~~~~~$$!!",
      "~~~~~~~~~~~8$8!!",
      "~~~~~~~~~~'888~~",
      "~~~~~~~~~~'888~~",
      "~~~~~~~~~~~8~8!!",
      "~~~~~~~~~~~~~~!!",
      "~~~~~~~~~~~~~~!!"
    ],
    [
      "~~~~~~~~~~~~~~~'",
      "~~~~~~~~~~~~~~''",
      "~~~~~~~~~~~~~~!!",
      "~~~~~~~~~~~~~~!!",
      "~~~~~~~~~~~~~~66",
      "~~~~~~~~~~~~~~~!",
      "~~~~~~~~~~~~~~!!",
      "~~~~~~~~~~~~~~!!",
      "~~~~~~~~~~~~~$!!",
      "~~~~~~~~~~~~$$!!",
      "~~~~~~~~~~~8$8!!",
      "~~~~~~~~~~!888!!",
      "~~~~~~~~~~!888'~",
      "~~~~~~~~~~~8~8!!",
      "~~~~~~~~~~~~~~!!",
      "~~~~~~~~~~~~~~!!"
    ],
    [
      "~~~~~~~~~~~~~~''",
      "~~~~~~~~~~~~~~''",
      "~~~~~~~~~~~~~~~~",
      "~~~~~~~~~~~~~~!!",
      "~~~~~~~~~~~~~~66",
      "~~~~~~~~~~~~~~~!",
      "~~~~~~~~~~~~~~~'",
      "~~~~~~~~~~~~~~~'",
      "~~~~~~~~~~~~~~$'",
      "~~~~~~~~~~~~~$!!",
      "~~~~~~~~~~~$$$!!",
      "~~~~~~~~~~$8!8!!",
      "~~~~~~~~~~!8!8!!",
      "~~~~~~~~~~!$~~!!",
      "~~~~~~~~~~!~~~~'",
      "~~~~~~~~~~!~~~~'"
    ]
  ]
}