{
  "xsize": 16,
  "zsize": 16,
  "refpalette": "lostcities:quarry",
  "slices": [
    [
      "~~~~~~~~~~~~~~~~",
      "~~~~~~~~~~~~~~~~",
      "~~~~~~~~~~~~~~~~",
      "~~~~~~~~~~~~~~~~",
      "~~~~~~~~~~~~~~~~",
      "~~~~~~~~~!!!!!~~",
      "~~!!!!~~~~~~~~~~",
      "~~~!!!~~~~~~~~~~",
      "~~~!!!~~~~~~~~~~",
      "~~!!!!~~~~~~~~~~",
      "~~~~~~~~~~~~~~~~",
      "~~~~~~~~~!!!!!~~",
      "~~~~~~~~~~~~~~~~",
      "~~~~~~~~~~~~~~~~",
      "~~~~~~~~~~~~~~~~",
      "~~~~~~~~~~~~~~~~"
    ],
    [
      "~~~~~~~~~~~~~~~~",
      "~~~~~~~~~~~~~~~~",
      "~~~~~~~~~~~~~~~~",
      "~~~~~~~~~~~~~~~~",
      "~~~~~~~~~~~~~~~~",
      "~~~~~~~~!&&&&&!~",
      "~!!!!~~~~~!!!~~~",
      "~~!~~~~~~~!!!~~~",
      "~~!~~~~~~~!!!~~2",
      "~!!!!~~~~~!!!~~2",
      "~~~~~~~~~~!!!~~~",
      "~~~~~~~~!&&&&&!~",
      "~~~~~~~~~~~~~~~~",
      "~~~~~~~~~~~~~~~~",
      "~~~~~~~~~~~~~~~~",
      "~~~~~~~~~~~~~~~~"
    ],
    [
      "~~~~~~~~~~~~~~~~",
      "~~~~~~~~~~~~~~~~",
      "~~~~~~~~~~~~~~~~",
      "~~~~~~~~~~~~~~~~",
      "~~~~~~~~~~~~~~~~",
      "~~~~~~~~~!!!!!~~",
      "~!!!~~~~~####~~~",
      "~~!~~~~~~#~~~~~~",
      "~~!~~~~~~####~~~",
      "~!!!~~~~~#~~~~~2",
      "~~~~~~~~~####~~2",
      "~~~~~~~~~!!!!!~~",
      "~~~~~~~~~~~~~~~~",
      "~~~~~~~~~~~~~~~~",
      "~~~~~~~~~~~~~~~~",
      "~~~~~~~~~~~~~~~~"
    ],
    [
      "~~~~~~~~~~~~~~~~",
      "~~~~~~~~~~~~~~~~",
      "~~~~~~~~~~~~~~~~",
      "~~~~~~~~~~~~~~~~",
      "~~~~~~~~~~~~~~~~",
      "~~~~~~~~~######~",
      "~!!~~~~~#######~",
      "~!#~~~~~#######~",
      "~!#~~~~~#######~",
      "~!!~~~~~#######~",
      "~~~~~~~~#######2",
      "~~~~~~~~#######~",
      "~~~~~~~~####~~~~",
      "~~~~~~~~~~~~~~~~",
      "~~~~~~~~~~~~~~~~",
      "~~~~~~~~~~~~~~~~"
    ],
    [
      "~~~~~~~~~~~~~~~~",
      "~~~~~~~~~~~~~~~~",
      "~~~~~~~~~~~~~~~~",
      "~~~~~~~~~~~~~~~~",
      "~~~~~~~~~~~~~~~~",
      "~~~~~~~~~######~",
      "~~~~~~~~#~~~~~#~",
      "~~#~~~~~#~~##~#~",
      "~~#~~~~~#~~#~~#~",
      "~~~~~~~~#~~##~#~",
      "~~~~~~~~#~~#~~#~",
      "~~~~~~~~~~~~~~#~",
      "~~~~~~~~##~#~~~~",
      "~~~~~~~~~~~~~~~~",
      "~~~~~~~~~~~~~~~~",
      "~~~~~~~~~~~~~~~~"
    ],
    [
      "~~~~~~~~~~~~~~~~",
      "~~~~~~~~~~~~~~~~",
      "~~~~~~~~~~~~~~~~",
      "~~~~~~~~~~~~~~~~",
      "~~~~~~~~~~~~~~~~",
      "~~~~~~~~~~~~~~#~",
      "~~~~~~~~~~~~~~~~",
      "~~#~~~~~~~~#~~~~",
      "~~#~~~~~~~~#~~~~",
      "~~~~~~~~~~~~~~~~",
      "~~~~~~~~#~~#~~~~",
      "~~~~~~~~~~~~~~#~",
      "~~~~~~~~#~~#~~~~",
      "~~~~~~~~~~~~~~~~",
      "~~~~~~~~~~~~~~~~",
      "~~~~~~~~~~~~~~~~"
    ]
  ]
}