{
  "xsize": 16,
  "zsize": 16,
  "refpalette": "lostcities:quarry",
  "slices": [
    [
      "~~~~~$~~~~~~~~~~",
      "~~~~$$$~~~~~~~~~",
      "~~~~~$~~~~~~~~~~",
      "~~~~~~~&~~~~~~~~",
      "~~~~~~~&~~~~~~~~",
      "~~~~~~~~~~~~~~~~",
      "~~~~~~~~~~~~~~~~",
      "~~~~~~~~~~~~~~~~",
      "~~~~~~~~~~~~~~~~",
      "~~~~~~~&~~~~~~~~",
      "~~~~~~~&~~~~~~~~",
      "~~~~~~<<&~~~~&&~",
      "~~~~~$<<~~~~~~~~",
      "~~~~~~$~~~~~~~~~",
      "~~~~~~~~~~~~~~~~",
      "~~~~~~~~~~~~~~~~"
    ],
    [
      "~~~~~$~&~~~~~~~~",
      "~~~~$$$&~~~~~~~~",
      "~~~~~$~&~~~~~~~~",
      "~~~~~~~&~~~~~~~~",
      "~~~~~~~&~~~~~~~~",
      "~~~~~~~&~~~~~~~~",
      "~~~~~~~&~~~~~~~~",
      "~~~~~~~&~~~~~~~~",
      "~~~~~~~&~~~~~~~~",
      "~~~~~~~&~~~~~~~~",
      "~~~~~~~&~~~~~~~~",
      "~~~~~~<<&&&&&&&&",
      "~~~~~$<<$~~~~~~~",
      "~~~~~~$$~~~~~~~~",
      "~~~~~~~~~~~~~~~~",
      "~~~~~~~~~~~~~~~~"
    ],
    [
      "~~~~~$~~00000000",
      "~~~~$$$~00000000",
      "~~~~~$~~00000000",
      "~~~~~~~~00000000",
      "~~~~~~~~00000000",
      "~~~~~~~~00000000",
      "~~~~~~~~00000000",
      "~~~~~~~~00000000",
      "~~~~~~~~00000000",
      "~~~~~~~~00000000",
      "~~~~~~~~00000000",
      "~~~~~~<<~~~&~~~~",
      "~~~~~~<<$~~~~~~~",
      "~~~~~~~$~~~~~~~~",
      "~~~~~~~~~~~~~~~~",
      "~~~~~~~~~~~~~~~~"
    ],
    [
      "~~~~~$~~&~~~~~~~",
      "~~~~$$$~~~~~~~~~",
      "~~~~$$$~~~~~~~~~",
      "~~~~~$~~~~~~~~~~",
      "~~~~~~~~&~~~~~~~",
      "~~~~~~~~~~~~~~~~",
      "~~~~~~~~~~~~~~~~",
      "~~~~~~~~~~~~~~~~",
      "~~~~~~~~~~~~~~~~",
      "~~~~~~~~~~~~~~~~",
      "~~~~~~~~&~~~~~~~",
      "~~~~~~<<~~~&~~~~",
      "~~~~~~<<$~~~~~~~",
      "~~~~~~$$$~~~~~~~",
      "~~~~~~~$~~~~~~~~",
      "~~~~~~~~~~~~~~~~"
    ],
    [
      "~~~~~~~~&~~~~~~~",
      "~~~~~$~~~~~~~~~~",
      "~~~~$$$~~~~~~~~~",
      "~~~~~$~~~~~~~~~~",
      "~~~~~~~~&~~~~~~~",
      "~~~~~~~~~~~~~~~~",
      "~~~~~~~~~~~~~~~~",
      "~~~~~~~~~~~~~~~~",
      "~~~~~~~~~~~~~~~~",
      "~~~~~~~~~~~~~~~~",
      "~~~~~~~~&~~~~~~~",
      "~~~~~~<<~~~&&&&&",
      "~~~~~~<<~~~~~~~~",
      "~~~~~~$$$~~~~~~~",
      "~~~~~~~$~~~~~~~~",
      "~~~~~~~~~~~~~~~~"
    ],
    [
      "~~~~~~~~&~~~$~~~",
      "~~~~~$~~&~~~$~~~",
      "~~~~$$$~&~~~$~~~",
      "~~~~~$$$&$$$$~~~",
      "~~~~~~~~&~~~~~~~",
      "~~~~~~~~~~~~~~~~",
      "~~~~~~~~~~~~~~~~",
      "~~~~~~~~~~~~~~~~",
      "~~~~~~~~~~~~~~~~",
      "~~~~~~~~~~~~~~~~",
      "~~~~~~~~&~~~~~~~",
      "~~~~~~<<~~~&~~~~",
      "~~~~~~<<$~~~~~~~",
      "~~~~~~$$$$~~~~~~",
      "~~~~~~~$$~~~~~~~",
      "~~~~~~~~~~~~~~~~"
    ]
  ]
}