{
  "xsize": 16,
  "zsize": 16,
  "refpalette": "pomkotsmechs:quarry",
  "slices": [
    [
      "~~~!~!~~~~~~~~~~",
      "!~~!~!~~~~~~~~~~",
      "!~~!~!~~~~~~~~~~",
      "66~!~~~~~~~~~~~~",
      "'~~!~~~~~~~~~~~~",
      "~~~!~~~~~~~~~~~~",
      "~~!!!~~~~~~~~~~~",
      "~~!!!~~~~~~~~~~~",
      "~~!!!~~~~~~~~~~~",
      "~!!!~~~~~~~~~~~~",
      "~!~!~~~~~~~~~~~~",
      "~!~!~~~~~~~~~~~~",
      "!!~!~~~~~~~~~~~~",
      "!~~!~~~~~~~~~~~~",
      "!~~!~~~~~~~~~~~~",
      "!~~!~~~~~~~~~~~~"
    ],
    [
      "~~~~~~~~~~~~~~~~",
      "!~~~~~~~~~~~~~~~",
      "66~~~!~~~~~~~~~~",
      "!~~~~!~~~~~~~~~~",
      "~~~~~!~~~~~~~~~~",
      "~~~~~~~~~~~~~~~~",
      "~~~!~~~~~~~~~~~~",
      "~~~!~~~~~~~~~~~~",
      "~~~!~~~~~~~~~~~~",
      "~~~~~~~~~~~~~~~~",
      "~~~~~~~~~~~~~~~~",
      "~~~~~~~~~~~~~~~~",
      "~~~~~~~~~~~~~~~~",
      "~~~~~~~~~~~~~~~~",
      "~~~~~~~~~~~~~~~~",
      "~~~~~~~~~~~~~~~~"
    ],
    [
      "!~~~~~~~~~~~~~~~",
      "66~~~~~~~~~~~~~~",
      "66~~~~~~~~~~~~~~",
      "!~~~~~~~~~~~~~~~",
      "~~~~~!~~~~~~~~~~",
      "~~~~~!~~~~~~~~~~",
      "~~~~~!~~~~~~~~~~",
      "~~~~~!~~~~~~~~~~",
      "~~~~~~~~~~~~~~~~",
      "~~~~~~~~~~~~~~~~",
      "~~~~~~~~~~~~~~~~",
      "~~~~~~~~~~~~~~~~",
      "~~~~~~~~~~~~~~~~",
      "~~~~~~~~~~~~~~~~",
      "~~~~~~~~~~~~~~~~",
      "~~~~~~~~~~~~~~~~"
    ],
    [
      "66~~~~~~~~~~~~~~",
      "66~~~~~~~~~~~~~~",
      "!!~~~~~~~~~~~~~~",
      "~~~~~~~~~~~~~~~~",
      "~~~~~~~~~~~~~~~~",
      "''~~~~~~~~~~~~~~",
      "''~~~~~~~~~~~~~~",
      "~~~~~!~~~~~~~~~~",
      "~~~~~!~~~~~~~~~~",
      "~~~~~!~~~~~~~~~~",
      "~~~~~!~~~~~~~~~~",
      "~~~~~~~~~~~~~~~~",
      "~~~~~~~~~~~~~~~~",
      "~~~~~~~~~~~~~~~~",
      "~~~~~~~~~~~~~~~~",
      "~~~~~~~~~~~~~~~~"
    ],
    [
      "66~~~~~~~~~~~~~~",
      "'!~~~~~~~~~~~~~~",
      "!!~~~~~~~~~~~~~~",
      "!!~~~~~~~~~~~~~~",
      "''~~~~~~~~~~~~~~",
      "''~~~~~~~~~~~~~~",
      "~~~~~~~~~~~~~~~~",
      "~~~~~~~~~~~~~~~~",
      "~~~~~~~~~~~~~~~~",
      "~~~~~~~~~~~~~~~~",
      "~~~~~!~~~~~~~~~~",
      "~~~~~!~~~~~~~~~~",
      "~~~~~!~~~~~~~~~~",
      "~~~~~!~~~~~~~~~~",
      "~~~~~~~~~~~~~~~~",
      "~~~~~~~~~~~~~~~~"
    ],
    [
      "'~~~~~~~~~~~~~~~",
      "'!~~~~~~~~~~~~~~",
      "'~~~~~~~~~~~~~~~",
      "'!~~~~~~~~~~~~~~",
      "'~~~~~~~~~~~~~~~",
      "~~~~~~~~~~~~~~~~",
      "~~~~~~~~~~~~~~~~",
      "~~~~~~~~~~~~~~~~",
      "~~~~~~~~~~~~~~~~",
      "~~~~~~~~~~~~~~~~",
      "~~~~~~~~~~~~~~~~",
      "~~~~~~~~~~~~~~~~",
      "~~~~~~~~~~~~~~~~",
      "~~~~~!~~~~~~~~~~",
      "~~~~~!~~~~~~~~~~",
      "~~~~~!~~~~~~~~~~"
    ]
  ]
}