{
  "xsize": 16,
  "zsize": 16,
  "refpalette": "pomkotsmechs:quarry",
  "slices": [
    [
      "~~~~~~~~~~~~~~~~",
      "~~~~~~~~~~~~~~~~",
      "~~~~~~~~~~~~~~~~",
      "~~~~~~~~~~~~~~~~",
      "~~~~~~~~~~~~~~~~",
      "~~~~~~~~~~~~~~~~",
      "~~~~~~~~~~~~~~~~",
      "~~~~~~~~~~~~~~~~",
      "~~~~~~~~~~~~~~~~",
      "~~~~~~~~~~~~~~~~",
      "~~~~~~~~~~~~~~~~",
      "!!~~~~~~~~~~~~~~",
      "''~~~~~~~~~~~~~~",
      "'~~~~~~~~~~~~~~~",
      "~~~~~~~~~~~~~~~~",
      "~~~~~~~~~~~~~~~~"
    ],
    [
      "~~~~~~~~~~~~~~~~",
      "~~~~~~~~~~~~~~~~",
      "~~~~~~~~~~~~~~~~",
      "~~~~~~~~~~~~~~~~",
      "'~~~~~~~~~~~~~~~",
      "'~~~~~~~~~~~~~~~",
      "'~~~~~~~~~~~~~~~",
      "7~~~~~~~~~~~~~~~",
      "7~~~~~~~~~~~~~~~",
      "7~~~~~~~~~~~~~~~",
      "!!~~~~~~~~~~~~~~",
      "!!~~~~~~~~~~~~~~",
      "!!~~~~~~~~~~~~~~",
      "''~~~~~~~~~~~~~~",
      "'~~~~~~~~~~~~~~~",
      "~~~~~~~~~~~~~~~~"
    ],
    [
      "~~~~~~~~~~~~~~~~",
      "~~~~~~~~~~~~~~~~",
      "~~~~~~~~~~~~~~~~",
      "'~~~~~~~~~~~~~~~",
      "'!~~~~~~~~~~~~~~",
      "'~~~~~~~~~~~~~~~",
      "'!~~~~~~~~~~~~~~",
      "'~~~~~~~~~~~~~~~",
      "!!~~~~~~~~~~~~~~",
      "66~~~~~~~~~~~~~~",
      "66~~~~~~~~~~~~~~",
      "66~~~~~~~~~~~~~~",
      "66~~~~~~~~~~~~~~",
      "66~~~~~~~~~~~~~~",
      "66~~~~~~~~~~~~~~",
      "!~~~~~~~~~~~~~~~"
    ],
    [
      "~~~~~~~~~~~~~~~~",
      "~~~~~~~~~~~~~~~~",
      "''~~~~~~~~~~~~~~",
      "''~~~~~~~~~~~~~~",
      "!!~~~~~~~~~~~~~~",
      "!!~~~~~~~~~~~~~~",
      "'!~~~~~~~~~~~~~~",
      "66~~~~~~~~~~~~~~",
      "66~~~~~~~~~~~~~~",
      "!~~~~~~~~~~~~~~~",
      "!~~~~~~~~~~~~~~~",
      "!~~~~~~~~~~~~~~~",
      "!~~~~~~~~~~~~~~~",
      "!~~~~~~~~~~~~~~~",
      "!~~~~~~~~~~~~~~~",
      "66~~~~~~~~~~~~~~"
    ],
    [
      "~~~~~~~~~~~~~~~~",
      "''~~~~~~~~~~~~~~",
      "''~~~~~~~~~~~~~~",
      "~~~~~~~~~~~~~~~~",
      "~~~~~~~~~~~~~~~~",
      "!!~~~~~~~~~~~~~~",
      "66~~~~~~~~~~~~~~",
      "66~~~~~~~~~~~~~~",
      "!~~~~~~~~~~~~~~~",
      "!~~~~~~~~~~~~~~~",
      "~~~~~~~~~~~~~~~~",
      "!~~~~~~~~~~~~~~~",
      "!~~~~~~~~~~~~~~~",
      "~~~~~~~~~~~~~~~~",
      "!~~~~~~~~~~~~~~~",
      "!~~~~~~~~~~~~~~~"
    ],
    [
      "~~~~~~~~~~~~~~~~",
      "~~~~~~~~~~~~~~~~",
      "~~~~~~~~~~~~~~~~",
      "~~~~~~~~~~~~~~~~",
      "!~~~~~~~~~~~~~~~",
      "66~~~~~~~~~~~~~~",
      "66~~~~~~~~~~~~~~",
      "!~~~~~~~~~~~~~~~",
      "!~~~~~~~~~~~~~~~",
      "~~~~~~~~~~~~~~~~",
      "~~~~~~~~~~~~~~~~",
      "!~~~~~~~~~~~~~~~",
      "!~~~~~~~~~~~~~~~",
      "~~~~~~~~~~~~~~~~",
      "~~~~~~~~~~~~~~~~",
      "~~~~~~~~~~~~~~~~"
    ]
  ]
}