{
  "xsize": 16,
  "zsize": 16,
  "refpalette": "pomkotsmechs:quarry",
  "slices": [
    [
      "~~~~~~~~~~~$!!!!",
      "~~~~~~~~~~!!!!!!",
      "~~~~~~~~!!!!!!!!",
      "~~~~!!!!!!!!!!!!",
      "~~~~!!!!!!!!!!!!",
      "~~~~!!!!!!!!!!!!",
      "~~~~!!!!!!!!!!!!",
      "~~~~!!!!!!!!!!!!",
      "~~~!!!!!!!!!!!!!",
      "~~~!!!!!!!!!!!!!",
      "~~!!!!!!!!!!!!!!",
      "~~!!!!!!!!!!!!!!",
      "~~!!!!!!!!!!!!!!",
      "~~!!!!!!!!!!!!!!",
      "~~!!!!!!!!!!!!!!",
      "~~!!!!!!!!!!!!!!"
    ],
    [
      "~~~~~~~~~~~$!$!!",
      "~~~~~~~~~~~~!~!$",
      "~~~~~~~~~~~~!!!$",
      "~~~~~~~~~~~!!!$$",
      "~~~~~~~~~~~~!~~$",
      "~~~~~~!0~~0~!~0~",
      "~~~~~~0~~~~!!!~~",
      "~~~~~~0~~~~!!!~~",
      "~~~~~~0~~~~!!!~~",
      "~~~~~~0~~~~!!!~~",
      "~~~~~~0~~~~~~~~~",
      "~~~~~~0~~~~~~~~~",
      "~~~~~~0~~~~~~~~~",
      "~~~~~~0~~~~~~~~~",
      "~~~~~~0~~~~~~~~~",
      "~~~~~~0~~~~~~~~~"
    ],
    [
      "~~~~~~~~~~~$$$~~",
      "~~~~~~~~~~~$!$$~",
      "~~~~~~~~~~~~!$$$",
      "~~~~~~~~~~~!!!$$",
      "~~~~~~~~~~~~!~~$",
      "~~~~~~!0~~0~~~0~",
      "~~~~~~0~~~~!~!~~",
      "~~~~~~~~~~~~~~~~",
      "~~~~~~~~~~~~!~~~",
      "~~~~~~~~~~~~~~~~",
      "~~~~~~~~~~~~~~~~",
      "~~~~~~0~~~~~~~~~",
      "~~~~~~~~~~~~~~~~",
      "~~~~~~~~~~~~~~~~",
      "~~~~~~~~~~~~~~~~",
      "~~~~~~~~~~~~~~~~"
    ],
    [
      "~~~~~~~~~~~~!$$~",
      "~~~~~~~~~~~$!$$$",
      "~~~~~~~~~~~~$$$$",
      "~~~~~~~~~~~!~!$$",
      "~~~~~~~~''~~~~$$",
      "~~~~~~!0000~~~00",
      "~~~~~~0~~~~!~!~~",
      "~~~~~'0~~~~~~~~~",
      "~~~~~'0~~~~~!~~~",
      "~~~~~'0~~~~~~~~~",
      "~~~~~'0~~~~~~~~~",
      "~~~~~'0~~~~~~~~~",
      "~~~~~'0~~~~~~~~~",
      "~~~~~'0~~~~~~~~~",
      "~~~~~'0~~~~~~~~~",
      "~~~~~'0~~~~~~~~~"
    ],
    [
      "~~~~~~~~~~~~$$~~",
      "~~~~~~~~~~~$$$$~",
      "~~~~~~~~~~~~$$$$",
      "~~~~~~~~~~~!~!$$",
      "~~~~~~~~~~~~~~$$",
      "~~~~~~!0000~~~00",
      "~~~~~~0~~~~!~!~~",
      "~~~~~~0~~~~~~~~~",
      "~~~~~~0~~~~~!~~~",
      "~~~~~~0~~~~~~~~~",
      "~~~~~~0~~~~~~~~~",
      "~~~~~~0~~~~~~~~~",
      "~~~~~~0~~~~~~~~~",
      "~~~~~~0~~~~~~~~~",
      "~~~~~~0~~~~~~~~~",
      "~~~~~~0~~~~~~~~~"
    ],
    [
      "~~~~~~~~~~~~$$~~",
      "~~~~~~~~~~~$$$$~",
      "~~~~~~~~~~~~$$$$",
      "~~~~~~~~~~~!$!$$",
      "~~~~~~!!!!~!~$$$",
      "~~~~~!!!!!!!!!!!",
      "~~~~~!!!!!!!!!!!",
      "~~~~~!!!!!!!!!!!",
      "~~~~~!!!!!!!!!!!",
      "~~~~~!!!!!!!!!!!",
      "~~~~~!!!!!!!!!!!",
      "~~~~~!!!!!!!!!!!",
      "~~~~~!!!!!!!!!!!",
      "~~~~~!!!!!!!!!!!",
      "~~~~~!!!!!!!!!!!",
      "~~~~~!!!!!!!!!!!"
    ]
  ]
}