{
  "xsize": 16,
  "zsize": 16,
  "refpalette": "pomkotsmechs:quarry",
  "slices": [
    [
      "~~~~~~~~~~~~~~~~",
      "~~~~~~~~~~~~~~~~",
      "~~~~~~~~~~~~~~~~",
      "~~~~~~~~~~$$~~~~",
      "~~~~~~<<~~$$$~~~",
      "~~~~~~<<0~~$00~~",
      "~~~~~~~&~~~~~~~~",
      "~~~~~~~&~~~~~~~~",
      "~~~~~~~&~~~~~~~~",
      "~~~~~~~~~~~~~~~~",
      "~~~~~~~~~~~~~~~~",
      "~~~~~~~~~~~~~~~~",
      "~~~~~~~~~~~~~~~~",
      "~~~~~~~&~~~~~~~~",
      "~~~~~~~&~~~~~~~~",
      "~~~~~~~~~~~~~~~~"
    ],
    [
      "~~~~~~~~~~~~~~~~",
      "~~~~~~~~~~~~~~~~",
      "~~~~~~~~~~$$~~~~",
      "~~~~~~~~~$$$$~~~",
      "~~~~~~<<~~$$$~~~",
      "~~~~~~<<00000000",
      "~~~~~~~&~~~~~~~~",
      "~~~~~~~&~~~~~~~~",
      "~~~~~~~&~~~~~~~~",
      "~~~~~~~&~~~~~~~~",
      "~~~~~~~&~~~~~~~~",
      "~~~~~~~&~~~~~~~~",
      "~~~~~~~&~~~~~~~~",
      "~~~~~~~&~~~~~~~~",
      "~~~~~~~&~~~~~~~~",
      "~~~~~~~&~~~~~~~~"
    ],
    [
      "~~~~~~~~~~~~~~~~",
      "~~~~~~~~~~~~~~~~",
      "~~~~~~~~~~$~~~~~",
      "~~~~~~~~~$$$~~~~",
      "~~~~~~<<~~$$~~~~",
      "~~~~~~<<00000000",
      "~~~~~~~~00000000",
      "~~~~~~~~00000000",
      "~~~~~~~~00000000",
      "~~~~~~~~00000000",
      "~~~~~~~~00000000",
      "~~~~~~~~00000000",
      "~~~~~~~~00000000",
      "~~~~~~~~00000000",
      "~~~~~~~~00000000",
      "~~~~~~~~00000000"
    ],
    [
      "~~~~~~~~~~~~~~~~",
      "~~~~~~~~~~~~~~~~",
      "~~~~~~~~~~$~~~~~",
      "~~~~~<<<<<<<<<<<",
      "~~~~~<<<<<<<<<<<",
      "~~~~~<<<<<<<<<<<",
      "~~~~~<<<<<<<<<<<",
      "~~~~~~~~&~~$$$~~",
      "~~~~~~~~&~~~$~~~",
      "~~~~~~~~&~~~$$~~",
      "~~~~~~~~&~~~~$~$",
      "~~~~~~~~&~~~~$~$",
      "~~~~~~~~~~~~~~~~",
      "~~~~~~~~~~~~~~~~",
      "~~~~~~~~~~~~~~~~",
      "~~~~~~~~~~~~~~~~"
    ],
    [
      "~~~~~~~~~~~~~~~~",
      "~~~~~~~~~~~~~~~~",
      "~~~~~~~~~~~~~~~~",
      "~~~~~~~~~~$~~~~~",
      "~~~~~~~~~~$~~~~~",
      "~~~~~~~~~~$$~~~~",
      "~~~~~~~~~~~$$~~~",
      "~~~~~<<<<<<<<<<<",
      "~~~~~<<<<<<<<<<<",
      "~~~~~<<<<<<<<<<<",
      "~~~~~<<<<<<<<<<<",
      "~~~~~~~~&~~~$$$$",
      "~~~~~~~~&~~~$$$$",
      "~~~~~~~~&~~~$$~~",
      "~~~~~~~~&~~~$~~~",
      "~~~~~~~~&~~~$~~~"
    ],
    [
      "~~~~~~~~~~~~~~~~",
      "~~~~~~~~~~~~~~~~",
      "~~~~~~~~~~~~~~~~",
      "~~~~~~~~~~~~~~~~",
      "~~~~~~~~~~~~~~~~",
      "~~~~~~~~~~~~~~~~",
      "~~~~~~~~~~~~~~~~",
      "~~~~~~~~~~~~$~~~",
      "~~~~~~~~~~~~$~~~",
      "~~~~~~~~~~~~$$~~",
      "~~~~~~~~~~~~$$$$",
      "~~~~~<<<<<<<<<<<",
      "~~~~~<<<<<<<<<<<",
      "~~~~~<<<<<<<<<<<",
      "~~~~~<<<<<<<<<<<",
      "~~~~~<<<<<<<<<<<"
    ]
  ]
}