{
  "xsize": 16,
  "zsize": 16,
  "refpalette": "lostcities:quarry",
  "slices": [
    [
      "~~~~~~~~~~~~~~~~",
      "~~~~~~~~~~~~~~~~",
      "~~~~~~~~~~~~~~~~",
      "~~~~~~~~~!!!!!~~",
      "~~~~~~~~~!!!!!~~",
      "~~~~~~~~~!!!!!~~",
      "~~~~~~~~~!!!!!~~",
      "~~~~~~~~~!!!!!~~",
      "~~~~~~~~~!!!!!~~",
      "~~~~~~~~~!!!!!~~",
      "~~~~~~~~~!!!!!~~",
      "~~~~~~~~~!!!!!~~",
      "~~~~~~~~~!!!!!~~",
      "~~~~~~~~~!!!!!~~",
      "~~~~~~~~~!!!!!~~",
      "~~~~~~~~~!!!!!~~"
    ],
    [
      "!!~~~~~~~~~~~~~~",
      "!!~~~~~~~~~~~~~~",
      "!!!~~~~~~!!!!!~~",
      "!!!~~~~~~!!!!!~~",
      "!!!~~~~~~~000~~~",
      "!!!~~~~~~~000~~~",
      "!!!~~~~~~~000~~~",
      "!!!~~~~~~~~~~~~~",
      "!!!~~~~~~~~~~~~~",
      "!!!~~~~~~~~~~~~~",
      "!!!~~~~~~~000~~~",
      "!!!~~~~~~~000~~~",
      "!!!~~~~~~~000~~~",
      "!!!~~~~~~~~~~~~~",
      "!!!~~~~~~~~~~~~~",
      "!!!~~~~~~~~~~~~~"
    ],
    [
      "~~~~~~~~~~~~~~~~",
      "~!~~~~~~~!!!!!~~",
      "!!!~~~~~~!!!!!~~",
      "~~!~~~~~~~000~~~",
      "~~!~~3~~~~'~'~~~",
      "333333333'~~~'~~",
      "~~!~~3~~~~'~'~~~",
      "~~!~~~~~~~000~~~",
      "~~!~~~~~~~~~~~~~",
      "~~!~~~~~~~000~~~",
      "~~!~~3~~~~'~'~~~",
      "333333333'~~~'~~",
      "~~!~~3~~~~'~'~~~",
      "~~!~~~~~~~000~~~",
      "~~!~~~~~~~~~~~~~",
      "~~!~~~~~~~000~~~"
    ],
    [
      "~~~~~~~~~~~~~~~~",
      "~!~~~~~~~!!!!!~~",
      "!!!~~~~~~~~~~~~~",
      "~~!~~~~~~~000~~~",
      "333333333'~~~'~~",
      "~~!~~~~~3~'~'~~~",
      "333333333'~~~'~~",
      "~~!~~~~~~~000~~~",
      "~~!~~~~~~~~~~~~~",
      "~~!~~~~~~~000~~~",
      "333333333'~~~'~~",
      "~~!~~~~~3~'~'~~~",
      "333333333'~~~'~~",
      "~~!~~~~~~~000~~~",
      "~~!~~~~~~~~~~~~~",
      "~~!~~~~~~~000~~~"
    ],
    [
      "!!~~~~~~~~~~~~~~",
      "!!~~~~~~~!!!!!~~",
      "!!!~~~~~~!!!!!~~",
      "~~!~~~~~~~000~~~",
      "~~!~~3~~~~'~'~~~",
      "333333333'~~~'~~",
      "~~!~~3~~~~'~'~~~",
      "~~!~~~~~~~000~~~",
      "~~!~~~~~~~~~~~~~",
      "~~!~~~~~~~000~~~",
      "~~!~~3~~~~'~'~~~",
      "333333333'~~~'~~",
      "~~!~~3~~~~'~'~~~",
      "~~!~~~~~~~000~~~",
      "~~!~~~~~~~~~~~~~",
      "~~!~~~~~~~000~~~"
    ],
    [
      "~~~~~~~~~~~~~~~~",
      "~!~~~~~~~~~~~~~~",
      "!!!~~~~~~!!!!!~~",
      "~~!~~~~~~!!!!!~~",
      "~~!~~~~~~~000~~~",
      "~~!~~~~~~~000~~~",
      "~~!~~~~~~~000~~~",
      "~~!~~~~~~~~~~~~~",
      "~~!~~~~~~~~~~~~~",
      "~~!~~~~~~~~~~~~~",
      "~~!~~~~~~~000~~~",
      "~~!~~~~~~~000~~~",
      "~~!~~~~~~~000~~~",
      "~~!~~~~~~~~~~~~~",
      "~~!~~~~~~~~~~~~~",
      "~~!~~~~~~~~~~~~~"
    ]
  ]
}