{
  "refpalette": "lcmt:town_interior",
  "xsize": 16,
  "zsize": 16,
  "slices": [
    [
      "                ",
      "                ",
      "                ",
      "                ",
      "                ",
      "                ",
      "                ",
      "                ",
      "                ",
      "                ",
      "                ",
      "                ",
      "                ",
      "                ",
      "                ",
      "                "
    ],
    [
      "                ",
      "   ###$:$#####  ",
      "   #         #  ",
      "   # ####### #  ",
      "   # #:      #  ",
      "   # #     # #  ",
      "   # ####### #  ",
      "   #     #V1 #  ",
      "   # ### #V  #  ",
      "   # #:  #V  #  ",
      "   # #   #   #  ",
      "   # #VV #VVV#  ",
      "   ###########  ",
      "                ",
      "                ",
      "                "
    ],
    [
      "                ",
      "   ###$:$#####  ",
      "   #         #  ",
      "   # ####### #  ",
      "   # #:      #  ",
      "   # # VVV # #  ",
      "   # ####### #  ",
      "   #     #   #  ",
      "   # ### #|  #  ",
      "   # #:  #|  #  ",
      "   # #   #   #  ",
      "   #V#oo # oo#  ",
      "   ###########  ",
      "                ",
      "                ",
      "                "
    ],
    [
      "                ",
      "   ###$$$#####  ",
      "   # :     : #  ",
      "   # ####### #  ",
      "   # #:    # #  ",
      "   # # ||  # #  ",
      "   # #########  ",
      "   #     #   #  ",
      "   #:#####   #  ",
      "   # #:  # V #  ",
      "   # # V #   #  ",
      "   #o#   #   #  ",
      "   ###########  ",
      "                ",
      "                ",
      "                "
    ],
    [
      "                ",
      "   ###########  ",
      "   # :     : #  ",
      "   # ####### #  ",
      "   # #:::  # #  ",
      "   # #:    # #  ",
      "   # #########  ",
      "   #     #   #  ",
      "   #:#####:::#  ",
      "   # #:  #:u:#  ",
      "   # # u #:::#  ",
      "   # #   #   #  ",
      "   ###########  ",
      "                ",
      "                ",
      "                "
    ]
  ]
}
