{
  "refpalette": "lcmt:town_interior",
  "xsize": 16,
  "zsize": 16,
  "slices": [
    [
      "                ",
      "                ",
      "                ",
      "                ",
      "                ",
      "                ",
      "                ",
      "                ",
      "                ",
      "                ",
      "                ",
      "                ",
      "                ",
      "                ",
      "                ",
      "                "
    ],
    [
      "                ",
      "   ###$:$#####  ",
      "   #         #  ",
      "   # ####### #  ",
      "   # #:      #  ",
      "   # #    1# #  ",
      "   # ####### #  ",
      "   #     #V1 #  ",
      "   # ### #V  #  ",
      "   # #:  #V  #  ",
      "   # #   #V  #  ",
      "   #1#VVV#VVV#  ",
      "   ###########  ",
      "                ",
      "                ",
      "                "
    ],
    [
      "                ",
      "   ###$:$#####  ",
      "   #         #  ",
      "   # ####### #  ",
      "   # #:      #  ",
      "   # # VVV # #  ",
      "   # ####### #  ",
      "   #     #   #  ",
      "   # ### #*  #  ",
      "   # #:  #*  #  ",
      "   # #   #   #  ",
      "   #V#!!1# !!#  ",
      "   ###########  ",
      "                ",
      "                ",
      "                "
    ],
    [
      "                ",
      "   ###$$$#####  ",
      "   # :     : #  ",
      "   # ####### #  ",
      "   # #:    # #  ",
      "   # # *?  # #  ",
      "   # #########  ",
      "   #     #   #  ",
      "   #:#####   #  ",
      "   # #:  # V #  ",
      "   # # V #   #  ",
      "   #C#   #   #  ",
      "   ###########  ",
      "                ",
      "                ",
      "                "
    ],
    [
      "                ",
      "   ###########  ",
      "   # :     : #  ",
      "   # ####### #  ",
      "   # #:::  # #  ",
      "   # #:    # #  ",
      "   # #########  ",
      "   #     #   #  ",
      "   #:#####:::#  ",
      "   # #:  #:u:#  ",
      "   # # u #:::#  ",
      "   # #   #   #  ",
      "   ###########  ",
      "                ",
      "                ",
      "                "
    ]
  ]
}
