{
  "xsize": 16,
  "zsize": 16,
  "slices": [
    [
      "################",
      "################",
      "################",
      "################",
      "################",
      "################",
      "################",
      "################",
      "################",
      "#############  #",
      "#############  #",
      "#############  #",
      "#############  #",
      "#############))#",
      "################",
      "################"
    ],
    [
      "################",
      "#DDDDDDDDDDDDDD#",
      "#DDDDDDDDDDGDDD#",
      "#DDDGDGDDDDGGDD#",
      "#DDGGGDDDDGGDDD#",
      "#DDGGGDDDDGGDDD#",
      "#DGDGGGDDGDGDDD#",
      "#DDDDDGDDDDDGDD#",
      "#DDDDDDGDDDD####",
      "#DDGDDGGDDDD#  #",
      "#DDDGGGDDDDD#  #",
      "#DDGGGGDDDDD#  #",
      "#DGDGDDGDDDD#  #",
      "#DDDDDGDDDDD#  #",
      "#DDDDDDDDDDD#  #",
      "################"
    ],
    [
      "                ",
      "        p       ",
      "       p        ",
      "    p       p   ",
      "                ",
      "           p    ",
      "  p             ",
      "                ",
      "       p        ",
      "                ",
      "                ",
      "     p          ",
      "  p             ",
      "                ",
      "                ",
      "                "
    ],
    [
      "                ",
      "                ",
      "                ",
      "                ",
      "                ",
      "                ",
      "                ",
      "                ",
      "                ",
      "                ",
      "                ",
      "                ",
      "                ",
      "                ",
      "                ",
      "                "
    ]
  ]
}
