{
  "xsize": 16,
  "zsize": 16,
  "slices": [
    [
      "################",
      "################",
      "################",
      "################",
      "################",
      "################",
      "################",
      "################",
      "################",
      "################",
      "#############  #",
      "#############  #",
      "#############  #",
      "#############))#",
      "################",
      "################"
    ],
    [
      "########        ",
      "#WWWWWW#        ",
      "#WWWWWW#        ",
      "#WWWWWW#        ",
      "#WWWWWW#        ",
      "#WWWWWW#        ",
      "#WWWWWW#        ",
      "#WWWWWW#        ",
      "#WWWWWW#    :  :",
      "#WWWWWW#       :",
      "#WWWWWW#       :",
      "#WWWWWW#       :",
      "#WWWWWW#       :",
      "#WWWWWW#       :",
      "#WWWWWW#       :",
      "########    ::::"
    ],
    [
      "::::::::        ",
      ":               ",
      ":               ",
      ":               ",
      ":               ",
      ":               ",
      ":               ",
      ":               ",
      ":           :  :",
      ":               ",
      ":               ",
      ":               ",
      ":               ",
      ":               ",
      ":               ",
      "::::::::    :  :"
    ],
    [
      "                ",
      "                ",
      "                ",
      "                ",
      "                ",
      "                ",
      "                ",
      "                ",
      "            ####",
      "            ####",
      "            ####",
      "            ####",
      "            ####",
      "            ####",
      "            ####",
      "            ####"
    ]
  ]
}
