{
  "xsize": 16,
  "zsize": 16,
  "slices": [
    [
      "################",
      "##QSQSQSQSQSQSQ#",
      "#QSQSQSQSQSQSQSQ",
      "#SQSQSQSQSQSQSQS",
      "#QSQSQSQSQSQSQSQ",
      "#SQSQSQSQSQSQSQS",
      "#QSQSQSQSQSQSQSQ",
      "#SQSQSQSQSQSQSQS",
      "#QSQSQSQSQSQSQSQ",
      "#SQSQSQSQSQSQ  S",
      "#QSQSQSQSQSQS  Q",
      "#SQSQSQSQSQSQ  S",
      "#QSQSQSQSQSQS  Q",
      "#SQSQSQSQSQSQ))S",
      "#QSQSQSQSQSQSQSQ",
      "##QSQSQSQSQSQSQS"
    ],
    [
      "##::#########::#",
      "##             #",
      ":               ",
      ":               ",
      "#               ",
      "#               ",
      "#               ",
      "#               ",
      "#            )) ",
      "#           Q  Q",
      "#           Q  Q",
      "#           Q  Q",
      "#           Q  Q",
      ":           Q  Q",
      ":               ",
      "##              "
    ],
    [
      "##::#########::#",
      "##             #",
      ":               ",
      ":               ",
      "#               ",
      "#               ",
      "#               ",
      "#               ",
      "#               ",
      "#           a))a",
      "#           a  a",
      "#           a  a",
      "#           a  a",
      ":           a  a",
      ":               ",
      "##              "
    ],
    [
      "##::#########::#",
      "##             #",
      ":               ",
      ":               ",
      "#               ",
      "#               ",
      "#               ",
      "#               ",
      "#               ",
      "#           a  a",
      "#           a))a",
      "#           a  a",
      "#           a  a",
      ":           a  a",
      ":               ",
      "##              "
    ],
    [
      "##::#########::#",
      "##             #",
      ":               ",
      ":               ",
      "#               ",
      "#               ",
      "#               ",
      "#               ",
      "#               ",
      "#           a  a",
      "#           a  a",
      "#           a))a",
      "#           a  a",
      ":           a  a",
      ":               ",
      "##              "
    ],
    [
      "################",
      "################",
      "################",
      "################",
      "################",
      "################",
      "################",
      "################",
      "################",
      "#############  #",
      "#############  #",
      "#############  #",
      "#############))#",
      "#############  #",
      "################",
      "################"
    ]
  ]
}