{
  "refpalette": "lcmt:town_interior",
  "xsize": 16,
  "zsize": 16,
  "slices": [
    [
      "                ",
      "                ",
      "                ",
      "                ",
      "                ",
      "                ",
      "      kkk kkk   ",
      "      k1k k1k   ",
      "      kkk kkk   ",
      "                ",
      "      kkk kkk   ",
      "      k1k k1k   ",
      "      kkk kkk   ",
      "                ",
      "                ",
      "                "
    ],
    [
      "                ",
      "                ",
      "                ",
      "   #  #++++++++ ",
      "       |   |    ",
      "                ",
      "   #  qqq qqq   ",
      "   +| qjq qjq   ",
      "   +  qqq qqq   ",
      "   +            ",
      "   +  qqq qqq   ",
      "   +| qjq qjq   ",
      "   +  qqq qqq   ",
      "   +            ",
      "   +            ",
      "                "
    ],
    [
      "                ",
      "                ",
      "                ",
      "   #  #++++++++ ",
      "       i   i    ",
      "                ",
      "   #            ",
      "   +i  C   C    ",
      "   +            ",
      "   +            ",
      "   +            ",
      "   +i  C   C    ",
      "   +            ",
      "   +            ",
      "   +            ",
      "                "
    ],
    [
      "                ",
      "                ",
      "                ",
      "   ####++++++++ ",
      "   #   i   i    ",
      "   #            ",
      "   #            ",
      "   +i           ",
      "   +            ",
      "   +            ",
      "   +            ",
      "   +i           ",
      "   +            ",
      "   +            ",
      "   +            ",
      "                "
    ],
    [
      "                ",
      "                ",
      "                ",
      "   ####++++++++ ",
      "   #            ",
      "   #            ",
      "   #            ",
      "   +   %   {    ",
      "   +            ",
      "   +            ",
      "   +            ",
      "   +   {   %    ",
      "   +            ",
      "   +            ",
      "   +            ",
      "                "
    ]
  ]
}
