{
  "xsize": 16,
  "zsize": 16,
  "refpalette": "lcmt:town_interior",
  "slices": [
    [
      "                ",
      "                ",
      "                ",
      "                ",
      "                ",
      "                ",
      "                ",
      "                ",
      "                ",
      "                ",
      "                ",
      "                ",
      "                ",
      "                ",
      "                ",
      "                "
    ],
    [
      "                ",
      "                ",
      "#               ",
      "#   uuuuuuu     ",
      "#   _uuuuu_     ",
      "#   _uuuuu_     ",
      "                ",
      "                ",
      "# )) )) )) ))   ",
      "#               ",
      "# )) )) )) ))   ",
      "#               ",
      "# )) )) )) ))   ",
      "#               ",
      "#               ",
      "######   #####  "
    ],
    [
      "                ",
      "                ",
      "#               ",
      "#   ooooooo     ",
      "#    qqqqq      ",
      "#    qqrqq      ",
      "                ",
      "                ",
      "#               ",
      "#               ",
      "#               ",
      "#               ",
      "#               ",
      "#               ",
      "#               ",
      "######   #####  "
    ],
    [
      "                ",
      "                ",
      "#               ",
      "#   ooooooo     ",
      "#               ",
      "#               ",
      "#               ",
      "#               ",
      "#               ",
      "#               ",
      "#               ",
      "#               ",
      "#               ",
      "#               ",
      "#               ",
      "##############  "
    ],
    [
      "                ",
      "                ",
      "#               ",
      "#   ooooooo     ",
      "#               ",
      "#               ",
      "#               ",
      "#               ",
      "#      E        ",
      "#               ",
      "#               ",
      "#               ",
      "#               ",
      "#               ",
      "#               ",
      "##############  "
    ]
  ]
}
