 {
  "refpalette": "lostcities:town_interior",
  "xsize": 16,
  "zsize": 16,
  "slices": [
    [
      "                ",
      "                ",
      "   kkkkkkkkkkk  ",
      "   k         k  ",
      "   kkkkkkkkkkk  ",
      "                ",
      "   kkkkkkkkkkk  ",
      "   k         k  ",
      "   kkkkkkkkkkk  ",
      "                ",
      "   kkkkkkkkkkk  ",
      "   k         k  ",
      "   kkkkkkkkkkk  ",
      "                ",
      "                ",
      "                "
    ],
    [
      "  ::::#  #:::::#",
      "               :",
      "               :",
      "    unnnnnnnu  :",
      "               :",
      "               :",
      "               #",
      "    unnnnnnnu   ",
      "                ",
      "               #",
      "               :",
      "    unnnnnnnu  :",
      "               :",
      "               :",
      "                ",
      "                "
    ],
    [
      "  ::::#  #:::::#",
      "               :",
      "               :",
      "    uIIIIIIIu  :",
      "               :",
      "               :",
      "               #",
      "    uIIIIIIIu   ",
      "                ",
      "               #",
      "               :",
      "    uIIIIIIIu  :",
      "               :",
      "               :",
      "                ",
      "                "
    ],
    [
      "  ::::#  #:::::#",
      "               :",
      "               :",
      "    uIIIIIIIu  :",
      "               :",
      "               :",
      "               #",
      "    uIIIIIIIu   ",
      "                ",
      "               #",
      "               :",
      "    uIIIIIIIu  :",
      "               :",
      "               :",
      "                ",
      "                "
    ],
    [
      "  ::::####:::::#",
      "               :",
      "               :",
      "               :",
      "               :",
      "    <   E   >  :",
      "               #",
      "               #",
      "               #",
      "    <   E   >  #",
      "               :",
      "               :",
      "               :",
      "               :",
      "                ",
      "                "
    ]
  ]
}
