{
  "refpalette": "lcmt:town_interior",
  "xsize": 16,
  "zsize": 16,
  "slices": [
    [
      "                ",
      "                ",
      "                ",
      "                ",
      "                ",
      "                ",
      "                ",
      "                ",
      "                ",
      "                ",
      "                ",
      "                ",
      "                ",
      "                ",
      "                ",
      "                "
    ],
    [
      "                ",
      "                ",
      "                ",
      "  ###########   ",
      "  #         #   ",
      "  # #:      #   ",
      "  # #########   ",
      "  #        j#   ",
      "  # ## ### ##   ",
      "  #  # #V1  #   ",
      "  #  # #    #   ",
      "  # :# #V   #   ",
      "  #  # #V   #   ",
      "  #VV# #V VV#   ",
      "  ###$:$#####   ",
      "                "
    ],
    [
      "                ",
      "                ",
      "                ",
      "  ###########   ",
      "  #         #   ",
      "  # #: VVVV #   ",
      "  # #########   ",
      "  #        |#   ",
      "  # ## ### ##   ",
      "  #  # #o   #   ",
      "  #  # #    #   ",
      "  # :# #|   #   ",
      "  #  # #|   #   ",
      "  #oo# #  | #   ",
      "  ###$:$#####   ",
      "                "
    ],
    [
      "                ",
      "                ",
      "                ",
      "  ###########   ",
      "  # #       #   ",
      "  # #: ooo  #   ",
      "  # #########   ",
      "  # #       #   ",
      "  #### ######   ",
      "  #  # #    #   ",
      "  #  # #    #   ",
      "  # :# #  V #   ",
      "  #  # #    #   ",
      "  #  # #    #   ",
      "  ###$$$#####   ",
      "                "
    ],
    [
      "                ",
      "                ",
      "                ",
      "  ###########   ",
      "  #{#       #   ",
      "  # #::     #   ",
      "  # #########   ",
      "  # #      {#   ",
      "  #### ######   ",
      "  #  # #    #   ",
      "  #  # #    #   ",
      "  # :# #  u #   ",
      "  # :# #    #   ",
      "  #  # #    #   ",
      "  ###########   ",
      "                "
    ]
  ]
}
