{
  "xsize": 16,
  "zsize": 16,
  "slices": [
    [
      "##::#aaaaaa#::##",
      "#####SQSQSQ#####",
      ":#SQSQSQSQSQSQSQ",
      ":#QSQSQSQSQSQSQS",
      "##SQSQSQSQSQSQSQ",
      "aSQSQSQSQSQSQSQS",
      "aQSQSQSQSQSQSQSQ",
      "aSQSQSQSQSQSQSQS",
      "aQSQSQSQSQSQSQSQ",
      "aSQSQSQSQSQSQ  S",
      "aQSQSQSQSQSQS  Q",
      "##QSQSQSQSQSQ  S",
      ":#SQSQSQSQSQS  Q",
      ":#QSQSQSQSQSQ))S",
      "##SQSQSQSQSQSQSQ",
      "##QSQSQSQSQSQSQS"
    ],
    [
      "##::#aaaaaa#::##",
      "##aa#      #aa##",
      ":a              ",
      ":a              ",
      "##              ",
      "a               ",
      "a               ",
      "a               ",
      "a            )) ",
      "a           Q  Q",
      "a           Q  Q",
      "##          Q  Q",
      ":a          Q  Q",
      ":a          Q  Q",
      "##              ",
      "##              "
    ],
    [
      "##::#aaaaaa#::##",
      "##aa#      #aa##",
      ":a              ",
      ":a              ",
      "##              ",
      "a               ",
      "a               ",
      "a               ",
      "a               ",
      "a           a))a",
      "a           a  a",
      "##          a  a",
      ":a          a  a",
      ":a          a  a",
      "##              ",
      "##              "
    ],
    [
      "##::#aaaaaa#::##",
      "##aa#      #aa##",
      ":a              ",
      ":a              ",
      "##              ",
      "a               ",
      "a               ",
      "a               ",
      "a               ",
      "a           a  a",
      "a           a))a",
      "##          a  a",
      ":a          a  a",
      ":a          a  a",
      "##              ",
      "##              "
    ],
    [
      "##::#aaaaaa#::##",
      "##aa#      #aa##",
      ":a              ",
      ":a              ",
      "##              ",
      "a               ",
      "a               ",
      "a               ",
      "a               ",
      "a           a  a",
      "a           a  a",
      "##          a))a",
      ":a          a  a",
      ":a          a  a",
      "##              ",
      "##              "
    ],
    [
      "##::#aaaaaa#::##",
      "################",
      ":###############",
      ":###############",
      "################",
      "a###############",
      "a###############",
      "a###############",
      "a###############",
      "a############  #",
      "a############  #",
      "#############  #",
      ":############))#",
      ":############  #",
      "################",
      "################"
    ]
  ]
}