{
  "refpalette": "lcmt:town_interior",
  "xsize": 16,
  "zsize": 16,
  "slices": [
    [
      "                ",
      "                ",
      "                ",
      "                ",
      "                ",
      "                ",
      "                ",
      "                ",
      "                ",
      "                ",
      "                ",
      "                ",
      "                ",
      "                ",
      "                ",
      "                "
    ],
    [
      "                ",
      "                ",
      "                ",
      "                ",
      "    ######|     ",
      "    #j OU#      ",
      "    #[   #      ",
      "    ## ###      ",
      "    #j          ",
      "    #j          ",
      "    ## ###      ",
      "    #[   #      ",
      "    #j OU#      ",
      "    ######      ",
      "                ",
      "                "
    ],
    [
      "                ",
      "                ",
      "                ",
      "                ",
      "    ######i     ",
      "    #* NQ#      ",
      "    #P : #      ",
      "    ## ###      ",
      "    #`          ",
      "    #`          ",
      "    ## ###      ",
      "    #P : #      ",
      "    #* NQ#      ",
      "    ######      ",
      "                ",
      "                "
    ],
    [
      "                ",
      "                ",
      "                ",
      "                ",
      "    ######i     ",
      "    #    #      ",
      "    #    #      ",
      "    ######      ",
      "    #`          ",
      "    #`          ",
      "    ######      ",
      "    #    #      ",
      "    #    #      ",
      "    ######      ",
      "                ",
      "                "
    ],
    [
      "                ",
      "                ",
      "                ",
      "                ",
      "    ######      ",
      "    #    #      ",
      "    #    #      ",
      "    ######      ",
      "    #           ",
      "    #   E       ",
      "    ######      ",
      "    #    #      ",
      "    #    #      ",
      "    ######      ",
      "                ",
      "                "
    ]
  ]
}
