{
  "xsize": 16,
  "zsize": 16,
  "refpalette": "lcmt:town_interior",
  "slices": [
    [
      "                ",
      "                ",
      "                ",
      "                ",
      "                ",
      "                ",
      "                ",
      "                ",
      "                ",
      "                ",
      "                ",
      "                ",
      "                ",
      "                ",
      "                ",
      "                "
    ],
    [
      "  #####   ######",
      "               #",
      "               #",
      "   (( (( (( (( #",
      "               #",
      "   (( (( (( (( #",
      "               #",
      "   (( (( (( (( #",
      "                ",
      "                ",
      "     _uuuuu_   #",
      "     _uuuuu_   #",
      "     uuuuuuu   #",
      "               #",
      "                ",
      "                "
    ],
    [
      "  #####   ######",
      "               #",
      "               #",
      "               #",
      "               #",
      "               #",
      "               #",
      "               #",
      "                ",
      "                ",
      "      qqsqq    #",
      "      qqqqq    #",
      "     ooooooo   #",
      "               #",
      "                ",
      "                "
    ],
    [
      "  ##############",
      "               #",
      "               #",
      "               #",
      "               #",
      "               #",
      "               #",
      "               #",
      "               #",
      "               #",
      "               #",
      "               #",
      "     ooooooo   #",
      "               #",
      "                ",
      "                "
    ],
    [
      "  ##############",
      "               #",
      "               #",
      "               #",
      "               #",
      "               #",
      "               #",
      "        E      #",
      "               #",
      "               #",
      "               #",
      "               #",
      "     ooooooo   #",
      "               #",
      "                ",
      "                "
    ]
  ]
}