{
  "refpalette": "lostcities:center_interior",
  "xsize": 16,
  "zsize": 16,
  "slices": [
    [
      "                ",
      "                ",
      "                ",
      "                ",
      "                ",
      "                ",
      "                ",
      "                ",
      "                ",
      "                ",
      "                ",
      "                ",
      "                ",
      "                ",
      "                ",
      "                "
    ],
    [
      "                ",
      "                ",
      "                ",
      "                ",
      "     #######    ",
      "     # ::: #    ",
      "    u#     #    ",
      "    u#:   :#    ",
      "     #:    #    ",
      "     #    :#    ",
      "    u#:    #    ",
      "    u#     #    ",
      "     #%  kk#    ",
      "     ###J###    ",
      "                ",
      "                "
    ],
    [
      "                ",
      "                ",
      "                ",
      "                ",
      "     #######    ",
      "     # uuu #    ",
      "    u#     #    ",
      "    u1u   u#    ",
      "     #u    #    ",
      "     #%   u#    ",
      "    u#u    #    ",
      "    u#     #    ",
      "     #   %?#    ",
      "     ###U###    ",
      "                ",
      "                "
    ],
    [
      "                ",
      "                ",
      "                ",
      "                ",
      "     #######    ",
      "     # uuu #    ",
      "    :#     #    ",
      "    :#u   u#    ",
      "     #u    #    ",
      "     #    u#    ",
      "    :#u    #    ",
      "    :#     #    ",
      "     #     #    ",
      "     #######    ",
      "                ",
      "                "
    ],
    [
      "                ",
      "                ",
      "                ",
      "                ",
      "     #######    ",
      "     #%::: #    ",
      "    :#     #    ",
      "    :#:   g#    ",
      "     #:   %#    ",
      "     #    g#    ",
      "    :#:    #    ",
      "    :#     #    ",
      "     #     #    ",
      "     #######    ",
      "                ",
      "                "
    ]
  ]
}
