{
  "xsize": 16,
  "zsize": 16,
  "slices": [
    [
      "################",
      "######QSQS######",
      "SQSQSQSQSQSQSQ##",
      "QSQSQSQSQSQSQS##",
      "SQSQSQSQSQSQSQ##",
      "QSQSQSQSQSQSQS##",
      "SQSQSQSQSQSQSQS#",
      "QSQSQSQSQSQSQSQ#",
      "SQSQSQSQSQSQSQS#",
      "QSQSQSQSQSQSQSQ#",
      "SQSQSQSQSQSQSQ##",
      "QSQSQSQSQSQSQS##",
      "SQSQSQSQSQSQSQ##",
      "QSQSQSQSQSQSQS##",
      "SQSQSQSQSQSQSQ##",
      "QSQSQSQSQSQSQS##"
    ],
    [
      "################",
      "######    ######",
      "              ##",
      "              ##",
      "              ##",
      "              ##",
      "               #",
      "               #",
      "               #",
      "               #",
      "              ##",
      "              ##",
      "              ##",
      "              ##",
      "              ##",
      "              ##"
    ],
    [
      "################",
      "######    ######",
      "              ##",
      "              ##",
      "              ##",
      "              ##",
      "               #",
      "               #",
      "               #",
      "               #",
      "              ##",
      "              ##",
      "              ##",
      "              ##",
      "              ##",
      "              ##"
    ],
    [
      "################",
      "######    ######",
      "              ##",
      "              ##",
      "              ##",
      "              ##",
      "               #",
      "               #",
      "               #",
      "               #",
      "              ##",
      "              ##",
      "              ##",
      "              ##",
      "              ##",
      "              ##"
    ],
    [
      "################",
      "######    ######",
      "              ##",
      "              ##",
      "              ##",
      "              ##",
      "               #",
      "               #",
      "               #",
      "               #",
      "              ##",
      "              ##",
      "              ##",
      "              ##",
      "              ##",
      "              ##"
    ],
    [
      "################",
      "################",
      "################",
      "################",
      "################",
      "################",
      "################",
      "################",
      "################",
      "################",
      "################",
      "################",
      "################",
      "################",
      "################",
      "################"
    ]
  ]
}